File: Sectio1_28_samples/XRD/No_006_600_17.ras
*RAS_DATA_START
*RAS_HEADER_START
*DISP_FMT_X "%.2f"
*DISP_FMT_Y "%.0f"
*DISP_FULLSCALE "4024.0000000000"
*DISP_LINE_COLOR "255.0000000000"
*DISP_LINE_STYLE "0.0000000000"
*DISP_LINE_WIDTH "0.2500000000"
*DISP_NOTE "測定データ-5"
*DISP_OFFSET_Y "0.0000000000"
*DISP_PEAKSEARCH_UNIT_Y "cps"
*DISP_RANGE_BOTTOM "0.0000000000"
*DISP_RANGE_LEFT "20.0000000000"
*DISP_RANGE_LOGCUTOFF "0.0100000000"
*DISP_RANGE_RIGHT "80.0000000000"
*DISP_RANGE_TOP "4024.0000000000"
*DISP_SCALE_MODE_Y "0.0000000000"
*DISP_TAB_NAME "2θ/θ"
*DISP_TITLE_Y "強度"
*DISP_UNIT_Y "cps"
*DISP_WINDOW_NAME "MSG_MACROENGINE"
*FILE_COMMENT " "
*FILE_MD5 ""
*FILE_MEMO " "
*FILE_OPERATOR "Administrator"
*FILE_SAMPLE " "
*FILE_TYPE "RAS_RAW"
*FILE_USERGROUP "システムマネージャ"
*FILE_VERSION "1.0000000000"
*HW_ATTACHMENT_ID "ATT0025"
*HW_ATTACHMENT_NAME "標準|Standard"
*HW_COUNTER_ID-0 "CUT0025"
*HW_COUNTER_ID-1 "CUT0020"
*HW_COUNTER_ID-2 "CUT0020"
*HW_COUNTER_ID-3 "CSL0021"
*HW_COUNTER_ID-4 "CMC0021"
*HW_COUNTER_NAME-0 "D/teX Ultra|D/teX Ultra"
*HW_COUNTER_NAME-1 "None|None"
*HW_COUNTER_NAME-2 "None|None"
*HW_COUNTER_NAME-3 "BBM|BBM"
*HW_COUNTER_NAME-4 "検出器モノクロメータ|Detector monochromator"
*HW_COUNTER_SELECT_NAME "D/teX Ultra|D/teX Ultra"
*HW_GONIOMETER_ID "GON0023"
*HW_GONIOMETER_NAME "SmartLab|SmartLab"
*HW_GONIOMETER_RADIUS-0 "90.0"
*HW_GONIOMETER_RADIUS-1 "114.0"
*HW_GONIOMETER_RADIUS-2 "190.0"
*HW_GONIOMETER_RADIUS-3 "300.0"
*HW_GONIOMETER_RADIUS-4 "187.0"
*HW_GONIOMETER_RADIUS-5 "300.0"
*HW_GONIOMETER_RADIUS-6 "113.0"
*HW_GONIOMETER_RADIUS-7 "331.0"
*HW_I_OPT_ID-0 "CBO0021"
*HW_I_OPT_ID-1 "ICR0023"
*HW_I_OPT_ID-2 "ISL0021"
*HW_I_OPT_ID-3 "ISO0021"
*HW_I_OPT_ID-4 "IAD0021"
*HW_I_OPT_ID-5 "IPR0001"
*HW_I_OPT_NAME-0 "CBOユニット|CBO unit"
*HW_I_OPT_NAME-1 "標準入射光学ユニット|Standard incident optical unit"
*HW_I_OPT_NAME-2 "標準入射スリットボックス|Standard incident slit box"
*HW_I_OPT_NAME-3 "入射平行スリット|Incident parallel slit"
*HW_I_OPT_NAME-4 "長手制限スリット|Length limiting slit"
*HW_I_OPT_NAME-5 "None|None"
*HW_R_ATTENUATER_AUTOMODE "0"
*HW_R_OPT_ID-0 "RSS0021"
*HW_R_OPT_ID-1 "RCR0023"
*HW_R_OPT_ID-2 "RSO0021"
*HW_R_OPT_ID-3 "RRS0021"
*HW_R_OPT_ID-4 "ATN0021"
*HW_R_OPT_ID-5 "RFL0021"
*HW_R_OPT_ID-6 "RAD0021"
*HW_R_OPT_NAME-0 "標準受光スリットボックス1|Standard receiving slit box # 1"
*HW_R_OPT_NAME-1 "標準受光光学ユニット1|Standard receiving unit # 1"
*HW_R_OPT_NAME-2 "標準受光光学ユニット2|Standard receiving optical unit # 2"
*HW_R_OPT_NAME-3 "標準受光スリットボックス2|Standard receiving slit box # 2"
*HW_R_OPT_NAME-4 "標準アッテネータ|Standard Attenuator"
*HW_R_OPT_NAME-5 "Cu Kβ|Cu K-beta"
*HW_R_OPT_NAME-6 "調整用受光スリット|Alignment receiving slit"
*HW_SAMPLE_HOLDER_ID "SMP0023"
*HW_SAMPLE_HOLDER_NAME "標準Zステージ|Standard Z stage"
*HW_XG_CURRENT_MAX "50"
*HW_XG_CURRENT_MIN "2"
*HW_XG_CURRENT_RESOLUTION "2"
*HW_XG_CURRENT_UNIT "mA"
*HW_XG_FOCUS "1mm x 10mm"
*HW_XG_FOCUS_TYPE "Normal"
*HW_XG_ID ""
*HW_XG_NAME "3kW 封入管(ID:1200)|3kW Sealed tube(ID:1200)"
*HW_XG_TARGET_ATOMIC_NUMBER "29.0000000000"
*HW_XG_TARGET_NAME "Cu"
*HW_XG_TYPE "Hermetic"
*HW_XG_VOLTAGE_MAX "60"
*HW_XG_VOLTAGE_MIN "20"
*HW_XG_VOLTAGE_RESOLUTION "2"
*HW_XG_VOLTAGE_UNIT "kV"
*HW_XG_WATT_MAX "2"
*HW_XG_WATT_UNIT "kW"
*HW_XG_WAVE_LENGTH_ALPHA1 "1.540593"
*HW_XG_WAVE_LENGTH_ALPHA2 "1.544414"
*HW_XG_WAVE_LENGTH_BETA "1.392250"
*MEAS_COND_AXIS_NAME-0 "2θ/θ"
*MEAS_COND_AXIS_NAME-1 "2θ"
*MEAS_COND_AXIS_NAME-2 "ω"
*MEAS_COND_AXIS_NAME-3 "Z"
*MEAS_COND_AXIS_NAME-4 "2θ/ω"
*MEAS_COND_AXIS_NAME-5 "θs"
*MEAS_COND_AXIS_NAME-6 "θd"
*MEAS_COND_AXIS_NAME-7 "Ts"
*MEAS_COND_AXIS_NAME-8 "CBO選択スリット"
*MEAS_COND_AXIS_NAME-9 "M"
*MEAS_COND_AXIS_NAME-10 "入射平行スリット"
*MEAS_COND_AXIS_NAME-11 "入射スリット"
*MEAS_COND_AXIS_NAME-12 ""
*MEAS_COND_AXIS_NAME-13 "Zs"
*MEAS_COND_AXIS_NAME-14 "入射光学素子"
*MEAS_COND_AXIS_NAME-15 "長手制限スリット"
*MEAS_COND_AXIS_NAME-16 "センタースリット"
*MEAS_COND_AXIS_NAME-17 "フィルター"
*MEAS_COND_AXIS_NAME-18 "受光スリット1"
*MEAS_COND_AXIS_NAME-19 "受光スリット2"
*MEAS_COND_AXIS_NAME-20 "受光光学素子"
*MEAS_COND_AXIS_NAME-21 "受光平行スリット"
*MEAS_COND_AXIS_NAME-22 "調整用受光スリット"
*MEAS_COND_AXIS_NAME-23 ""
*MEAS_COND_AXIS_NAME-24 ""
*MEAS_COND_AXIS_NAME-25 "Zd"
*MEAS_COND_AXIS_NAME-26 "アッテネータ"
*MEAS_COND_AXIS_NAME-27 "検出器モノクロメータ"
*MEAS_COND_AXIS_NAME-28 "モノクロメータスリット"
*MEAS_COND_AXIS_NAME-29 "プライマリビーム"
*MEAS_COND_AXIS_NAME-30 "PHA"
*MEAS_COND_AXIS_NAME_INTERNAL-0 "TwoThetaTheta"
*MEAS_COND_AXIS_NAME_INTERNAL-1 "TwoTheta"
*MEAS_COND_AXIS_NAME_INTERNAL-2 "Omega"
*MEAS_COND_AXIS_NAME_INTERNAL-3 "Z"
*MEAS_COND_AXIS_NAME_INTERNAL-4 "TwoThetaOmega"
*MEAS_COND_AXIS_NAME_INTERNAL-5 "ThetaS"
*MEAS_COND_AXIS_NAME_INTERNAL-6 "ThetaD"
*MEAS_COND_AXIS_NAME_INTERNAL-7 "Ts"
*MEAS_COND_AXIS_NAME_INTERNAL-8 "CBO"
*MEAS_COND_AXIS_NAME_INTERNAL-9 "CBO-M"
*MEAS_COND_AXIS_NAME_INTERNAL-10 "IncidentSollerSlit"
*MEAS_COND_AXIS_NAME_INTERNAL-11 "IncidentSlitBox"
*MEAS_COND_AXIS_NAME_INTERNAL-12 "IncidentSlitBox-_Axis"
*MEAS_COND_AXIS_NAME_INTERNAL-13 "Zs"
*MEAS_COND_AXIS_NAME_INTERNAL-14 "IncidentMonochromator"
*MEAS_COND_AXIS_NAME_INTERNAL-15 "IncidentAxdSlit"
*MEAS_COND_AXIS_NAME_INTERNAL-16 "CenterSlit"
*MEAS_COND_AXIS_NAME_INTERNAL-17 "Filter"
*MEAS_COND_AXIS_NAME_INTERNAL-18 "ReceivingSlitBox1"
*MEAS_COND_AXIS_NAME_INTERNAL-19 "ReceivingSlitBox2"
*MEAS_COND_AXIS_NAME_INTERNAL-20 "ReceivingOptics"
*MEAS_COND_AXIS_NAME_INTERNAL-21 "ReceivingSollerSlit"
*MEAS_COND_AXIS_NAME_INTERNAL-22 "ReceivingAxdSlit"
*MEAS_COND_AXIS_NAME_INTERNAL-23 "ReceivingSlitBox1-_Axis"
*MEAS_COND_AXIS_NAME_INTERNAL-24 "ReceivingSlitBox2-_Axis"
*MEAS_COND_AXIS_NAME_INTERNAL-25 "ReceivingSlitBox2-Zd"
*MEAS_COND_AXIS_NAME_INTERNAL-26 "Attenuator"
*MEAS_COND_AXIS_NAME_INTERNAL-27 "CounterMonochromator"
*MEAS_COND_AXIS_NAME_INTERNAL-28 "CounterSlit"
*MEAS_COND_AXIS_NAME_INTERNAL-29 "IncidentPrimary"
*MEAS_COND_AXIS_NAME_INTERNAL-30 "PHA"
*MEAS_COND_AXIS_NAME_MAGICNO-0 "83951616.0000000000"
*MEAS_COND_AXIS_NAME_MAGICNO-1 "268632064.0000000000"
*MEAS_COND_AXIS_NAME_MAGICNO-2 "268500992.0000000000"
*MEAS_COND_AXIS_NAME_MAGICNO-3 "285278208.0000000000"
*MEAS_COND_AXIS_NAME_MAGICNO-4 "83951616.0000000000"
*MEAS_COND_AXIS_NAME_MAGICNO-5 "131072.0000000000"
*MEAS_COND_AXIS_NAME_MAGICNO-6 "131072.0000000000"
*MEAS_COND_AXIS_NAME_MAGICNO-7 "318898176.0000000000"
*MEAS_COND_AXIS_NAME_MAGICNO-8 "20971521.0000000000"
*MEAS_COND_AXIS_NAME_MAGICNO-9 "285343744.0000000000"
*MEAS_COND_AXIS_NAME_MAGICNO-10 "20971521.0000000000"
*MEAS_COND_AXIS_NAME_MAGICNO-11 "22020097.0000000000"
*MEAS_COND_AXIS_NAME_MAGICNO-12 "25165824.0000000000"
*MEAS_COND_AXIS_NAME_MAGICNO-13 "318898176.0000000000"
*MEAS_COND_AXIS_NAME_MAGICNO-14 "1.0000000000"
*MEAS_COND_AXIS_NAME_MAGICNO-15 "20971521.0000000000"
*MEAS_COND_AXIS_NAME_MAGICNO-16 "20971521.0000000000"
*MEAS_COND_AXIS_NAME_MAGICNO-17 "20971521.0000000000"
*MEAS_COND_AXIS_NAME_MAGICNO-18 "23068673.0000000000"
*MEAS_COND_AXIS_NAME_MAGICNO-19 "23068673.0000000000"
*MEAS_COND_AXIS_NAME_MAGICNO-20 "20971521.0000000000"
*MEAS_COND_AXIS_NAME_MAGICNO-21 "20971521.0000000000"
*MEAS_COND_AXIS_NAME_MAGICNO-22 "20971521.0000000000"
*MEAS_COND_AXIS_NAME_MAGICNO-23 "25165824.0000000000"
*MEAS_COND_AXIS_NAME_MAGICNO-24 "25165824.0000000000"
*MEAS_COND_AXIS_NAME_MAGICNO-25 "285343744.0000000000"
*MEAS_COND_AXIS_NAME_MAGICNO-26 "17301505.0000000000"
*MEAS_COND_AXIS_NAME_MAGICNO-27 "20971521.0000000000"
*MEAS_COND_AXIS_NAME_MAGICNO-28 "20971521.0000000000"
*MEAS_COND_AXIS_NAME_MAGICNO-29 "20971521.0000000000"
*MEAS_COND_AXIS_NAME_MAGICNO-30 "0.0000000000"
*MEAS_COND_AXIS_OFFSET-0 "-"
*MEAS_COND_AXIS_OFFSET-1 "-0.1081000000"
*MEAS_COND_AXIS_OFFSET-2 "0.3758000000"
*MEAS_COND_AXIS_OFFSET-3 "-"
*MEAS_COND_AXIS_OFFSET-4 "-"
*MEAS_COND_AXIS_OFFSET-5 "0.3758000000"
*MEAS_COND_AXIS_OFFSET-6 "-0.4839000000"
*MEAS_COND_AXIS_OFFSET-7 "-"
*MEAS_COND_AXIS_OFFSET-8 "-"
*MEAS_COND_AXIS_OFFSET-9 "-"
*MEAS_COND_AXIS_OFFSET-10 "-"
*MEAS_COND_AXIS_OFFSET-11 "-"
*MEAS_COND_AXIS_OFFSET-12 "-"
*MEAS_COND_AXIS_OFFSET-13 "-"
*MEAS_COND_AXIS_OFFSET-14 "-"
*MEAS_COND_AXIS_OFFSET-15 "-"
*MEAS_COND_AXIS_OFFSET-16 "-"
*MEAS_COND_AXIS_OFFSET-17 "-"
*MEAS_COND_AXIS_OFFSET-18 "-"
*MEAS_COND_AXIS_OFFSET-19 "-"
*MEAS_COND_AXIS_OFFSET-20 "-"
*MEAS_COND_AXIS_OFFSET-21 "-"
*MEAS_COND_AXIS_OFFSET-22 "-"
*MEAS_COND_AXIS_OFFSET-23 "-"
*MEAS_COND_AXIS_OFFSET-24 "-"
*MEAS_COND_AXIS_OFFSET-25 "-"
*MEAS_COND_AXIS_OFFSET-26 "-"
*MEAS_COND_AXIS_OFFSET-27 "-"
*MEAS_COND_AXIS_OFFSET-28 "-"
*MEAS_COND_AXIS_OFFSET-29 "-"
*MEAS_COND_AXIS_OFFSET-30 "-"
*MEAS_COND_AXIS_POSITION-0 "0.0000000000"
*MEAS_COND_AXIS_POSITION-1 "0.0000000000"
*MEAS_COND_AXIS_POSITION-2 "0.0000000000"
*MEAS_COND_AXIS_POSITION-3 "-0.5500000000"
*MEAS_COND_AXIS_POSITION-4 "0.0000000000"
*MEAS_COND_AXIS_POSITION-5 "0.0000000000"
*MEAS_COND_AXIS_POSITION-6 "0.0000000000"
*MEAS_COND_AXIS_POSITION-7 "-0.4278800000"
*MEAS_COND_AXIS_POSITION-8 "BB"
*MEAS_COND_AXIS_POSITION-9 "0.0000000000"
*MEAS_COND_AXIS_POSITION-10 "Soller_slit_5.0deg"
*MEAS_COND_AXIS_POSITION-11 "2/3deg"
*MEAS_COND_AXIS_POSITION-12 "2.2088000000"
*MEAS_COND_AXIS_POSITION-13 "-0.4140600000"
*MEAS_COND_AXIS_POSITION-14 "0.0000000000"
*MEAS_COND_AXIS_POSITION-15 "10.0mm"
*MEAS_COND_AXIS_POSITION-16 "None"
*MEAS_COND_AXIS_POSITION-17 "Cu_K-beta"
*MEAS_COND_AXIS_POSITION-18 "13.000mm"
*MEAS_COND_AXIS_POSITION-19 "13.000mm"
*MEAS_COND_AXIS_POSITION-20 "No_unit"
*MEAS_COND_AXIS_POSITION-21 "Soller_slit_5.0deg"
*MEAS_COND_AXIS_POSITION-22 "None"
*MEAS_COND_AXIS_POSITION-23 "13.0000000000"
*MEAS_COND_AXIS_POSITION-24 "13.0000000000"
*MEAS_COND_AXIS_POSITION-25 "0.0109400000"
*MEAS_COND_AXIS_POSITION-26 "Open"
*MEAS_COND_AXIS_POSITION-27 "None"
*MEAS_COND_AXIS_POSITION-28 "None"
*MEAS_COND_AXIS_POSITION-29 "None"
*MEAS_COND_AXIS_POSITION-30 "38.0000000000"
*MEAS_COND_AXIS_UNIT-0 "deg"
*MEAS_COND_AXIS_UNIT-1 "deg"
*MEAS_COND_AXIS_UNIT-2 "deg"
*MEAS_COND_AXIS_UNIT-3 "mm"
*MEAS_COND_AXIS_UNIT-4 "deg"
*MEAS_COND_AXIS_UNIT-5 "deg"
*MEAS_COND_AXIS_UNIT-6 "deg"
*MEAS_COND_AXIS_UNIT-7 "mm"
*MEAS_COND_AXIS_UNIT-8 ""
*MEAS_COND_AXIS_UNIT-9 "pulse"
*MEAS_COND_AXIS_UNIT-10 ""
*MEAS_COND_AXIS_UNIT-11 ""
*MEAS_COND_AXIS_UNIT-12 "mm"
*MEAS_COND_AXIS_UNIT-13 "mm"
*MEAS_COND_AXIS_UNIT-14 ""
*MEAS_COND_AXIS_UNIT-15 ""
*MEAS_COND_AXIS_UNIT-16 ""
*MEAS_COND_AXIS_UNIT-17 ""
*MEAS_COND_AXIS_UNIT-18 ""
*MEAS_COND_AXIS_UNIT-19 ""
*MEAS_COND_AXIS_UNIT-20 ""
*MEAS_COND_AXIS_UNIT-21 ""
*MEAS_COND_AXIS_UNIT-22 ""
*MEAS_COND_AXIS_UNIT-23 "mm"
*MEAS_COND_AXIS_UNIT-24 "mm"
*MEAS_COND_AXIS_UNIT-25 "mm"
*MEAS_COND_AXIS_UNIT-26 ""
*MEAS_COND_AXIS_UNIT-27 ""
*MEAS_COND_AXIS_UNIT-28 ""
*MEAS_COND_AXIS_UNIT-29 ""
*MEAS_COND_AXIS_UNIT-30 "div"
*MEAS_COND_COUNTER_CNTLOSS_CORR "0.0000000000"
*MEAS_COND_COUNTER_PHABASE "38.0000000000"
*MEAS_COND_COUNTER_PHAWINDOW "16.0000000000"
*MEAS_COND_COUNTER_PHA_UNIT "div"
*MEAS_COND_COUNTER_TAUDIFF "30.0000000000"
*MEAS_COND_COUNTER_TAUINT "0.0000000000"
*MEAS_COND_IRRADIATION_MODE "OFF"
*MEAS_COND_IRRADIATION_WIDTH ""
*MEAS_COND_OPT_ATTR "集中法"
*MEAS_COND_OPT_NAME "@集中法"
*MEAS_COND_UNSYMMETRIC_MODE "OFF"
*MEAS_COND_XG_CURRENT "30.0000000000"
*MEAS_COND_XG_VOLTAGE "40.0000000000"
*MEAS_COND_XG_WAVE_TYPE "Ka"
*MEAS_DATA_COUNT "3001.0000000000"
*MEAS_SCAN_AXIS_X "2θ/θ"
*MEAS_SCAN_AXIS_X_INTERNAL "TwoThetaTheta"
*MEAS_SCAN_END_TIME "09/02/20 13:58:29"
*MEAS_SCAN_MODE "CONTINUOUS"
*MEAS_SCAN_MONITOR "0"
*MEAS_SCAN_RESOLUTION_X "0.0002"
*MEAS_SCAN_SPEED "2.0"
*MEAS_SCAN_SPEED_UNIT "deg/min"
*MEAS_SCAN_START "20.0000000000"
*MEAS_SCAN_START_TIME "09/02/20 13:26:50"
*MEAS_SCAN_STEP "0.0200000000"
*MEAS_SCAN_STOP "80.0000000000"
*MEAS_SCAN_UNIT_X "deg"
*MEAS_SCAN_UNIT_Y "counts"
*RAS_HEADER_END
*RAS_INT_START
20.0000 1855.0000 1.0000
20.0600 1866.0000 1.0000
20.1200 1889.0000 1.0000
20.1800 1908.0000 1.0000
20.2400 1986.0000 1.0000
20.3000 1906.0000 1.0000
20.3600 1794.0000 1.0000
20.4200 1807.0000 1.0000
20.4800 1848.0000 1.0000
20.5400 1811.0000 1.0000
20.6000 1782.0000 1.0000
20.6600 1835.0000 1.0000
20.7200 1844.0000 1.0000
20.7800 1833.0000 1.0000
20.8400 1868.0000 1.0000
20.9000 1873.0000 1.0000
20.9600 1787.0000 1.0000
21.0200 1768.0000 1.0000
21.0800 1719.0000 1.0000
21.1400 1726.0000 1.0000
21.2000 1728.0000 1.0000
21.2600 1663.0000 1.0000
21.3200 1701.0000 1.0000
21.3800 1724.0000 1.0000
21.4400 1691.0000 1.0000
21.5000 1692.0000 1.0000
21.5600 1698.0000 1.0000
21.6200 1743.0000 1.0000
21.6800 1590.0000 1.0000
21.7400 1647.0000 1.0000
21.8000 1652.0000 1.0000
21.8600 1617.0000 1.0000
21.9200 1590.0000 1.0000
21.9800 1627.0000 1.0000
22.0400 1607.0000 1.0000
22.1000 1648.0000 1.0000
22.1600 1606.0000 1.0000
22.2200 1562.0000 1.0000
22.2800 1579.0000 1.0000
22.3400 1555.0000 1.0000
22.4000 1534.0000 1.0000
22.4600 1562.0000 1.0000
22.5200 1625.0000 1.0000
22.5800 1543.0000 1.0000
22.6400 1544.0000 1.0000
22.7000 1533.0000 1.0000
22.7600 1464.0000 1.0000
22.8200 1446.0000 1.0000
22.8800 1469.0000 1.0000
22.9400 1447.0000 1.0000
23.0000 1452.0000 1.0000
23.0600 1478.0000 1.0000
23.1200 1430.0000 1.0000
23.1800 1443.0000 1.0000
23.2400 1471.0000 1.0000
23.3000 1405.0000 1.0000
23.3600 1401.0000 1.0000
23.4200 1410.0000 1.0000
23.4800 1511.0000 1.0000
23.5400 1432.0000 1.0000
23.6000 1308.0000 1.0000
23.6600 1381.0000 1.0000
23.7200 1367.0000 1.0000
23.7800 1396.0000 1.0000
23.8400 1350.0000 1.0000
23.9000 1323.0000 1.0000
23.9600 1383.0000 1.0000
24.0200 1395.0000 1.0000
24.0800 1347.0000 1.0000
24.1400 1368.0000 1.0000
24.2000 1284.0000 1.0000
24.2600 1299.0000 1.0000
24.3200 1283.0000 1.0000
24.3800 1276.0000 1.0000
24.4400 1350.0000 1.0000
24.5000 1287.0000 1.0000
24.5600 1259.0000 1.0000
24.6200 1322.0000 1.0000
24.6800 1267.0000 1.0000
24.7400 1284.0000 1.0000
24.8000 1243.0000 1.0000
24.8600 1219.0000 1.0000
24.9200 1289.0000 1.0000
24.9800 1212.0000 1.0000
25.0400 1228.0000 1.0000
25.1000 1236.0000 1.0000
25.1600 1255.0000 1.0000
25.2200 1243.0000 1.0000
25.2800 1205.0000 1.0000
25.3400 1263.0000 1.0000
25.4000 1204.0000 1.0000
25.4600 1148.0000 1.0000
25.5200 1188.0000 1.0000
25.5800 1210.0000 1.0000
25.6400 1200.0000 1.0000
25.7000 1172.0000 1.0000
25.7600 1192.0000 1.0000
25.8200 1163.0000 1.0000
25.8800 1192.0000 1.0000
25.9400 1169.0000 1.0000
26.0000 1165.0000 1.0000
26.0600 1145.0000 1.0000
26.1200 1146.0000 1.0000
26.1800 1108.0000 1.0000
26.2400 1132.0000 1.0000
26.3000 1167.0000 1.0000
26.3600 1092.0000 1.0000
26.4200 1123.0000 1.0000
26.4800 1091.0000 1.0000
26.5400 1068.0000 1.0000
26.6000 1019.0000 1.0000
26.6600 1101.0000 1.0000
26.7200 1066.0000 1.0000
26.7800 1064.0000 1.0000
26.8400 1031.0000 1.0000
26.9000 1096.0000 1.0000
26.9600 1039.0000 1.0000
27.0200 1102.0000 1.0000
27.0800 1043.0000 1.0000
27.1400 1040.0000 1.0000
27.2000 1067.0000 1.0000
27.2600 1051.0000 1.0000
27.3200 1036.0000 1.0000
27.3800 1173.0000 1.0000
27.4400 1071.0000 1.0000
27.5000 1079.0000 1.0000
27.5600 995.0000 1.0000
27.6200 1080.0000 1.0000
27.6800 1040.0000 1.0000
27.7400 1011.0000 1.0000
27.8000 1108.0000 1.0000
27.8600 950.0000 1.0000
27.9200 994.0000 1.0000
27.9800 955.0000 1.0000
28.0400 920.0000 1.0000
28.1000 934.0000 1.0000
28.1600 941.0000 1.0000
28.2200 940.0000 1.0000
28.2800 967.0000 1.0000
28.3400 936.0000 1.0000
28.4000 947.0000 1.0000
28.4600 950.0000 1.0000
28.5200 931.0000 1.0000
28.5800 897.0000 1.0000
28.6400 959.0000 1.0000
28.7000 929.0000 1.0000
28.7600 908.0000 1.0000
28.8200 915.0000 1.0000
28.8800 909.0000 1.0000
28.9400 918.0000 1.0000
29.0000 876.0000 1.0000
29.0600 905.0000 1.0000
29.1200 855.0000 1.0000
29.1800 874.0000 1.0000
29.2400 894.0000 1.0000
29.3000 854.0000 1.0000
29.3600 865.0000 1.0000
29.4200 875.0000 1.0000
29.4800 872.0000 1.0000
29.5400 890.0000 1.0000
29.6000 867.0000 1.0000
29.6600 890.0000 1.0000
29.7200 860.0000 1.0000
29.7800 868.0000 1.0000
29.8400 807.0000 1.0000
29.9000 816.0000 1.0000
29.9600 844.0000 1.0000
30.0200 795.0000 1.0000
30.0800 845.0000 1.0000
30.1400 811.0000 1.0000
30.2000 810.0000 1.0000
30.2600 777.0000 1.0000
30.3200 816.0000 1.0000
30.3800 751.0000 1.0000
30.4400 781.0000 1.0000
30.5000 808.0000 1.0000
30.5600 782.0000 1.0000
30.6200 752.0000 1.0000
30.6800 744.0000 1.0000
30.7400 760.0000 1.0000
30.8000 749.0000 1.0000
30.8600 796.0000 1.0000
30.9200 745.0000 1.0000
30.9800 756.0000 1.0000
31.0400 733.0000 1.0000
31.1000 752.0000 1.0000
31.1600 714.0000 1.0000
31.2200 727.0000 1.0000
31.2800 751.0000 1.0000
31.3400 732.0000 1.0000
31.4000 685.0000 1.0000
31.4600 715.0000 1.0000
31.5200 736.0000 1.0000
31.5800 785.0000 1.0000
31.6400 688.0000 1.0000
31.7000 730.0000 1.0000
31.7600 712.0000 1.0000
31.8200 724.0000 1.0000
31.8800 688.0000 1.0000
31.9400 731.0000 1.0000
32.0000 665.0000 1.0000
32.0600 658.0000 1.0000
32.1200 689.0000 1.0000
32.1800 696.0000 1.0000
32.2400 657.0000 1.0000
32.3000 721.0000 1.0000
32.3600 747.0000 1.0000
32.4200 715.0000 1.0000
32.4800 676.0000 1.0000
32.5400 676.0000 1.0000
32.6000 667.0000 1.0000
32.6600 688.0000 1.0000
32.7200 649.0000 1.0000
32.7800 693.0000 1.0000
32.8400 627.0000 1.0000
32.9000 675.0000 1.0000
32.9600 669.0000 1.0000
33.0200 676.0000 1.0000
33.0800 630.0000 1.0000
33.1400 630.0000 1.0000
33.2000 648.0000 1.0000
33.2600 611.0000 1.0000
33.3200 592.0000 1.0000
33.3800 673.0000 1.0000
33.4400 647.0000 1.0000
33.5000 655.0000 1.0000
33.5600 613.0000 1.0000
33.6200 644.0000 1.0000
33.6800 630.0000 1.0000
33.7400 601.0000 1.0000
33.8000 641.0000 1.0000
33.8600 680.0000 1.0000
33.9200 599.0000 1.0000
33.9800 669.0000 1.0000
34.0400 599.0000 1.0000
34.1000 627.0000 1.0000
34.1600 610.0000 1.0000
34.2200 595.0000 1.0000
34.2800 613.0000 1.0000
34.3400 659.0000 1.0000
34.4000 625.0000 1.0000
34.4600 611.0000 1.0000
34.5200 714.0000 1.0000
34.5800 677.0000 1.0000
34.6400 636.0000 1.0000
34.7000 633.0000 1.0000
34.7600 614.0000 1.0000
34.8200 592.0000 1.0000
34.8800 606.0000 1.0000
34.9400 598.0000 1.0000
35.0000 590.0000 1.0000
35.0600 538.0000 1.0000
35.1200 575.0000 1.0000
35.1800 550.0000 1.0000
35.2400 583.0000 1.0000
35.3000 569.0000 1.0000
35.3600 499.0000 1.0000
35.4200 568.0000 1.0000
35.4800 554.0000 1.0000
35.5400 532.0000 1.0000
35.6000 517.0000 1.0000
35.6600 538.0000 1.0000
35.7200 534.0000 1.0000
35.7800 522.0000 1.0000
35.8400 534.0000 1.0000
35.9000 533.0000 1.0000
35.9600 575.0000 1.0000
36.0200 539.0000 1.0000
36.0800 510.0000 1.0000
36.1400 549.0000 1.0000
36.2000 539.0000 1.0000
36.2600 519.0000 1.0000
36.3200 516.0000 1.0000
36.3800 577.0000 1.0000
36.4400 520.0000 1.0000
36.5000 537.0000 1.0000
36.5600 550.0000 1.0000
36.6200 519.0000 1.0000
36.6800 524.0000 1.0000
36.7400 525.0000 1.0000
36.8000 490.0000 1.0000
36.8600 469.0000 1.0000
36.9200 501.0000 1.0000
36.9800 448.0000 1.0000
37.0400 441.0000 1.0000
37.1000 489.0000 1.0000
37.1600 460.0000 1.0000
37.2200 472.0000 1.0000
37.2800 448.0000 1.0000
37.3400 487.0000 1.0000
37.4000 460.0000 1.0000
37.4600 462.0000 1.0000
37.5200 420.0000 1.0000
37.5800 479.0000 1.0000
37.6400 426.0000 1.0000
37.7000 418.0000 1.0000
37.7600 439.0000 1.0000
37.8200 427.0000 1.0000
37.8800 492.0000 1.0000
37.9400 467.0000 1.0000
38.0000 512.0000 1.0000
38.0600 445.0000 1.0000
38.1200 454.0000 1.0000
38.1800 453.0000 1.0000
38.2400 471.0000 1.0000
38.3000 484.0000 1.0000
38.3600 495.0000 1.0000
38.4200 531.0000 1.0000
38.4800 573.0000 1.0000
38.5400 656.0000 1.0000
38.6000 657.0000 1.0000
38.6600 622.0000 1.0000
38.7200 569.0000 1.0000
38.7800 504.0000 1.0000
38.8400 465.0000 1.0000
38.9000 471.0000 1.0000
38.9600 459.0000 1.0000
39.0200 421.0000 1.0000
39.0800 403.0000 1.0000
39.1400 459.0000 1.0000
39.2000 377.0000 1.0000
39.2600 424.0000 1.0000
39.3200 407.0000 1.0000
39.3800 416.0000 1.0000
39.4400 433.0000 1.0000
39.5000 412.0000 1.0000
39.5600 431.0000 1.0000
39.6200 412.0000 1.0000
39.6800 404.0000 1.0000
39.7400 396.0000 1.0000
39.8000 399.0000 1.0000
39.8600 393.0000 1.0000
39.9200 393.0000 1.0000
39.9800 421.0000 1.0000
40.0400 377.0000 1.0000
40.1000 419.0000 1.0000
40.1600 411.0000 1.0000
40.2200 401.0000 1.0000
40.2800 386.0000 1.0000
40.3400 361.0000 1.0000
40.4000 360.0000 1.0000
40.4600 362.0000 1.0000
40.5200 356.0000 1.0000
40.5800 386.0000 1.0000
40.6400 388.0000 1.0000
40.7000 353.0000 1.0000
40.7600 349.0000 1.0000
40.8200 389.0000 1.0000
40.8800 373.0000 1.0000
40.9400 379.0000 1.0000
41.0000 326.0000 1.0000
41.0600 345.0000 1.0000
41.1200 385.0000 1.0000
41.1800 348.0000 1.0000
41.2400 378.0000 1.0000
41.3000 374.0000 1.0000
41.3600 363.0000 1.0000
41.4200 367.0000 1.0000
41.4800 355.0000 1.0000
41.5400 358.0000 1.0000
41.6000 378.0000 1.0000
41.6600 367.0000 1.0000
41.7200 348.0000 1.0000
41.7800 350.0000 1.0000
41.8400 332.0000 1.0000
41.9000 347.0000 1.0000
41.9600 357.0000 1.0000
42.0200 341.0000 1.0000
42.0800 376.0000 1.0000
42.1400 364.0000 1.0000
42.2000 353.0000 1.0000
42.2600 343.0000 1.0000
42.3200 343.0000 1.0000
42.3800 354.0000 1.0000
42.4400 347.0000 1.0000
42.5000 356.0000 1.0000
42.5600 337.0000 1.0000
42.6200 336.0000 1.0000
42.6800 345.0000 1.0000
42.7400 344.0000 1.0000
42.8000 352.0000 1.0000
42.8600 344.0000 1.0000
42.9200 325.0000 1.0000
42.9800 357.0000 1.0000
43.0400 345.0000 1.0000
43.1000 354.0000 1.0000
43.1600 362.0000 1.0000
43.2200 350.0000 1.0000
43.2800 310.0000 1.0000
43.3400 316.0000 1.0000
43.4000 314.0000 1.0000
43.4600 311.0000 1.0000
43.5200 300.0000 1.0000
43.5800 317.0000 1.0000
43.6400 316.0000 1.0000
43.7000 322.0000 1.0000
43.7600 345.0000 1.0000
43.8200 328.0000 1.0000
43.8800 331.0000 1.0000
43.9400 304.0000 1.0000
44.0000 277.0000 1.0000
44.0600 343.0000 1.0000
44.1200 314.0000 1.0000
44.1800 309.0000 1.0000
44.2400 322.0000 1.0000
44.3000 298.0000 1.0000
44.3600 299.0000 1.0000
44.4200 362.0000 1.0000
44.4800 337.0000 1.0000
44.5400 307.0000 1.0000
44.6000 287.0000 1.0000
44.6600 310.0000 1.0000
44.7200 317.0000 1.0000
44.7800 322.0000 1.0000
44.8400 292.0000 1.0000
44.9000 308.0000 1.0000
44.9600 294.0000 1.0000
45.0200 300.0000 1.0000
45.0800 281.0000 1.0000
45.1400 272.0000 1.0000
45.2000 288.0000 1.0000
45.2600 295.0000 1.0000
45.3200 275.0000 1.0000
45.3800 283.0000 1.0000
45.4400 258.0000 1.0000
45.5000 314.0000 1.0000
45.5600 291.0000 1.0000
45.6200 281.0000 1.0000
45.6800 285.0000 1.0000
45.7400 286.0000 1.0000
45.8000 302.0000 1.0000
45.8600 286.0000 1.0000
45.9200 280.0000 1.0000
45.9800 290.0000 1.0000
46.0400 286.0000 1.0000
46.1000 290.0000 1.0000
46.1600 295.0000 1.0000
46.2200 281.0000 1.0000
46.2800 280.0000 1.0000
46.3400 263.0000 1.0000
46.4000 294.0000 1.0000
46.4600 280.0000 1.0000
46.5200 260.0000 1.0000
46.5800 259.0000 1.0000
46.6400 249.0000 1.0000
46.7000 269.0000 1.0000
46.7600 260.0000 1.0000
46.8200 279.0000 1.0000
46.8800 286.0000 1.0000
46.9400 272.0000 1.0000
47.0000 277.0000 1.0000
47.0600 261.0000 1.0000
47.1200 286.0000 1.0000
47.1800 254.0000 1.0000
47.2400 266.0000 1.0000
47.3000 286.0000 1.0000
47.3600 280.0000 1.0000
47.4200 265.0000 1.0000
47.4800 232.0000 1.0000
47.5400 254.0000 1.0000
47.6000 245.0000 1.0000
47.6600 245.0000 1.0000
47.7200 239.0000 1.0000
47.7800 251.0000 1.0000
47.8400 253.0000 1.0000
47.9000 262.0000 1.0000
47.9600 265.0000 1.0000
48.0200 239.0000 1.0000
48.0800 263.0000 1.0000
48.1400 255.0000 1.0000
48.2000 279.0000 1.0000
48.2600 245.0000 1.0000
48.3200 233.0000 1.0000
48.3800 237.0000 1.0000
48.4400 271.0000 1.0000
48.5000 259.0000 1.0000
48.5600 284.0000 1.0000
48.6200 266.0000 1.0000
48.6800 262.0000 1.0000
48.7400 273.0000 1.0000
48.8000 240.0000 1.0000
48.8600 248.0000 1.0000
48.9200 273.0000 1.0000
48.9800 249.0000 1.0000
49.0400 252.0000 1.0000
49.1000 237.0000 1.0000
49.1600 242.0000 1.0000
49.2200 262.0000 1.0000
49.2800 235.0000 1.0000
49.3400 241.0000 1.0000
49.4000 257.0000 1.0000
49.4600 233.0000 1.0000
49.5200 237.0000 1.0000
49.5800 212.0000 1.0000
49.6400 268.0000 1.0000
49.7000 240.0000 1.0000
49.7600 234.0000 1.0000
49.8200 234.0000 1.0000
49.8800 224.0000 1.0000
49.9400 234.0000 1.0000
50.0000 229.0000 1.0000
50.0600 232.0000 1.0000
50.1200 221.0000 1.0000
50.1800 229.0000 1.0000
50.2400 239.0000 1.0000
50.3000 230.0000 1.0000
50.3600 252.0000 1.0000
50.4200 236.0000 1.0000
50.4800 224.0000 1.0000
50.5400 241.0000 1.0000
50.6000 224.0000 1.0000
50.6600 264.0000 1.0000
50.7200 239.0000 1.0000
50.7800 241.0000 1.0000
50.8400 236.0000 1.0000
50.9000 204.0000 1.0000
50.9600 246.0000 1.0000
51.0200 210.0000 1.0000
51.0800 223.0000 1.0000
51.1400 228.0000 1.0000
51.2000 235.0000 1.0000
51.2600 240.0000 1.0000
51.3200 235.0000 1.0000
51.3800 233.0000 1.0000
51.4400 242.0000 1.0000
51.5000 231.0000 1.0000
51.5600 219.0000 1.0000
51.6200 231.0000 1.0000
51.6800 238.0000 1.0000
51.7400 229.0000 1.0000
51.8000 231.0000 1.0000
51.8600 232.0000 1.0000
51.9200 220.0000 1.0000
51.9800 260.0000 1.0000
52.0400 283.0000 1.0000
52.1000 288.0000 1.0000
52.1600 348.0000 1.0000
52.2200 506.0000 1.0000
52.2800 685.0000 1.0000
52.3400 657.0000 1.0000
52.4000 583.0000 1.0000
52.4600 522.0000 1.0000
52.5200 376.0000 1.0000
52.5800 333.0000 1.0000
52.6400 257.0000 1.0000
52.7000 260.0000 1.0000
52.7600 226.0000 1.0000
52.8200 231.0000 1.0000
52.8800 237.0000 1.0000
52.9400 202.0000 1.0000
53.0000 246.0000 1.0000
53.0600 240.0000 1.0000
53.1200 239.0000 1.0000
53.1800 225.0000 1.0000
53.2400 230.0000 1.0000
53.3000 232.0000 1.0000
53.3600 233.0000 1.0000
53.4200 209.0000 1.0000
53.4800 248.0000 1.0000
53.5400 223.0000 1.0000
53.6000 225.0000 1.0000
53.6600 230.0000 1.0000
53.7200 232.0000 1.0000
53.7800 215.0000 1.0000
53.8400 206.0000 1.0000
53.9000 197.0000 1.0000
53.9600 219.0000 1.0000
54.0200 220.0000 1.0000
54.0800 208.0000 1.0000
54.1400 207.0000 1.0000
54.2000 245.0000 1.0000
54.2600 235.0000 1.0000
54.3200 208.0000 1.0000
54.3800 216.0000 1.0000
54.4400 215.0000 1.0000
54.5000 216.0000 1.0000
54.5600 203.0000 1.0000
54.6200 205.0000 1.0000
54.6800 210.0000 1.0000
54.7400 241.0000 1.0000
54.8000 221.0000 1.0000
54.8600 235.0000 1.0000
54.9200 231.0000 1.0000
54.9800 222.0000 1.0000
55.0400 214.0000 1.0000
55.1000 219.0000 1.0000
55.1600 224.0000 1.0000
55.2200 247.0000 1.0000
55.2800 259.0000 1.0000
55.3400 262.0000 1.0000
55.4000 236.0000 1.0000
55.4600 237.0000 1.0000
55.5200 244.0000 1.0000
55.5800 242.0000 1.0000
55.6400 239.0000 1.0000
55.7000 213.0000 1.0000
55.7600 204.0000 1.0000
55.8200 210.0000 1.0000
55.8800 204.0000 1.0000
55.9400 210.0000 1.0000
56.0000 193.0000 1.0000
56.0600 215.0000 1.0000
56.1200 195.0000 1.0000
56.1800 204.0000 1.0000
56.2400 211.0000 1.0000
56.3000 210.0000 1.0000
56.3600 208.0000 1.0000
56.4200 194.0000 1.0000
56.4800 190.0000 1.0000
56.5400 215.0000 1.0000
56.6000 191.0000 1.0000
56.6600 199.0000 1.0000
56.7200 205.0000 1.0000
56.7800 205.0000 1.0000
56.8400 210.0000 1.0000
56.9000 201.0000 1.0000
56.9600 222.0000 1.0000
57.0200 199.0000 1.0000
57.0800 203.0000 1.0000
57.1400 207.0000 1.0000
57.2000 189.0000 1.0000
57.2600 212.0000 1.0000
57.3200 197.0000 1.0000
57.3800 201.0000 1.0000
57.4400 198.0000 1.0000
57.5000 221.0000 1.0000
57.5600 216.0000 1.0000
57.6200 198.0000 1.0000
57.6800 199.0000 1.0000
57.7400 218.0000 1.0000
57.8000 191.0000 1.0000
57.8600 176.0000 1.0000
57.9200 212.0000 1.0000
57.9800 213.0000 1.0000
58.0400 188.0000 1.0000
58.1000 220.0000 1.0000
58.1600 203.0000 1.0000
58.2200 210.0000 1.0000
58.2800 230.0000 1.0000
58.3400 197.0000 1.0000
58.4000 178.0000 1.0000
58.4600 203.0000 1.0000
58.5200 197.0000 1.0000
58.5800 217.0000 1.0000
58.6400 198.0000 1.0000
58.7000 193.0000 1.0000
58.7600 199.0000 1.0000
58.8200 182.0000 1.0000
58.8800 209.0000 1.0000
58.9400 208.0000 1.0000
59.0000 199.0000 1.0000
59.0600 207.0000 1.0000
59.1200 193.0000 1.0000
59.1800 229.0000 1.0000
59.2400 199.0000 1.0000
59.3000 172.0000 1.0000
59.3600 191.0000 1.0000
59.4200 180.0000 1.0000
59.4800 196.0000 1.0000
59.5400 205.0000 1.0000
59.6000 197.0000 1.0000
59.6600 185.0000 1.0000
59.7200 189.0000 1.0000
59.7800 175.0000 1.0000
59.8400 188.0000 1.0000
59.9000 201.0000 1.0000
59.9600 179.0000 1.0000
60.0200 188.0000 1.0000
60.0800 192.0000 1.0000
60.1400 191.0000 1.0000
60.2000 203.0000 1.0000
60.2600 185.0000 1.0000
60.3200 195.0000 1.0000
60.3800 199.0000 1.0000
60.4400 192.0000 1.0000
60.5000 201.0000 1.0000
60.5600 178.0000 1.0000
60.6200 184.0000 1.0000
60.6800 205.0000 1.0000
60.7400 193.0000 1.0000
60.8000 188.0000 1.0000
60.8600 212.0000 1.0000
60.9200 169.0000 1.0000
60.9800 205.0000 1.0000
61.0400 211.0000 1.0000
61.1000 202.0000 1.0000
61.1600 215.0000 1.0000
61.2200 197.0000 1.0000
61.2800 194.0000 1.0000
61.3400 189.0000 1.0000
61.4000 192.0000 1.0000
61.4600 213.0000 1.0000
61.5200 200.0000 1.0000
61.5800 196.0000 1.0000
61.6400 188.0000 1.0000
61.7000 224.0000 1.0000
61.7600 198.0000 1.0000
61.8200 184.0000 1.0000
61.8800 197.0000 1.0000
61.9400 221.0000 1.0000
62.0000 231.0000 1.0000
62.0600 224.0000 1.0000
62.1200 236.0000 1.0000
62.1800 238.0000 1.0000
62.2400 271.0000 1.0000
62.3000 318.0000 1.0000
62.3600 347.0000 1.0000
62.4200 302.0000 1.0000
62.4800 286.0000 1.0000
62.5400 251.0000 1.0000
62.6000 214.0000 1.0000
62.6600 203.0000 1.0000
62.7200 227.0000 1.0000
62.7800 213.0000 1.0000
62.8400 223.0000 1.0000
62.9000 193.0000 1.0000
62.9600 223.0000 1.0000
63.0200 199.0000 1.0000
63.0800 210.0000 1.0000
63.1400 224.0000 1.0000
63.2000 204.0000 1.0000
63.2600 185.0000 1.0000
63.3200 190.0000 1.0000
63.3800 211.0000 1.0000
63.4400 198.0000 1.0000
63.5000 180.0000 1.0000
63.5600 181.0000 1.0000
63.6200 209.0000 1.0000
63.6800 196.0000 1.0000
63.7400 218.0000 1.0000
63.8000 202.0000 1.0000
63.8600 182.0000 1.0000
63.9200 206.0000 1.0000
63.9800 204.0000 1.0000
64.0400 207.0000 1.0000
64.1000 196.0000 1.0000
64.1600 205.0000 1.0000
64.2200 206.0000 1.0000
64.2800 188.0000 1.0000
64.3400 202.0000 1.0000
64.4000 195.0000 1.0000
64.4600 195.0000 1.0000
64.5200 205.0000 1.0000
64.5800 206.0000 1.0000
64.6400 222.0000 1.0000
64.7000 216.0000 1.0000
64.7600 265.0000 1.0000
64.8200 231.0000 1.0000
64.8800 245.0000 1.0000
64.9400 230.0000 1.0000
65.0000 230.0000 1.0000
65.0600 214.0000 1.0000
65.1200 219.0000 1.0000
65.1800 202.0000 1.0000
65.2400 224.0000 1.0000
65.3000 208.0000 1.0000
65.3600 224.0000 1.0000
65.4200 215.0000 1.0000
65.4800 217.0000 1.0000
65.5400 234.0000 1.0000
65.6000 185.0000 1.0000
65.6600 196.0000 1.0000
65.7200 204.0000 1.0000
65.7800 196.0000 1.0000
65.8400 209.0000 1.0000
65.9000 191.0000 1.0000
65.9600 211.0000 1.0000
66.0200 230.0000 1.0000
66.0800 262.0000 1.0000
66.1400 300.0000 1.0000
66.2000 402.0000 1.0000
66.2600 469.0000 1.0000
66.3200 485.0000 1.0000
66.3800 432.0000 1.0000
66.4400 443.0000 1.0000
66.5000 354.0000 1.0000
66.5600 335.0000 1.0000
66.6200 257.0000 1.0000
66.6800 265.0000 1.0000
66.7400 212.0000 1.0000
66.8000 204.0000 1.0000
66.8600 195.0000 1.0000
66.9200 203.0000 1.0000
66.9800 187.0000 1.0000
67.0400 206.0000 1.0000
67.1000 197.0000 1.0000
67.1600 197.0000 1.0000
67.2200 215.0000 1.0000
67.2800 198.0000 1.0000
67.3400 204.0000 1.0000
67.4000 175.0000 1.0000
67.4600 166.0000 1.0000
67.5200 205.0000 1.0000
67.5800 185.0000 1.0000
67.6400 171.0000 1.0000
67.7000 179.0000 1.0000
67.7600 204.0000 1.0000
67.8200 188.0000 1.0000
67.8800 195.0000 1.0000
67.9400 201.0000 1.0000
68.0000 183.0000 1.0000
68.0600 171.0000 1.0000
68.1200 179.0000 1.0000
68.1800 191.0000 1.0000
68.2400 169.0000 1.0000
68.3000 183.0000 1.0000
68.3600 194.0000 1.0000
68.4200 164.0000 1.0000
68.4800 182.0000 1.0000
68.5400 177.0000 1.0000
68.6000 178.0000 1.0000
68.6600 180.0000 1.0000
68.7200 164.0000 1.0000
68.7800 173.0000 1.0000
68.8400 169.0000 1.0000
68.9000 189.0000 1.0000
68.9600 206.0000 1.0000
69.0200 173.0000 1.0000
69.0800 190.0000 1.0000
69.1400 182.0000 1.0000
69.2000 215.0000 1.0000
69.2600 206.0000 1.0000
69.3200 185.0000 1.0000
69.3800 196.0000 1.0000
69.4400 170.0000 1.0000
69.5000 178.0000 1.0000
69.5600 180.0000 1.0000
69.6200 166.0000 1.0000
69.6800 198.0000 1.0000
69.7400 207.0000 1.0000
69.8000 168.0000 1.0000
69.8600 175.0000 1.0000
69.9200 175.0000 1.0000
69.9800 193.0000 1.0000
70.0400 190.0000 1.0000
70.1000 182.0000 1.0000
70.1600 197.0000 1.0000
70.2200 209.0000 1.0000
70.2800 150.0000 1.0000
70.3400 170.0000 1.0000
70.4000 171.0000 1.0000
70.4600 171.0000 1.0000
70.5200 179.0000 1.0000
70.5800 167.0000 1.0000
70.6400 205.0000 1.0000
70.7000 183.0000 1.0000
70.7600 179.0000 1.0000
70.8200 195.0000 1.0000
70.8800 186.0000 1.0000
70.9400 167.0000 1.0000
71.0000 175.0000 1.0000
71.0600 177.0000 1.0000
71.1200 161.0000 1.0000
71.1800 187.0000 1.0000
71.2400 168.0000 1.0000
71.3000 201.0000 1.0000
71.3600 173.0000 1.0000
71.4200 189.0000 1.0000
71.4800 194.0000 1.0000
71.5400 210.0000 1.0000
71.6000 169.0000 1.0000
71.6600 208.0000 1.0000
71.7200 197.0000 1.0000
71.7800 193.0000 1.0000
71.8400 172.0000 1.0000
71.9000 173.0000 1.0000
71.9600 169.0000 1.0000
72.0200 169.0000 1.0000
72.0800 156.0000 1.0000
72.1400 165.0000 1.0000
72.2000 181.0000 1.0000
72.2600 169.0000 1.0000
72.3200 200.0000 1.0000
72.3800 187.0000 1.0000
72.4400 195.0000 1.0000
72.5000 189.0000 1.0000
72.5600 176.0000 1.0000
72.6200 180.0000 1.0000
72.6800 193.0000 1.0000
72.7400 171.0000 1.0000
72.8000 177.0000 1.0000
72.8600 160.0000 1.0000
72.9200 158.0000 1.0000
72.9800 175.0000 1.0000
73.0400 164.0000 1.0000
73.1000 187.0000 1.0000
73.1600 163.0000 1.0000
73.2200 204.0000 1.0000
73.2800 188.0000 1.0000
73.3400 173.0000 1.0000
73.4000 187.0000 1.0000
73.4600 154.0000 1.0000
73.5200 166.0000 1.0000
73.5800 174.0000 1.0000
73.6400 179.0000 1.0000
73.7000 196.0000 1.0000
73.7600 159.0000 1.0000
73.8200 169.0000 1.0000
73.8800 157.0000 1.0000
73.9400 168.0000 1.0000
74.0000 172.0000 1.0000
74.0600 176.0000 1.0000
74.1200 169.0000 1.0000
74.1800 154.0000 1.0000
74.2400 190.0000 1.0000
74.3000 166.0000 1.0000
74.3600 178.0000 1.0000
74.4200 175.0000 1.0000
74.4800 180.0000 1.0000
74.5400 154.0000 1.0000
74.6000 166.0000 1.0000
74.6600 199.0000 1.0000
74.7200 173.0000 1.0000
74.7800 157.0000 1.0000
74.8400 168.0000 1.0000
74.9000 177.0000 1.0000
74.9600 179.0000 1.0000
75.0200 171.0000 1.0000
75.0800 161.0000 1.0000
75.1400 174.0000 1.0000
75.2000 172.0000 1.0000
75.2600 175.0000 1.0000
75.3200 161.0000 1.0000
75.3800 155.0000 1.0000
75.4400 172.0000 1.0000
75.5000 198.0000 1.0000
75.5600 152.0000 1.0000
75.6200 179.0000 1.0000
75.6800 154.0000 1.0000
75.7400 164.0000 1.0000
75.8000 172.0000 1.0000
75.8600 159.0000 1.0000
75.9200 160.0000 1.0000
75.9800 189.0000 1.0000
76.0400 171.0000 1.0000
76.1000 166.0000 1.0000
76.1600 173.0000 1.0000
76.2200 162.0000 1.0000
76.2800 193.0000 1.0000
76.3400 181.0000 1.0000
76.4000 167.0000 1.0000
76.4600 177.0000 1.0000
76.5200 167.0000 1.0000
76.5800 192.0000 1.0000
76.6400 164.0000 1.0000
76.7000 174.0000 1.0000
76.7600 154.0000 1.0000
76.8200 159.0000 1.0000
76.8800 170.0000 1.0000
76.9400 177.0000 1.0000
77.0000 162.0000 1.0000
77.0600 171.0000 1.0000
77.1200 170.0000 1.0000
77.1800 185.0000 1.0000
77.2400 158.0000 1.0000
77.3000 174.0000 1.0000
77.3600 158.0000 1.0000
77.4200 142.0000 1.0000
77.4800 173.0000 1.0000
77.5400 161.0000 1.0000
77.6000 153.0000 1.0000
77.6600 167.0000 1.0000
77.7200 167.0000 1.0000
77.7800 171.0000 1.0000
77.8400 186.0000 1.0000
77.9000 208.0000 1.0000
77.9600 165.0000 1.0000
78.0200 176.0000 1.0000
78.0800 140.0000 1.0000
78.1400 168.0000 1.0000
78.2000 177.0000 1.0000
78.2600 179.0000 1.0000
78.3200 179.0000 1.0000
78.3800 184.0000 1.0000
78.4400 203.0000 1.0000
78.5000 178.0000 1.0000
78.5600 154.0000 1.0000
78.6200 174.0000 1.0000
78.6800 203.0000 1.0000
78.7400 175.0000 1.0000
78.8000 197.0000 1.0000
78.8600 201.0000 1.0000
78.9200 217.0000 1.0000
78.9800 222.0000 1.0000
79.0400 246.0000 1.0000
79.1000 238.0000 1.0000
79.1600 234.0000 1.0000
79.2200 225.0000 1.0000
79.2800 211.0000 1.0000
79.3400 198.0000 1.0000
79.4000 203.0000 1.0000
79.4600 171.0000 1.0000
79.5200 186.0000 1.0000
79.5800 175.0000 1.0000
79.6400 185.0000 1.0000
79.7000 177.0000 1.0000
79.7600 155.0000 1.0000
79.8200 148.0000 1.0000
79.8800 156.0000 1.0000
79.9400 154.0000 1.0000
80.0000 196.0000 1.0000
*RAS_INT_END
*RAS_TEMPERATURE_START
*RAS_TEMPERATURE_END
*RAS_DATA_END