File: Sectio1_28_samples/XRD/No_019_700_16.ras
*RAS_DATA_START
*RAS_HEADER_START
*DISP_FMT_X "%.2f"
*DISP_FMT_Y "%.0f"
*DISP_FULLSCALE "3750.0000000000"
*DISP_LINE_COLOR "255.0000000000"
*DISP_LINE_STYLE "0.0000000000"
*DISP_LINE_WIDTH "0.2500000000"
*DISP_NOTE "測定データ-3"
*DISP_OFFSET_Y "0.0000000000"
*DISP_PEAKSEARCH_UNIT_Y "cps"
*DISP_RANGE_BOTTOM "0.0000000000"
*DISP_RANGE_LEFT "20.0000000000"
*DISP_RANGE_LOGCUTOFF "0.0100000000"
*DISP_RANGE_RIGHT "80.0000000000"
*DISP_RANGE_TOP "3750.0000000000"
*DISP_SCALE_MODE_Y "0.0000000000"
*DISP_TAB_NAME "2θ/θ"
*DISP_TITLE_Y "強度"
*DISP_UNIT_Y "cps"
*DISP_WINDOW_NAME "MSG_MACROENGINE"
*FILE_COMMENT " "
*FILE_MD5 ""
*FILE_MEMO " "
*FILE_OPERATOR "Administrator"
*FILE_SAMPLE " "
*FILE_TYPE "RAS_RAW"
*FILE_USERGROUP "システムマネージャ"
*FILE_VERSION "1.0000000000"
*HW_ATTACHMENT_ID "ATT0025"
*HW_ATTACHMENT_NAME "標準|Standard"
*HW_COUNTER_ID-0 "CUT0025"
*HW_COUNTER_ID-1 "CUT0020"
*HW_COUNTER_ID-2 "CUT0020"
*HW_COUNTER_ID-3 "CSL0021"
*HW_COUNTER_ID-4 "CMC0021"
*HW_COUNTER_NAME-0 "D/teX Ultra|D/teX Ultra"
*HW_COUNTER_NAME-1 "None|None"
*HW_COUNTER_NAME-2 "None|None"
*HW_COUNTER_NAME-3 "BBM|BBM"
*HW_COUNTER_NAME-4 "検出器モノクロメータ|Detector monochromator"
*HW_COUNTER_SELECT_NAME "D/teX Ultra|D/teX Ultra"
*HW_GONIOMETER_ID "GON0023"
*HW_GONIOMETER_NAME "SmartLab|SmartLab"
*HW_GONIOMETER_RADIUS-0 "90.0"
*HW_GONIOMETER_RADIUS-1 "114.0"
*HW_GONIOMETER_RADIUS-2 "190.0"
*HW_GONIOMETER_RADIUS-3 "300.0"
*HW_GONIOMETER_RADIUS-4 "187.0"
*HW_GONIOMETER_RADIUS-5 "300.0"
*HW_GONIOMETER_RADIUS-6 "113.0"
*HW_GONIOMETER_RADIUS-7 "331.0"
*HW_I_OPT_ID-0 "CBO0021"
*HW_I_OPT_ID-1 "ICR0023"
*HW_I_OPT_ID-2 "ISL0021"
*HW_I_OPT_ID-3 "ISO0021"
*HW_I_OPT_ID-4 "IAD0021"
*HW_I_OPT_ID-5 "IPR0001"
*HW_I_OPT_NAME-0 "CBOユニット|CBO unit"
*HW_I_OPT_NAME-1 "標準入射光学ユニット|Standard incident optical unit"
*HW_I_OPT_NAME-2 "標準入射スリットボックス|Standard incident slit box"
*HW_I_OPT_NAME-3 "入射平行スリット|Incident parallel slit"
*HW_I_OPT_NAME-4 "長手制限スリット|Length limiting slit"
*HW_I_OPT_NAME-5 "None|None"
*HW_R_ATTENUATER_AUTOMODE "0"
*HW_R_OPT_ID-0 "RSS0021"
*HW_R_OPT_ID-1 "RCR0023"
*HW_R_OPT_ID-2 "RSO0021"
*HW_R_OPT_ID-3 "RRS0021"
*HW_R_OPT_ID-4 "ATN0021"
*HW_R_OPT_ID-5 "RFL0021"
*HW_R_OPT_ID-6 "RAD0021"
*HW_R_OPT_NAME-0 "標準受光スリットボックス1|Standard receiving slit box # 1"
*HW_R_OPT_NAME-1 "標準受光光学ユニット1|Standard receiving unit # 1"
*HW_R_OPT_NAME-2 "標準受光光学ユニット2|Standard receiving optical unit # 2"
*HW_R_OPT_NAME-3 "標準受光スリットボックス2|Standard receiving slit box # 2"
*HW_R_OPT_NAME-4 "標準アッテネータ|Standard Attenuator"
*HW_R_OPT_NAME-5 "Cu Kβ|Cu K-beta"
*HW_R_OPT_NAME-6 "調整用受光スリット|Alignment receiving slit"
*HW_SAMPLE_HOLDER_ID "SMP0023"
*HW_SAMPLE_HOLDER_NAME "標準Zステージ|Standard Z stage"
*HW_XG_CURRENT_MAX "50"
*HW_XG_CURRENT_MIN "2"
*HW_XG_CURRENT_RESOLUTION "2"
*HW_XG_CURRENT_UNIT "mA"
*HW_XG_FOCUS "1mm x 10mm"
*HW_XG_FOCUS_TYPE "Normal"
*HW_XG_ID ""
*HW_XG_NAME "3kW 封入管(ID:1200)|3kW Sealed tube(ID:1200)"
*HW_XG_TARGET_ATOMIC_NUMBER "29.0000000000"
*HW_XG_TARGET_NAME "Cu"
*HW_XG_TYPE "Hermetic"
*HW_XG_VOLTAGE_MAX "60"
*HW_XG_VOLTAGE_MIN "20"
*HW_XG_VOLTAGE_RESOLUTION "2"
*HW_XG_VOLTAGE_UNIT "kV"
*HW_XG_WATT_MAX "2"
*HW_XG_WATT_UNIT "kW"
*HW_XG_WAVE_LENGTH_ALPHA1 "1.540593"
*HW_XG_WAVE_LENGTH_ALPHA2 "1.544414"
*HW_XG_WAVE_LENGTH_BETA "1.392250"
*MEAS_COND_AXIS_NAME-0 "2θ/θ"
*MEAS_COND_AXIS_NAME-1 "2θ"
*MEAS_COND_AXIS_NAME-2 "ω"
*MEAS_COND_AXIS_NAME-3 "Z"
*MEAS_COND_AXIS_NAME-4 "2θ/ω"
*MEAS_COND_AXIS_NAME-5 "θs"
*MEAS_COND_AXIS_NAME-6 "θd"
*MEAS_COND_AXIS_NAME-7 "Ts"
*MEAS_COND_AXIS_NAME-8 "CBO選択スリット"
*MEAS_COND_AXIS_NAME-9 "M"
*MEAS_COND_AXIS_NAME-10 "入射平行スリット"
*MEAS_COND_AXIS_NAME-11 "入射スリット"
*MEAS_COND_AXIS_NAME-12 ""
*MEAS_COND_AXIS_NAME-13 "Zs"
*MEAS_COND_AXIS_NAME-14 "入射光学素子"
*MEAS_COND_AXIS_NAME-15 "長手制限スリット"
*MEAS_COND_AXIS_NAME-16 "センタースリット"
*MEAS_COND_AXIS_NAME-17 "フィルター"
*MEAS_COND_AXIS_NAME-18 "受光スリット1"
*MEAS_COND_AXIS_NAME-19 "受光スリット2"
*MEAS_COND_AXIS_NAME-20 "受光光学素子"
*MEAS_COND_AXIS_NAME-21 "受光平行スリット"
*MEAS_COND_AXIS_NAME-22 "調整用受光スリット"
*MEAS_COND_AXIS_NAME-23 ""
*MEAS_COND_AXIS_NAME-24 ""
*MEAS_COND_AXIS_NAME-25 "Zd"
*MEAS_COND_AXIS_NAME-26 "アッテネータ"
*MEAS_COND_AXIS_NAME-27 "検出器モノクロメータ"
*MEAS_COND_AXIS_NAME-28 "モノクロメータスリット"
*MEAS_COND_AXIS_NAME-29 "プライマリビーム"
*MEAS_COND_AXIS_NAME-30 "PHA"
*MEAS_COND_AXIS_NAME_INTERNAL-0 "TwoThetaTheta"
*MEAS_COND_AXIS_NAME_INTERNAL-1 "TwoTheta"
*MEAS_COND_AXIS_NAME_INTERNAL-2 "Omega"
*MEAS_COND_AXIS_NAME_INTERNAL-3 "Z"
*MEAS_COND_AXIS_NAME_INTERNAL-4 "TwoThetaOmega"
*MEAS_COND_AXIS_NAME_INTERNAL-5 "ThetaS"
*MEAS_COND_AXIS_NAME_INTERNAL-6 "ThetaD"
*MEAS_COND_AXIS_NAME_INTERNAL-7 "Ts"
*MEAS_COND_AXIS_NAME_INTERNAL-8 "CBO"
*MEAS_COND_AXIS_NAME_INTERNAL-9 "CBO-M"
*MEAS_COND_AXIS_NAME_INTERNAL-10 "IncidentSollerSlit"
*MEAS_COND_AXIS_NAME_INTERNAL-11 "IncidentSlitBox"
*MEAS_COND_AXIS_NAME_INTERNAL-12 "IncidentSlitBox-_Axis"
*MEAS_COND_AXIS_NAME_INTERNAL-13 "Zs"
*MEAS_COND_AXIS_NAME_INTERNAL-14 "IncidentMonochromator"
*MEAS_COND_AXIS_NAME_INTERNAL-15 "IncidentAxdSlit"
*MEAS_COND_AXIS_NAME_INTERNAL-16 "CenterSlit"
*MEAS_COND_AXIS_NAME_INTERNAL-17 "Filter"
*MEAS_COND_AXIS_NAME_INTERNAL-18 "ReceivingSlitBox1"
*MEAS_COND_AXIS_NAME_INTERNAL-19 "ReceivingSlitBox2"
*MEAS_COND_AXIS_NAME_INTERNAL-20 "ReceivingOptics"
*MEAS_COND_AXIS_NAME_INTERNAL-21 "ReceivingSollerSlit"
*MEAS_COND_AXIS_NAME_INTERNAL-22 "ReceivingAxdSlit"
*MEAS_COND_AXIS_NAME_INTERNAL-23 "ReceivingSlitBox1-_Axis"
*MEAS_COND_AXIS_NAME_INTERNAL-24 "ReceivingSlitBox2-_Axis"
*MEAS_COND_AXIS_NAME_INTERNAL-25 "ReceivingSlitBox2-Zd"
*MEAS_COND_AXIS_NAME_INTERNAL-26 "Attenuator"
*MEAS_COND_AXIS_NAME_INTERNAL-27 "CounterMonochromator"
*MEAS_COND_AXIS_NAME_INTERNAL-28 "CounterSlit"
*MEAS_COND_AXIS_NAME_INTERNAL-29 "IncidentPrimary"
*MEAS_COND_AXIS_NAME_INTERNAL-30 "PHA"
*MEAS_COND_AXIS_NAME_MAGICNO-0 "83951616.0000000000"
*MEAS_COND_AXIS_NAME_MAGICNO-1 "268632064.0000000000"
*MEAS_COND_AXIS_NAME_MAGICNO-2 "268500992.0000000000"
*MEAS_COND_AXIS_NAME_MAGICNO-3 "285278208.0000000000"
*MEAS_COND_AXIS_NAME_MAGICNO-4 "83951616.0000000000"
*MEAS_COND_AXIS_NAME_MAGICNO-5 "131072.0000000000"
*MEAS_COND_AXIS_NAME_MAGICNO-6 "131072.0000000000"
*MEAS_COND_AXIS_NAME_MAGICNO-7 "318898176.0000000000"
*MEAS_COND_AXIS_NAME_MAGICNO-8 "20971521.0000000000"
*MEAS_COND_AXIS_NAME_MAGICNO-9 "285343744.0000000000"
*MEAS_COND_AXIS_NAME_MAGICNO-10 "20971521.0000000000"
*MEAS_COND_AXIS_NAME_MAGICNO-11 "22020097.0000000000"
*MEAS_COND_AXIS_NAME_MAGICNO-12 "25165824.0000000000"
*MEAS_COND_AXIS_NAME_MAGICNO-13 "318898176.0000000000"
*MEAS_COND_AXIS_NAME_MAGICNO-14 "1.0000000000"
*MEAS_COND_AXIS_NAME_MAGICNO-15 "20971521.0000000000"
*MEAS_COND_AXIS_NAME_MAGICNO-16 "20971521.0000000000"
*MEAS_COND_AXIS_NAME_MAGICNO-17 "20971521.0000000000"
*MEAS_COND_AXIS_NAME_MAGICNO-18 "23068673.0000000000"
*MEAS_COND_AXIS_NAME_MAGICNO-19 "23068673.0000000000"
*MEAS_COND_AXIS_NAME_MAGICNO-20 "20971521.0000000000"
*MEAS_COND_AXIS_NAME_MAGICNO-21 "20971521.0000000000"
*MEAS_COND_AXIS_NAME_MAGICNO-22 "20971521.0000000000"
*MEAS_COND_AXIS_NAME_MAGICNO-23 "25165824.0000000000"
*MEAS_COND_AXIS_NAME_MAGICNO-24 "25165824.0000000000"
*MEAS_COND_AXIS_NAME_MAGICNO-25 "285343744.0000000000"
*MEAS_COND_AXIS_NAME_MAGICNO-26 "17301505.0000000000"
*MEAS_COND_AXIS_NAME_MAGICNO-27 "20971521.0000000000"
*MEAS_COND_AXIS_NAME_MAGICNO-28 "20971521.0000000000"
*MEAS_COND_AXIS_NAME_MAGICNO-29 "20971521.0000000000"
*MEAS_COND_AXIS_NAME_MAGICNO-30 "0.0000000000"
*MEAS_COND_AXIS_OFFSET-0 "-"
*MEAS_COND_AXIS_OFFSET-1 "-0.1081000000"
*MEAS_COND_AXIS_OFFSET-2 "0.3758000000"
*MEAS_COND_AXIS_OFFSET-3 "-"
*MEAS_COND_AXIS_OFFSET-4 "-"
*MEAS_COND_AXIS_OFFSET-5 "0.3758000000"
*MEAS_COND_AXIS_OFFSET-6 "-0.4839000000"
*MEAS_COND_AXIS_OFFSET-7 "-"
*MEAS_COND_AXIS_OFFSET-8 "-"
*MEAS_COND_AXIS_OFFSET-9 "-"
*MEAS_COND_AXIS_OFFSET-10 "-"
*MEAS_COND_AXIS_OFFSET-11 "-"
*MEAS_COND_AXIS_OFFSET-12 "-"
*MEAS_COND_AXIS_OFFSET-13 "-"
*MEAS_COND_AXIS_OFFSET-14 "-"
*MEAS_COND_AXIS_OFFSET-15 "-"
*MEAS_COND_AXIS_OFFSET-16 "-"
*MEAS_COND_AXIS_OFFSET-17 "-"
*MEAS_COND_AXIS_OFFSET-18 "-"
*MEAS_COND_AXIS_OFFSET-19 "-"
*MEAS_COND_AXIS_OFFSET-20 "-"
*MEAS_COND_AXIS_OFFSET-21 "-"
*MEAS_COND_AXIS_OFFSET-22 "-"
*MEAS_COND_AXIS_OFFSET-23 "-"
*MEAS_COND_AXIS_OFFSET-24 "-"
*MEAS_COND_AXIS_OFFSET-25 "-"
*MEAS_COND_AXIS_OFFSET-26 "-"
*MEAS_COND_AXIS_OFFSET-27 "-"
*MEAS_COND_AXIS_OFFSET-28 "-"
*MEAS_COND_AXIS_OFFSET-29 "-"
*MEAS_COND_AXIS_OFFSET-30 "-"
*MEAS_COND_AXIS_POSITION-0 "0.0000000000"
*MEAS_COND_AXIS_POSITION-1 "0.0000000000"
*MEAS_COND_AXIS_POSITION-2 "0.0000000000"
*MEAS_COND_AXIS_POSITION-3 "-0.5500000000"
*MEAS_COND_AXIS_POSITION-4 "0.0000000000"
*MEAS_COND_AXIS_POSITION-5 "0.0000000000"
*MEAS_COND_AXIS_POSITION-6 "0.0000000000"
*MEAS_COND_AXIS_POSITION-7 "-0.4278800000"
*MEAS_COND_AXIS_POSITION-8 "BB"
*MEAS_COND_AXIS_POSITION-9 "0.0000000000"
*MEAS_COND_AXIS_POSITION-10 "Soller_slit_5.0deg"
*MEAS_COND_AXIS_POSITION-11 "2/3deg"
*MEAS_COND_AXIS_POSITION-12 "2.2088000000"
*MEAS_COND_AXIS_POSITION-13 "-0.4140600000"
*MEAS_COND_AXIS_POSITION-14 "0.0000000000"
*MEAS_COND_AXIS_POSITION-15 "10.0mm"
*MEAS_COND_AXIS_POSITION-16 "None"
*MEAS_COND_AXIS_POSITION-17 "Cu_K-beta"
*MEAS_COND_AXIS_POSITION-18 "13.000mm"
*MEAS_COND_AXIS_POSITION-19 "13.000mm"
*MEAS_COND_AXIS_POSITION-20 "No_unit"
*MEAS_COND_AXIS_POSITION-21 "Soller_slit_5.0deg"
*MEAS_COND_AXIS_POSITION-22 "None"
*MEAS_COND_AXIS_POSITION-23 "13.0000000000"
*MEAS_COND_AXIS_POSITION-24 "13.0000000000"
*MEAS_COND_AXIS_POSITION-25 "0.0109400000"
*MEAS_COND_AXIS_POSITION-26 "Open"
*MEAS_COND_AXIS_POSITION-27 "None"
*MEAS_COND_AXIS_POSITION-28 "None"
*MEAS_COND_AXIS_POSITION-29 "None"
*MEAS_COND_AXIS_POSITION-30 "38.0000000000"
*MEAS_COND_AXIS_UNIT-0 "deg"
*MEAS_COND_AXIS_UNIT-1 "deg"
*MEAS_COND_AXIS_UNIT-2 "deg"
*MEAS_COND_AXIS_UNIT-3 "mm"
*MEAS_COND_AXIS_UNIT-4 "deg"
*MEAS_COND_AXIS_UNIT-5 "deg"
*MEAS_COND_AXIS_UNIT-6 "deg"
*MEAS_COND_AXIS_UNIT-7 "mm"
*MEAS_COND_AXIS_UNIT-8 ""
*MEAS_COND_AXIS_UNIT-9 "pulse"
*MEAS_COND_AXIS_UNIT-10 ""
*MEAS_COND_AXIS_UNIT-11 ""
*MEAS_COND_AXIS_UNIT-12 "mm"
*MEAS_COND_AXIS_UNIT-13 "mm"
*MEAS_COND_AXIS_UNIT-14 ""
*MEAS_COND_AXIS_UNIT-15 ""
*MEAS_COND_AXIS_UNIT-16 ""
*MEAS_COND_AXIS_UNIT-17 ""
*MEAS_COND_AXIS_UNIT-18 ""
*MEAS_COND_AXIS_UNIT-19 ""
*MEAS_COND_AXIS_UNIT-20 ""
*MEAS_COND_AXIS_UNIT-21 ""
*MEAS_COND_AXIS_UNIT-22 ""
*MEAS_COND_AXIS_UNIT-23 "mm"
*MEAS_COND_AXIS_UNIT-24 "mm"
*MEAS_COND_AXIS_UNIT-25 "mm"
*MEAS_COND_AXIS_UNIT-26 ""
*MEAS_COND_AXIS_UNIT-27 ""
*MEAS_COND_AXIS_UNIT-28 ""
*MEAS_COND_AXIS_UNIT-29 ""
*MEAS_COND_AXIS_UNIT-30 "div"
*MEAS_COND_COUNTER_CNTLOSS_CORR "0.0000000000"
*MEAS_COND_COUNTER_PHABASE "38.0000000000"
*MEAS_COND_COUNTER_PHAWINDOW "16.0000000000"
*MEAS_COND_COUNTER_PHA_UNIT "div"
*MEAS_COND_COUNTER_TAUDIFF "30.0000000000"
*MEAS_COND_COUNTER_TAUINT "0.0000000000"
*MEAS_COND_IRRADIATION_MODE "OFF"
*MEAS_COND_IRRADIATION_WIDTH ""
*MEAS_COND_OPT_ATTR "集中法"
*MEAS_COND_OPT_NAME "@集中法"
*MEAS_COND_UNSYMMETRIC_MODE "OFF"
*MEAS_COND_XG_CURRENT "30.0000000000"
*MEAS_COND_XG_VOLTAGE "40.0000000000"
*MEAS_COND_XG_WAVE_TYPE "Ka"
*MEAS_DATA_COUNT "3001.0000000000"
*MEAS_SCAN_AXIS_X "2θ/θ"
*MEAS_SCAN_AXIS_X_INTERNAL "TwoThetaTheta"
*MEAS_SCAN_END_TIME "09/02/20 12:52:57"
*MEAS_SCAN_MODE "CONTINUOUS"
*MEAS_SCAN_MONITOR "0"
*MEAS_SCAN_RESOLUTION_X "0.0002"
*MEAS_SCAN_SPEED "2.0"
*MEAS_SCAN_SPEED_UNIT "deg/min"
*MEAS_SCAN_START "20.0000000000"
*MEAS_SCAN_START_TIME "09/02/20 12:21:17"
*MEAS_SCAN_STEP "0.0200000000"
*MEAS_SCAN_STOP "80.0000000000"
*MEAS_SCAN_UNIT_X "deg"
*MEAS_SCAN_UNIT_Y "counts"
*RAS_HEADER_END
*RAS_INT_START
20.0000 1716.0000 1.0000
20.0600 1830.0000 1.0000
20.1200 1864.0000 1.0000
20.1800 1772.0000 1.0000
20.2400 1823.0000 1.0000
20.3000 1857.0000 1.0000
20.3600 1751.0000 1.0000
20.4200 1780.0000 1.0000
20.4800 1768.0000 1.0000
20.5400 1721.0000 1.0000
20.6000 1749.0000 1.0000
20.6600 1768.0000 1.0000
20.7200 1759.0000 1.0000
20.7800 1706.0000 1.0000
20.8400 1785.0000 1.0000
20.9000 1707.0000 1.0000
20.9600 1665.0000 1.0000
21.0200 1708.0000 1.0000
21.0800 1690.0000 1.0000
21.1400 1694.0000 1.0000
21.2000 1676.0000 1.0000
21.2600 1690.0000 1.0000
21.3200 1647.0000 1.0000
21.3800 1699.0000 1.0000
21.4400 1656.0000 1.0000
21.5000 1663.0000 1.0000
21.5600 1662.0000 1.0000
21.6200 1534.0000 1.0000
21.6800 1598.0000 1.0000
21.7400 1590.0000 1.0000
21.8000 1573.0000 1.0000
21.8600 1597.0000 1.0000
21.9200 1495.0000 1.0000
21.9800 1613.0000 1.0000
22.0400 1567.0000 1.0000
22.1000 1510.0000 1.0000
22.1600 1540.0000 1.0000
22.2200 1546.0000 1.0000
22.2800 1610.0000 1.0000
22.3400 1530.0000 1.0000
22.4000 1514.0000 1.0000
22.4600 1539.0000 1.0000
22.5200 1430.0000 1.0000
22.5800 1518.0000 1.0000
22.6400 1465.0000 1.0000
22.7000 1498.0000 1.0000
22.7600 1407.0000 1.0000
22.8200 1460.0000 1.0000
22.8800 1453.0000 1.0000
22.9400 1464.0000 1.0000
23.0000 1484.0000 1.0000
23.0600 1453.0000 1.0000
23.1200 1411.0000 1.0000
23.1800 1416.0000 1.0000
23.2400 1391.0000 1.0000
23.3000 1368.0000 1.0000
23.3600 1424.0000 1.0000
23.4200 1349.0000 1.0000
23.4800 1358.0000 1.0000
23.5400 1406.0000 1.0000
23.6000 1318.0000 1.0000
23.6600 1379.0000 1.0000
23.7200 1334.0000 1.0000
23.7800 1293.0000 1.0000
23.8400 1320.0000 1.0000
23.9000 1317.0000 1.0000
23.9600 1358.0000 1.0000
24.0200 1349.0000 1.0000
24.0800 1312.0000 1.0000
24.1400 1327.0000 1.0000
24.2000 1297.0000 1.0000
24.2600 1247.0000 1.0000
24.3200 1296.0000 1.0000
24.3800 1292.0000 1.0000
24.4400 1269.0000 1.0000
24.5000 1241.0000 1.0000
24.5600 1283.0000 1.0000
24.6200 1256.0000 1.0000
24.6800 1267.0000 1.0000
24.7400 1289.0000 1.0000
24.8000 1263.0000 1.0000
24.8600 1241.0000 1.0000
24.9200 1270.0000 1.0000
24.9800 1212.0000 1.0000
25.0400 1185.0000 1.0000
25.1000 1180.0000 1.0000
25.1600 1249.0000 1.0000
25.2200 1150.0000 1.0000
25.2800 1158.0000 1.0000
25.3400 1195.0000 1.0000
25.4000 1215.0000 1.0000
25.4600 1171.0000 1.0000
25.5200 1181.0000 1.0000
25.5800 1174.0000 1.0000
25.6400 1154.0000 1.0000
25.7000 1194.0000 1.0000
25.7600 1147.0000 1.0000
25.8200 1125.0000 1.0000
25.8800 1115.0000 1.0000
25.9400 1120.0000 1.0000
26.0000 1086.0000 1.0000
26.0600 1133.0000 1.0000
26.1200 1087.0000 1.0000
26.1800 1064.0000 1.0000
26.2400 1068.0000 1.0000
26.3000 1137.0000 1.0000
26.3600 1084.0000 1.0000
26.4200 1072.0000 1.0000
26.4800 1092.0000 1.0000
26.5400 1090.0000 1.0000
26.6000 1087.0000 1.0000
26.6600 1122.0000 1.0000
26.7200 1049.0000 1.0000
26.7800 1027.0000 1.0000
26.8400 1044.0000 1.0000
26.9000 1089.0000 1.0000
26.9600 1045.0000 1.0000
27.0200 987.0000 1.0000
27.0800 1000.0000 1.0000
27.1400 1101.0000 1.0000
27.2000 1082.0000 1.0000
27.2600 1192.0000 1.0000
27.3200 1213.0000 1.0000
27.3800 1163.0000 1.0000
27.4400 1131.0000 1.0000
27.5000 1120.0000 1.0000
27.5600 1052.0000 1.0000
27.6200 1077.0000 1.0000
27.6800 1002.0000 1.0000
27.7400 1033.0000 1.0000
27.8000 1020.0000 1.0000
27.8600 943.0000 1.0000
27.9200 991.0000 1.0000
27.9800 1008.0000 1.0000
28.0400 950.0000 1.0000
28.1000 978.0000 1.0000
28.1600 889.0000 1.0000
28.2200 974.0000 1.0000
28.2800 975.0000 1.0000
28.3400 931.0000 1.0000
28.4000 923.0000 1.0000
28.4600 939.0000 1.0000
28.5200 954.0000 1.0000
28.5800 901.0000 1.0000
28.6400 913.0000 1.0000
28.7000 921.0000 1.0000
28.7600 890.0000 1.0000
28.8200 930.0000 1.0000
28.8800 865.0000 1.0000
28.9400 866.0000 1.0000
29.0000 860.0000 1.0000
29.0600 940.0000 1.0000
29.1200 860.0000 1.0000
29.1800 845.0000 1.0000
29.2400 857.0000 1.0000
29.3000 869.0000 1.0000
29.3600 858.0000 1.0000
29.4200 855.0000 1.0000
29.4800 853.0000 1.0000
29.5400 840.0000 1.0000
29.6000 816.0000 1.0000
29.6600 849.0000 1.0000
29.7200 813.0000 1.0000
29.7800 843.0000 1.0000
29.8400 787.0000 1.0000
29.9000 746.0000 1.0000
29.9600 807.0000 1.0000
30.0200 859.0000 1.0000
30.0800 786.0000 1.0000
30.1400 802.0000 1.0000
30.2000 785.0000 1.0000
30.2600 792.0000 1.0000
30.3200 818.0000 1.0000
30.3800 816.0000 1.0000
30.4400 791.0000 1.0000
30.5000 793.0000 1.0000
30.5600 731.0000 1.0000
30.6200 778.0000 1.0000
30.6800 799.0000 1.0000
30.7400 753.0000 1.0000
30.8000 747.0000 1.0000
30.8600 763.0000 1.0000
30.9200 774.0000 1.0000
30.9800 765.0000 1.0000
31.0400 728.0000 1.0000
31.1000 760.0000 1.0000
31.1600 731.0000 1.0000
31.2200 752.0000 1.0000
31.2800 772.0000 1.0000
31.3400 726.0000 1.0000
31.4000 727.0000 1.0000
31.4600 712.0000 1.0000
31.5200 736.0000 1.0000
31.5800 727.0000 1.0000
31.6400 717.0000 1.0000
31.7000 708.0000 1.0000
31.7600 725.0000 1.0000
31.8200 718.0000 1.0000
31.8800 679.0000 1.0000
31.9400 667.0000 1.0000
32.0000 743.0000 1.0000
32.0600 706.0000 1.0000
32.1200 727.0000 1.0000
32.1800 686.0000 1.0000
32.2400 722.0000 1.0000
32.3000 708.0000 1.0000
32.3600 628.0000 1.0000
32.4200 722.0000 1.0000
32.4800 680.0000 1.0000
32.5400 653.0000 1.0000
32.6000 664.0000 1.0000
32.6600 649.0000 1.0000
32.7200 632.0000 1.0000
32.7800 675.0000 1.0000
32.8400 665.0000 1.0000
32.9000 674.0000 1.0000
32.9600 669.0000 1.0000
33.0200 645.0000 1.0000
33.0800 684.0000 1.0000
33.1400 614.0000 1.0000
33.2000 665.0000 1.0000
33.2600 632.0000 1.0000
33.3200 691.0000 1.0000
33.3800 661.0000 1.0000
33.4400 672.0000 1.0000
33.5000 613.0000 1.0000
33.5600 637.0000 1.0000
33.6200 617.0000 1.0000
33.6800 642.0000 1.0000
33.7400 623.0000 1.0000
33.8000 602.0000 1.0000
33.8600 614.0000 1.0000
33.9200 584.0000 1.0000
33.9800 623.0000 1.0000
34.0400 599.0000 1.0000
34.1000 597.0000 1.0000
34.1600 609.0000 1.0000
34.2200 634.0000 1.0000
34.2800 660.0000 1.0000
34.3400 602.0000 1.0000
34.4000 670.0000 1.0000
34.4600 719.0000 1.0000
34.5200 746.0000 1.0000
34.5800 712.0000 1.0000
34.6400 668.0000 1.0000
34.7000 619.0000 1.0000
34.7600 600.0000 1.0000
34.8200 583.0000 1.0000
34.8800 561.0000 1.0000
34.9400 546.0000 1.0000
35.0000 589.0000 1.0000
35.0600 590.0000 1.0000
35.1200 564.0000 1.0000
35.1800 560.0000 1.0000
35.2400 579.0000 1.0000
35.3000 554.0000 1.0000
35.3600 563.0000 1.0000
35.4200 536.0000 1.0000
35.4800 546.0000 1.0000
35.5400 534.0000 1.0000
35.6000 516.0000 1.0000
35.6600 508.0000 1.0000
35.7200 508.0000 1.0000
35.7800 507.0000 1.0000
35.8400 546.0000 1.0000
35.9000 501.0000 1.0000
35.9600 535.0000 1.0000
36.0200 509.0000 1.0000
36.0800 521.0000 1.0000
36.1400 523.0000 1.0000
36.2000 495.0000 1.0000
36.2600 488.0000 1.0000
36.3200 511.0000 1.0000
36.3800 565.0000 1.0000
36.4400 556.0000 1.0000
36.5000 571.0000 1.0000
36.5600 535.0000 1.0000
36.6200 536.0000 1.0000
36.6800 511.0000 1.0000
36.7400 500.0000 1.0000
36.8000 500.0000 1.0000
36.8600 484.0000 1.0000
36.9200 476.0000 1.0000
36.9800 514.0000 1.0000
37.0400 458.0000 1.0000
37.1000 449.0000 1.0000
37.1600 461.0000 1.0000
37.2200 440.0000 1.0000
37.2800 492.0000 1.0000
37.3400 492.0000 1.0000
37.4000 450.0000 1.0000
37.4600 483.0000 1.0000
37.5200 443.0000 1.0000
37.5800 481.0000 1.0000
37.6400 444.0000 1.0000
37.7000 453.0000 1.0000
37.7600 484.0000 1.0000
37.8200 447.0000 1.0000
37.8800 430.0000 1.0000
37.9400 439.0000 1.0000
38.0000 464.0000 1.0000
38.0600 473.0000 1.0000
38.1200 464.0000 1.0000
38.1800 481.0000 1.0000
38.2400 485.0000 1.0000
38.3000 481.0000 1.0000
38.3600 514.0000 1.0000
38.4200 589.0000 1.0000
38.4800 722.0000 1.0000
38.5400 793.0000 1.0000
38.6000 806.0000 1.0000
38.6600 735.0000 1.0000
38.7200 604.0000 1.0000
38.7800 549.0000 1.0000
38.8400 536.0000 1.0000
38.9000 461.0000 1.0000
38.9600 398.0000 1.0000
39.0200 402.0000 1.0000
39.0800 406.0000 1.0000
39.1400 463.0000 1.0000
39.2000 392.0000 1.0000
39.2600 403.0000 1.0000
39.3200 410.0000 1.0000
39.3800 406.0000 1.0000
39.4400 429.0000 1.0000
39.5000 412.0000 1.0000
39.5600 377.0000 1.0000
39.6200 403.0000 1.0000
39.6800 356.0000 1.0000
39.7400 426.0000 1.0000
39.8000 408.0000 1.0000
39.8600 404.0000 1.0000
39.9200 429.0000 1.0000
39.9800 392.0000 1.0000
40.0400 410.0000 1.0000
40.1000 369.0000 1.0000
40.1600 371.0000 1.0000
40.2200 403.0000 1.0000
40.2800 383.0000 1.0000
40.3400 396.0000 1.0000
40.4000 360.0000 1.0000
40.4600 393.0000 1.0000
40.5200 371.0000 1.0000
40.5800 346.0000 1.0000
40.6400 349.0000 1.0000
40.7000 364.0000 1.0000
40.7600 420.0000 1.0000
40.8200 389.0000 1.0000
40.8800 336.0000 1.0000
40.9400 365.0000 1.0000
41.0000 385.0000 1.0000
41.0600 391.0000 1.0000
41.1200 361.0000 1.0000
41.1800 346.0000 1.0000
41.2400 353.0000 1.0000
41.3000 366.0000 1.0000
41.3600 344.0000 1.0000
41.4200 363.0000 1.0000
41.4800 369.0000 1.0000
41.5400 367.0000 1.0000
41.6000 362.0000 1.0000
41.6600 367.0000 1.0000
41.7200 368.0000 1.0000
41.7800 334.0000 1.0000
41.8400 335.0000 1.0000
41.9000 339.0000 1.0000
41.9600 364.0000 1.0000
42.0200 358.0000 1.0000
42.0800 341.0000 1.0000
42.1400 341.0000 1.0000
42.2000 335.0000 1.0000
42.2600 338.0000 1.0000
42.3200 341.0000 1.0000
42.3800 341.0000 1.0000
42.4400 348.0000 1.0000
42.5000 316.0000 1.0000
42.5600 350.0000 1.0000
42.6200 340.0000 1.0000
42.6800 321.0000 1.0000
42.7400 321.0000 1.0000
42.8000 329.0000 1.0000
42.8600 321.0000 1.0000
42.9200 312.0000 1.0000
42.9800 340.0000 1.0000
43.0400 301.0000 1.0000
43.1000 340.0000 1.0000
43.1600 311.0000 1.0000
43.2200 315.0000 1.0000
43.2800 342.0000 1.0000
43.3400 328.0000 1.0000
43.4000 301.0000 1.0000
43.4600 339.0000 1.0000
43.5200 346.0000 1.0000
43.5800 347.0000 1.0000
43.6400 331.0000 1.0000
43.7000 321.0000 1.0000
43.7600 309.0000 1.0000
43.8200 320.0000 1.0000
43.8800 318.0000 1.0000
43.9400 313.0000 1.0000
44.0000 306.0000 1.0000
44.0600 294.0000 1.0000
44.1200 303.0000 1.0000
44.1800 302.0000 1.0000
44.2400 284.0000 1.0000
44.3000 332.0000 1.0000
44.3600 300.0000 1.0000
44.4200 329.0000 1.0000
44.4800 307.0000 1.0000
44.5400 288.0000 1.0000
44.6000 321.0000 1.0000
44.6600 275.0000 1.0000
44.7200 283.0000 1.0000
44.7800 314.0000 1.0000
44.8400 302.0000 1.0000
44.9000 280.0000 1.0000
44.9600 307.0000 1.0000
45.0200 320.0000 1.0000
45.0800 323.0000 1.0000
45.1400 303.0000 1.0000
45.2000 325.0000 1.0000
45.2600 299.0000 1.0000
45.3200 322.0000 1.0000
45.3800 274.0000 1.0000
45.4400 279.0000 1.0000
45.5000 311.0000 1.0000
45.5600 294.0000 1.0000
45.6200 305.0000 1.0000
45.6800 293.0000 1.0000
45.7400 289.0000 1.0000
45.8000 284.0000 1.0000
45.8600 272.0000 1.0000
45.9200 283.0000 1.0000
45.9800 278.0000 1.0000
46.0400 277.0000 1.0000
46.1000 277.0000 1.0000
46.1600 297.0000 1.0000
46.2200 293.0000 1.0000
46.2800 274.0000 1.0000
46.3400 274.0000 1.0000
46.4000 290.0000 1.0000
46.4600 251.0000 1.0000
46.5200 286.0000 1.0000
46.5800 279.0000 1.0000
46.6400 272.0000 1.0000
46.7000 285.0000 1.0000
46.7600 271.0000 1.0000
46.8200 328.0000 1.0000
46.8800 285.0000 1.0000
46.9400 287.0000 1.0000
47.0000 297.0000 1.0000
47.0600 275.0000 1.0000
47.1200 245.0000 1.0000
47.1800 294.0000 1.0000
47.2400 270.0000 1.0000
47.3000 266.0000 1.0000
47.3600 236.0000 1.0000
47.4200 278.0000 1.0000
47.4800 260.0000 1.0000
47.5400 284.0000 1.0000
47.6000 257.0000 1.0000
47.6600 293.0000 1.0000
47.7200 252.0000 1.0000
47.7800 266.0000 1.0000
47.8400 259.0000 1.0000
47.9000 276.0000 1.0000
47.9600 247.0000 1.0000
48.0200 257.0000 1.0000
48.0800 276.0000 1.0000
48.1400 267.0000 1.0000
48.2000 245.0000 1.0000
48.2600 258.0000 1.0000
48.3200 269.0000 1.0000
48.3800 248.0000 1.0000
48.4400 252.0000 1.0000
48.5000 280.0000 1.0000
48.5600 237.0000 1.0000
48.6200 249.0000 1.0000
48.6800 237.0000 1.0000
48.7400 249.0000 1.0000
48.8000 258.0000 1.0000
48.8600 244.0000 1.0000
48.9200 253.0000 1.0000
48.9800 259.0000 1.0000
49.0400 258.0000 1.0000
49.1000 250.0000 1.0000
49.1600 289.0000 1.0000
49.2200 217.0000 1.0000
49.2800 247.0000 1.0000
49.3400 286.0000 1.0000
49.4000 229.0000 1.0000
49.4600 248.0000 1.0000
49.5200 234.0000 1.0000
49.5800 228.0000 1.0000
49.6400 236.0000 1.0000
49.7000 263.0000 1.0000
49.7600 240.0000 1.0000
49.8200 227.0000 1.0000
49.8800 238.0000 1.0000
49.9400 234.0000 1.0000
50.0000 238.0000 1.0000
50.0600 229.0000 1.0000
50.1200 244.0000 1.0000
50.1800 245.0000 1.0000
50.2400 231.0000 1.0000
50.3000 236.0000 1.0000
50.3600 253.0000 1.0000
50.4200 239.0000 1.0000
50.4800 229.0000 1.0000
50.5400 254.0000 1.0000
50.6000 263.0000 1.0000
50.6600 252.0000 1.0000
50.7200 234.0000 1.0000
50.7800 207.0000 1.0000
50.8400 209.0000 1.0000
50.9000 252.0000 1.0000
50.9600 228.0000 1.0000
51.0200 246.0000 1.0000
51.0800 253.0000 1.0000
51.1400 230.0000 1.0000
51.2000 243.0000 1.0000
51.2600 213.0000 1.0000
51.3200 256.0000 1.0000
51.3800 256.0000 1.0000
51.4400 237.0000 1.0000
51.5000 247.0000 1.0000
51.5600 267.0000 1.0000
51.6200 227.0000 1.0000
51.6800 246.0000 1.0000
51.7400 238.0000 1.0000
51.8000 246.0000 1.0000
51.8600 235.0000 1.0000
51.9200 265.0000 1.0000
51.9800 267.0000 1.0000
52.0400 314.0000 1.0000
52.1000 331.0000 1.0000
52.1600 444.0000 1.0000
52.2200 698.0000 1.0000
52.2800 885.0000 1.0000
52.3400 818.0000 1.0000
52.4000 690.0000 1.0000
52.4600 601.0000 1.0000
52.5200 474.0000 1.0000
52.5800 390.0000 1.0000
52.6400 305.0000 1.0000
52.7000 269.0000 1.0000
52.7600 262.0000 1.0000
52.8200 259.0000 1.0000
52.8800 242.0000 1.0000
52.9400 224.0000 1.0000
53.0000 281.0000 1.0000
53.0600 228.0000 1.0000
53.1200 254.0000 1.0000
53.1800 223.0000 1.0000
53.2400 230.0000 1.0000
53.3000 244.0000 1.0000
53.3600 214.0000 1.0000
53.4200 230.0000 1.0000
53.4800 229.0000 1.0000
53.5400 242.0000 1.0000
53.6000 241.0000 1.0000
53.6600 222.0000 1.0000
53.7200 227.0000 1.0000
53.7800 260.0000 1.0000
53.8400 221.0000 1.0000
53.9000 227.0000 1.0000
53.9600 235.0000 1.0000
54.0200 227.0000 1.0000
54.0800 229.0000 1.0000
54.1400 238.0000 1.0000
54.2000 224.0000 1.0000
54.2600 233.0000 1.0000
54.3200 230.0000 1.0000
54.3800 216.0000 1.0000
54.4400 229.0000 1.0000
54.5000 210.0000 1.0000
54.5600 229.0000 1.0000
54.6200 209.0000 1.0000
54.6800 236.0000 1.0000
54.7400 232.0000 1.0000
54.8000 225.0000 1.0000
54.8600 268.0000 1.0000
54.9200 192.0000 1.0000
54.9800 226.0000 1.0000
55.0400 226.0000 1.0000
55.1000 246.0000 1.0000
55.1600 249.0000 1.0000
55.2200 264.0000 1.0000
55.2800 279.0000 1.0000
55.3400 285.0000 1.0000
55.4000 308.0000 1.0000
55.4600 242.0000 1.0000
55.5200 258.0000 1.0000
55.5800 237.0000 1.0000
55.6400 237.0000 1.0000
55.7000 221.0000 1.0000
55.7600 256.0000 1.0000
55.8200 225.0000 1.0000
55.8800 235.0000 1.0000
55.9400 211.0000 1.0000
56.0000 186.0000 1.0000
56.0600 224.0000 1.0000
56.1200 223.0000 1.0000
56.1800 204.0000 1.0000
56.2400 220.0000 1.0000
56.3000 222.0000 1.0000
56.3600 225.0000 1.0000
56.4200 220.0000 1.0000
56.4800 229.0000 1.0000
56.5400 219.0000 1.0000
56.6000 205.0000 1.0000
56.6600 214.0000 1.0000
56.7200 200.0000 1.0000
56.7800 204.0000 1.0000
56.8400 238.0000 1.0000
56.9000 240.0000 1.0000
56.9600 220.0000 1.0000
57.0200 209.0000 1.0000
57.0800 213.0000 1.0000
57.1400 218.0000 1.0000
57.2000 217.0000 1.0000
57.2600 229.0000 1.0000
57.3200 224.0000 1.0000
57.3800 201.0000 1.0000
57.4400 199.0000 1.0000
57.5000 204.0000 1.0000
57.5600 220.0000 1.0000
57.6200 219.0000 1.0000
57.6800 209.0000 1.0000
57.7400 207.0000 1.0000
57.8000 222.0000 1.0000
57.8600 220.0000 1.0000
57.9200 210.0000 1.0000
57.9800 237.0000 1.0000
58.0400 214.0000 1.0000
58.1000 230.0000 1.0000
58.1600 211.0000 1.0000
58.2200 196.0000 1.0000
58.2800 205.0000 1.0000
58.3400 214.0000 1.0000
58.4000 229.0000 1.0000
58.4600 210.0000 1.0000
58.5200 213.0000 1.0000
58.5800 218.0000 1.0000
58.6400 239.0000 1.0000
58.7000 235.0000 1.0000
58.7600 218.0000 1.0000
58.8200 201.0000 1.0000
58.8800 200.0000 1.0000
58.9400 200.0000 1.0000
59.0000 193.0000 1.0000
59.0600 229.0000 1.0000
59.1200 226.0000 1.0000
59.1800 226.0000 1.0000
59.2400 212.0000 1.0000
59.3000 210.0000 1.0000
59.3600 230.0000 1.0000
59.4200 203.0000 1.0000
59.4800 191.0000 1.0000
59.5400 194.0000 1.0000
59.6000 205.0000 1.0000
59.6600 193.0000 1.0000
59.7200 192.0000 1.0000
59.7800 179.0000 1.0000
59.8400 222.0000 1.0000
59.9000 193.0000 1.0000
59.9600 199.0000 1.0000
60.0200 197.0000 1.0000
60.0800 192.0000 1.0000
60.1400 192.0000 1.0000
60.2000 217.0000 1.0000
60.2600 203.0000 1.0000
60.3200 221.0000 1.0000
60.3800 201.0000 1.0000
60.4400 200.0000 1.0000
60.5000 224.0000 1.0000
60.5600 213.0000 1.0000
60.6200 196.0000 1.0000
60.6800 189.0000 1.0000
60.7400 189.0000 1.0000
60.8000 208.0000 1.0000
60.8600 213.0000 1.0000
60.9200 196.0000 1.0000
60.9800 217.0000 1.0000
61.0400 218.0000 1.0000
61.1000 206.0000 1.0000
61.1600 217.0000 1.0000
61.2200 197.0000 1.0000
61.2800 192.0000 1.0000
61.3400 222.0000 1.0000
61.4000 195.0000 1.0000
61.4600 201.0000 1.0000
61.5200 210.0000 1.0000
61.5800 185.0000 1.0000
61.6400 198.0000 1.0000
61.7000 206.0000 1.0000
61.7600 203.0000 1.0000
61.8200 208.0000 1.0000
61.8800 221.0000 1.0000
61.9400 233.0000 1.0000
62.0000 226.0000 1.0000
62.0600 251.0000 1.0000
62.1200 235.0000 1.0000
62.1800 307.0000 1.0000
62.2400 356.0000 1.0000
62.3000 381.0000 1.0000
62.3600 336.0000 1.0000
62.4200 348.0000 1.0000
62.4800 318.0000 1.0000
62.5400 292.0000 1.0000
62.6000 274.0000 1.0000
62.6600 266.0000 1.0000
62.7200 226.0000 1.0000
62.7800 231.0000 1.0000
62.8400 198.0000 1.0000
62.9000 195.0000 1.0000
62.9600 233.0000 1.0000
63.0200 217.0000 1.0000
63.0800 223.0000 1.0000
63.1400 207.0000 1.0000
63.2000 232.0000 1.0000
63.2600 205.0000 1.0000
63.3200 197.0000 1.0000
63.3800 188.0000 1.0000
63.4400 202.0000 1.0000
63.5000 241.0000 1.0000
63.5600 220.0000 1.0000
63.6200 205.0000 1.0000
63.6800 207.0000 1.0000
63.7400 223.0000 1.0000
63.8000 186.0000 1.0000
63.8600 223.0000 1.0000
63.9200 199.0000 1.0000
63.9800 203.0000 1.0000
64.0400 207.0000 1.0000
64.1000 201.0000 1.0000
64.1600 213.0000 1.0000
64.2200 197.0000 1.0000
64.2800 175.0000 1.0000
64.3400 204.0000 1.0000
64.4000 214.0000 1.0000
64.4600 230.0000 1.0000
64.5200 206.0000 1.0000
64.5800 247.0000 1.0000
64.6400 258.0000 1.0000
64.7000 300.0000 1.0000
64.7600 278.0000 1.0000
64.8200 242.0000 1.0000
64.8800 254.0000 1.0000
64.9400 253.0000 1.0000
65.0000 246.0000 1.0000
65.0600 203.0000 1.0000
65.1200 215.0000 1.0000
65.1800 244.0000 1.0000
65.2400 183.0000 1.0000
65.3000 241.0000 1.0000
65.3600 214.0000 1.0000
65.4200 216.0000 1.0000
65.4800 221.0000 1.0000
65.5400 224.0000 1.0000
65.6000 206.0000 1.0000
65.6600 212.0000 1.0000
65.7200 218.0000 1.0000
65.7800 230.0000 1.0000
65.8400 233.0000 1.0000
65.9000 237.0000 1.0000
65.9600 234.0000 1.0000
66.0200 273.0000 1.0000
66.0800 282.0000 1.0000
66.1400 385.0000 1.0000
66.2000 455.0000 1.0000
66.2600 623.0000 1.0000
66.3200 559.0000 1.0000
66.3800 534.0000 1.0000
66.4400 474.0000 1.0000
66.5000 418.0000 1.0000
66.5600 353.0000 1.0000
66.6200 282.0000 1.0000
66.6800 276.0000 1.0000
66.7400 243.0000 1.0000
66.8000 217.0000 1.0000
66.8600 242.0000 1.0000
66.9200 220.0000 1.0000
66.9800 217.0000 1.0000
67.0400 210.0000 1.0000
67.1000 207.0000 1.0000
67.1600 197.0000 1.0000
67.2200 191.0000 1.0000
67.2800 200.0000 1.0000
67.3400 223.0000 1.0000
67.4000 224.0000 1.0000
67.4600 208.0000 1.0000
67.5200 186.0000 1.0000
67.5800 230.0000 1.0000
67.6400 207.0000 1.0000
67.7000 222.0000 1.0000
67.7600 188.0000 1.0000
67.8200 202.0000 1.0000
67.8800 206.0000 1.0000
67.9400 196.0000 1.0000
68.0000 192.0000 1.0000
68.0600 194.0000 1.0000
68.1200 177.0000 1.0000
68.1800 190.0000 1.0000
68.2400 196.0000 1.0000
68.3000 207.0000 1.0000
68.3600 201.0000 1.0000
68.4200 169.0000 1.0000
68.4800 208.0000 1.0000
68.5400 177.0000 1.0000
68.6000 213.0000 1.0000
68.6600 212.0000 1.0000
68.7200 194.0000 1.0000
68.7800 183.0000 1.0000
68.8400 207.0000 1.0000
68.9000 206.0000 1.0000
68.9600 190.0000 1.0000
69.0200 183.0000 1.0000
69.0800 193.0000 1.0000
69.1400 210.0000 1.0000
69.2000 194.0000 1.0000
69.2600 187.0000 1.0000
69.3200 189.0000 1.0000
69.3800 196.0000 1.0000
69.4400 167.0000 1.0000
69.5000 190.0000 1.0000
69.5600 189.0000 1.0000
69.6200 205.0000 1.0000
69.6800 185.0000 1.0000
69.7400 204.0000 1.0000
69.8000 193.0000 1.0000
69.8600 226.0000 1.0000
69.9200 228.0000 1.0000
69.9800 193.0000 1.0000
70.0400 185.0000 1.0000
70.1000 200.0000 1.0000
70.1600 190.0000 1.0000
70.2200 221.0000 1.0000
70.2800 216.0000 1.0000
70.3400 199.0000 1.0000
70.4000 194.0000 1.0000
70.4600 207.0000 1.0000
70.5200 207.0000 1.0000
70.5800 171.0000 1.0000
70.6400 190.0000 1.0000
70.7000 185.0000 1.0000
70.7600 178.0000 1.0000
70.8200 182.0000 1.0000
70.8800 191.0000 1.0000
70.9400 186.0000 1.0000
71.0000 185.0000 1.0000
71.0600 179.0000 1.0000
71.1200 191.0000 1.0000
71.1800 200.0000 1.0000
71.2400 192.0000 1.0000
71.3000 207.0000 1.0000
71.3600 193.0000 1.0000
71.4200 196.0000 1.0000
71.4800 198.0000 1.0000
71.5400 223.0000 1.0000
71.6000 189.0000 1.0000
71.6600 214.0000 1.0000
71.7200 203.0000 1.0000
71.7800 203.0000 1.0000
71.8400 216.0000 1.0000
71.9000 180.0000 1.0000
71.9600 188.0000 1.0000
72.0200 198.0000 1.0000
72.0800 175.0000 1.0000
72.1400 185.0000 1.0000
72.2000 198.0000 1.0000
72.2600 193.0000 1.0000
72.3200 178.0000 1.0000
72.3800 191.0000 1.0000
72.4400 203.0000 1.0000
72.5000 192.0000 1.0000
72.5600 194.0000 1.0000
72.6200 216.0000 1.0000
72.6800 189.0000 1.0000
72.7400 205.0000 1.0000
72.8000 193.0000 1.0000
72.8600 194.0000 1.0000
72.9200 186.0000 1.0000
72.9800 192.0000 1.0000
73.0400 195.0000 1.0000
73.1000 181.0000 1.0000
73.1600 176.0000 1.0000
73.2200 176.0000 1.0000
73.2800 212.0000 1.0000
73.3400 164.0000 1.0000
73.4000 181.0000 1.0000
73.4600 157.0000 1.0000
73.5200 198.0000 1.0000
73.5800 190.0000 1.0000
73.6400 176.0000 1.0000
73.7000 193.0000 1.0000
73.7600 171.0000 1.0000
73.8200 187.0000 1.0000
73.8800 176.0000 1.0000
73.9400 189.0000 1.0000
74.0000 201.0000 1.0000
74.0600 177.0000 1.0000
74.1200 220.0000 1.0000
74.1800 171.0000 1.0000
74.2400 179.0000 1.0000
74.3000 169.0000 1.0000
74.3600 201.0000 1.0000
74.4200 193.0000 1.0000
74.4800 187.0000 1.0000
74.5400 193.0000 1.0000
74.6000 195.0000 1.0000
74.6600 185.0000 1.0000
74.7200 185.0000 1.0000
74.7800 193.0000 1.0000
74.8400 184.0000 1.0000
74.9000 197.0000 1.0000
74.9600 186.0000 1.0000
75.0200 178.0000 1.0000
75.0800 180.0000 1.0000
75.1400 187.0000 1.0000
75.2000 183.0000 1.0000
75.2600 199.0000 1.0000
75.3200 174.0000 1.0000
75.3800 202.0000 1.0000
75.4400 169.0000 1.0000
75.5000 172.0000 1.0000
75.5600 171.0000 1.0000
75.6200 193.0000 1.0000
75.6800 180.0000 1.0000
75.7400 170.0000 1.0000
75.8000 191.0000 1.0000
75.8600 211.0000 1.0000
75.9200 166.0000 1.0000
75.9800 171.0000 1.0000
76.0400 172.0000 1.0000
76.1000 185.0000 1.0000
76.1600 174.0000 1.0000
76.2200 172.0000 1.0000
76.2800 186.0000 1.0000
76.3400 190.0000 1.0000
76.4000 176.0000 1.0000
76.4600 181.0000 1.0000
76.5200 209.0000 1.0000
76.5800 179.0000 1.0000
76.6400 177.0000 1.0000
76.7000 193.0000 1.0000
76.7600 179.0000 1.0000
76.8200 197.0000 1.0000
76.8800 186.0000 1.0000
76.9400 188.0000 1.0000
77.0000 183.0000 1.0000
77.0600 187.0000 1.0000
77.1200 194.0000 1.0000
77.1800 200.0000 1.0000
77.2400 180.0000 1.0000
77.3000 176.0000 1.0000
77.3600 194.0000 1.0000
77.4200 169.0000 1.0000
77.4800 197.0000 1.0000
77.5400 187.0000 1.0000
77.6000 179.0000 1.0000
77.6600 180.0000 1.0000
77.7200 192.0000 1.0000
77.7800 185.0000 1.0000
77.8400 212.0000 1.0000
77.9000 175.0000 1.0000
77.9600 187.0000 1.0000
78.0200 170.0000 1.0000
78.0800 164.0000 1.0000
78.1400 194.0000 1.0000
78.2000 223.0000 1.0000
78.2600 185.0000 1.0000
78.3200 167.0000 1.0000
78.3800 170.0000 1.0000
78.4400 172.0000 1.0000
78.5000 184.0000 1.0000
78.5600 188.0000 1.0000
78.6200 194.0000 1.0000
78.6800 182.0000 1.0000
78.7400 197.0000 1.0000
78.8000 187.0000 1.0000
78.8600 222.0000 1.0000
78.9200 229.0000 1.0000
78.9800 261.0000 1.0000
79.0400 258.0000 1.0000
79.1000 234.0000 1.0000
79.1600 238.0000 1.0000
79.2200 272.0000 1.0000
79.2800 231.0000 1.0000
79.3400 221.0000 1.0000
79.4000 211.0000 1.0000
79.4600 190.0000 1.0000
79.5200 205.0000 1.0000
79.5800 196.0000 1.0000
79.6400 178.0000 1.0000
79.7000 159.0000 1.0000
79.7600 175.0000 1.0000
79.8200 203.0000 1.0000
79.8800 185.0000 1.0000
79.9400 159.0000 1.0000
80.0000 166.0000 1.0000
*RAS_INT_END
*RAS_TEMPERATURE_START
*RAS_TEMPERATURE_END
*RAS_DATA_END