File: Sectio1_28_samples/XRD/No_015_700_12_2.ras
*RAS_DATA_START
*RAS_HEADER_START
*DISP_FMT_X "%.2f"
*DISP_FMT_Y "%.0f"
*DISP_FULLSCALE "3746.0000000000"
*DISP_LINE_COLOR "255.0000000000"
*DISP_LINE_STYLE "0.0000000000"
*DISP_LINE_WIDTH "0.2500000000"
*DISP_NOTE "測定データ-6"
*DISP_OFFSET_Y "0.0000000000"
*DISP_PEAKSEARCH_UNIT_Y "cps"
*DISP_RANGE_BOTTOM "0.0000000000"
*DISP_RANGE_LEFT "20.0000000000"
*DISP_RANGE_LOGCUTOFF "0.0100000000"
*DISP_RANGE_RIGHT "80.0000000000"
*DISP_RANGE_TOP "3746.0000000000"
*DISP_SCALE_MODE_Y "0.0000000000"
*DISP_TAB_NAME "2θ/θ"
*DISP_TITLE_Y "強度"
*DISP_UNIT_Y "cps"
*DISP_WINDOW_NAME "MSG_MACROENGINE"
*FILE_COMMENT " "
*FILE_MD5 ""
*FILE_MEMO " "
*FILE_OPERATOR "Administrator"
*FILE_SAMPLE "hematite"
*FILE_TYPE "RAS_RAW"
*FILE_USERGROUP "システムマネージャ"
*FILE_VERSION "1.0000000000"
*HW_ATTACHMENT_ID "ATT0025"
*HW_ATTACHMENT_NAME "標準|Standard"
*HW_COUNTER_ID-0 "CUT0025"
*HW_COUNTER_ID-1 "CUT0020"
*HW_COUNTER_ID-2 "CUT0020"
*HW_COUNTER_ID-3 "CSL0021"
*HW_COUNTER_ID-4 "CMC0021"
*HW_COUNTER_NAME-0 "D/teX Ultra|D/teX Ultra"
*HW_COUNTER_NAME-1 "None|None"
*HW_COUNTER_NAME-2 "None|None"
*HW_COUNTER_NAME-3 "BBM|BBM"
*HW_COUNTER_NAME-4 "検出器モノクロメータ|Detector monochromator"
*HW_COUNTER_SELECT_NAME "D/teX Ultra|D/teX Ultra"
*HW_GONIOMETER_ID "GON0023"
*HW_GONIOMETER_NAME "SmartLab|SmartLab"
*HW_GONIOMETER_RADIUS-0 "90.0"
*HW_GONIOMETER_RADIUS-1 "114.0"
*HW_GONIOMETER_RADIUS-2 "190.0"
*HW_GONIOMETER_RADIUS-3 "300.0"
*HW_GONIOMETER_RADIUS-4 "187.0"
*HW_GONIOMETER_RADIUS-5 "300.0"
*HW_GONIOMETER_RADIUS-6 "113.0"
*HW_GONIOMETER_RADIUS-7 "331.0"
*HW_I_OPT_ID-0 "CBO0021"
*HW_I_OPT_ID-1 "ICR0023"
*HW_I_OPT_ID-2 "ISL0021"
*HW_I_OPT_ID-3 "ISO0021"
*HW_I_OPT_ID-4 "IAD0021"
*HW_I_OPT_ID-5 "IPR0001"
*HW_I_OPT_NAME-0 "CBOユニット|CBO unit"
*HW_I_OPT_NAME-1 "標準入射光学ユニット|Standard incident optical unit"
*HW_I_OPT_NAME-2 "標準入射スリットボックス|Standard incident slit box"
*HW_I_OPT_NAME-3 "入射平行スリット|Incident parallel slit"
*HW_I_OPT_NAME-4 "長手制限スリット|Length limiting slit"
*HW_I_OPT_NAME-5 "None|None"
*HW_R_ATTENUATER_AUTOMODE "0"
*HW_R_OPT_ID-0 "RSS0021"
*HW_R_OPT_ID-1 "RCR0023"
*HW_R_OPT_ID-2 "RSO0021"
*HW_R_OPT_ID-3 "RRS0021"
*HW_R_OPT_ID-4 "ATN0021"
*HW_R_OPT_ID-5 "RFL0021"
*HW_R_OPT_ID-6 "RAD0021"
*HW_R_OPT_NAME-0 "標準受光スリットボックス1|Standard receiving slit box # 1"
*HW_R_OPT_NAME-1 "標準受光光学ユニット1|Standard receiving unit # 1"
*HW_R_OPT_NAME-2 "標準受光光学ユニット2|Standard receiving optical unit # 2"
*HW_R_OPT_NAME-3 "標準受光スリットボックス2|Standard receiving slit box # 2"
*HW_R_OPT_NAME-4 "標準アッテネータ|Standard Attenuator"
*HW_R_OPT_NAME-5 "Cu Kβ|Cu K-beta"
*HW_R_OPT_NAME-6 "調整用受光スリット|Alignment receiving slit"
*HW_SAMPLE_HOLDER_ID "SMP0023"
*HW_SAMPLE_HOLDER_NAME "標準Zステージ|Standard Z stage"
*HW_XG_CURRENT_MAX "50"
*HW_XG_CURRENT_MIN "2"
*HW_XG_CURRENT_RESOLUTION "2"
*HW_XG_CURRENT_UNIT "mA"
*HW_XG_FOCUS "1mm x 10mm"
*HW_XG_FOCUS_TYPE "Normal"
*HW_XG_ID ""
*HW_XG_NAME "3kW 封入管(ID:1200)|3kW Sealed tube(ID:1200)"
*HW_XG_TARGET_ATOMIC_NUMBER "29.0000000000"
*HW_XG_TARGET_NAME "Cu"
*HW_XG_TYPE "Hermetic"
*HW_XG_VOLTAGE_MAX "60"
*HW_XG_VOLTAGE_MIN "20"
*HW_XG_VOLTAGE_RESOLUTION "2"
*HW_XG_VOLTAGE_UNIT "kV"
*HW_XG_WATT_MAX "2"
*HW_XG_WATT_UNIT "kW"
*HW_XG_WAVE_LENGTH_ALPHA1 "1.540593"
*HW_XG_WAVE_LENGTH_ALPHA2 "1.544414"
*HW_XG_WAVE_LENGTH_BETA "1.392250"
*MEAS_COND_AXIS_NAME-0 "2θ/θ"
*MEAS_COND_AXIS_NAME-1 "2θ"
*MEAS_COND_AXIS_NAME-2 "ω"
*MEAS_COND_AXIS_NAME-3 "Z"
*MEAS_COND_AXIS_NAME-4 "2θ/ω"
*MEAS_COND_AXIS_NAME-5 "θs"
*MEAS_COND_AXIS_NAME-6 "θd"
*MEAS_COND_AXIS_NAME-7 "Ts"
*MEAS_COND_AXIS_NAME-8 "CBO選択スリット"
*MEAS_COND_AXIS_NAME-9 "M"
*MEAS_COND_AXIS_NAME-10 "入射平行スリット"
*MEAS_COND_AXIS_NAME-11 "入射スリット"
*MEAS_COND_AXIS_NAME-12 ""
*MEAS_COND_AXIS_NAME-13 "Zs"
*MEAS_COND_AXIS_NAME-14 "入射光学素子"
*MEAS_COND_AXIS_NAME-15 "長手制限スリット"
*MEAS_COND_AXIS_NAME-16 "センタースリット"
*MEAS_COND_AXIS_NAME-17 "フィルター"
*MEAS_COND_AXIS_NAME-18 "受光スリット1"
*MEAS_COND_AXIS_NAME-19 "受光スリット2"
*MEAS_COND_AXIS_NAME-20 "受光光学素子"
*MEAS_COND_AXIS_NAME-21 "受光平行スリット"
*MEAS_COND_AXIS_NAME-22 "調整用受光スリット"
*MEAS_COND_AXIS_NAME-23 ""
*MEAS_COND_AXIS_NAME-24 ""
*MEAS_COND_AXIS_NAME-25 "Zd"
*MEAS_COND_AXIS_NAME-26 "アッテネータ"
*MEAS_COND_AXIS_NAME-27 "検出器モノクロメータ"
*MEAS_COND_AXIS_NAME-28 "モノクロメータスリット"
*MEAS_COND_AXIS_NAME-29 "プライマリビーム"
*MEAS_COND_AXIS_NAME-30 "PHA"
*MEAS_COND_AXIS_NAME_INTERNAL-0 "TwoThetaTheta"
*MEAS_COND_AXIS_NAME_INTERNAL-1 "TwoTheta"
*MEAS_COND_AXIS_NAME_INTERNAL-2 "Omega"
*MEAS_COND_AXIS_NAME_INTERNAL-3 "Z"
*MEAS_COND_AXIS_NAME_INTERNAL-4 "TwoThetaOmega"
*MEAS_COND_AXIS_NAME_INTERNAL-5 "ThetaS"
*MEAS_COND_AXIS_NAME_INTERNAL-6 "ThetaD"
*MEAS_COND_AXIS_NAME_INTERNAL-7 "Ts"
*MEAS_COND_AXIS_NAME_INTERNAL-8 "CBO"
*MEAS_COND_AXIS_NAME_INTERNAL-9 "CBO-M"
*MEAS_COND_AXIS_NAME_INTERNAL-10 "IncidentSollerSlit"
*MEAS_COND_AXIS_NAME_INTERNAL-11 "IncidentSlitBox"
*MEAS_COND_AXIS_NAME_INTERNAL-12 "IncidentSlitBox-_Axis"
*MEAS_COND_AXIS_NAME_INTERNAL-13 "Zs"
*MEAS_COND_AXIS_NAME_INTERNAL-14 "IncidentMonochromator"
*MEAS_COND_AXIS_NAME_INTERNAL-15 "IncidentAxdSlit"
*MEAS_COND_AXIS_NAME_INTERNAL-16 "CenterSlit"
*MEAS_COND_AXIS_NAME_INTERNAL-17 "Filter"
*MEAS_COND_AXIS_NAME_INTERNAL-18 "ReceivingSlitBox1"
*MEAS_COND_AXIS_NAME_INTERNAL-19 "ReceivingSlitBox2"
*MEAS_COND_AXIS_NAME_INTERNAL-20 "ReceivingOptics"
*MEAS_COND_AXIS_NAME_INTERNAL-21 "ReceivingSollerSlit"
*MEAS_COND_AXIS_NAME_INTERNAL-22 "ReceivingAxdSlit"
*MEAS_COND_AXIS_NAME_INTERNAL-23 "ReceivingSlitBox1-_Axis"
*MEAS_COND_AXIS_NAME_INTERNAL-24 "ReceivingSlitBox2-_Axis"
*MEAS_COND_AXIS_NAME_INTERNAL-25 "ReceivingSlitBox2-Zd"
*MEAS_COND_AXIS_NAME_INTERNAL-26 "Attenuator"
*MEAS_COND_AXIS_NAME_INTERNAL-27 "CounterMonochromator"
*MEAS_COND_AXIS_NAME_INTERNAL-28 "CounterSlit"
*MEAS_COND_AXIS_NAME_INTERNAL-29 "IncidentPrimary"
*MEAS_COND_AXIS_NAME_INTERNAL-30 "PHA"
*MEAS_COND_AXIS_NAME_MAGICNO-0 "83951616.0000000000"
*MEAS_COND_AXIS_NAME_MAGICNO-1 "268632064.0000000000"
*MEAS_COND_AXIS_NAME_MAGICNO-2 "268500992.0000000000"
*MEAS_COND_AXIS_NAME_MAGICNO-3 "285278208.0000000000"
*MEAS_COND_AXIS_NAME_MAGICNO-4 "83951616.0000000000"
*MEAS_COND_AXIS_NAME_MAGICNO-5 "131072.0000000000"
*MEAS_COND_AXIS_NAME_MAGICNO-6 "131072.0000000000"
*MEAS_COND_AXIS_NAME_MAGICNO-7 "318898176.0000000000"
*MEAS_COND_AXIS_NAME_MAGICNO-8 "20971521.0000000000"
*MEAS_COND_AXIS_NAME_MAGICNO-9 "285343744.0000000000"
*MEAS_COND_AXIS_NAME_MAGICNO-10 "20971521.0000000000"
*MEAS_COND_AXIS_NAME_MAGICNO-11 "22020097.0000000000"
*MEAS_COND_AXIS_NAME_MAGICNO-12 "25165824.0000000000"
*MEAS_COND_AXIS_NAME_MAGICNO-13 "318898176.0000000000"
*MEAS_COND_AXIS_NAME_MAGICNO-14 "1.0000000000"
*MEAS_COND_AXIS_NAME_MAGICNO-15 "20971521.0000000000"
*MEAS_COND_AXIS_NAME_MAGICNO-16 "20971521.0000000000"
*MEAS_COND_AXIS_NAME_MAGICNO-17 "20971521.0000000000"
*MEAS_COND_AXIS_NAME_MAGICNO-18 "23068673.0000000000"
*MEAS_COND_AXIS_NAME_MAGICNO-19 "23068673.0000000000"
*MEAS_COND_AXIS_NAME_MAGICNO-20 "20971521.0000000000"
*MEAS_COND_AXIS_NAME_MAGICNO-21 "20971521.0000000000"
*MEAS_COND_AXIS_NAME_MAGICNO-22 "20971521.0000000000"
*MEAS_COND_AXIS_NAME_MAGICNO-23 "25165824.0000000000"
*MEAS_COND_AXIS_NAME_MAGICNO-24 "25165824.0000000000"
*MEAS_COND_AXIS_NAME_MAGICNO-25 "285343744.0000000000"
*MEAS_COND_AXIS_NAME_MAGICNO-26 "17301505.0000000000"
*MEAS_COND_AXIS_NAME_MAGICNO-27 "20971521.0000000000"
*MEAS_COND_AXIS_NAME_MAGICNO-28 "20971521.0000000000"
*MEAS_COND_AXIS_NAME_MAGICNO-29 "20971521.0000000000"
*MEAS_COND_AXIS_NAME_MAGICNO-30 "0.0000000000"
*MEAS_COND_AXIS_OFFSET-0 "-"
*MEAS_COND_AXIS_OFFSET-1 "-0.1081000000"
*MEAS_COND_AXIS_OFFSET-2 "0.3758000000"
*MEAS_COND_AXIS_OFFSET-3 "-"
*MEAS_COND_AXIS_OFFSET-4 "-"
*MEAS_COND_AXIS_OFFSET-5 "0.3758000000"
*MEAS_COND_AXIS_OFFSET-6 "-0.4839000000"
*MEAS_COND_AXIS_OFFSET-7 "-"
*MEAS_COND_AXIS_OFFSET-8 "-"
*MEAS_COND_AXIS_OFFSET-9 "-"
*MEAS_COND_AXIS_OFFSET-10 "-"
*MEAS_COND_AXIS_OFFSET-11 "-"
*MEAS_COND_AXIS_OFFSET-12 "-"
*MEAS_COND_AXIS_OFFSET-13 "-"
*MEAS_COND_AXIS_OFFSET-14 "-"
*MEAS_COND_AXIS_OFFSET-15 "-"
*MEAS_COND_AXIS_OFFSET-16 "-"
*MEAS_COND_AXIS_OFFSET-17 "-"
*MEAS_COND_AXIS_OFFSET-18 "-"
*MEAS_COND_AXIS_OFFSET-19 "-"
*MEAS_COND_AXIS_OFFSET-20 "-"
*MEAS_COND_AXIS_OFFSET-21 "-"
*MEAS_COND_AXIS_OFFSET-22 "-"
*MEAS_COND_AXIS_OFFSET-23 "-"
*MEAS_COND_AXIS_OFFSET-24 "-"
*MEAS_COND_AXIS_OFFSET-25 "-"
*MEAS_COND_AXIS_OFFSET-26 "-"
*MEAS_COND_AXIS_OFFSET-27 "-"
*MEAS_COND_AXIS_OFFSET-28 "-"
*MEAS_COND_AXIS_OFFSET-29 "-"
*MEAS_COND_AXIS_OFFSET-30 "-"
*MEAS_COND_AXIS_POSITION-0 "0.0000000000"
*MEAS_COND_AXIS_POSITION-1 "0.0000000000"
*MEAS_COND_AXIS_POSITION-2 "0.0000000000"
*MEAS_COND_AXIS_POSITION-3 "-0.5500000000"
*MEAS_COND_AXIS_POSITION-4 "0.0000000000"
*MEAS_COND_AXIS_POSITION-5 "0.0000000000"
*MEAS_COND_AXIS_POSITION-6 "0.0000000000"
*MEAS_COND_AXIS_POSITION-7 "-0.4278800000"
*MEAS_COND_AXIS_POSITION-8 "BB"
*MEAS_COND_AXIS_POSITION-9 "0.0000000000"
*MEAS_COND_AXIS_POSITION-10 "Soller_slit_5.0deg"
*MEAS_COND_AXIS_POSITION-11 "2/3deg"
*MEAS_COND_AXIS_POSITION-12 "2.2088000000"
*MEAS_COND_AXIS_POSITION-13 "-0.4140600000"
*MEAS_COND_AXIS_POSITION-14 "0.0000000000"
*MEAS_COND_AXIS_POSITION-15 "10.0mm"
*MEAS_COND_AXIS_POSITION-16 "None"
*MEAS_COND_AXIS_POSITION-17 "Cu_K-beta"
*MEAS_COND_AXIS_POSITION-18 "13.000mm"
*MEAS_COND_AXIS_POSITION-19 "13.000mm"
*MEAS_COND_AXIS_POSITION-20 "No_unit"
*MEAS_COND_AXIS_POSITION-21 "Soller_slit_5.0deg"
*MEAS_COND_AXIS_POSITION-22 "None"
*MEAS_COND_AXIS_POSITION-23 "13.0000000000"
*MEAS_COND_AXIS_POSITION-24 "13.0000000000"
*MEAS_COND_AXIS_POSITION-25 "0.0109400000"
*MEAS_COND_AXIS_POSITION-26 "Open"
*MEAS_COND_AXIS_POSITION-27 "None"
*MEAS_COND_AXIS_POSITION-28 "None"
*MEAS_COND_AXIS_POSITION-29 "None"
*MEAS_COND_AXIS_POSITION-30 "38.0000000000"
*MEAS_COND_AXIS_UNIT-0 "deg"
*MEAS_COND_AXIS_UNIT-1 "deg"
*MEAS_COND_AXIS_UNIT-2 "deg"
*MEAS_COND_AXIS_UNIT-3 "mm"
*MEAS_COND_AXIS_UNIT-4 "deg"
*MEAS_COND_AXIS_UNIT-5 "deg"
*MEAS_COND_AXIS_UNIT-6 "deg"
*MEAS_COND_AXIS_UNIT-7 "mm"
*MEAS_COND_AXIS_UNIT-8 ""
*MEAS_COND_AXIS_UNIT-9 "pulse"
*MEAS_COND_AXIS_UNIT-10 ""
*MEAS_COND_AXIS_UNIT-11 ""
*MEAS_COND_AXIS_UNIT-12 "mm"
*MEAS_COND_AXIS_UNIT-13 "mm"
*MEAS_COND_AXIS_UNIT-14 ""
*MEAS_COND_AXIS_UNIT-15 ""
*MEAS_COND_AXIS_UNIT-16 ""
*MEAS_COND_AXIS_UNIT-17 ""
*MEAS_COND_AXIS_UNIT-18 ""
*MEAS_COND_AXIS_UNIT-19 ""
*MEAS_COND_AXIS_UNIT-20 ""
*MEAS_COND_AXIS_UNIT-21 ""
*MEAS_COND_AXIS_UNIT-22 ""
*MEAS_COND_AXIS_UNIT-23 "mm"
*MEAS_COND_AXIS_UNIT-24 "mm"
*MEAS_COND_AXIS_UNIT-25 "mm"
*MEAS_COND_AXIS_UNIT-26 ""
*MEAS_COND_AXIS_UNIT-27 ""
*MEAS_COND_AXIS_UNIT-28 ""
*MEAS_COND_AXIS_UNIT-29 ""
*MEAS_COND_AXIS_UNIT-30 "div"
*MEAS_COND_COUNTER_CNTLOSS_CORR "0.0000000000"
*MEAS_COND_COUNTER_PHABASE "38.0000000000"
*MEAS_COND_COUNTER_PHAWINDOW "16.0000000000"
*MEAS_COND_COUNTER_PHA_UNIT "div"
*MEAS_COND_COUNTER_TAUDIFF "30.0000000000"
*MEAS_COND_COUNTER_TAUINT "0.0000000000"
*MEAS_COND_IRRADIATION_MODE "OFF"
*MEAS_COND_IRRADIATION_WIDTH ""
*MEAS_COND_OPT_ATTR "集中法"
*MEAS_COND_OPT_NAME "@集中法"
*MEAS_COND_UNSYMMETRIC_MODE "OFF"
*MEAS_COND_XG_CURRENT "30.0000000000"
*MEAS_COND_XG_VOLTAGE "40.0000000000"
*MEAS_COND_XG_WAVE_TYPE "Ka"
*MEAS_DATA_COUNT "3001.0000000000"
*MEAS_SCAN_AXIS_X "2θ/θ"
*MEAS_SCAN_AXIS_X_INTERNAL "TwoThetaTheta"
*MEAS_SCAN_END_TIME "08/21/20 14:57:18"
*MEAS_SCAN_MODE "CONTINUOUS"
*MEAS_SCAN_MONITOR "0"
*MEAS_SCAN_RESOLUTION_X "0.0002"
*MEAS_SCAN_SPEED "2.0"
*MEAS_SCAN_SPEED_UNIT "deg/min"
*MEAS_SCAN_START "20.0000000000"
*MEAS_SCAN_START_TIME "08/21/20 14:25:38"
*MEAS_SCAN_STEP "0.0200000000"
*MEAS_SCAN_STOP "80.0000000000"
*MEAS_SCAN_UNIT_X "deg"
*MEAS_SCAN_UNIT_Y "counts"
*RAS_HEADER_END
*RAS_INT_START
20.0000 1853.0000 1.0000
20.0600 1836.0000 1.0000
20.1200 1830.0000 1.0000
20.1800 1778.0000 1.0000
20.2400 1806.0000 1.0000
20.3000 1768.0000 1.0000
20.3600 1820.0000 1.0000
20.4200 1756.0000 1.0000
20.4800 1713.0000 1.0000
20.5400 1757.0000 1.0000
20.6000 1699.0000 1.0000
20.6600 1722.0000 1.0000
20.7200 1799.0000 1.0000
20.7800 1664.0000 1.0000
20.8400 1664.0000 1.0000
20.9000 1648.0000 1.0000
20.9600 1714.0000 1.0000
21.0200 1739.0000 1.0000
21.0800 1665.0000 1.0000
21.1400 1616.0000 1.0000
21.2000 1613.0000 1.0000
21.2600 1620.0000 1.0000
21.3200 1653.0000 1.0000
21.3800 1626.0000 1.0000
21.4400 1616.0000 1.0000
21.5000 1617.0000 1.0000
21.5600 1675.0000 1.0000
21.6200 1580.0000 1.0000
21.6800 1547.0000 1.0000
21.7400 1459.0000 1.0000
21.8000 1599.0000 1.0000
21.8600 1576.0000 1.0000
21.9200 1540.0000 1.0000
21.9800 1594.0000 1.0000
22.0400 1517.0000 1.0000
22.1000 1434.0000 1.0000
22.1600 1558.0000 1.0000
22.2200 1541.0000 1.0000
22.2800 1514.0000 1.0000
22.3400 1532.0000 1.0000
22.4000 1493.0000 1.0000
22.4600 1466.0000 1.0000
22.5200 1476.0000 1.0000
22.5800 1387.0000 1.0000
22.6400 1433.0000 1.0000
22.7000 1406.0000 1.0000
22.7600 1396.0000 1.0000
22.8200 1449.0000 1.0000
22.8800 1415.0000 1.0000
22.9400 1420.0000 1.0000
23.0000 1472.0000 1.0000
23.0600 1441.0000 1.0000
23.1200 1397.0000 1.0000
23.1800 1385.0000 1.0000
23.2400 1403.0000 1.0000
23.3000 1388.0000 1.0000
23.3600 1417.0000 1.0000
23.4200 1323.0000 1.0000
23.4800 1351.0000 1.0000
23.5400 1331.0000 1.0000
23.6000 1286.0000 1.0000
23.6600 1319.0000 1.0000
23.7200 1295.0000 1.0000
23.7800 1305.0000 1.0000
23.8400 1293.0000 1.0000
23.9000 1344.0000 1.0000
23.9600 1307.0000 1.0000
24.0200 1294.0000 1.0000
24.0800 1360.0000 1.0000
24.1400 1272.0000 1.0000
24.2000 1266.0000 1.0000
24.2600 1217.0000 1.0000
24.3200 1228.0000 1.0000
24.3800 1278.0000 1.0000
24.4400 1197.0000 1.0000
24.5000 1238.0000 1.0000
24.5600 1291.0000 1.0000
24.6200 1240.0000 1.0000
24.6800 1223.0000 1.0000
24.7400 1222.0000 1.0000
24.8000 1164.0000 1.0000
24.8600 1244.0000 1.0000
24.9200 1195.0000 1.0000
24.9800 1234.0000 1.0000
25.0400 1230.0000 1.0000
25.1000 1137.0000 1.0000
25.1600 1157.0000 1.0000
25.2200 1179.0000 1.0000
25.2800 1168.0000 1.0000
25.3400 1186.0000 1.0000
25.4000 1175.0000 1.0000
25.4600 1126.0000 1.0000
25.5200 1122.0000 1.0000
25.5800 1132.0000 1.0000
25.6400 1158.0000 1.0000
25.7000 1137.0000 1.0000
25.7600 1150.0000 1.0000
25.8200 1143.0000 1.0000
25.8800 1159.0000 1.0000
25.9400 1112.0000 1.0000
26.0000 1102.0000 1.0000
26.0600 1157.0000 1.0000
26.1200 1116.0000 1.0000
26.1800 1114.0000 1.0000
26.2400 1113.0000 1.0000
26.3000 1022.0000 1.0000
26.3600 1103.0000 1.0000
26.4200 1069.0000 1.0000
26.4800 1128.0000 1.0000
26.5400 1082.0000 1.0000
26.6000 1109.0000 1.0000
26.6600 1092.0000 1.0000
26.7200 1068.0000 1.0000
26.7800 1092.0000 1.0000
26.8400 1101.0000 1.0000
26.9000 1080.0000 1.0000
26.9600 1049.0000 1.0000
27.0200 1045.0000 1.0000
27.0800 1139.0000 1.0000
27.1400 1047.0000 1.0000
27.2000 1149.0000 1.0000
27.2600 1196.0000 1.0000
27.3200 1343.0000 1.0000
27.3800 1229.0000 1.0000
27.4400 1132.0000 1.0000
27.5000 1055.0000 1.0000
27.5600 1007.0000 1.0000
27.6200 998.0000 1.0000
27.6800 983.0000 1.0000
27.7400 937.0000 1.0000
27.8000 983.0000 1.0000
27.8600 987.0000 1.0000
27.9200 977.0000 1.0000
27.9800 924.0000 1.0000
28.0400 980.0000 1.0000
28.1000 946.0000 1.0000
28.1600 965.0000 1.0000
28.2200 907.0000 1.0000
28.2800 956.0000 1.0000
28.3400 927.0000 1.0000
28.4000 908.0000 1.0000
28.4600 906.0000 1.0000
28.5200 893.0000 1.0000
28.5800 941.0000 1.0000
28.6400 888.0000 1.0000
28.7000 842.0000 1.0000
28.7600 868.0000 1.0000
28.8200 890.0000 1.0000
28.8800 850.0000 1.0000
28.9400 869.0000 1.0000
29.0000 833.0000 1.0000
29.0600 841.0000 1.0000
29.1200 897.0000 1.0000
29.1800 859.0000 1.0000
29.2400 872.0000 1.0000
29.3000 879.0000 1.0000
29.3600 903.0000 1.0000
29.4200 859.0000 1.0000
29.4800 808.0000 1.0000
29.5400 819.0000 1.0000
29.6000 803.0000 1.0000
29.6600 791.0000 1.0000
29.7200 851.0000 1.0000
29.7800 825.0000 1.0000
29.8400 836.0000 1.0000
29.9000 818.0000 1.0000
29.9600 811.0000 1.0000
30.0200 818.0000 1.0000
30.0800 768.0000 1.0000
30.1400 797.0000 1.0000
30.2000 818.0000 1.0000
30.2600 780.0000 1.0000
30.3200 811.0000 1.0000
30.3800 837.0000 1.0000
30.4400 745.0000 1.0000
30.5000 789.0000 1.0000
30.5600 758.0000 1.0000
30.6200 796.0000 1.0000
30.6800 759.0000 1.0000
30.7400 771.0000 1.0000
30.8000 711.0000 1.0000
30.8600 744.0000 1.0000
30.9200 798.0000 1.0000
30.9800 775.0000 1.0000
31.0400 736.0000 1.0000
31.1000 721.0000 1.0000
31.1600 695.0000 1.0000
31.2200 751.0000 1.0000
31.2800 724.0000 1.0000
31.3400 667.0000 1.0000
31.4000 697.0000 1.0000
31.4600 765.0000 1.0000
31.5200 716.0000 1.0000
31.5800 758.0000 1.0000
31.6400 679.0000 1.0000
31.7000 678.0000 1.0000
31.7600 705.0000 1.0000
31.8200 772.0000 1.0000
31.8800 681.0000 1.0000
31.9400 709.0000 1.0000
32.0000 691.0000 1.0000
32.0600 674.0000 1.0000
32.1200 674.0000 1.0000
32.1800 696.0000 1.0000
32.2400 673.0000 1.0000
32.3000 698.0000 1.0000
32.3600 715.0000 1.0000
32.4200 667.0000 1.0000
32.4800 686.0000 1.0000
32.5400 698.0000 1.0000
32.6000 700.0000 1.0000
32.6600 688.0000 1.0000
32.7200 663.0000 1.0000
32.7800 634.0000 1.0000
32.8400 630.0000 1.0000
32.9000 648.0000 1.0000
32.9600 603.0000 1.0000
33.0200 652.0000 1.0000
33.0800 653.0000 1.0000
33.1400 634.0000 1.0000
33.2000 626.0000 1.0000
33.2600 692.0000 1.0000
33.3200 636.0000 1.0000
33.3800 637.0000 1.0000
33.4400 645.0000 1.0000
33.5000 610.0000 1.0000
33.5600 598.0000 1.0000
33.6200 620.0000 1.0000
33.6800 603.0000 1.0000
33.7400 577.0000 1.0000
33.8000 627.0000 1.0000
33.8600 596.0000 1.0000
33.9200 599.0000 1.0000
33.9800 619.0000 1.0000
34.0400 652.0000 1.0000
34.1000 555.0000 1.0000
34.1600 621.0000 1.0000
34.2200 620.0000 1.0000
34.2800 615.0000 1.0000
34.3400 645.0000 1.0000
34.4000 699.0000 1.0000
34.4600 727.0000 1.0000
34.5200 743.0000 1.0000
34.5800 730.0000 1.0000
34.6400 675.0000 1.0000
34.7000 665.0000 1.0000
34.7600 651.0000 1.0000
34.8200 598.0000 1.0000
34.8800 566.0000 1.0000
34.9400 554.0000 1.0000
35.0000 556.0000 1.0000
35.0600 558.0000 1.0000
35.1200 538.0000 1.0000
35.1800 586.0000 1.0000
35.2400 558.0000 1.0000
35.3000 601.0000 1.0000
35.3600 517.0000 1.0000
35.4200 538.0000 1.0000
35.4800 542.0000 1.0000
35.5400 549.0000 1.0000
35.6000 551.0000 1.0000
35.6600 554.0000 1.0000
35.7200 504.0000 1.0000
35.7800 514.0000 1.0000
35.8400 507.0000 1.0000
35.9000 520.0000 1.0000
35.9600 469.0000 1.0000
36.0200 493.0000 1.0000
36.0800 500.0000 1.0000
36.1400 504.0000 1.0000
36.2000 552.0000 1.0000
36.2600 529.0000 1.0000
36.3200 486.0000 1.0000
36.3800 549.0000 1.0000
36.4400 547.0000 1.0000
36.5000 541.0000 1.0000
36.5600 560.0000 1.0000
36.6200 509.0000 1.0000
36.6800 507.0000 1.0000
36.7400 497.0000 1.0000
36.8000 490.0000 1.0000
36.8600 484.0000 1.0000
36.9200 495.0000 1.0000
36.9800 459.0000 1.0000
37.0400 500.0000 1.0000
37.1000 513.0000 1.0000
37.1600 472.0000 1.0000
37.2200 491.0000 1.0000
37.2800 484.0000 1.0000
37.3400 503.0000 1.0000
37.4000 484.0000 1.0000
37.4600 459.0000 1.0000
37.5200 495.0000 1.0000
37.5800 497.0000 1.0000
37.6400 473.0000 1.0000
37.7000 475.0000 1.0000
37.7600 479.0000 1.0000
37.8200 486.0000 1.0000
37.8800 478.0000 1.0000
37.9400 441.0000 1.0000
38.0000 445.0000 1.0000
38.0600 487.0000 1.0000
38.1200 434.0000 1.0000
38.1800 453.0000 1.0000
38.2400 468.0000 1.0000
38.3000 515.0000 1.0000
38.3600 527.0000 1.0000
38.4200 668.0000 1.0000
38.4800 748.0000 1.0000
38.5400 899.0000 1.0000
38.6000 909.0000 1.0000
38.6600 792.0000 1.0000
38.7200 647.0000 1.0000
38.7800 536.0000 1.0000
38.8400 526.0000 1.0000
38.9000 469.0000 1.0000
38.9600 484.0000 1.0000
39.0200 429.0000 1.0000
39.0800 451.0000 1.0000
39.1400 420.0000 1.0000
39.2000 394.0000 1.0000
39.2600 418.0000 1.0000
39.3200 414.0000 1.0000
39.3800 448.0000 1.0000
39.4400 405.0000 1.0000
39.5000 412.0000 1.0000
39.5600 408.0000 1.0000
39.6200 386.0000 1.0000
39.6800 398.0000 1.0000
39.7400 405.0000 1.0000
39.8000 403.0000 1.0000
39.8600 392.0000 1.0000
39.9200 412.0000 1.0000
39.9800 378.0000 1.0000
40.0400 419.0000 1.0000
40.1000 382.0000 1.0000
40.1600 414.0000 1.0000
40.2200 360.0000 1.0000
40.2800 375.0000 1.0000
40.3400 389.0000 1.0000
40.4000 380.0000 1.0000
40.4600 394.0000 1.0000
40.5200 391.0000 1.0000
40.5800 404.0000 1.0000
40.6400 357.0000 1.0000
40.7000 366.0000 1.0000
40.7600 380.0000 1.0000
40.8200 396.0000 1.0000
40.8800 375.0000 1.0000
40.9400 353.0000 1.0000
41.0000 372.0000 1.0000
41.0600 348.0000 1.0000
41.1200 351.0000 1.0000
41.1800 383.0000 1.0000
41.2400 372.0000 1.0000
41.3000 365.0000 1.0000
41.3600 330.0000 1.0000
41.4200 346.0000 1.0000
41.4800 357.0000 1.0000
41.5400 359.0000 1.0000
41.6000 378.0000 1.0000
41.6600 339.0000 1.0000
41.7200 381.0000 1.0000
41.7800 365.0000 1.0000
41.8400 340.0000 1.0000
41.9000 359.0000 1.0000
41.9600 343.0000 1.0000
42.0200 332.0000 1.0000
42.0800 323.0000 1.0000
42.1400 356.0000 1.0000
42.2000 357.0000 1.0000
42.2600 371.0000 1.0000
42.3200 338.0000 1.0000
42.3800 375.0000 1.0000
42.4400 338.0000 1.0000
42.5000 347.0000 1.0000
42.5600 342.0000 1.0000
42.6200 355.0000 1.0000
42.6800 325.0000 1.0000
42.7400 323.0000 1.0000
42.8000 312.0000 1.0000
42.8600 339.0000 1.0000
42.9200 355.0000 1.0000
42.9800 346.0000 1.0000
43.0400 352.0000 1.0000
43.1000 325.0000 1.0000
43.1600 371.0000 1.0000
43.2200 331.0000 1.0000
43.2800 342.0000 1.0000
43.3400 321.0000 1.0000
43.4000 342.0000 1.0000
43.4600 303.0000 1.0000
43.5200 306.0000 1.0000
43.5800 294.0000 1.0000
43.6400 323.0000 1.0000
43.7000 324.0000 1.0000
43.7600 326.0000 1.0000
43.8200 324.0000 1.0000
43.8800 299.0000 1.0000
43.9400 311.0000 1.0000
44.0000 309.0000 1.0000
44.0600 335.0000 1.0000
44.1200 319.0000 1.0000
44.1800 292.0000 1.0000
44.2400 316.0000 1.0000
44.3000 290.0000 1.0000
44.3600 346.0000 1.0000
44.4200 358.0000 1.0000
44.4800 300.0000 1.0000
44.5400 323.0000 1.0000
44.6000 309.0000 1.0000
44.6600 298.0000 1.0000
44.7200 307.0000 1.0000
44.7800 275.0000 1.0000
44.8400 316.0000 1.0000
44.9000 288.0000 1.0000
44.9600 307.0000 1.0000
45.0200 300.0000 1.0000
45.0800 269.0000 1.0000
45.1400 336.0000 1.0000
45.2000 296.0000 1.0000
45.2600 290.0000 1.0000
45.3200 309.0000 1.0000
45.3800 290.0000 1.0000
45.4400 296.0000 1.0000
45.5000 305.0000 1.0000
45.5600 267.0000 1.0000
45.6200 303.0000 1.0000
45.6800 295.0000 1.0000
45.7400 272.0000 1.0000
45.8000 317.0000 1.0000
45.8600 279.0000 1.0000
45.9200 309.0000 1.0000
45.9800 289.0000 1.0000
46.0400 295.0000 1.0000
46.1000 270.0000 1.0000
46.1600 272.0000 1.0000
46.2200 309.0000 1.0000
46.2800 260.0000 1.0000
46.3400 278.0000 1.0000
46.4000 299.0000 1.0000
46.4600 287.0000 1.0000
46.5200 265.0000 1.0000
46.5800 256.0000 1.0000
46.6400 282.0000 1.0000
46.7000 295.0000 1.0000
46.7600 305.0000 1.0000
46.8200 265.0000 1.0000
46.8800 292.0000 1.0000
46.9400 307.0000 1.0000
47.0000 286.0000 1.0000
47.0600 277.0000 1.0000
47.1200 278.0000 1.0000
47.1800 308.0000 1.0000
47.2400 280.0000 1.0000
47.3000 250.0000 1.0000
47.3600 265.0000 1.0000
47.4200 273.0000 1.0000
47.4800 266.0000 1.0000
47.5400 264.0000 1.0000
47.6000 262.0000 1.0000
47.6600 262.0000 1.0000
47.7200 239.0000 1.0000
47.7800 250.0000 1.0000
47.8400 255.0000 1.0000
47.9000 296.0000 1.0000
47.9600 257.0000 1.0000
48.0200 277.0000 1.0000
48.0800 281.0000 1.0000
48.1400 249.0000 1.0000
48.2000 248.0000 1.0000
48.2600 273.0000 1.0000
48.3200 252.0000 1.0000
48.3800 264.0000 1.0000
48.4400 290.0000 1.0000
48.5000 262.0000 1.0000
48.5600 309.0000 1.0000
48.6200 258.0000 1.0000
48.6800 264.0000 1.0000
48.7400 292.0000 1.0000
48.8000 233.0000 1.0000
48.8600 245.0000 1.0000
48.9200 254.0000 1.0000
48.9800 239.0000 1.0000
49.0400 237.0000 1.0000
49.1000 268.0000 1.0000
49.1600 257.0000 1.0000
49.2200 234.0000 1.0000
49.2800 235.0000 1.0000
49.3400 262.0000 1.0000
49.4000 263.0000 1.0000
49.4600 234.0000 1.0000
49.5200 274.0000 1.0000
49.5800 260.0000 1.0000
49.6400 249.0000 1.0000
49.7000 239.0000 1.0000
49.7600 236.0000 1.0000
49.8200 282.0000 1.0000
49.8800 239.0000 1.0000
49.9400 249.0000 1.0000
50.0000 245.0000 1.0000
50.0600 227.0000 1.0000
50.1200 263.0000 1.0000
50.1800 241.0000 1.0000
50.2400 228.0000 1.0000
50.3000 251.0000 1.0000
50.3600 253.0000 1.0000
50.4200 256.0000 1.0000
50.4800 236.0000 1.0000
50.5400 253.0000 1.0000
50.6000 226.0000 1.0000
50.6600 229.0000 1.0000
50.7200 269.0000 1.0000
50.7800 257.0000 1.0000
50.8400 255.0000 1.0000
50.9000 269.0000 1.0000
50.9600 263.0000 1.0000
51.0200 253.0000 1.0000
51.0800 265.0000 1.0000
51.1400 231.0000 1.0000
51.2000 273.0000 1.0000
51.2600 240.0000 1.0000
51.3200 267.0000 1.0000
51.3800 256.0000 1.0000
51.4400 253.0000 1.0000
51.5000 241.0000 1.0000
51.5600 243.0000 1.0000
51.6200 254.0000 1.0000
51.6800 251.0000 1.0000
51.7400 250.0000 1.0000
51.8000 274.0000 1.0000
51.8600 281.0000 1.0000
51.9200 265.0000 1.0000
51.9800 285.0000 1.0000
52.0400 312.0000 1.0000
52.1000 366.0000 1.0000
52.1600 481.0000 1.0000
52.2200 789.0000 1.0000
52.2800 1027.0000 1.0000
52.3400 913.0000 1.0000
52.4000 807.0000 1.0000
52.4600 735.0000 1.0000
52.5200 460.0000 1.0000
52.5800 437.0000 1.0000
52.6400 359.0000 1.0000
52.7000 250.0000 1.0000
52.7600 303.0000 1.0000
52.8200 256.0000 1.0000
52.8800 250.0000 1.0000
52.9400 260.0000 1.0000
53.0000 234.0000 1.0000
53.0600 250.0000 1.0000
53.1200 223.0000 1.0000
53.1800 259.0000 1.0000
53.2400 250.0000 1.0000
53.3000 240.0000 1.0000
53.3600 238.0000 1.0000
53.4200 221.0000 1.0000
53.4800 243.0000 1.0000
53.5400 237.0000 1.0000
53.6000 229.0000 1.0000
53.6600 227.0000 1.0000
53.7200 233.0000 1.0000
53.7800 212.0000 1.0000
53.8400 240.0000 1.0000
53.9000 214.0000 1.0000
53.9600 234.0000 1.0000
54.0200 229.0000 1.0000
54.0800 235.0000 1.0000
54.1400 240.0000 1.0000
54.2000 223.0000 1.0000
54.2600 253.0000 1.0000
54.3200 247.0000 1.0000
54.3800 220.0000 1.0000
54.4400 241.0000 1.0000
54.5000 209.0000 1.0000
54.5600 248.0000 1.0000
54.6200 232.0000 1.0000
54.6800 216.0000 1.0000
54.7400 234.0000 1.0000
54.8000 209.0000 1.0000
54.8600 239.0000 1.0000
54.9200 232.0000 1.0000
54.9800 261.0000 1.0000
55.0400 239.0000 1.0000
55.1000 241.0000 1.0000
55.1600 271.0000 1.0000
55.2200 285.0000 1.0000
55.2800 313.0000 1.0000
55.3400 298.0000 1.0000
55.4000 325.0000 1.0000
55.4600 281.0000 1.0000
55.5200 256.0000 1.0000
55.5800 252.0000 1.0000
55.6400 249.0000 1.0000
55.7000 243.0000 1.0000
55.7600 230.0000 1.0000
55.8200 227.0000 1.0000
55.8800 221.0000 1.0000
55.9400 204.0000 1.0000
56.0000 216.0000 1.0000
56.0600 223.0000 1.0000
56.1200 222.0000 1.0000
56.1800 237.0000 1.0000
56.2400 225.0000 1.0000
56.3000 232.0000 1.0000
56.3600 221.0000 1.0000
56.4200 206.0000 1.0000
56.4800 225.0000 1.0000
56.5400 217.0000 1.0000
56.6000 216.0000 1.0000
56.6600 210.0000 1.0000
56.7200 234.0000 1.0000
56.7800 217.0000 1.0000
56.8400 191.0000 1.0000
56.9000 204.0000 1.0000
56.9600 224.0000 1.0000
57.0200 207.0000 1.0000
57.0800 230.0000 1.0000
57.1400 217.0000 1.0000
57.2000 209.0000 1.0000
57.2600 231.0000 1.0000
57.3200 255.0000 1.0000
57.3800 188.0000 1.0000
57.4400 211.0000 1.0000
57.5000 195.0000 1.0000
57.5600 221.0000 1.0000
57.6200 220.0000 1.0000
57.6800 218.0000 1.0000
57.7400 205.0000 1.0000
57.8000 198.0000 1.0000
57.8600 195.0000 1.0000
57.9200 191.0000 1.0000
57.9800 186.0000 1.0000
58.0400 236.0000 1.0000
58.1000 200.0000 1.0000
58.1600 217.0000 1.0000
58.2200 231.0000 1.0000
58.2800 223.0000 1.0000
58.3400 213.0000 1.0000
58.4000 244.0000 1.0000
58.4600 204.0000 1.0000
58.5200 234.0000 1.0000
58.5800 210.0000 1.0000
58.6400 224.0000 1.0000
58.7000 195.0000 1.0000
58.7600 230.0000 1.0000
58.8200 197.0000 1.0000
58.8800 214.0000 1.0000
58.9400 197.0000 1.0000
59.0000 231.0000 1.0000
59.0600 206.0000 1.0000
59.1200 214.0000 1.0000
59.1800 232.0000 1.0000
59.2400 225.0000 1.0000
59.3000 209.0000 1.0000
59.3600 226.0000 1.0000
59.4200 216.0000 1.0000
59.4800 215.0000 1.0000
59.5400 220.0000 1.0000
59.6000 220.0000 1.0000
59.6600 221.0000 1.0000
59.7200 208.0000 1.0000
59.7800 214.0000 1.0000
59.8400 187.0000 1.0000
59.9000 205.0000 1.0000
59.9600 222.0000 1.0000
60.0200 224.0000 1.0000
60.0800 216.0000 1.0000
60.1400 195.0000 1.0000
60.2000 217.0000 1.0000
60.2600 226.0000 1.0000
60.3200 216.0000 1.0000
60.3800 195.0000 1.0000
60.4400 210.0000 1.0000
60.5000 216.0000 1.0000
60.5600 219.0000 1.0000
60.6200 199.0000 1.0000
60.6800 208.0000 1.0000
60.7400 205.0000 1.0000
60.8000 226.0000 1.0000
60.8600 209.0000 1.0000
60.9200 205.0000 1.0000
60.9800 218.0000 1.0000
61.0400 211.0000 1.0000
61.1000 237.0000 1.0000
61.1600 222.0000 1.0000
61.2200 211.0000 1.0000
61.2800 222.0000 1.0000
61.3400 219.0000 1.0000
61.4000 207.0000 1.0000
61.4600 224.0000 1.0000
61.5200 235.0000 1.0000
61.5800 203.0000 1.0000
61.6400 213.0000 1.0000
61.7000 213.0000 1.0000
61.7600 227.0000 1.0000
61.8200 228.0000 1.0000
61.8800 220.0000 1.0000
61.9400 230.0000 1.0000
62.0000 267.0000 1.0000
62.0600 272.0000 1.0000
62.1200 292.0000 1.0000
62.1800 317.0000 1.0000
62.2400 348.0000 1.0000
62.3000 379.0000 1.0000
62.3600 389.0000 1.0000
62.4200 391.0000 1.0000
62.4800 342.0000 1.0000
62.5400 365.0000 1.0000
62.6000 301.0000 1.0000
62.6600 266.0000 1.0000
62.7200 257.0000 1.0000
62.7800 236.0000 1.0000
62.8400 242.0000 1.0000
62.9000 238.0000 1.0000
62.9600 230.0000 1.0000
63.0200 217.0000 1.0000
63.0800 207.0000 1.0000
63.1400 210.0000 1.0000
63.2000 245.0000 1.0000
63.2600 236.0000 1.0000
63.3200 217.0000 1.0000
63.3800 201.0000 1.0000
63.4400 199.0000 1.0000
63.5000 208.0000 1.0000
63.5600 225.0000 1.0000
63.6200 214.0000 1.0000
63.6800 225.0000 1.0000
63.7400 200.0000 1.0000
63.8000 194.0000 1.0000
63.8600 212.0000 1.0000
63.9200 223.0000 1.0000
63.9800 214.0000 1.0000
64.0400 237.0000 1.0000
64.1000 219.0000 1.0000
64.1600 205.0000 1.0000
64.2200 228.0000 1.0000
64.2800 201.0000 1.0000
64.3400 220.0000 1.0000
64.4000 222.0000 1.0000
64.4600 213.0000 1.0000
64.5200 205.0000 1.0000
64.5800 242.0000 1.0000
64.6400 256.0000 1.0000
64.7000 239.0000 1.0000
64.7600 269.0000 1.0000
64.8200 262.0000 1.0000
64.8800 241.0000 1.0000
64.9400 230.0000 1.0000
65.0000 245.0000 1.0000
65.0600 236.0000 1.0000
65.1200 229.0000 1.0000
65.1800 241.0000 1.0000
65.2400 242.0000 1.0000
65.3000 230.0000 1.0000
65.3600 248.0000 1.0000
65.4200 210.0000 1.0000
65.4800 240.0000 1.0000
65.5400 242.0000 1.0000
65.6000 212.0000 1.0000
65.6600 218.0000 1.0000
65.7200 225.0000 1.0000
65.7800 247.0000 1.0000
65.8400 236.0000 1.0000
65.9000 245.0000 1.0000
65.9600 232.0000 1.0000
66.0200 291.0000 1.0000
66.0800 332.0000 1.0000
66.1400 430.0000 1.0000
66.2000 490.0000 1.0000
66.2600 650.0000 1.0000
66.3200 633.0000 1.0000
66.3800 543.0000 1.0000
66.4400 540.0000 1.0000
66.5000 479.0000 1.0000
66.5600 408.0000 1.0000
66.6200 349.0000 1.0000
66.6800 311.0000 1.0000
66.7400 262.0000 1.0000
66.8000 250.0000 1.0000
66.8600 240.0000 1.0000
66.9200 225.0000 1.0000
66.9800 242.0000 1.0000
67.0400 208.0000 1.0000
67.1000 222.0000 1.0000
67.1600 223.0000 1.0000
67.2200 212.0000 1.0000
67.2800 200.0000 1.0000
67.3400 191.0000 1.0000
67.4000 212.0000 1.0000
67.4600 209.0000 1.0000
67.5200 204.0000 1.0000
67.5800 200.0000 1.0000
67.6400 211.0000 1.0000
67.7000 216.0000 1.0000
67.7600 204.0000 1.0000
67.8200 206.0000 1.0000
67.8800 209.0000 1.0000
67.9400 207.0000 1.0000
68.0000 178.0000 1.0000
68.0600 198.0000 1.0000
68.1200 193.0000 1.0000
68.1800 187.0000 1.0000
68.2400 179.0000 1.0000
68.3000 194.0000 1.0000
68.3600 208.0000 1.0000
68.4200 198.0000 1.0000
68.4800 211.0000 1.0000
68.5400 211.0000 1.0000
68.6000 214.0000 1.0000
68.6600 199.0000 1.0000
68.7200 170.0000 1.0000
68.7800 200.0000 1.0000
68.8400 206.0000 1.0000
68.9000 209.0000 1.0000
68.9600 224.0000 1.0000
69.0200 211.0000 1.0000
69.0800 223.0000 1.0000
69.1400 204.0000 1.0000
69.2000 212.0000 1.0000
69.2600 201.0000 1.0000
69.3200 191.0000 1.0000
69.3800 203.0000 1.0000
69.4400 197.0000 1.0000
69.5000 183.0000 1.0000
69.5600 217.0000 1.0000
69.6200 209.0000 1.0000
69.6800 213.0000 1.0000
69.7400 198.0000 1.0000
69.8000 198.0000 1.0000
69.8600 202.0000 1.0000
69.9200 201.0000 1.0000
69.9800 212.0000 1.0000
70.0400 191.0000 1.0000
70.1000 187.0000 1.0000
70.1600 212.0000 1.0000
70.2200 224.0000 1.0000
70.2800 189.0000 1.0000
70.3400 181.0000 1.0000
70.4000 191.0000 1.0000
70.4600 205.0000 1.0000
70.5200 185.0000 1.0000
70.5800 212.0000 1.0000
70.6400 194.0000 1.0000
70.7000 207.0000 1.0000
70.7600 211.0000 1.0000
70.8200 201.0000 1.0000
70.8800 178.0000 1.0000
70.9400 175.0000 1.0000
71.0000 218.0000 1.0000
71.0600 188.0000 1.0000
71.1200 201.0000 1.0000
71.1800 207.0000 1.0000
71.2400 201.0000 1.0000
71.3000 219.0000 1.0000
71.3600 191.0000 1.0000
71.4200 209.0000 1.0000
71.4800 197.0000 1.0000
71.5400 206.0000 1.0000
71.6000 215.0000 1.0000
71.6600 205.0000 1.0000
71.7200 184.0000 1.0000
71.7800 216.0000 1.0000
71.8400 192.0000 1.0000
71.9000 216.0000 1.0000
71.9600 190.0000 1.0000
72.0200 209.0000 1.0000
72.0800 209.0000 1.0000
72.1400 210.0000 1.0000
72.2000 224.0000 1.0000
72.2600 187.0000 1.0000
72.3200 193.0000 1.0000
72.3800 188.0000 1.0000
72.4400 199.0000 1.0000
72.5000 190.0000 1.0000
72.5600 171.0000 1.0000
72.6200 168.0000 1.0000
72.6800 178.0000 1.0000
72.7400 214.0000 1.0000
72.8000 182.0000 1.0000
72.8600 196.0000 1.0000
72.9200 190.0000 1.0000
72.9800 218.0000 1.0000
73.0400 184.0000 1.0000
73.1000 184.0000 1.0000
73.1600 202.0000 1.0000
73.2200 194.0000 1.0000
73.2800 184.0000 1.0000
73.3400 173.0000 1.0000
73.4000 183.0000 1.0000
73.4600 186.0000 1.0000
73.5200 169.0000 1.0000
73.5800 179.0000 1.0000
73.6400 185.0000 1.0000
73.7000 198.0000 1.0000
73.7600 193.0000 1.0000
73.8200 168.0000 1.0000
73.8800 203.0000 1.0000
73.9400 178.0000 1.0000
74.0000 181.0000 1.0000
74.0600 185.0000 1.0000
74.1200 200.0000 1.0000
74.1800 197.0000 1.0000
74.2400 188.0000 1.0000
74.3000 186.0000 1.0000
74.3600 197.0000 1.0000
74.4200 190.0000 1.0000
74.4800 185.0000 1.0000
74.5400 190.0000 1.0000
74.6000 171.0000 1.0000
74.6600 203.0000 1.0000
74.7200 205.0000 1.0000
74.7800 216.0000 1.0000
74.8400 185.0000 1.0000
74.9000 192.0000 1.0000
74.9600 185.0000 1.0000
75.0200 179.0000 1.0000
75.0800 209.0000 1.0000
75.1400 186.0000 1.0000
75.2000 215.0000 1.0000
75.2600 188.0000 1.0000
75.3200 182.0000 1.0000
75.3800 172.0000 1.0000
75.4400 189.0000 1.0000
75.5000 191.0000 1.0000
75.5600 180.0000 1.0000
75.6200 182.0000 1.0000
75.6800 176.0000 1.0000
75.7400 194.0000 1.0000
75.8000 178.0000 1.0000
75.8600 191.0000 1.0000
75.9200 194.0000 1.0000
75.9800 173.0000 1.0000
76.0400 201.0000 1.0000
76.1000 186.0000 1.0000
76.1600 183.0000 1.0000
76.2200 187.0000 1.0000
76.2800 203.0000 1.0000
76.3400 196.0000 1.0000
76.4000 154.0000 1.0000
76.4600 187.0000 1.0000
76.5200 191.0000 1.0000
76.5800 187.0000 1.0000
76.6400 177.0000 1.0000
76.7000 179.0000 1.0000
76.7600 172.0000 1.0000
76.8200 178.0000 1.0000
76.8800 201.0000 1.0000
76.9400 196.0000 1.0000
77.0000 184.0000 1.0000
77.0600 205.0000 1.0000
77.1200 182.0000 1.0000
77.1800 175.0000 1.0000
77.2400 186.0000 1.0000
77.3000 167.0000 1.0000
77.3600 205.0000 1.0000
77.4200 171.0000 1.0000
77.4800 191.0000 1.0000
77.5400 196.0000 1.0000
77.6000 188.0000 1.0000
77.6600 176.0000 1.0000
77.7200 171.0000 1.0000
77.7800 193.0000 1.0000
77.8400 219.0000 1.0000
77.9000 201.0000 1.0000
77.9600 216.0000 1.0000
78.0200 174.0000 1.0000
78.0800 184.0000 1.0000
78.1400 177.0000 1.0000
78.2000 180.0000 1.0000
78.2600 182.0000 1.0000
78.3200 201.0000 1.0000
78.3800 182.0000 1.0000
78.4400 211.0000 1.0000
78.5000 183.0000 1.0000
78.5600 179.0000 1.0000
78.6200 194.0000 1.0000
78.6800 189.0000 1.0000
78.7400 206.0000 1.0000
78.8000 223.0000 1.0000
78.8600 250.0000 1.0000
78.9200 255.0000 1.0000
78.9800 290.0000 1.0000
79.0400 294.0000 1.0000
79.1000 283.0000 1.0000
79.1600 257.0000 1.0000
79.2200 267.0000 1.0000
79.2800 237.0000 1.0000
79.3400 238.0000 1.0000
79.4000 221.0000 1.0000
79.4600 214.0000 1.0000
79.5200 203.0000 1.0000
79.5800 191.0000 1.0000
79.6400 201.0000 1.0000
79.7000 197.0000 1.0000
79.7600 193.0000 1.0000
79.8200 193.0000 1.0000
79.8800 171.0000 1.0000
79.9400 183.0000 1.0000
80.0000 174.0000 1.0000
*RAS_INT_END
*RAS_TEMPERATURE_START
*RAS_TEMPERATURE_END
*RAS_DATA_END