File: Sectio1_28_samples/XRD/No_022_750_12_2.ras
*RAS_DATA_START
*RAS_HEADER_START
*DISP_FMT_X "%.2f"
*DISP_FMT_Y "%.0f"
*DISP_FULLSCALE "3640.0000000000"
*DISP_LINE_COLOR "255.0000000000"
*DISP_LINE_STYLE "0.0000000000"
*DISP_LINE_WIDTH "0.2500000000"
*DISP_NOTE "測定データ-5"
*DISP_OFFSET_Y "0.0000000000"
*DISP_PEAKSEARCH_UNIT_Y "cps"
*DISP_RANGE_BOTTOM "0.0000000000"
*DISP_RANGE_LEFT "20.0000000000"
*DISP_RANGE_LOGCUTOFF "0.0100000000"
*DISP_RANGE_RIGHT "80.0000000000"
*DISP_RANGE_TOP "3640.0000000000"
*DISP_SCALE_MODE_Y "0.0000000000"
*DISP_TAB_NAME "2θ/θ"
*DISP_TITLE_Y "強度"
*DISP_UNIT_Y "cps"
*DISP_WINDOW_NAME "MSG_MACROENGINE"
*FILE_COMMENT " "
*FILE_MD5 ""
*FILE_MEMO " "
*FILE_OPERATOR "Administrator"
*FILE_SAMPLE "hematite"
*FILE_TYPE "RAS_RAW"
*FILE_USERGROUP "システムマネージャ"
*FILE_VERSION "1.0000000000"
*HW_ATTACHMENT_ID "ATT0025"
*HW_ATTACHMENT_NAME "標準|Standard"
*HW_COUNTER_ID-0 "CUT0025"
*HW_COUNTER_ID-1 "CUT0020"
*HW_COUNTER_ID-2 "CUT0020"
*HW_COUNTER_ID-3 "CSL0021"
*HW_COUNTER_ID-4 "CMC0021"
*HW_COUNTER_NAME-0 "D/teX Ultra|D/teX Ultra"
*HW_COUNTER_NAME-1 "None|None"
*HW_COUNTER_NAME-2 "None|None"
*HW_COUNTER_NAME-3 "BBM|BBM"
*HW_COUNTER_NAME-4 "検出器モノクロメータ|Detector monochromator"
*HW_COUNTER_SELECT_NAME "D/teX Ultra|D/teX Ultra"
*HW_GONIOMETER_ID "GON0023"
*HW_GONIOMETER_NAME "SmartLab|SmartLab"
*HW_GONIOMETER_RADIUS-0 "90.0"
*HW_GONIOMETER_RADIUS-1 "114.0"
*HW_GONIOMETER_RADIUS-2 "190.0"
*HW_GONIOMETER_RADIUS-3 "300.0"
*HW_GONIOMETER_RADIUS-4 "187.0"
*HW_GONIOMETER_RADIUS-5 "300.0"
*HW_GONIOMETER_RADIUS-6 "113.0"
*HW_GONIOMETER_RADIUS-7 "331.0"
*HW_I_OPT_ID-0 "CBO0021"
*HW_I_OPT_ID-1 "ICR0023"
*HW_I_OPT_ID-2 "ISL0021"
*HW_I_OPT_ID-3 "ISO0021"
*HW_I_OPT_ID-4 "IAD0021"
*HW_I_OPT_ID-5 "IPR0001"
*HW_I_OPT_NAME-0 "CBOユニット|CBO unit"
*HW_I_OPT_NAME-1 "標準入射光学ユニット|Standard incident optical unit"
*HW_I_OPT_NAME-2 "標準入射スリットボックス|Standard incident slit box"
*HW_I_OPT_NAME-3 "入射平行スリット|Incident parallel slit"
*HW_I_OPT_NAME-4 "長手制限スリット|Length limiting slit"
*HW_I_OPT_NAME-5 "None|None"
*HW_R_ATTENUATER_AUTOMODE "0"
*HW_R_OPT_ID-0 "RSS0021"
*HW_R_OPT_ID-1 "RCR0023"
*HW_R_OPT_ID-2 "RSO0021"
*HW_R_OPT_ID-3 "RRS0021"
*HW_R_OPT_ID-4 "ATN0021"
*HW_R_OPT_ID-5 "RFL0021"
*HW_R_OPT_ID-6 "RAD0021"
*HW_R_OPT_NAME-0 "標準受光スリットボックス1|Standard receiving slit box # 1"
*HW_R_OPT_NAME-1 "標準受光光学ユニット1|Standard receiving unit # 1"
*HW_R_OPT_NAME-2 "標準受光光学ユニット2|Standard receiving optical unit # 2"
*HW_R_OPT_NAME-3 "標準受光スリットボックス2|Standard receiving slit box # 2"
*HW_R_OPT_NAME-4 "標準アッテネータ|Standard Attenuator"
*HW_R_OPT_NAME-5 "Cu Kβ|Cu K-beta"
*HW_R_OPT_NAME-6 "調整用受光スリット|Alignment receiving slit"
*HW_SAMPLE_HOLDER_ID "SMP0023"
*HW_SAMPLE_HOLDER_NAME "標準Zステージ|Standard Z stage"
*HW_XG_CURRENT_MAX "50"
*HW_XG_CURRENT_MIN "2"
*HW_XG_CURRENT_RESOLUTION "2"
*HW_XG_CURRENT_UNIT "mA"
*HW_XG_FOCUS "1mm x 10mm"
*HW_XG_FOCUS_TYPE "Normal"
*HW_XG_ID ""
*HW_XG_NAME "3kW 封入管(ID:1200)|3kW Sealed tube(ID:1200)"
*HW_XG_TARGET_ATOMIC_NUMBER "29.0000000000"
*HW_XG_TARGET_NAME "Cu"
*HW_XG_TYPE "Hermetic"
*HW_XG_VOLTAGE_MAX "60"
*HW_XG_VOLTAGE_MIN "20"
*HW_XG_VOLTAGE_RESOLUTION "2"
*HW_XG_VOLTAGE_UNIT "kV"
*HW_XG_WATT_MAX "2"
*HW_XG_WATT_UNIT "kW"
*HW_XG_WAVE_LENGTH_ALPHA1 "1.540593"
*HW_XG_WAVE_LENGTH_ALPHA2 "1.544414"
*HW_XG_WAVE_LENGTH_BETA "1.392250"
*MEAS_COND_AXIS_NAME-0 "2θ/θ"
*MEAS_COND_AXIS_NAME-1 "2θ"
*MEAS_COND_AXIS_NAME-2 "ω"
*MEAS_COND_AXIS_NAME-3 "Z"
*MEAS_COND_AXIS_NAME-4 "2θ/ω"
*MEAS_COND_AXIS_NAME-5 "θs"
*MEAS_COND_AXIS_NAME-6 "θd"
*MEAS_COND_AXIS_NAME-7 "Ts"
*MEAS_COND_AXIS_NAME-8 "CBO選択スリット"
*MEAS_COND_AXIS_NAME-9 "M"
*MEAS_COND_AXIS_NAME-10 "入射平行スリット"
*MEAS_COND_AXIS_NAME-11 "入射スリット"
*MEAS_COND_AXIS_NAME-12 ""
*MEAS_COND_AXIS_NAME-13 "Zs"
*MEAS_COND_AXIS_NAME-14 "入射光学素子"
*MEAS_COND_AXIS_NAME-15 "長手制限スリット"
*MEAS_COND_AXIS_NAME-16 "センタースリット"
*MEAS_COND_AXIS_NAME-17 "フィルター"
*MEAS_COND_AXIS_NAME-18 "受光スリット1"
*MEAS_COND_AXIS_NAME-19 "受光スリット2"
*MEAS_COND_AXIS_NAME-20 "受光光学素子"
*MEAS_COND_AXIS_NAME-21 "受光平行スリット"
*MEAS_COND_AXIS_NAME-22 "調整用受光スリット"
*MEAS_COND_AXIS_NAME-23 ""
*MEAS_COND_AXIS_NAME-24 ""
*MEAS_COND_AXIS_NAME-25 "Zd"
*MEAS_COND_AXIS_NAME-26 "アッテネータ"
*MEAS_COND_AXIS_NAME-27 "検出器モノクロメータ"
*MEAS_COND_AXIS_NAME-28 "モノクロメータスリット"
*MEAS_COND_AXIS_NAME-29 "プライマリビーム"
*MEAS_COND_AXIS_NAME-30 "PHA"
*MEAS_COND_AXIS_NAME_INTERNAL-0 "TwoThetaTheta"
*MEAS_COND_AXIS_NAME_INTERNAL-1 "TwoTheta"
*MEAS_COND_AXIS_NAME_INTERNAL-2 "Omega"
*MEAS_COND_AXIS_NAME_INTERNAL-3 "Z"
*MEAS_COND_AXIS_NAME_INTERNAL-4 "TwoThetaOmega"
*MEAS_COND_AXIS_NAME_INTERNAL-5 "ThetaS"
*MEAS_COND_AXIS_NAME_INTERNAL-6 "ThetaD"
*MEAS_COND_AXIS_NAME_INTERNAL-7 "Ts"
*MEAS_COND_AXIS_NAME_INTERNAL-8 "CBO"
*MEAS_COND_AXIS_NAME_INTERNAL-9 "CBO-M"
*MEAS_COND_AXIS_NAME_INTERNAL-10 "IncidentSollerSlit"
*MEAS_COND_AXIS_NAME_INTERNAL-11 "IncidentSlitBox"
*MEAS_COND_AXIS_NAME_INTERNAL-12 "IncidentSlitBox-_Axis"
*MEAS_COND_AXIS_NAME_INTERNAL-13 "Zs"
*MEAS_COND_AXIS_NAME_INTERNAL-14 "IncidentMonochromator"
*MEAS_COND_AXIS_NAME_INTERNAL-15 "IncidentAxdSlit"
*MEAS_COND_AXIS_NAME_INTERNAL-16 "CenterSlit"
*MEAS_COND_AXIS_NAME_INTERNAL-17 "Filter"
*MEAS_COND_AXIS_NAME_INTERNAL-18 "ReceivingSlitBox1"
*MEAS_COND_AXIS_NAME_INTERNAL-19 "ReceivingSlitBox2"
*MEAS_COND_AXIS_NAME_INTERNAL-20 "ReceivingOptics"
*MEAS_COND_AXIS_NAME_INTERNAL-21 "ReceivingSollerSlit"
*MEAS_COND_AXIS_NAME_INTERNAL-22 "ReceivingAxdSlit"
*MEAS_COND_AXIS_NAME_INTERNAL-23 "ReceivingSlitBox1-_Axis"
*MEAS_COND_AXIS_NAME_INTERNAL-24 "ReceivingSlitBox2-_Axis"
*MEAS_COND_AXIS_NAME_INTERNAL-25 "ReceivingSlitBox2-Zd"
*MEAS_COND_AXIS_NAME_INTERNAL-26 "Attenuator"
*MEAS_COND_AXIS_NAME_INTERNAL-27 "CounterMonochromator"
*MEAS_COND_AXIS_NAME_INTERNAL-28 "CounterSlit"
*MEAS_COND_AXIS_NAME_INTERNAL-29 "IncidentPrimary"
*MEAS_COND_AXIS_NAME_INTERNAL-30 "PHA"
*MEAS_COND_AXIS_NAME_MAGICNO-0 "83951616.0000000000"
*MEAS_COND_AXIS_NAME_MAGICNO-1 "268632064.0000000000"
*MEAS_COND_AXIS_NAME_MAGICNO-2 "268500992.0000000000"
*MEAS_COND_AXIS_NAME_MAGICNO-3 "285278208.0000000000"
*MEAS_COND_AXIS_NAME_MAGICNO-4 "83951616.0000000000"
*MEAS_COND_AXIS_NAME_MAGICNO-5 "131072.0000000000"
*MEAS_COND_AXIS_NAME_MAGICNO-6 "131072.0000000000"
*MEAS_COND_AXIS_NAME_MAGICNO-7 "318898176.0000000000"
*MEAS_COND_AXIS_NAME_MAGICNO-8 "20971521.0000000000"
*MEAS_COND_AXIS_NAME_MAGICNO-9 "285343744.0000000000"
*MEAS_COND_AXIS_NAME_MAGICNO-10 "20971521.0000000000"
*MEAS_COND_AXIS_NAME_MAGICNO-11 "22020097.0000000000"
*MEAS_COND_AXIS_NAME_MAGICNO-12 "25165824.0000000000"
*MEAS_COND_AXIS_NAME_MAGICNO-13 "318898176.0000000000"
*MEAS_COND_AXIS_NAME_MAGICNO-14 "1.0000000000"
*MEAS_COND_AXIS_NAME_MAGICNO-15 "20971521.0000000000"
*MEAS_COND_AXIS_NAME_MAGICNO-16 "20971521.0000000000"
*MEAS_COND_AXIS_NAME_MAGICNO-17 "20971521.0000000000"
*MEAS_COND_AXIS_NAME_MAGICNO-18 "23068673.0000000000"
*MEAS_COND_AXIS_NAME_MAGICNO-19 "23068673.0000000000"
*MEAS_COND_AXIS_NAME_MAGICNO-20 "20971521.0000000000"
*MEAS_COND_AXIS_NAME_MAGICNO-21 "20971521.0000000000"
*MEAS_COND_AXIS_NAME_MAGICNO-22 "20971521.0000000000"
*MEAS_COND_AXIS_NAME_MAGICNO-23 "25165824.0000000000"
*MEAS_COND_AXIS_NAME_MAGICNO-24 "25165824.0000000000"
*MEAS_COND_AXIS_NAME_MAGICNO-25 "285343744.0000000000"
*MEAS_COND_AXIS_NAME_MAGICNO-26 "17301505.0000000000"
*MEAS_COND_AXIS_NAME_MAGICNO-27 "20971521.0000000000"
*MEAS_COND_AXIS_NAME_MAGICNO-28 "20971521.0000000000"
*MEAS_COND_AXIS_NAME_MAGICNO-29 "20971521.0000000000"
*MEAS_COND_AXIS_NAME_MAGICNO-30 "0.0000000000"
*MEAS_COND_AXIS_OFFSET-0 "-"
*MEAS_COND_AXIS_OFFSET-1 "-0.1081000000"
*MEAS_COND_AXIS_OFFSET-2 "0.3758000000"
*MEAS_COND_AXIS_OFFSET-3 "-"
*MEAS_COND_AXIS_OFFSET-4 "-"
*MEAS_COND_AXIS_OFFSET-5 "0.3758000000"
*MEAS_COND_AXIS_OFFSET-6 "-0.4839000000"
*MEAS_COND_AXIS_OFFSET-7 "-"
*MEAS_COND_AXIS_OFFSET-8 "-"
*MEAS_COND_AXIS_OFFSET-9 "-"
*MEAS_COND_AXIS_OFFSET-10 "-"
*MEAS_COND_AXIS_OFFSET-11 "-"
*MEAS_COND_AXIS_OFFSET-12 "-"
*MEAS_COND_AXIS_OFFSET-13 "-"
*MEAS_COND_AXIS_OFFSET-14 "-"
*MEAS_COND_AXIS_OFFSET-15 "-"
*MEAS_COND_AXIS_OFFSET-16 "-"
*MEAS_COND_AXIS_OFFSET-17 "-"
*MEAS_COND_AXIS_OFFSET-18 "-"
*MEAS_COND_AXIS_OFFSET-19 "-"
*MEAS_COND_AXIS_OFFSET-20 "-"
*MEAS_COND_AXIS_OFFSET-21 "-"
*MEAS_COND_AXIS_OFFSET-22 "-"
*MEAS_COND_AXIS_OFFSET-23 "-"
*MEAS_COND_AXIS_OFFSET-24 "-"
*MEAS_COND_AXIS_OFFSET-25 "-"
*MEAS_COND_AXIS_OFFSET-26 "-"
*MEAS_COND_AXIS_OFFSET-27 "-"
*MEAS_COND_AXIS_OFFSET-28 "-"
*MEAS_COND_AXIS_OFFSET-29 "-"
*MEAS_COND_AXIS_OFFSET-30 "-"
*MEAS_COND_AXIS_POSITION-0 "0.0000000000"
*MEAS_COND_AXIS_POSITION-1 "0.0000000000"
*MEAS_COND_AXIS_POSITION-2 "0.0000000000"
*MEAS_COND_AXIS_POSITION-3 "-0.5500000000"
*MEAS_COND_AXIS_POSITION-4 "0.0000000000"
*MEAS_COND_AXIS_POSITION-5 "0.0000000000"
*MEAS_COND_AXIS_POSITION-6 "0.0000000000"
*MEAS_COND_AXIS_POSITION-7 "-0.4278800000"
*MEAS_COND_AXIS_POSITION-8 "BB"
*MEAS_COND_AXIS_POSITION-9 "0.0000000000"
*MEAS_COND_AXIS_POSITION-10 "Soller_slit_5.0deg"
*MEAS_COND_AXIS_POSITION-11 "2/3deg"
*MEAS_COND_AXIS_POSITION-12 "2.2088000000"
*MEAS_COND_AXIS_POSITION-13 "-0.4140600000"
*MEAS_COND_AXIS_POSITION-14 "0.0000000000"
*MEAS_COND_AXIS_POSITION-15 "10.0mm"
*MEAS_COND_AXIS_POSITION-16 "None"
*MEAS_COND_AXIS_POSITION-17 "Cu_K-beta"
*MEAS_COND_AXIS_POSITION-18 "13.000mm"
*MEAS_COND_AXIS_POSITION-19 "13.000mm"
*MEAS_COND_AXIS_POSITION-20 "No_unit"
*MEAS_COND_AXIS_POSITION-21 "Soller_slit_5.0deg"
*MEAS_COND_AXIS_POSITION-22 "None"
*MEAS_COND_AXIS_POSITION-23 "13.0000000000"
*MEAS_COND_AXIS_POSITION-24 "13.0000000000"
*MEAS_COND_AXIS_POSITION-25 "0.0109400000"
*MEAS_COND_AXIS_POSITION-26 "Open"
*MEAS_COND_AXIS_POSITION-27 "None"
*MEAS_COND_AXIS_POSITION-28 "None"
*MEAS_COND_AXIS_POSITION-29 "None"
*MEAS_COND_AXIS_POSITION-30 "38.0000000000"
*MEAS_COND_AXIS_UNIT-0 "deg"
*MEAS_COND_AXIS_UNIT-1 "deg"
*MEAS_COND_AXIS_UNIT-2 "deg"
*MEAS_COND_AXIS_UNIT-3 "mm"
*MEAS_COND_AXIS_UNIT-4 "deg"
*MEAS_COND_AXIS_UNIT-5 "deg"
*MEAS_COND_AXIS_UNIT-6 "deg"
*MEAS_COND_AXIS_UNIT-7 "mm"
*MEAS_COND_AXIS_UNIT-8 ""
*MEAS_COND_AXIS_UNIT-9 "pulse"
*MEAS_COND_AXIS_UNIT-10 ""
*MEAS_COND_AXIS_UNIT-11 ""
*MEAS_COND_AXIS_UNIT-12 "mm"
*MEAS_COND_AXIS_UNIT-13 "mm"
*MEAS_COND_AXIS_UNIT-14 ""
*MEAS_COND_AXIS_UNIT-15 ""
*MEAS_COND_AXIS_UNIT-16 ""
*MEAS_COND_AXIS_UNIT-17 ""
*MEAS_COND_AXIS_UNIT-18 ""
*MEAS_COND_AXIS_UNIT-19 ""
*MEAS_COND_AXIS_UNIT-20 ""
*MEAS_COND_AXIS_UNIT-21 ""
*MEAS_COND_AXIS_UNIT-22 ""
*MEAS_COND_AXIS_UNIT-23 "mm"
*MEAS_COND_AXIS_UNIT-24 "mm"
*MEAS_COND_AXIS_UNIT-25 "mm"
*MEAS_COND_AXIS_UNIT-26 ""
*MEAS_COND_AXIS_UNIT-27 ""
*MEAS_COND_AXIS_UNIT-28 ""
*MEAS_COND_AXIS_UNIT-29 ""
*MEAS_COND_AXIS_UNIT-30 "div"
*MEAS_COND_COUNTER_CNTLOSS_CORR "0.0000000000"
*MEAS_COND_COUNTER_PHABASE "38.0000000000"
*MEAS_COND_COUNTER_PHAWINDOW "16.0000000000"
*MEAS_COND_COUNTER_PHA_UNIT "div"
*MEAS_COND_COUNTER_TAUDIFF "30.0000000000"
*MEAS_COND_COUNTER_TAUINT "0.0000000000"
*MEAS_COND_IRRADIATION_MODE "OFF"
*MEAS_COND_IRRADIATION_WIDTH ""
*MEAS_COND_OPT_ATTR "集中法"
*MEAS_COND_OPT_NAME "@集中法"
*MEAS_COND_UNSYMMETRIC_MODE "OFF"
*MEAS_COND_XG_CURRENT "30.0000000000"
*MEAS_COND_XG_VOLTAGE "40.0000000000"
*MEAS_COND_XG_WAVE_TYPE "Ka"
*MEAS_DATA_COUNT "3001.0000000000"
*MEAS_SCAN_AXIS_X "2θ/θ"
*MEAS_SCAN_AXIS_X_INTERNAL "TwoThetaTheta"
*MEAS_SCAN_END_TIME "08/21/20 14:15:49"
*MEAS_SCAN_MODE "CONTINUOUS"
*MEAS_SCAN_MONITOR "0"
*MEAS_SCAN_RESOLUTION_X "0.0002"
*MEAS_SCAN_SPEED "2.0"
*MEAS_SCAN_SPEED_UNIT "deg/min"
*MEAS_SCAN_START "20.0000000000"
*MEAS_SCAN_START_TIME "08/21/20 13:44:09"
*MEAS_SCAN_STEP "0.0200000000"
*MEAS_SCAN_STOP "80.0000000000"
*MEAS_SCAN_UNIT_X "deg"
*MEAS_SCAN_UNIT_Y "counts"
*RAS_HEADER_END
*RAS_INT_START
20.0000 1725.0000 1.0000
20.0600 1764.0000 1.0000
20.1200 1729.0000 1.0000
20.1800 1814.0000 1.0000
20.2400 1750.0000 1.0000
20.3000 1766.0000 1.0000
20.3600 1792.0000 1.0000
20.4200 1705.0000 1.0000
20.4800 1749.0000 1.0000
20.5400 1656.0000 1.0000
20.6000 1705.0000 1.0000
20.6600 1717.0000 1.0000
20.7200 1696.0000 1.0000
20.7800 1715.0000 1.0000
20.8400 1660.0000 1.0000
20.9000 1605.0000 1.0000
20.9600 1590.0000 1.0000
21.0200 1591.0000 1.0000
21.0800 1623.0000 1.0000
21.1400 1490.0000 1.0000
21.2000 1554.0000 1.0000
21.2600 1593.0000 1.0000
21.3200 1601.0000 1.0000
21.3800 1530.0000 1.0000
21.4400 1585.0000 1.0000
21.5000 1561.0000 1.0000
21.5600 1528.0000 1.0000
21.6200 1506.0000 1.0000
21.6800 1487.0000 1.0000
21.7400 1589.0000 1.0000
21.8000 1572.0000 1.0000
21.8600 1474.0000 1.0000
21.9200 1469.0000 1.0000
21.9800 1509.0000 1.0000
22.0400 1463.0000 1.0000
22.1000 1477.0000 1.0000
22.1600 1486.0000 1.0000
22.2200 1457.0000 1.0000
22.2800 1544.0000 1.0000
22.3400 1458.0000 1.0000
22.4000 1429.0000 1.0000
22.4600 1383.0000 1.0000
22.5200 1419.0000 1.0000
22.5800 1373.0000 1.0000
22.6400 1357.0000 1.0000
22.7000 1473.0000 1.0000
22.7600 1419.0000 1.0000
22.8200 1350.0000 1.0000
22.8800 1466.0000 1.0000
22.9400 1429.0000 1.0000
23.0000 1403.0000 1.0000
23.0600 1354.0000 1.0000
23.1200 1351.0000 1.0000
23.1800 1335.0000 1.0000
23.2400 1300.0000 1.0000
23.3000 1312.0000 1.0000
23.3600 1352.0000 1.0000
23.4200 1326.0000 1.0000
23.4800 1265.0000 1.0000
23.5400 1287.0000 1.0000
23.6000 1300.0000 1.0000
23.6600 1256.0000 1.0000
23.7200 1299.0000 1.0000
23.7800 1324.0000 1.0000
23.8400 1273.0000 1.0000
23.9000 1294.0000 1.0000
23.9600 1266.0000 1.0000
24.0200 1300.0000 1.0000
24.0800 1247.0000 1.0000
24.1400 1253.0000 1.0000
24.2000 1270.0000 1.0000
24.2600 1205.0000 1.0000
24.3200 1185.0000 1.0000
24.3800 1196.0000 1.0000
24.4400 1287.0000 1.0000
24.5000 1161.0000 1.0000
24.5600 1238.0000 1.0000
24.6200 1161.0000 1.0000
24.6800 1138.0000 1.0000
24.7400 1154.0000 1.0000
24.8000 1236.0000 1.0000
24.8600 1156.0000 1.0000
24.9200 1193.0000 1.0000
24.9800 1172.0000 1.0000
25.0400 1165.0000 1.0000
25.1000 1128.0000 1.0000
25.1600 1149.0000 1.0000
25.2200 1102.0000 1.0000
25.2800 1088.0000 1.0000
25.3400 1199.0000 1.0000
25.4000 1128.0000 1.0000
25.4600 1081.0000 1.0000
25.5200 1198.0000 1.0000
25.5800 1125.0000 1.0000
25.6400 1075.0000 1.0000
25.7000 1102.0000 1.0000
25.7600 1089.0000 1.0000
25.8200 1067.0000 1.0000
25.8800 1054.0000 1.0000
25.9400 1039.0000 1.0000
26.0000 1100.0000 1.0000
26.0600 1056.0000 1.0000
26.1200 1002.0000 1.0000
26.1800 1011.0000 1.0000
26.2400 1032.0000 1.0000
26.3000 1046.0000 1.0000
26.3600 1023.0000 1.0000
26.4200 1076.0000 1.0000
26.4800 1047.0000 1.0000
26.5400 993.0000 1.0000
26.6000 977.0000 1.0000
26.6600 1010.0000 1.0000
26.7200 968.0000 1.0000
26.7800 1012.0000 1.0000
26.8400 999.0000 1.0000
26.9000 975.0000 1.0000
26.9600 989.0000 1.0000
27.0200 973.0000 1.0000
27.0800 1013.0000 1.0000
27.1400 986.0000 1.0000
27.2000 1047.0000 1.0000
27.2600 1112.0000 1.0000
27.3200 1166.0000 1.0000
27.3800 1074.0000 1.0000
27.4400 1065.0000 1.0000
27.5000 985.0000 1.0000
27.5600 959.0000 1.0000
27.6200 944.0000 1.0000
27.6800 974.0000 1.0000
27.7400 899.0000 1.0000
27.8000 906.0000 1.0000
27.8600 888.0000 1.0000
27.9200 884.0000 1.0000
27.9800 911.0000 1.0000
28.0400 914.0000 1.0000
28.1000 861.0000 1.0000
28.1600 864.0000 1.0000
28.2200 885.0000 1.0000
28.2800 913.0000 1.0000
28.3400 859.0000 1.0000
28.4000 863.0000 1.0000
28.4600 857.0000 1.0000
28.5200 891.0000 1.0000
28.5800 859.0000 1.0000
28.6400 844.0000 1.0000
28.7000 827.0000 1.0000
28.7600 812.0000 1.0000
28.8200 800.0000 1.0000
28.8800 821.0000 1.0000
28.9400 833.0000 1.0000
29.0000 809.0000 1.0000
29.0600 865.0000 1.0000
29.1200 825.0000 1.0000
29.1800 791.0000 1.0000
29.2400 782.0000 1.0000
29.3000 813.0000 1.0000
29.3600 816.0000 1.0000
29.4200 770.0000 1.0000
29.4800 840.0000 1.0000
29.5400 844.0000 1.0000
29.6000 827.0000 1.0000
29.6600 748.0000 1.0000
29.7200 794.0000 1.0000
29.7800 738.0000 1.0000
29.8400 794.0000 1.0000
29.9000 753.0000 1.0000
29.9600 728.0000 1.0000
30.0200 799.0000 1.0000
30.0800 756.0000 1.0000
30.1400 745.0000 1.0000
30.2000 759.0000 1.0000
30.2600 736.0000 1.0000
30.3200 724.0000 1.0000
30.3800 764.0000 1.0000
30.4400 748.0000 1.0000
30.5000 731.0000 1.0000
30.5600 710.0000 1.0000
30.6200 736.0000 1.0000
30.6800 710.0000 1.0000
30.7400 714.0000 1.0000
30.8000 710.0000 1.0000
30.8600 705.0000 1.0000
30.9200 675.0000 1.0000
30.9800 687.0000 1.0000
31.0400 699.0000 1.0000
31.1000 671.0000 1.0000
31.1600 743.0000 1.0000
31.2200 694.0000 1.0000
31.2800 744.0000 1.0000
31.3400 675.0000 1.0000
31.4000 677.0000 1.0000
31.4600 705.0000 1.0000
31.5200 713.0000 1.0000
31.5800 681.0000 1.0000
31.6400 655.0000 1.0000
31.7000 671.0000 1.0000
31.7600 626.0000 1.0000
31.8200 651.0000 1.0000
31.8800 700.0000 1.0000
31.9400 636.0000 1.0000
32.0000 681.0000 1.0000
32.0600 611.0000 1.0000
32.1200 661.0000 1.0000
32.1800 641.0000 1.0000
32.2400 593.0000 1.0000
32.3000 655.0000 1.0000
32.3600 670.0000 1.0000
32.4200 611.0000 1.0000
32.4800 625.0000 1.0000
32.5400 644.0000 1.0000
32.6000 626.0000 1.0000
32.6600 603.0000 1.0000
32.7200 584.0000 1.0000
32.7800 607.0000 1.0000
32.8400 592.0000 1.0000
32.9000 660.0000 1.0000
32.9600 621.0000 1.0000
33.0200 593.0000 1.0000
33.0800 619.0000 1.0000
33.1400 574.0000 1.0000
33.2000 584.0000 1.0000
33.2600 613.0000 1.0000
33.3200 612.0000 1.0000
33.3800 610.0000 1.0000
33.4400 597.0000 1.0000
33.5000 612.0000 1.0000
33.5600 622.0000 1.0000
33.6200 603.0000 1.0000
33.6800 542.0000 1.0000
33.7400 585.0000 1.0000
33.8000 566.0000 1.0000
33.8600 557.0000 1.0000
33.9200 600.0000 1.0000
33.9800 562.0000 1.0000
34.0400 586.0000 1.0000
34.1000 596.0000 1.0000
34.1600 603.0000 1.0000
34.2200 547.0000 1.0000
34.2800 577.0000 1.0000
34.3400 559.0000 1.0000
34.4000 610.0000 1.0000
34.4600 662.0000 1.0000
34.5200 697.0000 1.0000
34.5800 684.0000 1.0000
34.6400 635.0000 1.0000
34.7000 623.0000 1.0000
34.7600 547.0000 1.0000
34.8200 572.0000 1.0000
34.8800 526.0000 1.0000
34.9400 533.0000 1.0000
35.0000 495.0000 1.0000
35.0600 487.0000 1.0000
35.1200 532.0000 1.0000
35.1800 540.0000 1.0000
35.2400 536.0000 1.0000
35.3000 477.0000 1.0000
35.3600 525.0000 1.0000
35.4200 491.0000 1.0000
35.4800 515.0000 1.0000
35.5400 516.0000 1.0000
35.6000 522.0000 1.0000
35.6600 529.0000 1.0000
35.7200 517.0000 1.0000
35.7800 442.0000 1.0000
35.8400 486.0000 1.0000
35.9000 496.0000 1.0000
35.9600 523.0000 1.0000
36.0200 464.0000 1.0000
36.0800 512.0000 1.0000
36.1400 518.0000 1.0000
36.2000 500.0000 1.0000
36.2600 484.0000 1.0000
36.3200 498.0000 1.0000
36.3800 490.0000 1.0000
36.4400 514.0000 1.0000
36.5000 523.0000 1.0000
36.5600 481.0000 1.0000
36.6200 483.0000 1.0000
36.6800 468.0000 1.0000
36.7400 485.0000 1.0000
36.8000 455.0000 1.0000
36.8600 477.0000 1.0000
36.9200 453.0000 1.0000
36.9800 456.0000 1.0000
37.0400 447.0000 1.0000
37.1000 458.0000 1.0000
37.1600 444.0000 1.0000
37.2200 437.0000 1.0000
37.2800 463.0000 1.0000
37.3400 433.0000 1.0000
37.4000 411.0000 1.0000
37.4600 439.0000 1.0000
37.5200 441.0000 1.0000
37.5800 438.0000 1.0000
37.6400 438.0000 1.0000
37.7000 440.0000 1.0000
37.7600 395.0000 1.0000
37.8200 430.0000 1.0000
37.8800 453.0000 1.0000
37.9400 400.0000 1.0000
38.0000 418.0000 1.0000
38.0600 442.0000 1.0000
38.1200 390.0000 1.0000
38.1800 405.0000 1.0000
38.2400 421.0000 1.0000
38.3000 454.0000 1.0000
38.3600 457.0000 1.0000
38.4200 526.0000 1.0000
38.4800 599.0000 1.0000
38.5400 720.0000 1.0000
38.6000 759.0000 1.0000
38.6600 622.0000 1.0000
38.7200 582.0000 1.0000
38.7800 494.0000 1.0000
38.8400 430.0000 1.0000
38.9000 438.0000 1.0000
38.9600 420.0000 1.0000
39.0200 420.0000 1.0000
39.0800 416.0000 1.0000
39.1400 438.0000 1.0000
39.2000 379.0000 1.0000
39.2600 381.0000 1.0000
39.3200 435.0000 1.0000
39.3800 380.0000 1.0000
39.4400 370.0000 1.0000
39.5000 397.0000 1.0000
39.5600 386.0000 1.0000
39.6200 377.0000 1.0000
39.6800 372.0000 1.0000
39.7400 390.0000 1.0000
39.8000 384.0000 1.0000
39.8600 403.0000 1.0000
39.9200 407.0000 1.0000
39.9800 400.0000 1.0000
40.0400 363.0000 1.0000
40.1000 380.0000 1.0000
40.1600 402.0000 1.0000
40.2200 405.0000 1.0000
40.2800 355.0000 1.0000
40.3400 380.0000 1.0000
40.4000 335.0000 1.0000
40.4600 345.0000 1.0000
40.5200 328.0000 1.0000
40.5800 384.0000 1.0000
40.6400 341.0000 1.0000
40.7000 353.0000 1.0000
40.7600 344.0000 1.0000
40.8200 352.0000 1.0000
40.8800 389.0000 1.0000
40.9400 357.0000 1.0000
41.0000 364.0000 1.0000
41.0600 378.0000 1.0000
41.1200 360.0000 1.0000
41.1800 355.0000 1.0000
41.2400 333.0000 1.0000
41.3000 349.0000 1.0000
41.3600 346.0000 1.0000
41.4200 346.0000 1.0000
41.4800 365.0000 1.0000
41.5400 367.0000 1.0000
41.6000 315.0000 1.0000
41.6600 334.0000 1.0000
41.7200 344.0000 1.0000
41.7800 345.0000 1.0000
41.8400 337.0000 1.0000
41.9000 319.0000 1.0000
41.9600 308.0000 1.0000
42.0200 312.0000 1.0000
42.0800 314.0000 1.0000
42.1400 339.0000 1.0000
42.2000 294.0000 1.0000
42.2600 350.0000 1.0000
42.3200 350.0000 1.0000
42.3800 330.0000 1.0000
42.4400 312.0000 1.0000
42.5000 326.0000 1.0000
42.5600 324.0000 1.0000
42.6200 286.0000 1.0000
42.6800 309.0000 1.0000
42.7400 318.0000 1.0000
42.8000 318.0000 1.0000
42.8600 316.0000 1.0000
42.9200 312.0000 1.0000
42.9800 291.0000 1.0000
43.0400 322.0000 1.0000
43.1000 341.0000 1.0000
43.1600 282.0000 1.0000
43.2200 315.0000 1.0000
43.2800 331.0000 1.0000
43.3400 292.0000 1.0000
43.4000 301.0000 1.0000
43.4600 313.0000 1.0000
43.5200 291.0000 1.0000
43.5800 287.0000 1.0000
43.6400 308.0000 1.0000
43.7000 289.0000 1.0000
43.7600 297.0000 1.0000
43.8200 301.0000 1.0000
43.8800 289.0000 1.0000
43.9400 317.0000 1.0000
44.0000 290.0000 1.0000
44.0600 303.0000 1.0000
44.1200 304.0000 1.0000
44.1800 301.0000 1.0000
44.2400 311.0000 1.0000
44.3000 306.0000 1.0000
44.3600 325.0000 1.0000
44.4200 304.0000 1.0000
44.4800 306.0000 1.0000
44.5400 293.0000 1.0000
44.6000 297.0000 1.0000
44.6600 291.0000 1.0000
44.7200 279.0000 1.0000
44.7800 254.0000 1.0000
44.8400 262.0000 1.0000
44.9000 291.0000 1.0000
44.9600 301.0000 1.0000
45.0200 295.0000 1.0000
45.0800 273.0000 1.0000
45.1400 260.0000 1.0000
45.2000 270.0000 1.0000
45.2600 281.0000 1.0000
45.3200 263.0000 1.0000
45.3800 296.0000 1.0000
45.4400 288.0000 1.0000
45.5000 306.0000 1.0000
45.5600 287.0000 1.0000
45.6200 262.0000 1.0000
45.6800 269.0000 1.0000
45.7400 271.0000 1.0000
45.8000 285.0000 1.0000
45.8600 277.0000 1.0000
45.9200 236.0000 1.0000
45.9800 272.0000 1.0000
46.0400 243.0000 1.0000
46.1000 273.0000 1.0000
46.1600 281.0000 1.0000
46.2200 299.0000 1.0000
46.2800 255.0000 1.0000
46.3400 264.0000 1.0000
46.4000 277.0000 1.0000
46.4600 258.0000 1.0000
46.5200 271.0000 1.0000
46.5800 286.0000 1.0000
46.6400 247.0000 1.0000
46.7000 293.0000 1.0000
46.7600 269.0000 1.0000
46.8200 269.0000 1.0000
46.8800 272.0000 1.0000
46.9400 254.0000 1.0000
47.0000 250.0000 1.0000
47.0600 260.0000 1.0000
47.1200 244.0000 1.0000
47.1800 258.0000 1.0000
47.2400 250.0000 1.0000
47.3000 288.0000 1.0000
47.3600 248.0000 1.0000
47.4200 236.0000 1.0000
47.4800 244.0000 1.0000
47.5400 235.0000 1.0000
47.6000 255.0000 1.0000
47.6600 254.0000 1.0000
47.7200 267.0000 1.0000
47.7800 247.0000 1.0000
47.8400 240.0000 1.0000
47.9000 234.0000 1.0000
47.9600 260.0000 1.0000
48.0200 229.0000 1.0000
48.0800 253.0000 1.0000
48.1400 237.0000 1.0000
48.2000 257.0000 1.0000
48.2600 262.0000 1.0000
48.3200 239.0000 1.0000
48.3800 243.0000 1.0000
48.4400 248.0000 1.0000
48.5000 225.0000 1.0000
48.5600 246.0000 1.0000
48.6200 230.0000 1.0000
48.6800 204.0000 1.0000
48.7400 258.0000 1.0000
48.8000 233.0000 1.0000
48.8600 240.0000 1.0000
48.9200 245.0000 1.0000
48.9800 234.0000 1.0000
49.0400 216.0000 1.0000
49.1000 229.0000 1.0000
49.1600 230.0000 1.0000
49.2200 245.0000 1.0000
49.2800 235.0000 1.0000
49.3400 231.0000 1.0000
49.4000 217.0000 1.0000
49.4600 220.0000 1.0000
49.5200 229.0000 1.0000
49.5800 236.0000 1.0000
49.6400 236.0000 1.0000
49.7000 224.0000 1.0000
49.7600 244.0000 1.0000
49.8200 231.0000 1.0000
49.8800 229.0000 1.0000
49.9400 196.0000 1.0000
50.0000 238.0000 1.0000
50.0600 234.0000 1.0000
50.1200 244.0000 1.0000
50.1800 241.0000 1.0000
50.2400 209.0000 1.0000
50.3000 224.0000 1.0000
50.3600 198.0000 1.0000
50.4200 237.0000 1.0000
50.4800 243.0000 1.0000
50.5400 243.0000 1.0000
50.6000 196.0000 1.0000
50.6600 209.0000 1.0000
50.7200 235.0000 1.0000
50.7800 236.0000 1.0000
50.8400 233.0000 1.0000
50.9000 249.0000 1.0000
50.9600 207.0000 1.0000
51.0200 229.0000 1.0000
51.0800 245.0000 1.0000
51.1400 224.0000 1.0000
51.2000 218.0000 1.0000
51.2600 231.0000 1.0000
51.3200 240.0000 1.0000
51.3800 219.0000 1.0000
51.4400 242.0000 1.0000
51.5000 232.0000 1.0000
51.5600 221.0000 1.0000
51.6200 216.0000 1.0000
51.6800 215.0000 1.0000
51.7400 215.0000 1.0000
51.8000 231.0000 1.0000
51.8600 232.0000 1.0000
51.9200 237.0000 1.0000
51.9800 262.0000 1.0000
52.0400 302.0000 1.0000
52.1000 291.0000 1.0000
52.1600 430.0000 1.0000
52.2200 583.0000 1.0000
52.2800 862.0000 1.0000
52.3400 824.0000 1.0000
52.4000 732.0000 1.0000
52.4600 617.0000 1.0000
52.5200 473.0000 1.0000
52.5800 342.0000 1.0000
52.6400 302.0000 1.0000
52.7000 275.0000 1.0000
52.7600 270.0000 1.0000
52.8200 237.0000 1.0000
52.8800 219.0000 1.0000
52.9400 233.0000 1.0000
53.0000 217.0000 1.0000
53.0600 226.0000 1.0000
53.1200 210.0000 1.0000
53.1800 212.0000 1.0000
53.2400 190.0000 1.0000
53.3000 216.0000 1.0000
53.3600 195.0000 1.0000
53.4200 194.0000 1.0000
53.4800 197.0000 1.0000
53.5400 208.0000 1.0000
53.6000 209.0000 1.0000
53.6600 193.0000 1.0000
53.7200 208.0000 1.0000
53.7800 228.0000 1.0000
53.8400 213.0000 1.0000
53.9000 199.0000 1.0000
53.9600 217.0000 1.0000
54.0200 213.0000 1.0000
54.0800 202.0000 1.0000
54.1400 188.0000 1.0000
54.2000 204.0000 1.0000
54.2600 201.0000 1.0000
54.3200 194.0000 1.0000
54.3800 205.0000 1.0000
54.4400 201.0000 1.0000
54.5000 206.0000 1.0000
54.5600 218.0000 1.0000
54.6200 221.0000 1.0000
54.6800 211.0000 1.0000
54.7400 208.0000 1.0000
54.8000 240.0000 1.0000
54.8600 214.0000 1.0000
54.9200 216.0000 1.0000
54.9800 212.0000 1.0000
55.0400 216.0000 1.0000
55.1000 236.0000 1.0000
55.1600 243.0000 1.0000
55.2200 278.0000 1.0000
55.2800 267.0000 1.0000
55.3400 291.0000 1.0000
55.4000 281.0000 1.0000
55.4600 251.0000 1.0000
55.5200 238.0000 1.0000
55.5800 234.0000 1.0000
55.6400 215.0000 1.0000
55.7000 211.0000 1.0000
55.7600 219.0000 1.0000
55.8200 217.0000 1.0000
55.8800 224.0000 1.0000
55.9400 200.0000 1.0000
56.0000 230.0000 1.0000
56.0600 235.0000 1.0000
56.1200 214.0000 1.0000
56.1800 235.0000 1.0000
56.2400 200.0000 1.0000
56.3000 209.0000 1.0000
56.3600 198.0000 1.0000
56.4200 207.0000 1.0000
56.4800 212.0000 1.0000
56.5400 213.0000 1.0000
56.6000 207.0000 1.0000
56.6600 203.0000 1.0000
56.7200 214.0000 1.0000
56.7800 194.0000 1.0000
56.8400 224.0000 1.0000
56.9000 183.0000 1.0000
56.9600 217.0000 1.0000
57.0200 202.0000 1.0000
57.0800 213.0000 1.0000
57.1400 210.0000 1.0000
57.2000 182.0000 1.0000
57.2600 216.0000 1.0000
57.3200 217.0000 1.0000
57.3800 178.0000 1.0000
57.4400 210.0000 1.0000
57.5000 192.0000 1.0000
57.5600 202.0000 1.0000
57.6200 216.0000 1.0000
57.6800 216.0000 1.0000
57.7400 198.0000 1.0000
57.8000 196.0000 1.0000
57.8600 212.0000 1.0000
57.9200 211.0000 1.0000
57.9800 210.0000 1.0000
58.0400 204.0000 1.0000
58.1000 210.0000 1.0000
58.1600 208.0000 1.0000
58.2200 192.0000 1.0000
58.2800 204.0000 1.0000
58.3400 191.0000 1.0000
58.4000 195.0000 1.0000
58.4600 196.0000 1.0000
58.5200 206.0000 1.0000
58.5800 187.0000 1.0000
58.6400 203.0000 1.0000
58.7000 179.0000 1.0000
58.7600 197.0000 1.0000
58.8200 203.0000 1.0000
58.8800 219.0000 1.0000
58.9400 194.0000 1.0000
59.0000 192.0000 1.0000
59.0600 186.0000 1.0000
59.1200 216.0000 1.0000
59.1800 202.0000 1.0000
59.2400 175.0000 1.0000
59.3000 202.0000 1.0000
59.3600 190.0000 1.0000
59.4200 204.0000 1.0000
59.4800 191.0000 1.0000
59.5400 179.0000 1.0000
59.6000 208.0000 1.0000
59.6600 194.0000 1.0000
59.7200 212.0000 1.0000
59.7800 198.0000 1.0000
59.8400 200.0000 1.0000
59.9000 189.0000 1.0000
59.9600 209.0000 1.0000
60.0200 211.0000 1.0000
60.0800 183.0000 1.0000
60.1400 196.0000 1.0000
60.2000 179.0000 1.0000
60.2600 206.0000 1.0000
60.3200 185.0000 1.0000
60.3800 195.0000 1.0000
60.4400 205.0000 1.0000
60.5000 186.0000 1.0000
60.5600 194.0000 1.0000
60.6200 192.0000 1.0000
60.6800 192.0000 1.0000
60.7400 200.0000 1.0000
60.8000 232.0000 1.0000
60.8600 192.0000 1.0000
60.9200 210.0000 1.0000
60.9800 190.0000 1.0000
61.0400 207.0000 1.0000
61.1000 176.0000 1.0000
61.1600 197.0000 1.0000
61.2200 233.0000 1.0000
61.2800 215.0000 1.0000
61.3400 173.0000 1.0000
61.4000 190.0000 1.0000
61.4600 194.0000 1.0000
61.5200 222.0000 1.0000
61.5800 203.0000 1.0000
61.6400 181.0000 1.0000
61.7000 205.0000 1.0000
61.7600 182.0000 1.0000
61.8200 203.0000 1.0000
61.8800 216.0000 1.0000
61.9400 205.0000 1.0000
62.0000 202.0000 1.0000
62.0600 242.0000 1.0000
62.1200 261.0000 1.0000
62.1800 265.0000 1.0000
62.2400 312.0000 1.0000
62.3000 358.0000 1.0000
62.3600 341.0000 1.0000
62.4200 326.0000 1.0000
62.4800 306.0000 1.0000
62.5400 304.0000 1.0000
62.6000 260.0000 1.0000
62.6600 264.0000 1.0000
62.7200 260.0000 1.0000
62.7800 224.0000 1.0000
62.8400 213.0000 1.0000
62.9000 220.0000 1.0000
62.9600 220.0000 1.0000
63.0200 185.0000 1.0000
63.0800 192.0000 1.0000
63.1400 180.0000 1.0000
63.2000 196.0000 1.0000
63.2600 201.0000 1.0000
63.3200 205.0000 1.0000
63.3800 202.0000 1.0000
63.4400 206.0000 1.0000
63.5000 184.0000 1.0000
63.5600 219.0000 1.0000
63.6200 204.0000 1.0000
63.6800 184.0000 1.0000
63.7400 190.0000 1.0000
63.8000 203.0000 1.0000
63.8600 185.0000 1.0000
63.9200 214.0000 1.0000
63.9800 185.0000 1.0000
64.0400 176.0000 1.0000
64.1000 196.0000 1.0000
64.1600 184.0000 1.0000
64.2200 192.0000 1.0000
64.2800 171.0000 1.0000
64.3400 181.0000 1.0000
64.4000 196.0000 1.0000
64.4600 197.0000 1.0000
64.5200 214.0000 1.0000
64.5800 213.0000 1.0000
64.6400 245.0000 1.0000
64.7000 246.0000 1.0000
64.7600 250.0000 1.0000
64.8200 244.0000 1.0000
64.8800 224.0000 1.0000
64.9400 228.0000 1.0000
65.0000 249.0000 1.0000
65.0600 214.0000 1.0000
65.1200 222.0000 1.0000
65.1800 227.0000 1.0000
65.2400 207.0000 1.0000
65.3000 204.0000 1.0000
65.3600 226.0000 1.0000
65.4200 201.0000 1.0000
65.4800 195.0000 1.0000
65.5400 203.0000 1.0000
65.6000 181.0000 1.0000
65.6600 212.0000 1.0000
65.7200 207.0000 1.0000
65.7800 194.0000 1.0000
65.8400 234.0000 1.0000
65.9000 191.0000 1.0000
65.9600 214.0000 1.0000
66.0200 265.0000 1.0000
66.0800 254.0000 1.0000
66.1400 335.0000 1.0000
66.2000 438.0000 1.0000
66.2600 529.0000 1.0000
66.3200 509.0000 1.0000
66.3800 517.0000 1.0000
66.4400 478.0000 1.0000
66.5000 436.0000 1.0000
66.5600 394.0000 1.0000
66.6200 302.0000 1.0000
66.6800 248.0000 1.0000
66.7400 231.0000 1.0000
66.8000 233.0000 1.0000
66.8600 238.0000 1.0000
66.9200 194.0000 1.0000
66.9800 247.0000 1.0000
67.0400 208.0000 1.0000
67.1000 193.0000 1.0000
67.1600 193.0000 1.0000
67.2200 198.0000 1.0000
67.2800 185.0000 1.0000
67.3400 177.0000 1.0000
67.4000 174.0000 1.0000
67.4600 181.0000 1.0000
67.5200 190.0000 1.0000
67.5800 165.0000 1.0000
67.6400 191.0000 1.0000
67.7000 192.0000 1.0000
67.7600 184.0000 1.0000
67.8200 200.0000 1.0000
67.8800 202.0000 1.0000
67.9400 178.0000 1.0000
68.0000 175.0000 1.0000
68.0600 167.0000 1.0000
68.1200 180.0000 1.0000
68.1800 199.0000 1.0000
68.2400 182.0000 1.0000
68.3000 184.0000 1.0000
68.3600 190.0000 1.0000
68.4200 192.0000 1.0000
68.4800 182.0000 1.0000
68.5400 178.0000 1.0000
68.6000 177.0000 1.0000
68.6600 201.0000 1.0000
68.7200 177.0000 1.0000
68.7800 172.0000 1.0000
68.8400 188.0000 1.0000
68.9000 172.0000 1.0000
68.9600 195.0000 1.0000
69.0200 184.0000 1.0000
69.0800 181.0000 1.0000
69.1400 176.0000 1.0000
69.2000 178.0000 1.0000
69.2600 194.0000 1.0000
69.3200 191.0000 1.0000
69.3800 191.0000 1.0000
69.4400 186.0000 1.0000
69.5000 176.0000 1.0000
69.5600 192.0000 1.0000
69.6200 173.0000 1.0000
69.6800 198.0000 1.0000
69.7400 190.0000 1.0000
69.8000 202.0000 1.0000
69.8600 180.0000 1.0000
69.9200 190.0000 1.0000
69.9800 187.0000 1.0000
70.0400 192.0000 1.0000
70.1000 172.0000 1.0000
70.1600 182.0000 1.0000
70.2200 192.0000 1.0000
70.2800 173.0000 1.0000
70.3400 179.0000 1.0000
70.4000 197.0000 1.0000
70.4600 182.0000 1.0000
70.5200 152.0000 1.0000
70.5800 167.0000 1.0000
70.6400 181.0000 1.0000
70.7000 191.0000 1.0000
70.7600 180.0000 1.0000
70.8200 180.0000 1.0000
70.8800 193.0000 1.0000
70.9400 164.0000 1.0000
71.0000 197.0000 1.0000
71.0600 187.0000 1.0000
71.1200 187.0000 1.0000
71.1800 183.0000 1.0000
71.2400 175.0000 1.0000
71.3000 180.0000 1.0000
71.3600 181.0000 1.0000
71.4200 211.0000 1.0000
71.4800 198.0000 1.0000
71.5400 189.0000 1.0000
71.6000 199.0000 1.0000
71.6600 201.0000 1.0000
71.7200 215.0000 1.0000
71.7800 185.0000 1.0000
71.8400 192.0000 1.0000
71.9000 173.0000 1.0000
71.9600 174.0000 1.0000
72.0200 179.0000 1.0000
72.0800 192.0000 1.0000
72.1400 168.0000 1.0000
72.2000 165.0000 1.0000
72.2600 175.0000 1.0000
72.3200 152.0000 1.0000
72.3800 190.0000 1.0000
72.4400 146.0000 1.0000
72.5000 204.0000 1.0000
72.5600 154.0000 1.0000
72.6200 189.0000 1.0000
72.6800 193.0000 1.0000
72.7400 171.0000 1.0000
72.8000 173.0000 1.0000
72.8600 148.0000 1.0000
72.9200 179.0000 1.0000
72.9800 158.0000 1.0000
73.0400 166.0000 1.0000
73.1000 180.0000 1.0000
73.1600 187.0000 1.0000
73.2200 169.0000 1.0000
73.2800 193.0000 1.0000
73.3400 183.0000 1.0000
73.4000 175.0000 1.0000
73.4600 170.0000 1.0000
73.5200 190.0000 1.0000
73.5800 173.0000 1.0000
73.6400 191.0000 1.0000
73.7000 172.0000 1.0000
73.7600 160.0000 1.0000
73.8200 191.0000 1.0000
73.8800 178.0000 1.0000
73.9400 168.0000 1.0000
74.0000 185.0000 1.0000
74.0600 191.0000 1.0000
74.1200 153.0000 1.0000
74.1800 168.0000 1.0000
74.2400 163.0000 1.0000
74.3000 171.0000 1.0000
74.3600 166.0000 1.0000
74.4200 159.0000 1.0000
74.4800 156.0000 1.0000
74.5400 173.0000 1.0000
74.6000 183.0000 1.0000
74.6600 185.0000 1.0000
74.7200 158.0000 1.0000
74.7800 197.0000 1.0000
74.8400 168.0000 1.0000
74.9000 175.0000 1.0000
74.9600 205.0000 1.0000
75.0200 189.0000 1.0000
75.0800 154.0000 1.0000
75.1400 189.0000 1.0000
75.2000 160.0000 1.0000
75.2600 183.0000 1.0000
75.3200 152.0000 1.0000
75.3800 184.0000 1.0000
75.4400 171.0000 1.0000
75.5000 178.0000 1.0000
75.5600 166.0000 1.0000
75.6200 175.0000 1.0000
75.6800 173.0000 1.0000
75.7400 196.0000 1.0000
75.8000 156.0000 1.0000
75.8600 171.0000 1.0000
75.9200 172.0000 1.0000
75.9800 174.0000 1.0000
76.0400 182.0000 1.0000
76.1000 166.0000 1.0000
76.1600 168.0000 1.0000
76.2200 165.0000 1.0000
76.2800 183.0000 1.0000
76.3400 156.0000 1.0000
76.4000 154.0000 1.0000
76.4600 164.0000 1.0000
76.5200 168.0000 1.0000
76.5800 173.0000 1.0000
76.6400 193.0000 1.0000
76.7000 170.0000 1.0000
76.7600 157.0000 1.0000
76.8200 172.0000 1.0000
76.8800 176.0000 1.0000
76.9400 185.0000 1.0000
77.0000 176.0000 1.0000
77.0600 195.0000 1.0000
77.1200 193.0000 1.0000
77.1800 153.0000 1.0000
77.2400 187.0000 1.0000
77.3000 157.0000 1.0000
77.3600 170.0000 1.0000
77.4200 186.0000 1.0000
77.4800 196.0000 1.0000
77.5400 179.0000 1.0000
77.6000 153.0000 1.0000
77.6600 176.0000 1.0000
77.7200 181.0000 1.0000
77.7800 158.0000 1.0000
77.8400 184.0000 1.0000
77.9000 161.0000 1.0000
77.9600 184.0000 1.0000
78.0200 151.0000 1.0000
78.0800 157.0000 1.0000
78.1400 176.0000 1.0000
78.2000 208.0000 1.0000
78.2600 169.0000 1.0000
78.3200 195.0000 1.0000
78.3800 182.0000 1.0000
78.4400 190.0000 1.0000
78.5000 167.0000 1.0000
78.5600 181.0000 1.0000
78.6200 205.0000 1.0000
78.6800 197.0000 1.0000
78.7400 167.0000 1.0000
78.8000 182.0000 1.0000
78.8600 227.0000 1.0000
78.9200 222.0000 1.0000
78.9800 262.0000 1.0000
79.0400 265.0000 1.0000
79.1000 268.0000 1.0000
79.1600 270.0000 1.0000
79.2200 250.0000 1.0000
79.2800 238.0000 1.0000
79.3400 223.0000 1.0000
79.4000 197.0000 1.0000
79.4600 200.0000 1.0000
79.5200 173.0000 1.0000
79.5800 173.0000 1.0000
79.6400 180.0000 1.0000
79.7000 185.0000 1.0000
79.7600 177.0000 1.0000
79.8200 183.0000 1.0000
79.8800 181.0000 1.0000
79.9400 182.0000 1.0000
80.0000 166.0000 1.0000
*RAS_INT_END
*RAS_TEMPERATURE_START
*RAS_TEMPERATURE_END
*RAS_DATA_END