File: Sectio1_28_samples/XRD/No_005_600_16.ras
*RAS_DATA_START
*RAS_HEADER_START
*DISP_FMT_X "%.2f"
*DISP_FMT_Y "%.0f"
*DISP_FULLSCALE "3478.0000000000"
*DISP_LINE_COLOR "255.0000000000"
*DISP_LINE_STYLE "0.0000000000"
*DISP_LINE_WIDTH "0.2500000000"
*DISP_NOTE "測定データ-1"
*DISP_OFFSET_Y "0.0000000000"
*DISP_PEAKSEARCH_UNIT_Y "cps"
*DISP_RANGE_BOTTOM "0.0000000000"
*DISP_RANGE_LEFT "20.0000000000"
*DISP_RANGE_LOGCUTOFF "0.0100000000"
*DISP_RANGE_RIGHT "80.0000000000"
*DISP_RANGE_TOP "3478.0000000000"
*DISP_SCALE_MODE_Y "0.0000000000"
*DISP_TAB_NAME "2θ/θ"
*DISP_TITLE_Y "強度"
*DISP_UNIT_Y "cps"
*DISP_WINDOW_NAME "MSG_MACROENGINE"
*FILE_COMMENT " "
*FILE_MD5 ""
*FILE_MEMO " "
*FILE_OPERATOR "Administrator"
*FILE_SAMPLE " "
*FILE_TYPE "RAS_RAW"
*FILE_USERGROUP "システムマネージャ"
*FILE_VERSION "1.0000000000"
*HW_ATTACHMENT_ID "ATT0025"
*HW_ATTACHMENT_NAME "標準|Standard"
*HW_COUNTER_ID-0 "CUT0025"
*HW_COUNTER_ID-1 "CUT0020"
*HW_COUNTER_ID-2 "CUT0020"
*HW_COUNTER_ID-3 "CSL0021"
*HW_COUNTER_ID-4 "CMC0021"
*HW_COUNTER_NAME-0 "D/teX Ultra|D/teX Ultra"
*HW_COUNTER_NAME-1 "None|None"
*HW_COUNTER_NAME-2 "None|None"
*HW_COUNTER_NAME-3 "BBM|BBM"
*HW_COUNTER_NAME-4 "検出器モノクロメータ|Detector monochromator"
*HW_COUNTER_SELECT_NAME "D/teX Ultra|D/teX Ultra"
*HW_GONIOMETER_ID "GON0023"
*HW_GONIOMETER_NAME "SmartLab|SmartLab"
*HW_GONIOMETER_RADIUS-0 "90.0"
*HW_GONIOMETER_RADIUS-1 "114.0"
*HW_GONIOMETER_RADIUS-2 "190.0"
*HW_GONIOMETER_RADIUS-3 "300.0"
*HW_GONIOMETER_RADIUS-4 "187.0"
*HW_GONIOMETER_RADIUS-5 "300.0"
*HW_GONIOMETER_RADIUS-6 "113.0"
*HW_GONIOMETER_RADIUS-7 "331.0"
*HW_I_OPT_ID-0 "CBO0021"
*HW_I_OPT_ID-1 "ICR0023"
*HW_I_OPT_ID-2 "ISL0021"
*HW_I_OPT_ID-3 "ISO0021"
*HW_I_OPT_ID-4 "IAD0021"
*HW_I_OPT_ID-5 "IPR0001"
*HW_I_OPT_NAME-0 "CBOユニット|CBO unit"
*HW_I_OPT_NAME-1 "標準入射光学ユニット|Standard incident optical unit"
*HW_I_OPT_NAME-2 "標準入射スリットボックス|Standard incident slit box"
*HW_I_OPT_NAME-3 "入射平行スリット|Incident parallel slit"
*HW_I_OPT_NAME-4 "長手制限スリット|Length limiting slit"
*HW_I_OPT_NAME-5 "None|None"
*HW_R_ATTENUATER_AUTOMODE "0"
*HW_R_OPT_ID-0 "RSS0021"
*HW_R_OPT_ID-1 "RCR0023"
*HW_R_OPT_ID-2 "RSO0021"
*HW_R_OPT_ID-3 "RRS0021"
*HW_R_OPT_ID-4 "ATN0021"
*HW_R_OPT_ID-5 "RFL0021"
*HW_R_OPT_ID-6 "RAD0021"
*HW_R_OPT_NAME-0 "標準受光スリットボックス1|Standard receiving slit box # 1"
*HW_R_OPT_NAME-1 "標準受光光学ユニット1|Standard receiving unit # 1"
*HW_R_OPT_NAME-2 "標準受光光学ユニット2|Standard receiving optical unit # 2"
*HW_R_OPT_NAME-3 "標準受光スリットボックス2|Standard receiving slit box # 2"
*HW_R_OPT_NAME-4 "標準アッテネータ|Standard Attenuator"
*HW_R_OPT_NAME-5 "Cu Kβ|Cu K-beta"
*HW_R_OPT_NAME-6 "調整用受光スリット|Alignment receiving slit"
*HW_SAMPLE_HOLDER_ID "SMP0023"
*HW_SAMPLE_HOLDER_NAME "標準Zステージ|Standard Z stage"
*HW_XG_CURRENT_MAX "50"
*HW_XG_CURRENT_MIN "2"
*HW_XG_CURRENT_RESOLUTION "2"
*HW_XG_CURRENT_UNIT "mA"
*HW_XG_FOCUS "1mm x 10mm"
*HW_XG_FOCUS_TYPE "Normal"
*HW_XG_ID ""
*HW_XG_NAME "3kW 封入管(ID:1200)|3kW Sealed tube(ID:1200)"
*HW_XG_TARGET_ATOMIC_NUMBER "29.0000000000"
*HW_XG_TARGET_NAME "Cu"
*HW_XG_TYPE "Hermetic"
*HW_XG_VOLTAGE_MAX "60"
*HW_XG_VOLTAGE_MIN "20"
*HW_XG_VOLTAGE_RESOLUTION "2"
*HW_XG_VOLTAGE_UNIT "kV"
*HW_XG_WATT_MAX "2"
*HW_XG_WATT_UNIT "kW"
*HW_XG_WAVE_LENGTH_ALPHA1 "1.540593"
*HW_XG_WAVE_LENGTH_ALPHA2 "1.544414"
*HW_XG_WAVE_LENGTH_BETA "1.392250"
*MEAS_COND_AXIS_NAME-0 "2θ/θ"
*MEAS_COND_AXIS_NAME-1 "2θ"
*MEAS_COND_AXIS_NAME-2 "ω"
*MEAS_COND_AXIS_NAME-3 "Z"
*MEAS_COND_AXIS_NAME-4 "2θ/ω"
*MEAS_COND_AXIS_NAME-5 "θs"
*MEAS_COND_AXIS_NAME-6 "θd"
*MEAS_COND_AXIS_NAME-7 "Ts"
*MEAS_COND_AXIS_NAME-8 "CBO選択スリット"
*MEAS_COND_AXIS_NAME-9 "M"
*MEAS_COND_AXIS_NAME-10 "入射平行スリット"
*MEAS_COND_AXIS_NAME-11 "入射スリット"
*MEAS_COND_AXIS_NAME-12 ""
*MEAS_COND_AXIS_NAME-13 "Zs"
*MEAS_COND_AXIS_NAME-14 "入射光学素子"
*MEAS_COND_AXIS_NAME-15 "長手制限スリット"
*MEAS_COND_AXIS_NAME-16 "センタースリット"
*MEAS_COND_AXIS_NAME-17 "フィルター"
*MEAS_COND_AXIS_NAME-18 "受光スリット1"
*MEAS_COND_AXIS_NAME-19 "受光スリット2"
*MEAS_COND_AXIS_NAME-20 "受光光学素子"
*MEAS_COND_AXIS_NAME-21 "受光平行スリット"
*MEAS_COND_AXIS_NAME-22 "調整用受光スリット"
*MEAS_COND_AXIS_NAME-23 ""
*MEAS_COND_AXIS_NAME-24 ""
*MEAS_COND_AXIS_NAME-25 "Zd"
*MEAS_COND_AXIS_NAME-26 "アッテネータ"
*MEAS_COND_AXIS_NAME-27 "検出器モノクロメータ"
*MEAS_COND_AXIS_NAME-28 "モノクロメータスリット"
*MEAS_COND_AXIS_NAME-29 "プライマリビーム"
*MEAS_COND_AXIS_NAME-30 "PHA"
*MEAS_COND_AXIS_NAME_INTERNAL-0 "TwoThetaTheta"
*MEAS_COND_AXIS_NAME_INTERNAL-1 "TwoTheta"
*MEAS_COND_AXIS_NAME_INTERNAL-2 "Omega"
*MEAS_COND_AXIS_NAME_INTERNAL-3 "Z"
*MEAS_COND_AXIS_NAME_INTERNAL-4 "TwoThetaOmega"
*MEAS_COND_AXIS_NAME_INTERNAL-5 "ThetaS"
*MEAS_COND_AXIS_NAME_INTERNAL-6 "ThetaD"
*MEAS_COND_AXIS_NAME_INTERNAL-7 "Ts"
*MEAS_COND_AXIS_NAME_INTERNAL-8 "CBO"
*MEAS_COND_AXIS_NAME_INTERNAL-9 "CBO-M"
*MEAS_COND_AXIS_NAME_INTERNAL-10 "IncidentSollerSlit"
*MEAS_COND_AXIS_NAME_INTERNAL-11 "IncidentSlitBox"
*MEAS_COND_AXIS_NAME_INTERNAL-12 "IncidentSlitBox-_Axis"
*MEAS_COND_AXIS_NAME_INTERNAL-13 "Zs"
*MEAS_COND_AXIS_NAME_INTERNAL-14 "IncidentMonochromator"
*MEAS_COND_AXIS_NAME_INTERNAL-15 "IncidentAxdSlit"
*MEAS_COND_AXIS_NAME_INTERNAL-16 "CenterSlit"
*MEAS_COND_AXIS_NAME_INTERNAL-17 "Filter"
*MEAS_COND_AXIS_NAME_INTERNAL-18 "ReceivingSlitBox1"
*MEAS_COND_AXIS_NAME_INTERNAL-19 "ReceivingSlitBox2"
*MEAS_COND_AXIS_NAME_INTERNAL-20 "ReceivingOptics"
*MEAS_COND_AXIS_NAME_INTERNAL-21 "ReceivingSollerSlit"
*MEAS_COND_AXIS_NAME_INTERNAL-22 "ReceivingAxdSlit"
*MEAS_COND_AXIS_NAME_INTERNAL-23 "ReceivingSlitBox1-_Axis"
*MEAS_COND_AXIS_NAME_INTERNAL-24 "ReceivingSlitBox2-_Axis"
*MEAS_COND_AXIS_NAME_INTERNAL-25 "ReceivingSlitBox2-Zd"
*MEAS_COND_AXIS_NAME_INTERNAL-26 "Attenuator"
*MEAS_COND_AXIS_NAME_INTERNAL-27 "CounterMonochromator"
*MEAS_COND_AXIS_NAME_INTERNAL-28 "CounterSlit"
*MEAS_COND_AXIS_NAME_INTERNAL-29 "IncidentPrimary"
*MEAS_COND_AXIS_NAME_INTERNAL-30 "PHA"
*MEAS_COND_AXIS_NAME_MAGICNO-0 "83951616.0000000000"
*MEAS_COND_AXIS_NAME_MAGICNO-1 "268632064.0000000000"
*MEAS_COND_AXIS_NAME_MAGICNO-2 "268500992.0000000000"
*MEAS_COND_AXIS_NAME_MAGICNO-3 "285278208.0000000000"
*MEAS_COND_AXIS_NAME_MAGICNO-4 "83951616.0000000000"
*MEAS_COND_AXIS_NAME_MAGICNO-5 "131072.0000000000"
*MEAS_COND_AXIS_NAME_MAGICNO-6 "131072.0000000000"
*MEAS_COND_AXIS_NAME_MAGICNO-7 "318898176.0000000000"
*MEAS_COND_AXIS_NAME_MAGICNO-8 "20971521.0000000000"
*MEAS_COND_AXIS_NAME_MAGICNO-9 "285343744.0000000000"
*MEAS_COND_AXIS_NAME_MAGICNO-10 "20971521.0000000000"
*MEAS_COND_AXIS_NAME_MAGICNO-11 "22020097.0000000000"
*MEAS_COND_AXIS_NAME_MAGICNO-12 "25165824.0000000000"
*MEAS_COND_AXIS_NAME_MAGICNO-13 "318898176.0000000000"
*MEAS_COND_AXIS_NAME_MAGICNO-14 "1.0000000000"
*MEAS_COND_AXIS_NAME_MAGICNO-15 "20971521.0000000000"
*MEAS_COND_AXIS_NAME_MAGICNO-16 "20971521.0000000000"
*MEAS_COND_AXIS_NAME_MAGICNO-17 "20971521.0000000000"
*MEAS_COND_AXIS_NAME_MAGICNO-18 "23068673.0000000000"
*MEAS_COND_AXIS_NAME_MAGICNO-19 "23068673.0000000000"
*MEAS_COND_AXIS_NAME_MAGICNO-20 "20971521.0000000000"
*MEAS_COND_AXIS_NAME_MAGICNO-21 "20971521.0000000000"
*MEAS_COND_AXIS_NAME_MAGICNO-22 "20971521.0000000000"
*MEAS_COND_AXIS_NAME_MAGICNO-23 "25165824.0000000000"
*MEAS_COND_AXIS_NAME_MAGICNO-24 "25165824.0000000000"
*MEAS_COND_AXIS_NAME_MAGICNO-25 "285343744.0000000000"
*MEAS_COND_AXIS_NAME_MAGICNO-26 "17301505.0000000000"
*MEAS_COND_AXIS_NAME_MAGICNO-27 "20971521.0000000000"
*MEAS_COND_AXIS_NAME_MAGICNO-28 "20971521.0000000000"
*MEAS_COND_AXIS_NAME_MAGICNO-29 "20971521.0000000000"
*MEAS_COND_AXIS_NAME_MAGICNO-30 "0.0000000000"
*MEAS_COND_AXIS_OFFSET-0 "-"
*MEAS_COND_AXIS_OFFSET-1 "-0.1081000000"
*MEAS_COND_AXIS_OFFSET-2 "0.3758000000"
*MEAS_COND_AXIS_OFFSET-3 "-"
*MEAS_COND_AXIS_OFFSET-4 "-"
*MEAS_COND_AXIS_OFFSET-5 "0.3758000000"
*MEAS_COND_AXIS_OFFSET-6 "-0.4839000000"
*MEAS_COND_AXIS_OFFSET-7 "-"
*MEAS_COND_AXIS_OFFSET-8 "-"
*MEAS_COND_AXIS_OFFSET-9 "-"
*MEAS_COND_AXIS_OFFSET-10 "-"
*MEAS_COND_AXIS_OFFSET-11 "-"
*MEAS_COND_AXIS_OFFSET-12 "-"
*MEAS_COND_AXIS_OFFSET-13 "-"
*MEAS_COND_AXIS_OFFSET-14 "-"
*MEAS_COND_AXIS_OFFSET-15 "-"
*MEAS_COND_AXIS_OFFSET-16 "-"
*MEAS_COND_AXIS_OFFSET-17 "-"
*MEAS_COND_AXIS_OFFSET-18 "-"
*MEAS_COND_AXIS_OFFSET-19 "-"
*MEAS_COND_AXIS_OFFSET-20 "-"
*MEAS_COND_AXIS_OFFSET-21 "-"
*MEAS_COND_AXIS_OFFSET-22 "-"
*MEAS_COND_AXIS_OFFSET-23 "-"
*MEAS_COND_AXIS_OFFSET-24 "-"
*MEAS_COND_AXIS_OFFSET-25 "-"
*MEAS_COND_AXIS_OFFSET-26 "-"
*MEAS_COND_AXIS_OFFSET-27 "-"
*MEAS_COND_AXIS_OFFSET-28 "-"
*MEAS_COND_AXIS_OFFSET-29 "-"
*MEAS_COND_AXIS_OFFSET-30 "-"
*MEAS_COND_AXIS_POSITION-0 "0.0000000000"
*MEAS_COND_AXIS_POSITION-1 "0.0000000000"
*MEAS_COND_AXIS_POSITION-2 "0.0000000000"
*MEAS_COND_AXIS_POSITION-3 "-0.5500000000"
*MEAS_COND_AXIS_POSITION-4 "0.0000000000"
*MEAS_COND_AXIS_POSITION-5 "0.0000000000"
*MEAS_COND_AXIS_POSITION-6 "0.0000000000"
*MEAS_COND_AXIS_POSITION-7 "-0.4278800000"
*MEAS_COND_AXIS_POSITION-8 "BB"
*MEAS_COND_AXIS_POSITION-9 "0.0000000000"
*MEAS_COND_AXIS_POSITION-10 "Soller_slit_5.0deg"
*MEAS_COND_AXIS_POSITION-11 "2/3deg"
*MEAS_COND_AXIS_POSITION-12 "2.2088000000"
*MEAS_COND_AXIS_POSITION-13 "-0.4140600000"
*MEAS_COND_AXIS_POSITION-14 "0.0000000000"
*MEAS_COND_AXIS_POSITION-15 "10.0mm"
*MEAS_COND_AXIS_POSITION-16 "None"
*MEAS_COND_AXIS_POSITION-17 "Cu_K-beta"
*MEAS_COND_AXIS_POSITION-18 "13.000mm"
*MEAS_COND_AXIS_POSITION-19 "13.000mm"
*MEAS_COND_AXIS_POSITION-20 "No_unit"
*MEAS_COND_AXIS_POSITION-21 "Soller_slit_5.0deg"
*MEAS_COND_AXIS_POSITION-22 "None"
*MEAS_COND_AXIS_POSITION-23 "13.0000000000"
*MEAS_COND_AXIS_POSITION-24 "13.0000000000"
*MEAS_COND_AXIS_POSITION-25 "0.0109400000"
*MEAS_COND_AXIS_POSITION-26 "Open"
*MEAS_COND_AXIS_POSITION-27 "None"
*MEAS_COND_AXIS_POSITION-28 "None"
*MEAS_COND_AXIS_POSITION-29 "None"
*MEAS_COND_AXIS_POSITION-30 "38.0000000000"
*MEAS_COND_AXIS_UNIT-0 "deg"
*MEAS_COND_AXIS_UNIT-1 "deg"
*MEAS_COND_AXIS_UNIT-2 "deg"
*MEAS_COND_AXIS_UNIT-3 "mm"
*MEAS_COND_AXIS_UNIT-4 "deg"
*MEAS_COND_AXIS_UNIT-5 "deg"
*MEAS_COND_AXIS_UNIT-6 "deg"
*MEAS_COND_AXIS_UNIT-7 "mm"
*MEAS_COND_AXIS_UNIT-8 ""
*MEAS_COND_AXIS_UNIT-9 "pulse"
*MEAS_COND_AXIS_UNIT-10 ""
*MEAS_COND_AXIS_UNIT-11 ""
*MEAS_COND_AXIS_UNIT-12 "mm"
*MEAS_COND_AXIS_UNIT-13 "mm"
*MEAS_COND_AXIS_UNIT-14 ""
*MEAS_COND_AXIS_UNIT-15 ""
*MEAS_COND_AXIS_UNIT-16 ""
*MEAS_COND_AXIS_UNIT-17 ""
*MEAS_COND_AXIS_UNIT-18 ""
*MEAS_COND_AXIS_UNIT-19 ""
*MEAS_COND_AXIS_UNIT-20 ""
*MEAS_COND_AXIS_UNIT-21 ""
*MEAS_COND_AXIS_UNIT-22 ""
*MEAS_COND_AXIS_UNIT-23 "mm"
*MEAS_COND_AXIS_UNIT-24 "mm"
*MEAS_COND_AXIS_UNIT-25 "mm"
*MEAS_COND_AXIS_UNIT-26 ""
*MEAS_COND_AXIS_UNIT-27 ""
*MEAS_COND_AXIS_UNIT-28 ""
*MEAS_COND_AXIS_UNIT-29 ""
*MEAS_COND_AXIS_UNIT-30 "div"
*MEAS_COND_COUNTER_CNTLOSS_CORR "0.0000000000"
*MEAS_COND_COUNTER_PHABASE "38.0000000000"
*MEAS_COND_COUNTER_PHAWINDOW "16.0000000000"
*MEAS_COND_COUNTER_PHA_UNIT "div"
*MEAS_COND_COUNTER_TAUDIFF "30.0000000000"
*MEAS_COND_COUNTER_TAUINT "0.0000000000"
*MEAS_COND_IRRADIATION_MODE "OFF"
*MEAS_COND_IRRADIATION_WIDTH ""
*MEAS_COND_OPT_ATTR "集中法"
*MEAS_COND_OPT_NAME "@集中法"
*MEAS_COND_UNSYMMETRIC_MODE "OFF"
*MEAS_COND_XG_CURRENT "30.0000000000"
*MEAS_COND_XG_VOLTAGE "40.0000000000"
*MEAS_COND_XG_WAVE_TYPE "Ka"
*MEAS_DATA_COUNT "3001.0000000000"
*MEAS_SCAN_AXIS_X "2θ/θ"
*MEAS_SCAN_AXIS_X_INTERNAL "TwoThetaTheta"
*MEAS_SCAN_END_TIME "09/02/20 11:44:13"
*MEAS_SCAN_MODE "CONTINUOUS"
*MEAS_SCAN_MONITOR "0"
*MEAS_SCAN_RESOLUTION_X "0.0002"
*MEAS_SCAN_SPEED "2.0"
*MEAS_SCAN_SPEED_UNIT "deg/min"
*MEAS_SCAN_START "20.0000000000"
*MEAS_SCAN_START_TIME "09/02/20 11:12:34"
*MEAS_SCAN_STEP "0.0200000000"
*MEAS_SCAN_STOP "80.0000000000"
*MEAS_SCAN_UNIT_X "deg"
*MEAS_SCAN_UNIT_Y "counts"
*RAS_HEADER_END
*RAS_INT_START
20.0000 1685.0000 1.0000
20.0600 1662.0000 1.0000
20.1200 1690.0000 1.0000
20.1800 1667.0000 1.0000
20.2400 1657.0000 1.0000
20.3000 1656.0000 1.0000
20.3600 1634.0000 1.0000
20.4200 1638.0000 1.0000
20.4800 1649.0000 1.0000
20.5400 1661.0000 1.0000
20.6000 1607.0000 1.0000
20.6600 1639.0000 1.0000
20.7200 1631.0000 1.0000
20.7800 1603.0000 1.0000
20.8400 1625.0000 1.0000
20.9000 1636.0000 1.0000
20.9600 1525.0000 1.0000
21.0200 1551.0000 1.0000
21.0800 1536.0000 1.0000
21.1400 1565.0000 1.0000
21.2000 1605.0000 1.0000
21.2600 1536.0000 1.0000
21.3200 1494.0000 1.0000
21.3800 1466.0000 1.0000
21.4400 1594.0000 1.0000
21.5000 1538.0000 1.0000
21.5600 1500.0000 1.0000
21.6200 1551.0000 1.0000
21.6800 1522.0000 1.0000
21.7400 1470.0000 1.0000
21.8000 1408.0000 1.0000
21.8600 1431.0000 1.0000
21.9200 1434.0000 1.0000
21.9800 1483.0000 1.0000
22.0400 1390.0000 1.0000
22.1000 1469.0000 1.0000
22.1600 1391.0000 1.0000
22.2200 1383.0000 1.0000
22.2800 1456.0000 1.0000
22.3400 1420.0000 1.0000
22.4000 1400.0000 1.0000
22.4600 1414.0000 1.0000
22.5200 1376.0000 1.0000
22.5800 1419.0000 1.0000
22.6400 1387.0000 1.0000
22.7000 1417.0000 1.0000
22.7600 1351.0000 1.0000
22.8200 1301.0000 1.0000
22.8800 1375.0000 1.0000
22.9400 1372.0000 1.0000
23.0000 1413.0000 1.0000
23.0600 1322.0000 1.0000
23.1200 1280.0000 1.0000
23.1800 1357.0000 1.0000
23.2400 1257.0000 1.0000
23.3000 1328.0000 1.0000
23.3600 1289.0000 1.0000
23.4200 1257.0000 1.0000
23.4800 1232.0000 1.0000
23.5400 1252.0000 1.0000
23.6000 1296.0000 1.0000
23.6600 1233.0000 1.0000
23.7200 1259.0000 1.0000
23.7800 1251.0000 1.0000
23.8400 1237.0000 1.0000
23.9000 1177.0000 1.0000
23.9600 1257.0000 1.0000
24.0200 1186.0000 1.0000
24.0800 1256.0000 1.0000
24.1400 1290.0000 1.0000
24.2000 1163.0000 1.0000
24.2600 1265.0000 1.0000
24.3200 1156.0000 1.0000
24.3800 1198.0000 1.0000
24.4400 1165.0000 1.0000
24.5000 1202.0000 1.0000
24.5600 1147.0000 1.0000
24.6200 1203.0000 1.0000
24.6800 1109.0000 1.0000
24.7400 1138.0000 1.0000
24.8000 1098.0000 1.0000
24.8600 1141.0000 1.0000
24.9200 1073.0000 1.0000
24.9800 1089.0000 1.0000
25.0400 1096.0000 1.0000
25.1000 1040.0000 1.0000
25.1600 1061.0000 1.0000
25.2200 1123.0000 1.0000
25.2800 1049.0000 1.0000
25.3400 1093.0000 1.0000
25.4000 1100.0000 1.0000
25.4600 1066.0000 1.0000
25.5200 1004.0000 1.0000
25.5800 1089.0000 1.0000
25.6400 1046.0000 1.0000
25.7000 1086.0000 1.0000
25.7600 1054.0000 1.0000
25.8200 997.0000 1.0000
25.8800 1056.0000 1.0000
25.9400 1010.0000 1.0000
26.0000 1080.0000 1.0000
26.0600 981.0000 1.0000
26.1200 1018.0000 1.0000
26.1800 1036.0000 1.0000
26.2400 1017.0000 1.0000
26.3000 1004.0000 1.0000
26.3600 956.0000 1.0000
26.4200 971.0000 1.0000
26.4800 952.0000 1.0000
26.5400 995.0000 1.0000
26.6000 988.0000 1.0000
26.6600 1020.0000 1.0000
26.7200 959.0000 1.0000
26.7800 982.0000 1.0000
26.8400 939.0000 1.0000
26.9000 952.0000 1.0000
26.9600 969.0000 1.0000
27.0200 937.0000 1.0000
27.0800 965.0000 1.0000
27.1400 909.0000 1.0000
27.2000 990.0000 1.0000
27.2600 902.0000 1.0000
27.3200 969.0000 1.0000
27.3800 974.0000 1.0000
27.4400 983.0000 1.0000
27.5000 916.0000 1.0000
27.5600 928.0000 1.0000
27.6200 924.0000 1.0000
27.6800 903.0000 1.0000
27.7400 896.0000 1.0000
27.8000 920.0000 1.0000
27.8600 887.0000 1.0000
27.9200 904.0000 1.0000
27.9800 847.0000 1.0000
28.0400 851.0000 1.0000
28.1000 859.0000 1.0000
28.1600 853.0000 1.0000
28.2200 849.0000 1.0000
28.2800 841.0000 1.0000
28.3400 873.0000 1.0000
28.4000 880.0000 1.0000
28.4600 873.0000 1.0000
28.5200 875.0000 1.0000
28.5800 822.0000 1.0000
28.6400 789.0000 1.0000
28.7000 793.0000 1.0000
28.7600 799.0000 1.0000
28.8200 819.0000 1.0000
28.8800 840.0000 1.0000
28.9400 877.0000 1.0000
29.0000 782.0000 1.0000
29.0600 789.0000 1.0000
29.1200 786.0000 1.0000
29.1800 737.0000 1.0000
29.2400 813.0000 1.0000
29.3000 795.0000 1.0000
29.3600 755.0000 1.0000
29.4200 748.0000 1.0000
29.4800 770.0000 1.0000
29.5400 774.0000 1.0000
29.6000 718.0000 1.0000
29.6600 737.0000 1.0000
29.7200 762.0000 1.0000
29.7800 795.0000 1.0000
29.8400 778.0000 1.0000
29.9000 757.0000 1.0000
29.9600 765.0000 1.0000
30.0200 716.0000 1.0000
30.0800 746.0000 1.0000
30.1400 723.0000 1.0000
30.2000 739.0000 1.0000
30.2600 693.0000 1.0000
30.3200 738.0000 1.0000
30.3800 736.0000 1.0000
30.4400 716.0000 1.0000
30.5000 711.0000 1.0000
30.5600 728.0000 1.0000
30.6200 666.0000 1.0000
30.6800 703.0000 1.0000
30.7400 696.0000 1.0000
30.8000 747.0000 1.0000
30.8600 685.0000 1.0000
30.9200 663.0000 1.0000
30.9800 650.0000 1.0000
31.0400 667.0000 1.0000
31.1000 647.0000 1.0000
31.1600 689.0000 1.0000
31.2200 645.0000 1.0000
31.2800 653.0000 1.0000
31.3400 669.0000 1.0000
31.4000 636.0000 1.0000
31.4600 666.0000 1.0000
31.5200 694.0000 1.0000
31.5800 610.0000 1.0000
31.6400 639.0000 1.0000
31.7000 654.0000 1.0000
31.7600 634.0000 1.0000
31.8200 635.0000 1.0000
31.8800 597.0000 1.0000
31.9400 605.0000 1.0000
32.0000 616.0000 1.0000
32.0600 607.0000 1.0000
32.1200 647.0000 1.0000
32.1800 592.0000 1.0000
32.2400 609.0000 1.0000
32.3000 593.0000 1.0000
32.3600 626.0000 1.0000
32.4200 660.0000 1.0000
32.4800 598.0000 1.0000
32.5400 604.0000 1.0000
32.6000 612.0000 1.0000
32.6600 597.0000 1.0000
32.7200 558.0000 1.0000
32.7800 587.0000 1.0000
32.8400 547.0000 1.0000
32.9000 613.0000 1.0000
32.9600 568.0000 1.0000
33.0200 584.0000 1.0000
33.0800 618.0000 1.0000
33.1400 582.0000 1.0000
33.2000 553.0000 1.0000
33.2600 535.0000 1.0000
33.3200 570.0000 1.0000
33.3800 566.0000 1.0000
33.4400 546.0000 1.0000
33.5000 615.0000 1.0000
33.5600 559.0000 1.0000
33.6200 605.0000 1.0000
33.6800 540.0000 1.0000
33.7400 561.0000 1.0000
33.8000 576.0000 1.0000
33.8600 559.0000 1.0000
33.9200 587.0000 1.0000
33.9800 543.0000 1.0000
34.0400 523.0000 1.0000
34.1000 541.0000 1.0000
34.1600 525.0000 1.0000
34.2200 516.0000 1.0000
34.2800 561.0000 1.0000
34.3400 569.0000 1.0000
34.4000 537.0000 1.0000
34.4600 595.0000 1.0000
34.5200 575.0000 1.0000
34.5800 583.0000 1.0000
34.6400 604.0000 1.0000
34.7000 547.0000 1.0000
34.7600 497.0000 1.0000
34.8200 540.0000 1.0000
34.8800 491.0000 1.0000
34.9400 491.0000 1.0000
35.0000 514.0000 1.0000
35.0600 518.0000 1.0000
35.1200 508.0000 1.0000
35.1800 510.0000 1.0000
35.2400 511.0000 1.0000
35.3000 478.0000 1.0000
35.3600 480.0000 1.0000
35.4200 488.0000 1.0000
35.4800 441.0000 1.0000
35.5400 485.0000 1.0000
35.6000 465.0000 1.0000
35.6600 469.0000 1.0000
35.7200 505.0000 1.0000
35.7800 456.0000 1.0000
35.8400 447.0000 1.0000
35.9000 419.0000 1.0000
35.9600 445.0000 1.0000
36.0200 470.0000 1.0000
36.0800 451.0000 1.0000
36.1400 452.0000 1.0000
36.2000 515.0000 1.0000
36.2600 456.0000 1.0000
36.3200 495.0000 1.0000
36.3800 506.0000 1.0000
36.4400 456.0000 1.0000
36.5000 489.0000 1.0000
36.5600 473.0000 1.0000
36.6200 460.0000 1.0000
36.6800 451.0000 1.0000
36.7400 424.0000 1.0000
36.8000 443.0000 1.0000
36.8600 390.0000 1.0000
36.9200 422.0000 1.0000
36.9800 419.0000 1.0000
37.0400 422.0000 1.0000
37.1000 434.0000 1.0000
37.1600 409.0000 1.0000
37.2200 404.0000 1.0000
37.2800 430.0000 1.0000
37.3400 411.0000 1.0000
37.4000 387.0000 1.0000
37.4600 384.0000 1.0000
37.5200 398.0000 1.0000
37.5800 388.0000 1.0000
37.6400 398.0000 1.0000
37.7000 390.0000 1.0000
37.7600 405.0000 1.0000
37.8200 425.0000 1.0000
37.8800 401.0000 1.0000
37.9400 354.0000 1.0000
38.0000 400.0000 1.0000
38.0600 397.0000 1.0000
38.1200 418.0000 1.0000
38.1800 401.0000 1.0000
38.2400 434.0000 1.0000
38.3000 389.0000 1.0000
38.3600 464.0000 1.0000
38.4200 486.0000 1.0000
38.4800 561.0000 1.0000
38.5400 579.0000 1.0000
38.6000 564.0000 1.0000
38.6600 527.0000 1.0000
38.7200 440.0000 1.0000
38.7800 461.0000 1.0000
38.8400 381.0000 1.0000
38.9000 384.0000 1.0000
38.9600 388.0000 1.0000
39.0200 376.0000 1.0000
39.0800 375.0000 1.0000
39.1400 358.0000 1.0000
39.2000 353.0000 1.0000
39.2600 358.0000 1.0000
39.3200 388.0000 1.0000
39.3800 363.0000 1.0000
39.4400 367.0000 1.0000
39.5000 370.0000 1.0000
39.5600 385.0000 1.0000
39.6200 352.0000 1.0000
39.6800 372.0000 1.0000
39.7400 339.0000 1.0000
39.8000 339.0000 1.0000
39.8600 375.0000 1.0000
39.9200 357.0000 1.0000
39.9800 334.0000 1.0000
40.0400 316.0000 1.0000
40.1000 306.0000 1.0000
40.1600 322.0000 1.0000
40.2200 331.0000 1.0000
40.2800 321.0000 1.0000
40.3400 315.0000 1.0000
40.4000 325.0000 1.0000
40.4600 368.0000 1.0000
40.5200 331.0000 1.0000
40.5800 327.0000 1.0000
40.6400 325.0000 1.0000
40.7000 329.0000 1.0000
40.7600 329.0000 1.0000
40.8200 329.0000 1.0000
40.8800 298.0000 1.0000
40.9400 320.0000 1.0000
41.0000 319.0000 1.0000
41.0600 319.0000 1.0000
41.1200 290.0000 1.0000
41.1800 303.0000 1.0000
41.2400 317.0000 1.0000
41.3000 333.0000 1.0000
41.3600 308.0000 1.0000
41.4200 297.0000 1.0000
41.4800 291.0000 1.0000
41.5400 319.0000 1.0000
41.6000 301.0000 1.0000
41.6600 324.0000 1.0000
41.7200 302.0000 1.0000
41.7800 342.0000 1.0000
41.8400 291.0000 1.0000
41.9000 342.0000 1.0000
41.9600 304.0000 1.0000
42.0200 309.0000 1.0000
42.0800 278.0000 1.0000
42.1400 312.0000 1.0000
42.2000 269.0000 1.0000
42.2600 285.0000 1.0000
42.3200 284.0000 1.0000
42.3800 286.0000 1.0000
42.4400 298.0000 1.0000
42.5000 316.0000 1.0000
42.5600 313.0000 1.0000
42.6200 288.0000 1.0000
42.6800 271.0000 1.0000
42.7400 285.0000 1.0000
42.8000 293.0000 1.0000
42.8600 285.0000 1.0000
42.9200 288.0000 1.0000
42.9800 259.0000 1.0000
43.0400 288.0000 1.0000
43.1000 275.0000 1.0000
43.1600 277.0000 1.0000
43.2200 314.0000 1.0000
43.2800 306.0000 1.0000
43.3400 327.0000 1.0000
43.4000 278.0000 1.0000
43.4600 286.0000 1.0000
43.5200 301.0000 1.0000
43.5800 274.0000 1.0000
43.6400 279.0000 1.0000
43.7000 254.0000 1.0000
43.7600 276.0000 1.0000
43.8200 303.0000 1.0000
43.8800 266.0000 1.0000
43.9400 280.0000 1.0000
44.0000 268.0000 1.0000
44.0600 267.0000 1.0000
44.1200 261.0000 1.0000
44.1800 251.0000 1.0000
44.2400 308.0000 1.0000
44.3000 282.0000 1.0000
44.3600 268.0000 1.0000
44.4200 283.0000 1.0000
44.4800 272.0000 1.0000
44.5400 264.0000 1.0000
44.6000 265.0000 1.0000
44.6600 256.0000 1.0000
44.7200 267.0000 1.0000
44.7800 252.0000 1.0000
44.8400 249.0000 1.0000
44.9000 252.0000 1.0000
44.9600 268.0000 1.0000
45.0200 252.0000 1.0000
45.0800 271.0000 1.0000
45.1400 246.0000 1.0000
45.2000 241.0000 1.0000
45.2600 260.0000 1.0000
45.3200 251.0000 1.0000
45.3800 239.0000 1.0000
45.4400 262.0000 1.0000
45.5000 250.0000 1.0000
45.5600 241.0000 1.0000
45.6200 271.0000 1.0000
45.6800 230.0000 1.0000
45.7400 256.0000 1.0000
45.8000 245.0000 1.0000
45.8600 246.0000 1.0000
45.9200 263.0000 1.0000
45.9800 234.0000 1.0000
46.0400 221.0000 1.0000
46.1000 240.0000 1.0000
46.1600 245.0000 1.0000
46.2200 215.0000 1.0000
46.2800 245.0000 1.0000
46.3400 229.0000 1.0000
46.4000 238.0000 1.0000
46.4600 260.0000 1.0000
46.5200 227.0000 1.0000
46.5800 224.0000 1.0000
46.6400 255.0000 1.0000
46.7000 247.0000 1.0000
46.7600 234.0000 1.0000
46.8200 230.0000 1.0000
46.8800 254.0000 1.0000
46.9400 252.0000 1.0000
47.0000 259.0000 1.0000
47.0600 243.0000 1.0000
47.1200 241.0000 1.0000
47.1800 231.0000 1.0000
47.2400 228.0000 1.0000
47.3000 219.0000 1.0000
47.3600 233.0000 1.0000
47.4200 225.0000 1.0000
47.4800 213.0000 1.0000
47.5400 232.0000 1.0000
47.6000 229.0000 1.0000
47.6600 208.0000 1.0000
47.7200 209.0000 1.0000
47.7800 225.0000 1.0000
47.8400 228.0000 1.0000
47.9000 222.0000 1.0000
47.9600 204.0000 1.0000
48.0200 205.0000 1.0000
48.0800 217.0000 1.0000
48.1400 206.0000 1.0000
48.2000 214.0000 1.0000
48.2600 228.0000 1.0000
48.3200 221.0000 1.0000
48.3800 213.0000 1.0000
48.4400 205.0000 1.0000
48.5000 205.0000 1.0000
48.5600 219.0000 1.0000
48.6200 195.0000 1.0000
48.6800 190.0000 1.0000
48.7400 188.0000 1.0000
48.8000 197.0000 1.0000
48.8600 224.0000 1.0000
48.9200 189.0000 1.0000
48.9800 195.0000 1.0000
49.0400 214.0000 1.0000
49.1000 197.0000 1.0000
49.1600 207.0000 1.0000
49.2200 210.0000 1.0000
49.2800 198.0000 1.0000
49.3400 190.0000 1.0000
49.4000 223.0000 1.0000
49.4600 217.0000 1.0000
49.5200 210.0000 1.0000
49.5800 201.0000 1.0000
49.6400 197.0000 1.0000
49.7000 201.0000 1.0000
49.7600 215.0000 1.0000
49.8200 213.0000 1.0000
49.8800 181.0000 1.0000
49.9400 194.0000 1.0000
50.0000 195.0000 1.0000
50.0600 225.0000 1.0000
50.1200 216.0000 1.0000
50.1800 210.0000 1.0000
50.2400 212.0000 1.0000
50.3000 206.0000 1.0000
50.3600 209.0000 1.0000
50.4200 196.0000 1.0000
50.4800 200.0000 1.0000
50.5400 203.0000 1.0000
50.6000 196.0000 1.0000
50.6600 219.0000 1.0000
50.7200 196.0000 1.0000
50.7800 207.0000 1.0000
50.8400 210.0000 1.0000
50.9000 185.0000 1.0000
50.9600 200.0000 1.0000
51.0200 167.0000 1.0000
51.0800 209.0000 1.0000
51.1400 209.0000 1.0000
51.2000 204.0000 1.0000
51.2600 214.0000 1.0000
51.3200 179.0000 1.0000
51.3800 215.0000 1.0000
51.4400 195.0000 1.0000
51.5000 182.0000 1.0000
51.5600 217.0000 1.0000
51.6200 187.0000 1.0000
51.6800 190.0000 1.0000
51.7400 190.0000 1.0000
51.8000 227.0000 1.0000
51.8600 206.0000 1.0000
51.9200 186.0000 1.0000
51.9800 235.0000 1.0000
52.0400 241.0000 1.0000
52.1000 277.0000 1.0000
52.1600 350.0000 1.0000
52.2200 530.0000 1.0000
52.2800 559.0000 1.0000
52.3400 480.0000 1.0000
52.4000 490.0000 1.0000
52.4600 411.0000 1.0000
52.5200 276.0000 1.0000
52.5800 217.0000 1.0000
52.6400 229.0000 1.0000
52.7000 243.0000 1.0000
52.7600 230.0000 1.0000
52.8200 204.0000 1.0000
52.8800 190.0000 1.0000
52.9400 201.0000 1.0000
53.0000 211.0000 1.0000
53.0600 208.0000 1.0000
53.1200 196.0000 1.0000
53.1800 182.0000 1.0000
53.2400 189.0000 1.0000
53.3000 174.0000 1.0000
53.3600 184.0000 1.0000
53.4200 193.0000 1.0000
53.4800 200.0000 1.0000
53.5400 170.0000 1.0000
53.6000 161.0000 1.0000
53.6600 193.0000 1.0000
53.7200 201.0000 1.0000
53.7800 181.0000 1.0000
53.8400 174.0000 1.0000
53.9000 170.0000 1.0000
53.9600 184.0000 1.0000
54.0200 177.0000 1.0000
54.0800 179.0000 1.0000
54.1400 192.0000 1.0000
54.2000 188.0000 1.0000
54.2600 164.0000 1.0000
54.3200 188.0000 1.0000
54.3800 189.0000 1.0000
54.4400 209.0000 1.0000
54.5000 157.0000 1.0000
54.5600 171.0000 1.0000
54.6200 183.0000 1.0000
54.6800 186.0000 1.0000
54.7400 168.0000 1.0000
54.8000 182.0000 1.0000
54.8600 184.0000 1.0000
54.9200 186.0000 1.0000
54.9800 170.0000 1.0000
55.0400 195.0000 1.0000
55.1000 187.0000 1.0000
55.1600 198.0000 1.0000
55.2200 214.0000 1.0000
55.2800 220.0000 1.0000
55.3400 214.0000 1.0000
55.4000 200.0000 1.0000
55.4600 216.0000 1.0000
55.5200 194.0000 1.0000
55.5800 189.0000 1.0000
55.6400 191.0000 1.0000
55.7000 170.0000 1.0000
55.7600 172.0000 1.0000
55.8200 204.0000 1.0000
55.8800 189.0000 1.0000
55.9400 175.0000 1.0000
56.0000 184.0000 1.0000
56.0600 181.0000 1.0000
56.1200 176.0000 1.0000
56.1800 182.0000 1.0000
56.2400 172.0000 1.0000
56.3000 171.0000 1.0000
56.3600 175.0000 1.0000
56.4200 161.0000 1.0000
56.4800 187.0000 1.0000
56.5400 183.0000 1.0000
56.6000 167.0000 1.0000
56.6600 174.0000 1.0000
56.7200 165.0000 1.0000
56.7800 166.0000 1.0000
56.8400 173.0000 1.0000
56.9000 172.0000 1.0000
56.9600 166.0000 1.0000
57.0200 171.0000 1.0000
57.0800 168.0000 1.0000
57.1400 168.0000 1.0000
57.2000 200.0000 1.0000
57.2600 170.0000 1.0000
57.3200 176.0000 1.0000
57.3800 170.0000 1.0000
57.4400 171.0000 1.0000
57.5000 153.0000 1.0000
57.5600 179.0000 1.0000
57.6200 159.0000 1.0000
57.6800 166.0000 1.0000
57.7400 156.0000 1.0000
57.8000 156.0000 1.0000
57.8600 170.0000 1.0000
57.9200 180.0000 1.0000
57.9800 172.0000 1.0000
58.0400 171.0000 1.0000
58.1000 142.0000 1.0000
58.1600 182.0000 1.0000
58.2200 173.0000 1.0000
58.2800 164.0000 1.0000
58.3400 169.0000 1.0000
58.4000 173.0000 1.0000
58.4600 188.0000 1.0000
58.5200 184.0000 1.0000
58.5800 179.0000 1.0000
58.6400 169.0000 1.0000
58.7000 156.0000 1.0000
58.7600 171.0000 1.0000
58.8200 189.0000 1.0000
58.8800 161.0000 1.0000
58.9400 166.0000 1.0000
59.0000 163.0000 1.0000
59.0600 153.0000 1.0000
59.1200 168.0000 1.0000
59.1800 153.0000 1.0000
59.2400 156.0000 1.0000
59.3000 165.0000 1.0000
59.3600 162.0000 1.0000
59.4200 159.0000 1.0000
59.4800 146.0000 1.0000
59.5400 163.0000 1.0000
59.6000 163.0000 1.0000
59.6600 162.0000 1.0000
59.7200 149.0000 1.0000
59.7800 149.0000 1.0000
59.8400 160.0000 1.0000
59.9000 166.0000 1.0000
59.9600 157.0000 1.0000
60.0200 164.0000 1.0000
60.0800 159.0000 1.0000
60.1400 157.0000 1.0000
60.2000 165.0000 1.0000
60.2600 160.0000 1.0000
60.3200 163.0000 1.0000
60.3800 156.0000 1.0000
60.4400 175.0000 1.0000
60.5000 167.0000 1.0000
60.5600 161.0000 1.0000
60.6200 170.0000 1.0000
60.6800 161.0000 1.0000
60.7400 146.0000 1.0000
60.8000 147.0000 1.0000
60.8600 149.0000 1.0000
60.9200 155.0000 1.0000
60.9800 150.0000 1.0000
61.0400 181.0000 1.0000
61.1000 161.0000 1.0000
61.1600 158.0000 1.0000
61.2200 170.0000 1.0000
61.2800 193.0000 1.0000
61.3400 161.0000 1.0000
61.4000 181.0000 1.0000
61.4600 166.0000 1.0000
61.5200 168.0000 1.0000
61.5800 175.0000 1.0000
61.6400 169.0000 1.0000
61.7000 180.0000 1.0000
61.7600 181.0000 1.0000
61.8200 162.0000 1.0000
61.8800 173.0000 1.0000
61.9400 164.0000 1.0000
62.0000 193.0000 1.0000
62.0600 192.0000 1.0000
62.1200 183.0000 1.0000
62.1800 258.0000 1.0000
62.2400 263.0000 1.0000
62.3000 272.0000 1.0000
62.3600 269.0000 1.0000
62.4200 255.0000 1.0000
62.4800 209.0000 1.0000
62.5400 224.0000 1.0000
62.6000 208.0000 1.0000
62.6600 197.0000 1.0000
62.7200 166.0000 1.0000
62.7800 178.0000 1.0000
62.8400 163.0000 1.0000
62.9000 176.0000 1.0000
62.9600 169.0000 1.0000
63.0200 162.0000 1.0000
63.0800 171.0000 1.0000
63.1400 151.0000 1.0000
63.2000 157.0000 1.0000
63.2600 162.0000 1.0000
63.3200 169.0000 1.0000
63.3800 165.0000 1.0000
63.4400 151.0000 1.0000
63.5000 161.0000 1.0000
63.5600 151.0000 1.0000
63.6200 150.0000 1.0000
63.6800 165.0000 1.0000
63.7400 151.0000 1.0000
63.8000 181.0000 1.0000
63.8600 140.0000 1.0000
63.9200 147.0000 1.0000
63.9800 154.0000 1.0000
64.0400 184.0000 1.0000
64.1000 151.0000 1.0000
64.1600 172.0000 1.0000
64.2200 161.0000 1.0000
64.2800 140.0000 1.0000
64.3400 159.0000 1.0000
64.4000 179.0000 1.0000
64.4600 171.0000 1.0000
64.5200 203.0000 1.0000
64.5800 158.0000 1.0000
64.6400 187.0000 1.0000
64.7000 179.0000 1.0000
64.7600 182.0000 1.0000
64.8200 197.0000 1.0000
64.8800 192.0000 1.0000
64.9400 187.0000 1.0000
65.0000 206.0000 1.0000
65.0600 187.0000 1.0000
65.1200 180.0000 1.0000
65.1800 163.0000 1.0000
65.2400 158.0000 1.0000
65.3000 180.0000 1.0000
65.3600 169.0000 1.0000
65.4200 182.0000 1.0000
65.4800 169.0000 1.0000
65.5400 149.0000 1.0000
65.6000 157.0000 1.0000
65.6600 169.0000 1.0000
65.7200 167.0000 1.0000
65.7800 173.0000 1.0000
65.8400 176.0000 1.0000
65.9000 188.0000 1.0000
65.9600 189.0000 1.0000
66.0200 187.0000 1.0000
66.0800 230.0000 1.0000
66.1400 308.0000 1.0000
66.2000 370.0000 1.0000
66.2600 377.0000 1.0000
66.3200 375.0000 1.0000
66.3800 372.0000 1.0000
66.4400 342.0000 1.0000
66.5000 296.0000 1.0000
66.5600 256.0000 1.0000
66.6200 205.0000 1.0000
66.6800 189.0000 1.0000
66.7400 171.0000 1.0000
66.8000 159.0000 1.0000
66.8600 181.0000 1.0000
66.9200 139.0000 1.0000
66.9800 155.0000 1.0000
67.0400 146.0000 1.0000
67.1000 157.0000 1.0000
67.1600 169.0000 1.0000
67.2200 162.0000 1.0000
67.2800 165.0000 1.0000
67.3400 149.0000 1.0000
67.4000 149.0000 1.0000
67.4600 155.0000 1.0000
67.5200 158.0000 1.0000
67.5800 163.0000 1.0000
67.6400 167.0000 1.0000
67.7000 131.0000 1.0000
67.7600 141.0000 1.0000
67.8200 167.0000 1.0000
67.8800 154.0000 1.0000
67.9400 168.0000 1.0000
68.0000 145.0000 1.0000
68.0600 166.0000 1.0000
68.1200 146.0000 1.0000
68.1800 138.0000 1.0000
68.2400 134.0000 1.0000
68.3000 158.0000 1.0000
68.3600 148.0000 1.0000
68.4200 151.0000 1.0000
68.4800 148.0000 1.0000
68.5400 149.0000 1.0000
68.6000 136.0000 1.0000
68.6600 145.0000 1.0000
68.7200 146.0000 1.0000
68.7800 155.0000 1.0000
68.8400 163.0000 1.0000
68.9000 144.0000 1.0000
68.9600 136.0000 1.0000
69.0200 122.0000 1.0000
69.0800 136.0000 1.0000
69.1400 141.0000 1.0000
69.2000 130.0000 1.0000
69.2600 156.0000 1.0000
69.3200 154.0000 1.0000
69.3800 164.0000 1.0000
69.4400 166.0000 1.0000
69.5000 151.0000 1.0000
69.5600 158.0000 1.0000
69.6200 171.0000 1.0000
69.6800 154.0000 1.0000
69.7400 141.0000 1.0000
69.8000 152.0000 1.0000
69.8600 132.0000 1.0000
69.9200 145.0000 1.0000
69.9800 153.0000 1.0000
70.0400 148.0000 1.0000
70.1000 147.0000 1.0000
70.1600 176.0000 1.0000
70.2200 151.0000 1.0000
70.2800 144.0000 1.0000
70.3400 127.0000 1.0000
70.4000 170.0000 1.0000
70.4600 149.0000 1.0000
70.5200 143.0000 1.0000
70.5800 142.0000 1.0000
70.6400 138.0000 1.0000
70.7000 156.0000 1.0000
70.7600 147.0000 1.0000
70.8200 148.0000 1.0000
70.8800 144.0000 1.0000
70.9400 146.0000 1.0000
71.0000 155.0000 1.0000
71.0600 130.0000 1.0000
71.1200 146.0000 1.0000
71.1800 151.0000 1.0000
71.2400 162.0000 1.0000
71.3000 141.0000 1.0000
71.3600 160.0000 1.0000
71.4200 154.0000 1.0000
71.4800 149.0000 1.0000
71.5400 145.0000 1.0000
71.6000 182.0000 1.0000
71.6600 149.0000 1.0000
71.7200 164.0000 1.0000
71.7800 145.0000 1.0000
71.8400 166.0000 1.0000
71.9000 149.0000 1.0000
71.9600 134.0000 1.0000
72.0200 148.0000 1.0000
72.0800 145.0000 1.0000
72.1400 132.0000 1.0000
72.2000 130.0000 1.0000
72.2600 157.0000 1.0000
72.3200 147.0000 1.0000
72.3800 134.0000 1.0000
72.4400 153.0000 1.0000
72.5000 147.0000 1.0000
72.5600 137.0000 1.0000
72.6200 142.0000 1.0000
72.6800 157.0000 1.0000
72.7400 118.0000 1.0000
72.8000 133.0000 1.0000
72.8600 132.0000 1.0000
72.9200 132.0000 1.0000
72.9800 140.0000 1.0000
73.0400 143.0000 1.0000
73.1000 155.0000 1.0000
73.1600 140.0000 1.0000
73.2200 144.0000 1.0000
73.2800 161.0000 1.0000
73.3400 140.0000 1.0000
73.4000 145.0000 1.0000
73.4600 148.0000 1.0000
73.5200 145.0000 1.0000
73.5800 130.0000 1.0000
73.6400 160.0000 1.0000
73.7000 133.0000 1.0000
73.7600 125.0000 1.0000
73.8200 156.0000 1.0000
73.8800 163.0000 1.0000
73.9400 132.0000 1.0000
74.0000 123.0000 1.0000
74.0600 133.0000 1.0000
74.1200 145.0000 1.0000
74.1800 125.0000 1.0000
74.2400 127.0000 1.0000
74.3000 145.0000 1.0000
74.3600 138.0000 1.0000
74.4200 145.0000 1.0000
74.4800 124.0000 1.0000
74.5400 162.0000 1.0000
74.6000 133.0000 1.0000
74.6600 138.0000 1.0000
74.7200 123.0000 1.0000
74.7800 138.0000 1.0000
74.8400 155.0000 1.0000
74.9000 165.0000 1.0000
74.9600 162.0000 1.0000
75.0200 152.0000 1.0000
75.0800 134.0000 1.0000
75.1400 126.0000 1.0000
75.2000 166.0000 1.0000
75.2600 145.0000 1.0000
75.3200 138.0000 1.0000
75.3800 138.0000 1.0000
75.4400 136.0000 1.0000
75.5000 153.0000 1.0000
75.5600 122.0000 1.0000
75.6200 145.0000 1.0000
75.6800 143.0000 1.0000
75.7400 137.0000 1.0000
75.8000 138.0000 1.0000
75.8600 145.0000 1.0000
75.9200 130.0000 1.0000
75.9800 151.0000 1.0000
76.0400 135.0000 1.0000
76.1000 163.0000 1.0000
76.1600 132.0000 1.0000
76.2200 163.0000 1.0000
76.2800 137.0000 1.0000
76.3400 159.0000 1.0000
76.4000 161.0000 1.0000
76.4600 157.0000 1.0000
76.5200 137.0000 1.0000
76.5800 145.0000 1.0000
76.6400 154.0000 1.0000
76.7000 133.0000 1.0000
76.7600 154.0000 1.0000
76.8200 132.0000 1.0000
76.8800 137.0000 1.0000
76.9400 113.0000 1.0000
77.0000 153.0000 1.0000
77.0600 147.0000 1.0000
77.1200 142.0000 1.0000
77.1800 124.0000 1.0000
77.2400 140.0000 1.0000
77.3000 142.0000 1.0000
77.3600 128.0000 1.0000
77.4200 137.0000 1.0000
77.4800 145.0000 1.0000
77.5400 139.0000 1.0000
77.6000 163.0000 1.0000
77.6600 138.0000 1.0000
77.7200 131.0000 1.0000
77.7800 158.0000 1.0000
77.8400 147.0000 1.0000
77.9000 145.0000 1.0000
77.9600 177.0000 1.0000
78.0200 141.0000 1.0000
78.0800 151.0000 1.0000
78.1400 157.0000 1.0000
78.2000 146.0000 1.0000
78.2600 133.0000 1.0000
78.3200 141.0000 1.0000
78.3800 164.0000 1.0000
78.4400 143.0000 1.0000
78.5000 124.0000 1.0000
78.5600 158.0000 1.0000
78.6200 148.0000 1.0000
78.6800 155.0000 1.0000
78.7400 142.0000 1.0000
78.8000 158.0000 1.0000
78.8600 195.0000 1.0000
78.9200 188.0000 1.0000
78.9800 212.0000 1.0000
79.0400 200.0000 1.0000
79.1000 187.0000 1.0000
79.1600 183.0000 1.0000
79.2200 180.0000 1.0000
79.2800 172.0000 1.0000
79.3400 167.0000 1.0000
79.4000 175.0000 1.0000
79.4600 143.0000 1.0000
79.5200 148.0000 1.0000
79.5800 153.0000 1.0000
79.6400 148.0000 1.0000
79.7000 145.0000 1.0000
79.7600 151.0000 1.0000
79.8200 148.0000 1.0000
79.8800 151.0000 1.0000
79.9400 145.0000 1.0000
80.0000 159.0000 1.0000
*RAS_INT_END
*RAS_TEMPERATURE_START
*RAS_TEMPERATURE_END
*RAS_DATA_END