File: Sectio1_28_samples/XRD/No_014_650_18.ras
*RAS_DATA_START
*RAS_HEADER_START
*DISP_FMT_X "%.2f"
*DISP_FMT_Y "%.0f"
*DISP_FULLSCALE "3782.0000000000"
*DISP_LINE_COLOR "255.0000000000"
*DISP_LINE_STYLE "0.0000000000"
*DISP_LINE_WIDTH "0.2500000000"
*DISP_NOTE "測定データ-2"
*DISP_OFFSET_Y "0.0000000000"
*DISP_PEAKSEARCH_UNIT_Y "cps"
*DISP_RANGE_BOTTOM "0.0000000000"
*DISP_RANGE_LEFT "20.0000000000"
*DISP_RANGE_LOGCUTOFF "0.0100000000"
*DISP_RANGE_RIGHT "80.0000000000"
*DISP_RANGE_TOP "3782.0000000000"
*DISP_SCALE_MODE_Y "0.0000000000"
*DISP_TAB_NAME "2θ/θ"
*DISP_TITLE_Y "強度"
*DISP_UNIT_Y "cps"
*DISP_WINDOW_NAME "MSG_MACROENGINE"
*FILE_COMMENT " "
*FILE_MD5 ""
*FILE_MEMO " "
*FILE_OPERATOR "Administrator"
*FILE_SAMPLE " "
*FILE_TYPE "RAS_RAW"
*FILE_USERGROUP "システムマネージャ"
*FILE_VERSION "1.0000000000"
*HW_ATTACHMENT_ID "ATT0025"
*HW_ATTACHMENT_NAME "標準|Standard"
*HW_COUNTER_ID-0 "CUT0025"
*HW_COUNTER_ID-1 "CUT0020"
*HW_COUNTER_ID-2 "CUT0020"
*HW_COUNTER_ID-3 "CSL0021"
*HW_COUNTER_ID-4 "CMC0021"
*HW_COUNTER_NAME-0 "D/teX Ultra|D/teX Ultra"
*HW_COUNTER_NAME-1 "None|None"
*HW_COUNTER_NAME-2 "None|None"
*HW_COUNTER_NAME-3 "BBM|BBM"
*HW_COUNTER_NAME-4 "検出器モノクロメータ|Detector monochromator"
*HW_COUNTER_SELECT_NAME "D/teX Ultra|D/teX Ultra"
*HW_GONIOMETER_ID "GON0023"
*HW_GONIOMETER_NAME "SmartLab|SmartLab"
*HW_GONIOMETER_RADIUS-0 "90.0"
*HW_GONIOMETER_RADIUS-1 "114.0"
*HW_GONIOMETER_RADIUS-2 "190.0"
*HW_GONIOMETER_RADIUS-3 "300.0"
*HW_GONIOMETER_RADIUS-4 "187.0"
*HW_GONIOMETER_RADIUS-5 "300.0"
*HW_GONIOMETER_RADIUS-6 "113.0"
*HW_GONIOMETER_RADIUS-7 "331.0"
*HW_I_OPT_ID-0 "CBO0021"
*HW_I_OPT_ID-1 "ICR0023"
*HW_I_OPT_ID-2 "ISL0021"
*HW_I_OPT_ID-3 "ISO0021"
*HW_I_OPT_ID-4 "IAD0021"
*HW_I_OPT_ID-5 "IPR0001"
*HW_I_OPT_NAME-0 "CBOユニット|CBO unit"
*HW_I_OPT_NAME-1 "標準入射光学ユニット|Standard incident optical unit"
*HW_I_OPT_NAME-2 "標準入射スリットボックス|Standard incident slit box"
*HW_I_OPT_NAME-3 "入射平行スリット|Incident parallel slit"
*HW_I_OPT_NAME-4 "長手制限スリット|Length limiting slit"
*HW_I_OPT_NAME-5 "None|None"
*HW_R_ATTENUATER_AUTOMODE "0"
*HW_R_OPT_ID-0 "RSS0021"
*HW_R_OPT_ID-1 "RCR0023"
*HW_R_OPT_ID-2 "RSO0021"
*HW_R_OPT_ID-3 "RRS0021"
*HW_R_OPT_ID-4 "ATN0021"
*HW_R_OPT_ID-5 "RFL0021"
*HW_R_OPT_ID-6 "RAD0021"
*HW_R_OPT_NAME-0 "標準受光スリットボックス1|Standard receiving slit box # 1"
*HW_R_OPT_NAME-1 "標準受光光学ユニット1|Standard receiving unit # 1"
*HW_R_OPT_NAME-2 "標準受光光学ユニット2|Standard receiving optical unit # 2"
*HW_R_OPT_NAME-3 "標準受光スリットボックス2|Standard receiving slit box # 2"
*HW_R_OPT_NAME-4 "標準アッテネータ|Standard Attenuator"
*HW_R_OPT_NAME-5 "Cu Kβ|Cu K-beta"
*HW_R_OPT_NAME-6 "調整用受光スリット|Alignment receiving slit"
*HW_SAMPLE_HOLDER_ID "SMP0023"
*HW_SAMPLE_HOLDER_NAME "標準Zステージ|Standard Z stage"
*HW_XG_CURRENT_MAX "50"
*HW_XG_CURRENT_MIN "2"
*HW_XG_CURRENT_RESOLUTION "2"
*HW_XG_CURRENT_UNIT "mA"
*HW_XG_FOCUS "1mm x 10mm"
*HW_XG_FOCUS_TYPE "Normal"
*HW_XG_ID ""
*HW_XG_NAME "3kW 封入管(ID:1200)|3kW Sealed tube(ID:1200)"
*HW_XG_TARGET_ATOMIC_NUMBER "29.0000000000"
*HW_XG_TARGET_NAME "Cu"
*HW_XG_TYPE "Hermetic"
*HW_XG_VOLTAGE_MAX "60"
*HW_XG_VOLTAGE_MIN "20"
*HW_XG_VOLTAGE_RESOLUTION "2"
*HW_XG_VOLTAGE_UNIT "kV"
*HW_XG_WATT_MAX "2"
*HW_XG_WATT_UNIT "kW"
*HW_XG_WAVE_LENGTH_ALPHA1 "1.540593"
*HW_XG_WAVE_LENGTH_ALPHA2 "1.544414"
*HW_XG_WAVE_LENGTH_BETA "1.392250"
*MEAS_COND_AXIS_NAME-0 "2θ/θ"
*MEAS_COND_AXIS_NAME-1 "2θ"
*MEAS_COND_AXIS_NAME-2 "ω"
*MEAS_COND_AXIS_NAME-3 "Z"
*MEAS_COND_AXIS_NAME-4 "2θ/ω"
*MEAS_COND_AXIS_NAME-5 "θs"
*MEAS_COND_AXIS_NAME-6 "θd"
*MEAS_COND_AXIS_NAME-7 "Ts"
*MEAS_COND_AXIS_NAME-8 "CBO選択スリット"
*MEAS_COND_AXIS_NAME-9 "M"
*MEAS_COND_AXIS_NAME-10 "入射平行スリット"
*MEAS_COND_AXIS_NAME-11 "入射スリット"
*MEAS_COND_AXIS_NAME-12 ""
*MEAS_COND_AXIS_NAME-13 "Zs"
*MEAS_COND_AXIS_NAME-14 "入射光学素子"
*MEAS_COND_AXIS_NAME-15 "長手制限スリット"
*MEAS_COND_AXIS_NAME-16 "センタースリット"
*MEAS_COND_AXIS_NAME-17 "フィルター"
*MEAS_COND_AXIS_NAME-18 "受光スリット1"
*MEAS_COND_AXIS_NAME-19 "受光スリット2"
*MEAS_COND_AXIS_NAME-20 "受光光学素子"
*MEAS_COND_AXIS_NAME-21 "受光平行スリット"
*MEAS_COND_AXIS_NAME-22 "調整用受光スリット"
*MEAS_COND_AXIS_NAME-23 ""
*MEAS_COND_AXIS_NAME-24 ""
*MEAS_COND_AXIS_NAME-25 "Zd"
*MEAS_COND_AXIS_NAME-26 "アッテネータ"
*MEAS_COND_AXIS_NAME-27 "検出器モノクロメータ"
*MEAS_COND_AXIS_NAME-28 "モノクロメータスリット"
*MEAS_COND_AXIS_NAME-29 "プライマリビーム"
*MEAS_COND_AXIS_NAME-30 "PHA"
*MEAS_COND_AXIS_NAME_INTERNAL-0 "TwoThetaTheta"
*MEAS_COND_AXIS_NAME_INTERNAL-1 "TwoTheta"
*MEAS_COND_AXIS_NAME_INTERNAL-2 "Omega"
*MEAS_COND_AXIS_NAME_INTERNAL-3 "Z"
*MEAS_COND_AXIS_NAME_INTERNAL-4 "TwoThetaOmega"
*MEAS_COND_AXIS_NAME_INTERNAL-5 "ThetaS"
*MEAS_COND_AXIS_NAME_INTERNAL-6 "ThetaD"
*MEAS_COND_AXIS_NAME_INTERNAL-7 "Ts"
*MEAS_COND_AXIS_NAME_INTERNAL-8 "CBO"
*MEAS_COND_AXIS_NAME_INTERNAL-9 "CBO-M"
*MEAS_COND_AXIS_NAME_INTERNAL-10 "IncidentSollerSlit"
*MEAS_COND_AXIS_NAME_INTERNAL-11 "IncidentSlitBox"
*MEAS_COND_AXIS_NAME_INTERNAL-12 "IncidentSlitBox-_Axis"
*MEAS_COND_AXIS_NAME_INTERNAL-13 "Zs"
*MEAS_COND_AXIS_NAME_INTERNAL-14 "IncidentMonochromator"
*MEAS_COND_AXIS_NAME_INTERNAL-15 "IncidentAxdSlit"
*MEAS_COND_AXIS_NAME_INTERNAL-16 "CenterSlit"
*MEAS_COND_AXIS_NAME_INTERNAL-17 "Filter"
*MEAS_COND_AXIS_NAME_INTERNAL-18 "ReceivingSlitBox1"
*MEAS_COND_AXIS_NAME_INTERNAL-19 "ReceivingSlitBox2"
*MEAS_COND_AXIS_NAME_INTERNAL-20 "ReceivingOptics"
*MEAS_COND_AXIS_NAME_INTERNAL-21 "ReceivingSollerSlit"
*MEAS_COND_AXIS_NAME_INTERNAL-22 "ReceivingAxdSlit"
*MEAS_COND_AXIS_NAME_INTERNAL-23 "ReceivingSlitBox1-_Axis"
*MEAS_COND_AXIS_NAME_INTERNAL-24 "ReceivingSlitBox2-_Axis"
*MEAS_COND_AXIS_NAME_INTERNAL-25 "ReceivingSlitBox2-Zd"
*MEAS_COND_AXIS_NAME_INTERNAL-26 "Attenuator"
*MEAS_COND_AXIS_NAME_INTERNAL-27 "CounterMonochromator"
*MEAS_COND_AXIS_NAME_INTERNAL-28 "CounterSlit"
*MEAS_COND_AXIS_NAME_INTERNAL-29 "IncidentPrimary"
*MEAS_COND_AXIS_NAME_INTERNAL-30 "PHA"
*MEAS_COND_AXIS_NAME_MAGICNO-0 "83951616.0000000000"
*MEAS_COND_AXIS_NAME_MAGICNO-1 "268632064.0000000000"
*MEAS_COND_AXIS_NAME_MAGICNO-2 "268500992.0000000000"
*MEAS_COND_AXIS_NAME_MAGICNO-3 "285278208.0000000000"
*MEAS_COND_AXIS_NAME_MAGICNO-4 "83951616.0000000000"
*MEAS_COND_AXIS_NAME_MAGICNO-5 "131072.0000000000"
*MEAS_COND_AXIS_NAME_MAGICNO-6 "131072.0000000000"
*MEAS_COND_AXIS_NAME_MAGICNO-7 "318898176.0000000000"
*MEAS_COND_AXIS_NAME_MAGICNO-8 "20971521.0000000000"
*MEAS_COND_AXIS_NAME_MAGICNO-9 "285343744.0000000000"
*MEAS_COND_AXIS_NAME_MAGICNO-10 "20971521.0000000000"
*MEAS_COND_AXIS_NAME_MAGICNO-11 "22020097.0000000000"
*MEAS_COND_AXIS_NAME_MAGICNO-12 "25165824.0000000000"
*MEAS_COND_AXIS_NAME_MAGICNO-13 "318898176.0000000000"
*MEAS_COND_AXIS_NAME_MAGICNO-14 "1.0000000000"
*MEAS_COND_AXIS_NAME_MAGICNO-15 "20971521.0000000000"
*MEAS_COND_AXIS_NAME_MAGICNO-16 "20971521.0000000000"
*MEAS_COND_AXIS_NAME_MAGICNO-17 "20971521.0000000000"
*MEAS_COND_AXIS_NAME_MAGICNO-18 "23068673.0000000000"
*MEAS_COND_AXIS_NAME_MAGICNO-19 "23068673.0000000000"
*MEAS_COND_AXIS_NAME_MAGICNO-20 "20971521.0000000000"
*MEAS_COND_AXIS_NAME_MAGICNO-21 "20971521.0000000000"
*MEAS_COND_AXIS_NAME_MAGICNO-22 "20971521.0000000000"
*MEAS_COND_AXIS_NAME_MAGICNO-23 "25165824.0000000000"
*MEAS_COND_AXIS_NAME_MAGICNO-24 "25165824.0000000000"
*MEAS_COND_AXIS_NAME_MAGICNO-25 "285343744.0000000000"
*MEAS_COND_AXIS_NAME_MAGICNO-26 "17301505.0000000000"
*MEAS_COND_AXIS_NAME_MAGICNO-27 "20971521.0000000000"
*MEAS_COND_AXIS_NAME_MAGICNO-28 "20971521.0000000000"
*MEAS_COND_AXIS_NAME_MAGICNO-29 "20971521.0000000000"
*MEAS_COND_AXIS_NAME_MAGICNO-30 "0.0000000000"
*MEAS_COND_AXIS_OFFSET-0 "-"
*MEAS_COND_AXIS_OFFSET-1 "-0.1081000000"
*MEAS_COND_AXIS_OFFSET-2 "0.3758000000"
*MEAS_COND_AXIS_OFFSET-3 "-"
*MEAS_COND_AXIS_OFFSET-4 "-"
*MEAS_COND_AXIS_OFFSET-5 "0.3758000000"
*MEAS_COND_AXIS_OFFSET-6 "-0.4839000000"
*MEAS_COND_AXIS_OFFSET-7 "-"
*MEAS_COND_AXIS_OFFSET-8 "-"
*MEAS_COND_AXIS_OFFSET-9 "-"
*MEAS_COND_AXIS_OFFSET-10 "-"
*MEAS_COND_AXIS_OFFSET-11 "-"
*MEAS_COND_AXIS_OFFSET-12 "-"
*MEAS_COND_AXIS_OFFSET-13 "-"
*MEAS_COND_AXIS_OFFSET-14 "-"
*MEAS_COND_AXIS_OFFSET-15 "-"
*MEAS_COND_AXIS_OFFSET-16 "-"
*MEAS_COND_AXIS_OFFSET-17 "-"
*MEAS_COND_AXIS_OFFSET-18 "-"
*MEAS_COND_AXIS_OFFSET-19 "-"
*MEAS_COND_AXIS_OFFSET-20 "-"
*MEAS_COND_AXIS_OFFSET-21 "-"
*MEAS_COND_AXIS_OFFSET-22 "-"
*MEAS_COND_AXIS_OFFSET-23 "-"
*MEAS_COND_AXIS_OFFSET-24 "-"
*MEAS_COND_AXIS_OFFSET-25 "-"
*MEAS_COND_AXIS_OFFSET-26 "-"
*MEAS_COND_AXIS_OFFSET-27 "-"
*MEAS_COND_AXIS_OFFSET-28 "-"
*MEAS_COND_AXIS_OFFSET-29 "-"
*MEAS_COND_AXIS_OFFSET-30 "-"
*MEAS_COND_AXIS_POSITION-0 "0.0000000000"
*MEAS_COND_AXIS_POSITION-1 "0.0000000000"
*MEAS_COND_AXIS_POSITION-2 "0.0000000000"
*MEAS_COND_AXIS_POSITION-3 "-0.5500000000"
*MEAS_COND_AXIS_POSITION-4 "0.0000000000"
*MEAS_COND_AXIS_POSITION-5 "0.0000000000"
*MEAS_COND_AXIS_POSITION-6 "0.0000000000"
*MEAS_COND_AXIS_POSITION-7 "-0.4278800000"
*MEAS_COND_AXIS_POSITION-8 "BB"
*MEAS_COND_AXIS_POSITION-9 "0.0000000000"
*MEAS_COND_AXIS_POSITION-10 "Soller_slit_5.0deg"
*MEAS_COND_AXIS_POSITION-11 "2/3deg"
*MEAS_COND_AXIS_POSITION-12 "2.2088000000"
*MEAS_COND_AXIS_POSITION-13 "-0.4140600000"
*MEAS_COND_AXIS_POSITION-14 "0.0000000000"
*MEAS_COND_AXIS_POSITION-15 "10.0mm"
*MEAS_COND_AXIS_POSITION-16 "None"
*MEAS_COND_AXIS_POSITION-17 "Cu_K-beta"
*MEAS_COND_AXIS_POSITION-18 "13.000mm"
*MEAS_COND_AXIS_POSITION-19 "13.000mm"
*MEAS_COND_AXIS_POSITION-20 "No_unit"
*MEAS_COND_AXIS_POSITION-21 "Soller_slit_5.0deg"
*MEAS_COND_AXIS_POSITION-22 "None"
*MEAS_COND_AXIS_POSITION-23 "13.0000000000"
*MEAS_COND_AXIS_POSITION-24 "13.0000000000"
*MEAS_COND_AXIS_POSITION-25 "0.0109400000"
*MEAS_COND_AXIS_POSITION-26 "Open"
*MEAS_COND_AXIS_POSITION-27 "None"
*MEAS_COND_AXIS_POSITION-28 "None"
*MEAS_COND_AXIS_POSITION-29 "None"
*MEAS_COND_AXIS_POSITION-30 "38.0000000000"
*MEAS_COND_AXIS_UNIT-0 "deg"
*MEAS_COND_AXIS_UNIT-1 "deg"
*MEAS_COND_AXIS_UNIT-2 "deg"
*MEAS_COND_AXIS_UNIT-3 "mm"
*MEAS_COND_AXIS_UNIT-4 "deg"
*MEAS_COND_AXIS_UNIT-5 "deg"
*MEAS_COND_AXIS_UNIT-6 "deg"
*MEAS_COND_AXIS_UNIT-7 "mm"
*MEAS_COND_AXIS_UNIT-8 ""
*MEAS_COND_AXIS_UNIT-9 "pulse"
*MEAS_COND_AXIS_UNIT-10 ""
*MEAS_COND_AXIS_UNIT-11 ""
*MEAS_COND_AXIS_UNIT-12 "mm"
*MEAS_COND_AXIS_UNIT-13 "mm"
*MEAS_COND_AXIS_UNIT-14 ""
*MEAS_COND_AXIS_UNIT-15 ""
*MEAS_COND_AXIS_UNIT-16 ""
*MEAS_COND_AXIS_UNIT-17 ""
*MEAS_COND_AXIS_UNIT-18 ""
*MEAS_COND_AXIS_UNIT-19 ""
*MEAS_COND_AXIS_UNIT-20 ""
*MEAS_COND_AXIS_UNIT-21 ""
*MEAS_COND_AXIS_UNIT-22 ""
*MEAS_COND_AXIS_UNIT-23 "mm"
*MEAS_COND_AXIS_UNIT-24 "mm"
*MEAS_COND_AXIS_UNIT-25 "mm"
*MEAS_COND_AXIS_UNIT-26 ""
*MEAS_COND_AXIS_UNIT-27 ""
*MEAS_COND_AXIS_UNIT-28 ""
*MEAS_COND_AXIS_UNIT-29 ""
*MEAS_COND_AXIS_UNIT-30 "div"
*MEAS_COND_COUNTER_CNTLOSS_CORR "0.0000000000"
*MEAS_COND_COUNTER_PHABASE "38.0000000000"
*MEAS_COND_COUNTER_PHAWINDOW "16.0000000000"
*MEAS_COND_COUNTER_PHA_UNIT "div"
*MEAS_COND_COUNTER_TAUDIFF "30.0000000000"
*MEAS_COND_COUNTER_TAUINT "0.0000000000"
*MEAS_COND_IRRADIATION_MODE "OFF"
*MEAS_COND_IRRADIATION_WIDTH ""
*MEAS_COND_OPT_ATTR "集中法"
*MEAS_COND_OPT_NAME "@集中法"
*MEAS_COND_UNSYMMETRIC_MODE "OFF"
*MEAS_COND_XG_CURRENT "30.0000000000"
*MEAS_COND_XG_VOLTAGE "40.0000000000"
*MEAS_COND_XG_WAVE_TYPE "Ka"
*MEAS_DATA_COUNT "3001.0000000000"
*MEAS_SCAN_AXIS_X "2θ/θ"
*MEAS_SCAN_AXIS_X_INTERNAL "TwoThetaTheta"
*MEAS_SCAN_END_TIME "09/04/20 11:00:20"
*MEAS_SCAN_MODE "CONTINUOUS"
*MEAS_SCAN_MONITOR "0"
*MEAS_SCAN_RESOLUTION_X "0.0002"
*MEAS_SCAN_SPEED "2.0"
*MEAS_SCAN_SPEED_UNIT "deg/min"
*MEAS_SCAN_START "20.0000000000"
*MEAS_SCAN_START_TIME "09/04/20 10:28:40"
*MEAS_SCAN_STEP "0.0200000000"
*MEAS_SCAN_STOP "80.0000000000"
*MEAS_SCAN_UNIT_X "deg"
*MEAS_SCAN_UNIT_Y "counts"
*RAS_HEADER_END
*RAS_INT_START
20.0000 1891.0000 1.0000
20.0600 1760.0000 1.0000
20.1200 1787.0000 1.0000
20.1800 1699.0000 1.0000
20.2400 1863.0000 1.0000
20.3000 1776.0000 1.0000
20.3600 1716.0000 1.0000
20.4200 1776.0000 1.0000
20.4800 1784.0000 1.0000
20.5400 1674.0000 1.0000
20.6000 1741.0000 1.0000
20.6600 1741.0000 1.0000
20.7200 1727.0000 1.0000
20.7800 1701.0000 1.0000
20.8400 1678.0000 1.0000
20.9000 1652.0000 1.0000
20.9600 1656.0000 1.0000
21.0200 1692.0000 1.0000
21.0800 1679.0000 1.0000
21.1400 1751.0000 1.0000
21.2000 1688.0000 1.0000
21.2600 1644.0000 1.0000
21.3200 1584.0000 1.0000
21.3800 1595.0000 1.0000
21.4400 1597.0000 1.0000
21.5000 1609.0000 1.0000
21.5600 1602.0000 1.0000
21.6200 1524.0000 1.0000
21.6800 1518.0000 1.0000
21.7400 1606.0000 1.0000
21.8000 1566.0000 1.0000
21.8600 1530.0000 1.0000
21.9200 1543.0000 1.0000
21.9800 1560.0000 1.0000
22.0400 1481.0000 1.0000
22.1000 1448.0000 1.0000
22.1600 1477.0000 1.0000
22.2200 1476.0000 1.0000
22.2800 1466.0000 1.0000
22.3400 1447.0000 1.0000
22.4000 1371.0000 1.0000
22.4600 1518.0000 1.0000
22.5200 1448.0000 1.0000
22.5800 1448.0000 1.0000
22.6400 1537.0000 1.0000
22.7000 1448.0000 1.0000
22.7600 1428.0000 1.0000
22.8200 1441.0000 1.0000
22.8800 1357.0000 1.0000
22.9400 1397.0000 1.0000
23.0000 1398.0000 1.0000
23.0600 1328.0000 1.0000
23.1200 1355.0000 1.0000
23.1800 1377.0000 1.0000
23.2400 1334.0000 1.0000
23.3000 1400.0000 1.0000
23.3600 1401.0000 1.0000
23.4200 1356.0000 1.0000
23.4800 1320.0000 1.0000
23.5400 1368.0000 1.0000
23.6000 1361.0000 1.0000
23.6600 1348.0000 1.0000
23.7200 1277.0000 1.0000
23.7800 1338.0000 1.0000
23.8400 1291.0000 1.0000
23.9000 1312.0000 1.0000
23.9600 1298.0000 1.0000
24.0200 1327.0000 1.0000
24.0800 1242.0000 1.0000
24.1400 1300.0000 1.0000
24.2000 1214.0000 1.0000
24.2600 1268.0000 1.0000
24.3200 1227.0000 1.0000
24.3800 1291.0000 1.0000
24.4400 1250.0000 1.0000
24.5000 1203.0000 1.0000
24.5600 1216.0000 1.0000
24.6200 1244.0000 1.0000
24.6800 1281.0000 1.0000
24.7400 1227.0000 1.0000
24.8000 1212.0000 1.0000
24.8600 1195.0000 1.0000
24.9200 1262.0000 1.0000
24.9800 1223.0000 1.0000
25.0400 1188.0000 1.0000
25.1000 1216.0000 1.0000
25.1600 1180.0000 1.0000
25.2200 1168.0000 1.0000
25.2800 1176.0000 1.0000
25.3400 1135.0000 1.0000
25.4000 1124.0000 1.0000
25.4600 1175.0000 1.0000
25.5200 1139.0000 1.0000
25.5800 1104.0000 1.0000
25.6400 1151.0000 1.0000
25.7000 1181.0000 1.0000
25.7600 1138.0000 1.0000
25.8200 1161.0000 1.0000
25.8800 1109.0000 1.0000
25.9400 1129.0000 1.0000
26.0000 1146.0000 1.0000
26.0600 1101.0000 1.0000
26.1200 1102.0000 1.0000
26.1800 1105.0000 1.0000
26.2400 1053.0000 1.0000
26.3000 1044.0000 1.0000
26.3600 1073.0000 1.0000
26.4200 1056.0000 1.0000
26.4800 1070.0000 1.0000
26.5400 1019.0000 1.0000
26.6000 1054.0000 1.0000
26.6600 1090.0000 1.0000
26.7200 1090.0000 1.0000
26.7800 985.0000 1.0000
26.8400 1068.0000 1.0000
26.9000 1011.0000 1.0000
26.9600 1065.0000 1.0000
27.0200 1019.0000 1.0000
27.0800 1060.0000 1.0000
27.1400 1131.0000 1.0000
27.2000 1211.0000 1.0000
27.2600 1222.0000 1.0000
27.3200 1330.0000 1.0000
27.3800 1216.0000 1.0000
27.4400 1121.0000 1.0000
27.5000 1005.0000 1.0000
27.5600 1038.0000 1.0000
27.6200 982.0000 1.0000
27.6800 962.0000 1.0000
27.7400 986.0000 1.0000
27.8000 1017.0000 1.0000
27.8600 970.0000 1.0000
27.9200 999.0000 1.0000
27.9800 959.0000 1.0000
28.0400 961.0000 1.0000
28.1000 912.0000 1.0000
28.1600 964.0000 1.0000
28.2200 950.0000 1.0000
28.2800 913.0000 1.0000
28.3400 937.0000 1.0000
28.4000 861.0000 1.0000
28.4600 911.0000 1.0000
28.5200 940.0000 1.0000
28.5800 882.0000 1.0000
28.6400 870.0000 1.0000
28.7000 890.0000 1.0000
28.7600 904.0000 1.0000
28.8200 852.0000 1.0000
28.8800 880.0000 1.0000
28.9400 871.0000 1.0000
29.0000 931.0000 1.0000
29.0600 890.0000 1.0000
29.1200 821.0000 1.0000
29.1800 851.0000 1.0000
29.2400 838.0000 1.0000
29.3000 870.0000 1.0000
29.3600 844.0000 1.0000
29.4200 834.0000 1.0000
29.4800 871.0000 1.0000
29.5400 869.0000 1.0000
29.6000 857.0000 1.0000
29.6600 815.0000 1.0000
29.7200 856.0000 1.0000
29.7800 800.0000 1.0000
29.8400 852.0000 1.0000
29.9000 819.0000 1.0000
29.9600 813.0000 1.0000
30.0200 792.0000 1.0000
30.0800 784.0000 1.0000
30.1400 790.0000 1.0000
30.2000 783.0000 1.0000
30.2600 820.0000 1.0000
30.3200 771.0000 1.0000
30.3800 817.0000 1.0000
30.4400 792.0000 1.0000
30.5000 821.0000 1.0000
30.5600 747.0000 1.0000
30.6200 750.0000 1.0000
30.6800 804.0000 1.0000
30.7400 758.0000 1.0000
30.8000 768.0000 1.0000
30.8600 718.0000 1.0000
30.9200 754.0000 1.0000
30.9800 706.0000 1.0000
31.0400 713.0000 1.0000
31.1000 741.0000 1.0000
31.1600 762.0000 1.0000
31.2200 705.0000 1.0000
31.2800 720.0000 1.0000
31.3400 727.0000 1.0000
31.4000 725.0000 1.0000
31.4600 739.0000 1.0000
31.5200 743.0000 1.0000
31.5800 722.0000 1.0000
31.6400 731.0000 1.0000
31.7000 720.0000 1.0000
31.7600 726.0000 1.0000
31.8200 704.0000 1.0000
31.8800 701.0000 1.0000
31.9400 677.0000 1.0000
32.0000 746.0000 1.0000
32.0600 688.0000 1.0000
32.1200 668.0000 1.0000
32.1800 718.0000 1.0000
32.2400 725.0000 1.0000
32.3000 668.0000 1.0000
32.3600 621.0000 1.0000
32.4200 675.0000 1.0000
32.4800 743.0000 1.0000
32.5400 699.0000 1.0000
32.6000 686.0000 1.0000
32.6600 635.0000 1.0000
32.7200 635.0000 1.0000
32.7800 642.0000 1.0000
32.8400 680.0000 1.0000
32.9000 632.0000 1.0000
32.9600 686.0000 1.0000
33.0200 686.0000 1.0000
33.0800 647.0000 1.0000
33.1400 608.0000 1.0000
33.2000 612.0000 1.0000
33.2600 648.0000 1.0000
33.3200 637.0000 1.0000
33.3800 635.0000 1.0000
33.4400 651.0000 1.0000
33.5000 660.0000 1.0000
33.5600 599.0000 1.0000
33.6200 643.0000 1.0000
33.6800 580.0000 1.0000
33.7400 597.0000 1.0000
33.8000 602.0000 1.0000
33.8600 589.0000 1.0000
33.9200 647.0000 1.0000
33.9800 613.0000 1.0000
34.0400 634.0000 1.0000
34.1000 628.0000 1.0000
34.1600 641.0000 1.0000
34.2200 611.0000 1.0000
34.2800 644.0000 1.0000
34.3400 674.0000 1.0000
34.4000 718.0000 1.0000
34.4600 703.0000 1.0000
34.5200 741.0000 1.0000
34.5800 708.0000 1.0000
34.6400 652.0000 1.0000
34.7000 661.0000 1.0000
34.7600 601.0000 1.0000
34.8200 575.0000 1.0000
34.8800 566.0000 1.0000
34.9400 550.0000 1.0000
35.0000 560.0000 1.0000
35.0600 558.0000 1.0000
35.1200 567.0000 1.0000
35.1800 549.0000 1.0000
35.2400 551.0000 1.0000
35.3000 519.0000 1.0000
35.3600 523.0000 1.0000
35.4200 516.0000 1.0000
35.4800 526.0000 1.0000
35.5400 536.0000 1.0000
35.6000 496.0000 1.0000
35.6600 505.0000 1.0000
35.7200 537.0000 1.0000
35.7800 498.0000 1.0000
35.8400 551.0000 1.0000
35.9000 565.0000 1.0000
35.9600 530.0000 1.0000
36.0200 488.0000 1.0000
36.0800 536.0000 1.0000
36.1400 496.0000 1.0000
36.2000 543.0000 1.0000
36.2600 549.0000 1.0000
36.3200 502.0000 1.0000
36.3800 558.0000 1.0000
36.4400 607.0000 1.0000
36.5000 564.0000 1.0000
36.5600 505.0000 1.0000
36.6200 521.0000 1.0000
36.6800 509.0000 1.0000
36.7400 507.0000 1.0000
36.8000 482.0000 1.0000
36.8600 481.0000 1.0000
36.9200 433.0000 1.0000
36.9800 476.0000 1.0000
37.0400 517.0000 1.0000
37.1000 457.0000 1.0000
37.1600 522.0000 1.0000
37.2200 477.0000 1.0000
37.2800 461.0000 1.0000
37.3400 474.0000 1.0000
37.4000 455.0000 1.0000
37.4600 450.0000 1.0000
37.5200 471.0000 1.0000
37.5800 445.0000 1.0000
37.6400 445.0000 1.0000
37.7000 445.0000 1.0000
37.7600 458.0000 1.0000
37.8200 491.0000 1.0000
37.8800 485.0000 1.0000
37.9400 424.0000 1.0000
38.0000 450.0000 1.0000
38.0600 468.0000 1.0000
38.1200 476.0000 1.0000
38.1800 449.0000 1.0000
38.2400 458.0000 1.0000
38.3000 522.0000 1.0000
38.3600 585.0000 1.0000
38.4200 686.0000 1.0000
38.4800 857.0000 1.0000
38.5400 859.0000 1.0000
38.6000 827.0000 1.0000
38.6600 709.0000 1.0000
38.7200 567.0000 1.0000
38.7800 517.0000 1.0000
38.8400 495.0000 1.0000
38.9000 456.0000 1.0000
38.9600 418.0000 1.0000
39.0200 443.0000 1.0000
39.0800 463.0000 1.0000
39.1400 407.0000 1.0000
39.2000 417.0000 1.0000
39.2600 425.0000 1.0000
39.3200 382.0000 1.0000
39.3800 406.0000 1.0000
39.4400 400.0000 1.0000
39.5000 420.0000 1.0000
39.5600 404.0000 1.0000
39.6200 436.0000 1.0000
39.6800 389.0000 1.0000
39.7400 397.0000 1.0000
39.8000 398.0000 1.0000
39.8600 393.0000 1.0000
39.9200 409.0000 1.0000
39.9800 388.0000 1.0000
40.0400 381.0000 1.0000
40.1000 380.0000 1.0000
40.1600 386.0000 1.0000
40.2200 419.0000 1.0000
40.2800 355.0000 1.0000
40.3400 379.0000 1.0000
40.4000 408.0000 1.0000
40.4600 396.0000 1.0000
40.5200 358.0000 1.0000
40.5800 394.0000 1.0000
40.6400 406.0000 1.0000
40.7000 359.0000 1.0000
40.7600 365.0000 1.0000
40.8200 369.0000 1.0000
40.8800 377.0000 1.0000
40.9400 383.0000 1.0000
41.0000 351.0000 1.0000
41.0600 389.0000 1.0000
41.1200 359.0000 1.0000
41.1800 331.0000 1.0000
41.2400 361.0000 1.0000
41.3000 344.0000 1.0000
41.3600 383.0000 1.0000
41.4200 330.0000 1.0000
41.4800 368.0000 1.0000
41.5400 385.0000 1.0000
41.6000 345.0000 1.0000
41.6600 354.0000 1.0000
41.7200 369.0000 1.0000
41.7800 362.0000 1.0000
41.8400 361.0000 1.0000
41.9000 367.0000 1.0000
41.9600 343.0000 1.0000
42.0200 324.0000 1.0000
42.0800 353.0000 1.0000
42.1400 365.0000 1.0000
42.2000 348.0000 1.0000
42.2600 368.0000 1.0000
42.3200 370.0000 1.0000
42.3800 345.0000 1.0000
42.4400 363.0000 1.0000
42.5000 340.0000 1.0000
42.5600 316.0000 1.0000
42.6200 320.0000 1.0000
42.6800 323.0000 1.0000
42.7400 362.0000 1.0000
42.8000 354.0000 1.0000
42.8600 351.0000 1.0000
42.9200 342.0000 1.0000
42.9800 357.0000 1.0000
43.0400 299.0000 1.0000
43.1000 316.0000 1.0000
43.1600 351.0000 1.0000
43.2200 344.0000 1.0000
43.2800 362.0000 1.0000
43.3400 326.0000 1.0000
43.4000 316.0000 1.0000
43.4600 315.0000 1.0000
43.5200 345.0000 1.0000
43.5800 325.0000 1.0000
43.6400 324.0000 1.0000
43.7000 310.0000 1.0000
43.7600 332.0000 1.0000
43.8200 331.0000 1.0000
43.8800 302.0000 1.0000
43.9400 323.0000 1.0000
44.0000 335.0000 1.0000
44.0600 314.0000 1.0000
44.1200 328.0000 1.0000
44.1800 305.0000 1.0000
44.2400 332.0000 1.0000
44.3000 312.0000 1.0000
44.3600 286.0000 1.0000
44.4200 297.0000 1.0000
44.4800 288.0000 1.0000
44.5400 322.0000 1.0000
44.6000 347.0000 1.0000
44.6600 313.0000 1.0000
44.7200 315.0000 1.0000
44.7800 290.0000 1.0000
44.8400 311.0000 1.0000
44.9000 313.0000 1.0000
44.9600 298.0000 1.0000
45.0200 304.0000 1.0000
45.0800 309.0000 1.0000
45.1400 271.0000 1.0000
45.2000 280.0000 1.0000
45.2600 270.0000 1.0000
45.3200 311.0000 1.0000
45.3800 308.0000 1.0000
45.4400 278.0000 1.0000
45.5000 286.0000 1.0000
45.5600 299.0000 1.0000
45.6200 296.0000 1.0000
45.6800 298.0000 1.0000
45.7400 300.0000 1.0000
45.8000 288.0000 1.0000
45.8600 315.0000 1.0000
45.9200 316.0000 1.0000
45.9800 276.0000 1.0000
46.0400 308.0000 1.0000
46.1000 271.0000 1.0000
46.1600 305.0000 1.0000
46.2200 275.0000 1.0000
46.2800 260.0000 1.0000
46.3400 292.0000 1.0000
46.4000 289.0000 1.0000
46.4600 294.0000 1.0000
46.5200 289.0000 1.0000
46.5800 267.0000 1.0000
46.6400 276.0000 1.0000
46.7000 251.0000 1.0000
46.7600 301.0000 1.0000
46.8200 324.0000 1.0000
46.8800 271.0000 1.0000
46.9400 288.0000 1.0000
47.0000 257.0000 1.0000
47.0600 262.0000 1.0000
47.1200 263.0000 1.0000
47.1800 258.0000 1.0000
47.2400 270.0000 1.0000
47.3000 261.0000 1.0000
47.3600 262.0000 1.0000
47.4200 287.0000 1.0000
47.4800 263.0000 1.0000
47.5400 286.0000 1.0000
47.6000 272.0000 1.0000
47.6600 268.0000 1.0000
47.7200 259.0000 1.0000
47.7800 255.0000 1.0000
47.8400 248.0000 1.0000
47.9000 290.0000 1.0000
47.9600 250.0000 1.0000
48.0200 259.0000 1.0000
48.0800 252.0000 1.0000
48.1400 278.0000 1.0000
48.2000 292.0000 1.0000
48.2600 286.0000 1.0000
48.3200 286.0000 1.0000
48.3800 240.0000 1.0000
48.4400 268.0000 1.0000
48.5000 277.0000 1.0000
48.5600 237.0000 1.0000
48.6200 257.0000 1.0000
48.6800 244.0000 1.0000
48.7400 249.0000 1.0000
48.8000 260.0000 1.0000
48.8600 235.0000 1.0000
48.9200 274.0000 1.0000
48.9800 276.0000 1.0000
49.0400 280.0000 1.0000
49.1000 252.0000 1.0000
49.1600 265.0000 1.0000
49.2200 247.0000 1.0000
49.2800 240.0000 1.0000
49.3400 268.0000 1.0000
49.4000 253.0000 1.0000
49.4600 247.0000 1.0000
49.5200 269.0000 1.0000
49.5800 249.0000 1.0000
49.6400 223.0000 1.0000
49.7000 240.0000 1.0000
49.7600 252.0000 1.0000
49.8200 247.0000 1.0000
49.8800 242.0000 1.0000
49.9400 230.0000 1.0000
50.0000 241.0000 1.0000
50.0600 251.0000 1.0000
50.1200 251.0000 1.0000
50.1800 274.0000 1.0000
50.2400 223.0000 1.0000
50.3000 286.0000 1.0000
50.3600 275.0000 1.0000
50.4200 291.0000 1.0000
50.4800 250.0000 1.0000
50.5400 229.0000 1.0000
50.6000 248.0000 1.0000
50.6600 224.0000 1.0000
50.7200 265.0000 1.0000
50.7800 265.0000 1.0000
50.8400 229.0000 1.0000
50.9000 259.0000 1.0000
50.9600 264.0000 1.0000
51.0200 238.0000 1.0000
51.0800 267.0000 1.0000
51.1400 225.0000 1.0000
51.2000 240.0000 1.0000
51.2600 252.0000 1.0000
51.3200 231.0000 1.0000
51.3800 239.0000 1.0000
51.4400 256.0000 1.0000
51.5000 225.0000 1.0000
51.5600 224.0000 1.0000
51.6200 262.0000 1.0000
51.6800 262.0000 1.0000
51.7400 263.0000 1.0000
51.8000 300.0000 1.0000
51.8600 245.0000 1.0000
51.9200 237.0000 1.0000
51.9800 279.0000 1.0000
52.0400 367.0000 1.0000
52.1000 414.0000 1.0000
52.1600 567.0000 1.0000
52.2200 893.0000 1.0000
52.2800 933.0000 1.0000
52.3400 828.0000 1.0000
52.4000 737.0000 1.0000
52.4600 573.0000 1.0000
52.5200 425.0000 1.0000
52.5800 365.0000 1.0000
52.6400 273.0000 1.0000
52.7000 282.0000 1.0000
52.7600 266.0000 1.0000
52.8200 263.0000 1.0000
52.8800 270.0000 1.0000
52.9400 261.0000 1.0000
53.0000 242.0000 1.0000
53.0600 228.0000 1.0000
53.1200 257.0000 1.0000
53.1800 235.0000 1.0000
53.2400 265.0000 1.0000
53.3000 257.0000 1.0000
53.3600 244.0000 1.0000
53.4200 235.0000 1.0000
53.4800 242.0000 1.0000
53.5400 242.0000 1.0000
53.6000 244.0000 1.0000
53.6600 211.0000 1.0000
53.7200 232.0000 1.0000
53.7800 214.0000 1.0000
53.8400 234.0000 1.0000
53.9000 240.0000 1.0000
53.9600 249.0000 1.0000
54.0200 246.0000 1.0000
54.0800 218.0000 1.0000
54.1400 233.0000 1.0000
54.2000 232.0000 1.0000
54.2600 251.0000 1.0000
54.3200 238.0000 1.0000
54.3800 231.0000 1.0000
54.4400 230.0000 1.0000
54.5000 226.0000 1.0000
54.5600 228.0000 1.0000
54.6200 237.0000 1.0000
54.6800 224.0000 1.0000
54.7400 272.0000 1.0000
54.8000 232.0000 1.0000
54.8600 230.0000 1.0000
54.9200 230.0000 1.0000
54.9800 240.0000 1.0000
55.0400 237.0000 1.0000
55.1000 276.0000 1.0000
55.1600 230.0000 1.0000
55.2200 271.0000 1.0000
55.2800 312.0000 1.0000
55.3400 309.0000 1.0000
55.4000 313.0000 1.0000
55.4600 283.0000 1.0000
55.5200 264.0000 1.0000
55.5800 233.0000 1.0000
55.6400 234.0000 1.0000
55.7000 251.0000 1.0000
55.7600 215.0000 1.0000
55.8200 233.0000 1.0000
55.8800 211.0000 1.0000
55.9400 239.0000 1.0000
56.0000 236.0000 1.0000
56.0600 214.0000 1.0000
56.1200 229.0000 1.0000
56.1800 214.0000 1.0000
56.2400 203.0000 1.0000
56.3000 248.0000 1.0000
56.3600 217.0000 1.0000
56.4200 239.0000 1.0000
56.4800 210.0000 1.0000
56.5400 231.0000 1.0000
56.6000 220.0000 1.0000
56.6600 220.0000 1.0000
56.7200 244.0000 1.0000
56.7800 226.0000 1.0000
56.8400 220.0000 1.0000
56.9000 208.0000 1.0000
56.9600 187.0000 1.0000
57.0200 227.0000 1.0000
57.0800 210.0000 1.0000
57.1400 213.0000 1.0000
57.2000 216.0000 1.0000
57.2600 211.0000 1.0000
57.3200 223.0000 1.0000
57.3800 211.0000 1.0000
57.4400 219.0000 1.0000
57.5000 239.0000 1.0000
57.5600 227.0000 1.0000
57.6200 198.0000 1.0000
57.6800 246.0000 1.0000
57.7400 227.0000 1.0000
57.8000 227.0000 1.0000
57.8600 215.0000 1.0000
57.9200 224.0000 1.0000
57.9800 219.0000 1.0000
58.0400 213.0000 1.0000
58.1000 222.0000 1.0000
58.1600 221.0000 1.0000
58.2200 257.0000 1.0000
58.2800 204.0000 1.0000
58.3400 236.0000 1.0000
58.4000 237.0000 1.0000
58.4600 235.0000 1.0000
58.5200 222.0000 1.0000
58.5800 223.0000 1.0000
58.6400 184.0000 1.0000
58.7000 212.0000 1.0000
58.7600 221.0000 1.0000
58.8200 220.0000 1.0000
58.8800 193.0000 1.0000
58.9400 221.0000 1.0000
59.0000 218.0000 1.0000
59.0600 232.0000 1.0000
59.1200 218.0000 1.0000
59.1800 232.0000 1.0000
59.2400 216.0000 1.0000
59.3000 210.0000 1.0000
59.3600 228.0000 1.0000
59.4200 211.0000 1.0000
59.4800 207.0000 1.0000
59.5400 232.0000 1.0000
59.6000 195.0000 1.0000
59.6600 209.0000 1.0000
59.7200 190.0000 1.0000
59.7800 244.0000 1.0000
59.8400 221.0000 1.0000
59.9000 208.0000 1.0000
59.9600 220.0000 1.0000
60.0200 215.0000 1.0000
60.0800 205.0000 1.0000
60.1400 216.0000 1.0000
60.2000 187.0000 1.0000
60.2600 227.0000 1.0000
60.3200 221.0000 1.0000
60.3800 206.0000 1.0000
60.4400 236.0000 1.0000
60.5000 244.0000 1.0000
60.5600 220.0000 1.0000
60.6200 212.0000 1.0000
60.6800 236.0000 1.0000
60.7400 196.0000 1.0000
60.8000 226.0000 1.0000
60.8600 201.0000 1.0000
60.9200 210.0000 1.0000
60.9800 236.0000 1.0000
61.0400 217.0000 1.0000
61.1000 227.0000 1.0000
61.1600 203.0000 1.0000
61.2200 220.0000 1.0000
61.2800 201.0000 1.0000
61.3400 219.0000 1.0000
61.4000 226.0000 1.0000
61.4600 193.0000 1.0000
61.5200 185.0000 1.0000
61.5800 214.0000 1.0000
61.6400 204.0000 1.0000
61.7000 208.0000 1.0000
61.7600 208.0000 1.0000
61.8200 236.0000 1.0000
61.8800 196.0000 1.0000
61.9400 228.0000 1.0000
62.0000 254.0000 1.0000
62.0600 282.0000 1.0000
62.1200 282.0000 1.0000
62.1800 341.0000 1.0000
62.2400 371.0000 1.0000
62.3000 342.0000 1.0000
62.3600 355.0000 1.0000
62.4200 347.0000 1.0000
62.4800 345.0000 1.0000
62.5400 289.0000 1.0000
62.6000 296.0000 1.0000
62.6600 249.0000 1.0000
62.7200 246.0000 1.0000
62.7800 242.0000 1.0000
62.8400 215.0000 1.0000
62.9000 215.0000 1.0000
62.9600 221.0000 1.0000
63.0200 226.0000 1.0000
63.0800 215.0000 1.0000
63.1400 209.0000 1.0000
63.2000 240.0000 1.0000
63.2600 227.0000 1.0000
63.3200 198.0000 1.0000
63.3800 228.0000 1.0000
63.4400 199.0000 1.0000
63.5000 251.0000 1.0000
63.5600 239.0000 1.0000
63.6200 214.0000 1.0000
63.6800 206.0000 1.0000
63.7400 224.0000 1.0000
63.8000 213.0000 1.0000
63.8600 207.0000 1.0000
63.9200 213.0000 1.0000
63.9800 201.0000 1.0000
64.0400 206.0000 1.0000
64.1000 202.0000 1.0000
64.1600 210.0000 1.0000
64.2200 226.0000 1.0000
64.2800 212.0000 1.0000
64.3400 221.0000 1.0000
64.4000 228.0000 1.0000
64.4600 202.0000 1.0000
64.5200 220.0000 1.0000
64.5800 235.0000 1.0000
64.6400 276.0000 1.0000
64.7000 253.0000 1.0000
64.7600 235.0000 1.0000
64.8200 248.0000 1.0000
64.8800 238.0000 1.0000
64.9400 247.0000 1.0000
65.0000 236.0000 1.0000
65.0600 229.0000 1.0000
65.1200 224.0000 1.0000
65.1800 257.0000 1.0000
65.2400 238.0000 1.0000
65.3000 220.0000 1.0000
65.3600 238.0000 1.0000
65.4200 211.0000 1.0000
65.4800 205.0000 1.0000
65.5400 248.0000 1.0000
65.6000 210.0000 1.0000
65.6600 211.0000 1.0000
65.7200 222.0000 1.0000
65.7800 210.0000 1.0000
65.8400 240.0000 1.0000
65.9000 232.0000 1.0000
65.9600 301.0000 1.0000
66.0200 298.0000 1.0000
66.0800 387.0000 1.0000
66.1400 480.0000 1.0000
66.2000 615.0000 1.0000
66.2600 608.0000 1.0000
66.3200 590.0000 1.0000
66.3800 541.0000 1.0000
66.4400 510.0000 1.0000
66.5000 397.0000 1.0000
66.5600 335.0000 1.0000
66.6200 283.0000 1.0000
66.6800 294.0000 1.0000
66.7400 247.0000 1.0000
66.8000 221.0000 1.0000
66.8600 228.0000 1.0000
66.9200 233.0000 1.0000
66.9800 193.0000 1.0000
67.0400 232.0000 1.0000
67.1000 188.0000 1.0000
67.1600 215.0000 1.0000
67.2200 208.0000 1.0000
67.2800 221.0000 1.0000
67.3400 231.0000 1.0000
67.4000 222.0000 1.0000
67.4600 217.0000 1.0000
67.5200 205.0000 1.0000
67.5800 200.0000 1.0000
67.6400 224.0000 1.0000
67.7000 235.0000 1.0000
67.7600 227.0000 1.0000
67.8200 215.0000 1.0000
67.8800 204.0000 1.0000
67.9400 184.0000 1.0000
68.0000 199.0000 1.0000
68.0600 201.0000 1.0000
68.1200 199.0000 1.0000
68.1800 201.0000 1.0000
68.2400 210.0000 1.0000
68.3000 193.0000 1.0000
68.3600 203.0000 1.0000
68.4200 211.0000 1.0000
68.4800 196.0000 1.0000
68.5400 207.0000 1.0000
68.6000 216.0000 1.0000
68.6600 216.0000 1.0000
68.7200 216.0000 1.0000
68.7800 181.0000 1.0000
68.8400 197.0000 1.0000
68.9000 183.0000 1.0000
68.9600 206.0000 1.0000
69.0200 181.0000 1.0000
69.0800 214.0000 1.0000
69.1400 196.0000 1.0000
69.2000 193.0000 1.0000
69.2600 188.0000 1.0000
69.3200 210.0000 1.0000
69.3800 178.0000 1.0000
69.4400 209.0000 1.0000
69.5000 233.0000 1.0000
69.5600 185.0000 1.0000
69.6200 216.0000 1.0000
69.6800 200.0000 1.0000
69.7400 175.0000 1.0000
69.8000 188.0000 1.0000
69.8600 195.0000 1.0000
69.9200 196.0000 1.0000
69.9800 198.0000 1.0000
70.0400 189.0000 1.0000
70.1000 180.0000 1.0000
70.1600 215.0000 1.0000
70.2200 222.0000 1.0000
70.2800 207.0000 1.0000
70.3400 219.0000 1.0000
70.4000 196.0000 1.0000
70.4600 188.0000 1.0000
70.5200 192.0000 1.0000
70.5800 208.0000 1.0000
70.6400 187.0000 1.0000
70.7000 182.0000 1.0000
70.7600 209.0000 1.0000
70.8200 187.0000 1.0000
70.8800 206.0000 1.0000
70.9400 190.0000 1.0000
71.0000 206.0000 1.0000
71.0600 188.0000 1.0000
71.1200 202.0000 1.0000
71.1800 192.0000 1.0000
71.2400 208.0000 1.0000
71.3000 196.0000 1.0000
71.3600 189.0000 1.0000
71.4200 209.0000 1.0000
71.4800 211.0000 1.0000
71.5400 203.0000 1.0000
71.6000 198.0000 1.0000
71.6600 243.0000 1.0000
71.7200 211.0000 1.0000
71.7800 211.0000 1.0000
71.8400 235.0000 1.0000
71.9000 182.0000 1.0000
71.9600 189.0000 1.0000
72.0200 202.0000 1.0000
72.0800 188.0000 1.0000
72.1400 174.0000 1.0000
72.2000 210.0000 1.0000
72.2600 211.0000 1.0000
72.3200 188.0000 1.0000
72.3800 184.0000 1.0000
72.4400 193.0000 1.0000
72.5000 212.0000 1.0000
72.5600 200.0000 1.0000
72.6200 189.0000 1.0000
72.6800 197.0000 1.0000
72.7400 176.0000 1.0000
72.8000 169.0000 1.0000
72.8600 180.0000 1.0000
72.9200 206.0000 1.0000
72.9800 183.0000 1.0000
73.0400 197.0000 1.0000
73.1000 188.0000 1.0000
73.1600 167.0000 1.0000
73.2200 183.0000 1.0000
73.2800 168.0000 1.0000
73.3400 191.0000 1.0000
73.4000 202.0000 1.0000
73.4600 199.0000 1.0000
73.5200 197.0000 1.0000
73.5800 193.0000 1.0000
73.6400 176.0000 1.0000
73.7000 230.0000 1.0000
73.7600 191.0000 1.0000
73.8200 194.0000 1.0000
73.8800 190.0000 1.0000
73.9400 201.0000 1.0000
74.0000 187.0000 1.0000
74.0600 187.0000 1.0000
74.1200 189.0000 1.0000
74.1800 172.0000 1.0000
74.2400 205.0000 1.0000
74.3000 184.0000 1.0000
74.3600 190.0000 1.0000
74.4200 192.0000 1.0000
74.4800 206.0000 1.0000
74.5400 194.0000 1.0000
74.6000 177.0000 1.0000
74.6600 187.0000 1.0000
74.7200 202.0000 1.0000
74.7800 201.0000 1.0000
74.8400 185.0000 1.0000
74.9000 187.0000 1.0000
74.9600 172.0000 1.0000
75.0200 182.0000 1.0000
75.0800 199.0000 1.0000
75.1400 187.0000 1.0000
75.2000 183.0000 1.0000
75.2600 207.0000 1.0000
75.3200 193.0000 1.0000
75.3800 210.0000 1.0000
75.4400 202.0000 1.0000
75.5000 193.0000 1.0000
75.5600 192.0000 1.0000
75.6200 172.0000 1.0000
75.6800 174.0000 1.0000
75.7400 192.0000 1.0000
75.8000 173.0000 1.0000
75.8600 231.0000 1.0000
75.9200 198.0000 1.0000
75.9800 190.0000 1.0000
76.0400 195.0000 1.0000
76.1000 192.0000 1.0000
76.1600 198.0000 1.0000
76.2200 210.0000 1.0000
76.2800 207.0000 1.0000
76.3400 189.0000 1.0000
76.4000 177.0000 1.0000
76.4600 189.0000 1.0000
76.5200 185.0000 1.0000
76.5800 191.0000 1.0000
76.6400 192.0000 1.0000
76.7000 189.0000 1.0000
76.7600 204.0000 1.0000
76.8200 175.0000 1.0000
76.8800 187.0000 1.0000
76.9400 201.0000 1.0000
77.0000 179.0000 1.0000
77.0600 212.0000 1.0000
77.1200 186.0000 1.0000
77.1800 186.0000 1.0000
77.2400 170.0000 1.0000
77.3000 186.0000 1.0000
77.3600 181.0000 1.0000
77.4200 195.0000 1.0000
77.4800 198.0000 1.0000
77.5400 183.0000 1.0000
77.6000 189.0000 1.0000
77.6600 197.0000 1.0000
77.7200 196.0000 1.0000
77.7800 226.0000 1.0000
77.8400 197.0000 1.0000
77.9000 203.0000 1.0000
77.9600 197.0000 1.0000
78.0200 161.0000 1.0000
78.0800 193.0000 1.0000
78.1400 181.0000 1.0000
78.2000 200.0000 1.0000
78.2600 187.0000 1.0000
78.3200 193.0000 1.0000
78.3800 180.0000 1.0000
78.4400 191.0000 1.0000
78.5000 183.0000 1.0000
78.5600 182.0000 1.0000
78.6200 197.0000 1.0000
78.6800 190.0000 1.0000
78.7400 195.0000 1.0000
78.8000 228.0000 1.0000
78.8600 261.0000 1.0000
78.9200 280.0000 1.0000
78.9800 266.0000 1.0000
79.0400 264.0000 1.0000
79.1000 265.0000 1.0000
79.1600 260.0000 1.0000
79.2200 241.0000 1.0000
79.2800 234.0000 1.0000
79.3400 226.0000 1.0000
79.4000 203.0000 1.0000
79.4600 198.0000 1.0000
79.5200 209.0000 1.0000
79.5800 186.0000 1.0000
79.6400 190.0000 1.0000
79.7000 181.0000 1.0000
79.7600 194.0000 1.0000
79.8200 203.0000 1.0000
79.8800 199.0000 1.0000
79.9400 214.0000 1.0000
80.0000 175.0000 1.0000
*RAS_INT_END
*RAS_TEMPERATURE_START
*RAS_TEMPERATURE_END
*RAS_DATA_END