File: Sectio1_28_samples/XRD/No_001_600_12_2.ras
*RAS_DATA_START
*RAS_HEADER_START
*DISP_FMT_X "%.2f"
*DISP_FMT_Y "%.0f"
*DISP_FULLSCALE "3912.0000000000"
*DISP_LINE_COLOR "255.0000000000"
*DISP_LINE_STYLE "0.0000000000"
*DISP_LINE_WIDTH "0.2500000000"
*DISP_NOTE "測定データ-8"
*DISP_OFFSET_Y "0.0000000000"
*DISP_PEAKSEARCH_UNIT_Y "cps"
*DISP_RANGE_BOTTOM "0.0000000000"
*DISP_RANGE_LEFT "20.0000000000"
*DISP_RANGE_LOGCUTOFF "0.0100000000"
*DISP_RANGE_RIGHT "80.0000000000"
*DISP_RANGE_TOP "3912.0000000000"
*DISP_SCALE_MODE_Y "0.0000000000"
*DISP_TAB_NAME "2θ/θ"
*DISP_TITLE_Y "強度"
*DISP_UNIT_Y "cps"
*DISP_WINDOW_NAME "MSG_MACROENGINE"
*FILE_COMMENT " "
*FILE_MD5 ""
*FILE_MEMO " "
*FILE_OPERATOR "Administrator"
*FILE_SAMPLE "hematite"
*FILE_TYPE "RAS_RAW"
*FILE_USERGROUP "システムマネージャ"
*FILE_VERSION "1.0000000000"
*HW_ATTACHMENT_ID "ATT0025"
*HW_ATTACHMENT_NAME "標準|Standard"
*HW_COUNTER_ID-0 "CUT0025"
*HW_COUNTER_ID-1 "CUT0020"
*HW_COUNTER_ID-2 "CUT0020"
*HW_COUNTER_ID-3 "CSL0021"
*HW_COUNTER_ID-4 "CMC0021"
*HW_COUNTER_NAME-0 "D/teX Ultra|D/teX Ultra"
*HW_COUNTER_NAME-1 "None|None"
*HW_COUNTER_NAME-2 "None|None"
*HW_COUNTER_NAME-3 "BBM|BBM"
*HW_COUNTER_NAME-4 "検出器モノクロメータ|Detector monochromator"
*HW_COUNTER_SELECT_NAME "D/teX Ultra|D/teX Ultra"
*HW_GONIOMETER_ID "GON0023"
*HW_GONIOMETER_NAME "SmartLab|SmartLab"
*HW_GONIOMETER_RADIUS-0 "90.0"
*HW_GONIOMETER_RADIUS-1 "114.0"
*HW_GONIOMETER_RADIUS-2 "190.0"
*HW_GONIOMETER_RADIUS-3 "300.0"
*HW_GONIOMETER_RADIUS-4 "187.0"
*HW_GONIOMETER_RADIUS-5 "300.0"
*HW_GONIOMETER_RADIUS-6 "113.0"
*HW_GONIOMETER_RADIUS-7 "331.0"
*HW_I_OPT_ID-0 "CBO0021"
*HW_I_OPT_ID-1 "ICR0023"
*HW_I_OPT_ID-2 "ISL0021"
*HW_I_OPT_ID-3 "ISO0021"
*HW_I_OPT_ID-4 "IAD0021"
*HW_I_OPT_ID-5 "IPR0001"
*HW_I_OPT_NAME-0 "CBOユニット|CBO unit"
*HW_I_OPT_NAME-1 "標準入射光学ユニット|Standard incident optical unit"
*HW_I_OPT_NAME-2 "標準入射スリットボックス|Standard incident slit box"
*HW_I_OPT_NAME-3 "入射平行スリット|Incident parallel slit"
*HW_I_OPT_NAME-4 "長手制限スリット|Length limiting slit"
*HW_I_OPT_NAME-5 "None|None"
*HW_R_ATTENUATER_AUTOMODE "0"
*HW_R_OPT_ID-0 "RSS0021"
*HW_R_OPT_ID-1 "RCR0023"
*HW_R_OPT_ID-2 "RSO0021"
*HW_R_OPT_ID-3 "RRS0021"
*HW_R_OPT_ID-4 "ATN0021"
*HW_R_OPT_ID-5 "RFL0021"
*HW_R_OPT_ID-6 "RAD0021"
*HW_R_OPT_NAME-0 "標準受光スリットボックス1|Standard receiving slit box # 1"
*HW_R_OPT_NAME-1 "標準受光光学ユニット1|Standard receiving unit # 1"
*HW_R_OPT_NAME-2 "標準受光光学ユニット2|Standard receiving optical unit # 2"
*HW_R_OPT_NAME-3 "標準受光スリットボックス2|Standard receiving slit box # 2"
*HW_R_OPT_NAME-4 "標準アッテネータ|Standard Attenuator"
*HW_R_OPT_NAME-5 "Cu Kβ|Cu K-beta"
*HW_R_OPT_NAME-6 "調整用受光スリット|Alignment receiving slit"
*HW_SAMPLE_HOLDER_ID "SMP0023"
*HW_SAMPLE_HOLDER_NAME "標準Zステージ|Standard Z stage"
*HW_XG_CURRENT_MAX "50"
*HW_XG_CURRENT_MIN "2"
*HW_XG_CURRENT_RESOLUTION "2"
*HW_XG_CURRENT_UNIT "mA"
*HW_XG_FOCUS "1mm x 10mm"
*HW_XG_FOCUS_TYPE "Normal"
*HW_XG_ID ""
*HW_XG_NAME "3kW 封入管(ID:1200)|3kW Sealed tube(ID:1200)"
*HW_XG_TARGET_ATOMIC_NUMBER "29.0000000000"
*HW_XG_TARGET_NAME "Cu"
*HW_XG_TYPE "Hermetic"
*HW_XG_VOLTAGE_MAX "60"
*HW_XG_VOLTAGE_MIN "20"
*HW_XG_VOLTAGE_RESOLUTION "2"
*HW_XG_VOLTAGE_UNIT "kV"
*HW_XG_WATT_MAX "2"
*HW_XG_WATT_UNIT "kW"
*HW_XG_WAVE_LENGTH_ALPHA1 "1.540593"
*HW_XG_WAVE_LENGTH_ALPHA2 "1.544414"
*HW_XG_WAVE_LENGTH_BETA "1.392250"
*MEAS_COND_AXIS_NAME-0 "2θ/θ"
*MEAS_COND_AXIS_NAME-1 "2θ"
*MEAS_COND_AXIS_NAME-2 "ω"
*MEAS_COND_AXIS_NAME-3 "Z"
*MEAS_COND_AXIS_NAME-4 "2θ/ω"
*MEAS_COND_AXIS_NAME-5 "θs"
*MEAS_COND_AXIS_NAME-6 "θd"
*MEAS_COND_AXIS_NAME-7 "Ts"
*MEAS_COND_AXIS_NAME-8 "CBO選択スリット"
*MEAS_COND_AXIS_NAME-9 "M"
*MEAS_COND_AXIS_NAME-10 "入射平行スリット"
*MEAS_COND_AXIS_NAME-11 "入射スリット"
*MEAS_COND_AXIS_NAME-12 ""
*MEAS_COND_AXIS_NAME-13 "Zs"
*MEAS_COND_AXIS_NAME-14 "入射光学素子"
*MEAS_COND_AXIS_NAME-15 "長手制限スリット"
*MEAS_COND_AXIS_NAME-16 "センタースリット"
*MEAS_COND_AXIS_NAME-17 "フィルター"
*MEAS_COND_AXIS_NAME-18 "受光スリット1"
*MEAS_COND_AXIS_NAME-19 "受光スリット2"
*MEAS_COND_AXIS_NAME-20 "受光光学素子"
*MEAS_COND_AXIS_NAME-21 "受光平行スリット"
*MEAS_COND_AXIS_NAME-22 "調整用受光スリット"
*MEAS_COND_AXIS_NAME-23 ""
*MEAS_COND_AXIS_NAME-24 ""
*MEAS_COND_AXIS_NAME-25 "Zd"
*MEAS_COND_AXIS_NAME-26 "アッテネータ"
*MEAS_COND_AXIS_NAME-27 "検出器モノクロメータ"
*MEAS_COND_AXIS_NAME-28 "モノクロメータスリット"
*MEAS_COND_AXIS_NAME-29 "プライマリビーム"
*MEAS_COND_AXIS_NAME-30 "PHA"
*MEAS_COND_AXIS_NAME_INTERNAL-0 "TwoThetaTheta"
*MEAS_COND_AXIS_NAME_INTERNAL-1 "TwoTheta"
*MEAS_COND_AXIS_NAME_INTERNAL-2 "Omega"
*MEAS_COND_AXIS_NAME_INTERNAL-3 "Z"
*MEAS_COND_AXIS_NAME_INTERNAL-4 "TwoThetaOmega"
*MEAS_COND_AXIS_NAME_INTERNAL-5 "ThetaS"
*MEAS_COND_AXIS_NAME_INTERNAL-6 "ThetaD"
*MEAS_COND_AXIS_NAME_INTERNAL-7 "Ts"
*MEAS_COND_AXIS_NAME_INTERNAL-8 "CBO"
*MEAS_COND_AXIS_NAME_INTERNAL-9 "CBO-M"
*MEAS_COND_AXIS_NAME_INTERNAL-10 "IncidentSollerSlit"
*MEAS_COND_AXIS_NAME_INTERNAL-11 "IncidentSlitBox"
*MEAS_COND_AXIS_NAME_INTERNAL-12 "IncidentSlitBox-_Axis"
*MEAS_COND_AXIS_NAME_INTERNAL-13 "Zs"
*MEAS_COND_AXIS_NAME_INTERNAL-14 "IncidentMonochromator"
*MEAS_COND_AXIS_NAME_INTERNAL-15 "IncidentAxdSlit"
*MEAS_COND_AXIS_NAME_INTERNAL-16 "CenterSlit"
*MEAS_COND_AXIS_NAME_INTERNAL-17 "Filter"
*MEAS_COND_AXIS_NAME_INTERNAL-18 "ReceivingSlitBox1"
*MEAS_COND_AXIS_NAME_INTERNAL-19 "ReceivingSlitBox2"
*MEAS_COND_AXIS_NAME_INTERNAL-20 "ReceivingOptics"
*MEAS_COND_AXIS_NAME_INTERNAL-21 "ReceivingSollerSlit"
*MEAS_COND_AXIS_NAME_INTERNAL-22 "ReceivingAxdSlit"
*MEAS_COND_AXIS_NAME_INTERNAL-23 "ReceivingSlitBox1-_Axis"
*MEAS_COND_AXIS_NAME_INTERNAL-24 "ReceivingSlitBox2-_Axis"
*MEAS_COND_AXIS_NAME_INTERNAL-25 "ReceivingSlitBox2-Zd"
*MEAS_COND_AXIS_NAME_INTERNAL-26 "Attenuator"
*MEAS_COND_AXIS_NAME_INTERNAL-27 "CounterMonochromator"
*MEAS_COND_AXIS_NAME_INTERNAL-28 "CounterSlit"
*MEAS_COND_AXIS_NAME_INTERNAL-29 "IncidentPrimary"
*MEAS_COND_AXIS_NAME_INTERNAL-30 "PHA"
*MEAS_COND_AXIS_NAME_MAGICNO-0 "83951616.0000000000"
*MEAS_COND_AXIS_NAME_MAGICNO-1 "268632064.0000000000"
*MEAS_COND_AXIS_NAME_MAGICNO-2 "268500992.0000000000"
*MEAS_COND_AXIS_NAME_MAGICNO-3 "285278208.0000000000"
*MEAS_COND_AXIS_NAME_MAGICNO-4 "83951616.0000000000"
*MEAS_COND_AXIS_NAME_MAGICNO-5 "131072.0000000000"
*MEAS_COND_AXIS_NAME_MAGICNO-6 "131072.0000000000"
*MEAS_COND_AXIS_NAME_MAGICNO-7 "318898176.0000000000"
*MEAS_COND_AXIS_NAME_MAGICNO-8 "20971521.0000000000"
*MEAS_COND_AXIS_NAME_MAGICNO-9 "285343744.0000000000"
*MEAS_COND_AXIS_NAME_MAGICNO-10 "20971521.0000000000"
*MEAS_COND_AXIS_NAME_MAGICNO-11 "22020097.0000000000"
*MEAS_COND_AXIS_NAME_MAGICNO-12 "25165824.0000000000"
*MEAS_COND_AXIS_NAME_MAGICNO-13 "318898176.0000000000"
*MEAS_COND_AXIS_NAME_MAGICNO-14 "1.0000000000"
*MEAS_COND_AXIS_NAME_MAGICNO-15 "20971521.0000000000"
*MEAS_COND_AXIS_NAME_MAGICNO-16 "20971521.0000000000"
*MEAS_COND_AXIS_NAME_MAGICNO-17 "20971521.0000000000"
*MEAS_COND_AXIS_NAME_MAGICNO-18 "23068673.0000000000"
*MEAS_COND_AXIS_NAME_MAGICNO-19 "23068673.0000000000"
*MEAS_COND_AXIS_NAME_MAGICNO-20 "20971521.0000000000"
*MEAS_COND_AXIS_NAME_MAGICNO-21 "20971521.0000000000"
*MEAS_COND_AXIS_NAME_MAGICNO-22 "20971521.0000000000"
*MEAS_COND_AXIS_NAME_MAGICNO-23 "25165824.0000000000"
*MEAS_COND_AXIS_NAME_MAGICNO-24 "25165824.0000000000"
*MEAS_COND_AXIS_NAME_MAGICNO-25 "285343744.0000000000"
*MEAS_COND_AXIS_NAME_MAGICNO-26 "17301505.0000000000"
*MEAS_COND_AXIS_NAME_MAGICNO-27 "20971521.0000000000"
*MEAS_COND_AXIS_NAME_MAGICNO-28 "20971521.0000000000"
*MEAS_COND_AXIS_NAME_MAGICNO-29 "20971521.0000000000"
*MEAS_COND_AXIS_NAME_MAGICNO-30 "0.0000000000"
*MEAS_COND_AXIS_OFFSET-0 "-"
*MEAS_COND_AXIS_OFFSET-1 "-0.1081000000"
*MEAS_COND_AXIS_OFFSET-2 "0.3758000000"
*MEAS_COND_AXIS_OFFSET-3 "-"
*MEAS_COND_AXIS_OFFSET-4 "-"
*MEAS_COND_AXIS_OFFSET-5 "0.3758000000"
*MEAS_COND_AXIS_OFFSET-6 "-0.4839000000"
*MEAS_COND_AXIS_OFFSET-7 "-"
*MEAS_COND_AXIS_OFFSET-8 "-"
*MEAS_COND_AXIS_OFFSET-9 "-"
*MEAS_COND_AXIS_OFFSET-10 "-"
*MEAS_COND_AXIS_OFFSET-11 "-"
*MEAS_COND_AXIS_OFFSET-12 "-"
*MEAS_COND_AXIS_OFFSET-13 "-"
*MEAS_COND_AXIS_OFFSET-14 "-"
*MEAS_COND_AXIS_OFFSET-15 "-"
*MEAS_COND_AXIS_OFFSET-16 "-"
*MEAS_COND_AXIS_OFFSET-17 "-"
*MEAS_COND_AXIS_OFFSET-18 "-"
*MEAS_COND_AXIS_OFFSET-19 "-"
*MEAS_COND_AXIS_OFFSET-20 "-"
*MEAS_COND_AXIS_OFFSET-21 "-"
*MEAS_COND_AXIS_OFFSET-22 "-"
*MEAS_COND_AXIS_OFFSET-23 "-"
*MEAS_COND_AXIS_OFFSET-24 "-"
*MEAS_COND_AXIS_OFFSET-25 "-"
*MEAS_COND_AXIS_OFFSET-26 "-"
*MEAS_COND_AXIS_OFFSET-27 "-"
*MEAS_COND_AXIS_OFFSET-28 "-"
*MEAS_COND_AXIS_OFFSET-29 "-"
*MEAS_COND_AXIS_OFFSET-30 "-"
*MEAS_COND_AXIS_POSITION-0 "0.0000000000"
*MEAS_COND_AXIS_POSITION-1 "0.0000000000"
*MEAS_COND_AXIS_POSITION-2 "0.0000000000"
*MEAS_COND_AXIS_POSITION-3 "-0.5500000000"
*MEAS_COND_AXIS_POSITION-4 "0.0000000000"
*MEAS_COND_AXIS_POSITION-5 "0.0000000000"
*MEAS_COND_AXIS_POSITION-6 "0.0000000000"
*MEAS_COND_AXIS_POSITION-7 "-0.4278800000"
*MEAS_COND_AXIS_POSITION-8 "BB"
*MEAS_COND_AXIS_POSITION-9 "0.0000000000"
*MEAS_COND_AXIS_POSITION-10 "Soller_slit_5.0deg"
*MEAS_COND_AXIS_POSITION-11 "2/3deg"
*MEAS_COND_AXIS_POSITION-12 "2.2088000000"
*MEAS_COND_AXIS_POSITION-13 "-0.4140600000"
*MEAS_COND_AXIS_POSITION-14 "0.0000000000"
*MEAS_COND_AXIS_POSITION-15 "10.0mm"
*MEAS_COND_AXIS_POSITION-16 "None"
*MEAS_COND_AXIS_POSITION-17 "Cu_K-beta"
*MEAS_COND_AXIS_POSITION-18 "13.000mm"
*MEAS_COND_AXIS_POSITION-19 "13.000mm"
*MEAS_COND_AXIS_POSITION-20 "No_unit"
*MEAS_COND_AXIS_POSITION-21 "Soller_slit_5.0deg"
*MEAS_COND_AXIS_POSITION-22 "None"
*MEAS_COND_AXIS_POSITION-23 "13.0000000000"
*MEAS_COND_AXIS_POSITION-24 "13.0000000000"
*MEAS_COND_AXIS_POSITION-25 "0.0109400000"
*MEAS_COND_AXIS_POSITION-26 "Open"
*MEAS_COND_AXIS_POSITION-27 "None"
*MEAS_COND_AXIS_POSITION-28 "None"
*MEAS_COND_AXIS_POSITION-29 "None"
*MEAS_COND_AXIS_POSITION-30 "38.0000000000"
*MEAS_COND_AXIS_UNIT-0 "deg"
*MEAS_COND_AXIS_UNIT-1 "deg"
*MEAS_COND_AXIS_UNIT-2 "deg"
*MEAS_COND_AXIS_UNIT-3 "mm"
*MEAS_COND_AXIS_UNIT-4 "deg"
*MEAS_COND_AXIS_UNIT-5 "deg"
*MEAS_COND_AXIS_UNIT-6 "deg"
*MEAS_COND_AXIS_UNIT-7 "mm"
*MEAS_COND_AXIS_UNIT-8 ""
*MEAS_COND_AXIS_UNIT-9 "pulse"
*MEAS_COND_AXIS_UNIT-10 ""
*MEAS_COND_AXIS_UNIT-11 ""
*MEAS_COND_AXIS_UNIT-12 "mm"
*MEAS_COND_AXIS_UNIT-13 "mm"
*MEAS_COND_AXIS_UNIT-14 ""
*MEAS_COND_AXIS_UNIT-15 ""
*MEAS_COND_AXIS_UNIT-16 ""
*MEAS_COND_AXIS_UNIT-17 ""
*MEAS_COND_AXIS_UNIT-18 ""
*MEAS_COND_AXIS_UNIT-19 ""
*MEAS_COND_AXIS_UNIT-20 ""
*MEAS_COND_AXIS_UNIT-21 ""
*MEAS_COND_AXIS_UNIT-22 ""
*MEAS_COND_AXIS_UNIT-23 "mm"
*MEAS_COND_AXIS_UNIT-24 "mm"
*MEAS_COND_AXIS_UNIT-25 "mm"
*MEAS_COND_AXIS_UNIT-26 ""
*MEAS_COND_AXIS_UNIT-27 ""
*MEAS_COND_AXIS_UNIT-28 ""
*MEAS_COND_AXIS_UNIT-29 ""
*MEAS_COND_AXIS_UNIT-30 "div"
*MEAS_COND_COUNTER_CNTLOSS_CORR "0.0000000000"
*MEAS_COND_COUNTER_PHABASE "38.0000000000"
*MEAS_COND_COUNTER_PHAWINDOW "16.0000000000"
*MEAS_COND_COUNTER_PHA_UNIT "div"
*MEAS_COND_COUNTER_TAUDIFF "30.0000000000"
*MEAS_COND_COUNTER_TAUINT "0.0000000000"
*MEAS_COND_IRRADIATION_MODE "OFF"
*MEAS_COND_IRRADIATION_WIDTH ""
*MEAS_COND_OPT_ATTR "集中法"
*MEAS_COND_OPT_NAME "@集中法"
*MEAS_COND_UNSYMMETRIC_MODE "OFF"
*MEAS_COND_XG_CURRENT "30.0000000000"
*MEAS_COND_XG_VOLTAGE "40.0000000000"
*MEAS_COND_XG_WAVE_TYPE "Ka"
*MEAS_DATA_COUNT "3001.0000000000"
*MEAS_SCAN_AXIS_X "2θ/θ"
*MEAS_SCAN_AXIS_X_INTERNAL "TwoThetaTheta"
*MEAS_SCAN_END_TIME "08/21/20 16:04:58"
*MEAS_SCAN_MODE "CONTINUOUS"
*MEAS_SCAN_MONITOR "0"
*MEAS_SCAN_RESOLUTION_X "0.0002"
*MEAS_SCAN_SPEED "2.0"
*MEAS_SCAN_SPEED_UNIT "deg/min"
*MEAS_SCAN_START "20.0000000000"
*MEAS_SCAN_START_TIME "08/21/20 15:33:18"
*MEAS_SCAN_STEP "0.0200000000"
*MEAS_SCAN_STOP "80.0000000000"
*MEAS_SCAN_UNIT_X "deg"
*MEAS_SCAN_UNIT_Y "counts"
*RAS_HEADER_END
*RAS_INT_START
20.0000 1819.0000 1.0000
20.0600 1956.0000 1.0000
20.1200 1896.0000 1.0000
20.1800 1905.0000 1.0000
20.2400 1856.0000 1.0000
20.3000 1857.0000 1.0000
20.3600 1824.0000 1.0000
20.4200 1837.0000 1.0000
20.4800 1804.0000 1.0000
20.5400 1784.0000 1.0000
20.6000 1792.0000 1.0000
20.6600 1861.0000 1.0000
20.7200 1749.0000 1.0000
20.7800 1715.0000 1.0000
20.8400 1740.0000 1.0000
20.9000 1809.0000 1.0000
20.9600 1729.0000 1.0000
21.0200 1719.0000 1.0000
21.0800 1753.0000 1.0000
21.1400 1678.0000 1.0000
21.2000 1716.0000 1.0000
21.2600 1706.0000 1.0000
21.3200 1668.0000 1.0000
21.3800 1641.0000 1.0000
21.4400 1661.0000 1.0000
21.5000 1689.0000 1.0000
21.5600 1627.0000 1.0000
21.6200 1684.0000 1.0000
21.6800 1671.0000 1.0000
21.7400 1636.0000 1.0000
21.8000 1576.0000 1.0000
21.8600 1633.0000 1.0000
21.9200 1585.0000 1.0000
21.9800 1607.0000 1.0000
22.0400 1595.0000 1.0000
22.1000 1565.0000 1.0000
22.1600 1530.0000 1.0000
22.2200 1582.0000 1.0000
22.2800 1488.0000 1.0000
22.3400 1465.0000 1.0000
22.4000 1525.0000 1.0000
22.4600 1488.0000 1.0000
22.5200 1497.0000 1.0000
22.5800 1538.0000 1.0000
22.6400 1450.0000 1.0000
22.7000 1489.0000 1.0000
22.7600 1468.0000 1.0000
22.8200 1533.0000 1.0000
22.8800 1416.0000 1.0000
22.9400 1482.0000 1.0000
23.0000 1404.0000 1.0000
23.0600 1489.0000 1.0000
23.1200 1398.0000 1.0000
23.1800 1400.0000 1.0000
23.2400 1459.0000 1.0000
23.3000 1441.0000 1.0000
23.3600 1433.0000 1.0000
23.4200 1393.0000 1.0000
23.4800 1446.0000 1.0000
23.5400 1397.0000 1.0000
23.6000 1337.0000 1.0000
23.6600 1324.0000 1.0000
23.7200 1401.0000 1.0000
23.7800 1376.0000 1.0000
23.8400 1361.0000 1.0000
23.9000 1337.0000 1.0000
23.9600 1353.0000 1.0000
24.0200 1313.0000 1.0000
24.0800 1302.0000 1.0000
24.1400 1292.0000 1.0000
24.2000 1308.0000 1.0000
24.2600 1277.0000 1.0000
24.3200 1335.0000 1.0000
24.3800 1318.0000 1.0000
24.4400 1247.0000 1.0000
24.5000 1264.0000 1.0000
24.5600 1218.0000 1.0000
24.6200 1272.0000 1.0000
24.6800 1233.0000 1.0000
24.7400 1250.0000 1.0000
24.8000 1252.0000 1.0000
24.8600 1225.0000 1.0000
24.9200 1169.0000 1.0000
24.9800 1205.0000 1.0000
25.0400 1217.0000 1.0000
25.1000 1204.0000 1.0000
25.1600 1177.0000 1.0000
25.2200 1222.0000 1.0000
25.2800 1219.0000 1.0000
25.3400 1189.0000 1.0000
25.4000 1144.0000 1.0000
25.4600 1128.0000 1.0000
25.5200 1140.0000 1.0000
25.5800 1130.0000 1.0000
25.6400 1136.0000 1.0000
25.7000 1155.0000 1.0000
25.7600 1194.0000 1.0000
25.8200 1138.0000 1.0000
25.8800 1121.0000 1.0000
25.9400 1117.0000 1.0000
26.0000 1166.0000 1.0000
26.0600 1092.0000 1.0000
26.1200 1062.0000 1.0000
26.1800 1015.0000 1.0000
26.2400 1070.0000 1.0000
26.3000 1095.0000 1.0000
26.3600 1053.0000 1.0000
26.4200 1062.0000 1.0000
26.4800 1082.0000 1.0000
26.5400 1107.0000 1.0000
26.6000 1037.0000 1.0000
26.6600 1088.0000 1.0000
26.7200 1041.0000 1.0000
26.7800 1062.0000 1.0000
26.8400 1067.0000 1.0000
26.9000 1043.0000 1.0000
26.9600 1042.0000 1.0000
27.0200 1037.0000 1.0000
27.0800 1040.0000 1.0000
27.1400 1060.0000 1.0000
27.2000 1054.0000 1.0000
27.2600 1031.0000 1.0000
27.3200 1051.0000 1.0000
27.3800 1074.0000 1.0000
27.4400 1007.0000 1.0000
27.5000 979.0000 1.0000
27.5600 949.0000 1.0000
27.6200 1039.0000 1.0000
27.6800 1009.0000 1.0000
27.7400 940.0000 1.0000
27.8000 943.0000 1.0000
27.8600 1000.0000 1.0000
27.9200 950.0000 1.0000
27.9800 941.0000 1.0000
28.0400 933.0000 1.0000
28.1000 904.0000 1.0000
28.1600 894.0000 1.0000
28.2200 885.0000 1.0000
28.2800 938.0000 1.0000
28.3400 926.0000 1.0000
28.4000 941.0000 1.0000
28.4600 895.0000 1.0000
28.5200 931.0000 1.0000
28.5800 935.0000 1.0000
28.6400 826.0000 1.0000
28.7000 864.0000 1.0000
28.7600 922.0000 1.0000
28.8200 875.0000 1.0000
28.8800 882.0000 1.0000
28.9400 863.0000 1.0000
29.0000 878.0000 1.0000
29.0600 882.0000 1.0000
29.1200 857.0000 1.0000
29.1800 883.0000 1.0000
29.2400 806.0000 1.0000
29.3000 828.0000 1.0000
29.3600 834.0000 1.0000
29.4200 851.0000 1.0000
29.4800 831.0000 1.0000
29.5400 836.0000 1.0000
29.6000 814.0000 1.0000
29.6600 845.0000 1.0000
29.7200 853.0000 1.0000
29.7800 820.0000 1.0000
29.8400 796.0000 1.0000
29.9000 823.0000 1.0000
29.9600 800.0000 1.0000
30.0200 788.0000 1.0000
30.0800 815.0000 1.0000
30.1400 845.0000 1.0000
30.2000 775.0000 1.0000
30.2600 762.0000 1.0000
30.3200 724.0000 1.0000
30.3800 761.0000 1.0000
30.4400 776.0000 1.0000
30.5000 800.0000 1.0000
30.5600 757.0000 1.0000
30.6200 827.0000 1.0000
30.6800 734.0000 1.0000
30.7400 670.0000 1.0000
30.8000 738.0000 1.0000
30.8600 750.0000 1.0000
30.9200 702.0000 1.0000
30.9800 759.0000 1.0000
31.0400 732.0000 1.0000
31.1000 724.0000 1.0000
31.1600 705.0000 1.0000
31.2200 763.0000 1.0000
31.2800 692.0000 1.0000
31.3400 687.0000 1.0000
31.4000 746.0000 1.0000
31.4600 678.0000 1.0000
31.5200 675.0000 1.0000
31.5800 726.0000 1.0000
31.6400 728.0000 1.0000
31.7000 716.0000 1.0000
31.7600 648.0000 1.0000
31.8200 677.0000 1.0000
31.8800 733.0000 1.0000
31.9400 671.0000 1.0000
32.0000 642.0000 1.0000
32.0600 675.0000 1.0000
32.1200 662.0000 1.0000
32.1800 685.0000 1.0000
32.2400 703.0000 1.0000
32.3000 671.0000 1.0000
32.3600 693.0000 1.0000
32.4200 628.0000 1.0000
32.4800 642.0000 1.0000
32.5400 623.0000 1.0000
32.6000 632.0000 1.0000
32.6600 602.0000 1.0000
32.7200 643.0000 1.0000
32.7800 654.0000 1.0000
32.8400 619.0000 1.0000
32.9000 645.0000 1.0000
32.9600 647.0000 1.0000
33.0200 641.0000 1.0000
33.0800 628.0000 1.0000
33.1400 680.0000 1.0000
33.2000 620.0000 1.0000
33.2600 673.0000 1.0000
33.3200 633.0000 1.0000
33.3800 610.0000 1.0000
33.4400 620.0000 1.0000
33.5000 608.0000 1.0000
33.5600 619.0000 1.0000
33.6200 586.0000 1.0000
33.6800 591.0000 1.0000
33.7400 588.0000 1.0000
33.8000 608.0000 1.0000
33.8600 602.0000 1.0000
33.9200 555.0000 1.0000
33.9800 578.0000 1.0000
34.0400 580.0000 1.0000
34.1000 596.0000 1.0000
34.1600 590.0000 1.0000
34.2200 588.0000 1.0000
34.2800 572.0000 1.0000
34.3400 634.0000 1.0000
34.4000 592.0000 1.0000
34.4600 601.0000 1.0000
34.5200 589.0000 1.0000
34.5800 620.0000 1.0000
34.6400 602.0000 1.0000
34.7000 610.0000 1.0000
34.7600 590.0000 1.0000
34.8200 555.0000 1.0000
34.8800 546.0000 1.0000
34.9400 591.0000 1.0000
35.0000 547.0000 1.0000
35.0600 553.0000 1.0000
35.1200 524.0000 1.0000
35.1800 536.0000 1.0000
35.2400 568.0000 1.0000
35.3000 532.0000 1.0000
35.3600 557.0000 1.0000
35.4200 583.0000 1.0000
35.4800 506.0000 1.0000
35.5400 517.0000 1.0000
35.6000 510.0000 1.0000
35.6600 477.0000 1.0000
35.7200 500.0000 1.0000
35.7800 498.0000 1.0000
35.8400 522.0000 1.0000
35.9000 489.0000 1.0000
35.9600 463.0000 1.0000
36.0200 512.0000 1.0000
36.0800 529.0000 1.0000
36.1400 460.0000 1.0000
36.2000 473.0000 1.0000
36.2600 500.0000 1.0000
36.3200 502.0000 1.0000
36.3800 489.0000 1.0000
36.4400 500.0000 1.0000
36.5000 486.0000 1.0000
36.5600 474.0000 1.0000
36.6200 461.0000 1.0000
36.6800 446.0000 1.0000
36.7400 510.0000 1.0000
36.8000 448.0000 1.0000
36.8600 459.0000 1.0000
36.9200 471.0000 1.0000
36.9800 502.0000 1.0000
37.0400 488.0000 1.0000
37.1000 441.0000 1.0000
37.1600 470.0000 1.0000
37.2200 442.0000 1.0000
37.2800 440.0000 1.0000
37.3400 440.0000 1.0000
37.4000 440.0000 1.0000
37.4600 478.0000 1.0000
37.5200 472.0000 1.0000
37.5800 419.0000 1.0000
37.6400 462.0000 1.0000
37.7000 427.0000 1.0000
37.7600 420.0000 1.0000
37.8200 431.0000 1.0000
37.8800 453.0000 1.0000
37.9400 409.0000 1.0000
38.0000 421.0000 1.0000
38.0600 443.0000 1.0000
38.1200 430.0000 1.0000
38.1800 435.0000 1.0000
38.2400 439.0000 1.0000
38.3000 474.0000 1.0000
38.3600 464.0000 1.0000
38.4200 527.0000 1.0000
38.4800 542.0000 1.0000
38.5400 600.0000 1.0000
38.6000 634.0000 1.0000
38.6600 544.0000 1.0000
38.7200 516.0000 1.0000
38.7800 501.0000 1.0000
38.8400 416.0000 1.0000
38.9000 418.0000 1.0000
38.9600 421.0000 1.0000
39.0200 405.0000 1.0000
39.0800 409.0000 1.0000
39.1400 402.0000 1.0000
39.2000 371.0000 1.0000
39.2600 387.0000 1.0000
39.3200 390.0000 1.0000
39.3800 393.0000 1.0000
39.4400 395.0000 1.0000
39.5000 362.0000 1.0000
39.5600 404.0000 1.0000
39.6200 389.0000 1.0000
39.6800 396.0000 1.0000
39.7400 365.0000 1.0000
39.8000 391.0000 1.0000
39.8600 390.0000 1.0000
39.9200 353.0000 1.0000
39.9800 358.0000 1.0000
40.0400 373.0000 1.0000
40.1000 346.0000 1.0000
40.1600 388.0000 1.0000
40.2200 369.0000 1.0000
40.2800 383.0000 1.0000
40.3400 337.0000 1.0000
40.4000 379.0000 1.0000
40.4600 349.0000 1.0000
40.5200 381.0000 1.0000
40.5800 370.0000 1.0000
40.6400 357.0000 1.0000
40.7000 388.0000 1.0000
40.7600 340.0000 1.0000
40.8200 356.0000 1.0000
40.8800 349.0000 1.0000
40.9400 339.0000 1.0000
41.0000 335.0000 1.0000
41.0600 314.0000 1.0000
41.1200 353.0000 1.0000
41.1800 312.0000 1.0000
41.2400 328.0000 1.0000
41.3000 349.0000 1.0000
41.3600 344.0000 1.0000
41.4200 351.0000 1.0000
41.4800 334.0000 1.0000
41.5400 349.0000 1.0000
41.6000 335.0000 1.0000
41.6600 315.0000 1.0000
41.7200 343.0000 1.0000
41.7800 339.0000 1.0000
41.8400 294.0000 1.0000
41.9000 316.0000 1.0000
41.9600 319.0000 1.0000
42.0200 335.0000 1.0000
42.0800 329.0000 1.0000
42.1400 328.0000 1.0000
42.2000 308.0000 1.0000
42.2600 340.0000 1.0000
42.3200 298.0000 1.0000
42.3800 302.0000 1.0000
42.4400 336.0000 1.0000
42.5000 294.0000 1.0000
42.5600 326.0000 1.0000
42.6200 289.0000 1.0000
42.6800 357.0000 1.0000
42.7400 314.0000 1.0000
42.8000 307.0000 1.0000
42.8600 335.0000 1.0000
42.9200 313.0000 1.0000
42.9800 280.0000 1.0000
43.0400 311.0000 1.0000
43.1000 316.0000 1.0000
43.1600 290.0000 1.0000
43.2200 269.0000 1.0000
43.2800 306.0000 1.0000
43.3400 310.0000 1.0000
43.4000 284.0000 1.0000
43.4600 285.0000 1.0000
43.5200 276.0000 1.0000
43.5800 321.0000 1.0000
43.6400 313.0000 1.0000
43.7000 286.0000 1.0000
43.7600 295.0000 1.0000
43.8200 270.0000 1.0000
43.8800 283.0000 1.0000
43.9400 307.0000 1.0000
44.0000 306.0000 1.0000
44.0600 302.0000 1.0000
44.1200 279.0000 1.0000
44.1800 294.0000 1.0000
44.2400 266.0000 1.0000
44.3000 281.0000 1.0000
44.3600 283.0000 1.0000
44.4200 284.0000 1.0000
44.4800 281.0000 1.0000
44.5400 274.0000 1.0000
44.6000 317.0000 1.0000
44.6600 250.0000 1.0000
44.7200 264.0000 1.0000
44.7800 296.0000 1.0000
44.8400 242.0000 1.0000
44.9000 254.0000 1.0000
44.9600 283.0000 1.0000
45.0200 264.0000 1.0000
45.0800 264.0000 1.0000
45.1400 277.0000 1.0000
45.2000 281.0000 1.0000
45.2600 283.0000 1.0000
45.3200 273.0000 1.0000
45.3800 228.0000 1.0000
45.4400 257.0000 1.0000
45.5000 244.0000 1.0000
45.5600 274.0000 1.0000
45.6200 283.0000 1.0000
45.6800 247.0000 1.0000
45.7400 238.0000 1.0000
45.8000 240.0000 1.0000
45.8600 264.0000 1.0000
45.9200 253.0000 1.0000
45.9800 289.0000 1.0000
46.0400 258.0000 1.0000
46.1000 255.0000 1.0000
46.1600 269.0000 1.0000
46.2200 272.0000 1.0000
46.2800 284.0000 1.0000
46.3400 246.0000 1.0000
46.4000 262.0000 1.0000
46.4600 249.0000 1.0000
46.5200 252.0000 1.0000
46.5800 279.0000 1.0000
46.6400 244.0000 1.0000
46.7000 249.0000 1.0000
46.7600 262.0000 1.0000
46.8200 271.0000 1.0000
46.8800 264.0000 1.0000
46.9400 241.0000 1.0000
47.0000 246.0000 1.0000
47.0600 250.0000 1.0000
47.1200 269.0000 1.0000
47.1800 257.0000 1.0000
47.2400 237.0000 1.0000
47.3000 217.0000 1.0000
47.3600 242.0000 1.0000
47.4200 235.0000 1.0000
47.4800 254.0000 1.0000
47.5400 238.0000 1.0000
47.6000 233.0000 1.0000
47.6600 246.0000 1.0000
47.7200 261.0000 1.0000
47.7800 231.0000 1.0000
47.8400 252.0000 1.0000
47.9000 237.0000 1.0000
47.9600 258.0000 1.0000
48.0200 226.0000 1.0000
48.0800 239.0000 1.0000
48.1400 243.0000 1.0000
48.2000 238.0000 1.0000
48.2600 201.0000 1.0000
48.3200 217.0000 1.0000
48.3800 236.0000 1.0000
48.4400 254.0000 1.0000
48.5000 234.0000 1.0000
48.5600 257.0000 1.0000
48.6200 196.0000 1.0000
48.6800 241.0000 1.0000
48.7400 247.0000 1.0000
48.8000 221.0000 1.0000
48.8600 239.0000 1.0000
48.9200 222.0000 1.0000
48.9800 247.0000 1.0000
49.0400 238.0000 1.0000
49.1000 224.0000 1.0000
49.1600 222.0000 1.0000
49.2200 234.0000 1.0000
49.2800 226.0000 1.0000
49.3400 222.0000 1.0000
49.4000 225.0000 1.0000
49.4600 221.0000 1.0000
49.5200 226.0000 1.0000
49.5800 211.0000 1.0000
49.6400 214.0000 1.0000
49.7000 223.0000 1.0000
49.7600 225.0000 1.0000
49.8200 236.0000 1.0000
49.8800 211.0000 1.0000
49.9400 247.0000 1.0000
50.0000 218.0000 1.0000
50.0600 220.0000 1.0000
50.1200 192.0000 1.0000
50.1800 196.0000 1.0000
50.2400 209.0000 1.0000
50.3000 206.0000 1.0000
50.3600 201.0000 1.0000
50.4200 241.0000 1.0000
50.4800 205.0000 1.0000
50.5400 223.0000 1.0000
50.6000 214.0000 1.0000
50.6600 220.0000 1.0000
50.7200 212.0000 1.0000
50.7800 209.0000 1.0000
50.8400 220.0000 1.0000
50.9000 225.0000 1.0000
50.9600 187.0000 1.0000
51.0200 180.0000 1.0000
51.0800 216.0000 1.0000
51.1400 199.0000 1.0000
51.2000 205.0000 1.0000
51.2600 210.0000 1.0000
51.3200 199.0000 1.0000
51.3800 215.0000 1.0000
51.4400 202.0000 1.0000
51.5000 203.0000 1.0000
51.5600 188.0000 1.0000
51.6200 201.0000 1.0000
51.6800 201.0000 1.0000
51.7400 231.0000 1.0000
51.8000 204.0000 1.0000
51.8600 247.0000 1.0000
51.9200 227.0000 1.0000
51.9800 215.0000 1.0000
52.0400 238.0000 1.0000
52.1000 301.0000 1.0000
52.1600 351.0000 1.0000
52.2200 495.0000 1.0000
52.2800 630.0000 1.0000
52.3400 582.0000 1.0000
52.4000 562.0000 1.0000
52.4600 488.0000 1.0000
52.5200 356.0000 1.0000
52.5800 288.0000 1.0000
52.6400 258.0000 1.0000
52.7000 243.0000 1.0000
52.7600 208.0000 1.0000
52.8200 207.0000 1.0000
52.8800 196.0000 1.0000
52.9400 213.0000 1.0000
53.0000 195.0000 1.0000
53.0600 203.0000 1.0000
53.1200 219.0000 1.0000
53.1800 193.0000 1.0000
53.2400 181.0000 1.0000
53.3000 216.0000 1.0000
53.3600 214.0000 1.0000
53.4200 183.0000 1.0000
53.4800 192.0000 1.0000
53.5400 180.0000 1.0000
53.6000 204.0000 1.0000
53.6600 200.0000 1.0000
53.7200 208.0000 1.0000
53.7800 188.0000 1.0000
53.8400 205.0000 1.0000
53.9000 202.0000 1.0000
53.9600 206.0000 1.0000
54.0200 227.0000 1.0000
54.0800 186.0000 1.0000
54.1400 182.0000 1.0000
54.2000 201.0000 1.0000
54.2600 160.0000 1.0000
54.3200 188.0000 1.0000
54.3800 180.0000 1.0000
54.4400 204.0000 1.0000
54.5000 213.0000 1.0000
54.5600 196.0000 1.0000
54.6200 157.0000 1.0000
54.6800 195.0000 1.0000
54.7400 204.0000 1.0000
54.8000 193.0000 1.0000
54.8600 197.0000 1.0000
54.9200 200.0000 1.0000
54.9800 186.0000 1.0000
55.0400 182.0000 1.0000
55.1000 235.0000 1.0000
55.1600 190.0000 1.0000
55.2200 217.0000 1.0000
55.2800 233.0000 1.0000
55.3400 219.0000 1.0000
55.4000 223.0000 1.0000
55.4600 213.0000 1.0000
55.5200 194.0000 1.0000
55.5800 183.0000 1.0000
55.6400 197.0000 1.0000
55.7000 187.0000 1.0000
55.7600 171.0000 1.0000
55.8200 181.0000 1.0000
55.8800 190.0000 1.0000
55.9400 191.0000 1.0000
56.0000 172.0000 1.0000
56.0600 186.0000 1.0000
56.1200 191.0000 1.0000
56.1800 163.0000 1.0000
56.2400 183.0000 1.0000
56.3000 151.0000 1.0000
56.3600 181.0000 1.0000
56.4200 195.0000 1.0000
56.4800 165.0000 1.0000
56.5400 207.0000 1.0000
56.6000 182.0000 1.0000
56.6600 187.0000 1.0000
56.7200 193.0000 1.0000
56.7800 202.0000 1.0000
56.8400 186.0000 1.0000
56.9000 198.0000 1.0000
56.9600 192.0000 1.0000
57.0200 150.0000 1.0000
57.0800 179.0000 1.0000
57.1400 173.0000 1.0000
57.2000 183.0000 1.0000
57.2600 147.0000 1.0000
57.3200 184.0000 1.0000
57.3800 182.0000 1.0000
57.4400 173.0000 1.0000
57.5000 193.0000 1.0000
57.5600 176.0000 1.0000
57.6200 187.0000 1.0000
57.6800 179.0000 1.0000
57.7400 179.0000 1.0000
57.8000 173.0000 1.0000
57.8600 176.0000 1.0000
57.9200 221.0000 1.0000
57.9800 162.0000 1.0000
58.0400 180.0000 1.0000
58.1000 184.0000 1.0000
58.1600 160.0000 1.0000
58.2200 195.0000 1.0000
58.2800 172.0000 1.0000
58.3400 197.0000 1.0000
58.4000 204.0000 1.0000
58.4600 178.0000 1.0000
58.5200 171.0000 1.0000
58.5800 165.0000 1.0000
58.6400 190.0000 1.0000
58.7000 189.0000 1.0000
58.7600 186.0000 1.0000
58.8200 178.0000 1.0000
58.8800 169.0000 1.0000
58.9400 167.0000 1.0000
59.0000 179.0000 1.0000
59.0600 182.0000 1.0000
59.1200 176.0000 1.0000
59.1800 158.0000 1.0000
59.2400 159.0000 1.0000
59.3000 190.0000 1.0000
59.3600 162.0000 1.0000
59.4200 162.0000 1.0000
59.4800 186.0000 1.0000
59.5400 200.0000 1.0000
59.6000 184.0000 1.0000
59.6600 181.0000 1.0000
59.7200 175.0000 1.0000
59.7800 164.0000 1.0000
59.8400 164.0000 1.0000
59.9000 172.0000 1.0000
59.9600 160.0000 1.0000
60.0200 190.0000 1.0000
60.0800 202.0000 1.0000
60.1400 157.0000 1.0000
60.2000 177.0000 1.0000
60.2600 166.0000 1.0000
60.3200 182.0000 1.0000
60.3800 168.0000 1.0000
60.4400 187.0000 1.0000
60.5000 164.0000 1.0000
60.5600 171.0000 1.0000
60.6200 164.0000 1.0000
60.6800 168.0000 1.0000
60.7400 170.0000 1.0000
60.8000 161.0000 1.0000
60.8600 161.0000 1.0000
60.9200 170.0000 1.0000
60.9800 187.0000 1.0000
61.0400 175.0000 1.0000
61.1000 172.0000 1.0000
61.1600 175.0000 1.0000
61.2200 181.0000 1.0000
61.2800 186.0000 1.0000
61.3400 162.0000 1.0000
61.4000 164.0000 1.0000
61.4600 163.0000 1.0000
61.5200 189.0000 1.0000
61.5800 187.0000 1.0000
61.6400 179.0000 1.0000
61.7000 169.0000 1.0000
61.7600 173.0000 1.0000
61.8200 178.0000 1.0000
61.8800 170.0000 1.0000
61.9400 182.0000 1.0000
62.0000 207.0000 1.0000
62.0600 188.0000 1.0000
62.1200 214.0000 1.0000
62.1800 244.0000 1.0000
62.2400 269.0000 1.0000
62.3000 300.0000 1.0000
62.3600 235.0000 1.0000
62.4200 273.0000 1.0000
62.4800 271.0000 1.0000
62.5400 280.0000 1.0000
62.6000 211.0000 1.0000
62.6600 206.0000 1.0000
62.7200 188.0000 1.0000
62.7800 195.0000 1.0000
62.8400 189.0000 1.0000
62.9000 193.0000 1.0000
62.9600 163.0000 1.0000
63.0200 195.0000 1.0000
63.0800 184.0000 1.0000
63.1400 168.0000 1.0000
63.2000 181.0000 1.0000
63.2600 188.0000 1.0000
63.3200 159.0000 1.0000
63.3800 166.0000 1.0000
63.4400 152.0000 1.0000
63.5000 183.0000 1.0000
63.5600 184.0000 1.0000
63.6200 149.0000 1.0000
63.6800 142.0000 1.0000
63.7400 160.0000 1.0000
63.8000 205.0000 1.0000
63.8600 182.0000 1.0000
63.9200 188.0000 1.0000
63.9800 186.0000 1.0000
64.0400 161.0000 1.0000
64.1000 169.0000 1.0000
64.1600 161.0000 1.0000
64.2200 176.0000 1.0000
64.2800 174.0000 1.0000
64.3400 163.0000 1.0000
64.4000 172.0000 1.0000
64.4600 185.0000 1.0000
64.5200 195.0000 1.0000
64.5800 184.0000 1.0000
64.6400 197.0000 1.0000
64.7000 201.0000 1.0000
64.7600 193.0000 1.0000
64.8200 207.0000 1.0000
64.8800 196.0000 1.0000
64.9400 179.0000 1.0000
65.0000 175.0000 1.0000
65.0600 192.0000 1.0000
65.1200 179.0000 1.0000
65.1800 181.0000 1.0000
65.2400 176.0000 1.0000
65.3000 161.0000 1.0000
65.3600 174.0000 1.0000
65.4200 158.0000 1.0000
65.4800 190.0000 1.0000
65.5400 197.0000 1.0000
65.6000 178.0000 1.0000
65.6600 169.0000 1.0000
65.7200 169.0000 1.0000
65.7800 165.0000 1.0000
65.8400 187.0000 1.0000
65.9000 205.0000 1.0000
65.9600 201.0000 1.0000
66.0200 189.0000 1.0000
66.0800 241.0000 1.0000
66.1400 283.0000 1.0000
66.2000 364.0000 1.0000
66.2600 412.0000 1.0000
66.3200 382.0000 1.0000
66.3800 425.0000 1.0000
66.4400 381.0000 1.0000
66.5000 332.0000 1.0000
66.5600 285.0000 1.0000
66.6200 272.0000 1.0000
66.6800 240.0000 1.0000
66.7400 211.0000 1.0000
66.8000 200.0000 1.0000
66.8600 194.0000 1.0000
66.9200 166.0000 1.0000
66.9800 197.0000 1.0000
67.0400 161.0000 1.0000
67.1000 163.0000 1.0000
67.1600 172.0000 1.0000
67.2200 191.0000 1.0000
67.2800 169.0000 1.0000
67.3400 156.0000 1.0000
67.4000 164.0000 1.0000
67.4600 169.0000 1.0000
67.5200 155.0000 1.0000
67.5800 160.0000 1.0000
67.6400 140.0000 1.0000
67.7000 163.0000 1.0000
67.7600 166.0000 1.0000
67.8200 160.0000 1.0000
67.8800 183.0000 1.0000
67.9400 154.0000 1.0000
68.0000 165.0000 1.0000
68.0600 170.0000 1.0000
68.1200 161.0000 1.0000
68.1800 162.0000 1.0000
68.2400 150.0000 1.0000
68.3000 155.0000 1.0000
68.3600 188.0000 1.0000
68.4200 163.0000 1.0000
68.4800 159.0000 1.0000
68.5400 153.0000 1.0000
68.6000 167.0000 1.0000
68.6600 156.0000 1.0000
68.7200 164.0000 1.0000
68.7800 171.0000 1.0000
68.8400 170.0000 1.0000
68.9000 175.0000 1.0000
68.9600 163.0000 1.0000
69.0200 164.0000 1.0000
69.0800 160.0000 1.0000
69.1400 133.0000 1.0000
69.2000 173.0000 1.0000
69.2600 169.0000 1.0000
69.3200 161.0000 1.0000
69.3800 155.0000 1.0000
69.4400 149.0000 1.0000
69.5000 154.0000 1.0000
69.5600 144.0000 1.0000
69.6200 142.0000 1.0000
69.6800 161.0000 1.0000
69.7400 152.0000 1.0000
69.8000 172.0000 1.0000
69.8600 163.0000 1.0000
69.9200 171.0000 1.0000
69.9800 153.0000 1.0000
70.0400 148.0000 1.0000
70.1000 160.0000 1.0000
70.1600 166.0000 1.0000
70.2200 163.0000 1.0000
70.2800 156.0000 1.0000
70.3400 182.0000 1.0000
70.4000 146.0000 1.0000
70.4600 152.0000 1.0000
70.5200 152.0000 1.0000
70.5800 137.0000 1.0000
70.6400 153.0000 1.0000
70.7000 163.0000 1.0000
70.7600 169.0000 1.0000
70.8200 183.0000 1.0000
70.8800 154.0000 1.0000
70.9400 156.0000 1.0000
71.0000 150.0000 1.0000
71.0600 160.0000 1.0000
71.1200 168.0000 1.0000
71.1800 165.0000 1.0000
71.2400 144.0000 1.0000
71.3000 153.0000 1.0000
71.3600 164.0000 1.0000
71.4200 158.0000 1.0000
71.4800 169.0000 1.0000
71.5400 150.0000 1.0000
71.6000 173.0000 1.0000
71.6600 169.0000 1.0000
71.7200 174.0000 1.0000
71.7800 184.0000 1.0000
71.8400 164.0000 1.0000
71.9000 160.0000 1.0000
71.9600 180.0000 1.0000
72.0200 143.0000 1.0000
72.0800 154.0000 1.0000
72.1400 159.0000 1.0000
72.2000 161.0000 1.0000
72.2600 141.0000 1.0000
72.3200 160.0000 1.0000
72.3800 148.0000 1.0000
72.4400 149.0000 1.0000
72.5000 153.0000 1.0000
72.5600 168.0000 1.0000
72.6200 147.0000 1.0000
72.6800 144.0000 1.0000
72.7400 135.0000 1.0000
72.8000 165.0000 1.0000
72.8600 132.0000 1.0000
72.9200 162.0000 1.0000
72.9800 178.0000 1.0000
73.0400 147.0000 1.0000
73.1000 163.0000 1.0000
73.1600 144.0000 1.0000
73.2200 157.0000 1.0000
73.2800 151.0000 1.0000
73.3400 169.0000 1.0000
73.4000 153.0000 1.0000
73.4600 151.0000 1.0000
73.5200 128.0000 1.0000
73.5800 131.0000 1.0000
73.6400 168.0000 1.0000
73.7000 159.0000 1.0000
73.7600 148.0000 1.0000
73.8200 127.0000 1.0000
73.8800 163.0000 1.0000
73.9400 128.0000 1.0000
74.0000 150.0000 1.0000
74.0600 150.0000 1.0000
74.1200 144.0000 1.0000
74.1800 154.0000 1.0000
74.2400 162.0000 1.0000
74.3000 132.0000 1.0000
74.3600 116.0000 1.0000
74.4200 137.0000 1.0000
74.4800 161.0000 1.0000
74.5400 138.0000 1.0000
74.6000 140.0000 1.0000
74.6600 158.0000 1.0000
74.7200 146.0000 1.0000
74.7800 143.0000 1.0000
74.8400 168.0000 1.0000
74.9000 157.0000 1.0000
74.9600 138.0000 1.0000
75.0200 157.0000 1.0000
75.0800 144.0000 1.0000
75.1400 152.0000 1.0000
75.2000 154.0000 1.0000
75.2600 144.0000 1.0000
75.3200 149.0000 1.0000
75.3800 126.0000 1.0000
75.4400 132.0000 1.0000
75.5000 158.0000 1.0000
75.5600 135.0000 1.0000
75.6200 164.0000 1.0000
75.6800 157.0000 1.0000
75.7400 164.0000 1.0000
75.8000 168.0000 1.0000
75.8600 127.0000 1.0000
75.9200 162.0000 1.0000
75.9800 153.0000 1.0000
76.0400 156.0000 1.0000
76.1000 147.0000 1.0000
76.1600 180.0000 1.0000
76.2200 160.0000 1.0000
76.2800 135.0000 1.0000
76.3400 138.0000 1.0000
76.4000 145.0000 1.0000
76.4600 141.0000 1.0000
76.5200 143.0000 1.0000
76.5800 136.0000 1.0000
76.6400 120.0000 1.0000
76.7000 146.0000 1.0000
76.7600 142.0000 1.0000
76.8200 126.0000 1.0000
76.8800 176.0000 1.0000
76.9400 147.0000 1.0000
77.0000 151.0000 1.0000
77.0600 147.0000 1.0000
77.1200 141.0000 1.0000
77.1800 141.0000 1.0000
77.2400 129.0000 1.0000
77.3000 137.0000 1.0000
77.3600 132.0000 1.0000
77.4200 153.0000 1.0000
77.4800 147.0000 1.0000
77.5400 126.0000 1.0000
77.6000 126.0000 1.0000
77.6600 167.0000 1.0000
77.7200 137.0000 1.0000
77.7800 155.0000 1.0000
77.8400 145.0000 1.0000
77.9000 146.0000 1.0000
77.9600 153.0000 1.0000
78.0200 149.0000 1.0000
78.0800 164.0000 1.0000
78.1400 166.0000 1.0000
78.2000 159.0000 1.0000
78.2600 145.0000 1.0000
78.3200 133.0000 1.0000
78.3800 137.0000 1.0000
78.4400 156.0000 1.0000
78.5000 144.0000 1.0000
78.5600 144.0000 1.0000
78.6200 159.0000 1.0000
78.6800 172.0000 1.0000
78.7400 178.0000 1.0000
78.8000 193.0000 1.0000
78.8600 186.0000 1.0000
78.9200 183.0000 1.0000
78.9800 225.0000 1.0000
79.0400 196.0000 1.0000
79.1000 199.0000 1.0000
79.1600 210.0000 1.0000
79.2200 188.0000 1.0000
79.2800 182.0000 1.0000
79.3400 174.0000 1.0000
79.4000 164.0000 1.0000
79.4600 156.0000 1.0000
79.5200 162.0000 1.0000
79.5800 154.0000 1.0000
79.6400 153.0000 1.0000
79.7000 158.0000 1.0000
79.7600 157.0000 1.0000
79.8200 161.0000 1.0000
79.8800 144.0000 1.0000
79.9400 143.0000 1.0000
80.0000 125.0000 1.0000
*RAS_INT_END
*RAS_TEMPERATURE_START
*RAS_TEMPERATURE_END
*RAS_DATA_END