File: Sectio1_28_samples/XRD/No_026_750_16.ras
*RAS_DATA_START
*RAS_HEADER_START
*DISP_FMT_X "%.2f"
*DISP_FMT_Y "%.0f"
*DISP_FULLSCALE "4046.0000000000"
*DISP_LINE_COLOR "255.0000000000"
*DISP_LINE_STYLE "0.0000000000"
*DISP_LINE_WIDTH "0.2500000000"
*DISP_NOTE "測定データ-4"
*DISP_OFFSET_Y "0.0000000000"
*DISP_PEAKSEARCH_UNIT_Y "cps"
*DISP_RANGE_BOTTOM "0.0000000000"
*DISP_RANGE_LEFT "20.0000000000"
*DISP_RANGE_LOGCUTOFF "0.0100000000"
*DISP_RANGE_RIGHT "80.0000000000"
*DISP_RANGE_TOP "4046.0000000000"
*DISP_SCALE_MODE_Y "0.0000000000"
*DISP_TAB_NAME "2θ/θ"
*DISP_TITLE_Y "強度"
*DISP_UNIT_Y "cps"
*DISP_WINDOW_NAME "MSG_MACROENGINE"
*FILE_COMMENT " "
*FILE_MD5 ""
*FILE_MEMO " "
*FILE_OPERATOR "Administrator"
*FILE_SAMPLE " "
*FILE_TYPE "RAS_RAW"
*FILE_USERGROUP "システムマネージャ"
*FILE_VERSION "1.0000000000"
*HW_ATTACHMENT_ID "ATT0025"
*HW_ATTACHMENT_NAME "標準|Standard"
*HW_COUNTER_ID-0 "CUT0025"
*HW_COUNTER_ID-1 "CUT0020"
*HW_COUNTER_ID-2 "CUT0020"
*HW_COUNTER_ID-3 "CSL0021"
*HW_COUNTER_ID-4 "CMC0021"
*HW_COUNTER_NAME-0 "D/teX Ultra|D/teX Ultra"
*HW_COUNTER_NAME-1 "None|None"
*HW_COUNTER_NAME-2 "None|None"
*HW_COUNTER_NAME-3 "BBM|BBM"
*HW_COUNTER_NAME-4 "検出器モノクロメータ|Detector monochromator"
*HW_COUNTER_SELECT_NAME "D/teX Ultra|D/teX Ultra"
*HW_GONIOMETER_ID "GON0023"
*HW_GONIOMETER_NAME "SmartLab|SmartLab"
*HW_GONIOMETER_RADIUS-0 "90.0"
*HW_GONIOMETER_RADIUS-1 "114.0"
*HW_GONIOMETER_RADIUS-2 "190.0"
*HW_GONIOMETER_RADIUS-3 "300.0"
*HW_GONIOMETER_RADIUS-4 "187.0"
*HW_GONIOMETER_RADIUS-5 "300.0"
*HW_GONIOMETER_RADIUS-6 "113.0"
*HW_GONIOMETER_RADIUS-7 "331.0"
*HW_I_OPT_ID-0 "CBO0021"
*HW_I_OPT_ID-1 "ICR0023"
*HW_I_OPT_ID-2 "ISL0021"
*HW_I_OPT_ID-3 "ISO0021"
*HW_I_OPT_ID-4 "IAD0021"
*HW_I_OPT_ID-5 "IPR0001"
*HW_I_OPT_NAME-0 "CBOユニット|CBO unit"
*HW_I_OPT_NAME-1 "標準入射光学ユニット|Standard incident optical unit"
*HW_I_OPT_NAME-2 "標準入射スリットボックス|Standard incident slit box"
*HW_I_OPT_NAME-3 "入射平行スリット|Incident parallel slit"
*HW_I_OPT_NAME-4 "長手制限スリット|Length limiting slit"
*HW_I_OPT_NAME-5 "None|None"
*HW_R_ATTENUATER_AUTOMODE "0"
*HW_R_OPT_ID-0 "RSS0021"
*HW_R_OPT_ID-1 "RCR0023"
*HW_R_OPT_ID-2 "RSO0021"
*HW_R_OPT_ID-3 "RRS0021"
*HW_R_OPT_ID-4 "ATN0021"
*HW_R_OPT_ID-5 "RFL0021"
*HW_R_OPT_ID-6 "RAD0021"
*HW_R_OPT_NAME-0 "標準受光スリットボックス1|Standard receiving slit box # 1"
*HW_R_OPT_NAME-1 "標準受光光学ユニット1|Standard receiving unit # 1"
*HW_R_OPT_NAME-2 "標準受光光学ユニット2|Standard receiving optical unit # 2"
*HW_R_OPT_NAME-3 "標準受光スリットボックス2|Standard receiving slit box # 2"
*HW_R_OPT_NAME-4 "標準アッテネータ|Standard Attenuator"
*HW_R_OPT_NAME-5 "Cu Kβ|Cu K-beta"
*HW_R_OPT_NAME-6 "調整用受光スリット|Alignment receiving slit"
*HW_SAMPLE_HOLDER_ID "SMP0023"
*HW_SAMPLE_HOLDER_NAME "標準Zステージ|Standard Z stage"
*HW_XG_CURRENT_MAX "50"
*HW_XG_CURRENT_MIN "2"
*HW_XG_CURRENT_RESOLUTION "2"
*HW_XG_CURRENT_UNIT "mA"
*HW_XG_FOCUS "1mm x 10mm"
*HW_XG_FOCUS_TYPE "Normal"
*HW_XG_ID ""
*HW_XG_NAME "3kW 封入管(ID:1200)|3kW Sealed tube(ID:1200)"
*HW_XG_TARGET_ATOMIC_NUMBER "29.0000000000"
*HW_XG_TARGET_NAME "Cu"
*HW_XG_TYPE "Hermetic"
*HW_XG_VOLTAGE_MAX "60"
*HW_XG_VOLTAGE_MIN "20"
*HW_XG_VOLTAGE_RESOLUTION "2"
*HW_XG_VOLTAGE_UNIT "kV"
*HW_XG_WATT_MAX "2"
*HW_XG_WATT_UNIT "kW"
*HW_XG_WAVE_LENGTH_ALPHA1 "1.540593"
*HW_XG_WAVE_LENGTH_ALPHA2 "1.544414"
*HW_XG_WAVE_LENGTH_BETA "1.392250"
*MEAS_COND_AXIS_NAME-0 "2θ/θ"
*MEAS_COND_AXIS_NAME-1 "2θ"
*MEAS_COND_AXIS_NAME-2 "ω"
*MEAS_COND_AXIS_NAME-3 "Z"
*MEAS_COND_AXIS_NAME-4 "2θ/ω"
*MEAS_COND_AXIS_NAME-5 "θs"
*MEAS_COND_AXIS_NAME-6 "θd"
*MEAS_COND_AXIS_NAME-7 "Ts"
*MEAS_COND_AXIS_NAME-8 "CBO選択スリット"
*MEAS_COND_AXIS_NAME-9 "M"
*MEAS_COND_AXIS_NAME-10 "入射平行スリット"
*MEAS_COND_AXIS_NAME-11 "入射スリット"
*MEAS_COND_AXIS_NAME-12 ""
*MEAS_COND_AXIS_NAME-13 "Zs"
*MEAS_COND_AXIS_NAME-14 "入射光学素子"
*MEAS_COND_AXIS_NAME-15 "長手制限スリット"
*MEAS_COND_AXIS_NAME-16 "センタースリット"
*MEAS_COND_AXIS_NAME-17 "フィルター"
*MEAS_COND_AXIS_NAME-18 "受光スリット1"
*MEAS_COND_AXIS_NAME-19 "受光スリット2"
*MEAS_COND_AXIS_NAME-20 "受光光学素子"
*MEAS_COND_AXIS_NAME-21 "受光平行スリット"
*MEAS_COND_AXIS_NAME-22 "調整用受光スリット"
*MEAS_COND_AXIS_NAME-23 ""
*MEAS_COND_AXIS_NAME-24 ""
*MEAS_COND_AXIS_NAME-25 "Zd"
*MEAS_COND_AXIS_NAME-26 "アッテネータ"
*MEAS_COND_AXIS_NAME-27 "検出器モノクロメータ"
*MEAS_COND_AXIS_NAME-28 "モノクロメータスリット"
*MEAS_COND_AXIS_NAME-29 "プライマリビーム"
*MEAS_COND_AXIS_NAME-30 "PHA"
*MEAS_COND_AXIS_NAME_INTERNAL-0 "TwoThetaTheta"
*MEAS_COND_AXIS_NAME_INTERNAL-1 "TwoTheta"
*MEAS_COND_AXIS_NAME_INTERNAL-2 "Omega"
*MEAS_COND_AXIS_NAME_INTERNAL-3 "Z"
*MEAS_COND_AXIS_NAME_INTERNAL-4 "TwoThetaOmega"
*MEAS_COND_AXIS_NAME_INTERNAL-5 "ThetaS"
*MEAS_COND_AXIS_NAME_INTERNAL-6 "ThetaD"
*MEAS_COND_AXIS_NAME_INTERNAL-7 "Ts"
*MEAS_COND_AXIS_NAME_INTERNAL-8 "CBO"
*MEAS_COND_AXIS_NAME_INTERNAL-9 "CBO-M"
*MEAS_COND_AXIS_NAME_INTERNAL-10 "IncidentSollerSlit"
*MEAS_COND_AXIS_NAME_INTERNAL-11 "IncidentSlitBox"
*MEAS_COND_AXIS_NAME_INTERNAL-12 "IncidentSlitBox-_Axis"
*MEAS_COND_AXIS_NAME_INTERNAL-13 "Zs"
*MEAS_COND_AXIS_NAME_INTERNAL-14 "IncidentMonochromator"
*MEAS_COND_AXIS_NAME_INTERNAL-15 "IncidentAxdSlit"
*MEAS_COND_AXIS_NAME_INTERNAL-16 "CenterSlit"
*MEAS_COND_AXIS_NAME_INTERNAL-17 "Filter"
*MEAS_COND_AXIS_NAME_INTERNAL-18 "ReceivingSlitBox1"
*MEAS_COND_AXIS_NAME_INTERNAL-19 "ReceivingSlitBox2"
*MEAS_COND_AXIS_NAME_INTERNAL-20 "ReceivingOptics"
*MEAS_COND_AXIS_NAME_INTERNAL-21 "ReceivingSollerSlit"
*MEAS_COND_AXIS_NAME_INTERNAL-22 "ReceivingAxdSlit"
*MEAS_COND_AXIS_NAME_INTERNAL-23 "ReceivingSlitBox1-_Axis"
*MEAS_COND_AXIS_NAME_INTERNAL-24 "ReceivingSlitBox2-_Axis"
*MEAS_COND_AXIS_NAME_INTERNAL-25 "ReceivingSlitBox2-Zd"
*MEAS_COND_AXIS_NAME_INTERNAL-26 "Attenuator"
*MEAS_COND_AXIS_NAME_INTERNAL-27 "CounterMonochromator"
*MEAS_COND_AXIS_NAME_INTERNAL-28 "CounterSlit"
*MEAS_COND_AXIS_NAME_INTERNAL-29 "IncidentPrimary"
*MEAS_COND_AXIS_NAME_INTERNAL-30 "PHA"
*MEAS_COND_AXIS_NAME_MAGICNO-0 "83951616.0000000000"
*MEAS_COND_AXIS_NAME_MAGICNO-1 "268632064.0000000000"
*MEAS_COND_AXIS_NAME_MAGICNO-2 "268500992.0000000000"
*MEAS_COND_AXIS_NAME_MAGICNO-3 "285278208.0000000000"
*MEAS_COND_AXIS_NAME_MAGICNO-4 "83951616.0000000000"
*MEAS_COND_AXIS_NAME_MAGICNO-5 "131072.0000000000"
*MEAS_COND_AXIS_NAME_MAGICNO-6 "131072.0000000000"
*MEAS_COND_AXIS_NAME_MAGICNO-7 "318898176.0000000000"
*MEAS_COND_AXIS_NAME_MAGICNO-8 "20971521.0000000000"
*MEAS_COND_AXIS_NAME_MAGICNO-9 "285343744.0000000000"
*MEAS_COND_AXIS_NAME_MAGICNO-10 "20971521.0000000000"
*MEAS_COND_AXIS_NAME_MAGICNO-11 "22020097.0000000000"
*MEAS_COND_AXIS_NAME_MAGICNO-12 "25165824.0000000000"
*MEAS_COND_AXIS_NAME_MAGICNO-13 "318898176.0000000000"
*MEAS_COND_AXIS_NAME_MAGICNO-14 "1.0000000000"
*MEAS_COND_AXIS_NAME_MAGICNO-15 "20971521.0000000000"
*MEAS_COND_AXIS_NAME_MAGICNO-16 "20971521.0000000000"
*MEAS_COND_AXIS_NAME_MAGICNO-17 "20971521.0000000000"
*MEAS_COND_AXIS_NAME_MAGICNO-18 "23068673.0000000000"
*MEAS_COND_AXIS_NAME_MAGICNO-19 "23068673.0000000000"
*MEAS_COND_AXIS_NAME_MAGICNO-20 "20971521.0000000000"
*MEAS_COND_AXIS_NAME_MAGICNO-21 "20971521.0000000000"
*MEAS_COND_AXIS_NAME_MAGICNO-22 "20971521.0000000000"
*MEAS_COND_AXIS_NAME_MAGICNO-23 "25165824.0000000000"
*MEAS_COND_AXIS_NAME_MAGICNO-24 "25165824.0000000000"
*MEAS_COND_AXIS_NAME_MAGICNO-25 "285343744.0000000000"
*MEAS_COND_AXIS_NAME_MAGICNO-26 "17301505.0000000000"
*MEAS_COND_AXIS_NAME_MAGICNO-27 "20971521.0000000000"
*MEAS_COND_AXIS_NAME_MAGICNO-28 "20971521.0000000000"
*MEAS_COND_AXIS_NAME_MAGICNO-29 "20971521.0000000000"
*MEAS_COND_AXIS_NAME_MAGICNO-30 "0.0000000000"
*MEAS_COND_AXIS_OFFSET-0 "-"
*MEAS_COND_AXIS_OFFSET-1 "-0.1081000000"
*MEAS_COND_AXIS_OFFSET-2 "0.3758000000"
*MEAS_COND_AXIS_OFFSET-3 "-"
*MEAS_COND_AXIS_OFFSET-4 "-"
*MEAS_COND_AXIS_OFFSET-5 "0.3758000000"
*MEAS_COND_AXIS_OFFSET-6 "-0.4839000000"
*MEAS_COND_AXIS_OFFSET-7 "-"
*MEAS_COND_AXIS_OFFSET-8 "-"
*MEAS_COND_AXIS_OFFSET-9 "-"
*MEAS_COND_AXIS_OFFSET-10 "-"
*MEAS_COND_AXIS_OFFSET-11 "-"
*MEAS_COND_AXIS_OFFSET-12 "-"
*MEAS_COND_AXIS_OFFSET-13 "-"
*MEAS_COND_AXIS_OFFSET-14 "-"
*MEAS_COND_AXIS_OFFSET-15 "-"
*MEAS_COND_AXIS_OFFSET-16 "-"
*MEAS_COND_AXIS_OFFSET-17 "-"
*MEAS_COND_AXIS_OFFSET-18 "-"
*MEAS_COND_AXIS_OFFSET-19 "-"
*MEAS_COND_AXIS_OFFSET-20 "-"
*MEAS_COND_AXIS_OFFSET-21 "-"
*MEAS_COND_AXIS_OFFSET-22 "-"
*MEAS_COND_AXIS_OFFSET-23 "-"
*MEAS_COND_AXIS_OFFSET-24 "-"
*MEAS_COND_AXIS_OFFSET-25 "-"
*MEAS_COND_AXIS_OFFSET-26 "-"
*MEAS_COND_AXIS_OFFSET-27 "-"
*MEAS_COND_AXIS_OFFSET-28 "-"
*MEAS_COND_AXIS_OFFSET-29 "-"
*MEAS_COND_AXIS_OFFSET-30 "-"
*MEAS_COND_AXIS_POSITION-0 "0.0000000000"
*MEAS_COND_AXIS_POSITION-1 "0.0000000000"
*MEAS_COND_AXIS_POSITION-2 "0.0000000000"
*MEAS_COND_AXIS_POSITION-3 "-0.5500000000"
*MEAS_COND_AXIS_POSITION-4 "0.0000000000"
*MEAS_COND_AXIS_POSITION-5 "0.0000000000"
*MEAS_COND_AXIS_POSITION-6 "0.0000000000"
*MEAS_COND_AXIS_POSITION-7 "-0.4278800000"
*MEAS_COND_AXIS_POSITION-8 "BB"
*MEAS_COND_AXIS_POSITION-9 "0.0000000000"
*MEAS_COND_AXIS_POSITION-10 "Soller_slit_5.0deg"
*MEAS_COND_AXIS_POSITION-11 "2/3deg"
*MEAS_COND_AXIS_POSITION-12 "2.2088000000"
*MEAS_COND_AXIS_POSITION-13 "-0.4140600000"
*MEAS_COND_AXIS_POSITION-14 "0.0000000000"
*MEAS_COND_AXIS_POSITION-15 "10.0mm"
*MEAS_COND_AXIS_POSITION-16 "None"
*MEAS_COND_AXIS_POSITION-17 "Cu_K-beta"
*MEAS_COND_AXIS_POSITION-18 "13.000mm"
*MEAS_COND_AXIS_POSITION-19 "13.000mm"
*MEAS_COND_AXIS_POSITION-20 "No_unit"
*MEAS_COND_AXIS_POSITION-21 "Soller_slit_5.0deg"
*MEAS_COND_AXIS_POSITION-22 "None"
*MEAS_COND_AXIS_POSITION-23 "13.0000000000"
*MEAS_COND_AXIS_POSITION-24 "13.0000000000"
*MEAS_COND_AXIS_POSITION-25 "0.0109400000"
*MEAS_COND_AXIS_POSITION-26 "Open"
*MEAS_COND_AXIS_POSITION-27 "None"
*MEAS_COND_AXIS_POSITION-28 "None"
*MEAS_COND_AXIS_POSITION-29 "None"
*MEAS_COND_AXIS_POSITION-30 "38.0000000000"
*MEAS_COND_AXIS_UNIT-0 "deg"
*MEAS_COND_AXIS_UNIT-1 "deg"
*MEAS_COND_AXIS_UNIT-2 "deg"
*MEAS_COND_AXIS_UNIT-3 "mm"
*MEAS_COND_AXIS_UNIT-4 "deg"
*MEAS_COND_AXIS_UNIT-5 "deg"
*MEAS_COND_AXIS_UNIT-6 "deg"
*MEAS_COND_AXIS_UNIT-7 "mm"
*MEAS_COND_AXIS_UNIT-8 ""
*MEAS_COND_AXIS_UNIT-9 "pulse"
*MEAS_COND_AXIS_UNIT-10 ""
*MEAS_COND_AXIS_UNIT-11 ""
*MEAS_COND_AXIS_UNIT-12 "mm"
*MEAS_COND_AXIS_UNIT-13 "mm"
*MEAS_COND_AXIS_UNIT-14 ""
*MEAS_COND_AXIS_UNIT-15 ""
*MEAS_COND_AXIS_UNIT-16 ""
*MEAS_COND_AXIS_UNIT-17 ""
*MEAS_COND_AXIS_UNIT-18 ""
*MEAS_COND_AXIS_UNIT-19 ""
*MEAS_COND_AXIS_UNIT-20 ""
*MEAS_COND_AXIS_UNIT-21 ""
*MEAS_COND_AXIS_UNIT-22 ""
*MEAS_COND_AXIS_UNIT-23 "mm"
*MEAS_COND_AXIS_UNIT-24 "mm"
*MEAS_COND_AXIS_UNIT-25 "mm"
*MEAS_COND_AXIS_UNIT-26 ""
*MEAS_COND_AXIS_UNIT-27 ""
*MEAS_COND_AXIS_UNIT-28 ""
*MEAS_COND_AXIS_UNIT-29 ""
*MEAS_COND_AXIS_UNIT-30 "div"
*MEAS_COND_COUNTER_CNTLOSS_CORR "0.0000000000"
*MEAS_COND_COUNTER_PHABASE "38.0000000000"
*MEAS_COND_COUNTER_PHAWINDOW "16.0000000000"
*MEAS_COND_COUNTER_PHA_UNIT "div"
*MEAS_COND_COUNTER_TAUDIFF "30.0000000000"
*MEAS_COND_COUNTER_TAUINT "0.0000000000"
*MEAS_COND_IRRADIATION_MODE "OFF"
*MEAS_COND_IRRADIATION_WIDTH ""
*MEAS_COND_OPT_ATTR "集中法"
*MEAS_COND_OPT_NAME "@集中法"
*MEAS_COND_UNSYMMETRIC_MODE "OFF"
*MEAS_COND_XG_CURRENT "30.0000000000"
*MEAS_COND_XG_VOLTAGE "40.0000000000"
*MEAS_COND_XG_WAVE_TYPE "Ka"
*MEAS_DATA_COUNT "3001.0000000000"
*MEAS_SCAN_AXIS_X "2θ/θ"
*MEAS_SCAN_AXIS_X_INTERNAL "TwoThetaTheta"
*MEAS_SCAN_END_TIME "09/02/20 13:25:38"
*MEAS_SCAN_MODE "CONTINUOUS"
*MEAS_SCAN_MONITOR "0"
*MEAS_SCAN_RESOLUTION_X "0.0002"
*MEAS_SCAN_SPEED "2.0"
*MEAS_SCAN_SPEED_UNIT "deg/min"
*MEAS_SCAN_START "20.0000000000"
*MEAS_SCAN_START_TIME "09/02/20 12:53:58"
*MEAS_SCAN_STEP "0.0200000000"
*MEAS_SCAN_STOP "80.0000000000"
*MEAS_SCAN_UNIT_X "deg"
*MEAS_SCAN_UNIT_Y "counts"
*RAS_HEADER_END
*RAS_INT_START
20.0000 2023.0000 1.0000
20.0600 1851.0000 1.0000
20.1200 1882.0000 1.0000
20.1800 1862.0000 1.0000
20.2400 1830.0000 1.0000
20.3000 1897.0000 1.0000
20.3600 1857.0000 1.0000
20.4200 1802.0000 1.0000
20.4800 1916.0000 1.0000
20.5400 1841.0000 1.0000
20.6000 1803.0000 1.0000
20.6600 1794.0000 1.0000
20.7200 1879.0000 1.0000
20.7800 1795.0000 1.0000
20.8400 1796.0000 1.0000
20.9000 1776.0000 1.0000
20.9600 1745.0000 1.0000
21.0200 1726.0000 1.0000
21.0800 1705.0000 1.0000
21.1400 1663.0000 1.0000
21.2000 1701.0000 1.0000
21.2600 1774.0000 1.0000
21.3200 1739.0000 1.0000
21.3800 1649.0000 1.0000
21.4400 1640.0000 1.0000
21.5000 1662.0000 1.0000
21.5600 1704.0000 1.0000
21.6200 1644.0000 1.0000
21.6800 1718.0000 1.0000
21.7400 1671.0000 1.0000
21.8000 1628.0000 1.0000
21.8600 1644.0000 1.0000
21.9200 1599.0000 1.0000
21.9800 1592.0000 1.0000
22.0400 1698.0000 1.0000
22.1000 1643.0000 1.0000
22.1600 1587.0000 1.0000
22.2200 1525.0000 1.0000
22.2800 1640.0000 1.0000
22.3400 1678.0000 1.0000
22.4000 1565.0000 1.0000
22.4600 1512.0000 1.0000
22.5200 1522.0000 1.0000
22.5800 1575.0000 1.0000
22.6400 1522.0000 1.0000
22.7000 1474.0000 1.0000
22.7600 1479.0000 1.0000
22.8200 1466.0000 1.0000
22.8800 1465.0000 1.0000
22.9400 1505.0000 1.0000
23.0000 1507.0000 1.0000
23.0600 1451.0000 1.0000
23.1200 1498.0000 1.0000
23.1800 1471.0000 1.0000
23.2400 1405.0000 1.0000
23.3000 1441.0000 1.0000
23.3600 1404.0000 1.0000
23.4200 1397.0000 1.0000
23.4800 1492.0000 1.0000
23.5400 1463.0000 1.0000
23.6000 1362.0000 1.0000
23.6600 1470.0000 1.0000
23.7200 1435.0000 1.0000
23.7800 1368.0000 1.0000
23.8400 1463.0000 1.0000
23.9000 1384.0000 1.0000
23.9600 1364.0000 1.0000
24.0200 1358.0000 1.0000
24.0800 1352.0000 1.0000
24.1400 1326.0000 1.0000
24.2000 1371.0000 1.0000
24.2600 1309.0000 1.0000
24.3200 1360.0000 1.0000
24.3800 1330.0000 1.0000
24.4400 1313.0000 1.0000
24.5000 1371.0000 1.0000
24.5600 1388.0000 1.0000
24.6200 1281.0000 1.0000
24.6800 1334.0000 1.0000
24.7400 1302.0000 1.0000
24.8000 1276.0000 1.0000
24.8600 1321.0000 1.0000
24.9200 1295.0000 1.0000
24.9800 1302.0000 1.0000
25.0400 1197.0000 1.0000
25.1000 1312.0000 1.0000
25.1600 1282.0000 1.0000
25.2200 1197.0000 1.0000
25.2800 1271.0000 1.0000
25.3400 1190.0000 1.0000
25.4000 1252.0000 1.0000
25.4600 1219.0000 1.0000
25.5200 1244.0000 1.0000
25.5800 1222.0000 1.0000
25.6400 1199.0000 1.0000
25.7000 1160.0000 1.0000
25.7600 1231.0000 1.0000
25.8200 1194.0000 1.0000
25.8800 1206.0000 1.0000
25.9400 1171.0000 1.0000
26.0000 1103.0000 1.0000
26.0600 1115.0000 1.0000
26.1200 1128.0000 1.0000
26.1800 1186.0000 1.0000
26.2400 1140.0000 1.0000
26.3000 1093.0000 1.0000
26.3600 1063.0000 1.0000
26.4200 1132.0000 1.0000
26.4800 1097.0000 1.0000
26.5400 1078.0000 1.0000
26.6000 1067.0000 1.0000
26.6600 1091.0000 1.0000
26.7200 1134.0000 1.0000
26.7800 1086.0000 1.0000
26.8400 1069.0000 1.0000
26.9000 1100.0000 1.0000
26.9600 1078.0000 1.0000
27.0200 1137.0000 1.0000
27.0800 1157.0000 1.0000
27.1400 1073.0000 1.0000
27.2000 1175.0000 1.0000
27.2600 1126.0000 1.0000
27.3200 1249.0000 1.0000
27.3800 1178.0000 1.0000
27.4400 1130.0000 1.0000
27.5000 1064.0000 1.0000
27.5600 1030.0000 1.0000
27.6200 1079.0000 1.0000
27.6800 1028.0000 1.0000
27.7400 999.0000 1.0000
27.8000 1002.0000 1.0000
27.8600 976.0000 1.0000
27.9200 1001.0000 1.0000
27.9800 928.0000 1.0000
28.0400 910.0000 1.0000
28.1000 932.0000 1.0000
28.1600 975.0000 1.0000
28.2200 996.0000 1.0000
28.2800 990.0000 1.0000
28.3400 944.0000 1.0000
28.4000 913.0000 1.0000
28.4600 947.0000 1.0000
28.5200 925.0000 1.0000
28.5800 927.0000 1.0000
28.6400 918.0000 1.0000
28.7000 959.0000 1.0000
28.7600 924.0000 1.0000
28.8200 934.0000 1.0000
28.8800 906.0000 1.0000
28.9400 880.0000 1.0000
29.0000 908.0000 1.0000
29.0600 911.0000 1.0000
29.1200 874.0000 1.0000
29.1800 883.0000 1.0000
29.2400 885.0000 1.0000
29.3000 915.0000 1.0000
29.3600 910.0000 1.0000
29.4200 862.0000 1.0000
29.4800 855.0000 1.0000
29.5400 902.0000 1.0000
29.6000 856.0000 1.0000
29.6600 839.0000 1.0000
29.7200 845.0000 1.0000
29.7800 938.0000 1.0000
29.8400 877.0000 1.0000
29.9000 801.0000 1.0000
29.9600 817.0000 1.0000
30.0200 846.0000 1.0000
30.0800 833.0000 1.0000
30.1400 810.0000 1.0000
30.2000 846.0000 1.0000
30.2600 815.0000 1.0000
30.3200 816.0000 1.0000
30.3800 795.0000 1.0000
30.4400 794.0000 1.0000
30.5000 825.0000 1.0000
30.5600 844.0000 1.0000
30.6200 837.0000 1.0000
30.6800 751.0000 1.0000
30.7400 832.0000 1.0000
30.8000 823.0000 1.0000
30.8600 791.0000 1.0000
30.9200 819.0000 1.0000
30.9800 720.0000 1.0000
31.0400 735.0000 1.0000
31.1000 782.0000 1.0000
31.1600 754.0000 1.0000
31.2200 713.0000 1.0000
31.2800 761.0000 1.0000
31.3400 734.0000 1.0000
31.4000 752.0000 1.0000
31.4600 750.0000 1.0000
31.5200 712.0000 1.0000
31.5800 724.0000 1.0000
31.6400 755.0000 1.0000
31.7000 744.0000 1.0000
31.7600 734.0000 1.0000
31.8200 728.0000 1.0000
31.8800 678.0000 1.0000
31.9400 707.0000 1.0000
32.0000 732.0000 1.0000
32.0600 727.0000 1.0000
32.1200 718.0000 1.0000
32.1800 691.0000 1.0000
32.2400 694.0000 1.0000
32.3000 706.0000 1.0000
32.3600 679.0000 1.0000
32.4200 691.0000 1.0000
32.4800 689.0000 1.0000
32.5400 711.0000 1.0000
32.6000 745.0000 1.0000
32.6600 666.0000 1.0000
32.7200 709.0000 1.0000
32.7800 674.0000 1.0000
32.8400 619.0000 1.0000
32.9000 652.0000 1.0000
32.9600 663.0000 1.0000
33.0200 652.0000 1.0000
33.0800 640.0000 1.0000
33.1400 636.0000 1.0000
33.2000 650.0000 1.0000
33.2600 638.0000 1.0000
33.3200 630.0000 1.0000
33.3800 630.0000 1.0000
33.4400 641.0000 1.0000
33.5000 644.0000 1.0000
33.5600 653.0000 1.0000
33.6200 617.0000 1.0000
33.6800 644.0000 1.0000
33.7400 602.0000 1.0000
33.8000 653.0000 1.0000
33.8600 629.0000 1.0000
33.9200 595.0000 1.0000
33.9800 602.0000 1.0000
34.0400 581.0000 1.0000
34.1000 667.0000 1.0000
34.1600 654.0000 1.0000
34.2200 634.0000 1.0000
34.2800 649.0000 1.0000
34.3400 647.0000 1.0000
34.4000 695.0000 1.0000
34.4600 734.0000 1.0000
34.5200 741.0000 1.0000
34.5800 711.0000 1.0000
34.6400 707.0000 1.0000
34.7000 602.0000 1.0000
34.7600 639.0000 1.0000
34.8200 593.0000 1.0000
34.8800 593.0000 1.0000
34.9400 559.0000 1.0000
35.0000 585.0000 1.0000
35.0600 577.0000 1.0000
35.1200 563.0000 1.0000
35.1800 557.0000 1.0000
35.2400 565.0000 1.0000
35.3000 559.0000 1.0000
35.3600 578.0000 1.0000
35.4200 565.0000 1.0000
35.4800 577.0000 1.0000
35.5400 535.0000 1.0000
35.6000 537.0000 1.0000
35.6600 536.0000 1.0000
35.7200 576.0000 1.0000
35.7800 505.0000 1.0000
35.8400 538.0000 1.0000
35.9000 539.0000 1.0000
35.9600 545.0000 1.0000
36.0200 489.0000 1.0000
36.0800 517.0000 1.0000
36.1400 467.0000 1.0000
36.2000 510.0000 1.0000
36.2600 567.0000 1.0000
36.3200 520.0000 1.0000
36.3800 592.0000 1.0000
36.4400 540.0000 1.0000
36.5000 520.0000 1.0000
36.5600 558.0000 1.0000
36.6200 532.0000 1.0000
36.6800 478.0000 1.0000
36.7400 485.0000 1.0000
36.8000 488.0000 1.0000
36.8600 450.0000 1.0000
36.9200 482.0000 1.0000
36.9800 465.0000 1.0000
37.0400 489.0000 1.0000
37.1000 530.0000 1.0000
37.1600 495.0000 1.0000
37.2200 509.0000 1.0000
37.2800 457.0000 1.0000
37.3400 465.0000 1.0000
37.4000 471.0000 1.0000
37.4600 462.0000 1.0000
37.5200 488.0000 1.0000
37.5800 520.0000 1.0000
37.6400 473.0000 1.0000
37.7000 490.0000 1.0000
37.7600 464.0000 1.0000
37.8200 465.0000 1.0000
37.8800 439.0000 1.0000
37.9400 465.0000 1.0000
38.0000 454.0000 1.0000
38.0600 449.0000 1.0000
38.1200 428.0000 1.0000
38.1800 486.0000 1.0000
38.2400 463.0000 1.0000
38.3000 462.0000 1.0000
38.3600 488.0000 1.0000
38.4200 532.0000 1.0000
38.4800 660.0000 1.0000
38.5400 727.0000 1.0000
38.6000 726.0000 1.0000
38.6600 646.0000 1.0000
38.7200 561.0000 1.0000
38.7800 476.0000 1.0000
38.8400 457.0000 1.0000
38.9000 429.0000 1.0000
38.9600 447.0000 1.0000
39.0200 437.0000 1.0000
39.0800 407.0000 1.0000
39.1400 443.0000 1.0000
39.2000 425.0000 1.0000
39.2600 429.0000 1.0000
39.3200 400.0000 1.0000
39.3800 419.0000 1.0000
39.4400 435.0000 1.0000
39.5000 433.0000 1.0000
39.5600 405.0000 1.0000
39.6200 385.0000 1.0000
39.6800 433.0000 1.0000
39.7400 422.0000 1.0000
39.8000 385.0000 1.0000
39.8600 389.0000 1.0000
39.9200 380.0000 1.0000
39.9800 388.0000 1.0000
40.0400 382.0000 1.0000
40.1000 382.0000 1.0000
40.1600 392.0000 1.0000
40.2200 374.0000 1.0000
40.2800 360.0000 1.0000
40.3400 385.0000 1.0000
40.4000 374.0000 1.0000
40.4600 384.0000 1.0000
40.5200 349.0000 1.0000
40.5800 399.0000 1.0000
40.6400 379.0000 1.0000
40.7000 374.0000 1.0000
40.7600 372.0000 1.0000
40.8200 340.0000 1.0000
40.8800 354.0000 1.0000
40.9400 375.0000 1.0000
41.0000 344.0000 1.0000
41.0600 387.0000 1.0000
41.1200 388.0000 1.0000
41.1800 388.0000 1.0000
41.2400 369.0000 1.0000
41.3000 377.0000 1.0000
41.3600 348.0000 1.0000
41.4200 371.0000 1.0000
41.4800 366.0000 1.0000
41.5400 320.0000 1.0000
41.6000 322.0000 1.0000
41.6600 369.0000 1.0000
41.7200 373.0000 1.0000
41.7800 374.0000 1.0000
41.8400 302.0000 1.0000
41.9000 358.0000 1.0000
41.9600 348.0000 1.0000
42.0200 331.0000 1.0000
42.0800 347.0000 1.0000
42.1400 340.0000 1.0000
42.2000 344.0000 1.0000
42.2600 341.0000 1.0000
42.3200 350.0000 1.0000
42.3800 338.0000 1.0000
42.4400 346.0000 1.0000
42.5000 319.0000 1.0000
42.5600 340.0000 1.0000
42.6200 357.0000 1.0000
42.6800 347.0000 1.0000
42.7400 295.0000 1.0000
42.8000 348.0000 1.0000
42.8600 342.0000 1.0000
42.9200 334.0000 1.0000
42.9800 324.0000 1.0000
43.0400 317.0000 1.0000
43.1000 347.0000 1.0000
43.1600 349.0000 1.0000
43.2200 307.0000 1.0000
43.2800 318.0000 1.0000
43.3400 367.0000 1.0000
43.4000 332.0000 1.0000
43.4600 316.0000 1.0000
43.5200 324.0000 1.0000
43.5800 293.0000 1.0000
43.6400 302.0000 1.0000
43.7000 297.0000 1.0000
43.7600 325.0000 1.0000
43.8200 317.0000 1.0000
43.8800 335.0000 1.0000
43.9400 315.0000 1.0000
44.0000 294.0000 1.0000
44.0600 308.0000 1.0000
44.1200 311.0000 1.0000
44.1800 315.0000 1.0000
44.2400 311.0000 1.0000
44.3000 325.0000 1.0000
44.3600 295.0000 1.0000
44.4200 327.0000 1.0000
44.4800 283.0000 1.0000
44.5400 339.0000 1.0000
44.6000 268.0000 1.0000
44.6600 283.0000 1.0000
44.7200 263.0000 1.0000
44.7800 318.0000 1.0000
44.8400 298.0000 1.0000
44.9000 268.0000 1.0000
44.9600 302.0000 1.0000
45.0200 304.0000 1.0000
45.0800 254.0000 1.0000
45.1400 296.0000 1.0000
45.2000 285.0000 1.0000
45.2600 289.0000 1.0000
45.3200 263.0000 1.0000
45.3800 265.0000 1.0000
45.4400 332.0000 1.0000
45.5000 297.0000 1.0000
45.5600 268.0000 1.0000
45.6200 288.0000 1.0000
45.6800 283.0000 1.0000
45.7400 276.0000 1.0000
45.8000 269.0000 1.0000
45.8600 260.0000 1.0000
45.9200 289.0000 1.0000
45.9800 284.0000 1.0000
46.0400 318.0000 1.0000
46.1000 286.0000 1.0000
46.1600 309.0000 1.0000
46.2200 289.0000 1.0000
46.2800 284.0000 1.0000
46.3400 251.0000 1.0000
46.4000 258.0000 1.0000
46.4600 255.0000 1.0000
46.5200 275.0000 1.0000
46.5800 274.0000 1.0000
46.6400 237.0000 1.0000
46.7000 262.0000 1.0000
46.7600 236.0000 1.0000
46.8200 280.0000 1.0000
46.8800 272.0000 1.0000
46.9400 276.0000 1.0000
47.0000 232.0000 1.0000
47.0600 250.0000 1.0000
47.1200 279.0000 1.0000
47.1800 259.0000 1.0000
47.2400 271.0000 1.0000
47.3000 269.0000 1.0000
47.3600 274.0000 1.0000
47.4200 273.0000 1.0000
47.4800 263.0000 1.0000
47.5400 277.0000 1.0000
47.6000 258.0000 1.0000
47.6600 264.0000 1.0000
47.7200 248.0000 1.0000
47.7800 233.0000 1.0000
47.8400 259.0000 1.0000
47.9000 227.0000 1.0000
47.9600 243.0000 1.0000
48.0200 246.0000 1.0000
48.0800 251.0000 1.0000
48.1400 259.0000 1.0000
48.2000 245.0000 1.0000
48.2600 253.0000 1.0000
48.3200 248.0000 1.0000
48.3800 240.0000 1.0000
48.4400 241.0000 1.0000
48.5000 238.0000 1.0000
48.5600 236.0000 1.0000
48.6200 248.0000 1.0000
48.6800 229.0000 1.0000
48.7400 271.0000 1.0000
48.8000 255.0000 1.0000
48.8600 242.0000 1.0000
48.9200 243.0000 1.0000
48.9800 232.0000 1.0000
49.0400 219.0000 1.0000
49.1000 235.0000 1.0000
49.1600 260.0000 1.0000
49.2200 244.0000 1.0000
49.2800 262.0000 1.0000
49.3400 258.0000 1.0000
49.4000 233.0000 1.0000
49.4600 241.0000 1.0000
49.5200 233.0000 1.0000
49.5800 237.0000 1.0000
49.6400 227.0000 1.0000
49.7000 233.0000 1.0000
49.7600 252.0000 1.0000
49.8200 227.0000 1.0000
49.8800 237.0000 1.0000
49.9400 246.0000 1.0000
50.0000 220.0000 1.0000
50.0600 231.0000 1.0000
50.1200 232.0000 1.0000
50.1800 263.0000 1.0000
50.2400 209.0000 1.0000
50.3000 245.0000 1.0000
50.3600 249.0000 1.0000
50.4200 238.0000 1.0000
50.4800 233.0000 1.0000
50.5400 227.0000 1.0000
50.6000 242.0000 1.0000
50.6600 232.0000 1.0000
50.7200 217.0000 1.0000
50.7800 240.0000 1.0000
50.8400 246.0000 1.0000
50.9000 228.0000 1.0000
50.9600 232.0000 1.0000
51.0200 229.0000 1.0000
51.0800 208.0000 1.0000
51.1400 242.0000 1.0000
51.2000 218.0000 1.0000
51.2600 217.0000 1.0000
51.3200 228.0000 1.0000
51.3800 244.0000 1.0000
51.4400 217.0000 1.0000
51.5000 204.0000 1.0000
51.5600 222.0000 1.0000
51.6200 261.0000 1.0000
51.6800 243.0000 1.0000
51.7400 236.0000 1.0000
51.8000 239.0000 1.0000
51.8600 231.0000 1.0000
51.9200 237.0000 1.0000
51.9800 211.0000 1.0000
52.0400 251.0000 1.0000
52.1000 268.0000 1.0000
52.1600 399.0000 1.0000
52.2200 584.0000 1.0000
52.2800 756.0000 1.0000
52.3400 715.0000 1.0000
52.4000 614.0000 1.0000
52.4600 549.0000 1.0000
52.5200 416.0000 1.0000
52.5800 334.0000 1.0000
52.6400 286.0000 1.0000
52.7000 247.0000 1.0000
52.7600 253.0000 1.0000
52.8200 280.0000 1.0000
52.8800 243.0000 1.0000
52.9400 226.0000 1.0000
53.0000 234.0000 1.0000
53.0600 240.0000 1.0000
53.1200 231.0000 1.0000
53.1800 210.0000 1.0000
53.2400 244.0000 1.0000
53.3000 211.0000 1.0000
53.3600 229.0000 1.0000
53.4200 223.0000 1.0000
53.4800 205.0000 1.0000
53.5400 212.0000 1.0000
53.6000 201.0000 1.0000
53.6600 214.0000 1.0000
53.7200 223.0000 1.0000
53.7800 204.0000 1.0000
53.8400 221.0000 1.0000
53.9000 221.0000 1.0000
53.9600 210.0000 1.0000
54.0200 207.0000 1.0000
54.0800 237.0000 1.0000
54.1400 207.0000 1.0000
54.2000 217.0000 1.0000
54.2600 213.0000 1.0000
54.3200 225.0000 1.0000
54.3800 229.0000 1.0000
54.4400 222.0000 1.0000
54.5000 223.0000 1.0000
54.5600 209.0000 1.0000
54.6200 210.0000 1.0000
54.6800 189.0000 1.0000
54.7400 234.0000 1.0000
54.8000 229.0000 1.0000
54.8600 243.0000 1.0000
54.9200 224.0000 1.0000
54.9800 215.0000 1.0000
55.0400 222.0000 1.0000
55.1000 209.0000 1.0000
55.1600 253.0000 1.0000
55.2200 271.0000 1.0000
55.2800 253.0000 1.0000
55.3400 262.0000 1.0000
55.4000 268.0000 1.0000
55.4600 264.0000 1.0000
55.5200 247.0000 1.0000
55.5800 231.0000 1.0000
55.6400 224.0000 1.0000
55.7000 222.0000 1.0000
55.7600 203.0000 1.0000
55.8200 220.0000 1.0000
55.8800 215.0000 1.0000
55.9400 200.0000 1.0000
56.0000 209.0000 1.0000
56.0600 205.0000 1.0000
56.1200 206.0000 1.0000
56.1800 191.0000 1.0000
56.2400 223.0000 1.0000
56.3000 218.0000 1.0000
56.3600 226.0000 1.0000
56.4200 226.0000 1.0000
56.4800 229.0000 1.0000
56.5400 198.0000 1.0000
56.6000 186.0000 1.0000
56.6600 194.0000 1.0000
56.7200 215.0000 1.0000
56.7800 226.0000 1.0000
56.8400 199.0000 1.0000
56.9000 213.0000 1.0000
56.9600 216.0000 1.0000
57.0200 208.0000 1.0000
57.0800 205.0000 1.0000
57.1400 183.0000 1.0000
57.2000 215.0000 1.0000
57.2600 213.0000 1.0000
57.3200 197.0000 1.0000
57.3800 206.0000 1.0000
57.4400 177.0000 1.0000
57.5000 211.0000 1.0000
57.5600 208.0000 1.0000
57.6200 190.0000 1.0000
57.6800 189.0000 1.0000
57.7400 193.0000 1.0000
57.8000 170.0000 1.0000
57.8600 202.0000 1.0000
57.9200 197.0000 1.0000
57.9800 201.0000 1.0000
58.0400 212.0000 1.0000
58.1000 189.0000 1.0000
58.1600 194.0000 1.0000
58.2200 211.0000 1.0000
58.2800 208.0000 1.0000
58.3400 212.0000 1.0000
58.4000 204.0000 1.0000
58.4600 205.0000 1.0000
58.5200 192.0000 1.0000
58.5800 170.0000 1.0000
58.6400 176.0000 1.0000
58.7000 193.0000 1.0000
58.7600 207.0000 1.0000
58.8200 211.0000 1.0000
58.8800 195.0000 1.0000
58.9400 196.0000 1.0000
59.0000 179.0000 1.0000
59.0600 190.0000 1.0000
59.1200 214.0000 1.0000
59.1800 212.0000 1.0000
59.2400 193.0000 1.0000
59.3000 174.0000 1.0000
59.3600 219.0000 1.0000
59.4200 177.0000 1.0000
59.4800 201.0000 1.0000
59.5400 207.0000 1.0000
59.6000 210.0000 1.0000
59.6600 201.0000 1.0000
59.7200 195.0000 1.0000
59.7800 183.0000 1.0000
59.8400 196.0000 1.0000
59.9000 204.0000 1.0000
59.9600 200.0000 1.0000
60.0200 205.0000 1.0000
60.0800 181.0000 1.0000
60.1400 178.0000 1.0000
60.2000 201.0000 1.0000
60.2600 211.0000 1.0000
60.3200 201.0000 1.0000
60.3800 186.0000 1.0000
60.4400 184.0000 1.0000
60.5000 177.0000 1.0000
60.5600 176.0000 1.0000
60.6200 202.0000 1.0000
60.6800 193.0000 1.0000
60.7400 192.0000 1.0000
60.8000 200.0000 1.0000
60.8600 189.0000 1.0000
60.9200 190.0000 1.0000
60.9800 193.0000 1.0000
61.0400 197.0000 1.0000
61.1000 174.0000 1.0000
61.1600 217.0000 1.0000
61.2200 168.0000 1.0000
61.2800 178.0000 1.0000
61.3400 193.0000 1.0000
61.4000 210.0000 1.0000
61.4600 191.0000 1.0000
61.5200 183.0000 1.0000
61.5800 182.0000 1.0000
61.6400 206.0000 1.0000
61.7000 196.0000 1.0000
61.7600 210.0000 1.0000
61.8200 214.0000 1.0000
61.8800 206.0000 1.0000
61.9400 202.0000 1.0000
62.0000 195.0000 1.0000
62.0600 257.0000 1.0000
62.1200 247.0000 1.0000
62.1800 248.0000 1.0000
62.2400 311.0000 1.0000
62.3000 326.0000 1.0000
62.3600 314.0000 1.0000
62.4200 296.0000 1.0000
62.4800 288.0000 1.0000
62.5400 283.0000 1.0000
62.6000 250.0000 1.0000
62.6600 241.0000 1.0000
62.7200 198.0000 1.0000
62.7800 219.0000 1.0000
62.8400 213.0000 1.0000
62.9000 207.0000 1.0000
62.9600 221.0000 1.0000
63.0200 186.0000 1.0000
63.0800 212.0000 1.0000
63.1400 202.0000 1.0000
63.2000 221.0000 1.0000
63.2600 209.0000 1.0000
63.3200 207.0000 1.0000
63.3800 211.0000 1.0000
63.4400 210.0000 1.0000
63.5000 166.0000 1.0000
63.5600 193.0000 1.0000
63.6200 156.0000 1.0000
63.6800 185.0000 1.0000
63.7400 197.0000 1.0000
63.8000 185.0000 1.0000
63.8600 195.0000 1.0000
63.9200 180.0000 1.0000
63.9800 205.0000 1.0000
64.0400 199.0000 1.0000
64.1000 179.0000 1.0000
64.1600 171.0000 1.0000
64.2200 189.0000 1.0000
64.2800 173.0000 1.0000
64.3400 195.0000 1.0000
64.4000 201.0000 1.0000
64.4600 206.0000 1.0000
64.5200 195.0000 1.0000
64.5800 215.0000 1.0000
64.6400 206.0000 1.0000
64.7000 247.0000 1.0000
64.7600 213.0000 1.0000
64.8200 242.0000 1.0000
64.8800 189.0000 1.0000
64.9400 208.0000 1.0000
65.0000 211.0000 1.0000
65.0600 197.0000 1.0000
65.1200 200.0000 1.0000
65.1800 222.0000 1.0000
65.2400 197.0000 1.0000
65.3000 203.0000 1.0000
65.3600 194.0000 1.0000
65.4200 181.0000 1.0000
65.4800 192.0000 1.0000
65.5400 190.0000 1.0000
65.6000 188.0000 1.0000
65.6600 197.0000 1.0000
65.7200 197.0000 1.0000
65.7800 204.0000 1.0000
65.8400 198.0000 1.0000
65.9000 203.0000 1.0000
65.9600 217.0000 1.0000
66.0200 232.0000 1.0000
66.0800 267.0000 1.0000
66.1400 311.0000 1.0000
66.2000 382.0000 1.0000
66.2600 463.0000 1.0000
66.3200 452.0000 1.0000
66.3800 398.0000 1.0000
66.4400 410.0000 1.0000
66.5000 396.0000 1.0000
66.5600 310.0000 1.0000
66.6200 280.0000 1.0000
66.6800 238.0000 1.0000
66.7400 226.0000 1.0000
66.8000 193.0000 1.0000
66.8600 203.0000 1.0000
66.9200 212.0000 1.0000
66.9800 201.0000 1.0000
67.0400 203.0000 1.0000
67.1000 187.0000 1.0000
67.1600 176.0000 1.0000
67.2200 175.0000 1.0000
67.2800 186.0000 1.0000
67.3400 192.0000 1.0000
67.4000 189.0000 1.0000
67.4600 182.0000 1.0000
67.5200 168.0000 1.0000
67.5800 163.0000 1.0000
67.6400 174.0000 1.0000
67.7000 178.0000 1.0000
67.7600 174.0000 1.0000
67.8200 200.0000 1.0000
67.8800 162.0000 1.0000
67.9400 190.0000 1.0000
68.0000 195.0000 1.0000
68.0600 181.0000 1.0000
68.1200 187.0000 1.0000
68.1800 193.0000 1.0000
68.2400 194.0000 1.0000
68.3000 186.0000 1.0000
68.3600 163.0000 1.0000
68.4200 164.0000 1.0000
68.4800 181.0000 1.0000
68.5400 191.0000 1.0000
68.6000 201.0000 1.0000
68.6600 184.0000 1.0000
68.7200 187.0000 1.0000
68.7800 147.0000 1.0000
68.8400 180.0000 1.0000
68.9000 157.0000 1.0000
68.9600 183.0000 1.0000
69.0200 156.0000 1.0000
69.0800 187.0000 1.0000
69.1400 173.0000 1.0000
69.2000 166.0000 1.0000
69.2600 187.0000 1.0000
69.3200 161.0000 1.0000
69.3800 189.0000 1.0000
69.4400 170.0000 1.0000
69.5000 188.0000 1.0000
69.5600 174.0000 1.0000
69.6200 180.0000 1.0000
69.6800 174.0000 1.0000
69.7400 180.0000 1.0000
69.8000 155.0000 1.0000
69.8600 191.0000 1.0000
69.9200 161.0000 1.0000
69.9800 161.0000 1.0000
70.0400 185.0000 1.0000
70.1000 170.0000 1.0000
70.1600 171.0000 1.0000
70.2200 176.0000 1.0000
70.2800 167.0000 1.0000
70.3400 153.0000 1.0000
70.4000 169.0000 1.0000
70.4600 182.0000 1.0000
70.5200 169.0000 1.0000
70.5800 164.0000 1.0000
70.6400 186.0000 1.0000
70.7000 190.0000 1.0000
70.7600 167.0000 1.0000
70.8200 164.0000 1.0000
70.8800 153.0000 1.0000
70.9400 162.0000 1.0000
71.0000 172.0000 1.0000
71.0600 184.0000 1.0000
71.1200 180.0000 1.0000
71.1800 177.0000 1.0000
71.2400 169.0000 1.0000
71.3000 179.0000 1.0000
71.3600 163.0000 1.0000
71.4200 179.0000 1.0000
71.4800 177.0000 1.0000
71.5400 204.0000 1.0000
71.6000 203.0000 1.0000
71.6600 174.0000 1.0000
71.7200 187.0000 1.0000
71.7800 195.0000 1.0000
71.8400 186.0000 1.0000
71.9000 179.0000 1.0000
71.9600 182.0000 1.0000
72.0200 175.0000 1.0000
72.0800 178.0000 1.0000
72.1400 156.0000 1.0000
72.2000 169.0000 1.0000
72.2600 177.0000 1.0000
72.3200 175.0000 1.0000
72.3800 173.0000 1.0000
72.4400 192.0000 1.0000
72.5000 171.0000 1.0000
72.5600 175.0000 1.0000
72.6200 166.0000 1.0000
72.6800 170.0000 1.0000
72.7400 179.0000 1.0000
72.8000 165.0000 1.0000
72.8600 169.0000 1.0000
72.9200 162.0000 1.0000
72.9800 180.0000 1.0000
73.0400 169.0000 1.0000
73.1000 190.0000 1.0000
73.1600 168.0000 1.0000
73.2200 160.0000 1.0000
73.2800 149.0000 1.0000
73.3400 156.0000 1.0000
73.4000 150.0000 1.0000
73.4600 171.0000 1.0000
73.5200 182.0000 1.0000
73.5800 159.0000 1.0000
73.6400 160.0000 1.0000
73.7000 179.0000 1.0000
73.7600 160.0000 1.0000
73.8200 174.0000 1.0000
73.8800 180.0000 1.0000
73.9400 179.0000 1.0000
74.0000 160.0000 1.0000
74.0600 180.0000 1.0000
74.1200 181.0000 1.0000
74.1800 175.0000 1.0000
74.2400 168.0000 1.0000
74.3000 162.0000 1.0000
74.3600 156.0000 1.0000
74.4200 180.0000 1.0000
74.4800 164.0000 1.0000
74.5400 169.0000 1.0000
74.6000 156.0000 1.0000
74.6600 184.0000 1.0000
74.7200 182.0000 1.0000
74.7800 154.0000 1.0000
74.8400 174.0000 1.0000
74.9000 150.0000 1.0000
74.9600 173.0000 1.0000
75.0200 168.0000 1.0000
75.0800 170.0000 1.0000
75.1400 170.0000 1.0000
75.2000 166.0000 1.0000
75.2600 170.0000 1.0000
75.3200 153.0000 1.0000
75.3800 140.0000 1.0000
75.4400 180.0000 1.0000
75.5000 148.0000 1.0000
75.5600 155.0000 1.0000
75.6200 167.0000 1.0000
75.6800 170.0000 1.0000
75.7400 171.0000 1.0000
75.8000 160.0000 1.0000
75.8600 166.0000 1.0000
75.9200 188.0000 1.0000
75.9800 154.0000 1.0000
76.0400 186.0000 1.0000
76.1000 174.0000 1.0000
76.1600 158.0000 1.0000
76.2200 160.0000 1.0000
76.2800 188.0000 1.0000
76.3400 168.0000 1.0000
76.4000 157.0000 1.0000
76.4600 157.0000 1.0000
76.5200 159.0000 1.0000
76.5800 152.0000 1.0000
76.6400 159.0000 1.0000
76.7000 175.0000 1.0000
76.7600 180.0000 1.0000
76.8200 142.0000 1.0000
76.8800 172.0000 1.0000
76.9400 153.0000 1.0000
77.0000 157.0000 1.0000
77.0600 174.0000 1.0000
77.1200 171.0000 1.0000
77.1800 167.0000 1.0000
77.2400 165.0000 1.0000
77.3000 182.0000 1.0000
77.3600 167.0000 1.0000
77.4200 180.0000 1.0000
77.4800 171.0000 1.0000
77.5400 153.0000 1.0000
77.6000 169.0000 1.0000
77.6600 157.0000 1.0000
77.7200 154.0000 1.0000
77.7800 172.0000 1.0000
77.8400 171.0000 1.0000
77.9000 149.0000 1.0000
77.9600 161.0000 1.0000
78.0200 165.0000 1.0000
78.0800 168.0000 1.0000
78.1400 185.0000 1.0000
78.2000 182.0000 1.0000
78.2600 165.0000 1.0000
78.3200 170.0000 1.0000
78.3800 172.0000 1.0000
78.4400 159.0000 1.0000
78.5000 171.0000 1.0000
78.5600 165.0000 1.0000
78.6200 171.0000 1.0000
78.6800 159.0000 1.0000
78.7400 183.0000 1.0000
78.8000 207.0000 1.0000
78.8600 195.0000 1.0000
78.9200 216.0000 1.0000
78.9800 231.0000 1.0000
79.0400 245.0000 1.0000
79.1000 256.0000 1.0000
79.1600 225.0000 1.0000
79.2200 243.0000 1.0000
79.2800 252.0000 1.0000
79.3400 234.0000 1.0000
79.4000 198.0000 1.0000
79.4600 184.0000 1.0000
79.5200 154.0000 1.0000
79.5800 174.0000 1.0000
79.6400 182.0000 1.0000
79.7000 159.0000 1.0000
79.7600 162.0000 1.0000
79.8200 157.0000 1.0000
79.8800 154.0000 1.0000
79.9400 167.0000 1.0000
80.0000 178.0000 1.0000
*RAS_INT_END
*RAS_TEMPERATURE_START
*RAS_TEMPERATURE_END
*RAS_DATA_END