File: Section2_75_samples/XRD/No_021_700_18.ras
*RAS_DATA_START
*RAS_HEADER_START
*DISP_FMT_X "%.2f"
*DISP_FMT_Y "%.0f"
*DISP_FULLSCALE "3638.0000000000"
*DISP_LINE_COLOR "255.0000000000"
*DISP_LINE_STYLE "0.0000000000"
*DISP_LINE_WIDTH "0.2500000000"
*DISP_NOTE "測定データ-3"
*DISP_OFFSET_Y "0.0000000000"
*DISP_PEAKSEARCH_UNIT_Y "cps"
*DISP_RANGE_BOTTOM "0.0000000000"
*DISP_RANGE_LEFT "20.0000000000"
*DISP_RANGE_LOGCUTOFF "0.0100000000"
*DISP_RANGE_RIGHT "80.0000000000"
*DISP_RANGE_TOP "3638.0000000000"
*DISP_SCALE_MODE_Y "0.0000000000"
*DISP_TAB_NAME "2θ/θ"
*DISP_TITLE_Y "強度"
*DISP_UNIT_Y "cps"
*DISP_WINDOW_NAME "MSG_MACROENGINE"
*FILE_COMMENT " "
*FILE_MD5 ""
*FILE_MEMO " "
*FILE_OPERATOR "Administrator"
*FILE_SAMPLE " "
*FILE_TYPE "RAS_RAW"
*FILE_USERGROUP "システムマネージャ"
*FILE_VERSION "1.0000000000"
*HW_ATTACHMENT_ID "ATT0025"
*HW_ATTACHMENT_NAME "標準|Standard"
*HW_COUNTER_ID-0 "CUT0025"
*HW_COUNTER_ID-1 "CUT0020"
*HW_COUNTER_ID-2 "CUT0020"
*HW_COUNTER_ID-3 "CSL0021"
*HW_COUNTER_ID-4 "CMC0021"
*HW_COUNTER_NAME-0 "D/teX Ultra|D/teX Ultra"
*HW_COUNTER_NAME-1 "None|None"
*HW_COUNTER_NAME-2 "None|None"
*HW_COUNTER_NAME-3 "BBM|BBM"
*HW_COUNTER_NAME-4 "検出器モノクロメータ|Detector monochromator"
*HW_COUNTER_SELECT_NAME "D/teX Ultra|D/teX Ultra"
*HW_GONIOMETER_ID "GON0023"
*HW_GONIOMETER_NAME "SmartLab|SmartLab"
*HW_GONIOMETER_RADIUS-0 "90.0"
*HW_GONIOMETER_RADIUS-1 "114.0"
*HW_GONIOMETER_RADIUS-2 "190.0"
*HW_GONIOMETER_RADIUS-3 "300.0"
*HW_GONIOMETER_RADIUS-4 "187.0"
*HW_GONIOMETER_RADIUS-5 "300.0"
*HW_GONIOMETER_RADIUS-6 "113.0"
*HW_GONIOMETER_RADIUS-7 "331.0"
*HW_I_OPT_ID-0 "CBO0021"
*HW_I_OPT_ID-1 "ICR0023"
*HW_I_OPT_ID-2 "ISL0021"
*HW_I_OPT_ID-3 "ISO0021"
*HW_I_OPT_ID-4 "IAD0021"
*HW_I_OPT_ID-5 "IPR0001"
*HW_I_OPT_NAME-0 "CBOユニット|CBO unit"
*HW_I_OPT_NAME-1 "標準入射光学ユニット|Standard incident optical unit"
*HW_I_OPT_NAME-2 "標準入射スリットボックス|Standard incident slit box"
*HW_I_OPT_NAME-3 "入射平行スリット|Incident parallel slit"
*HW_I_OPT_NAME-4 "長手制限スリット|Length limiting slit"
*HW_I_OPT_NAME-5 "None|None"
*HW_R_ATTENUATER_AUTOMODE "0"
*HW_R_OPT_ID-0 "RSS0021"
*HW_R_OPT_ID-1 "RCR0023"
*HW_R_OPT_ID-2 "RSO0021"
*HW_R_OPT_ID-3 "RRS0021"
*HW_R_OPT_ID-4 "ATN0021"
*HW_R_OPT_ID-5 "RFL0021"
*HW_R_OPT_ID-6 "RAD0021"
*HW_R_OPT_NAME-0 "標準受光スリットボックス1|Standard receiving slit box # 1"
*HW_R_OPT_NAME-1 "標準受光光学ユニット1|Standard receiving unit # 1"
*HW_R_OPT_NAME-2 "標準受光光学ユニット2|Standard receiving optical unit # 2"
*HW_R_OPT_NAME-3 "標準受光スリットボックス2|Standard receiving slit box # 2"
*HW_R_OPT_NAME-4 "標準アッテネータ|Standard Attenuator"
*HW_R_OPT_NAME-5 "Cu Kβ|Cu K-beta"
*HW_R_OPT_NAME-6 "調整用受光スリット|Alignment receiving slit"
*HW_SAMPLE_HOLDER_ID "SMP0023"
*HW_SAMPLE_HOLDER_NAME "標準Zステージ|Standard Z stage"
*HW_XG_CURRENT_MAX "50"
*HW_XG_CURRENT_MIN "2"
*HW_XG_CURRENT_RESOLUTION "2"
*HW_XG_CURRENT_UNIT "mA"
*HW_XG_FOCUS "1mm x 10mm"
*HW_XG_FOCUS_TYPE "Normal"
*HW_XG_ID ""
*HW_XG_NAME "3kW 封入管(ID:1200)|3kW Sealed tube(ID:1200)"
*HW_XG_TARGET_ATOMIC_NUMBER "29.0000000000"
*HW_XG_TARGET_NAME "Cu"
*HW_XG_TYPE "Hermetic"
*HW_XG_VOLTAGE_MAX "60"
*HW_XG_VOLTAGE_MIN "20"
*HW_XG_VOLTAGE_RESOLUTION "2"
*HW_XG_VOLTAGE_UNIT "kV"
*HW_XG_WATT_MAX "2"
*HW_XG_WATT_UNIT "kW"
*HW_XG_WAVE_LENGTH_ALPHA1 "1.540593"
*HW_XG_WAVE_LENGTH_ALPHA2 "1.544414"
*HW_XG_WAVE_LENGTH_BETA "1.392250"
*MEAS_COND_AXIS_NAME-0 "2θ/θ"
*MEAS_COND_AXIS_NAME-1 "2θ"
*MEAS_COND_AXIS_NAME-2 "ω"
*MEAS_COND_AXIS_NAME-3 "Z"
*MEAS_COND_AXIS_NAME-4 "2θ/ω"
*MEAS_COND_AXIS_NAME-5 "θs"
*MEAS_COND_AXIS_NAME-6 "θd"
*MEAS_COND_AXIS_NAME-7 "Ts"
*MEAS_COND_AXIS_NAME-8 "CBO選択スリット"
*MEAS_COND_AXIS_NAME-9 "M"
*MEAS_COND_AXIS_NAME-10 "入射平行スリット"
*MEAS_COND_AXIS_NAME-11 "入射スリット"
*MEAS_COND_AXIS_NAME-12 ""
*MEAS_COND_AXIS_NAME-13 "Zs"
*MEAS_COND_AXIS_NAME-14 "入射光学素子"
*MEAS_COND_AXIS_NAME-15 "長手制限スリット"
*MEAS_COND_AXIS_NAME-16 "センタースリット"
*MEAS_COND_AXIS_NAME-17 "フィルター"
*MEAS_COND_AXIS_NAME-18 "受光スリット1"
*MEAS_COND_AXIS_NAME-19 "受光スリット2"
*MEAS_COND_AXIS_NAME-20 "受光光学素子"
*MEAS_COND_AXIS_NAME-21 "受光平行スリット"
*MEAS_COND_AXIS_NAME-22 "調整用受光スリット"
*MEAS_COND_AXIS_NAME-23 ""
*MEAS_COND_AXIS_NAME-24 ""
*MEAS_COND_AXIS_NAME-25 "Zd"
*MEAS_COND_AXIS_NAME-26 "アッテネータ"
*MEAS_COND_AXIS_NAME-27 "検出器モノクロメータ"
*MEAS_COND_AXIS_NAME-28 "モノクロメータスリット"
*MEAS_COND_AXIS_NAME-29 "プライマリビーム"
*MEAS_COND_AXIS_NAME-30 "PHA"
*MEAS_COND_AXIS_NAME_INTERNAL-0 "TwoThetaTheta"
*MEAS_COND_AXIS_NAME_INTERNAL-1 "TwoTheta"
*MEAS_COND_AXIS_NAME_INTERNAL-2 "Omega"
*MEAS_COND_AXIS_NAME_INTERNAL-3 "Z"
*MEAS_COND_AXIS_NAME_INTERNAL-4 "TwoThetaOmega"
*MEAS_COND_AXIS_NAME_INTERNAL-5 "ThetaS"
*MEAS_COND_AXIS_NAME_INTERNAL-6 "ThetaD"
*MEAS_COND_AXIS_NAME_INTERNAL-7 "Ts"
*MEAS_COND_AXIS_NAME_INTERNAL-8 "CBO"
*MEAS_COND_AXIS_NAME_INTERNAL-9 "CBO-M"
*MEAS_COND_AXIS_NAME_INTERNAL-10 "IncidentSollerSlit"
*MEAS_COND_AXIS_NAME_INTERNAL-11 "IncidentSlitBox"
*MEAS_COND_AXIS_NAME_INTERNAL-12 "IncidentSlitBox-_Axis"
*MEAS_COND_AXIS_NAME_INTERNAL-13 "Zs"
*MEAS_COND_AXIS_NAME_INTERNAL-14 "IncidentMonochromator"
*MEAS_COND_AXIS_NAME_INTERNAL-15 "IncidentAxdSlit"
*MEAS_COND_AXIS_NAME_INTERNAL-16 "CenterSlit"
*MEAS_COND_AXIS_NAME_INTERNAL-17 "Filter"
*MEAS_COND_AXIS_NAME_INTERNAL-18 "ReceivingSlitBox1"
*MEAS_COND_AXIS_NAME_INTERNAL-19 "ReceivingSlitBox2"
*MEAS_COND_AXIS_NAME_INTERNAL-20 "ReceivingOptics"
*MEAS_COND_AXIS_NAME_INTERNAL-21 "ReceivingSollerSlit"
*MEAS_COND_AXIS_NAME_INTERNAL-22 "ReceivingAxdSlit"
*MEAS_COND_AXIS_NAME_INTERNAL-23 "ReceivingSlitBox1-_Axis"
*MEAS_COND_AXIS_NAME_INTERNAL-24 "ReceivingSlitBox2-_Axis"
*MEAS_COND_AXIS_NAME_INTERNAL-25 "ReceivingSlitBox2-Zd"
*MEAS_COND_AXIS_NAME_INTERNAL-26 "Attenuator"
*MEAS_COND_AXIS_NAME_INTERNAL-27 "CounterMonochromator"
*MEAS_COND_AXIS_NAME_INTERNAL-28 "CounterSlit"
*MEAS_COND_AXIS_NAME_INTERNAL-29 "IncidentPrimary"
*MEAS_COND_AXIS_NAME_INTERNAL-30 "PHA"
*MEAS_COND_AXIS_NAME_MAGICNO-0 "83951616.0000000000"
*MEAS_COND_AXIS_NAME_MAGICNO-1 "268632064.0000000000"
*MEAS_COND_AXIS_NAME_MAGICNO-2 "268500992.0000000000"
*MEAS_COND_AXIS_NAME_MAGICNO-3 "285278208.0000000000"
*MEAS_COND_AXIS_NAME_MAGICNO-4 "83951616.0000000000"
*MEAS_COND_AXIS_NAME_MAGICNO-5 "131072.0000000000"
*MEAS_COND_AXIS_NAME_MAGICNO-6 "131072.0000000000"
*MEAS_COND_AXIS_NAME_MAGICNO-7 "318898176.0000000000"
*MEAS_COND_AXIS_NAME_MAGICNO-8 "20971521.0000000000"
*MEAS_COND_AXIS_NAME_MAGICNO-9 "285343744.0000000000"
*MEAS_COND_AXIS_NAME_MAGICNO-10 "20971521.0000000000"
*MEAS_COND_AXIS_NAME_MAGICNO-11 "22020097.0000000000"
*MEAS_COND_AXIS_NAME_MAGICNO-12 "25165824.0000000000"
*MEAS_COND_AXIS_NAME_MAGICNO-13 "318898176.0000000000"
*MEAS_COND_AXIS_NAME_MAGICNO-14 "1.0000000000"
*MEAS_COND_AXIS_NAME_MAGICNO-15 "20971521.0000000000"
*MEAS_COND_AXIS_NAME_MAGICNO-16 "20971521.0000000000"
*MEAS_COND_AXIS_NAME_MAGICNO-17 "20971521.0000000000"
*MEAS_COND_AXIS_NAME_MAGICNO-18 "23068673.0000000000"
*MEAS_COND_AXIS_NAME_MAGICNO-19 "23068673.0000000000"
*MEAS_COND_AXIS_NAME_MAGICNO-20 "20971521.0000000000"
*MEAS_COND_AXIS_NAME_MAGICNO-21 "20971521.0000000000"
*MEAS_COND_AXIS_NAME_MAGICNO-22 "20971521.0000000000"
*MEAS_COND_AXIS_NAME_MAGICNO-23 "25165824.0000000000"
*MEAS_COND_AXIS_NAME_MAGICNO-24 "25165824.0000000000"
*MEAS_COND_AXIS_NAME_MAGICNO-25 "285343744.0000000000"
*MEAS_COND_AXIS_NAME_MAGICNO-26 "17301505.0000000000"
*MEAS_COND_AXIS_NAME_MAGICNO-27 "20971521.0000000000"
*MEAS_COND_AXIS_NAME_MAGICNO-28 "20971521.0000000000"
*MEAS_COND_AXIS_NAME_MAGICNO-29 "20971521.0000000000"
*MEAS_COND_AXIS_NAME_MAGICNO-30 "0.0000000000"
*MEAS_COND_AXIS_OFFSET-0 "-"
*MEAS_COND_AXIS_OFFSET-1 "-0.1081000000"
*MEAS_COND_AXIS_OFFSET-2 "0.3758000000"
*MEAS_COND_AXIS_OFFSET-3 "-"
*MEAS_COND_AXIS_OFFSET-4 "-"
*MEAS_COND_AXIS_OFFSET-5 "0.3758000000"
*MEAS_COND_AXIS_OFFSET-6 "-0.4839000000"
*MEAS_COND_AXIS_OFFSET-7 "-"
*MEAS_COND_AXIS_OFFSET-8 "-"
*MEAS_COND_AXIS_OFFSET-9 "-"
*MEAS_COND_AXIS_OFFSET-10 "-"
*MEAS_COND_AXIS_OFFSET-11 "-"
*MEAS_COND_AXIS_OFFSET-12 "-"
*MEAS_COND_AXIS_OFFSET-13 "-"
*MEAS_COND_AXIS_OFFSET-14 "-"
*MEAS_COND_AXIS_OFFSET-15 "-"
*MEAS_COND_AXIS_OFFSET-16 "-"
*MEAS_COND_AXIS_OFFSET-17 "-"
*MEAS_COND_AXIS_OFFSET-18 "-"
*MEAS_COND_AXIS_OFFSET-19 "-"
*MEAS_COND_AXIS_OFFSET-20 "-"
*MEAS_COND_AXIS_OFFSET-21 "-"
*MEAS_COND_AXIS_OFFSET-22 "-"
*MEAS_COND_AXIS_OFFSET-23 "-"
*MEAS_COND_AXIS_OFFSET-24 "-"
*MEAS_COND_AXIS_OFFSET-25 "-"
*MEAS_COND_AXIS_OFFSET-26 "-"
*MEAS_COND_AXIS_OFFSET-27 "-"
*MEAS_COND_AXIS_OFFSET-28 "-"
*MEAS_COND_AXIS_OFFSET-29 "-"
*MEAS_COND_AXIS_OFFSET-30 "-"
*MEAS_COND_AXIS_POSITION-0 "0.0000000000"
*MEAS_COND_AXIS_POSITION-1 "0.0000000000"
*MEAS_COND_AXIS_POSITION-2 "0.0000000000"
*MEAS_COND_AXIS_POSITION-3 "-0.5500000000"
*MEAS_COND_AXIS_POSITION-4 "0.0000000000"
*MEAS_COND_AXIS_POSITION-5 "0.0000000000"
*MEAS_COND_AXIS_POSITION-6 "0.0000000000"
*MEAS_COND_AXIS_POSITION-7 "-0.4278800000"
*MEAS_COND_AXIS_POSITION-8 "BB"
*MEAS_COND_AXIS_POSITION-9 "0.0000000000"
*MEAS_COND_AXIS_POSITION-10 "Soller_slit_5.0deg"
*MEAS_COND_AXIS_POSITION-11 "2/3deg"
*MEAS_COND_AXIS_POSITION-12 "2.2088000000"
*MEAS_COND_AXIS_POSITION-13 "-0.4140600000"
*MEAS_COND_AXIS_POSITION-14 "0.0000000000"
*MEAS_COND_AXIS_POSITION-15 "10.0mm"
*MEAS_COND_AXIS_POSITION-16 "None"
*MEAS_COND_AXIS_POSITION-17 "Cu_K-beta"
*MEAS_COND_AXIS_POSITION-18 "13.000mm"
*MEAS_COND_AXIS_POSITION-19 "13.000mm"
*MEAS_COND_AXIS_POSITION-20 "No_unit"
*MEAS_COND_AXIS_POSITION-21 "Soller_slit_5.0deg"
*MEAS_COND_AXIS_POSITION-22 "None"
*MEAS_COND_AXIS_POSITION-23 "13.0000000000"
*MEAS_COND_AXIS_POSITION-24 "13.0000000000"
*MEAS_COND_AXIS_POSITION-25 "0.0109400000"
*MEAS_COND_AXIS_POSITION-26 "Open"
*MEAS_COND_AXIS_POSITION-27 "None"
*MEAS_COND_AXIS_POSITION-28 "None"
*MEAS_COND_AXIS_POSITION-29 "None"
*MEAS_COND_AXIS_POSITION-30 "38.0000000000"
*MEAS_COND_AXIS_UNIT-0 "deg"
*MEAS_COND_AXIS_UNIT-1 "deg"
*MEAS_COND_AXIS_UNIT-2 "deg"
*MEAS_COND_AXIS_UNIT-3 "mm"
*MEAS_COND_AXIS_UNIT-4 "deg"
*MEAS_COND_AXIS_UNIT-5 "deg"
*MEAS_COND_AXIS_UNIT-6 "deg"
*MEAS_COND_AXIS_UNIT-7 "mm"
*MEAS_COND_AXIS_UNIT-8 ""
*MEAS_COND_AXIS_UNIT-9 "pulse"
*MEAS_COND_AXIS_UNIT-10 ""
*MEAS_COND_AXIS_UNIT-11 ""
*MEAS_COND_AXIS_UNIT-12 "mm"
*MEAS_COND_AXIS_UNIT-13 "mm"
*MEAS_COND_AXIS_UNIT-14 ""
*MEAS_COND_AXIS_UNIT-15 ""
*MEAS_COND_AXIS_UNIT-16 ""
*MEAS_COND_AXIS_UNIT-17 ""
*MEAS_COND_AXIS_UNIT-18 ""
*MEAS_COND_AXIS_UNIT-19 ""
*MEAS_COND_AXIS_UNIT-20 ""
*MEAS_COND_AXIS_UNIT-21 ""
*MEAS_COND_AXIS_UNIT-22 ""
*MEAS_COND_AXIS_UNIT-23 "mm"
*MEAS_COND_AXIS_UNIT-24 "mm"
*MEAS_COND_AXIS_UNIT-25 "mm"
*MEAS_COND_AXIS_UNIT-26 ""
*MEAS_COND_AXIS_UNIT-27 ""
*MEAS_COND_AXIS_UNIT-28 ""
*MEAS_COND_AXIS_UNIT-29 ""
*MEAS_COND_AXIS_UNIT-30 "div"
*MEAS_COND_COUNTER_CNTLOSS_CORR "0.0000000000"
*MEAS_COND_COUNTER_PHABASE "38.0000000000"
*MEAS_COND_COUNTER_PHAWINDOW "16.0000000000"
*MEAS_COND_COUNTER_PHA_UNIT "div"
*MEAS_COND_COUNTER_TAUDIFF "30.0000000000"
*MEAS_COND_COUNTER_TAUINT "0.0000000000"
*MEAS_COND_IRRADIATION_MODE "OFF"
*MEAS_COND_IRRADIATION_WIDTH ""
*MEAS_COND_OPT_ATTR "集中法"
*MEAS_COND_OPT_NAME "@集中法"
*MEAS_COND_UNSYMMETRIC_MODE "OFF"
*MEAS_COND_XG_CURRENT "30.0000000000"
*MEAS_COND_XG_VOLTAGE "40.0000000000"
*MEAS_COND_XG_WAVE_TYPE "Ka"
*MEAS_DATA_COUNT "3001.0000000000"
*MEAS_SCAN_AXIS_X "2θ/θ"
*MEAS_SCAN_AXIS_X_INTERNAL "TwoThetaTheta"
*MEAS_SCAN_END_TIME "09/04/20 11:33:41"
*MEAS_SCAN_MODE "CONTINUOUS"
*MEAS_SCAN_MONITOR "0"
*MEAS_SCAN_RESOLUTION_X "0.0002"
*MEAS_SCAN_SPEED "2.0"
*MEAS_SCAN_SPEED_UNIT "deg/min"
*MEAS_SCAN_START "20.0000000000"
*MEAS_SCAN_START_TIME "09/04/20 11:02:01"
*MEAS_SCAN_STEP "0.0200000000"
*MEAS_SCAN_STOP "80.0000000000"
*MEAS_SCAN_UNIT_X "deg"
*MEAS_SCAN_UNIT_Y "counts"
*RAS_HEADER_END
*RAS_INT_START
20.0000 1819.0000 1.0000
20.0600 1797.0000 1.0000
20.1200 1728.0000 1.0000
20.1800 1767.0000 1.0000
20.2400 1712.0000 1.0000
20.3000 1787.0000 1.0000
20.3600 1751.0000 1.0000
20.4200 1701.0000 1.0000
20.4800 1686.0000 1.0000
20.5400 1721.0000 1.0000
20.6000 1660.0000 1.0000
20.6600 1726.0000 1.0000
20.7200 1711.0000 1.0000
20.7800 1646.0000 1.0000
20.8400 1662.0000 1.0000
20.9000 1715.0000 1.0000
20.9600 1590.0000 1.0000
21.0200 1640.0000 1.0000
21.0800 1634.0000 1.0000
21.1400 1581.0000 1.0000
21.2000 1648.0000 1.0000
21.2600 1579.0000 1.0000
21.3200 1660.0000 1.0000
21.3800 1592.0000 1.0000
21.4400 1535.0000 1.0000
21.5000 1605.0000 1.0000
21.5600 1564.0000 1.0000
21.6200 1514.0000 1.0000
21.6800 1534.0000 1.0000
21.7400 1517.0000 1.0000
21.8000 1515.0000 1.0000
21.8600 1515.0000 1.0000
21.9200 1513.0000 1.0000
21.9800 1531.0000 1.0000
22.0400 1475.0000 1.0000
22.1000 1477.0000 1.0000
22.1600 1489.0000 1.0000
22.2200 1503.0000 1.0000
22.2800 1431.0000 1.0000
22.3400 1544.0000 1.0000
22.4000 1467.0000 1.0000
22.4600 1495.0000 1.0000
22.5200 1399.0000 1.0000
22.5800 1461.0000 1.0000
22.6400 1422.0000 1.0000
22.7000 1391.0000 1.0000
22.7600 1426.0000 1.0000
22.8200 1398.0000 1.0000
22.8800 1420.0000 1.0000
22.9400 1469.0000 1.0000
23.0000 1392.0000 1.0000
23.0600 1366.0000 1.0000
23.1200 1378.0000 1.0000
23.1800 1365.0000 1.0000
23.2400 1328.0000 1.0000
23.3000 1304.0000 1.0000
23.3600 1306.0000 1.0000
23.4200 1255.0000 1.0000
23.4800 1342.0000 1.0000
23.5400 1360.0000 1.0000
23.6000 1315.0000 1.0000
23.6600 1342.0000 1.0000
23.7200 1323.0000 1.0000
23.7800 1319.0000 1.0000
23.8400 1295.0000 1.0000
23.9000 1287.0000 1.0000
23.9600 1303.0000 1.0000
24.0200 1286.0000 1.0000
24.0800 1260.0000 1.0000
24.1400 1336.0000 1.0000
24.2000 1274.0000 1.0000
24.2600 1313.0000 1.0000
24.3200 1261.0000 1.0000
24.3800 1302.0000 1.0000
24.4400 1212.0000 1.0000
24.5000 1250.0000 1.0000
24.5600 1195.0000 1.0000
24.6200 1189.0000 1.0000
24.6800 1199.0000 1.0000
24.7400 1219.0000 1.0000
24.8000 1186.0000 1.0000
24.8600 1191.0000 1.0000
24.9200 1180.0000 1.0000
24.9800 1205.0000 1.0000
25.0400 1138.0000 1.0000
25.1000 1161.0000 1.0000
25.1600 1222.0000 1.0000
25.2200 1154.0000 1.0000
25.2800 1164.0000 1.0000
25.3400 1153.0000 1.0000
25.4000 1156.0000 1.0000
25.4600 1152.0000 1.0000
25.5200 1101.0000 1.0000
25.5800 1141.0000 1.0000
25.6400 1147.0000 1.0000
25.7000 1125.0000 1.0000
25.7600 1062.0000 1.0000
25.8200 1114.0000 1.0000
25.8800 1138.0000 1.0000
25.9400 1065.0000 1.0000
26.0000 1093.0000 1.0000
26.0600 1075.0000 1.0000
26.1200 1107.0000 1.0000
26.1800 1075.0000 1.0000
26.2400 1076.0000 1.0000
26.3000 1121.0000 1.0000
26.3600 1108.0000 1.0000
26.4200 1052.0000 1.0000
26.4800 1063.0000 1.0000
26.5400 1054.0000 1.0000
26.6000 1039.0000 1.0000
26.6600 1058.0000 1.0000
26.7200 1096.0000 1.0000
26.7800 1082.0000 1.0000
26.8400 997.0000 1.0000
26.9000 1050.0000 1.0000
26.9600 1004.0000 1.0000
27.0200 1020.0000 1.0000
27.0800 1064.0000 1.0000
27.1400 1109.0000 1.0000
27.2000 1203.0000 1.0000
27.2600 1304.0000 1.0000
27.3200 1388.0000 1.0000
27.3800 1220.0000 1.0000
27.4400 1179.0000 1.0000
27.5000 1054.0000 1.0000
27.5600 1013.0000 1.0000
27.6200 999.0000 1.0000
27.6800 1009.0000 1.0000
27.7400 1008.0000 1.0000
27.8000 975.0000 1.0000
27.8600 939.0000 1.0000
27.9200 916.0000 1.0000
27.9800 939.0000 1.0000
28.0400 974.0000 1.0000
28.1000 975.0000 1.0000
28.1600 885.0000 1.0000
28.2200 931.0000 1.0000
28.2800 904.0000 1.0000
28.3400 924.0000 1.0000
28.4000 965.0000 1.0000
28.4600 902.0000 1.0000
28.5200 861.0000 1.0000
28.5800 890.0000 1.0000
28.6400 853.0000 1.0000
28.7000 910.0000 1.0000
28.7600 896.0000 1.0000
28.8200 897.0000 1.0000
28.8800 850.0000 1.0000
28.9400 931.0000 1.0000
29.0000 858.0000 1.0000
29.0600 841.0000 1.0000
29.1200 891.0000 1.0000
29.1800 849.0000 1.0000
29.2400 809.0000 1.0000
29.3000 866.0000 1.0000
29.3600 844.0000 1.0000
29.4200 851.0000 1.0000
29.4800 842.0000 1.0000
29.5400 862.0000 1.0000
29.6000 813.0000 1.0000
29.6600 810.0000 1.0000
29.7200 804.0000 1.0000
29.7800 818.0000 1.0000
29.8400 763.0000 1.0000
29.9000 786.0000 1.0000
29.9600 775.0000 1.0000
30.0200 777.0000 1.0000
30.0800 802.0000 1.0000
30.1400 809.0000 1.0000
30.2000 738.0000 1.0000
30.2600 821.0000 1.0000
30.3200 759.0000 1.0000
30.3800 748.0000 1.0000
30.4400 817.0000 1.0000
30.5000 777.0000 1.0000
30.5600 724.0000 1.0000
30.6200 792.0000 1.0000
30.6800 759.0000 1.0000
30.7400 753.0000 1.0000
30.8000 736.0000 1.0000
30.8600 720.0000 1.0000
30.9200 742.0000 1.0000
30.9800 724.0000 1.0000
31.0400 752.0000 1.0000
31.1000 740.0000 1.0000
31.1600 706.0000 1.0000
31.2200 696.0000 1.0000
31.2800 727.0000 1.0000
31.3400 763.0000 1.0000
31.4000 736.0000 1.0000
31.4600 676.0000 1.0000
31.5200 759.0000 1.0000
31.5800 712.0000 1.0000
31.6400 683.0000 1.0000
31.7000 678.0000 1.0000
31.7600 722.0000 1.0000
31.8200 687.0000 1.0000
31.8800 692.0000 1.0000
31.9400 725.0000 1.0000
32.0000 720.0000 1.0000
32.0600 667.0000 1.0000
32.1200 710.0000 1.0000
32.1800 686.0000 1.0000
32.2400 701.0000 1.0000
32.3000 659.0000 1.0000
32.3600 626.0000 1.0000
32.4200 689.0000 1.0000
32.4800 629.0000 1.0000
32.5400 712.0000 1.0000
32.6000 692.0000 1.0000
32.6600 644.0000 1.0000
32.7200 634.0000 1.0000
32.7800 681.0000 1.0000
32.8400 626.0000 1.0000
32.9000 675.0000 1.0000
32.9600 644.0000 1.0000
33.0200 652.0000 1.0000
33.0800 623.0000 1.0000
33.1400 665.0000 1.0000
33.2000 629.0000 1.0000
33.2600 676.0000 1.0000
33.3200 628.0000 1.0000
33.3800 643.0000 1.0000
33.4400 611.0000 1.0000
33.5000 683.0000 1.0000
33.5600 659.0000 1.0000
33.6200 624.0000 1.0000
33.6800 613.0000 1.0000
33.7400 607.0000 1.0000
33.8000 608.0000 1.0000
33.8600 612.0000 1.0000
33.9200 642.0000 1.0000
33.9800 626.0000 1.0000
34.0400 626.0000 1.0000
34.1000 630.0000 1.0000
34.1600 613.0000 1.0000
34.2200 611.0000 1.0000
34.2800 650.0000 1.0000
34.3400 688.0000 1.0000
34.4000 693.0000 1.0000
34.4600 788.0000 1.0000
34.5200 789.0000 1.0000
34.5800 771.0000 1.0000
34.6400 695.0000 1.0000
34.7000 647.0000 1.0000
34.7600 616.0000 1.0000
34.8200 610.0000 1.0000
34.8800 613.0000 1.0000
34.9400 551.0000 1.0000
35.0000 603.0000 1.0000
35.0600 533.0000 1.0000
35.1200 569.0000 1.0000
35.1800 523.0000 1.0000
35.2400 582.0000 1.0000
35.3000 550.0000 1.0000
35.3600 547.0000 1.0000
35.4200 545.0000 1.0000
35.4800 526.0000 1.0000
35.5400 550.0000 1.0000
35.6000 525.0000 1.0000
35.6600 530.0000 1.0000
35.7200 501.0000 1.0000
35.7800 524.0000 1.0000
35.8400 508.0000 1.0000
35.9000 553.0000 1.0000
35.9600 546.0000 1.0000
36.0200 518.0000 1.0000
36.0800 566.0000 1.0000
36.1400 532.0000 1.0000
36.2000 565.0000 1.0000
36.2600 546.0000 1.0000
36.3200 555.0000 1.0000
36.3800 593.0000 1.0000
36.4400 591.0000 1.0000
36.5000 556.0000 1.0000
36.5600 529.0000 1.0000
36.6200 500.0000 1.0000
36.6800 534.0000 1.0000
36.7400 471.0000 1.0000
36.8000 497.0000 1.0000
36.8600 494.0000 1.0000
36.9200 503.0000 1.0000
36.9800 481.0000 1.0000
37.0400 458.0000 1.0000
37.1000 495.0000 1.0000
37.1600 488.0000 1.0000
37.2200 473.0000 1.0000
37.2800 495.0000 1.0000
37.3400 453.0000 1.0000
37.4000 464.0000 1.0000
37.4600 465.0000 1.0000
37.5200 472.0000 1.0000
37.5800 463.0000 1.0000
37.6400 456.0000 1.0000
37.7000 403.0000 1.0000
37.7600 460.0000 1.0000
37.8200 474.0000 1.0000
37.8800 448.0000 1.0000
37.9400 451.0000 1.0000
38.0000 469.0000 1.0000
38.0600 469.0000 1.0000
38.1200 498.0000 1.0000
38.1800 528.0000 1.0000
38.2400 496.0000 1.0000
38.3000 507.0000 1.0000
38.3600 584.0000 1.0000
38.4200 744.0000 1.0000
38.4800 921.0000 1.0000
38.5400 1027.0000 1.0000
38.6000 894.0000 1.0000
38.6600 749.0000 1.0000
38.7200 599.0000 1.0000
38.7800 524.0000 1.0000
38.8400 492.0000 1.0000
38.9000 469.0000 1.0000
38.9600 435.0000 1.0000
39.0200 411.0000 1.0000
39.0800 402.0000 1.0000
39.1400 432.0000 1.0000
39.2000 412.0000 1.0000
39.2600 443.0000 1.0000
39.3200 413.0000 1.0000
39.3800 394.0000 1.0000
39.4400 424.0000 1.0000
39.5000 444.0000 1.0000
39.5600 424.0000 1.0000
39.6200 392.0000 1.0000
39.6800 396.0000 1.0000
39.7400 397.0000 1.0000
39.8000 399.0000 1.0000
39.8600 393.0000 1.0000
39.9200 405.0000 1.0000
39.9800 391.0000 1.0000
40.0400 377.0000 1.0000
40.1000 392.0000 1.0000
40.1600 405.0000 1.0000
40.2200 390.0000 1.0000
40.2800 387.0000 1.0000
40.3400 386.0000 1.0000
40.4000 375.0000 1.0000
40.4600 373.0000 1.0000
40.5200 359.0000 1.0000
40.5800 383.0000 1.0000
40.6400 375.0000 1.0000
40.7000 352.0000 1.0000
40.7600 387.0000 1.0000
40.8200 356.0000 1.0000
40.8800 366.0000 1.0000
40.9400 415.0000 1.0000
41.0000 376.0000 1.0000
41.0600 382.0000 1.0000
41.1200 362.0000 1.0000
41.1800 377.0000 1.0000
41.2400 383.0000 1.0000
41.3000 364.0000 1.0000
41.3600 360.0000 1.0000
41.4200 386.0000 1.0000
41.4800 352.0000 1.0000
41.5400 364.0000 1.0000
41.6000 383.0000 1.0000
41.6600 372.0000 1.0000
41.7200 345.0000 1.0000
41.7800 353.0000 1.0000
41.8400 364.0000 1.0000
41.9000 364.0000 1.0000
41.9600 348.0000 1.0000
42.0200 363.0000 1.0000
42.0800 327.0000 1.0000
42.1400 355.0000 1.0000
42.2000 356.0000 1.0000
42.2600 330.0000 1.0000
42.3200 365.0000 1.0000
42.3800 353.0000 1.0000
42.4400 309.0000 1.0000
42.5000 329.0000 1.0000
42.5600 362.0000 1.0000
42.6200 331.0000 1.0000
42.6800 332.0000 1.0000
42.7400 341.0000 1.0000
42.8000 305.0000 1.0000
42.8600 381.0000 1.0000
42.9200 340.0000 1.0000
42.9800 344.0000 1.0000
43.0400 333.0000 1.0000
43.1000 338.0000 1.0000
43.1600 348.0000 1.0000
43.2200 331.0000 1.0000
43.2800 348.0000 1.0000
43.3400 353.0000 1.0000
43.4000 317.0000 1.0000
43.4600 324.0000 1.0000
43.5200 363.0000 1.0000
43.5800 352.0000 1.0000
43.6400 317.0000 1.0000
43.7000 316.0000 1.0000
43.7600 333.0000 1.0000
43.8200 305.0000 1.0000
43.8800 302.0000 1.0000
43.9400 334.0000 1.0000
44.0000 320.0000 1.0000
44.0600 317.0000 1.0000
44.1200 339.0000 1.0000
44.1800 306.0000 1.0000
44.2400 331.0000 1.0000
44.3000 325.0000 1.0000
44.3600 316.0000 1.0000
44.4200 323.0000 1.0000
44.4800 302.0000 1.0000
44.5400 325.0000 1.0000
44.6000 297.0000 1.0000
44.6600 330.0000 1.0000
44.7200 283.0000 1.0000
44.7800 309.0000 1.0000
44.8400 316.0000 1.0000
44.9000 319.0000 1.0000
44.9600 315.0000 1.0000
45.0200 344.0000 1.0000
45.0800 313.0000 1.0000
45.1400 291.0000 1.0000
45.2000 350.0000 1.0000
45.2600 315.0000 1.0000
45.3200 316.0000 1.0000
45.3800 330.0000 1.0000
45.4400 293.0000 1.0000
45.5000 289.0000 1.0000
45.5600 289.0000 1.0000
45.6200 307.0000 1.0000
45.6800 304.0000 1.0000
45.7400 310.0000 1.0000
45.8000 293.0000 1.0000
45.8600 310.0000 1.0000
45.9200 328.0000 1.0000
45.9800 292.0000 1.0000
46.0400 307.0000 1.0000
46.1000 275.0000 1.0000
46.1600 294.0000 1.0000
46.2200 296.0000 1.0000
46.2800 299.0000 1.0000
46.3400 295.0000 1.0000
46.4000 274.0000 1.0000
46.4600 305.0000 1.0000
46.5200 273.0000 1.0000
46.5800 308.0000 1.0000
46.6400 276.0000 1.0000
46.7000 299.0000 1.0000
46.7600 282.0000 1.0000
46.8200 298.0000 1.0000
46.8800 290.0000 1.0000
46.9400 294.0000 1.0000
47.0000 293.0000 1.0000
47.0600 275.0000 1.0000
47.1200 306.0000 1.0000
47.1800 270.0000 1.0000
47.2400 287.0000 1.0000
47.3000 279.0000 1.0000
47.3600 284.0000 1.0000
47.4200 280.0000 1.0000
47.4800 281.0000 1.0000
47.5400 255.0000 1.0000
47.6000 288.0000 1.0000
47.6600 298.0000 1.0000
47.7200 264.0000 1.0000
47.7800 333.0000 1.0000
47.8400 288.0000 1.0000
47.9000 274.0000 1.0000
47.9600 250.0000 1.0000
48.0200 261.0000 1.0000
48.0800 256.0000 1.0000
48.1400 305.0000 1.0000
48.2000 268.0000 1.0000
48.2600 253.0000 1.0000
48.3200 276.0000 1.0000
48.3800 275.0000 1.0000
48.4400 293.0000 1.0000
48.5000 268.0000 1.0000
48.5600 252.0000 1.0000
48.6200 265.0000 1.0000
48.6800 260.0000 1.0000
48.7400 264.0000 1.0000
48.8000 269.0000 1.0000
48.8600 277.0000 1.0000
48.9200 247.0000 1.0000
48.9800 277.0000 1.0000
49.0400 242.0000 1.0000
49.1000 252.0000 1.0000
49.1600 288.0000 1.0000
49.2200 266.0000 1.0000
49.2800 278.0000 1.0000
49.3400 241.0000 1.0000
49.4000 266.0000 1.0000
49.4600 272.0000 1.0000
49.5200 265.0000 1.0000
49.5800 243.0000 1.0000
49.6400 289.0000 1.0000
49.7000 254.0000 1.0000
49.7600 256.0000 1.0000
49.8200 272.0000 1.0000
49.8800 260.0000 1.0000
49.9400 244.0000 1.0000
50.0000 263.0000 1.0000
50.0600 275.0000 1.0000
50.1200 282.0000 1.0000
50.1800 242.0000 1.0000
50.2400 254.0000 1.0000
50.3000 263.0000 1.0000
50.3600 269.0000 1.0000
50.4200 274.0000 1.0000
50.4800 250.0000 1.0000
50.5400 231.0000 1.0000
50.6000 253.0000 1.0000
50.6600 263.0000 1.0000
50.7200 246.0000 1.0000
50.7800 252.0000 1.0000
50.8400 261.0000 1.0000
50.9000 252.0000 1.0000
50.9600 282.0000 1.0000
51.0200 253.0000 1.0000
51.0800 245.0000 1.0000
51.1400 244.0000 1.0000
51.2000 252.0000 1.0000
51.2600 251.0000 1.0000
51.3200 260.0000 1.0000
51.3800 270.0000 1.0000
51.4400 261.0000 1.0000
51.5000 263.0000 1.0000
51.5600 268.0000 1.0000
51.6200 277.0000 1.0000
51.6800 252.0000 1.0000
51.7400 276.0000 1.0000
51.8000 264.0000 1.0000
51.8600 280.0000 1.0000
51.9200 280.0000 1.0000
51.9800 310.0000 1.0000
52.0400 353.0000 1.0000
52.1000 437.0000 1.0000
52.1600 698.0000 1.0000
52.2200 1036.0000 1.0000
52.2800 1075.0000 1.0000
52.3400 958.0000 1.0000
52.4000 852.0000 1.0000
52.4600 635.0000 1.0000
52.5200 479.0000 1.0000
52.5800 381.0000 1.0000
52.6400 305.0000 1.0000
52.7000 280.0000 1.0000
52.7600 264.0000 1.0000
52.8200 287.0000 1.0000
52.8800 274.0000 1.0000
52.9400 257.0000 1.0000
53.0000 230.0000 1.0000
53.0600 264.0000 1.0000
53.1200 243.0000 1.0000
53.1800 250.0000 1.0000
53.2400 218.0000 1.0000
53.3000 266.0000 1.0000
53.3600 237.0000 1.0000
53.4200 241.0000 1.0000
53.4800 285.0000 1.0000
53.5400 227.0000 1.0000
53.6000 264.0000 1.0000
53.6600 237.0000 1.0000
53.7200 287.0000 1.0000
53.7800 233.0000 1.0000
53.8400 251.0000 1.0000
53.9000 256.0000 1.0000
53.9600 246.0000 1.0000
54.0200 260.0000 1.0000
54.0800 220.0000 1.0000
54.1400 240.0000 1.0000
54.2000 276.0000 1.0000
54.2600 249.0000 1.0000
54.3200 246.0000 1.0000
54.3800 257.0000 1.0000
54.4400 239.0000 1.0000
54.5000 224.0000 1.0000
54.5600 241.0000 1.0000
54.6200 219.0000 1.0000
54.6800 220.0000 1.0000
54.7400 244.0000 1.0000
54.8000 274.0000 1.0000
54.8600 215.0000 1.0000
54.9200 264.0000 1.0000
54.9800 232.0000 1.0000
55.0400 283.0000 1.0000
55.1000 272.0000 1.0000
55.1600 297.0000 1.0000
55.2200 308.0000 1.0000
55.2800 341.0000 1.0000
55.3400 365.0000 1.0000
55.4000 315.0000 1.0000
55.4600 292.0000 1.0000
55.5200 276.0000 1.0000
55.5800 283.0000 1.0000
55.6400 268.0000 1.0000
55.7000 238.0000 1.0000
55.7600 230.0000 1.0000
55.8200 246.0000 1.0000
55.8800 213.0000 1.0000
55.9400 255.0000 1.0000
56.0000 220.0000 1.0000
56.0600 223.0000 1.0000
56.1200 218.0000 1.0000
56.1800 225.0000 1.0000
56.2400 237.0000 1.0000
56.3000 238.0000 1.0000
56.3600 254.0000 1.0000
56.4200 220.0000 1.0000
56.4800 229.0000 1.0000
56.5400 236.0000 1.0000
56.6000 252.0000 1.0000
56.6600 241.0000 1.0000
56.7200 211.0000 1.0000
56.7800 239.0000 1.0000
56.8400 245.0000 1.0000
56.9000 222.0000 1.0000
56.9600 223.0000 1.0000
57.0200 217.0000 1.0000
57.0800 239.0000 1.0000
57.1400 230.0000 1.0000
57.2000 224.0000 1.0000
57.2600 257.0000 1.0000
57.3200 251.0000 1.0000
57.3800 223.0000 1.0000
57.4400 241.0000 1.0000
57.5000 253.0000 1.0000
57.5600 240.0000 1.0000
57.6200 229.0000 1.0000
57.6800 231.0000 1.0000
57.7400 217.0000 1.0000
57.8000 230.0000 1.0000
57.8600 211.0000 1.0000
57.9200 229.0000 1.0000
57.9800 239.0000 1.0000
58.0400 229.0000 1.0000
58.1000 236.0000 1.0000
58.1600 232.0000 1.0000
58.2200 226.0000 1.0000
58.2800 232.0000 1.0000
58.3400 244.0000 1.0000
58.4000 227.0000 1.0000
58.4600 209.0000 1.0000
58.5200 225.0000 1.0000
58.5800 232.0000 1.0000
58.6400 236.0000 1.0000
58.7000 251.0000 1.0000
58.7600 243.0000 1.0000
58.8200 188.0000 1.0000
58.8800 224.0000 1.0000
58.9400 226.0000 1.0000
59.0000 238.0000 1.0000
59.0600 232.0000 1.0000
59.1200 250.0000 1.0000
59.1800 239.0000 1.0000
59.2400 240.0000 1.0000
59.3000 236.0000 1.0000
59.3600 227.0000 1.0000
59.4200 246.0000 1.0000
59.4800 209.0000 1.0000
59.5400 227.0000 1.0000
59.6000 224.0000 1.0000
59.6600 247.0000 1.0000
59.7200 239.0000 1.0000
59.7800 214.0000 1.0000
59.8400 194.0000 1.0000
59.9000 208.0000 1.0000
59.9600 201.0000 1.0000
60.0200 245.0000 1.0000
60.0800 226.0000 1.0000
60.1400 237.0000 1.0000
60.2000 207.0000 1.0000
60.2600 224.0000 1.0000
60.3200 234.0000 1.0000
60.3800 223.0000 1.0000
60.4400 217.0000 1.0000
60.5000 215.0000 1.0000
60.5600 196.0000 1.0000
60.6200 220.0000 1.0000
60.6800 199.0000 1.0000
60.7400 224.0000 1.0000
60.8000 218.0000 1.0000
60.8600 238.0000 1.0000
60.9200 220.0000 1.0000
60.9800 223.0000 1.0000
61.0400 231.0000 1.0000
61.1000 209.0000 1.0000
61.1600 226.0000 1.0000
61.2200 216.0000 1.0000
61.2800 235.0000 1.0000
61.3400 239.0000 1.0000
61.4000 244.0000 1.0000
61.4600 235.0000 1.0000
61.5200 262.0000 1.0000
61.5800 231.0000 1.0000
61.6400 232.0000 1.0000
61.7000 265.0000 1.0000
61.7600 236.0000 1.0000
61.8200 229.0000 1.0000
61.8800 247.0000 1.0000
61.9400 255.0000 1.0000
62.0000 255.0000 1.0000
62.0600 266.0000 1.0000
62.1200 348.0000 1.0000
62.1800 403.0000 1.0000
62.2400 423.0000 1.0000
62.3000 430.0000 1.0000
62.3600 410.0000 1.0000
62.4200 459.0000 1.0000
62.4800 360.0000 1.0000
62.5400 334.0000 1.0000
62.6000 284.0000 1.0000
62.6600 271.0000 1.0000
62.7200 240.0000 1.0000
62.7800 263.0000 1.0000
62.8400 269.0000 1.0000
62.9000 282.0000 1.0000
62.9600 234.0000 1.0000
63.0200 228.0000 1.0000
63.0800 248.0000 1.0000
63.1400 236.0000 1.0000
63.2000 246.0000 1.0000
63.2600 228.0000 1.0000
63.3200 249.0000 1.0000
63.3800 238.0000 1.0000
63.4400 208.0000 1.0000
63.5000 212.0000 1.0000
63.5600 244.0000 1.0000
63.6200 240.0000 1.0000
63.6800 248.0000 1.0000
63.7400 224.0000 1.0000
63.8000 229.0000 1.0000
63.8600 233.0000 1.0000
63.9200 264.0000 1.0000
63.9800 235.0000 1.0000
64.0400 225.0000 1.0000
64.1000 261.0000 1.0000
64.1600 237.0000 1.0000
64.2200 240.0000 1.0000
64.2800 236.0000 1.0000
64.3400 241.0000 1.0000
64.4000 235.0000 1.0000
64.4600 243.0000 1.0000
64.5200 258.0000 1.0000
64.5800 278.0000 1.0000
64.6400 311.0000 1.0000
64.7000 247.0000 1.0000
64.7600 254.0000 1.0000
64.8200 300.0000 1.0000
64.8800 255.0000 1.0000
64.9400 272.0000 1.0000
65.0000 262.0000 1.0000
65.0600 280.0000 1.0000
65.1200 219.0000 1.0000
65.1800 239.0000 1.0000
65.2400 237.0000 1.0000
65.3000 243.0000 1.0000
65.3600 266.0000 1.0000
65.4200 249.0000 1.0000
65.4800 210.0000 1.0000
65.5400 267.0000 1.0000
65.6000 235.0000 1.0000
65.6600 240.0000 1.0000
65.7200 248.0000 1.0000
65.7800 248.0000 1.0000
65.8400 247.0000 1.0000
65.9000 276.0000 1.0000
65.9600 284.0000 1.0000
66.0200 332.0000 1.0000
66.0800 382.0000 1.0000
66.1400 489.0000 1.0000
66.2000 661.0000 1.0000
66.2600 706.0000 1.0000
66.3200 676.0000 1.0000
66.3800 646.0000 1.0000
66.4400 575.0000 1.0000
66.5000 482.0000 1.0000
66.5600 397.0000 1.0000
66.6200 372.0000 1.0000
66.6800 320.0000 1.0000
66.7400 318.0000 1.0000
66.8000 278.0000 1.0000
66.8600 242.0000 1.0000
66.9200 243.0000 1.0000
66.9800 247.0000 1.0000
67.0400 237.0000 1.0000
67.1000 225.0000 1.0000
67.1600 227.0000 1.0000
67.2200 237.0000 1.0000
67.2800 211.0000 1.0000
67.3400 248.0000 1.0000
67.4000 221.0000 1.0000
67.4600 225.0000 1.0000
67.5200 230.0000 1.0000
67.5800 259.0000 1.0000
67.6400 198.0000 1.0000
67.7000 199.0000 1.0000
67.7600 250.0000 1.0000
67.8200 262.0000 1.0000
67.8800 247.0000 1.0000
67.9400 214.0000 1.0000
68.0000 230.0000 1.0000
68.0600 208.0000 1.0000
68.1200 216.0000 1.0000
68.1800 239.0000 1.0000
68.2400 227.0000 1.0000
68.3000 205.0000 1.0000
68.3600 217.0000 1.0000
68.4200 215.0000 1.0000
68.4800 228.0000 1.0000
68.5400 225.0000 1.0000
68.6000 211.0000 1.0000
68.6600 234.0000 1.0000
68.7200 217.0000 1.0000
68.7800 218.0000 1.0000
68.8400 216.0000 1.0000
68.9000 222.0000 1.0000
68.9600 245.0000 1.0000
69.0200 210.0000 1.0000
69.0800 222.0000 1.0000
69.1400 228.0000 1.0000
69.2000 212.0000 1.0000
69.2600 221.0000 1.0000
69.3200 202.0000 1.0000
69.3800 219.0000 1.0000
69.4400 185.0000 1.0000
69.5000 210.0000 1.0000
69.5600 209.0000 1.0000
69.6200 189.0000 1.0000
69.6800 210.0000 1.0000
69.7400 204.0000 1.0000
69.8000 190.0000 1.0000
69.8600 223.0000 1.0000
69.9200 200.0000 1.0000
69.9800 206.0000 1.0000
70.0400 214.0000 1.0000
70.1000 194.0000 1.0000
70.1600 221.0000 1.0000
70.2200 230.0000 1.0000
70.2800 208.0000 1.0000
70.3400 203.0000 1.0000
70.4000 210.0000 1.0000
70.4600 202.0000 1.0000
70.5200 195.0000 1.0000
70.5800 213.0000 1.0000
70.6400 237.0000 1.0000
70.7000 213.0000 1.0000
70.7600 214.0000 1.0000
70.8200 224.0000 1.0000
70.8800 213.0000 1.0000
70.9400 203.0000 1.0000
71.0000 210.0000 1.0000
71.0600 216.0000 1.0000
71.1200 215.0000 1.0000
71.1800 217.0000 1.0000
71.2400 220.0000 1.0000
71.3000 219.0000 1.0000
71.3600 220.0000 1.0000
71.4200 225.0000 1.0000
71.4800 253.0000 1.0000
71.5400 205.0000 1.0000
71.6000 235.0000 1.0000
71.6600 223.0000 1.0000
71.7200 221.0000 1.0000
71.7800 209.0000 1.0000
71.8400 221.0000 1.0000
71.9000 208.0000 1.0000
71.9600 194.0000 1.0000
72.0200 202.0000 1.0000
72.0800 230.0000 1.0000
72.1400 236.0000 1.0000
72.2000 182.0000 1.0000
72.2600 187.0000 1.0000
72.3200 222.0000 1.0000
72.3800 206.0000 1.0000
72.4400 203.0000 1.0000
72.5000 228.0000 1.0000
72.5600 239.0000 1.0000
72.6200 196.0000 1.0000
72.6800 182.0000 1.0000
72.7400 197.0000 1.0000
72.8000 215.0000 1.0000
72.8600 205.0000 1.0000
72.9200 222.0000 1.0000
72.9800 217.0000 1.0000
73.0400 207.0000 1.0000
73.1000 215.0000 1.0000
73.1600 207.0000 1.0000
73.2200 227.0000 1.0000
73.2800 221.0000 1.0000
73.3400 212.0000 1.0000
73.4000 216.0000 1.0000
73.4600 188.0000 1.0000
73.5200 206.0000 1.0000
73.5800 193.0000 1.0000
73.6400 200.0000 1.0000
73.7000 227.0000 1.0000
73.7600 189.0000 1.0000
73.8200 231.0000 1.0000
73.8800 185.0000 1.0000
73.9400 217.0000 1.0000
74.0000 206.0000 1.0000
74.0600 219.0000 1.0000
74.1200 191.0000 1.0000
74.1800 198.0000 1.0000
74.2400 191.0000 1.0000
74.3000 211.0000 1.0000
74.3600 209.0000 1.0000
74.4200 208.0000 1.0000
74.4800 190.0000 1.0000
74.5400 224.0000 1.0000
74.6000 193.0000 1.0000
74.6600 187.0000 1.0000
74.7200 183.0000 1.0000
74.7800 212.0000 1.0000
74.8400 215.0000 1.0000
74.9000 204.0000 1.0000
74.9600 204.0000 1.0000
75.0200 222.0000 1.0000
75.0800 230.0000 1.0000
75.1400 204.0000 1.0000
75.2000 205.0000 1.0000
75.2600 203.0000 1.0000
75.3200 207.0000 1.0000
75.3800 201.0000 1.0000
75.4400 188.0000 1.0000
75.5000 206.0000 1.0000
75.5600 202.0000 1.0000
75.6200 189.0000 1.0000
75.6800 206.0000 1.0000
75.7400 207.0000 1.0000
75.8000 205.0000 1.0000
75.8600 206.0000 1.0000
75.9200 206.0000 1.0000
75.9800 196.0000 1.0000
76.0400 225.0000 1.0000
76.1000 192.0000 1.0000
76.1600 236.0000 1.0000
76.2200 193.0000 1.0000
76.2800 189.0000 1.0000
76.3400 222.0000 1.0000
76.4000 203.0000 1.0000
76.4600 201.0000 1.0000
76.5200 207.0000 1.0000
76.5800 192.0000 1.0000
76.6400 225.0000 1.0000
76.7000 220.0000 1.0000
76.7600 178.0000 1.0000
76.8200 212.0000 1.0000
76.8800 221.0000 1.0000
76.9400 199.0000 1.0000
77.0000 195.0000 1.0000
77.0600 193.0000 1.0000
77.1200 179.0000 1.0000
77.1800 205.0000 1.0000
77.2400 212.0000 1.0000
77.3000 207.0000 1.0000
77.3600 210.0000 1.0000
77.4200 202.0000 1.0000
77.4800 210.0000 1.0000
77.5400 197.0000 1.0000
77.6000 207.0000 1.0000
77.6600 226.0000 1.0000
77.7200 199.0000 1.0000
77.7800 212.0000 1.0000
77.8400 209.0000 1.0000
77.9000 191.0000 1.0000
77.9600 228.0000 1.0000
78.0200 187.0000 1.0000
78.0800 205.0000 1.0000
78.1400 198.0000 1.0000
78.2000 201.0000 1.0000
78.2600 200.0000 1.0000
78.3200 193.0000 1.0000
78.3800 215.0000 1.0000
78.4400 210.0000 1.0000
78.5000 208.0000 1.0000
78.5600 210.0000 1.0000
78.6200 225.0000 1.0000
78.6800 208.0000 1.0000
78.7400 229.0000 1.0000
78.8000 269.0000 1.0000
78.8600 279.0000 1.0000
78.9200 298.0000 1.0000
78.9800 307.0000 1.0000
79.0400 292.0000 1.0000
79.1000 328.0000 1.0000
79.1600 303.0000 1.0000
79.2200 259.0000 1.0000
79.2800 229.0000 1.0000
79.3400 223.0000 1.0000
79.4000 241.0000 1.0000
79.4600 215.0000 1.0000
79.5200 203.0000 1.0000
79.5800 210.0000 1.0000
79.6400 211.0000 1.0000
79.7000 191.0000 1.0000
79.7600 233.0000 1.0000
79.8200 219.0000 1.0000
79.8800 185.0000 1.0000
79.9400 215.0000 1.0000
80.0000 209.0000 1.0000
*RAS_INT_END
*RAS_TEMPERATURE_START
*RAS_TEMPERATURE_END
*RAS_DATA_END