File: Section2_75_samples/XRD/No_002_600_13.ras
*RAS_DATA_START
*RAS_HEADER_START
*DISP_FMT_X "%.2f"
*DISP_FMT_Y "%.0f"
*DISP_FULLSCALE "3534.0000000000"
*DISP_LINE_COLOR "255.0000000000"
*DISP_LINE_STYLE "0.0000000000"
*DISP_LINE_WIDTH "0.2500000000"
*DISP_NOTE "測定データ-1"
*DISP_OFFSET_Y "0.0000000000"
*DISP_PEAKSEARCH_UNIT_Y "cps"
*DISP_RANGE_BOTTOM "0.0000000000"
*DISP_RANGE_LEFT "20.0000000000"
*DISP_RANGE_LOGCUTOFF "0.0100000000"
*DISP_RANGE_RIGHT "80.0000000000"
*DISP_RANGE_TOP "3534.0000000000"
*DISP_SCALE_MODE_Y "0.0000000000"
*DISP_TAB_NAME "2θ/θ"
*DISP_TITLE_Y "強度"
*DISP_UNIT_Y "cps"
*DISP_WINDOW_NAME "MSG_MACROENGINE"
*FILE_COMMENT " "
*FILE_MD5 ""
*FILE_MEMO " "
*FILE_OPERATOR "Administrator"
*FILE_SAMPLE " "
*FILE_TYPE "RAS_RAW"
*FILE_USERGROUP "システムマネージャ"
*FILE_VERSION "1.0000000000"
*HW_ATTACHMENT_ID "ATT0025"
*HW_ATTACHMENT_NAME "標準|Standard"
*HW_COUNTER_ID-0 "CUT0025"
*HW_COUNTER_ID-1 "CUT0020"
*HW_COUNTER_ID-2 "CUT0020"
*HW_COUNTER_ID-3 "CSL0021"
*HW_COUNTER_ID-4 "CMC0021"
*HW_COUNTER_NAME-0 "D/teX Ultra|D/teX Ultra"
*HW_COUNTER_NAME-1 "None|None"
*HW_COUNTER_NAME-2 "None|None"
*HW_COUNTER_NAME-3 "BBM|BBM"
*HW_COUNTER_NAME-4 "検出器モノクロメータ|Detector monochromator"
*HW_COUNTER_SELECT_NAME "D/teX Ultra|D/teX Ultra"
*HW_GONIOMETER_ID "GON0023"
*HW_GONIOMETER_NAME "SmartLab|SmartLab"
*HW_GONIOMETER_RADIUS-0 "90.0"
*HW_GONIOMETER_RADIUS-1 "114.0"
*HW_GONIOMETER_RADIUS-2 "190.0"
*HW_GONIOMETER_RADIUS-3 "300.0"
*HW_GONIOMETER_RADIUS-4 "187.0"
*HW_GONIOMETER_RADIUS-5 "300.0"
*HW_GONIOMETER_RADIUS-6 "113.0"
*HW_GONIOMETER_RADIUS-7 "331.0"
*HW_I_OPT_ID-0 "CBO0021"
*HW_I_OPT_ID-1 "ICR0023"
*HW_I_OPT_ID-2 "ISL0021"
*HW_I_OPT_ID-3 "ISO0021"
*HW_I_OPT_ID-4 "IAD0021"
*HW_I_OPT_ID-5 "IPR0001"
*HW_I_OPT_NAME-0 "CBOユニット|CBO unit"
*HW_I_OPT_NAME-1 "標準入射光学ユニット|Standard incident optical unit"
*HW_I_OPT_NAME-2 "標準入射スリットボックス|Standard incident slit box"
*HW_I_OPT_NAME-3 "入射平行スリット|Incident parallel slit"
*HW_I_OPT_NAME-4 "長手制限スリット|Length limiting slit"
*HW_I_OPT_NAME-5 "None|None"
*HW_R_ATTENUATER_AUTOMODE "0"
*HW_R_OPT_ID-0 "RSS0021"
*HW_R_OPT_ID-1 "RCR0023"
*HW_R_OPT_ID-2 "RSO0021"
*HW_R_OPT_ID-3 "RRS0021"
*HW_R_OPT_ID-4 "ATN0021"
*HW_R_OPT_ID-5 "RFL0021"
*HW_R_OPT_ID-6 "RAD0021"
*HW_R_OPT_NAME-0 "標準受光スリットボックス1|Standard receiving slit box # 1"
*HW_R_OPT_NAME-1 "標準受光光学ユニット1|Standard receiving unit # 1"
*HW_R_OPT_NAME-2 "標準受光光学ユニット2|Standard receiving optical unit # 2"
*HW_R_OPT_NAME-3 "標準受光スリットボックス2|Standard receiving slit box # 2"
*HW_R_OPT_NAME-4 "標準アッテネータ|Standard Attenuator"
*HW_R_OPT_NAME-5 "Cu Kβ|Cu K-beta"
*HW_R_OPT_NAME-6 "調整用受光スリット|Alignment receiving slit"
*HW_SAMPLE_HOLDER_ID "SMP0023"
*HW_SAMPLE_HOLDER_NAME "標準Zステージ|Standard Z stage"
*HW_XG_CURRENT_MAX "50"
*HW_XG_CURRENT_MIN "2"
*HW_XG_CURRENT_RESOLUTION "2"
*HW_XG_CURRENT_UNIT "mA"
*HW_XG_FOCUS "1mm x 10mm"
*HW_XG_FOCUS_TYPE "Normal"
*HW_XG_ID ""
*HW_XG_NAME "3kW 封入管(ID:1200)|3kW Sealed tube(ID:1200)"
*HW_XG_TARGET_ATOMIC_NUMBER "29.0000000000"
*HW_XG_TARGET_NAME "Cu"
*HW_XG_TYPE "Hermetic"
*HW_XG_VOLTAGE_MAX "60"
*HW_XG_VOLTAGE_MIN "20"
*HW_XG_VOLTAGE_RESOLUTION "2"
*HW_XG_VOLTAGE_UNIT "kV"
*HW_XG_WATT_MAX "2"
*HW_XG_WATT_UNIT "kW"
*HW_XG_WAVE_LENGTH_ALPHA1 "1.540593"
*HW_XG_WAVE_LENGTH_ALPHA2 "1.544414"
*HW_XG_WAVE_LENGTH_BETA "1.392250"
*MEAS_COND_AXIS_NAME-0 "2θ/θ"
*MEAS_COND_AXIS_NAME-1 "2θ"
*MEAS_COND_AXIS_NAME-2 "ω"
*MEAS_COND_AXIS_NAME-3 "Z"
*MEAS_COND_AXIS_NAME-4 "2θ/ω"
*MEAS_COND_AXIS_NAME-5 "θs"
*MEAS_COND_AXIS_NAME-6 "θd"
*MEAS_COND_AXIS_NAME-7 "Ts"
*MEAS_COND_AXIS_NAME-8 "CBO選択スリット"
*MEAS_COND_AXIS_NAME-9 "M"
*MEAS_COND_AXIS_NAME-10 "入射平行スリット"
*MEAS_COND_AXIS_NAME-11 "入射スリット"
*MEAS_COND_AXIS_NAME-12 ""
*MEAS_COND_AXIS_NAME-13 "Zs"
*MEAS_COND_AXIS_NAME-14 "入射光学素子"
*MEAS_COND_AXIS_NAME-15 "長手制限スリット"
*MEAS_COND_AXIS_NAME-16 "センタースリット"
*MEAS_COND_AXIS_NAME-17 "フィルター"
*MEAS_COND_AXIS_NAME-18 "受光スリット1"
*MEAS_COND_AXIS_NAME-19 "受光スリット2"
*MEAS_COND_AXIS_NAME-20 "受光光学素子"
*MEAS_COND_AXIS_NAME-21 "受光平行スリット"
*MEAS_COND_AXIS_NAME-22 "調整用受光スリット"
*MEAS_COND_AXIS_NAME-23 ""
*MEAS_COND_AXIS_NAME-24 ""
*MEAS_COND_AXIS_NAME-25 "Zd"
*MEAS_COND_AXIS_NAME-26 "アッテネータ"
*MEAS_COND_AXIS_NAME-27 "検出器モノクロメータ"
*MEAS_COND_AXIS_NAME-28 "モノクロメータスリット"
*MEAS_COND_AXIS_NAME-29 "プライマリビーム"
*MEAS_COND_AXIS_NAME-30 "PHA"
*MEAS_COND_AXIS_NAME_INTERNAL-0 "TwoThetaTheta"
*MEAS_COND_AXIS_NAME_INTERNAL-1 "TwoTheta"
*MEAS_COND_AXIS_NAME_INTERNAL-2 "Omega"
*MEAS_COND_AXIS_NAME_INTERNAL-3 "Z"
*MEAS_COND_AXIS_NAME_INTERNAL-4 "TwoThetaOmega"
*MEAS_COND_AXIS_NAME_INTERNAL-5 "ThetaS"
*MEAS_COND_AXIS_NAME_INTERNAL-6 "ThetaD"
*MEAS_COND_AXIS_NAME_INTERNAL-7 "Ts"
*MEAS_COND_AXIS_NAME_INTERNAL-8 "CBO"
*MEAS_COND_AXIS_NAME_INTERNAL-9 "CBO-M"
*MEAS_COND_AXIS_NAME_INTERNAL-10 "IncidentSollerSlit"
*MEAS_COND_AXIS_NAME_INTERNAL-11 "IncidentSlitBox"
*MEAS_COND_AXIS_NAME_INTERNAL-12 "IncidentSlitBox-_Axis"
*MEAS_COND_AXIS_NAME_INTERNAL-13 "Zs"
*MEAS_COND_AXIS_NAME_INTERNAL-14 "IncidentMonochromator"
*MEAS_COND_AXIS_NAME_INTERNAL-15 "IncidentAxdSlit"
*MEAS_COND_AXIS_NAME_INTERNAL-16 "CenterSlit"
*MEAS_COND_AXIS_NAME_INTERNAL-17 "Filter"
*MEAS_COND_AXIS_NAME_INTERNAL-18 "ReceivingSlitBox1"
*MEAS_COND_AXIS_NAME_INTERNAL-19 "ReceivingSlitBox2"
*MEAS_COND_AXIS_NAME_INTERNAL-20 "ReceivingOptics"
*MEAS_COND_AXIS_NAME_INTERNAL-21 "ReceivingSollerSlit"
*MEAS_COND_AXIS_NAME_INTERNAL-22 "ReceivingAxdSlit"
*MEAS_COND_AXIS_NAME_INTERNAL-23 "ReceivingSlitBox1-_Axis"
*MEAS_COND_AXIS_NAME_INTERNAL-24 "ReceivingSlitBox2-_Axis"
*MEAS_COND_AXIS_NAME_INTERNAL-25 "ReceivingSlitBox2-Zd"
*MEAS_COND_AXIS_NAME_INTERNAL-26 "Attenuator"
*MEAS_COND_AXIS_NAME_INTERNAL-27 "CounterMonochromator"
*MEAS_COND_AXIS_NAME_INTERNAL-28 "CounterSlit"
*MEAS_COND_AXIS_NAME_INTERNAL-29 "IncidentPrimary"
*MEAS_COND_AXIS_NAME_INTERNAL-30 "PHA"
*MEAS_COND_AXIS_NAME_MAGICNO-0 "83951616.0000000000"
*MEAS_COND_AXIS_NAME_MAGICNO-1 "268632064.0000000000"
*MEAS_COND_AXIS_NAME_MAGICNO-2 "268500992.0000000000"
*MEAS_COND_AXIS_NAME_MAGICNO-3 "285278208.0000000000"
*MEAS_COND_AXIS_NAME_MAGICNO-4 "83951616.0000000000"
*MEAS_COND_AXIS_NAME_MAGICNO-5 "131072.0000000000"
*MEAS_COND_AXIS_NAME_MAGICNO-6 "131072.0000000000"
*MEAS_COND_AXIS_NAME_MAGICNO-7 "318898176.0000000000"
*MEAS_COND_AXIS_NAME_MAGICNO-8 "20971521.0000000000"
*MEAS_COND_AXIS_NAME_MAGICNO-9 "285343744.0000000000"
*MEAS_COND_AXIS_NAME_MAGICNO-10 "20971521.0000000000"
*MEAS_COND_AXIS_NAME_MAGICNO-11 "22020097.0000000000"
*MEAS_COND_AXIS_NAME_MAGICNO-12 "25165824.0000000000"
*MEAS_COND_AXIS_NAME_MAGICNO-13 "318898176.0000000000"
*MEAS_COND_AXIS_NAME_MAGICNO-14 "1.0000000000"
*MEAS_COND_AXIS_NAME_MAGICNO-15 "20971521.0000000000"
*MEAS_COND_AXIS_NAME_MAGICNO-16 "20971521.0000000000"
*MEAS_COND_AXIS_NAME_MAGICNO-17 "20971521.0000000000"
*MEAS_COND_AXIS_NAME_MAGICNO-18 "23068673.0000000000"
*MEAS_COND_AXIS_NAME_MAGICNO-19 "23068673.0000000000"
*MEAS_COND_AXIS_NAME_MAGICNO-20 "20971521.0000000000"
*MEAS_COND_AXIS_NAME_MAGICNO-21 "20971521.0000000000"
*MEAS_COND_AXIS_NAME_MAGICNO-22 "20971521.0000000000"
*MEAS_COND_AXIS_NAME_MAGICNO-23 "25165824.0000000000"
*MEAS_COND_AXIS_NAME_MAGICNO-24 "25165824.0000000000"
*MEAS_COND_AXIS_NAME_MAGICNO-25 "285343744.0000000000"
*MEAS_COND_AXIS_NAME_MAGICNO-26 "17301505.0000000000"
*MEAS_COND_AXIS_NAME_MAGICNO-27 "20971521.0000000000"
*MEAS_COND_AXIS_NAME_MAGICNO-28 "20971521.0000000000"
*MEAS_COND_AXIS_NAME_MAGICNO-29 "20971521.0000000000"
*MEAS_COND_AXIS_NAME_MAGICNO-30 "0.0000000000"
*MEAS_COND_AXIS_OFFSET-0 "-"
*MEAS_COND_AXIS_OFFSET-1 "-0.1081000000"
*MEAS_COND_AXIS_OFFSET-2 "0.3758000000"
*MEAS_COND_AXIS_OFFSET-3 "-"
*MEAS_COND_AXIS_OFFSET-4 "-"
*MEAS_COND_AXIS_OFFSET-5 "0.3758000000"
*MEAS_COND_AXIS_OFFSET-6 "-0.4839000000"
*MEAS_COND_AXIS_OFFSET-7 "-"
*MEAS_COND_AXIS_OFFSET-8 "-"
*MEAS_COND_AXIS_OFFSET-9 "-"
*MEAS_COND_AXIS_OFFSET-10 "-"
*MEAS_COND_AXIS_OFFSET-11 "-"
*MEAS_COND_AXIS_OFFSET-12 "-"
*MEAS_COND_AXIS_OFFSET-13 "-"
*MEAS_COND_AXIS_OFFSET-14 "-"
*MEAS_COND_AXIS_OFFSET-15 "-"
*MEAS_COND_AXIS_OFFSET-16 "-"
*MEAS_COND_AXIS_OFFSET-17 "-"
*MEAS_COND_AXIS_OFFSET-18 "-"
*MEAS_COND_AXIS_OFFSET-19 "-"
*MEAS_COND_AXIS_OFFSET-20 "-"
*MEAS_COND_AXIS_OFFSET-21 "-"
*MEAS_COND_AXIS_OFFSET-22 "-"
*MEAS_COND_AXIS_OFFSET-23 "-"
*MEAS_COND_AXIS_OFFSET-24 "-"
*MEAS_COND_AXIS_OFFSET-25 "-"
*MEAS_COND_AXIS_OFFSET-26 "-"
*MEAS_COND_AXIS_OFFSET-27 "-"
*MEAS_COND_AXIS_OFFSET-28 "-"
*MEAS_COND_AXIS_OFFSET-29 "-"
*MEAS_COND_AXIS_OFFSET-30 "-"
*MEAS_COND_AXIS_POSITION-0 "0.0000000000"
*MEAS_COND_AXIS_POSITION-1 "0.0000000000"
*MEAS_COND_AXIS_POSITION-2 "0.0000000000"
*MEAS_COND_AXIS_POSITION-3 "-0.5500000000"
*MEAS_COND_AXIS_POSITION-4 "0.0000000000"
*MEAS_COND_AXIS_POSITION-5 "0.0000000000"
*MEAS_COND_AXIS_POSITION-6 "0.0000000000"
*MEAS_COND_AXIS_POSITION-7 "-0.4278800000"
*MEAS_COND_AXIS_POSITION-8 "BB"
*MEAS_COND_AXIS_POSITION-9 "0.0000000000"
*MEAS_COND_AXIS_POSITION-10 "Soller_slit_5.0deg"
*MEAS_COND_AXIS_POSITION-11 "2/3deg"
*MEAS_COND_AXIS_POSITION-12 "2.2088000000"
*MEAS_COND_AXIS_POSITION-13 "-0.4140600000"
*MEAS_COND_AXIS_POSITION-14 "0.0000000000"
*MEAS_COND_AXIS_POSITION-15 "10.0mm"
*MEAS_COND_AXIS_POSITION-16 "None"
*MEAS_COND_AXIS_POSITION-17 "Cu_K-beta"
*MEAS_COND_AXIS_POSITION-18 "13.000mm"
*MEAS_COND_AXIS_POSITION-19 "13.000mm"
*MEAS_COND_AXIS_POSITION-20 "No_unit"
*MEAS_COND_AXIS_POSITION-21 "Soller_slit_5.0deg"
*MEAS_COND_AXIS_POSITION-22 "None"
*MEAS_COND_AXIS_POSITION-23 "13.0000000000"
*MEAS_COND_AXIS_POSITION-24 "13.0000000000"
*MEAS_COND_AXIS_POSITION-25 "0.0109400000"
*MEAS_COND_AXIS_POSITION-26 "Open"
*MEAS_COND_AXIS_POSITION-27 "None"
*MEAS_COND_AXIS_POSITION-28 "None"
*MEAS_COND_AXIS_POSITION-29 "None"
*MEAS_COND_AXIS_POSITION-30 "38.0000000000"
*MEAS_COND_AXIS_UNIT-0 "deg"
*MEAS_COND_AXIS_UNIT-1 "deg"
*MEAS_COND_AXIS_UNIT-2 "deg"
*MEAS_COND_AXIS_UNIT-3 "mm"
*MEAS_COND_AXIS_UNIT-4 "deg"
*MEAS_COND_AXIS_UNIT-5 "deg"
*MEAS_COND_AXIS_UNIT-6 "deg"
*MEAS_COND_AXIS_UNIT-7 "mm"
*MEAS_COND_AXIS_UNIT-8 ""
*MEAS_COND_AXIS_UNIT-9 "pulse"
*MEAS_COND_AXIS_UNIT-10 ""
*MEAS_COND_AXIS_UNIT-11 ""
*MEAS_COND_AXIS_UNIT-12 "mm"
*MEAS_COND_AXIS_UNIT-13 "mm"
*MEAS_COND_AXIS_UNIT-14 ""
*MEAS_COND_AXIS_UNIT-15 ""
*MEAS_COND_AXIS_UNIT-16 ""
*MEAS_COND_AXIS_UNIT-17 ""
*MEAS_COND_AXIS_UNIT-18 ""
*MEAS_COND_AXIS_UNIT-19 ""
*MEAS_COND_AXIS_UNIT-20 ""
*MEAS_COND_AXIS_UNIT-21 ""
*MEAS_COND_AXIS_UNIT-22 ""
*MEAS_COND_AXIS_UNIT-23 "mm"
*MEAS_COND_AXIS_UNIT-24 "mm"
*MEAS_COND_AXIS_UNIT-25 "mm"
*MEAS_COND_AXIS_UNIT-26 ""
*MEAS_COND_AXIS_UNIT-27 ""
*MEAS_COND_AXIS_UNIT-28 ""
*MEAS_COND_AXIS_UNIT-29 ""
*MEAS_COND_AXIS_UNIT-30 "div"
*MEAS_COND_COUNTER_CNTLOSS_CORR "0.0000000000"
*MEAS_COND_COUNTER_PHABASE "38.0000000000"
*MEAS_COND_COUNTER_PHAWINDOW "16.0000000000"
*MEAS_COND_COUNTER_PHA_UNIT "div"
*MEAS_COND_COUNTER_TAUDIFF "30.0000000000"
*MEAS_COND_COUNTER_TAUINT "0.0000000000"
*MEAS_COND_IRRADIATION_MODE "OFF"
*MEAS_COND_IRRADIATION_WIDTH ""
*MEAS_COND_OPT_ATTR "集中法"
*MEAS_COND_OPT_NAME "@集中法"
*MEAS_COND_UNSYMMETRIC_MODE "OFF"
*MEAS_COND_XG_CURRENT "30.0000000000"
*MEAS_COND_XG_VOLTAGE "40.0000000000"
*MEAS_COND_XG_WAVE_TYPE "Ka"
*MEAS_DATA_COUNT "3001.0000000000"
*MEAS_SCAN_AXIS_X "2θ/θ"
*MEAS_SCAN_AXIS_X_INTERNAL "TwoThetaTheta"
*MEAS_SCAN_END_TIME "08/27/20 11:27:10"
*MEAS_SCAN_MODE "CONTINUOUS"
*MEAS_SCAN_MONITOR "0"
*MEAS_SCAN_RESOLUTION_X "0.0002"
*MEAS_SCAN_SPEED "2.0"
*MEAS_SCAN_SPEED_UNIT "deg/min"
*MEAS_SCAN_START "20.0000000000"
*MEAS_SCAN_START_TIME "08/27/20 10:55:31"
*MEAS_SCAN_STEP "0.0200000000"
*MEAS_SCAN_STOP "80.0000000000"
*MEAS_SCAN_UNIT_X "deg"
*MEAS_SCAN_UNIT_Y "counts"
*RAS_HEADER_END
*RAS_INT_START
20.0000 1766.0000 1.0000
20.0600 1729.0000 1.0000
20.1200 1712.0000 1.0000
20.1800 1756.0000 1.0000
20.2400 1634.0000 1.0000
20.3000 1706.0000 1.0000
20.3600 1657.0000 1.0000
20.4200 1680.0000 1.0000
20.4800 1662.0000 1.0000
20.5400 1617.0000 1.0000
20.6000 1664.0000 1.0000
20.6600 1574.0000 1.0000
20.7200 1601.0000 1.0000
20.7800 1629.0000 1.0000
20.8400 1603.0000 1.0000
20.9000 1648.0000 1.0000
20.9600 1635.0000 1.0000
21.0200 1601.0000 1.0000
21.0800 1621.0000 1.0000
21.1400 1572.0000 1.0000
21.2000 1574.0000 1.0000
21.2600 1610.0000 1.0000
21.3200 1596.0000 1.0000
21.3800 1548.0000 1.0000
21.4400 1528.0000 1.0000
21.5000 1586.0000 1.0000
21.5600 1481.0000 1.0000
21.6200 1524.0000 1.0000
21.6800 1465.0000 1.0000
21.7400 1465.0000 1.0000
21.8000 1449.0000 1.0000
21.8600 1462.0000 1.0000
21.9200 1515.0000 1.0000
21.9800 1454.0000 1.0000
22.0400 1401.0000 1.0000
22.1000 1488.0000 1.0000
22.1600 1381.0000 1.0000
22.2200 1422.0000 1.0000
22.2800 1404.0000 1.0000
22.3400 1439.0000 1.0000
22.4000 1363.0000 1.0000
22.4600 1372.0000 1.0000
22.5200 1397.0000 1.0000
22.5800 1438.0000 1.0000
22.6400 1348.0000 1.0000
22.7000 1390.0000 1.0000
22.7600 1346.0000 1.0000
22.8200 1392.0000 1.0000
22.8800 1359.0000 1.0000
22.9400 1353.0000 1.0000
23.0000 1317.0000 1.0000
23.0600 1296.0000 1.0000
23.1200 1331.0000 1.0000
23.1800 1316.0000 1.0000
23.2400 1298.0000 1.0000
23.3000 1273.0000 1.0000
23.3600 1278.0000 1.0000
23.4200 1246.0000 1.0000
23.4800 1194.0000 1.0000
23.5400 1305.0000 1.0000
23.6000 1251.0000 1.0000
23.6600 1279.0000 1.0000
23.7200 1290.0000 1.0000
23.7800 1210.0000 1.0000
23.8400 1289.0000 1.0000
23.9000 1192.0000 1.0000
23.9600 1195.0000 1.0000
24.0200 1163.0000 1.0000
24.0800 1220.0000 1.0000
24.1400 1145.0000 1.0000
24.2000 1212.0000 1.0000
24.2600 1222.0000 1.0000
24.3200 1103.0000 1.0000
24.3800 1214.0000 1.0000
24.4400 1176.0000 1.0000
24.5000 1139.0000 1.0000
24.5600 1107.0000 1.0000
24.6200 1184.0000 1.0000
24.6800 1130.0000 1.0000
24.7400 1156.0000 1.0000
24.8000 1164.0000 1.0000
24.8600 1135.0000 1.0000
24.9200 1149.0000 1.0000
24.9800 1123.0000 1.0000
25.0400 1125.0000 1.0000
25.1000 1074.0000 1.0000
25.1600 1066.0000 1.0000
25.2200 1073.0000 1.0000
25.2800 1105.0000 1.0000
25.3400 1075.0000 1.0000
25.4000 1085.0000 1.0000
25.4600 1094.0000 1.0000
25.5200 1113.0000 1.0000
25.5800 1068.0000 1.0000
25.6400 1093.0000 1.0000
25.7000 1008.0000 1.0000
25.7600 1058.0000 1.0000
25.8200 1024.0000 1.0000
25.8800 1030.0000 1.0000
25.9400 1018.0000 1.0000
26.0000 986.0000 1.0000
26.0600 1015.0000 1.0000
26.1200 1018.0000 1.0000
26.1800 1035.0000 1.0000
26.2400 1028.0000 1.0000
26.3000 1040.0000 1.0000
26.3600 1012.0000 1.0000
26.4200 970.0000 1.0000
26.4800 984.0000 1.0000
26.5400 1008.0000 1.0000
26.6000 986.0000 1.0000
26.6600 991.0000 1.0000
26.7200 947.0000 1.0000
26.7800 970.0000 1.0000
26.8400 950.0000 1.0000
26.9000 910.0000 1.0000
26.9600 943.0000 1.0000
27.0200 978.0000 1.0000
27.0800 980.0000 1.0000
27.1400 1050.0000 1.0000
27.2000 1175.0000 1.0000
27.2600 1118.0000 1.0000
27.3200 1144.0000 1.0000
27.3800 1097.0000 1.0000
27.4400 1037.0000 1.0000
27.5000 960.0000 1.0000
27.5600 943.0000 1.0000
27.6200 981.0000 1.0000
27.6800 945.0000 1.0000
27.7400 988.0000 1.0000
27.8000 900.0000 1.0000
27.8600 878.0000 1.0000
27.9200 873.0000 1.0000
27.9800 869.0000 1.0000
28.0400 866.0000 1.0000
28.1000 879.0000 1.0000
28.1600 864.0000 1.0000
28.2200 870.0000 1.0000
28.2800 824.0000 1.0000
28.3400 875.0000 1.0000
28.4000 830.0000 1.0000
28.4600 865.0000 1.0000
28.5200 828.0000 1.0000
28.5800 859.0000 1.0000
28.6400 902.0000 1.0000
28.7000 885.0000 1.0000
28.7600 827.0000 1.0000
28.8200 810.0000 1.0000
28.8800 825.0000 1.0000
28.9400 816.0000 1.0000
29.0000 809.0000 1.0000
29.0600 838.0000 1.0000
29.1200 792.0000 1.0000
29.1800 842.0000 1.0000
29.2400 791.0000 1.0000
29.3000 816.0000 1.0000
29.3600 830.0000 1.0000
29.4200 784.0000 1.0000
29.4800 744.0000 1.0000
29.5400 746.0000 1.0000
29.6000 804.0000 1.0000
29.6600 784.0000 1.0000
29.7200 804.0000 1.0000
29.7800 751.0000 1.0000
29.8400 746.0000 1.0000
29.9000 730.0000 1.0000
29.9600 729.0000 1.0000
30.0200 740.0000 1.0000
30.0800 738.0000 1.0000
30.1400 752.0000 1.0000
30.2000 706.0000 1.0000
30.2600 685.0000 1.0000
30.3200 767.0000 1.0000
30.3800 719.0000 1.0000
30.4400 701.0000 1.0000
30.5000 764.0000 1.0000
30.5600 704.0000 1.0000
30.6200 718.0000 1.0000
30.6800 671.0000 1.0000
30.7400 709.0000 1.0000
30.8000 741.0000 1.0000
30.8600 695.0000 1.0000
30.9200 695.0000 1.0000
30.9800 681.0000 1.0000
31.0400 662.0000 1.0000
31.1000 680.0000 1.0000
31.1600 687.0000 1.0000
31.2200 669.0000 1.0000
31.2800 666.0000 1.0000
31.3400 650.0000 1.0000
31.4000 657.0000 1.0000
31.4600 626.0000 1.0000
31.5200 666.0000 1.0000
31.5800 644.0000 1.0000
31.6400 709.0000 1.0000
31.7000 640.0000 1.0000
31.7600 649.0000 1.0000
31.8200 649.0000 1.0000
31.8800 664.0000 1.0000
31.9400 663.0000 1.0000
32.0000 601.0000 1.0000
32.0600 623.0000 1.0000
32.1200 623.0000 1.0000
32.1800 610.0000 1.0000
32.2400 601.0000 1.0000
32.3000 588.0000 1.0000
32.3600 605.0000 1.0000
32.4200 625.0000 1.0000
32.4800 645.0000 1.0000
32.5400 637.0000 1.0000
32.6000 603.0000 1.0000
32.6600 596.0000 1.0000
32.7200 615.0000 1.0000
32.7800 618.0000 1.0000
32.8400 595.0000 1.0000
32.9000 595.0000 1.0000
32.9600 580.0000 1.0000
33.0200 637.0000 1.0000
33.0800 624.0000 1.0000
33.1400 603.0000 1.0000
33.2000 607.0000 1.0000
33.2600 577.0000 1.0000
33.3200 607.0000 1.0000
33.3800 593.0000 1.0000
33.4400 602.0000 1.0000
33.5000 593.0000 1.0000
33.5600 555.0000 1.0000
33.6200 556.0000 1.0000
33.6800 574.0000 1.0000
33.7400 569.0000 1.0000
33.8000 586.0000 1.0000
33.8600 597.0000 1.0000
33.9200 562.0000 1.0000
33.9800 573.0000 1.0000
34.0400 574.0000 1.0000
34.1000 566.0000 1.0000
34.1600 585.0000 1.0000
34.2200 538.0000 1.0000
34.2800 628.0000 1.0000
34.3400 571.0000 1.0000
34.4000 688.0000 1.0000
34.4600 702.0000 1.0000
34.5200 663.0000 1.0000
34.5800 642.0000 1.0000
34.6400 542.0000 1.0000
34.7000 605.0000 1.0000
34.7600 566.0000 1.0000
34.8200 549.0000 1.0000
34.8800 532.0000 1.0000
34.9400 524.0000 1.0000
35.0000 490.0000 1.0000
35.0600 519.0000 1.0000
35.1200 500.0000 1.0000
35.1800 501.0000 1.0000
35.2400 499.0000 1.0000
35.3000 524.0000 1.0000
35.3600 509.0000 1.0000
35.4200 525.0000 1.0000
35.4800 521.0000 1.0000
35.5400 496.0000 1.0000
35.6000 519.0000 1.0000
35.6600 463.0000 1.0000
35.7200 467.0000 1.0000
35.7800 488.0000 1.0000
35.8400 485.0000 1.0000
35.9000 449.0000 1.0000
35.9600 479.0000 1.0000
36.0200 503.0000 1.0000
36.0800 455.0000 1.0000
36.1400 475.0000 1.0000
36.2000 488.0000 1.0000
36.2600 481.0000 1.0000
36.3200 473.0000 1.0000
36.3800 514.0000 1.0000
36.4400 512.0000 1.0000
36.5000 489.0000 1.0000
36.5600 441.0000 1.0000
36.6200 451.0000 1.0000
36.6800 488.0000 1.0000
36.7400 447.0000 1.0000
36.8000 471.0000 1.0000
36.8600 427.0000 1.0000
36.9200 466.0000 1.0000
36.9800 434.0000 1.0000
37.0400 446.0000 1.0000
37.1000 439.0000 1.0000
37.1600 420.0000 1.0000
37.2200 425.0000 1.0000
37.2800 435.0000 1.0000
37.3400 442.0000 1.0000
37.4000 474.0000 1.0000
37.4600 416.0000 1.0000
37.5200 458.0000 1.0000
37.5800 412.0000 1.0000
37.6400 406.0000 1.0000
37.7000 438.0000 1.0000
37.7600 426.0000 1.0000
37.8200 357.0000 1.0000
37.8800 426.0000 1.0000
37.9400 427.0000 1.0000
38.0000 409.0000 1.0000
38.0600 410.0000 1.0000
38.1200 412.0000 1.0000
38.1800 458.0000 1.0000
38.2400 466.0000 1.0000
38.3000 469.0000 1.0000
38.3600 578.0000 1.0000
38.4200 622.0000 1.0000
38.4800 741.0000 1.0000
38.5400 799.0000 1.0000
38.6000 718.0000 1.0000
38.6600 620.0000 1.0000
38.7200 532.0000 1.0000
38.7800 460.0000 1.0000
38.8400 430.0000 1.0000
38.9000 435.0000 1.0000
38.9600 394.0000 1.0000
39.0200 393.0000 1.0000
39.0800 396.0000 1.0000
39.1400 405.0000 1.0000
39.2000 363.0000 1.0000
39.2600 364.0000 1.0000
39.3200 397.0000 1.0000
39.3800 377.0000 1.0000
39.4400 388.0000 1.0000
39.5000 383.0000 1.0000
39.5600 358.0000 1.0000
39.6200 398.0000 1.0000
39.6800 379.0000 1.0000
39.7400 402.0000 1.0000
39.8000 364.0000 1.0000
39.8600 374.0000 1.0000
39.9200 344.0000 1.0000
39.9800 390.0000 1.0000
40.0400 352.0000 1.0000
40.1000 359.0000 1.0000
40.1600 373.0000 1.0000
40.2200 371.0000 1.0000
40.2800 357.0000 1.0000
40.3400 359.0000 1.0000
40.4000 375.0000 1.0000
40.4600 304.0000 1.0000
40.5200 349.0000 1.0000
40.5800 381.0000 1.0000
40.6400 356.0000 1.0000
40.7000 372.0000 1.0000
40.7600 334.0000 1.0000
40.8200 338.0000 1.0000
40.8800 339.0000 1.0000
40.9400 325.0000 1.0000
41.0000 335.0000 1.0000
41.0600 329.0000 1.0000
41.1200 315.0000 1.0000
41.1800 347.0000 1.0000
41.2400 325.0000 1.0000
41.3000 371.0000 1.0000
41.3600 368.0000 1.0000
41.4200 332.0000 1.0000
41.4800 313.0000 1.0000
41.5400 353.0000 1.0000
41.6000 334.0000 1.0000
41.6600 360.0000 1.0000
41.7200 329.0000 1.0000
41.7800 300.0000 1.0000
41.8400 328.0000 1.0000
41.9000 343.0000 1.0000
41.9600 340.0000 1.0000
42.0200 312.0000 1.0000
42.0800 352.0000 1.0000
42.1400 330.0000 1.0000
42.2000 325.0000 1.0000
42.2600 328.0000 1.0000
42.3200 333.0000 1.0000
42.3800 329.0000 1.0000
42.4400 283.0000 1.0000
42.5000 338.0000 1.0000
42.5600 291.0000 1.0000
42.6200 340.0000 1.0000
42.6800 317.0000 1.0000
42.7400 319.0000 1.0000
42.8000 291.0000 1.0000
42.8600 337.0000 1.0000
42.9200 310.0000 1.0000
42.9800 331.0000 1.0000
43.0400 322.0000 1.0000
43.1000 348.0000 1.0000
43.1600 337.0000 1.0000
43.2200 304.0000 1.0000
43.2800 308.0000 1.0000
43.3400 321.0000 1.0000
43.4000 303.0000 1.0000
43.4600 294.0000 1.0000
43.5200 292.0000 1.0000
43.5800 301.0000 1.0000
43.6400 324.0000 1.0000
43.7000 296.0000 1.0000
43.7600 303.0000 1.0000
43.8200 293.0000 1.0000
43.8800 284.0000 1.0000
43.9400 286.0000 1.0000
44.0000 305.0000 1.0000
44.0600 278.0000 1.0000
44.1200 294.0000 1.0000
44.1800 287.0000 1.0000
44.2400 292.0000 1.0000
44.3000 262.0000 1.0000
44.3600 256.0000 1.0000
44.4200 317.0000 1.0000
44.4800 297.0000 1.0000
44.5400 298.0000 1.0000
44.6000 298.0000 1.0000
44.6600 322.0000 1.0000
44.7200 280.0000 1.0000
44.7800 279.0000 1.0000
44.8400 295.0000 1.0000
44.9000 273.0000 1.0000
44.9600 294.0000 1.0000
45.0200 294.0000 1.0000
45.0800 280.0000 1.0000
45.1400 306.0000 1.0000
45.2000 285.0000 1.0000
45.2600 274.0000 1.0000
45.3200 258.0000 1.0000
45.3800 289.0000 1.0000
45.4400 271.0000 1.0000
45.5000 288.0000 1.0000
45.5600 275.0000 1.0000
45.6200 282.0000 1.0000
45.6800 263.0000 1.0000
45.7400 248.0000 1.0000
45.8000 276.0000 1.0000
45.8600 266.0000 1.0000
45.9200 270.0000 1.0000
45.9800 258.0000 1.0000
46.0400 250.0000 1.0000
46.1000 272.0000 1.0000
46.1600 268.0000 1.0000
46.2200 255.0000 1.0000
46.2800 270.0000 1.0000
46.3400 287.0000 1.0000
46.4000 259.0000 1.0000
46.4600 264.0000 1.0000
46.5200 272.0000 1.0000
46.5800 249.0000 1.0000
46.6400 269.0000 1.0000
46.7000 251.0000 1.0000
46.7600 253.0000 1.0000
46.8200 266.0000 1.0000
46.8800 265.0000 1.0000
46.9400 268.0000 1.0000
47.0000 265.0000 1.0000
47.0600 258.0000 1.0000
47.1200 261.0000 1.0000
47.1800 256.0000 1.0000
47.2400 272.0000 1.0000
47.3000 259.0000 1.0000
47.3600 264.0000 1.0000
47.4200 257.0000 1.0000
47.4800 270.0000 1.0000
47.5400 246.0000 1.0000
47.6000 248.0000 1.0000
47.6600 249.0000 1.0000
47.7200 247.0000 1.0000
47.7800 245.0000 1.0000
47.8400 264.0000 1.0000
47.9000 260.0000 1.0000
47.9600 253.0000 1.0000
48.0200 245.0000 1.0000
48.0800 251.0000 1.0000
48.1400 226.0000 1.0000
48.2000 224.0000 1.0000
48.2600 260.0000 1.0000
48.3200 257.0000 1.0000
48.3800 228.0000 1.0000
48.4400 233.0000 1.0000
48.5000 249.0000 1.0000
48.5600 219.0000 1.0000
48.6200 256.0000 1.0000
48.6800 244.0000 1.0000
48.7400 247.0000 1.0000
48.8000 254.0000 1.0000
48.8600 219.0000 1.0000
48.9200 246.0000 1.0000
48.9800 252.0000 1.0000
49.0400 224.0000 1.0000
49.1000 247.0000 1.0000
49.1600 252.0000 1.0000
49.2200 255.0000 1.0000
49.2800 231.0000 1.0000
49.3400 226.0000 1.0000
49.4000 231.0000 1.0000
49.4600 242.0000 1.0000
49.5200 216.0000 1.0000
49.5800 237.0000 1.0000
49.6400 215.0000 1.0000
49.7000 228.0000 1.0000
49.7600 231.0000 1.0000
49.8200 236.0000 1.0000
49.8800 247.0000 1.0000
49.9400 253.0000 1.0000
50.0000 233.0000 1.0000
50.0600 233.0000 1.0000
50.1200 250.0000 1.0000
50.1800 238.0000 1.0000
50.2400 224.0000 1.0000
50.3000 220.0000 1.0000
50.3600 258.0000 1.0000
50.4200 229.0000 1.0000
50.4800 242.0000 1.0000
50.5400 235.0000 1.0000
50.6000 239.0000 1.0000
50.6600 234.0000 1.0000
50.7200 203.0000 1.0000
50.7800 224.0000 1.0000
50.8400 260.0000 1.0000
50.9000 238.0000 1.0000
50.9600 224.0000 1.0000
51.0200 212.0000 1.0000
51.0800 218.0000 1.0000
51.1400 210.0000 1.0000
51.2000 215.0000 1.0000
51.2600 247.0000 1.0000
51.3200 241.0000 1.0000
51.3800 226.0000 1.0000
51.4400 228.0000 1.0000
51.5000 236.0000 1.0000
51.5600 233.0000 1.0000
51.6200 216.0000 1.0000
51.6800 234.0000 1.0000
51.7400 245.0000 1.0000
51.8000 273.0000 1.0000
51.8600 246.0000 1.0000
51.9200 268.0000 1.0000
51.9800 272.0000 1.0000
52.0400 287.0000 1.0000
52.1000 371.0000 1.0000
52.1600 590.0000 1.0000
52.2200 780.0000 1.0000
52.2800 874.0000 1.0000
52.3400 771.0000 1.0000
52.4000 663.0000 1.0000
52.4600 547.0000 1.0000
52.5200 351.0000 1.0000
52.5800 325.0000 1.0000
52.6400 294.0000 1.0000
52.7000 257.0000 1.0000
52.7600 264.0000 1.0000
52.8200 248.0000 1.0000
52.8800 232.0000 1.0000
52.9400 254.0000 1.0000
53.0000 212.0000 1.0000
53.0600 218.0000 1.0000
53.1200 227.0000 1.0000
53.1800 223.0000 1.0000
53.2400 218.0000 1.0000
53.3000 237.0000 1.0000
53.3600 229.0000 1.0000
53.4200 232.0000 1.0000
53.4800 217.0000 1.0000
53.5400 238.0000 1.0000
53.6000 210.0000 1.0000
53.6600 226.0000 1.0000
53.7200 204.0000 1.0000
53.7800 236.0000 1.0000
53.8400 218.0000 1.0000
53.9000 211.0000 1.0000
53.9600 223.0000 1.0000
54.0200 227.0000 1.0000
54.0800 222.0000 1.0000
54.1400 214.0000 1.0000
54.2000 217.0000 1.0000
54.2600 218.0000 1.0000
54.3200 218.0000 1.0000
54.3800 199.0000 1.0000
54.4400 228.0000 1.0000
54.5000 240.0000 1.0000
54.5600 234.0000 1.0000
54.6200 231.0000 1.0000
54.6800 220.0000 1.0000
54.7400 237.0000 1.0000
54.8000 209.0000 1.0000
54.8600 223.0000 1.0000
54.9200 244.0000 1.0000
54.9800 238.0000 1.0000
55.0400 227.0000 1.0000
55.1000 221.0000 1.0000
55.1600 256.0000 1.0000
55.2200 257.0000 1.0000
55.2800 281.0000 1.0000
55.3400 278.0000 1.0000
55.4000 262.0000 1.0000
55.4600 263.0000 1.0000
55.5200 227.0000 1.0000
55.5800 221.0000 1.0000
55.6400 237.0000 1.0000
55.7000 201.0000 1.0000
55.7600 244.0000 1.0000
55.8200 197.0000 1.0000
55.8800 215.0000 1.0000
55.9400 199.0000 1.0000
56.0000 202.0000 1.0000
56.0600 216.0000 1.0000
56.1200 227.0000 1.0000
56.1800 199.0000 1.0000
56.2400 217.0000 1.0000
56.3000 202.0000 1.0000
56.3600 234.0000 1.0000
56.4200 208.0000 1.0000
56.4800 204.0000 1.0000
56.5400 189.0000 1.0000
56.6000 197.0000 1.0000
56.6600 223.0000 1.0000
56.7200 190.0000 1.0000
56.7800 216.0000 1.0000
56.8400 222.0000 1.0000
56.9000 192.0000 1.0000
56.9600 200.0000 1.0000
57.0200 198.0000 1.0000
57.0800 218.0000 1.0000
57.1400 202.0000 1.0000
57.2000 189.0000 1.0000
57.2600 225.0000 1.0000
57.3200 201.0000 1.0000
57.3800 199.0000 1.0000
57.4400 201.0000 1.0000
57.5000 181.0000 1.0000
57.5600 208.0000 1.0000
57.6200 200.0000 1.0000
57.6800 205.0000 1.0000
57.7400 216.0000 1.0000
57.8000 207.0000 1.0000
57.8600 211.0000 1.0000
57.9200 215.0000 1.0000
57.9800 198.0000 1.0000
58.0400 182.0000 1.0000
58.1000 249.0000 1.0000
58.1600 211.0000 1.0000
58.2200 203.0000 1.0000
58.2800 200.0000 1.0000
58.3400 208.0000 1.0000
58.4000 196.0000 1.0000
58.4600 205.0000 1.0000
58.5200 226.0000 1.0000
58.5800 170.0000 1.0000
58.6400 177.0000 1.0000
58.7000 205.0000 1.0000
58.7600 189.0000 1.0000
58.8200 194.0000 1.0000
58.8800 204.0000 1.0000
58.9400 175.0000 1.0000
59.0000 190.0000 1.0000
59.0600 197.0000 1.0000
59.1200 183.0000 1.0000
59.1800 203.0000 1.0000
59.2400 187.0000 1.0000
59.3000 208.0000 1.0000
59.3600 239.0000 1.0000
59.4200 195.0000 1.0000
59.4800 184.0000 1.0000
59.5400 200.0000 1.0000
59.6000 191.0000 1.0000
59.6600 210.0000 1.0000
59.7200 197.0000 1.0000
59.7800 208.0000 1.0000
59.8400 206.0000 1.0000
59.9000 219.0000 1.0000
59.9600 209.0000 1.0000
60.0200 205.0000 1.0000
60.0800 203.0000 1.0000
60.1400 199.0000 1.0000
60.2000 208.0000 1.0000
60.2600 201.0000 1.0000
60.3200 203.0000 1.0000
60.3800 201.0000 1.0000
60.4400 210.0000 1.0000
60.5000 192.0000 1.0000
60.5600 184.0000 1.0000
60.6200 184.0000 1.0000
60.6800 203.0000 1.0000
60.7400 194.0000 1.0000
60.8000 186.0000 1.0000
60.8600 191.0000 1.0000
60.9200 199.0000 1.0000
60.9800 191.0000 1.0000
61.0400 218.0000 1.0000
61.1000 220.0000 1.0000
61.1600 203.0000 1.0000
61.2200 198.0000 1.0000
61.2800 196.0000 1.0000
61.3400 206.0000 1.0000
61.4000 218.0000 1.0000
61.4600 188.0000 1.0000
61.5200 222.0000 1.0000
61.5800 199.0000 1.0000
61.6400 205.0000 1.0000
61.7000 193.0000 1.0000
61.7600 208.0000 1.0000
61.8200 222.0000 1.0000
61.8800 208.0000 1.0000
61.9400 247.0000 1.0000
62.0000 188.0000 1.0000
62.0600 236.0000 1.0000
62.1200 272.0000 1.0000
62.1800 314.0000 1.0000
62.2400 361.0000 1.0000
62.3000 333.0000 1.0000
62.3600 384.0000 1.0000
62.4200 357.0000 1.0000
62.4800 291.0000 1.0000
62.5400 292.0000 1.0000
62.6000 250.0000 1.0000
62.6600 227.0000 1.0000
62.7200 217.0000 1.0000
62.7800 218.0000 1.0000
62.8400 219.0000 1.0000
62.9000 201.0000 1.0000
62.9600 217.0000 1.0000
63.0200 181.0000 1.0000
63.0800 214.0000 1.0000
63.1400 218.0000 1.0000
63.2000 197.0000 1.0000
63.2600 204.0000 1.0000
63.3200 190.0000 1.0000
63.3800 204.0000 1.0000
63.4400 218.0000 1.0000
63.5000 190.0000 1.0000
63.5600 189.0000 1.0000
63.6200 195.0000 1.0000
63.6800 205.0000 1.0000
63.7400 197.0000 1.0000
63.8000 204.0000 1.0000
63.8600 218.0000 1.0000
63.9200 195.0000 1.0000
63.9800 195.0000 1.0000
64.0400 187.0000 1.0000
64.1000 194.0000 1.0000
64.1600 193.0000 1.0000
64.2200 180.0000 1.0000
64.2800 214.0000 1.0000
64.3400 208.0000 1.0000
64.4000 173.0000 1.0000
64.4600 238.0000 1.0000
64.5200 216.0000 1.0000
64.5800 201.0000 1.0000
64.6400 215.0000 1.0000
64.7000 218.0000 1.0000
64.7600 236.0000 1.0000
64.8200 251.0000 1.0000
64.8800 213.0000 1.0000
64.9400 213.0000 1.0000
65.0000 241.0000 1.0000
65.0600 209.0000 1.0000
65.1200 204.0000 1.0000
65.1800 180.0000 1.0000
65.2400 220.0000 1.0000
65.3000 208.0000 1.0000
65.3600 200.0000 1.0000
65.4200 217.0000 1.0000
65.4800 209.0000 1.0000
65.5400 221.0000 1.0000
65.6000 218.0000 1.0000
65.6600 209.0000 1.0000
65.7200 196.0000 1.0000
65.7800 193.0000 1.0000
65.8400 220.0000 1.0000
65.9000 217.0000 1.0000
65.9600 241.0000 1.0000
66.0200 262.0000 1.0000
66.0800 308.0000 1.0000
66.1400 450.0000 1.0000
66.2000 519.0000 1.0000
66.2600 532.0000 1.0000
66.3200 496.0000 1.0000
66.3800 492.0000 1.0000
66.4400 493.0000 1.0000
66.5000 387.0000 1.0000
66.5600 326.0000 1.0000
66.6200 283.0000 1.0000
66.6800 236.0000 1.0000
66.7400 239.0000 1.0000
66.8000 203.0000 1.0000
66.8600 213.0000 1.0000
66.9200 212.0000 1.0000
66.9800 211.0000 1.0000
67.0400 186.0000 1.0000
67.1000 184.0000 1.0000
67.1600 201.0000 1.0000
67.2200 190.0000 1.0000
67.2800 183.0000 1.0000
67.3400 207.0000 1.0000
67.4000 187.0000 1.0000
67.4600 199.0000 1.0000
67.5200 185.0000 1.0000
67.5800 208.0000 1.0000
67.6400 173.0000 1.0000
67.7000 192.0000 1.0000
67.7600 184.0000 1.0000
67.8200 191.0000 1.0000
67.8800 179.0000 1.0000
67.9400 191.0000 1.0000
68.0000 191.0000 1.0000
68.0600 180.0000 1.0000
68.1200 195.0000 1.0000
68.1800 210.0000 1.0000
68.2400 192.0000 1.0000
68.3000 198.0000 1.0000
68.3600 184.0000 1.0000
68.4200 192.0000 1.0000
68.4800 199.0000 1.0000
68.5400 173.0000 1.0000
68.6000 188.0000 1.0000
68.6600 178.0000 1.0000
68.7200 185.0000 1.0000
68.7800 188.0000 1.0000
68.8400 193.0000 1.0000
68.9000 204.0000 1.0000
68.9600 204.0000 1.0000
69.0200 177.0000 1.0000
69.0800 230.0000 1.0000
69.1400 179.0000 1.0000
69.2000 175.0000 1.0000
69.2600 179.0000 1.0000
69.3200 199.0000 1.0000
69.3800 198.0000 1.0000
69.4400 171.0000 1.0000
69.5000 215.0000 1.0000
69.5600 197.0000 1.0000
69.6200 189.0000 1.0000
69.6800 193.0000 1.0000
69.7400 182.0000 1.0000
69.8000 204.0000 1.0000
69.8600 184.0000 1.0000
69.9200 167.0000 1.0000
69.9800 188.0000 1.0000
70.0400 182.0000 1.0000
70.1000 201.0000 1.0000
70.1600 178.0000 1.0000
70.2200 181.0000 1.0000
70.2800 197.0000 1.0000
70.3400 191.0000 1.0000
70.4000 186.0000 1.0000
70.4600 179.0000 1.0000
70.5200 193.0000 1.0000
70.5800 149.0000 1.0000
70.6400 204.0000 1.0000
70.7000 181.0000 1.0000
70.7600 172.0000 1.0000
70.8200 183.0000 1.0000
70.8800 185.0000 1.0000
70.9400 197.0000 1.0000
71.0000 197.0000 1.0000
71.0600 173.0000 1.0000
71.1200 207.0000 1.0000
71.1800 195.0000 1.0000
71.2400 184.0000 1.0000
71.3000 199.0000 1.0000
71.3600 194.0000 1.0000
71.4200 193.0000 1.0000
71.4800 222.0000 1.0000
71.5400 193.0000 1.0000
71.6000 194.0000 1.0000
71.6600 198.0000 1.0000
71.7200 175.0000 1.0000
71.7800 201.0000 1.0000
71.8400 208.0000 1.0000
71.9000 197.0000 1.0000
71.9600 170.0000 1.0000
72.0200 187.0000 1.0000
72.0800 196.0000 1.0000
72.1400 175.0000 1.0000
72.2000 179.0000 1.0000
72.2600 167.0000 1.0000
72.3200 185.0000 1.0000
72.3800 193.0000 1.0000
72.4400 174.0000 1.0000
72.5000 180.0000 1.0000
72.5600 206.0000 1.0000
72.6200 165.0000 1.0000
72.6800 156.0000 1.0000
72.7400 177.0000 1.0000
72.8000 182.0000 1.0000
72.8600 167.0000 1.0000
72.9200 191.0000 1.0000
72.9800 159.0000 1.0000
73.0400 165.0000 1.0000
73.1000 200.0000 1.0000
73.1600 182.0000 1.0000
73.2200 182.0000 1.0000
73.2800 175.0000 1.0000
73.3400 178.0000 1.0000
73.4000 144.0000 1.0000
73.4600 168.0000 1.0000
73.5200 194.0000 1.0000
73.5800 189.0000 1.0000
73.6400 188.0000 1.0000
73.7000 183.0000 1.0000
73.7600 183.0000 1.0000
73.8200 192.0000 1.0000
73.8800 171.0000 1.0000
73.9400 169.0000 1.0000
74.0000 154.0000 1.0000
74.0600 177.0000 1.0000
74.1200 159.0000 1.0000
74.1800 180.0000 1.0000
74.2400 178.0000 1.0000
74.3000 183.0000 1.0000
74.3600 176.0000 1.0000
74.4200 187.0000 1.0000
74.4800 187.0000 1.0000
74.5400 181.0000 1.0000
74.6000 176.0000 1.0000
74.6600 154.0000 1.0000
74.7200 181.0000 1.0000
74.7800 159.0000 1.0000
74.8400 157.0000 1.0000
74.9000 175.0000 1.0000
74.9600 168.0000 1.0000
75.0200 165.0000 1.0000
75.0800 153.0000 1.0000
75.1400 175.0000 1.0000
75.2000 197.0000 1.0000
75.2600 171.0000 1.0000
75.3200 182.0000 1.0000
75.3800 186.0000 1.0000
75.4400 159.0000 1.0000
75.5000 182.0000 1.0000
75.5600 173.0000 1.0000
75.6200 171.0000 1.0000
75.6800 162.0000 1.0000
75.7400 169.0000 1.0000
75.8000 180.0000 1.0000
75.8600 209.0000 1.0000
75.9200 174.0000 1.0000
75.9800 168.0000 1.0000
76.0400 211.0000 1.0000
76.1000 188.0000 1.0000
76.1600 171.0000 1.0000
76.2200 172.0000 1.0000
76.2800 187.0000 1.0000
76.3400 176.0000 1.0000
76.4000 193.0000 1.0000
76.4600 191.0000 1.0000
76.5200 188.0000 1.0000
76.5800 170.0000 1.0000
76.6400 182.0000 1.0000
76.7000 189.0000 1.0000
76.7600 175.0000 1.0000
76.8200 164.0000 1.0000
76.8800 191.0000 1.0000
76.9400 173.0000 1.0000
77.0000 173.0000 1.0000
77.0600 172.0000 1.0000
77.1200 157.0000 1.0000
77.1800 192.0000 1.0000
77.2400 159.0000 1.0000
77.3000 176.0000 1.0000
77.3600 188.0000 1.0000
77.4200 165.0000 1.0000
77.4800 167.0000 1.0000
77.5400 153.0000 1.0000
77.6000 194.0000 1.0000
77.6600 172.0000 1.0000
77.7200 173.0000 1.0000
77.7800 167.0000 1.0000
77.8400 209.0000 1.0000
77.9000 186.0000 1.0000
77.9600 183.0000 1.0000
78.0200 176.0000 1.0000
78.0800 184.0000 1.0000
78.1400 180.0000 1.0000
78.2000 186.0000 1.0000
78.2600 171.0000 1.0000
78.3200 194.0000 1.0000
78.3800 156.0000 1.0000
78.4400 182.0000 1.0000
78.5000 191.0000 1.0000
78.5600 198.0000 1.0000
78.6200 178.0000 1.0000
78.6800 200.0000 1.0000
78.7400 202.0000 1.0000
78.8000 211.0000 1.0000
78.8600 237.0000 1.0000
78.9200 259.0000 1.0000
78.9800 285.0000 1.0000
79.0400 237.0000 1.0000
79.1000 227.0000 1.0000
79.1600 246.0000 1.0000
79.2200 215.0000 1.0000
79.2800 220.0000 1.0000
79.3400 224.0000 1.0000
79.4000 184.0000 1.0000
79.4600 179.0000 1.0000
79.5200 203.0000 1.0000
79.5800 180.0000 1.0000
79.6400 175.0000 1.0000
79.7000 188.0000 1.0000
79.7600 173.0000 1.0000
79.8200 175.0000 1.0000
79.8800 168.0000 1.0000
79.9400 178.0000 1.0000
80.0000 167.0000 1.0000
*RAS_INT_END
*RAS_TEMPERATURE_START
*RAS_TEMPERATURE_END
*RAS_DATA_END