File: Section2_75_samples/XRD/No_025_750_15.ras
*RAS_DATA_START
*RAS_HEADER_START
*DISP_FMT_X "%.2f"
*DISP_FMT_Y "%.0f"
*DISP_FULLSCALE "2356.0000000000"
*DISP_LINE_COLOR "255.0000000000"
*DISP_LINE_STYLE "0.0000000000"
*DISP_LINE_WIDTH "0.2500000000"
*DISP_NOTE "測定データ-12"
*DISP_OFFSET_Y "0.0000000000"
*DISP_PEAKSEARCH_UNIT_Y "cps"
*DISP_RANGE_BOTTOM "0.0000000000"
*DISP_RANGE_LEFT "20.0000000000"
*DISP_RANGE_LOGCUTOFF "0.0100000000"
*DISP_RANGE_RIGHT "80.0000000000"
*DISP_RANGE_TOP "2356.0000000000"
*DISP_SCALE_MODE_Y "0.0000000000"
*DISP_TAB_NAME "2θ/θ"
*DISP_TITLE_Y "強度"
*DISP_UNIT_Y "cps"
*DISP_WINDOW_NAME "MSG_MACROENGINE"
*FILE_COMMENT " "
*FILE_MD5 ""
*FILE_MEMO " "
*FILE_OPERATOR "Administrator"
*FILE_SAMPLE " "
*FILE_TYPE "RAS_RAW"
*FILE_USERGROUP "システムマネージャ"
*FILE_VERSION "1.0000000000"
*HW_ATTACHMENT_ID "ATT0025"
*HW_ATTACHMENT_NAME "標準|Standard"
*HW_COUNTER_ID-0 "CUT0025"
*HW_COUNTER_ID-1 "CUT0020"
*HW_COUNTER_ID-2 "CUT0020"
*HW_COUNTER_ID-3 "CSL0021"
*HW_COUNTER_ID-4 "CMC0021"
*HW_COUNTER_NAME-0 "D/teX Ultra|D/teX Ultra"
*HW_COUNTER_NAME-1 "None|None"
*HW_COUNTER_NAME-2 "None|None"
*HW_COUNTER_NAME-3 "BBM|BBM"
*HW_COUNTER_NAME-4 "検出器モノクロメータ|Detector monochromator"
*HW_COUNTER_SELECT_NAME "D/teX Ultra|D/teX Ultra"
*HW_GONIOMETER_ID "GON0023"
*HW_GONIOMETER_NAME "SmartLab|SmartLab"
*HW_GONIOMETER_RADIUS-0 "90.0"
*HW_GONIOMETER_RADIUS-1 "114.0"
*HW_GONIOMETER_RADIUS-2 "190.0"
*HW_GONIOMETER_RADIUS-3 "300.0"
*HW_GONIOMETER_RADIUS-4 "187.0"
*HW_GONIOMETER_RADIUS-5 "300.0"
*HW_GONIOMETER_RADIUS-6 "113.0"
*HW_GONIOMETER_RADIUS-7 "331.0"
*HW_I_OPT_ID-0 "CBO0021"
*HW_I_OPT_ID-1 "ICR0023"
*HW_I_OPT_ID-2 "ISL0021"
*HW_I_OPT_ID-3 "ISO0021"
*HW_I_OPT_ID-4 "IAD0021"
*HW_I_OPT_ID-5 "IPR0001"
*HW_I_OPT_NAME-0 "CBOユニット|CBO unit"
*HW_I_OPT_NAME-1 "標準入射光学ユニット|Standard incident optical unit"
*HW_I_OPT_NAME-2 "標準入射スリットボックス|Standard incident slit box"
*HW_I_OPT_NAME-3 "入射平行スリット|Incident parallel slit"
*HW_I_OPT_NAME-4 "長手制限スリット|Length limiting slit"
*HW_I_OPT_NAME-5 "None|None"
*HW_R_ATTENUATER_AUTOMODE "0"
*HW_R_OPT_ID-0 "RSS0021"
*HW_R_OPT_ID-1 "RCR0023"
*HW_R_OPT_ID-2 "RSO0021"
*HW_R_OPT_ID-3 "RRS0021"
*HW_R_OPT_ID-4 "ATN0021"
*HW_R_OPT_ID-5 "RFL0021"
*HW_R_OPT_ID-6 "RAD0021"
*HW_R_OPT_NAME-0 "標準受光スリットボックス1|Standard receiving slit box # 1"
*HW_R_OPT_NAME-1 "標準受光光学ユニット1|Standard receiving unit # 1"
*HW_R_OPT_NAME-2 "標準受光光学ユニット2|Standard receiving optical unit # 2"
*HW_R_OPT_NAME-3 "標準受光スリットボックス2|Standard receiving slit box # 2"
*HW_R_OPT_NAME-4 "標準アッテネータ|Standard Attenuator"
*HW_R_OPT_NAME-5 "Cu Kβ|Cu K-beta"
*HW_R_OPT_NAME-6 "調整用受光スリット|Alignment receiving slit"
*HW_SAMPLE_HOLDER_ID "SMP0023"
*HW_SAMPLE_HOLDER_NAME "標準Zステージ|Standard Z stage"
*HW_XG_CURRENT_MAX "50"
*HW_XG_CURRENT_MIN "2"
*HW_XG_CURRENT_RESOLUTION "2"
*HW_XG_CURRENT_UNIT "mA"
*HW_XG_FOCUS "1mm x 10mm"
*HW_XG_FOCUS_TYPE "Normal"
*HW_XG_ID ""
*HW_XG_NAME "3kW 封入管(ID:1200)|3kW Sealed tube(ID:1200)"
*HW_XG_TARGET_ATOMIC_NUMBER "29.0000000000"
*HW_XG_TARGET_NAME "Cu"
*HW_XG_TYPE "Hermetic"
*HW_XG_VOLTAGE_MAX "60"
*HW_XG_VOLTAGE_MIN "20"
*HW_XG_VOLTAGE_RESOLUTION "2"
*HW_XG_VOLTAGE_UNIT "kV"
*HW_XG_WATT_MAX "2"
*HW_XG_WATT_UNIT "kW"
*HW_XG_WAVE_LENGTH_ALPHA1 "1.540593"
*HW_XG_WAVE_LENGTH_ALPHA2 "1.544414"
*HW_XG_WAVE_LENGTH_BETA "1.392250"
*MEAS_COND_AXIS_NAME-0 "2θ/θ"
*MEAS_COND_AXIS_NAME-1 "2θ"
*MEAS_COND_AXIS_NAME-2 "ω"
*MEAS_COND_AXIS_NAME-3 "Z"
*MEAS_COND_AXIS_NAME-4 "2θ/ω"
*MEAS_COND_AXIS_NAME-5 "θs"
*MEAS_COND_AXIS_NAME-6 "θd"
*MEAS_COND_AXIS_NAME-7 "Ts"
*MEAS_COND_AXIS_NAME-8 "CBO選択スリット"
*MEAS_COND_AXIS_NAME-9 "M"
*MEAS_COND_AXIS_NAME-10 "入射平行スリット"
*MEAS_COND_AXIS_NAME-11 "入射スリット"
*MEAS_COND_AXIS_NAME-12 ""
*MEAS_COND_AXIS_NAME-13 "Zs"
*MEAS_COND_AXIS_NAME-14 "入射光学素子"
*MEAS_COND_AXIS_NAME-15 "長手制限スリット"
*MEAS_COND_AXIS_NAME-16 "センタースリット"
*MEAS_COND_AXIS_NAME-17 "フィルター"
*MEAS_COND_AXIS_NAME-18 "受光スリット1"
*MEAS_COND_AXIS_NAME-19 "受光スリット2"
*MEAS_COND_AXIS_NAME-20 "受光光学素子"
*MEAS_COND_AXIS_NAME-21 "受光平行スリット"
*MEAS_COND_AXIS_NAME-22 "調整用受光スリット"
*MEAS_COND_AXIS_NAME-23 ""
*MEAS_COND_AXIS_NAME-24 ""
*MEAS_COND_AXIS_NAME-25 "Zd"
*MEAS_COND_AXIS_NAME-26 "アッテネータ"
*MEAS_COND_AXIS_NAME-27 "検出器モノクロメータ"
*MEAS_COND_AXIS_NAME-28 "モノクロメータスリット"
*MEAS_COND_AXIS_NAME-29 "プライマリビーム"
*MEAS_COND_AXIS_NAME-30 "PHA"
*MEAS_COND_AXIS_NAME_INTERNAL-0 "TwoThetaTheta"
*MEAS_COND_AXIS_NAME_INTERNAL-1 "TwoTheta"
*MEAS_COND_AXIS_NAME_INTERNAL-2 "Omega"
*MEAS_COND_AXIS_NAME_INTERNAL-3 "Z"
*MEAS_COND_AXIS_NAME_INTERNAL-4 "TwoThetaOmega"
*MEAS_COND_AXIS_NAME_INTERNAL-5 "ThetaS"
*MEAS_COND_AXIS_NAME_INTERNAL-6 "ThetaD"
*MEAS_COND_AXIS_NAME_INTERNAL-7 "Ts"
*MEAS_COND_AXIS_NAME_INTERNAL-8 "CBO"
*MEAS_COND_AXIS_NAME_INTERNAL-9 "CBO-M"
*MEAS_COND_AXIS_NAME_INTERNAL-10 "IncidentSollerSlit"
*MEAS_COND_AXIS_NAME_INTERNAL-11 "IncidentSlitBox"
*MEAS_COND_AXIS_NAME_INTERNAL-12 "IncidentSlitBox-_Axis"
*MEAS_COND_AXIS_NAME_INTERNAL-13 "Zs"
*MEAS_COND_AXIS_NAME_INTERNAL-14 "IncidentMonochromator"
*MEAS_COND_AXIS_NAME_INTERNAL-15 "IncidentAxdSlit"
*MEAS_COND_AXIS_NAME_INTERNAL-16 "CenterSlit"
*MEAS_COND_AXIS_NAME_INTERNAL-17 "Filter"
*MEAS_COND_AXIS_NAME_INTERNAL-18 "ReceivingSlitBox1"
*MEAS_COND_AXIS_NAME_INTERNAL-19 "ReceivingSlitBox2"
*MEAS_COND_AXIS_NAME_INTERNAL-20 "ReceivingOptics"
*MEAS_COND_AXIS_NAME_INTERNAL-21 "ReceivingSollerSlit"
*MEAS_COND_AXIS_NAME_INTERNAL-22 "ReceivingAxdSlit"
*MEAS_COND_AXIS_NAME_INTERNAL-23 "ReceivingSlitBox1-_Axis"
*MEAS_COND_AXIS_NAME_INTERNAL-24 "ReceivingSlitBox2-_Axis"
*MEAS_COND_AXIS_NAME_INTERNAL-25 "ReceivingSlitBox2-Zd"
*MEAS_COND_AXIS_NAME_INTERNAL-26 "Attenuator"
*MEAS_COND_AXIS_NAME_INTERNAL-27 "CounterMonochromator"
*MEAS_COND_AXIS_NAME_INTERNAL-28 "CounterSlit"
*MEAS_COND_AXIS_NAME_INTERNAL-29 "IncidentPrimary"
*MEAS_COND_AXIS_NAME_INTERNAL-30 "PHA"
*MEAS_COND_AXIS_NAME_MAGICNO-0 "83951616.0000000000"
*MEAS_COND_AXIS_NAME_MAGICNO-1 "268632064.0000000000"
*MEAS_COND_AXIS_NAME_MAGICNO-2 "268500992.0000000000"
*MEAS_COND_AXIS_NAME_MAGICNO-3 "285278208.0000000000"
*MEAS_COND_AXIS_NAME_MAGICNO-4 "83951616.0000000000"
*MEAS_COND_AXIS_NAME_MAGICNO-5 "131072.0000000000"
*MEAS_COND_AXIS_NAME_MAGICNO-6 "131072.0000000000"
*MEAS_COND_AXIS_NAME_MAGICNO-7 "318898176.0000000000"
*MEAS_COND_AXIS_NAME_MAGICNO-8 "20971521.0000000000"
*MEAS_COND_AXIS_NAME_MAGICNO-9 "285343744.0000000000"
*MEAS_COND_AXIS_NAME_MAGICNO-10 "20971521.0000000000"
*MEAS_COND_AXIS_NAME_MAGICNO-11 "22020097.0000000000"
*MEAS_COND_AXIS_NAME_MAGICNO-12 "25165824.0000000000"
*MEAS_COND_AXIS_NAME_MAGICNO-13 "318898176.0000000000"
*MEAS_COND_AXIS_NAME_MAGICNO-14 "1.0000000000"
*MEAS_COND_AXIS_NAME_MAGICNO-15 "20971521.0000000000"
*MEAS_COND_AXIS_NAME_MAGICNO-16 "20971521.0000000000"
*MEAS_COND_AXIS_NAME_MAGICNO-17 "20971521.0000000000"
*MEAS_COND_AXIS_NAME_MAGICNO-18 "23068673.0000000000"
*MEAS_COND_AXIS_NAME_MAGICNO-19 "23068673.0000000000"
*MEAS_COND_AXIS_NAME_MAGICNO-20 "20971521.0000000000"
*MEAS_COND_AXIS_NAME_MAGICNO-21 "20971521.0000000000"
*MEAS_COND_AXIS_NAME_MAGICNO-22 "20971521.0000000000"
*MEAS_COND_AXIS_NAME_MAGICNO-23 "25165824.0000000000"
*MEAS_COND_AXIS_NAME_MAGICNO-24 "25165824.0000000000"
*MEAS_COND_AXIS_NAME_MAGICNO-25 "285343744.0000000000"
*MEAS_COND_AXIS_NAME_MAGICNO-26 "17301505.0000000000"
*MEAS_COND_AXIS_NAME_MAGICNO-27 "20971521.0000000000"
*MEAS_COND_AXIS_NAME_MAGICNO-28 "20971521.0000000000"
*MEAS_COND_AXIS_NAME_MAGICNO-29 "20971521.0000000000"
*MEAS_COND_AXIS_NAME_MAGICNO-30 "0.0000000000"
*MEAS_COND_AXIS_OFFSET-0 "-"
*MEAS_COND_AXIS_OFFSET-1 "-0.1081000000"
*MEAS_COND_AXIS_OFFSET-2 "0.3758000000"
*MEAS_COND_AXIS_OFFSET-3 "-"
*MEAS_COND_AXIS_OFFSET-4 "-"
*MEAS_COND_AXIS_OFFSET-5 "0.3758000000"
*MEAS_COND_AXIS_OFFSET-6 "-0.4839000000"
*MEAS_COND_AXIS_OFFSET-7 "-"
*MEAS_COND_AXIS_OFFSET-8 "-"
*MEAS_COND_AXIS_OFFSET-9 "-"
*MEAS_COND_AXIS_OFFSET-10 "-"
*MEAS_COND_AXIS_OFFSET-11 "-"
*MEAS_COND_AXIS_OFFSET-12 "-"
*MEAS_COND_AXIS_OFFSET-13 "-"
*MEAS_COND_AXIS_OFFSET-14 "-"
*MEAS_COND_AXIS_OFFSET-15 "-"
*MEAS_COND_AXIS_OFFSET-16 "-"
*MEAS_COND_AXIS_OFFSET-17 "-"
*MEAS_COND_AXIS_OFFSET-18 "-"
*MEAS_COND_AXIS_OFFSET-19 "-"
*MEAS_COND_AXIS_OFFSET-20 "-"
*MEAS_COND_AXIS_OFFSET-21 "-"
*MEAS_COND_AXIS_OFFSET-22 "-"
*MEAS_COND_AXIS_OFFSET-23 "-"
*MEAS_COND_AXIS_OFFSET-24 "-"
*MEAS_COND_AXIS_OFFSET-25 "-"
*MEAS_COND_AXIS_OFFSET-26 "-"
*MEAS_COND_AXIS_OFFSET-27 "-"
*MEAS_COND_AXIS_OFFSET-28 "-"
*MEAS_COND_AXIS_OFFSET-29 "-"
*MEAS_COND_AXIS_OFFSET-30 "-"
*MEAS_COND_AXIS_POSITION-0 "0.0000000000"
*MEAS_COND_AXIS_POSITION-1 "0.0000000000"
*MEAS_COND_AXIS_POSITION-2 "0.0000000000"
*MEAS_COND_AXIS_POSITION-3 "-0.5500000000"
*MEAS_COND_AXIS_POSITION-4 "0.0000000000"
*MEAS_COND_AXIS_POSITION-5 "0.0000000000"
*MEAS_COND_AXIS_POSITION-6 "0.0000000000"
*MEAS_COND_AXIS_POSITION-7 "-0.4278800000"
*MEAS_COND_AXIS_POSITION-8 "BB"
*MEAS_COND_AXIS_POSITION-9 "0.0000000000"
*MEAS_COND_AXIS_POSITION-10 "Soller_slit_5.0deg"
*MEAS_COND_AXIS_POSITION-11 "2/3deg"
*MEAS_COND_AXIS_POSITION-12 "2.2088000000"
*MEAS_COND_AXIS_POSITION-13 "-0.4140600000"
*MEAS_COND_AXIS_POSITION-14 "0.0000000000"
*MEAS_COND_AXIS_POSITION-15 "10.0mm"
*MEAS_COND_AXIS_POSITION-16 "None"
*MEAS_COND_AXIS_POSITION-17 "Cu_K-beta"
*MEAS_COND_AXIS_POSITION-18 "13.000mm"
*MEAS_COND_AXIS_POSITION-19 "13.000mm"
*MEAS_COND_AXIS_POSITION-20 "No_unit"
*MEAS_COND_AXIS_POSITION-21 "Soller_slit_5.0deg"
*MEAS_COND_AXIS_POSITION-22 "None"
*MEAS_COND_AXIS_POSITION-23 "13.0000000000"
*MEAS_COND_AXIS_POSITION-24 "13.0000000000"
*MEAS_COND_AXIS_POSITION-25 "0.0109400000"
*MEAS_COND_AXIS_POSITION-26 "Open"
*MEAS_COND_AXIS_POSITION-27 "None"
*MEAS_COND_AXIS_POSITION-28 "None"
*MEAS_COND_AXIS_POSITION-29 "None"
*MEAS_COND_AXIS_POSITION-30 "38.0000000000"
*MEAS_COND_AXIS_UNIT-0 "deg"
*MEAS_COND_AXIS_UNIT-1 "deg"
*MEAS_COND_AXIS_UNIT-2 "deg"
*MEAS_COND_AXIS_UNIT-3 "mm"
*MEAS_COND_AXIS_UNIT-4 "deg"
*MEAS_COND_AXIS_UNIT-5 "deg"
*MEAS_COND_AXIS_UNIT-6 "deg"
*MEAS_COND_AXIS_UNIT-7 "mm"
*MEAS_COND_AXIS_UNIT-8 ""
*MEAS_COND_AXIS_UNIT-9 "pulse"
*MEAS_COND_AXIS_UNIT-10 ""
*MEAS_COND_AXIS_UNIT-11 ""
*MEAS_COND_AXIS_UNIT-12 "mm"
*MEAS_COND_AXIS_UNIT-13 "mm"
*MEAS_COND_AXIS_UNIT-14 ""
*MEAS_COND_AXIS_UNIT-15 ""
*MEAS_COND_AXIS_UNIT-16 ""
*MEAS_COND_AXIS_UNIT-17 ""
*MEAS_COND_AXIS_UNIT-18 ""
*MEAS_COND_AXIS_UNIT-19 ""
*MEAS_COND_AXIS_UNIT-20 ""
*MEAS_COND_AXIS_UNIT-21 ""
*MEAS_COND_AXIS_UNIT-22 ""
*MEAS_COND_AXIS_UNIT-23 "mm"
*MEAS_COND_AXIS_UNIT-24 "mm"
*MEAS_COND_AXIS_UNIT-25 "mm"
*MEAS_COND_AXIS_UNIT-26 ""
*MEAS_COND_AXIS_UNIT-27 ""
*MEAS_COND_AXIS_UNIT-28 ""
*MEAS_COND_AXIS_UNIT-29 ""
*MEAS_COND_AXIS_UNIT-30 "div"
*MEAS_COND_COUNTER_CNTLOSS_CORR "0.0000000000"
*MEAS_COND_COUNTER_PHABASE "38.0000000000"
*MEAS_COND_COUNTER_PHAWINDOW "16.0000000000"
*MEAS_COND_COUNTER_PHA_UNIT "div"
*MEAS_COND_COUNTER_TAUDIFF "30.0000000000"
*MEAS_COND_COUNTER_TAUINT "0.0000000000"
*MEAS_COND_IRRADIATION_MODE "OFF"
*MEAS_COND_IRRADIATION_WIDTH ""
*MEAS_COND_OPT_ATTR "集中法"
*MEAS_COND_OPT_NAME "@集中法"
*MEAS_COND_UNSYMMETRIC_MODE "OFF"
*MEAS_COND_XG_CURRENT "30.0000000000"
*MEAS_COND_XG_VOLTAGE "40.0000000000"
*MEAS_COND_XG_WAVE_TYPE "Ka"
*MEAS_DATA_COUNT "3001.0000000000"
*MEAS_SCAN_AXIS_X "2θ/θ"
*MEAS_SCAN_AXIS_X_INTERNAL "TwoThetaTheta"
*MEAS_SCAN_END_TIME "08/27/20 18:08:26"
*MEAS_SCAN_MODE "CONTINUOUS"
*MEAS_SCAN_MONITOR "0"
*MEAS_SCAN_RESOLUTION_X "0.0002"
*MEAS_SCAN_SPEED "2.0"
*MEAS_SCAN_SPEED_UNIT "deg/min"
*MEAS_SCAN_START "20.0000000000"
*MEAS_SCAN_START_TIME "08/27/20 17:36:46"
*MEAS_SCAN_STEP "0.0200000000"
*MEAS_SCAN_STOP "80.0000000000"
*MEAS_SCAN_UNIT_X "deg"
*MEAS_SCAN_UNIT_Y "counts"
*RAS_HEADER_END
*RAS_INT_START
20.0000 1105.0000 1.0000
20.0600 1158.0000 1.0000
20.1200 1146.0000 1.0000
20.1800 1084.0000 1.0000
20.2400 1078.0000 1.0000
20.3000 1084.0000 1.0000
20.3600 1077.0000 1.0000
20.4200 1123.0000 1.0000
20.4800 1034.0000 1.0000
20.5400 1074.0000 1.0000
20.6000 1111.0000 1.0000
20.6600 1024.0000 1.0000
20.7200 1037.0000 1.0000
20.7800 1088.0000 1.0000
20.8400 1061.0000 1.0000
20.9000 1069.0000 1.0000
20.9600 1089.0000 1.0000
21.0200 1024.0000 1.0000
21.0800 1068.0000 1.0000
21.1400 963.0000 1.0000
21.2000 1007.0000 1.0000
21.2600 1022.0000 1.0000
21.3200 1039.0000 1.0000
21.3800 977.0000 1.0000
21.4400 1018.0000 1.0000
21.5000 969.0000 1.0000
21.5600 1002.0000 1.0000
21.6200 999.0000 1.0000
21.6800 1002.0000 1.0000
21.7400 1000.0000 1.0000
21.8000 949.0000 1.0000
21.8600 971.0000 1.0000
21.9200 989.0000 1.0000
21.9800 981.0000 1.0000
22.0400 953.0000 1.0000
22.1000 900.0000 1.0000
22.1600 955.0000 1.0000
22.2200 854.0000 1.0000
22.2800 960.0000 1.0000
22.3400 916.0000 1.0000
22.4000 936.0000 1.0000
22.4600 937.0000 1.0000
22.5200 967.0000 1.0000
22.5800 883.0000 1.0000
22.6400 937.0000 1.0000
22.7000 846.0000 1.0000
22.7600 960.0000 1.0000
22.8200 947.0000 1.0000
22.8800 919.0000 1.0000
22.9400 936.0000 1.0000
23.0000 834.0000 1.0000
23.0600 877.0000 1.0000
23.1200 960.0000 1.0000
23.1800 896.0000 1.0000
23.2400 879.0000 1.0000
23.3000 888.0000 1.0000
23.3600 894.0000 1.0000
23.4200 906.0000 1.0000
23.4800 899.0000 1.0000
23.5400 866.0000 1.0000
23.6000 810.0000 1.0000
23.6600 834.0000 1.0000
23.7200 877.0000 1.0000
23.7800 859.0000 1.0000
23.8400 829.0000 1.0000
23.9000 856.0000 1.0000
23.9600 871.0000 1.0000
24.0200 804.0000 1.0000
24.0800 864.0000 1.0000
24.1400 786.0000 1.0000
24.2000 864.0000 1.0000
24.2600 824.0000 1.0000
24.3200 766.0000 1.0000
24.3800 847.0000 1.0000
24.4400 776.0000 1.0000
24.5000 765.0000 1.0000
24.5600 849.0000 1.0000
24.6200 754.0000 1.0000
24.6800 762.0000 1.0000
24.7400 769.0000 1.0000
24.8000 785.0000 1.0000
24.8600 757.0000 1.0000
24.9200 790.0000 1.0000
24.9800 729.0000 1.0000
25.0400 757.0000 1.0000
25.1000 756.0000 1.0000
25.1600 732.0000 1.0000
25.2200 708.0000 1.0000
25.2800 723.0000 1.0000
25.3400 743.0000 1.0000
25.4000 772.0000 1.0000
25.4600 768.0000 1.0000
25.5200 748.0000 1.0000
25.5800 706.0000 1.0000
25.6400 709.0000 1.0000
25.7000 692.0000 1.0000
25.7600 704.0000 1.0000
25.8200 681.0000 1.0000
25.8800 741.0000 1.0000
25.9400 693.0000 1.0000
26.0000 707.0000 1.0000
26.0600 673.0000 1.0000
26.1200 659.0000 1.0000
26.1800 721.0000 1.0000
26.2400 687.0000 1.0000
26.3000 656.0000 1.0000
26.3600 681.0000 1.0000
26.4200 678.0000 1.0000
26.4800 687.0000 1.0000
26.5400 630.0000 1.0000
26.6000 655.0000 1.0000
26.6600 652.0000 1.0000
26.7200 667.0000 1.0000
26.7800 653.0000 1.0000
26.8400 647.0000 1.0000
26.9000 626.0000 1.0000
26.9600 648.0000 1.0000
27.0200 649.0000 1.0000
27.0800 643.0000 1.0000
27.1400 691.0000 1.0000
27.2000 643.0000 1.0000
27.2600 660.0000 1.0000
27.3200 672.0000 1.0000
27.3800 671.0000 1.0000
27.4400 686.0000 1.0000
27.5000 634.0000 1.0000
27.5600 622.0000 1.0000
27.6200 621.0000 1.0000
27.6800 622.0000 1.0000
27.7400 606.0000 1.0000
27.8000 615.0000 1.0000
27.8600 607.0000 1.0000
27.9200 621.0000 1.0000
27.9800 529.0000 1.0000
28.0400 562.0000 1.0000
28.1000 601.0000 1.0000
28.1600 595.0000 1.0000
28.2200 596.0000 1.0000
28.2800 564.0000 1.0000
28.3400 587.0000 1.0000
28.4000 570.0000 1.0000
28.4600 590.0000 1.0000
28.5200 577.0000 1.0000
28.5800 599.0000 1.0000
28.6400 547.0000 1.0000
28.7000 588.0000 1.0000
28.7600 567.0000 1.0000
28.8200 564.0000 1.0000
28.8800 548.0000 1.0000
28.9400 526.0000 1.0000
29.0000 583.0000 1.0000
29.0600 562.0000 1.0000
29.1200 484.0000 1.0000
29.1800 597.0000 1.0000
29.2400 529.0000 1.0000
29.3000 539.0000 1.0000
29.3600 555.0000 1.0000
29.4200 554.0000 1.0000
29.4800 517.0000 1.0000
29.5400 528.0000 1.0000
29.6000 546.0000 1.0000
29.6600 510.0000 1.0000
29.7200 563.0000 1.0000
29.7800 538.0000 1.0000
29.8400 516.0000 1.0000
29.9000 481.0000 1.0000
29.9600 513.0000 1.0000
30.0200 496.0000 1.0000
30.0800 517.0000 1.0000
30.1400 499.0000 1.0000
30.2000 458.0000 1.0000
30.2600 487.0000 1.0000
30.3200 486.0000 1.0000
30.3800 481.0000 1.0000
30.4400 489.0000 1.0000
30.5000 464.0000 1.0000
30.5600 483.0000 1.0000
30.6200 522.0000 1.0000
30.6800 476.0000 1.0000
30.7400 456.0000 1.0000
30.8000 474.0000 1.0000
30.8600 431.0000 1.0000
30.9200 476.0000 1.0000
30.9800 484.0000 1.0000
31.0400 443.0000 1.0000
31.1000 498.0000 1.0000
31.1600 457.0000 1.0000
31.2200 421.0000 1.0000
31.2800 460.0000 1.0000
31.3400 454.0000 1.0000
31.4000 443.0000 1.0000
31.4600 452.0000 1.0000
31.5200 444.0000 1.0000
31.5800 426.0000 1.0000
31.6400 434.0000 1.0000
31.7000 422.0000 1.0000
31.7600 448.0000 1.0000
31.8200 440.0000 1.0000
31.8800 453.0000 1.0000
31.9400 424.0000 1.0000
32.0000 441.0000 1.0000
32.0600 420.0000 1.0000
32.1200 411.0000 1.0000
32.1800 442.0000 1.0000
32.2400 430.0000 1.0000
32.3000 422.0000 1.0000
32.3600 430.0000 1.0000
32.4200 429.0000 1.0000
32.4800 373.0000 1.0000
32.5400 417.0000 1.0000
32.6000 403.0000 1.0000
32.6600 427.0000 1.0000
32.7200 397.0000 1.0000
32.7800 388.0000 1.0000
32.8400 385.0000 1.0000
32.9000 401.0000 1.0000
32.9600 402.0000 1.0000
33.0200 389.0000 1.0000
33.0800 398.0000 1.0000
33.1400 422.0000 1.0000
33.2000 416.0000 1.0000
33.2600 403.0000 1.0000
33.3200 375.0000 1.0000
33.3800 387.0000 1.0000
33.4400 402.0000 1.0000
33.5000 371.0000 1.0000
33.5600 380.0000 1.0000
33.6200 398.0000 1.0000
33.6800 383.0000 1.0000
33.7400 349.0000 1.0000
33.8000 348.0000 1.0000
33.8600 370.0000 1.0000
33.9200 400.0000 1.0000
33.9800 383.0000 1.0000
34.0400 337.0000 1.0000
34.1000 348.0000 1.0000
34.1600 382.0000 1.0000
34.2200 381.0000 1.0000
34.2800 363.0000 1.0000
34.3400 352.0000 1.0000
34.4000 373.0000 1.0000
34.4600 395.0000 1.0000
34.5200 360.0000 1.0000
34.5800 367.0000 1.0000
34.6400 377.0000 1.0000
34.7000 369.0000 1.0000
34.7600 351.0000 1.0000
34.8200 324.0000 1.0000
34.8800 378.0000 1.0000
34.9400 343.0000 1.0000
35.0000 323.0000 1.0000
35.0600 323.0000 1.0000
35.1200 354.0000 1.0000
35.1800 334.0000 1.0000
35.2400 330.0000 1.0000
35.3000 303.0000 1.0000
35.3600 330.0000 1.0000
35.4200 333.0000 1.0000
35.4800 321.0000 1.0000
35.5400 310.0000 1.0000
35.6000 328.0000 1.0000
35.6600 332.0000 1.0000
35.7200 334.0000 1.0000
35.7800 318.0000 1.0000
35.8400 294.0000 1.0000
35.9000 312.0000 1.0000
35.9600 295.0000 1.0000
36.0200 319.0000 1.0000
36.0800 315.0000 1.0000
36.1400 294.0000 1.0000
36.2000 320.0000 1.0000
36.2600 305.0000 1.0000
36.3200 318.0000 1.0000
36.3800 297.0000 1.0000
36.4400 300.0000 1.0000
36.5000 279.0000 1.0000
36.5600 328.0000 1.0000
36.6200 302.0000 1.0000
36.6800 301.0000 1.0000
36.7400 297.0000 1.0000
36.8000 302.0000 1.0000
36.8600 271.0000 1.0000
36.9200 287.0000 1.0000
36.9800 276.0000 1.0000
37.0400 255.0000 1.0000
37.1000 287.0000 1.0000
37.1600 282.0000 1.0000
37.2200 282.0000 1.0000
37.2800 285.0000 1.0000
37.3400 284.0000 1.0000
37.4000 294.0000 1.0000
37.4600 243.0000 1.0000
37.5200 276.0000 1.0000
37.5800 287.0000 1.0000
37.6400 271.0000 1.0000
37.7000 259.0000 1.0000
37.7600 269.0000 1.0000
37.8200 279.0000 1.0000
37.8800 287.0000 1.0000
37.9400 271.0000 1.0000
38.0000 271.0000 1.0000
38.0600 235.0000 1.0000
38.1200 253.0000 1.0000
38.1800 257.0000 1.0000
38.2400 288.0000 1.0000
38.3000 276.0000 1.0000
38.3600 302.0000 1.0000
38.4200 269.0000 1.0000
38.4800 272.0000 1.0000
38.5400 282.0000 1.0000
38.6000 305.0000 1.0000
38.6600 284.0000 1.0000
38.7200 269.0000 1.0000
38.7800 220.0000 1.0000
38.8400 250.0000 1.0000
38.9000 259.0000 1.0000
38.9600 260.0000 1.0000
39.0200 207.0000 1.0000
39.0800 274.0000 1.0000
39.1400 250.0000 1.0000
39.2000 276.0000 1.0000
39.2600 262.0000 1.0000
39.3200 264.0000 1.0000
39.3800 250.0000 1.0000
39.4400 240.0000 1.0000
39.5000 253.0000 1.0000
39.5600 276.0000 1.0000
39.6200 248.0000 1.0000
39.6800 254.0000 1.0000
39.7400 217.0000 1.0000
39.8000 216.0000 1.0000
39.8600 252.0000 1.0000
39.9200 259.0000 1.0000
39.9800 233.0000 1.0000
40.0400 199.0000 1.0000
40.1000 226.0000 1.0000
40.1600 215.0000 1.0000
40.2200 238.0000 1.0000
40.2800 235.0000 1.0000
40.3400 225.0000 1.0000
40.4000 242.0000 1.0000
40.4600 236.0000 1.0000
40.5200 228.0000 1.0000
40.5800 243.0000 1.0000
40.6400 213.0000 1.0000
40.7000 219.0000 1.0000
40.7600 218.0000 1.0000
40.8200 203.0000 1.0000
40.8800 207.0000 1.0000
40.9400 201.0000 1.0000
41.0000 210.0000 1.0000
41.0600 238.0000 1.0000
41.1200 209.0000 1.0000
41.1800 210.0000 1.0000
41.2400 219.0000 1.0000
41.3000 214.0000 1.0000
41.3600 213.0000 1.0000
41.4200 214.0000 1.0000
41.4800 215.0000 1.0000
41.5400 206.0000 1.0000
41.6000 223.0000 1.0000
41.6600 235.0000 1.0000
41.7200 213.0000 1.0000
41.7800 203.0000 1.0000
41.8400 192.0000 1.0000
41.9000 197.0000 1.0000
41.9600 215.0000 1.0000
42.0200 204.0000 1.0000
42.0800 195.0000 1.0000
42.1400 181.0000 1.0000
42.2000 186.0000 1.0000
42.2600 209.0000 1.0000
42.3200 195.0000 1.0000
42.3800 200.0000 1.0000
42.4400 195.0000 1.0000
42.5000 190.0000 1.0000
42.5600 210.0000 1.0000
42.6200 183.0000 1.0000
42.6800 206.0000 1.0000
42.7400 191.0000 1.0000
42.8000 197.0000 1.0000
42.8600 196.0000 1.0000
42.9200 162.0000 1.0000
42.9800 197.0000 1.0000
43.0400 191.0000 1.0000
43.1000 202.0000 1.0000
43.1600 178.0000 1.0000
43.2200 197.0000 1.0000
43.2800 191.0000 1.0000
43.3400 183.0000 1.0000
43.4000 174.0000 1.0000
43.4600 177.0000 1.0000
43.5200 188.0000 1.0000
43.5800 181.0000 1.0000
43.6400 184.0000 1.0000
43.7000 171.0000 1.0000
43.7600 190.0000 1.0000
43.8200 169.0000 1.0000
43.8800 190.0000 1.0000
43.9400 167.0000 1.0000
44.0000 180.0000 1.0000
44.0600 174.0000 1.0000
44.1200 170.0000 1.0000
44.1800 173.0000 1.0000
44.2400 173.0000 1.0000
44.3000 151.0000 1.0000
44.3600 186.0000 1.0000
44.4200 191.0000 1.0000
44.4800 187.0000 1.0000
44.5400 179.0000 1.0000
44.6000 180.0000 1.0000
44.6600 171.0000 1.0000
44.7200 151.0000 1.0000
44.7800 158.0000 1.0000
44.8400 153.0000 1.0000
44.9000 180.0000 1.0000
44.9600 168.0000 1.0000
45.0200 161.0000 1.0000
45.0800 155.0000 1.0000
45.1400 171.0000 1.0000
45.2000 172.0000 1.0000
45.2600 169.0000 1.0000
45.3200 172.0000 1.0000
45.3800 183.0000 1.0000
45.4400 163.0000 1.0000
45.5000 168.0000 1.0000
45.5600 167.0000 1.0000
45.6200 166.0000 1.0000
45.6800 150.0000 1.0000
45.7400 141.0000 1.0000
45.8000 145.0000 1.0000
45.8600 158.0000 1.0000
45.9200 150.0000 1.0000
45.9800 163.0000 1.0000
46.0400 161.0000 1.0000
46.1000 159.0000 1.0000
46.1600 139.0000 1.0000
46.2200 154.0000 1.0000
46.2800 155.0000 1.0000
46.3400 136.0000 1.0000
46.4000 166.0000 1.0000
46.4600 156.0000 1.0000
46.5200 160.0000 1.0000
46.5800 147.0000 1.0000
46.6400 156.0000 1.0000
46.7000 156.0000 1.0000
46.7600 145.0000 1.0000
46.8200 185.0000 1.0000
46.8800 129.0000 1.0000
46.9400 162.0000 1.0000
47.0000 144.0000 1.0000
47.0600 137.0000 1.0000
47.1200 140.0000 1.0000
47.1800 151.0000 1.0000
47.2400 158.0000 1.0000
47.3000 145.0000 1.0000
47.3600 148.0000 1.0000
47.4200 173.0000 1.0000
47.4800 136.0000 1.0000
47.5400 130.0000 1.0000
47.6000 140.0000 1.0000
47.6600 147.0000 1.0000
47.7200 134.0000 1.0000
47.7800 140.0000 1.0000
47.8400 141.0000 1.0000
47.9000 146.0000 1.0000
47.9600 115.0000 1.0000
48.0200 147.0000 1.0000
48.0800 143.0000 1.0000
48.1400 149.0000 1.0000
48.2000 141.0000 1.0000
48.2600 116.0000 1.0000
48.3200 145.0000 1.0000
48.3800 151.0000 1.0000
48.4400 137.0000 1.0000
48.5000 151.0000 1.0000
48.5600 143.0000 1.0000
48.6200 119.0000 1.0000
48.6800 147.0000 1.0000
48.7400 154.0000 1.0000
48.8000 147.0000 1.0000
48.8600 138.0000 1.0000
48.9200 125.0000 1.0000
48.9800 154.0000 1.0000
49.0400 127.0000 1.0000
49.1000 132.0000 1.0000
49.1600 141.0000 1.0000
49.2200 133.0000 1.0000
49.2800 136.0000 1.0000
49.3400 128.0000 1.0000
49.4000 147.0000 1.0000
49.4600 119.0000 1.0000
49.5200 135.0000 1.0000
49.5800 115.0000 1.0000
49.6400 142.0000 1.0000
49.7000 148.0000 1.0000
49.7600 128.0000 1.0000
49.8200 149.0000 1.0000
49.8800 150.0000 1.0000
49.9400 126.0000 1.0000
50.0000 137.0000 1.0000
50.0600 129.0000 1.0000
50.1200 111.0000 1.0000
50.1800 137.0000 1.0000
50.2400 131.0000 1.0000
50.3000 123.0000 1.0000
50.3600 125.0000 1.0000
50.4200 135.0000 1.0000
50.4800 118.0000 1.0000
50.5400 133.0000 1.0000
50.6000 119.0000 1.0000
50.6600 127.0000 1.0000
50.7200 134.0000 1.0000
50.7800 128.0000 1.0000
50.8400 127.0000 1.0000
50.9000 145.0000 1.0000
50.9600 122.0000 1.0000
51.0200 138.0000 1.0000
51.0800 124.0000 1.0000
51.1400 136.0000 1.0000
51.2000 134.0000 1.0000
51.2600 105.0000 1.0000
51.3200 119.0000 1.0000
51.3800 117.0000 1.0000
51.4400 108.0000 1.0000
51.5000 118.0000 1.0000
51.5600 124.0000 1.0000
51.6200 128.0000 1.0000
51.6800 135.0000 1.0000
51.7400 132.0000 1.0000
51.8000 126.0000 1.0000
51.8600 124.0000 1.0000
51.9200 107.0000 1.0000
51.9800 131.0000 1.0000
52.0400 115.0000 1.0000
52.1000 139.0000 1.0000
52.1600 158.0000 1.0000
52.2200 204.0000 1.0000
52.2800 234.0000 1.0000
52.3400 253.0000 1.0000
52.4000 242.0000 1.0000
52.4600 214.0000 1.0000
52.5200 168.0000 1.0000
52.5800 147.0000 1.0000
52.6400 140.0000 1.0000
52.7000 133.0000 1.0000
52.7600 135.0000 1.0000
52.8200 111.0000 1.0000
52.8800 107.0000 1.0000
52.9400 138.0000 1.0000
53.0000 118.0000 1.0000
53.0600 108.0000 1.0000
53.1200 122.0000 1.0000
53.1800 123.0000 1.0000
53.2400 117.0000 1.0000
53.3000 124.0000 1.0000
53.3600 120.0000 1.0000
53.4200 128.0000 1.0000
53.4800 123.0000 1.0000
53.5400 103.0000 1.0000
53.6000 118.0000 1.0000
53.6600 128.0000 1.0000
53.7200 101.0000 1.0000
53.7800 99.0000 1.0000
53.8400 107.0000 1.0000
53.9000 117.0000 1.0000
53.9600 113.0000 1.0000
54.0200 112.0000 1.0000
54.0800 96.0000 1.0000
54.1400 126.0000 1.0000
54.2000 105.0000 1.0000
54.2600 106.0000 1.0000
54.3200 120.0000 1.0000
54.3800 101.0000 1.0000
54.4400 98.0000 1.0000
54.5000 131.0000 1.0000
54.5600 142.0000 1.0000
54.6200 96.0000 1.0000
54.6800 106.0000 1.0000
54.7400 104.0000 1.0000
54.8000 110.0000 1.0000
54.8600 110.0000 1.0000
54.9200 104.0000 1.0000
54.9800 113.0000 1.0000
55.0400 108.0000 1.0000
55.1000 111.0000 1.0000
55.1600 127.0000 1.0000
55.2200 138.0000 1.0000
55.2800 141.0000 1.0000
55.3400 132.0000 1.0000
55.4000 128.0000 1.0000
55.4600 124.0000 1.0000
55.5200 111.0000 1.0000
55.5800 103.0000 1.0000
55.6400 123.0000 1.0000
55.7000 107.0000 1.0000
55.7600 117.0000 1.0000
55.8200 107.0000 1.0000
55.8800 107.0000 1.0000
55.9400 106.0000 1.0000
56.0000 108.0000 1.0000
56.0600 110.0000 1.0000
56.1200 102.0000 1.0000
56.1800 104.0000 1.0000
56.2400 98.0000 1.0000
56.3000 119.0000 1.0000
56.3600 133.0000 1.0000
56.4200 111.0000 1.0000
56.4800 99.0000 1.0000
56.5400 119.0000 1.0000
56.6000 100.0000 1.0000
56.6600 82.0000 1.0000
56.7200 100.0000 1.0000
56.7800 109.0000 1.0000
56.8400 106.0000 1.0000
56.9000 112.0000 1.0000
56.9600 116.0000 1.0000
57.0200 94.0000 1.0000
57.0800 98.0000 1.0000
57.1400 107.0000 1.0000
57.2000 108.0000 1.0000
57.2600 100.0000 1.0000
57.3200 73.0000 1.0000
57.3800 111.0000 1.0000
57.4400 87.0000 1.0000
57.5000 105.0000 1.0000
57.5600 115.0000 1.0000
57.6200 111.0000 1.0000
57.6800 104.0000 1.0000
57.7400 105.0000 1.0000
57.8000 100.0000 1.0000
57.8600 102.0000 1.0000
57.9200 83.0000 1.0000
57.9800 93.0000 1.0000
58.0400 114.0000 1.0000
58.1000 104.0000 1.0000
58.1600 87.0000 1.0000
58.2200 114.0000 1.0000
58.2800 104.0000 1.0000
58.3400 103.0000 1.0000
58.4000 105.0000 1.0000
58.4600 103.0000 1.0000
58.5200 102.0000 1.0000
58.5800 82.0000 1.0000
58.6400 116.0000 1.0000
58.7000 118.0000 1.0000
58.7600 113.0000 1.0000
58.8200 100.0000 1.0000
58.8800 98.0000 1.0000
58.9400 100.0000 1.0000
59.0000 97.0000 1.0000
59.0600 94.0000 1.0000
59.1200 98.0000 1.0000
59.1800 108.0000 1.0000
59.2400 89.0000 1.0000
59.3000 106.0000 1.0000
59.3600 107.0000 1.0000
59.4200 102.0000 1.0000
59.4800 97.0000 1.0000
59.5400 121.0000 1.0000
59.6000 90.0000 1.0000
59.6600 99.0000 1.0000
59.7200 87.0000 1.0000
59.7800 102.0000 1.0000
59.8400 101.0000 1.0000
59.9000 114.0000 1.0000
59.9600 94.0000 1.0000
60.0200 90.0000 1.0000
60.0800 89.0000 1.0000
60.1400 100.0000 1.0000
60.2000 83.0000 1.0000
60.2600 99.0000 1.0000
60.3200 85.0000 1.0000
60.3800 93.0000 1.0000
60.4400 109.0000 1.0000
60.5000 107.0000 1.0000
60.5600 94.0000 1.0000
60.6200 91.0000 1.0000
60.6800 95.0000 1.0000
60.7400 100.0000 1.0000
60.8000 94.0000 1.0000
60.8600 101.0000 1.0000
60.9200 92.0000 1.0000
60.9800 93.0000 1.0000
61.0400 94.0000 1.0000
61.1000 107.0000 1.0000
61.1600 98.0000 1.0000
61.2200 107.0000 1.0000
61.2800 92.0000 1.0000
61.3400 110.0000 1.0000
61.4000 89.0000 1.0000
61.4600 95.0000 1.0000
61.5200 106.0000 1.0000
61.5800 94.0000 1.0000
61.6400 82.0000 1.0000
61.7000 98.0000 1.0000
61.7600 76.0000 1.0000
61.8200 99.0000 1.0000
61.8800 101.0000 1.0000
61.9400 90.0000 1.0000
62.0000 101.0000 1.0000
62.0600 102.0000 1.0000
62.1200 99.0000 1.0000
62.1800 115.0000 1.0000
62.2400 129.0000 1.0000
62.3000 132.0000 1.0000
62.3600 106.0000 1.0000
62.4200 115.0000 1.0000
62.4800 116.0000 1.0000
62.5400 123.0000 1.0000
62.6000 121.0000 1.0000
62.6600 130.0000 1.0000
62.7200 102.0000 1.0000
62.7800 93.0000 1.0000
62.8400 92.0000 1.0000
62.9000 98.0000 1.0000
62.9600 89.0000 1.0000
63.0200 95.0000 1.0000
63.0800 94.0000 1.0000
63.1400 84.0000 1.0000
63.2000 88.0000 1.0000
63.2600 79.0000 1.0000
63.3200 90.0000 1.0000
63.3800 78.0000 1.0000
63.4400 104.0000 1.0000
63.5000 106.0000 1.0000
63.5600 93.0000 1.0000
63.6200 99.0000 1.0000
63.6800 106.0000 1.0000
63.7400 100.0000 1.0000
63.8000 101.0000 1.0000
63.8600 74.0000 1.0000
63.9200 97.0000 1.0000
63.9800 83.0000 1.0000
64.0400 87.0000 1.0000
64.1000 93.0000 1.0000
64.1600 85.0000 1.0000
64.2200 73.0000 1.0000
64.2800 80.0000 1.0000
64.3400 97.0000 1.0000
64.4000 88.0000 1.0000
64.4600 97.0000 1.0000
64.5200 98.0000 1.0000
64.5800 86.0000 1.0000
64.6400 116.0000 1.0000
64.7000 123.0000 1.0000
64.7600 106.0000 1.0000
64.8200 104.0000 1.0000
64.8800 108.0000 1.0000
64.9400 110.0000 1.0000
65.0000 99.0000 1.0000
65.0600 95.0000 1.0000
65.1200 89.0000 1.0000
65.1800 98.0000 1.0000
65.2400 108.0000 1.0000
65.3000 109.0000 1.0000
65.3600 102.0000 1.0000
65.4200 82.0000 1.0000
65.4800 94.0000 1.0000
65.5400 103.0000 1.0000
65.6000 88.0000 1.0000
65.6600 91.0000 1.0000
65.7200 81.0000 1.0000
65.7800 88.0000 1.0000
65.8400 95.0000 1.0000
65.9000 66.0000 1.0000
65.9600 92.0000 1.0000
66.0200 101.0000 1.0000
66.0800 110.0000 1.0000
66.1400 134.0000 1.0000
66.2000 124.0000 1.0000
66.2600 170.0000 1.0000
66.3200 168.0000 1.0000
66.3800 161.0000 1.0000
66.4400 157.0000 1.0000
66.5000 167.0000 1.0000
66.5600 135.0000 1.0000
66.6200 119.0000 1.0000
66.6800 103.0000 1.0000
66.7400 91.0000 1.0000
66.8000 88.0000 1.0000
66.8600 82.0000 1.0000
66.9200 88.0000 1.0000
66.9800 95.0000 1.0000
67.0400 92.0000 1.0000
67.1000 74.0000 1.0000
67.1600 74.0000 1.0000
67.2200 89.0000 1.0000
67.2800 74.0000 1.0000
67.3400 82.0000 1.0000
67.4000 80.0000 1.0000
67.4600 80.0000 1.0000
67.5200 89.0000 1.0000
67.5800 94.0000 1.0000
67.6400 80.0000 1.0000
67.7000 85.0000 1.0000
67.7600 80.0000 1.0000
67.8200 88.0000 1.0000
67.8800 68.0000 1.0000
67.9400 70.0000 1.0000
68.0000 78.0000 1.0000
68.0600 98.0000 1.0000
68.1200 80.0000 1.0000
68.1800 81.0000 1.0000
68.2400 80.0000 1.0000
68.3000 95.0000 1.0000
68.3600 73.0000 1.0000
68.4200 80.0000 1.0000
68.4800 88.0000 1.0000
68.5400 97.0000 1.0000
68.6000 90.0000 1.0000
68.6600 83.0000 1.0000
68.7200 87.0000 1.0000
68.7800 88.0000 1.0000
68.8400 81.0000 1.0000
68.9000 88.0000 1.0000
68.9600 76.0000 1.0000
69.0200 88.0000 1.0000
69.0800 89.0000 1.0000
69.1400 85.0000 1.0000
69.2000 76.0000 1.0000
69.2600 98.0000 1.0000
69.3200 88.0000 1.0000
69.3800 69.0000 1.0000
69.4400 77.0000 1.0000
69.5000 86.0000 1.0000
69.5600 96.0000 1.0000
69.6200 76.0000 1.0000
69.6800 86.0000 1.0000
69.7400 79.0000 1.0000
69.8000 89.0000 1.0000
69.8600 91.0000 1.0000
69.9200 68.0000 1.0000
69.9800 97.0000 1.0000
70.0400 99.0000 1.0000
70.1000 75.0000 1.0000
70.1600 74.0000 1.0000
70.2200 93.0000 1.0000
70.2800 83.0000 1.0000
70.3400 76.0000 1.0000
70.4000 85.0000 1.0000
70.4600 72.0000 1.0000
70.5200 80.0000 1.0000
70.5800 92.0000 1.0000
70.6400 77.0000 1.0000
70.7000 81.0000 1.0000
70.7600 83.0000 1.0000
70.8200 78.0000 1.0000
70.8800 81.0000 1.0000
70.9400 86.0000 1.0000
71.0000 94.0000 1.0000
71.0600 87.0000 1.0000
71.1200 75.0000 1.0000
71.1800 75.0000 1.0000
71.2400 78.0000 1.0000
71.3000 92.0000 1.0000
71.3600 74.0000 1.0000
71.4200 80.0000 1.0000
71.4800 87.0000 1.0000
71.5400 81.0000 1.0000
71.6000 76.0000 1.0000
71.6600 88.0000 1.0000
71.7200 100.0000 1.0000
71.7800 83.0000 1.0000
71.8400 90.0000 1.0000
71.9000 87.0000 1.0000
71.9600 106.0000 1.0000
72.0200 68.0000 1.0000
72.0800 78.0000 1.0000
72.1400 63.0000 1.0000
72.2000 81.0000 1.0000
72.2600 71.0000 1.0000
72.3200 90.0000 1.0000
72.3800 84.0000 1.0000
72.4400 77.0000 1.0000
72.5000 66.0000 1.0000
72.5600 77.0000 1.0000
72.6200 94.0000 1.0000
72.6800 83.0000 1.0000
72.7400 79.0000 1.0000
72.8000 89.0000 1.0000
72.8600 72.0000 1.0000
72.9200 92.0000 1.0000
72.9800 80.0000 1.0000
73.0400 69.0000 1.0000
73.1000 74.0000 1.0000
73.1600 77.0000 1.0000
73.2200 74.0000 1.0000
73.2800 79.0000 1.0000
73.3400 93.0000 1.0000
73.4000 86.0000 1.0000
73.4600 80.0000 1.0000
73.5200 80.0000 1.0000
73.5800 88.0000 1.0000
73.6400 65.0000 1.0000
73.7000 90.0000 1.0000
73.7600 83.0000 1.0000
73.8200 73.0000 1.0000
73.8800 82.0000 1.0000
73.9400 90.0000 1.0000
74.0000 75.0000 1.0000
74.0600 79.0000 1.0000
74.1200 76.0000 1.0000
74.1800 98.0000 1.0000
74.2400 77.0000 1.0000
74.3000 70.0000 1.0000
74.3600 79.0000 1.0000
74.4200 80.0000 1.0000
74.4800 89.0000 1.0000
74.5400 83.0000 1.0000
74.6000 73.0000 1.0000
74.6600 62.0000 1.0000
74.7200 81.0000 1.0000
74.7800 74.0000 1.0000
74.8400 63.0000 1.0000
74.9000 65.0000 1.0000
74.9600 83.0000 1.0000
75.0200 67.0000 1.0000
75.0800 101.0000 1.0000
75.1400 87.0000 1.0000
75.2000 69.0000 1.0000
75.2600 63.0000 1.0000
75.3200 82.0000 1.0000
75.3800 60.0000 1.0000
75.4400 65.0000 1.0000
75.5000 69.0000 1.0000
75.5600 77.0000 1.0000
75.6200 79.0000 1.0000
75.6800 85.0000 1.0000
75.7400 86.0000 1.0000
75.8000 73.0000 1.0000
75.8600 72.0000 1.0000
75.9200 68.0000 1.0000
75.9800 85.0000 1.0000
76.0400 90.0000 1.0000
76.1000 72.0000 1.0000
76.1600 66.0000 1.0000
76.2200 90.0000 1.0000
76.2800 82.0000 1.0000
76.3400 80.0000 1.0000
76.4000 74.0000 1.0000
76.4600 77.0000 1.0000
76.5200 71.0000 1.0000
76.5800 75.0000 1.0000
76.6400 79.0000 1.0000
76.7000 65.0000 1.0000
76.7600 83.0000 1.0000
76.8200 79.0000 1.0000
76.8800 67.0000 1.0000
76.9400 82.0000 1.0000
77.0000 77.0000 1.0000
77.0600 83.0000 1.0000
77.1200 74.0000 1.0000
77.1800 78.0000 1.0000
77.2400 72.0000 1.0000
77.3000 83.0000 1.0000
77.3600 81.0000 1.0000
77.4200 83.0000 1.0000
77.4800 88.0000 1.0000
77.5400 82.0000 1.0000
77.6000 78.0000 1.0000
77.6600 84.0000 1.0000
77.7200 80.0000 1.0000
77.7800 94.0000 1.0000
77.8400 85.0000 1.0000
77.9000 91.0000 1.0000
77.9600 83.0000 1.0000
78.0200 88.0000 1.0000
78.0800 81.0000 1.0000
78.1400 72.0000 1.0000
78.2000 86.0000 1.0000
78.2600 78.0000 1.0000
78.3200 66.0000 1.0000
78.3800 78.0000 1.0000
78.4400 67.0000 1.0000
78.5000 72.0000 1.0000
78.5600 85.0000 1.0000
78.6200 88.0000 1.0000
78.6800 73.0000 1.0000
78.7400 81.0000 1.0000
78.8000 58.0000 1.0000
78.8600 90.0000 1.0000
78.9200 105.0000 1.0000
78.9800 103.0000 1.0000
79.0400 93.0000 1.0000
79.1000 90.0000 1.0000
79.1600 93.0000 1.0000
79.2200 123.0000 1.0000
79.2800 105.0000 1.0000
79.3400 100.0000 1.0000
79.4000 68.0000 1.0000
79.4600 95.0000 1.0000
79.5200 74.0000 1.0000
79.5800 79.0000 1.0000
79.6400 85.0000 1.0000
79.7000 69.0000 1.0000
79.7600 86.0000 1.0000
79.8200 88.0000 1.0000
79.8800 75.0000 1.0000
79.9400 71.0000 1.0000
80.0000 95.0000 1.0000
*RAS_INT_END
*RAS_TEMPERATURE_START
*RAS_TEMPERATURE_END
*RAS_DATA_END