File: Section2_75_samples/XRD/No_052_NSS2_1.ras
*RAS_DATA_START
*RAS_HEADER_START
*DISP_FMT_X "%.2f"
*DISP_FMT_Y "%.0f"
*DISP_FULLSCALE "14482.0000000000"
*DISP_LINE_COLOR "255.0000000000"
*DISP_LINE_STYLE "0.0000000000"
*DISP_LINE_WIDTH "0.2500000000"
*DISP_NOTE "測定データ-8"
*DISP_OFFSET_Y "0.0000000000"
*DISP_PEAKSEARCH_UNIT_Y "cps"
*DISP_RANGE_BOTTOM "0.0000000000"
*DISP_RANGE_LEFT "20.0000000000"
*DISP_RANGE_LOGCUTOFF "0.0100000000"
*DISP_RANGE_RIGHT "70.0000000000"
*DISP_RANGE_TOP "14482.0000000000"
*DISP_SCALE_MODE_Y "0.0000000000"
*DISP_TAB_NAME "2θ/θ"
*DISP_TITLE_Y "強度"
*DISP_UNIT_Y "cps"
*DISP_WINDOW_NAME "MSG_MACROENGINE"
*FILE_COMMENT " "
*FILE_MD5 ""
*FILE_MEMO " "
*FILE_OPERATOR "Administrator"
*FILE_SAMPLE " "
*FILE_TYPE "RAS_RAW"
*FILE_USERGROUP "システムマネージャ"
*FILE_VERSION "1.0000000000"
*HW_ATTACHMENT_ID "ATT0025"
*HW_ATTACHMENT_NAME "標準|Standard"
*HW_COUNTER_ID-0 "CUT0025"
*HW_COUNTER_ID-1 "CUT0020"
*HW_COUNTER_ID-2 "CUT0020"
*HW_COUNTER_ID-3 "CSL0021"
*HW_COUNTER_ID-4 "CMC0021"
*HW_COUNTER_NAME-0 "D/teX Ultra|D/teX Ultra"
*HW_COUNTER_NAME-1 "None|None"
*HW_COUNTER_NAME-2 "None|None"
*HW_COUNTER_NAME-3 "BBM|BBM"
*HW_COUNTER_NAME-4 "検出器モノクロメータ|Detector monochromator"
*HW_COUNTER_SELECT_NAME "D/teX Ultra|D/teX Ultra"
*HW_GONIOMETER_ID "GON0023"
*HW_GONIOMETER_NAME "SmartLab|SmartLab"
*HW_GONIOMETER_RADIUS-0 "90.0"
*HW_GONIOMETER_RADIUS-1 "114.0"
*HW_GONIOMETER_RADIUS-2 "190.0"
*HW_GONIOMETER_RADIUS-3 "300.0"
*HW_GONIOMETER_RADIUS-4 "187.0"
*HW_GONIOMETER_RADIUS-5 "300.0"
*HW_GONIOMETER_RADIUS-6 "113.0"
*HW_GONIOMETER_RADIUS-7 "331.0"
*HW_I_OPT_ID-0 "CBO0021"
*HW_I_OPT_ID-1 "ICR0023"
*HW_I_OPT_ID-2 "ISL0021"
*HW_I_OPT_ID-3 "ISO0021"
*HW_I_OPT_ID-4 "IAD0021"
*HW_I_OPT_ID-5 "IPR0001"
*HW_I_OPT_NAME-0 "CBOユニット|CBO unit"
*HW_I_OPT_NAME-1 "標準入射光学ユニット|Standard incident optical unit"
*HW_I_OPT_NAME-2 "標準入射スリットボックス|Standard incident slit box"
*HW_I_OPT_NAME-3 "入射平行スリット|Incident parallel slit"
*HW_I_OPT_NAME-4 "長手制限スリット|Length limiting slit"
*HW_I_OPT_NAME-5 "None|None"
*HW_R_ATTENUATER_AUTOMODE "0"
*HW_R_OPT_ID-0 "RSS0021"
*HW_R_OPT_ID-1 "RCR0023"
*HW_R_OPT_ID-2 "RSO0021"
*HW_R_OPT_ID-3 "RRS0021"
*HW_R_OPT_ID-4 "ATN0021"
*HW_R_OPT_ID-5 "RFL0021"
*HW_R_OPT_ID-6 "RAD0021"
*HW_R_OPT_NAME-0 "標準受光スリットボックス1|Standard receiving slit box # 1"
*HW_R_OPT_NAME-1 "標準受光光学ユニット1|Standard receiving unit # 1"
*HW_R_OPT_NAME-2 "標準受光光学ユニット2|Standard receiving optical unit # 2"
*HW_R_OPT_NAME-3 "標準受光スリットボックス2|Standard receiving slit box # 2"
*HW_R_OPT_NAME-4 "標準アッテネータ|Standard Attenuator"
*HW_R_OPT_NAME-5 "Cu Kβ|Cu K-beta"
*HW_R_OPT_NAME-6 "調整用受光スリット|Alignment receiving slit"
*HW_SAMPLE_HOLDER_ID "SMP0023"
*HW_SAMPLE_HOLDER_NAME "標準Zステージ|Standard Z stage"
*HW_XG_CURRENT_MAX "50"
*HW_XG_CURRENT_MIN "2"
*HW_XG_CURRENT_RESOLUTION "1"
*HW_XG_CURRENT_UNIT "mA"
*HW_XG_FOCUS "1mm x 10mm"
*HW_XG_FOCUS_TYPE "Normal"
*HW_XG_ID ""
*HW_XG_NAME "3kW 封入管(ID:1200)|3kW Sealed tube(ID:1200)"
*HW_XG_TARGET_ATOMIC_NUMBER "29.0000000000"
*HW_XG_TARGET_NAME "Cu"
*HW_XG_TYPE "Hermetic"
*HW_XG_VOLTAGE_MAX "60"
*HW_XG_VOLTAGE_MIN "20"
*HW_XG_VOLTAGE_RESOLUTION "1"
*HW_XG_VOLTAGE_UNIT "kV"
*HW_XG_WATT_MAX "1.500"
*HW_XG_WATT_UNIT "kW"
*HW_XG_WAVE_LENGTH_ALPHA1 "1.540593"
*HW_XG_WAVE_LENGTH_ALPHA2 "1.544414"
*HW_XG_WAVE_LENGTH_BETA "1.392250"
*MEAS_COND_AXIS_NAME-0 "2θ/θ"
*MEAS_COND_AXIS_NAME-1 "2θ"
*MEAS_COND_AXIS_NAME-2 "ω"
*MEAS_COND_AXIS_NAME-3 "Z"
*MEAS_COND_AXIS_NAME-4 "2θ/ω"
*MEAS_COND_AXIS_NAME-5 "θs"
*MEAS_COND_AXIS_NAME-6 "θd"
*MEAS_COND_AXIS_NAME-7 "Ts"
*MEAS_COND_AXIS_NAME-8 "CBO選択スリット"
*MEAS_COND_AXIS_NAME-9 "M"
*MEAS_COND_AXIS_NAME-10 "入射平行スリット"
*MEAS_COND_AXIS_NAME-11 "入射スリット"
*MEAS_COND_AXIS_NAME-12 ""
*MEAS_COND_AXIS_NAME-13 "Zs"
*MEAS_COND_AXIS_NAME-14 "入射光学素子"
*MEAS_COND_AXIS_NAME-15 "長手制限スリット"
*MEAS_COND_AXIS_NAME-16 "センタースリット"
*MEAS_COND_AXIS_NAME-17 "フィルター"
*MEAS_COND_AXIS_NAME-18 "受光スリット1"
*MEAS_COND_AXIS_NAME-19 "受光スリット2"
*MEAS_COND_AXIS_NAME-20 "受光光学素子"
*MEAS_COND_AXIS_NAME-21 "受光平行スリット"
*MEAS_COND_AXIS_NAME-22 "調整用受光スリット"
*MEAS_COND_AXIS_NAME-23 ""
*MEAS_COND_AXIS_NAME-24 ""
*MEAS_COND_AXIS_NAME-25 "Zd"
*MEAS_COND_AXIS_NAME-26 "アッテネータ"
*MEAS_COND_AXIS_NAME-27 "検出器モノクロメータ"
*MEAS_COND_AXIS_NAME-28 "モノクロメータスリット"
*MEAS_COND_AXIS_NAME-29 "プライマリビーム"
*MEAS_COND_AXIS_NAME-30 "PHA"
*MEAS_COND_AXIS_NAME_INTERNAL-0 "TwoThetaTheta"
*MEAS_COND_AXIS_NAME_INTERNAL-1 "TwoTheta"
*MEAS_COND_AXIS_NAME_INTERNAL-2 "Omega"
*MEAS_COND_AXIS_NAME_INTERNAL-3 "Z"
*MEAS_COND_AXIS_NAME_INTERNAL-4 "TwoThetaOmega"
*MEAS_COND_AXIS_NAME_INTERNAL-5 "ThetaS"
*MEAS_COND_AXIS_NAME_INTERNAL-6 "ThetaD"
*MEAS_COND_AXIS_NAME_INTERNAL-7 "Ts"
*MEAS_COND_AXIS_NAME_INTERNAL-8 "CBO"
*MEAS_COND_AXIS_NAME_INTERNAL-9 "CBO-M"
*MEAS_COND_AXIS_NAME_INTERNAL-10 "IncidentSollerSlit"
*MEAS_COND_AXIS_NAME_INTERNAL-11 "IncidentSlitBox"
*MEAS_COND_AXIS_NAME_INTERNAL-12 "IncidentSlitBox-_Axis"
*MEAS_COND_AXIS_NAME_INTERNAL-13 "Zs"
*MEAS_COND_AXIS_NAME_INTERNAL-14 "IncidentMonochromator"
*MEAS_COND_AXIS_NAME_INTERNAL-15 "IncidentAxdSlit"
*MEAS_COND_AXIS_NAME_INTERNAL-16 "CenterSlit"
*MEAS_COND_AXIS_NAME_INTERNAL-17 "Filter"
*MEAS_COND_AXIS_NAME_INTERNAL-18 "ReceivingSlitBox1"
*MEAS_COND_AXIS_NAME_INTERNAL-19 "ReceivingSlitBox2"
*MEAS_COND_AXIS_NAME_INTERNAL-20 "ReceivingOptics"
*MEAS_COND_AXIS_NAME_INTERNAL-21 "ReceivingSollerSlit"
*MEAS_COND_AXIS_NAME_INTERNAL-22 "ReceivingAxdSlit"
*MEAS_COND_AXIS_NAME_INTERNAL-23 "ReceivingSlitBox1-_Axis"
*MEAS_COND_AXIS_NAME_INTERNAL-24 "ReceivingSlitBox2-_Axis"
*MEAS_COND_AXIS_NAME_INTERNAL-25 "ReceivingSlitBox2-Zd"
*MEAS_COND_AXIS_NAME_INTERNAL-26 "Attenuator"
*MEAS_COND_AXIS_NAME_INTERNAL-27 "CounterMonochromator"
*MEAS_COND_AXIS_NAME_INTERNAL-28 "CounterSlit"
*MEAS_COND_AXIS_NAME_INTERNAL-29 "IncidentPrimary"
*MEAS_COND_AXIS_NAME_INTERNAL-30 "PHA"
*MEAS_COND_AXIS_NAME_MAGICNO-0 "83951616.0000000000"
*MEAS_COND_AXIS_NAME_MAGICNO-1 "268632064.0000000000"
*MEAS_COND_AXIS_NAME_MAGICNO-2 "268500992.0000000000"
*MEAS_COND_AXIS_NAME_MAGICNO-3 "285278208.0000000000"
*MEAS_COND_AXIS_NAME_MAGICNO-4 "83951616.0000000000"
*MEAS_COND_AXIS_NAME_MAGICNO-5 "131072.0000000000"
*MEAS_COND_AXIS_NAME_MAGICNO-6 "131072.0000000000"
*MEAS_COND_AXIS_NAME_MAGICNO-7 "318898176.0000000000"
*MEAS_COND_AXIS_NAME_MAGICNO-8 "20971521.0000000000"
*MEAS_COND_AXIS_NAME_MAGICNO-9 "285343744.0000000000"
*MEAS_COND_AXIS_NAME_MAGICNO-10 "20971521.0000000000"
*MEAS_COND_AXIS_NAME_MAGICNO-11 "22020097.0000000000"
*MEAS_COND_AXIS_NAME_MAGICNO-12 "25165824.0000000000"
*MEAS_COND_AXIS_NAME_MAGICNO-13 "318898176.0000000000"
*MEAS_COND_AXIS_NAME_MAGICNO-14 "1.0000000000"
*MEAS_COND_AXIS_NAME_MAGICNO-15 "20971521.0000000000"
*MEAS_COND_AXIS_NAME_MAGICNO-16 "20971521.0000000000"
*MEAS_COND_AXIS_NAME_MAGICNO-17 "20971521.0000000000"
*MEAS_COND_AXIS_NAME_MAGICNO-18 "23068673.0000000000"
*MEAS_COND_AXIS_NAME_MAGICNO-19 "23068673.0000000000"
*MEAS_COND_AXIS_NAME_MAGICNO-20 "20971521.0000000000"
*MEAS_COND_AXIS_NAME_MAGICNO-21 "20971521.0000000000"
*MEAS_COND_AXIS_NAME_MAGICNO-22 "20971521.0000000000"
*MEAS_COND_AXIS_NAME_MAGICNO-23 "25165824.0000000000"
*MEAS_COND_AXIS_NAME_MAGICNO-24 "25165824.0000000000"
*MEAS_COND_AXIS_NAME_MAGICNO-25 "285343744.0000000000"
*MEAS_COND_AXIS_NAME_MAGICNO-26 "17301505.0000000000"
*MEAS_COND_AXIS_NAME_MAGICNO-27 "20971521.0000000000"
*MEAS_COND_AXIS_NAME_MAGICNO-28 "20971521.0000000000"
*MEAS_COND_AXIS_NAME_MAGICNO-29 "20971521.0000000000"
*MEAS_COND_AXIS_NAME_MAGICNO-30 "0.0000000000"
*MEAS_COND_AXIS_OFFSET-0 "-"
*MEAS_COND_AXIS_OFFSET-1 "-0.1081000000"
*MEAS_COND_AXIS_OFFSET-2 "0.3758000000"
*MEAS_COND_AXIS_OFFSET-3 "-"
*MEAS_COND_AXIS_OFFSET-4 "-"
*MEAS_COND_AXIS_OFFSET-5 "0.3758000000"
*MEAS_COND_AXIS_OFFSET-6 "-0.4839000000"
*MEAS_COND_AXIS_OFFSET-7 "-"
*MEAS_COND_AXIS_OFFSET-8 "-"
*MEAS_COND_AXIS_OFFSET-9 "-"
*MEAS_COND_AXIS_OFFSET-10 "-"
*MEAS_COND_AXIS_OFFSET-11 "-"
*MEAS_COND_AXIS_OFFSET-12 "-"
*MEAS_COND_AXIS_OFFSET-13 "-"
*MEAS_COND_AXIS_OFFSET-14 "-"
*MEAS_COND_AXIS_OFFSET-15 "-"
*MEAS_COND_AXIS_OFFSET-16 "-"
*MEAS_COND_AXIS_OFFSET-17 "-"
*MEAS_COND_AXIS_OFFSET-18 "-"
*MEAS_COND_AXIS_OFFSET-19 "-"
*MEAS_COND_AXIS_OFFSET-20 "-"
*MEAS_COND_AXIS_OFFSET-21 "-"
*MEAS_COND_AXIS_OFFSET-22 "-"
*MEAS_COND_AXIS_OFFSET-23 "-"
*MEAS_COND_AXIS_OFFSET-24 "-"
*MEAS_COND_AXIS_OFFSET-25 "-"
*MEAS_COND_AXIS_OFFSET-26 "-"
*MEAS_COND_AXIS_OFFSET-27 "-"
*MEAS_COND_AXIS_OFFSET-28 "-"
*MEAS_COND_AXIS_OFFSET-29 "-"
*MEAS_COND_AXIS_OFFSET-30 "-"
*MEAS_COND_AXIS_POSITION-0 "0.0000000000"
*MEAS_COND_AXIS_POSITION-1 "0.0000000000"
*MEAS_COND_AXIS_POSITION-2 "0.0000000000"
*MEAS_COND_AXIS_POSITION-3 "-0.5500000000"
*MEAS_COND_AXIS_POSITION-4 "0.0000000000"
*MEAS_COND_AXIS_POSITION-5 "0.0000000000"
*MEAS_COND_AXIS_POSITION-6 "0.0000000000"
*MEAS_COND_AXIS_POSITION-7 "-0.4278800000"
*MEAS_COND_AXIS_POSITION-8 "BB"
*MEAS_COND_AXIS_POSITION-9 "0.0000000000"
*MEAS_COND_AXIS_POSITION-10 "Soller_slit_5.0deg"
*MEAS_COND_AXIS_POSITION-11 "2/3deg"
*MEAS_COND_AXIS_POSITION-12 "2.2088000000"
*MEAS_COND_AXIS_POSITION-13 "-0.4140600000"
*MEAS_COND_AXIS_POSITION-14 "0.0000000000"
*MEAS_COND_AXIS_POSITION-15 "10.0mm"
*MEAS_COND_AXIS_POSITION-16 "None"
*MEAS_COND_AXIS_POSITION-17 "Cu_K-beta"
*MEAS_COND_AXIS_POSITION-18 "13.000mm"
*MEAS_COND_AXIS_POSITION-19 "13.000mm"
*MEAS_COND_AXIS_POSITION-20 "No_unit"
*MEAS_COND_AXIS_POSITION-21 "Soller_slit_5.0deg"
*MEAS_COND_AXIS_POSITION-22 "None"
*MEAS_COND_AXIS_POSITION-23 "13.0000000000"
*MEAS_COND_AXIS_POSITION-24 "13.0000000000"
*MEAS_COND_AXIS_POSITION-25 "0.0109400000"
*MEAS_COND_AXIS_POSITION-26 "Open"
*MEAS_COND_AXIS_POSITION-27 "None"
*MEAS_COND_AXIS_POSITION-28 "None"
*MEAS_COND_AXIS_POSITION-29 "None"
*MEAS_COND_AXIS_POSITION-30 "38.0000000000"
*MEAS_COND_AXIS_UNIT-0 "deg"
*MEAS_COND_AXIS_UNIT-1 "deg"
*MEAS_COND_AXIS_UNIT-2 "deg"
*MEAS_COND_AXIS_UNIT-3 "mm"
*MEAS_COND_AXIS_UNIT-4 "deg"
*MEAS_COND_AXIS_UNIT-5 "deg"
*MEAS_COND_AXIS_UNIT-6 "deg"
*MEAS_COND_AXIS_UNIT-7 "mm"
*MEAS_COND_AXIS_UNIT-8 ""
*MEAS_COND_AXIS_UNIT-9 "pulse"
*MEAS_COND_AXIS_UNIT-10 ""
*MEAS_COND_AXIS_UNIT-11 ""
*MEAS_COND_AXIS_UNIT-12 "mm"
*MEAS_COND_AXIS_UNIT-13 "mm"
*MEAS_COND_AXIS_UNIT-14 ""
*MEAS_COND_AXIS_UNIT-15 ""
*MEAS_COND_AXIS_UNIT-16 ""
*MEAS_COND_AXIS_UNIT-17 ""
*MEAS_COND_AXIS_UNIT-18 ""
*MEAS_COND_AXIS_UNIT-19 ""
*MEAS_COND_AXIS_UNIT-20 ""
*MEAS_COND_AXIS_UNIT-21 ""
*MEAS_COND_AXIS_UNIT-22 ""
*MEAS_COND_AXIS_UNIT-23 "mm"
*MEAS_COND_AXIS_UNIT-24 "mm"
*MEAS_COND_AXIS_UNIT-25 "mm"
*MEAS_COND_AXIS_UNIT-26 ""
*MEAS_COND_AXIS_UNIT-27 ""
*MEAS_COND_AXIS_UNIT-28 ""
*MEAS_COND_AXIS_UNIT-29 ""
*MEAS_COND_AXIS_UNIT-30 "div"
*MEAS_COND_COUNTER_CNTLOSS_CORR "0.0000000000"
*MEAS_COND_COUNTER_PHABASE "38.0000000000"
*MEAS_COND_COUNTER_PHAWINDOW "16.0000000000"
*MEAS_COND_COUNTER_PHA_UNIT "div"
*MEAS_COND_COUNTER_TAUDIFF "30.0000000000"
*MEAS_COND_COUNTER_TAUINT "0.0000000000"
*MEAS_COND_IRRADIATION_MODE "OFF"
*MEAS_COND_IRRADIATION_WIDTH ""
*MEAS_COND_OPT_ATTR "集中法"
*MEAS_COND_OPT_NAME "@集中法"
*MEAS_COND_UNSYMMETRIC_MODE "OFF"
*MEAS_COND_XG_CURRENT "30.0000000000"
*MEAS_COND_XG_VOLTAGE "40.0000000000"
*MEAS_COND_XG_WAVE_TYPE "Ka"
*MEAS_DATA_COUNT "5001.0000000000"
*MEAS_SCAN_AXIS_X "2θ/θ"
*MEAS_SCAN_AXIS_X_INTERNAL "TwoThetaTheta"
*MEAS_SCAN_END_TIME "07/12/21 15:07:02"
*MEAS_SCAN_MODE "CONTINUOUS"
*MEAS_SCAN_MONITOR "0"
*MEAS_SCAN_RESOLUTION_X "0.0002"
*MEAS_SCAN_SPEED "1.0"
*MEAS_SCAN_SPEED_UNIT "deg/min"
*MEAS_SCAN_START "20.0000000000"
*MEAS_SCAN_START_TIME "07/12/21 14:14:08"
*MEAS_SCAN_STEP "0.0100000000"
*MEAS_SCAN_STOP "70.0000000000"
*MEAS_SCAN_UNIT_X "deg"
*MEAS_SCAN_UNIT_Y "counts"
*RAS_HEADER_END
*RAS_INT_START
20.0000 1600.0000 1.0000
20.0400 1622.0000 1.0000
20.0800 1537.0000 1.0000
20.1200 1597.0000 1.0000
20.1600 1614.0000 1.0000
20.2000 1543.0000 1.0000
20.2400 1647.0000 1.0000
20.2800 1586.0000 1.0000
20.3200 1540.0000 1.0000
20.3600 1546.0000 1.0000
20.4000 1559.0000 1.0000
20.4400 1583.0000 1.0000
20.4800 1587.0000 1.0000
20.5200 1586.0000 1.0000
20.5600 1620.0000 1.0000
20.6000 1620.0000 1.0000
20.6400 1538.0000 1.0000
20.6800 1666.0000 1.0000
20.7200 1653.0000 1.0000
20.7600 1624.0000 1.0000
20.8000 1635.0000 1.0000
20.8400 1660.0000 1.0000
20.8800 1564.0000 1.0000
20.9200 1629.0000 1.0000
20.9600 1584.0000 1.0000
21.0000 1632.0000 1.0000
21.0400 1661.0000 1.0000
21.0800 1621.0000 1.0000
21.1200 1629.0000 1.0000
21.1600 1594.0000 1.0000
21.2000 1573.0000 1.0000
21.2400 1673.0000 1.0000
21.2800 1617.0000 1.0000
21.3200 1640.0000 1.0000
21.3600 1604.0000 1.0000
21.4000 1633.0000 1.0000
21.4400 1576.0000 1.0000
21.4800 1563.0000 1.0000
21.5200 1610.0000 1.0000
21.5600 1625.0000 1.0000
21.6000 1509.0000 1.0000
21.6400 1559.0000 1.0000
21.6800 1617.0000 1.0000
21.7200 1595.0000 1.0000
21.7600 1684.0000 1.0000
21.8000 1630.0000 1.0000
21.8400 1622.0000 1.0000
21.8800 1671.0000 1.0000
21.9200 1562.0000 1.0000
21.9600 1551.0000 1.0000
22.0000 1673.0000 1.0000
22.0400 1609.0000 1.0000
22.0800 1632.0000 1.0000
22.1200 1609.0000 1.0000
22.1600 1652.0000 1.0000
22.2000 1608.0000 1.0000
22.2400 1602.0000 1.0000
22.2800 1650.0000 1.0000
22.3200 1570.0000 1.0000
22.3600 1605.0000 1.0000
22.4000 1675.0000 1.0000
22.4400 1636.0000 1.0000
22.4800 1619.0000 1.0000
22.5200 1644.0000 1.0000
22.5600 1616.0000 1.0000
22.6000 1646.0000 1.0000
22.6400 1652.0000 1.0000
22.6800 1686.0000 1.0000
22.7200 1637.0000 1.0000
22.7600 1609.0000 1.0000
22.8000 1733.0000 1.0000
22.8400 1649.0000 1.0000
22.8800 1667.0000 1.0000
22.9200 1592.0000 1.0000
22.9600 1681.0000 1.0000
23.0000 1611.0000 1.0000
23.0400 1639.0000 1.0000
23.0800 1628.0000 1.0000
23.1200 1656.0000 1.0000
23.1600 1606.0000 1.0000
23.2000 1709.0000 1.0000
23.2400 1666.0000 1.0000
23.2800 1638.0000 1.0000
23.3200 1696.0000 1.0000
23.3600 1747.0000 1.0000
23.4000 1593.0000 1.0000
23.4400 1645.0000 1.0000
23.4800 1681.0000 1.0000
23.5200 1671.0000 1.0000
23.5600 1639.0000 1.0000
23.6000 1727.0000 1.0000
23.6400 1618.0000 1.0000
23.6800 1642.0000 1.0000
23.7200 1655.0000 1.0000
23.7600 1598.0000 1.0000
23.8000 1654.0000 1.0000
23.8400 1627.0000 1.0000
23.8800 1671.0000 1.0000
23.9200 1707.0000 1.0000
23.9600 1711.0000 1.0000
24.0000 1662.0000 1.0000
24.0400 1637.0000 1.0000
24.0800 1696.0000 1.0000
24.1200 1682.0000 1.0000
24.1600 1664.0000 1.0000
24.2000 1642.0000 1.0000
24.2400 1666.0000 1.0000
24.2800 1696.0000 1.0000
24.3200 1661.0000 1.0000
24.3600 1624.0000 1.0000
24.4000 1724.0000 1.0000
24.4400 1753.0000 1.0000
24.4800 1758.0000 1.0000
24.5200 1714.0000 1.0000
24.5600 1674.0000 1.0000
24.6000 1716.0000 1.0000
24.6400 1765.0000 1.0000
24.6800 1716.0000 1.0000
24.7200 1774.0000 1.0000
24.7600 1779.0000 1.0000
24.8000 1765.0000 1.0000
24.8400 1717.0000 1.0000
24.8800 1767.0000 1.0000
24.9200 1784.0000 1.0000
24.9600 1706.0000 1.0000
25.0000 1724.0000 1.0000
25.0400 1761.0000 1.0000
25.0800 1784.0000 1.0000
25.1200 1793.0000 1.0000
25.1600 1870.0000 1.0000
25.2000 1762.0000 1.0000
25.2400 1740.0000 1.0000
25.2800 1726.0000 1.0000
25.3200 1777.0000 1.0000
25.3600 1779.0000 1.0000
25.4000 1747.0000 1.0000
25.4400 1727.0000 1.0000
25.4800 1755.0000 1.0000
25.5200 1786.0000 1.0000
25.5600 1818.0000 1.0000
25.6000 1761.0000 1.0000
25.6400 1729.0000 1.0000
25.6800 1713.0000 1.0000
25.7200 1679.0000 1.0000
25.7600 1695.0000 1.0000
25.8000 1757.0000 1.0000
25.8400 1769.0000 1.0000
25.8800 1728.0000 1.0000
25.9200 1732.0000 1.0000
25.9600 1746.0000 1.0000
26.0000 1751.0000 1.0000
26.0400 1683.0000 1.0000
26.0800 1760.0000 1.0000
26.1200 1763.0000 1.0000
26.1600 1714.0000 1.0000
26.2000 1771.0000 1.0000
26.2400 1754.0000 1.0000
26.2800 1768.0000 1.0000
26.3200 1763.0000 1.0000
26.3600 1815.0000 1.0000
26.4000 1758.0000 1.0000
26.4400 1802.0000 1.0000
26.4800 1784.0000 1.0000
26.5200 1876.0000 1.0000
26.5600 1815.0000 1.0000
26.6000 1803.0000 1.0000
26.6400 1800.0000 1.0000
26.6800 1906.0000 1.0000
26.7200 1887.0000 1.0000
26.7600 1905.0000 1.0000
26.8000 1873.0000 1.0000
26.8400 1977.0000 1.0000
26.8800 2053.0000 1.0000
26.9200 2132.0000 1.0000
26.9600 2137.0000 1.0000
27.0000 2271.0000 1.0000
27.0400 2455.0000 1.0000
27.0800 2690.0000 1.0000
27.1200 3030.0000 1.0000
27.1600 3473.0000 1.0000
27.2000 4189.0000 1.0000
27.2400 5037.0000 1.0000
27.2800 5919.0000 1.0000
27.3200 6215.0000 1.0000
27.3600 5994.0000 1.0000
27.4000 4932.0000 1.0000
27.4400 4106.0000 1.0000
27.4800 3478.0000 1.0000
27.5200 2876.0000 1.0000
27.5600 2552.0000 1.0000
27.6000 2413.0000 1.0000
27.6400 2136.0000 1.0000
27.6800 2052.0000 1.0000
27.7200 1967.0000 1.0000
27.7600 1977.0000 1.0000
27.8000 1922.0000 1.0000
27.8400 1798.0000 1.0000
27.8800 1894.0000 1.0000
27.9200 1823.0000 1.0000
27.9600 1832.0000 1.0000
28.0000 1768.0000 1.0000
28.0400 1767.0000 1.0000
28.0800 1723.0000 1.0000
28.1200 1733.0000 1.0000
28.1600 1669.0000 1.0000
28.2000 1648.0000 1.0000
28.2400 1651.0000 1.0000
28.2800 1579.0000 1.0000
28.3200 1712.0000 1.0000
28.3600 1667.0000 1.0000
28.4000 1632.0000 1.0000
28.4400 1665.0000 1.0000
28.4800 1580.0000 1.0000
28.5200 1599.0000 1.0000
28.5600 1592.0000 1.0000
28.6000 1631.0000 1.0000
28.6400 1619.0000 1.0000
28.6800 1700.0000 1.0000
28.7200 1662.0000 1.0000
28.7600 1536.0000 1.0000
28.8000 1649.0000 1.0000
28.8400 1577.0000 1.0000
28.8800 1497.0000 1.0000
28.9200 1666.0000 1.0000
28.9600 1653.0000 1.0000
29.0000 1575.0000 1.0000
29.0400 1533.0000 1.0000
29.0800 1589.0000 1.0000
29.1200 1596.0000 1.0000
29.1600 1626.0000 1.0000
29.2000 1630.0000 1.0000
29.2400 1519.0000 1.0000
29.2800 1577.0000 1.0000
29.3200 1516.0000 1.0000
29.3600 1591.0000 1.0000
29.4000 1518.0000 1.0000
29.4400 1520.0000 1.0000
29.4800 1640.0000 1.0000
29.5200 1546.0000 1.0000
29.5600 1478.0000 1.0000
29.6000 1512.0000 1.0000
29.6400 1552.0000 1.0000
29.6800 1519.0000 1.0000
29.7200 1520.0000 1.0000
29.7600 1569.0000 1.0000
29.8000 1522.0000 1.0000
29.8400 1522.0000 1.0000
29.8800 1538.0000 1.0000
29.9200 1583.0000 1.0000
29.9600 1574.0000 1.0000
30.0000 1538.0000 1.0000
30.0400 1546.0000 1.0000
30.0800 1492.0000 1.0000
30.1200 1518.0000 1.0000
30.1600 1419.0000 1.0000
30.2000 1493.0000 1.0000
30.2400 1460.0000 1.0000
30.2800 1481.0000 1.0000
30.3200 1482.0000 1.0000
30.3600 1474.0000 1.0000
30.4000 1501.0000 1.0000
30.4400 1477.0000 1.0000
30.4800 1491.0000 1.0000
30.5200 1476.0000 1.0000
30.5600 1488.0000 1.0000
30.6000 1498.0000 1.0000
30.6400 1472.0000 1.0000
30.6800 1370.0000 1.0000
30.7200 1445.0000 1.0000
30.7600 1462.0000 1.0000
30.8000 1456.0000 1.0000
30.8400 1464.0000 1.0000
30.8800 1488.0000 1.0000
30.9200 1447.0000 1.0000
30.9600 1426.0000 1.0000
31.0000 1428.0000 1.0000
31.0400 1443.0000 1.0000
31.0800 1427.0000 1.0000
31.1200 1408.0000 1.0000
31.1600 1447.0000 1.0000
31.2000 1483.0000 1.0000
31.2400 1442.0000 1.0000
31.2800 1496.0000 1.0000
31.3200 1452.0000 1.0000
31.3600 1460.0000 1.0000
31.4000 1421.0000 1.0000
31.4400 1420.0000 1.0000
31.4800 1435.0000 1.0000
31.5200 1464.0000 1.0000
31.5600 1364.0000 1.0000
31.6000 1444.0000 1.0000
31.6400 1469.0000 1.0000
31.6800 1309.0000 1.0000
31.7200 1361.0000 1.0000
31.7600 1401.0000 1.0000
31.8000 1439.0000 1.0000
31.8400 1390.0000 1.0000
31.8800 1397.0000 1.0000
31.9200 1464.0000 1.0000
31.9600 1543.0000 1.0000
32.0000 1452.0000 1.0000
32.0400 1460.0000 1.0000
32.0800 1441.0000 1.0000
32.1200 1388.0000 1.0000
32.1600 1449.0000 1.0000
32.2000 1417.0000 1.0000
32.2400 1371.0000 1.0000
32.2800 1403.0000 1.0000
32.3200 1423.0000 1.0000
32.3600 1366.0000 1.0000
32.4000 1392.0000 1.0000
32.4400 1363.0000 1.0000
32.4800 1398.0000 1.0000
32.5200 1386.0000 1.0000
32.5600 1364.0000 1.0000
32.6000 1325.0000 1.0000
32.6400 1316.0000 1.0000
32.6800 1333.0000 1.0000
32.7200 1338.0000 1.0000
32.7600 1388.0000 1.0000
32.8000 1360.0000 1.0000
32.8400 1349.0000 1.0000
32.8800 1383.0000 1.0000
32.9200 1375.0000 1.0000
32.9600 1318.0000 1.0000
33.0000 1328.0000 1.0000
33.0400 1383.0000 1.0000
33.0800 1376.0000 1.0000
33.1200 1340.0000 1.0000
33.1600 1359.0000 1.0000
33.2000 1285.0000 1.0000
33.2400 1361.0000 1.0000
33.2800 1335.0000 1.0000
33.3200 1306.0000 1.0000
33.3600 1383.0000 1.0000
33.4000 1310.0000 1.0000
33.4400 1374.0000 1.0000
33.4800 1363.0000 1.0000
33.5200 1305.0000 1.0000
33.5600 1312.0000 1.0000
33.6000 1372.0000 1.0000
33.6400 1351.0000 1.0000
33.6800 1366.0000 1.0000
33.7200 1431.0000 1.0000
33.7600 1389.0000 1.0000
33.8000 1396.0000 1.0000
33.8400 1474.0000 1.0000
33.8800 1412.0000 1.0000
33.9200 1494.0000 1.0000
33.9600 1517.0000 1.0000
34.0000 1480.0000 1.0000
34.0400 1486.0000 1.0000
34.0800 1512.0000 1.0000
34.1200 1514.0000 1.0000
34.1600 1507.0000 1.0000
34.2000 1478.0000 1.0000
34.2400 1576.0000 1.0000
34.2800 1669.0000 1.0000
34.3200 1749.0000 1.0000
34.3600 1933.0000 1.0000
34.4000 2214.0000 1.0000
34.4400 2488.0000 1.0000
34.4800 2725.0000 1.0000
34.5200 2757.0000 1.0000
34.5600 2688.0000 1.0000
34.6000 2456.0000 1.0000
34.6400 2255.0000 1.0000
34.6800 1943.0000 1.0000
34.7200 1754.0000 1.0000
34.7600 1681.0000 1.0000
34.8000 1578.0000 1.0000
34.8400 1504.0000 1.0000
34.8800 1367.0000 1.0000
34.9200 1378.0000 1.0000
34.9600 1312.0000 1.0000
35.0000 1242.0000 1.0000
35.0400 1283.0000 1.0000
35.0800 1299.0000 1.0000
35.1200 1254.0000 1.0000
35.1600 1298.0000 1.0000
35.2000 1226.0000 1.0000
35.2400 1287.0000 1.0000
35.2800 1229.0000 1.0000
35.3200 1230.0000 1.0000
35.3600 1252.0000 1.0000
35.4000 1195.0000 1.0000
35.4400 1216.0000 1.0000
35.4800 1186.0000 1.0000
35.5200 1223.0000 1.0000
35.5600 1142.0000 1.0000
35.6000 1146.0000 1.0000
35.6400 1171.0000 1.0000
35.6800 1212.0000 1.0000
35.7200 1206.0000 1.0000
35.7600 1164.0000 1.0000
35.8000 1165.0000 1.0000
35.8400 1137.0000 1.0000
35.8800 1170.0000 1.0000
35.9200 1205.0000 1.0000
35.9600 1140.0000 1.0000
36.0000 1170.0000 1.0000
36.0400 1210.0000 1.0000
36.0800 1193.0000 1.0000
36.1200 1234.0000 1.0000
36.1600 1322.0000 1.0000
36.2000 1333.0000 1.0000
36.2400 1478.0000 1.0000
36.2800 1640.0000 1.0000
36.3200 1794.0000 1.0000
36.3600 1977.0000 1.0000
36.4000 2079.0000 1.0000
36.4400 2133.0000 1.0000
36.4800 1958.0000 1.0000
36.5200 1972.0000 1.0000
36.5600 1687.0000 1.0000
36.6000 1593.0000 1.0000
36.6400 1455.0000 1.0000
36.6800 1274.0000 1.0000
36.7200 1192.0000 1.0000
36.7600 1185.0000 1.0000
36.8000 1144.0000 1.0000
36.8400 1118.0000 1.0000
36.8800 1130.0000 1.0000
36.9200 1136.0000 1.0000
36.9600 1127.0000 1.0000
37.0000 1034.0000 1.0000
37.0400 1068.0000 1.0000
37.0800 1086.0000 1.0000
37.1200 1020.0000 1.0000
37.1600 1050.0000 1.0000
37.2000 1071.0000 1.0000
37.2400 1170.0000 1.0000
37.2800 1106.0000 1.0000
37.3200 1069.0000 1.0000
37.3600 1112.0000 1.0000
37.4000 1143.0000 1.0000
37.4400 1086.0000 1.0000
37.4800 1067.0000 1.0000
37.5200 1069.0000 1.0000
37.5600 1080.0000 1.0000
37.6000 1070.0000 1.0000
37.6400 1070.0000 1.0000
37.6800 1063.0000 1.0000
37.7200 1106.0000 1.0000
37.7600 1082.0000 1.0000
37.8000 1113.0000 1.0000
37.8400 1045.0000 1.0000
37.8800 1138.0000 1.0000
37.9200 1136.0000 1.0000
37.9600 1183.0000 1.0000
38.0000 1161.0000 1.0000
38.0400 1184.0000 1.0000
38.0800 1258.0000 1.0000
38.1200 1352.0000 1.0000
38.1600 1371.0000 1.0000
38.2000 1402.0000 1.0000
38.2400 1594.0000 1.0000
38.2800 1802.0000 1.0000
38.3200 2182.0000 1.0000
38.3600 2605.0000 1.0000
38.4000 3232.0000 1.0000
38.4400 4272.0000 1.0000
38.4800 5535.0000 1.0000
38.5200 6778.0000 1.0000
38.5600 7070.0000 1.0000
38.6000 6712.0000 1.0000
38.6400 5932.0000 1.0000
38.6800 4817.0000 1.0000
38.7200 3724.0000 1.0000
38.7600 2806.0000 1.0000
38.8000 2358.0000 1.0000
38.8400 1806.0000 1.0000
38.8800 1573.0000 1.0000
38.9200 1441.0000 1.0000
38.9600 1259.0000 1.0000
39.0000 1237.0000 1.0000
39.0400 1149.0000 1.0000
39.0800 1101.0000 1.0000
39.1200 1118.0000 1.0000
39.1600 1119.0000 1.0000
39.2000 1042.0000 1.0000
39.2400 1017.0000 1.0000
39.2800 1003.0000 1.0000
39.3200 996.0000 1.0000
39.3600 1016.0000 1.0000
39.4000 1014.0000 1.0000
39.4400 1007.0000 1.0000
39.4800 1023.0000 1.0000
39.5200 1036.0000 1.0000
39.5600 1018.0000 1.0000
39.6000 991.0000 1.0000
39.6400 976.0000 1.0000
39.6800 1011.0000 1.0000
39.7200 952.0000 1.0000
39.7600 980.0000 1.0000
39.8000 974.0000 1.0000
39.8400 962.0000 1.0000
39.8800 919.0000 1.0000
39.9200 908.0000 1.0000
39.9600 924.0000 1.0000
40.0000 887.0000 1.0000
40.0400 889.0000 1.0000
40.0800 929.0000 1.0000
40.1200 916.0000 1.0000
40.1600 877.0000 1.0000
40.2000 903.0000 1.0000
40.2400 936.0000 1.0000
40.2800 929.0000 1.0000
40.3200 895.0000 1.0000
40.3600 956.0000 1.0000
40.4000 941.0000 1.0000
40.4400 954.0000 1.0000
40.4800 880.0000 1.0000
40.5200 899.0000 1.0000
40.5600 957.0000 1.0000
40.6000 927.0000 1.0000
40.6400 934.0000 1.0000
40.6800 881.0000 1.0000
40.7200 873.0000 1.0000
40.7600 882.0000 1.0000
40.8000 942.0000 1.0000
40.8400 906.0000 1.0000
40.8800 932.0000 1.0000
40.9200 910.0000 1.0000
40.9600 885.0000 1.0000
41.0000 878.0000 1.0000
41.0400 888.0000 1.0000
41.0800 895.0000 1.0000
41.1200 895.0000 1.0000
41.1600 888.0000 1.0000
41.2000 861.0000 1.0000
41.2400 846.0000 1.0000
41.2800 901.0000 1.0000
41.3200 890.0000 1.0000
41.3600 873.0000 1.0000
41.4000 889.0000 1.0000
41.4400 911.0000 1.0000
41.4800 909.0000 1.0000
41.5200 949.0000 1.0000
41.5600 906.0000 1.0000
41.6000 908.0000 1.0000
41.6400 899.0000 1.0000
41.6800 952.0000 1.0000
41.7200 941.0000 1.0000
41.7600 892.0000 1.0000
41.8000 914.0000 1.0000
41.8400 878.0000 1.0000
41.8800 868.0000 1.0000
41.9200 914.0000 1.0000
41.9600 885.0000 1.0000
42.0000 855.0000 1.0000
42.0400 888.0000 1.0000
42.0800 875.0000 1.0000
42.1200 890.0000 1.0000
42.1600 880.0000 1.0000
42.2000 886.0000 1.0000
42.2400 871.0000 1.0000
42.2800 845.0000 1.0000
42.3200 884.0000 1.0000
42.3600 846.0000 1.0000
42.4000 864.0000 1.0000
42.4400 856.0000 1.0000
42.4800 834.0000 1.0000
42.5200 893.0000 1.0000
42.5600 897.0000 1.0000
42.6000 872.0000 1.0000
42.6400 861.0000 1.0000
42.6800 880.0000 1.0000
42.7200 857.0000 1.0000
42.7600 889.0000 1.0000
42.8000 879.0000 1.0000
42.8400 948.0000 1.0000
42.8800 850.0000 1.0000
42.9200 857.0000 1.0000
42.9600 902.0000 1.0000
43.0000 884.0000 1.0000
43.0400 865.0000 1.0000
43.0800 893.0000 1.0000
43.1200 919.0000 1.0000
43.1600 920.0000 1.0000
43.2000 938.0000 1.0000
43.2400 984.0000 1.0000
43.2800 954.0000 1.0000
43.3200 911.0000 1.0000
43.3600 967.0000 1.0000
43.4000 950.0000 1.0000
43.4400 946.0000 1.0000
43.4800 913.0000 1.0000
43.5200 898.0000 1.0000
43.5600 838.0000 1.0000
43.6000 853.0000 1.0000
43.6400 875.0000 1.0000
43.6800 866.0000 1.0000
43.7200 903.0000 1.0000
43.7600 854.0000 1.0000
43.8000 882.0000 1.0000
43.8400 831.0000 1.0000
43.8800 810.0000 1.0000
43.9200 858.0000 1.0000
43.9600 832.0000 1.0000
44.0000 819.0000 1.0000
44.0400 824.0000 1.0000
44.0800 868.0000 1.0000
44.1200 841.0000 1.0000
44.1600 812.0000 1.0000
44.2000 792.0000 1.0000
44.2400 844.0000 1.0000
44.2800 870.0000 1.0000
44.3200 868.0000 1.0000
44.3600 870.0000 1.0000
44.4000 861.0000 1.0000
44.4400 846.0000 1.0000
44.4800 828.0000 1.0000
44.5200 852.0000 1.0000
44.5600 854.0000 1.0000
44.6000 811.0000 1.0000
44.6400 812.0000 1.0000
44.6800 867.0000 1.0000
44.7200 786.0000 1.0000
44.7600 838.0000 1.0000
44.8000 827.0000 1.0000
44.8400 846.0000 1.0000
44.8800 832.0000 1.0000
44.9200 829.0000 1.0000
44.9600 791.0000 1.0000
45.0000 865.0000 1.0000
45.0400 811.0000 1.0000
45.0800 889.0000 1.0000
45.1200 830.0000 1.0000
45.1600 796.0000 1.0000
45.2000 849.0000 1.0000
45.2400 827.0000 1.0000
45.2800 827.0000 1.0000
45.3200 865.0000 1.0000
45.3600 762.0000 1.0000
45.4000 836.0000 1.0000
45.4400 816.0000 1.0000
45.4800 813.0000 1.0000
45.5200 839.0000 1.0000
45.5600 825.0000 1.0000
45.6000 809.0000 1.0000
45.6400 827.0000 1.0000
45.6800 868.0000 1.0000
45.7200 803.0000 1.0000
45.7600 824.0000 1.0000
45.8000 820.0000 1.0000
45.8400 818.0000 1.0000
45.8800 789.0000 1.0000
45.9200 779.0000 1.0000
45.9600 872.0000 1.0000
46.0000 798.0000 1.0000
46.0400 800.0000 1.0000
46.0800 841.0000 1.0000
46.1200 742.0000 1.0000
46.1600 754.0000 1.0000
46.2000 795.0000 1.0000
46.2400 814.0000 1.0000
46.2800 768.0000 1.0000
46.3200 807.0000 1.0000
46.3600 772.0000 1.0000
46.4000 778.0000 1.0000
46.4400 760.0000 1.0000
46.4800 807.0000 1.0000
46.5200 803.0000 1.0000
46.5600 774.0000 1.0000
46.6000 776.0000 1.0000
46.6400 772.0000 1.0000
46.6800 806.0000 1.0000
46.7200 789.0000 1.0000
46.7600 826.0000 1.0000
46.8000 810.0000 1.0000
46.8400 798.0000 1.0000
46.8800 801.0000 1.0000
46.9200 800.0000 1.0000
46.9600 787.0000 1.0000
47.0000 785.0000 1.0000
47.0400 814.0000 1.0000
47.0800 805.0000 1.0000
47.1200 789.0000 1.0000
47.1600 816.0000 1.0000
47.2000 793.0000 1.0000
47.2400 773.0000 1.0000
47.2800 806.0000 1.0000
47.3200 728.0000 1.0000
47.3600 767.0000 1.0000
47.4000 792.0000 1.0000
47.4400 734.0000 1.0000
47.4800 785.0000 1.0000
47.5200 738.0000 1.0000
47.5600 767.0000 1.0000
47.6000 772.0000 1.0000
47.6400 802.0000 1.0000
47.6800 799.0000 1.0000
47.7200 804.0000 1.0000
47.7600 788.0000 1.0000
47.8000 827.0000 1.0000
47.8400 808.0000 1.0000
47.8800 780.0000 1.0000
47.9200 775.0000 1.0000
47.9600 760.0000 1.0000
48.0000 750.0000 1.0000
48.0400 782.0000 1.0000
48.0800 784.0000 1.0000
48.1200 792.0000 1.0000
48.1600 805.0000 1.0000
48.2000 790.0000 1.0000
48.2400 775.0000 1.0000
48.2800 754.0000 1.0000
48.3200 786.0000 1.0000
48.3600 740.0000 1.0000
48.4000 804.0000 1.0000
48.4400 743.0000 1.0000
48.4800 778.0000 1.0000
48.5200 737.0000 1.0000
48.5600 751.0000 1.0000
48.6000 750.0000 1.0000
48.6400 762.0000 1.0000
48.6800 736.0000 1.0000
48.7200 790.0000 1.0000
48.7600 716.0000 1.0000
48.8000 793.0000 1.0000
48.8400 742.0000 1.0000
48.8800 732.0000 1.0000
48.9200 777.0000 1.0000
48.9600 740.0000 1.0000
49.0000 764.0000 1.0000
49.0400 775.0000 1.0000
49.0800 763.0000 1.0000
49.1200 762.0000 1.0000
49.1600 743.0000 1.0000
49.2000 794.0000 1.0000
49.2400 710.0000 1.0000
49.2800 784.0000 1.0000
49.3200 751.0000 1.0000
49.3600 779.0000 1.0000
49.4000 738.0000 1.0000
49.4400 739.0000 1.0000
49.4800 764.0000 1.0000
49.5200 727.0000 1.0000
49.5600 745.0000 1.0000
49.6000 782.0000 1.0000
49.6400 715.0000 1.0000
49.6800 810.0000 1.0000
49.7200 784.0000 1.0000
49.7600 793.0000 1.0000
49.8000 720.0000 1.0000
49.8400 748.0000 1.0000
49.8800 739.0000 1.0000
49.9200 793.0000 1.0000
49.9600 734.0000 1.0000
50.0000 725.0000 1.0000
50.0400 753.0000 1.0000
50.0800 775.0000 1.0000
50.1200 807.0000 1.0000
50.1600 758.0000 1.0000
50.2000 809.0000 1.0000
50.2400 807.0000 1.0000
50.2800 780.0000 1.0000
50.3200 761.0000 1.0000
50.3600 729.0000 1.0000
50.4000 747.0000 1.0000
50.4400 737.0000 1.0000
50.4800 769.0000 1.0000
50.5200 761.0000 1.0000
50.5600 774.0000 1.0000
50.6000 747.0000 1.0000
50.6400 741.0000 1.0000
50.6800 734.0000 1.0000
50.7200 780.0000 1.0000
50.7600 749.0000 1.0000
50.8000 728.0000 1.0000
50.8400 773.0000 1.0000
50.8800 760.0000 1.0000
50.9200 743.0000 1.0000
50.9600 775.0000 1.0000
51.0000 726.0000 1.0000
51.0400 761.0000 1.0000
51.0800 752.0000 1.0000
51.1200 788.0000 1.0000
51.1600 735.0000 1.0000
51.2000 717.0000 1.0000
51.2400 782.0000 1.0000
51.2800 787.0000 1.0000
51.3200 728.0000 1.0000
51.3600 723.0000 1.0000
51.4000 771.0000 1.0000
51.4400 776.0000 1.0000
51.4800 832.0000 1.0000
51.5200 780.0000 1.0000
51.5600 732.0000 1.0000
51.6000 797.0000 1.0000
51.6400 777.0000 1.0000
51.6800 796.0000 1.0000
51.7200 781.0000 1.0000
51.7600 829.0000 1.0000
51.8000 854.0000 1.0000
51.8400 907.0000 1.0000
51.8800 887.0000 1.0000
51.9200 930.0000 1.0000
51.9600 1019.0000 1.0000
52.0000 1128.0000 1.0000
52.0400 1186.0000 1.0000
52.0800 1430.0000 1.0000
52.1200 1774.0000 1.0000
52.1600 2284.0000 1.0000
52.2000 3012.0000 1.0000
52.2400 3997.0000 1.0000
52.2800 4659.0000 1.0000
52.3200 4457.0000 1.0000
52.3600 3986.0000 1.0000
52.4000 3709.0000 1.0000
52.4400 3151.0000 1.0000
52.4800 2494.0000 1.0000
52.5200 1927.0000 1.0000
52.5600 1488.0000 1.0000
52.6000 1307.0000 1.0000
52.6400 1192.0000 1.0000
52.6800 1129.0000 1.0000
52.7200 979.0000 1.0000
52.7600 935.0000 1.0000
52.8000 862.0000 1.0000
52.8400 808.0000 1.0000
52.8800 834.0000 1.0000
52.9200 805.0000 1.0000
52.9600 756.0000 1.0000
53.0000 782.0000 1.0000
53.0400 809.0000 1.0000
53.0800 813.0000 1.0000
53.1200 750.0000 1.0000
53.1600 814.0000 1.0000
53.2000 787.0000 1.0000
53.2400 747.0000 1.0000
53.2800 750.0000 1.0000
53.3200 773.0000 1.0000
53.3600 729.0000 1.0000
53.4000 765.0000 1.0000
53.4400 723.0000 1.0000
53.4800 760.0000 1.0000
53.5200 742.0000 1.0000
53.5600 719.0000 1.0000
53.6000 686.0000 1.0000
53.6400 812.0000 1.0000
53.6800 775.0000 1.0000
53.7200 724.0000 1.0000
53.7600 745.0000 1.0000
53.8000 766.0000 1.0000
53.8400 763.0000 1.0000
53.8800 716.0000 1.0000
53.9200 709.0000 1.0000
53.9600 727.0000 1.0000
54.0000 732.0000 1.0000
54.0400 736.0000 1.0000
54.0800 751.0000 1.0000
54.1200 763.0000 1.0000
54.1600 732.0000 1.0000
54.2000 729.0000 1.0000
54.2400 735.0000 1.0000
54.2800 701.0000 1.0000
54.3200 697.0000 1.0000
54.3600 714.0000 1.0000
54.4000 751.0000 1.0000
54.4400 755.0000 1.0000
54.4800 705.0000 1.0000
54.5200 721.0000 1.0000
54.5600 693.0000 1.0000
54.6000 741.0000 1.0000
54.6400 781.0000 1.0000
54.6800 727.0000 1.0000
54.7200 756.0000 1.0000
54.7600 780.0000 1.0000
54.8000 754.0000 1.0000
54.8400 805.0000 1.0000
54.8800 761.0000 1.0000
54.9200 808.0000 1.0000
54.9600 806.0000 1.0000
55.0000 811.0000 1.0000
55.0400 792.0000 1.0000
55.0800 859.0000 1.0000
55.1200 879.0000 1.0000
55.1600 902.0000 1.0000
55.2000 963.0000 1.0000
55.2400 1062.0000 1.0000
55.2800 1072.0000 1.0000
55.3200 1118.0000 1.0000
55.3600 1098.0000 1.0000
55.4000 1050.0000 1.0000
55.4400 1049.0000 1.0000
55.4800 949.0000 1.0000
55.5200 888.0000 1.0000
55.5600 872.0000 1.0000
55.6000 793.0000 1.0000
55.6400 818.0000 1.0000
55.6800 798.0000 1.0000
55.7200 800.0000 1.0000
55.7600 741.0000 1.0000
55.8000 780.0000 1.0000
55.8400 737.0000 1.0000
55.8800 746.0000 1.0000
55.9200 743.0000 1.0000
55.9600 747.0000 1.0000
56.0000 797.0000 1.0000
56.0400 671.0000 1.0000
56.0800 718.0000 1.0000
56.1200 697.0000 1.0000
56.1600 683.0000 1.0000
56.2000 749.0000 1.0000
56.2400 740.0000 1.0000
56.2800 731.0000 1.0000
56.3200 735.0000 1.0000
56.3600 742.0000 1.0000
56.4000 722.0000 1.0000
56.4400 721.0000 1.0000
56.4800 734.0000 1.0000
56.5200 695.0000 1.0000
56.5600 730.0000 1.0000
56.6000 740.0000 1.0000
56.6400 704.0000 1.0000
56.6800 674.0000 1.0000
56.7200 728.0000 1.0000
56.7600 707.0000 1.0000
56.8000 675.0000 1.0000
56.8400 690.0000 1.0000
56.8800 680.0000 1.0000
56.9200 690.0000 1.0000
56.9600 658.0000 1.0000
57.0000 716.0000 1.0000
57.0400 710.0000 1.0000
57.0800 706.0000 1.0000
57.1200 697.0000 1.0000
57.1600 718.0000 1.0000
57.2000 737.0000 1.0000
57.2400 718.0000 1.0000
57.2800 716.0000 1.0000
57.3200 697.0000 1.0000
57.3600 717.0000 1.0000
57.4000 752.0000 1.0000
57.4400 658.0000 1.0000
57.4800 667.0000 1.0000
57.5200 678.0000 1.0000
57.5600 713.0000 1.0000
57.6000 677.0000 1.0000
57.6400 731.0000 1.0000
57.6800 721.0000 1.0000
57.7200 697.0000 1.0000
57.7600 708.0000 1.0000
57.8000 718.0000 1.0000
57.8400 689.0000 1.0000
57.8800 738.0000 1.0000
57.9200 679.0000 1.0000
57.9600 745.0000 1.0000
58.0000 728.0000 1.0000
58.0400 730.0000 1.0000
58.0800 695.0000 1.0000
58.1200 718.0000 1.0000
58.1600 678.0000 1.0000
58.2000 746.0000 1.0000
58.2400 711.0000 1.0000
58.2800 717.0000 1.0000
58.3200 760.0000 1.0000
58.3600 728.0000 1.0000
58.4000 726.0000 1.0000
58.4400 736.0000 1.0000
58.4800 662.0000 1.0000
58.5200 726.0000 1.0000
58.5600 734.0000 1.0000
58.6000 677.0000 1.0000
58.6400 650.0000 1.0000
58.6800 731.0000 1.0000
58.7200 697.0000 1.0000
58.7600 705.0000 1.0000
58.8000 686.0000 1.0000
58.8400 669.0000 1.0000
58.8800 696.0000 1.0000
58.9200 730.0000 1.0000
58.9600 751.0000 1.0000
59.0000 723.0000 1.0000
59.0400 700.0000 1.0000
59.0800 661.0000 1.0000
59.1200 709.0000 1.0000
59.1600 754.0000 1.0000
59.2000 736.0000 1.0000
59.2400 660.0000 1.0000
59.2800 692.0000 1.0000
59.3200 722.0000 1.0000
59.3600 714.0000 1.0000
59.4000 698.0000 1.0000
59.4400 706.0000 1.0000
59.4800 714.0000 1.0000
59.5200 673.0000 1.0000
59.5600 699.0000 1.0000
59.6000 666.0000 1.0000
59.6400 680.0000 1.0000
59.6800 701.0000 1.0000
59.7200 706.0000 1.0000
59.7600 678.0000 1.0000
59.8000 689.0000 1.0000
59.8400 654.0000 1.0000
59.8800 689.0000 1.0000
59.9200 723.0000 1.0000
59.9600 708.0000 1.0000
60.0000 723.0000 1.0000
60.0400 674.0000 1.0000
60.0800 701.0000 1.0000
60.1200 733.0000 1.0000
60.1600 700.0000 1.0000
60.2000 711.0000 1.0000
60.2400 697.0000 1.0000
60.2800 728.0000 1.0000
60.3200 678.0000 1.0000
60.3600 687.0000 1.0000
60.4000 723.0000 1.0000
60.4400 706.0000 1.0000
60.4800 686.0000 1.0000
60.5200 719.0000 1.0000
60.5600 666.0000 1.0000
60.6000 671.0000 1.0000
60.6400 702.0000 1.0000
60.6800 683.0000 1.0000
60.7200 682.0000 1.0000
60.7600 694.0000 1.0000
60.8000 697.0000 1.0000
60.8400 669.0000 1.0000
60.8800 698.0000 1.0000
60.9200 705.0000 1.0000
60.9600 706.0000 1.0000
61.0000 682.0000 1.0000
61.0400 714.0000 1.0000
61.0800 685.0000 1.0000
61.1200 709.0000 1.0000
61.1600 703.0000 1.0000
61.2000 738.0000 1.0000
61.2400 734.0000 1.0000
61.2800 686.0000 1.0000
61.3200 740.0000 1.0000
61.3600 715.0000 1.0000
61.4000 643.0000 1.0000
61.4400 695.0000 1.0000
61.4800 714.0000 1.0000
61.5200 739.0000 1.0000
61.5600 687.0000 1.0000
61.6000 695.0000 1.0000
61.6400 745.0000 1.0000
61.6800 732.0000 1.0000
61.7200 772.0000 1.0000
61.7600 806.0000 1.0000
61.8000 795.0000 1.0000
61.8400 732.0000 1.0000
61.8800 763.0000 1.0000
61.9200 824.0000 1.0000
61.9600 853.0000 1.0000
62.0000 867.0000 1.0000
62.0400 949.0000 1.0000
62.0800 1020.0000 1.0000
62.1200 1174.0000 1.0000
62.1600 1247.0000 1.0000
62.2000 1366.0000 1.0000
62.2400 1483.0000 1.0000
62.2800 1552.0000 1.0000
62.3200 1652.0000 1.0000
62.3600 1685.0000 1.0000
62.4000 1658.0000 1.0000
62.4400 1556.0000 1.0000
62.4800 1395.0000 1.0000
62.5200 1284.0000 1.0000
62.5600 1262.0000 1.0000
62.6000 1118.0000 1.0000
62.6400 983.0000 1.0000
62.6800 966.0000 1.0000
62.7200 923.0000 1.0000
62.7600 878.0000 1.0000
62.8000 893.0000 1.0000
62.8400 799.0000 1.0000
62.8800 794.0000 1.0000
62.9200 782.0000 1.0000
62.9600 782.0000 1.0000
63.0000 827.0000 1.0000
63.0400 798.0000 1.0000
63.0800 764.0000 1.0000
63.1200 790.0000 1.0000
63.1600 762.0000 1.0000
63.2000 761.0000 1.0000
63.2400 771.0000 1.0000
63.2800 764.0000 1.0000
63.3200 699.0000 1.0000
63.3600 767.0000 1.0000
63.4000 711.0000 1.0000
63.4400 785.0000 1.0000
63.4800 726.0000 1.0000
63.5200 682.0000 1.0000
63.5600 741.0000 1.0000
63.6000 710.0000 1.0000
63.6400 756.0000 1.0000
63.6800 691.0000 1.0000
63.7200 731.0000 1.0000
63.7600 713.0000 1.0000
63.8000 717.0000 1.0000
63.8400 745.0000 1.0000
63.8800 733.0000 1.0000
63.9200 728.0000 1.0000
63.9600 699.0000 1.0000
64.0000 757.0000 1.0000
64.0400 734.0000 1.0000
64.0800 738.0000 1.0000
64.1200 762.0000 1.0000
64.1600 745.0000 1.0000
64.2000 727.0000 1.0000
64.2400 735.0000 1.0000
64.2800 750.0000 1.0000
64.3200 701.0000 1.0000
64.3600 746.0000 1.0000
64.4000 762.0000 1.0000
64.4400 760.0000 1.0000
64.4800 824.0000 1.0000
64.5200 800.0000 1.0000
64.5600 811.0000 1.0000
64.6000 874.0000 1.0000
64.6400 908.0000 1.0000
64.6800 973.0000 1.0000
64.7200 969.0000 1.0000
64.7600 957.0000 1.0000
64.8000 941.0000 1.0000
64.8400 948.0000 1.0000
64.8800 940.0000 1.0000
64.9200 889.0000 1.0000
64.9600 892.0000 1.0000
65.0000 870.0000 1.0000
65.0400 839.0000 1.0000
65.0800 840.0000 1.0000
65.1200 764.0000 1.0000
65.1600 727.0000 1.0000
65.2000 755.0000 1.0000
65.2400 745.0000 1.0000
65.2800 793.0000 1.0000
65.3200 777.0000 1.0000
65.3600 741.0000 1.0000
65.4000 736.0000 1.0000
65.4400 784.0000 1.0000
65.4800 724.0000 1.0000
65.5200 759.0000 1.0000
65.5600 811.0000 1.0000
65.6000 759.0000 1.0000
65.6400 737.0000 1.0000
65.6800 751.0000 1.0000
65.7200 783.0000 1.0000
65.7600 776.0000 1.0000
65.8000 806.0000 1.0000
65.8400 888.0000 1.0000
65.8800 929.0000 1.0000
65.9200 886.0000 1.0000
65.9600 914.0000 1.0000
66.0000 1053.0000 1.0000
66.0400 1085.0000 1.0000
66.0800 1314.0000 1.0000
66.1200 1545.0000 1.0000
66.1600 1804.0000 1.0000
66.2000 2238.0000 1.0000
66.2400 2574.0000 1.0000
66.2800 2675.0000 1.0000
66.3200 2470.0000 1.0000
66.3600 2348.0000 1.0000
66.4000 2231.0000 1.0000
66.4400 2150.0000 1.0000
66.4800 1940.0000 1.0000
66.5200 1600.0000 1.0000
66.5600 1403.0000 1.0000
66.6000 1221.0000 1.0000
66.6400 1101.0000 1.0000
66.6800 1034.0000 1.0000
66.7200 945.0000 1.0000
66.7600 868.0000 1.0000
66.8000 832.0000 1.0000
66.8400 802.0000 1.0000
66.8800 793.0000 1.0000
66.9200 732.0000 1.0000
66.9600 704.0000 1.0000
67.0000 696.0000 1.0000
67.0400 751.0000 1.0000
67.0800 698.0000 1.0000
67.1200 706.0000 1.0000
67.1600 685.0000 1.0000
67.2000 707.0000 1.0000
67.2400 670.0000 1.0000
67.2800 725.0000 1.0000
67.3200 678.0000 1.0000
67.3600 686.0000 1.0000
67.4000 659.0000 1.0000
67.4400 666.0000 1.0000
67.4800 631.0000 1.0000
67.5200 665.0000 1.0000
67.5600 686.0000 1.0000
67.6000 649.0000 1.0000
67.6400 688.0000 1.0000
67.6800 683.0000 1.0000
67.7200 652.0000 1.0000
67.7600 676.0000 1.0000
67.8000 637.0000 1.0000
67.8400 632.0000 1.0000
67.8800 662.0000 1.0000
67.9200 651.0000 1.0000
67.9600 659.0000 1.0000
68.0000 653.0000 1.0000
68.0400 623.0000 1.0000
68.0800 647.0000 1.0000
68.1200 645.0000 1.0000
68.1600 630.0000 1.0000
68.2000 610.0000 1.0000
68.2400 628.0000 1.0000
68.2800 677.0000 1.0000
68.3200 676.0000 1.0000
68.3600 643.0000 1.0000
68.4000 648.0000 1.0000
68.4400 660.0000 1.0000
68.4800 658.0000 1.0000
68.5200 664.0000 1.0000
68.5600 662.0000 1.0000
68.6000 658.0000 1.0000
68.6400 677.0000 1.0000
68.6800 648.0000 1.0000
68.7200 622.0000 1.0000
68.7600 654.0000 1.0000
68.8000 622.0000 1.0000
68.8400 662.0000 1.0000
68.8800 606.0000 1.0000
68.9200 617.0000 1.0000
68.9600 590.0000 1.0000
69.0000 606.0000 1.0000
69.0400 590.0000 1.0000
69.0800 621.0000 1.0000
69.1200 623.0000 1.0000
69.1600 576.0000 1.0000
69.2000 607.0000 1.0000
69.2400 594.0000 1.0000
69.2800 623.0000 1.0000
69.3200 610.0000 1.0000
69.3600 618.0000 1.0000
69.4000 596.0000 1.0000
69.4400 631.0000 1.0000
69.4800 621.0000 1.0000
69.5200 612.0000 1.0000
69.5600 644.0000 1.0000
69.6000 631.0000 1.0000
69.6400 624.0000 1.0000
69.6800 619.0000 1.0000
69.7200 609.0000 1.0000
69.7600 643.0000 1.0000
69.8000 635.0000 1.0000
69.8400 680.0000 1.0000
69.8800 606.0000 1.0000
69.9200 630.0000 1.0000
69.9600 663.0000 1.0000
70.0000 622.0000 1.0000
*RAS_INT_END
*RAS_TEMPERATURE_START
*RAS_TEMPERATURE_END
*RAS_DATA_END