File: Section2_75_samples/XRD/No_004_600_15.ras
*RAS_DATA_START
*RAS_HEADER_START
*DISP_FMT_X "%.2f"
*DISP_FMT_Y "%.0f"
*DISP_FULLSCALE "3562.0000000000"
*DISP_LINE_COLOR "255.0000000000"
*DISP_LINE_STYLE "0.0000000000"
*DISP_LINE_WIDTH "0.2500000000"
*DISP_NOTE "測定データ-9"
*DISP_OFFSET_Y "0.0000000000"
*DISP_PEAKSEARCH_UNIT_Y "cps"
*DISP_RANGE_BOTTOM "0.0000000000"
*DISP_RANGE_LEFT "20.0000000000"
*DISP_RANGE_LOGCUTOFF "0.0100000000"
*DISP_RANGE_RIGHT "80.0000000000"
*DISP_RANGE_TOP "3562.0000000000"
*DISP_SCALE_MODE_Y "0.0000000000"
*DISP_TAB_NAME "2θ/θ"
*DISP_TITLE_Y "強度"
*DISP_UNIT_Y "cps"
*DISP_WINDOW_NAME "MSG_MACROENGINE"
*FILE_COMMENT " "
*FILE_MD5 ""
*FILE_MEMO " "
*FILE_OPERATOR "Administrator"
*FILE_SAMPLE " "
*FILE_TYPE "RAS_RAW"
*FILE_USERGROUP "システムマネージャ"
*FILE_VERSION "1.0000000000"
*HW_ATTACHMENT_ID "ATT0025"
*HW_ATTACHMENT_NAME "標準|Standard"
*HW_COUNTER_ID-0 "CUT0025"
*HW_COUNTER_ID-1 "CUT0020"
*HW_COUNTER_ID-2 "CUT0020"
*HW_COUNTER_ID-3 "CSL0021"
*HW_COUNTER_ID-4 "CMC0021"
*HW_COUNTER_NAME-0 "D/teX Ultra|D/teX Ultra"
*HW_COUNTER_NAME-1 "None|None"
*HW_COUNTER_NAME-2 "None|None"
*HW_COUNTER_NAME-3 "BBM|BBM"
*HW_COUNTER_NAME-4 "検出器モノクロメータ|Detector monochromator"
*HW_COUNTER_SELECT_NAME "D/teX Ultra|D/teX Ultra"
*HW_GONIOMETER_ID "GON0023"
*HW_GONIOMETER_NAME "SmartLab|SmartLab"
*HW_GONIOMETER_RADIUS-0 "90.0"
*HW_GONIOMETER_RADIUS-1 "114.0"
*HW_GONIOMETER_RADIUS-2 "190.0"
*HW_GONIOMETER_RADIUS-3 "300.0"
*HW_GONIOMETER_RADIUS-4 "187.0"
*HW_GONIOMETER_RADIUS-5 "300.0"
*HW_GONIOMETER_RADIUS-6 "113.0"
*HW_GONIOMETER_RADIUS-7 "331.0"
*HW_I_OPT_ID-0 "CBO0021"
*HW_I_OPT_ID-1 "ICR0023"
*HW_I_OPT_ID-2 "ISL0021"
*HW_I_OPT_ID-3 "ISO0021"
*HW_I_OPT_ID-4 "IAD0021"
*HW_I_OPT_ID-5 "IPR0001"
*HW_I_OPT_NAME-0 "CBOユニット|CBO unit"
*HW_I_OPT_NAME-1 "標準入射光学ユニット|Standard incident optical unit"
*HW_I_OPT_NAME-2 "標準入射スリットボックス|Standard incident slit box"
*HW_I_OPT_NAME-3 "入射平行スリット|Incident parallel slit"
*HW_I_OPT_NAME-4 "長手制限スリット|Length limiting slit"
*HW_I_OPT_NAME-5 "None|None"
*HW_R_ATTENUATER_AUTOMODE "0"
*HW_R_OPT_ID-0 "RSS0021"
*HW_R_OPT_ID-1 "RCR0023"
*HW_R_OPT_ID-2 "RSO0021"
*HW_R_OPT_ID-3 "RRS0021"
*HW_R_OPT_ID-4 "ATN0021"
*HW_R_OPT_ID-5 "RFL0021"
*HW_R_OPT_ID-6 "RAD0021"
*HW_R_OPT_NAME-0 "標準受光スリットボックス1|Standard receiving slit box # 1"
*HW_R_OPT_NAME-1 "標準受光光学ユニット1|Standard receiving unit # 1"
*HW_R_OPT_NAME-2 "標準受光光学ユニット2|Standard receiving optical unit # 2"
*HW_R_OPT_NAME-3 "標準受光スリットボックス2|Standard receiving slit box # 2"
*HW_R_OPT_NAME-4 "標準アッテネータ|Standard Attenuator"
*HW_R_OPT_NAME-5 "Cu Kβ|Cu K-beta"
*HW_R_OPT_NAME-6 "調整用受光スリット|Alignment receiving slit"
*HW_SAMPLE_HOLDER_ID "SMP0023"
*HW_SAMPLE_HOLDER_NAME "標準Zステージ|Standard Z stage"
*HW_XG_CURRENT_MAX "50"
*HW_XG_CURRENT_MIN "2"
*HW_XG_CURRENT_RESOLUTION "2"
*HW_XG_CURRENT_UNIT "mA"
*HW_XG_FOCUS "1mm x 10mm"
*HW_XG_FOCUS_TYPE "Normal"
*HW_XG_ID ""
*HW_XG_NAME "3kW 封入管(ID:1200)|3kW Sealed tube(ID:1200)"
*HW_XG_TARGET_ATOMIC_NUMBER "29.0000000000"
*HW_XG_TARGET_NAME "Cu"
*HW_XG_TYPE "Hermetic"
*HW_XG_VOLTAGE_MAX "60"
*HW_XG_VOLTAGE_MIN "20"
*HW_XG_VOLTAGE_RESOLUTION "2"
*HW_XG_VOLTAGE_UNIT "kV"
*HW_XG_WATT_MAX "2"
*HW_XG_WATT_UNIT "kW"
*HW_XG_WAVE_LENGTH_ALPHA1 "1.540593"
*HW_XG_WAVE_LENGTH_ALPHA2 "1.544414"
*HW_XG_WAVE_LENGTH_BETA "1.392250"
*MEAS_COND_AXIS_NAME-0 "2θ/θ"
*MEAS_COND_AXIS_NAME-1 "2θ"
*MEAS_COND_AXIS_NAME-2 "ω"
*MEAS_COND_AXIS_NAME-3 "Z"
*MEAS_COND_AXIS_NAME-4 "2θ/ω"
*MEAS_COND_AXIS_NAME-5 "θs"
*MEAS_COND_AXIS_NAME-6 "θd"
*MEAS_COND_AXIS_NAME-7 "Ts"
*MEAS_COND_AXIS_NAME-8 "CBO選択スリット"
*MEAS_COND_AXIS_NAME-9 "M"
*MEAS_COND_AXIS_NAME-10 "入射平行スリット"
*MEAS_COND_AXIS_NAME-11 "入射スリット"
*MEAS_COND_AXIS_NAME-12 ""
*MEAS_COND_AXIS_NAME-13 "Zs"
*MEAS_COND_AXIS_NAME-14 "入射光学素子"
*MEAS_COND_AXIS_NAME-15 "長手制限スリット"
*MEAS_COND_AXIS_NAME-16 "センタースリット"
*MEAS_COND_AXIS_NAME-17 "フィルター"
*MEAS_COND_AXIS_NAME-18 "受光スリット1"
*MEAS_COND_AXIS_NAME-19 "受光スリット2"
*MEAS_COND_AXIS_NAME-20 "受光光学素子"
*MEAS_COND_AXIS_NAME-21 "受光平行スリット"
*MEAS_COND_AXIS_NAME-22 "調整用受光スリット"
*MEAS_COND_AXIS_NAME-23 ""
*MEAS_COND_AXIS_NAME-24 ""
*MEAS_COND_AXIS_NAME-25 "Zd"
*MEAS_COND_AXIS_NAME-26 "アッテネータ"
*MEAS_COND_AXIS_NAME-27 "検出器モノクロメータ"
*MEAS_COND_AXIS_NAME-28 "モノクロメータスリット"
*MEAS_COND_AXIS_NAME-29 "プライマリビーム"
*MEAS_COND_AXIS_NAME-30 "PHA"
*MEAS_COND_AXIS_NAME_INTERNAL-0 "TwoThetaTheta"
*MEAS_COND_AXIS_NAME_INTERNAL-1 "TwoTheta"
*MEAS_COND_AXIS_NAME_INTERNAL-2 "Omega"
*MEAS_COND_AXIS_NAME_INTERNAL-3 "Z"
*MEAS_COND_AXIS_NAME_INTERNAL-4 "TwoThetaOmega"
*MEAS_COND_AXIS_NAME_INTERNAL-5 "ThetaS"
*MEAS_COND_AXIS_NAME_INTERNAL-6 "ThetaD"
*MEAS_COND_AXIS_NAME_INTERNAL-7 "Ts"
*MEAS_COND_AXIS_NAME_INTERNAL-8 "CBO"
*MEAS_COND_AXIS_NAME_INTERNAL-9 "CBO-M"
*MEAS_COND_AXIS_NAME_INTERNAL-10 "IncidentSollerSlit"
*MEAS_COND_AXIS_NAME_INTERNAL-11 "IncidentSlitBox"
*MEAS_COND_AXIS_NAME_INTERNAL-12 "IncidentSlitBox-_Axis"
*MEAS_COND_AXIS_NAME_INTERNAL-13 "Zs"
*MEAS_COND_AXIS_NAME_INTERNAL-14 "IncidentMonochromator"
*MEAS_COND_AXIS_NAME_INTERNAL-15 "IncidentAxdSlit"
*MEAS_COND_AXIS_NAME_INTERNAL-16 "CenterSlit"
*MEAS_COND_AXIS_NAME_INTERNAL-17 "Filter"
*MEAS_COND_AXIS_NAME_INTERNAL-18 "ReceivingSlitBox1"
*MEAS_COND_AXIS_NAME_INTERNAL-19 "ReceivingSlitBox2"
*MEAS_COND_AXIS_NAME_INTERNAL-20 "ReceivingOptics"
*MEAS_COND_AXIS_NAME_INTERNAL-21 "ReceivingSollerSlit"
*MEAS_COND_AXIS_NAME_INTERNAL-22 "ReceivingAxdSlit"
*MEAS_COND_AXIS_NAME_INTERNAL-23 "ReceivingSlitBox1-_Axis"
*MEAS_COND_AXIS_NAME_INTERNAL-24 "ReceivingSlitBox2-_Axis"
*MEAS_COND_AXIS_NAME_INTERNAL-25 "ReceivingSlitBox2-Zd"
*MEAS_COND_AXIS_NAME_INTERNAL-26 "Attenuator"
*MEAS_COND_AXIS_NAME_INTERNAL-27 "CounterMonochromator"
*MEAS_COND_AXIS_NAME_INTERNAL-28 "CounterSlit"
*MEAS_COND_AXIS_NAME_INTERNAL-29 "IncidentPrimary"
*MEAS_COND_AXIS_NAME_INTERNAL-30 "PHA"
*MEAS_COND_AXIS_NAME_MAGICNO-0 "83951616.0000000000"
*MEAS_COND_AXIS_NAME_MAGICNO-1 "268632064.0000000000"
*MEAS_COND_AXIS_NAME_MAGICNO-2 "268500992.0000000000"
*MEAS_COND_AXIS_NAME_MAGICNO-3 "285278208.0000000000"
*MEAS_COND_AXIS_NAME_MAGICNO-4 "83951616.0000000000"
*MEAS_COND_AXIS_NAME_MAGICNO-5 "131072.0000000000"
*MEAS_COND_AXIS_NAME_MAGICNO-6 "131072.0000000000"
*MEAS_COND_AXIS_NAME_MAGICNO-7 "318898176.0000000000"
*MEAS_COND_AXIS_NAME_MAGICNO-8 "20971521.0000000000"
*MEAS_COND_AXIS_NAME_MAGICNO-9 "285343744.0000000000"
*MEAS_COND_AXIS_NAME_MAGICNO-10 "20971521.0000000000"
*MEAS_COND_AXIS_NAME_MAGICNO-11 "22020097.0000000000"
*MEAS_COND_AXIS_NAME_MAGICNO-12 "25165824.0000000000"
*MEAS_COND_AXIS_NAME_MAGICNO-13 "318898176.0000000000"
*MEAS_COND_AXIS_NAME_MAGICNO-14 "1.0000000000"
*MEAS_COND_AXIS_NAME_MAGICNO-15 "20971521.0000000000"
*MEAS_COND_AXIS_NAME_MAGICNO-16 "20971521.0000000000"
*MEAS_COND_AXIS_NAME_MAGICNO-17 "20971521.0000000000"
*MEAS_COND_AXIS_NAME_MAGICNO-18 "23068673.0000000000"
*MEAS_COND_AXIS_NAME_MAGICNO-19 "23068673.0000000000"
*MEAS_COND_AXIS_NAME_MAGICNO-20 "20971521.0000000000"
*MEAS_COND_AXIS_NAME_MAGICNO-21 "20971521.0000000000"
*MEAS_COND_AXIS_NAME_MAGICNO-22 "20971521.0000000000"
*MEAS_COND_AXIS_NAME_MAGICNO-23 "25165824.0000000000"
*MEAS_COND_AXIS_NAME_MAGICNO-24 "25165824.0000000000"
*MEAS_COND_AXIS_NAME_MAGICNO-25 "285343744.0000000000"
*MEAS_COND_AXIS_NAME_MAGICNO-26 "17301505.0000000000"
*MEAS_COND_AXIS_NAME_MAGICNO-27 "20971521.0000000000"
*MEAS_COND_AXIS_NAME_MAGICNO-28 "20971521.0000000000"
*MEAS_COND_AXIS_NAME_MAGICNO-29 "20971521.0000000000"
*MEAS_COND_AXIS_NAME_MAGICNO-30 "0.0000000000"
*MEAS_COND_AXIS_OFFSET-0 "-"
*MEAS_COND_AXIS_OFFSET-1 "-0.1081000000"
*MEAS_COND_AXIS_OFFSET-2 "0.3758000000"
*MEAS_COND_AXIS_OFFSET-3 "-"
*MEAS_COND_AXIS_OFFSET-4 "-"
*MEAS_COND_AXIS_OFFSET-5 "0.3758000000"
*MEAS_COND_AXIS_OFFSET-6 "-0.4839000000"
*MEAS_COND_AXIS_OFFSET-7 "-"
*MEAS_COND_AXIS_OFFSET-8 "-"
*MEAS_COND_AXIS_OFFSET-9 "-"
*MEAS_COND_AXIS_OFFSET-10 "-"
*MEAS_COND_AXIS_OFFSET-11 "-"
*MEAS_COND_AXIS_OFFSET-12 "-"
*MEAS_COND_AXIS_OFFSET-13 "-"
*MEAS_COND_AXIS_OFFSET-14 "-"
*MEAS_COND_AXIS_OFFSET-15 "-"
*MEAS_COND_AXIS_OFFSET-16 "-"
*MEAS_COND_AXIS_OFFSET-17 "-"
*MEAS_COND_AXIS_OFFSET-18 "-"
*MEAS_COND_AXIS_OFFSET-19 "-"
*MEAS_COND_AXIS_OFFSET-20 "-"
*MEAS_COND_AXIS_OFFSET-21 "-"
*MEAS_COND_AXIS_OFFSET-22 "-"
*MEAS_COND_AXIS_OFFSET-23 "-"
*MEAS_COND_AXIS_OFFSET-24 "-"
*MEAS_COND_AXIS_OFFSET-25 "-"
*MEAS_COND_AXIS_OFFSET-26 "-"
*MEAS_COND_AXIS_OFFSET-27 "-"
*MEAS_COND_AXIS_OFFSET-28 "-"
*MEAS_COND_AXIS_OFFSET-29 "-"
*MEAS_COND_AXIS_OFFSET-30 "-"
*MEAS_COND_AXIS_POSITION-0 "0.0000000000"
*MEAS_COND_AXIS_POSITION-1 "0.0000000000"
*MEAS_COND_AXIS_POSITION-2 "0.0000000000"
*MEAS_COND_AXIS_POSITION-3 "-0.5500000000"
*MEAS_COND_AXIS_POSITION-4 "0.0000000000"
*MEAS_COND_AXIS_POSITION-5 "0.0000000000"
*MEAS_COND_AXIS_POSITION-6 "0.0000000000"
*MEAS_COND_AXIS_POSITION-7 "-0.4278800000"
*MEAS_COND_AXIS_POSITION-8 "BB"
*MEAS_COND_AXIS_POSITION-9 "0.0000000000"
*MEAS_COND_AXIS_POSITION-10 "Soller_slit_5.0deg"
*MEAS_COND_AXIS_POSITION-11 "2/3deg"
*MEAS_COND_AXIS_POSITION-12 "2.2088000000"
*MEAS_COND_AXIS_POSITION-13 "-0.4140600000"
*MEAS_COND_AXIS_POSITION-14 "0.0000000000"
*MEAS_COND_AXIS_POSITION-15 "10.0mm"
*MEAS_COND_AXIS_POSITION-16 "None"
*MEAS_COND_AXIS_POSITION-17 "Cu_K-beta"
*MEAS_COND_AXIS_POSITION-18 "13.000mm"
*MEAS_COND_AXIS_POSITION-19 "13.000mm"
*MEAS_COND_AXIS_POSITION-20 "No_unit"
*MEAS_COND_AXIS_POSITION-21 "Soller_slit_5.0deg"
*MEAS_COND_AXIS_POSITION-22 "None"
*MEAS_COND_AXIS_POSITION-23 "13.0000000000"
*MEAS_COND_AXIS_POSITION-24 "13.0000000000"
*MEAS_COND_AXIS_POSITION-25 "0.0109400000"
*MEAS_COND_AXIS_POSITION-26 "Open"
*MEAS_COND_AXIS_POSITION-27 "None"
*MEAS_COND_AXIS_POSITION-28 "None"
*MEAS_COND_AXIS_POSITION-29 "None"
*MEAS_COND_AXIS_POSITION-30 "38.0000000000"
*MEAS_COND_AXIS_UNIT-0 "deg"
*MEAS_COND_AXIS_UNIT-1 "deg"
*MEAS_COND_AXIS_UNIT-2 "deg"
*MEAS_COND_AXIS_UNIT-3 "mm"
*MEAS_COND_AXIS_UNIT-4 "deg"
*MEAS_COND_AXIS_UNIT-5 "deg"
*MEAS_COND_AXIS_UNIT-6 "deg"
*MEAS_COND_AXIS_UNIT-7 "mm"
*MEAS_COND_AXIS_UNIT-8 ""
*MEAS_COND_AXIS_UNIT-9 "pulse"
*MEAS_COND_AXIS_UNIT-10 ""
*MEAS_COND_AXIS_UNIT-11 ""
*MEAS_COND_AXIS_UNIT-12 "mm"
*MEAS_COND_AXIS_UNIT-13 "mm"
*MEAS_COND_AXIS_UNIT-14 ""
*MEAS_COND_AXIS_UNIT-15 ""
*MEAS_COND_AXIS_UNIT-16 ""
*MEAS_COND_AXIS_UNIT-17 ""
*MEAS_COND_AXIS_UNIT-18 ""
*MEAS_COND_AXIS_UNIT-19 ""
*MEAS_COND_AXIS_UNIT-20 ""
*MEAS_COND_AXIS_UNIT-21 ""
*MEAS_COND_AXIS_UNIT-22 ""
*MEAS_COND_AXIS_UNIT-23 "mm"
*MEAS_COND_AXIS_UNIT-24 "mm"
*MEAS_COND_AXIS_UNIT-25 "mm"
*MEAS_COND_AXIS_UNIT-26 ""
*MEAS_COND_AXIS_UNIT-27 ""
*MEAS_COND_AXIS_UNIT-28 ""
*MEAS_COND_AXIS_UNIT-29 ""
*MEAS_COND_AXIS_UNIT-30 "div"
*MEAS_COND_COUNTER_CNTLOSS_CORR "0.0000000000"
*MEAS_COND_COUNTER_PHABASE "38.0000000000"
*MEAS_COND_COUNTER_PHAWINDOW "16.0000000000"
*MEAS_COND_COUNTER_PHA_UNIT "div"
*MEAS_COND_COUNTER_TAUDIFF "30.0000000000"
*MEAS_COND_COUNTER_TAUINT "0.0000000000"
*MEAS_COND_IRRADIATION_MODE "OFF"
*MEAS_COND_IRRADIATION_WIDTH ""
*MEAS_COND_OPT_ATTR "集中法"
*MEAS_COND_OPT_NAME "@集中法"
*MEAS_COND_UNSYMMETRIC_MODE "OFF"
*MEAS_COND_XG_CURRENT "30.0000000000"
*MEAS_COND_XG_VOLTAGE "40.0000000000"
*MEAS_COND_XG_WAVE_TYPE "Ka"
*MEAS_DATA_COUNT "3001.0000000000"
*MEAS_SCAN_AXIS_X "2θ/θ"
*MEAS_SCAN_AXIS_X_INTERNAL "TwoThetaTheta"
*MEAS_SCAN_END_TIME "08/27/20 16:19:16"
*MEAS_SCAN_MODE "CONTINUOUS"
*MEAS_SCAN_MONITOR "0"
*MEAS_SCAN_RESOLUTION_X "0.0002"
*MEAS_SCAN_SPEED "2.0"
*MEAS_SCAN_SPEED_UNIT "deg/min"
*MEAS_SCAN_START "20.0000000000"
*MEAS_SCAN_START_TIME "08/27/20 15:47:37"
*MEAS_SCAN_STEP "0.0200000000"
*MEAS_SCAN_STOP "80.0000000000"
*MEAS_SCAN_UNIT_X "deg"
*MEAS_SCAN_UNIT_Y "counts"
*RAS_HEADER_END
*RAS_INT_START
20.0000 1756.0000 1.0000
20.0600 1749.0000 1.0000
20.1200 1781.0000 1.0000
20.1800 1731.0000 1.0000
20.2400 1706.0000 1.0000
20.3000 1731.0000 1.0000
20.3600 1673.0000 1.0000
20.4200 1661.0000 1.0000
20.4800 1676.0000 1.0000
20.5400 1679.0000 1.0000
20.6000 1725.0000 1.0000
20.6600 1641.0000 1.0000
20.7200 1597.0000 1.0000
20.7800 1623.0000 1.0000
20.8400 1655.0000 1.0000
20.9000 1604.0000 1.0000
20.9600 1684.0000 1.0000
21.0200 1641.0000 1.0000
21.0800 1565.0000 1.0000
21.1400 1518.0000 1.0000
21.2000 1536.0000 1.0000
21.2600 1540.0000 1.0000
21.3200 1573.0000 1.0000
21.3800 1622.0000 1.0000
21.4400 1504.0000 1.0000
21.5000 1481.0000 1.0000
21.5600 1497.0000 1.0000
21.6200 1550.0000 1.0000
21.6800 1556.0000 1.0000
21.7400 1532.0000 1.0000
21.8000 1469.0000 1.0000
21.8600 1484.0000 1.0000
21.9200 1466.0000 1.0000
21.9800 1527.0000 1.0000
22.0400 1529.0000 1.0000
22.1000 1411.0000 1.0000
22.1600 1459.0000 1.0000
22.2200 1463.0000 1.0000
22.2800 1473.0000 1.0000
22.3400 1464.0000 1.0000
22.4000 1379.0000 1.0000
22.4600 1363.0000 1.0000
22.5200 1443.0000 1.0000
22.5800 1447.0000 1.0000
22.6400 1419.0000 1.0000
22.7000 1354.0000 1.0000
22.7600 1345.0000 1.0000
22.8200 1270.0000 1.0000
22.8800 1373.0000 1.0000
22.9400 1322.0000 1.0000
23.0000 1378.0000 1.0000
23.0600 1309.0000 1.0000
23.1200 1367.0000 1.0000
23.1800 1326.0000 1.0000
23.2400 1317.0000 1.0000
23.3000 1355.0000 1.0000
23.3600 1268.0000 1.0000
23.4200 1279.0000 1.0000
23.4800 1266.0000 1.0000
23.5400 1285.0000 1.0000
23.6000 1364.0000 1.0000
23.6600 1355.0000 1.0000
23.7200 1218.0000 1.0000
23.7800 1263.0000 1.0000
23.8400 1312.0000 1.0000
23.9000 1277.0000 1.0000
23.9600 1220.0000 1.0000
24.0200 1255.0000 1.0000
24.0800 1276.0000 1.0000
24.1400 1295.0000 1.0000
24.2000 1186.0000 1.0000
24.2600 1226.0000 1.0000
24.3200 1212.0000 1.0000
24.3800 1208.0000 1.0000
24.4400 1202.0000 1.0000
24.5000 1136.0000 1.0000
24.5600 1164.0000 1.0000
24.6200 1218.0000 1.0000
24.6800 1208.0000 1.0000
24.7400 1172.0000 1.0000
24.8000 1165.0000 1.0000
24.8600 1211.0000 1.0000
24.9200 1105.0000 1.0000
24.9800 1165.0000 1.0000
25.0400 1148.0000 1.0000
25.1000 1109.0000 1.0000
25.1600 1135.0000 1.0000
25.2200 1116.0000 1.0000
25.2800 1124.0000 1.0000
25.3400 1161.0000 1.0000
25.4000 1149.0000 1.0000
25.4600 1132.0000 1.0000
25.5200 1083.0000 1.0000
25.5800 1097.0000 1.0000
25.6400 1099.0000 1.0000
25.7000 1073.0000 1.0000
25.7600 1088.0000 1.0000
25.8200 1048.0000 1.0000
25.8800 1078.0000 1.0000
25.9400 1114.0000 1.0000
26.0000 1027.0000 1.0000
26.0600 1093.0000 1.0000
26.1200 1041.0000 1.0000
26.1800 1027.0000 1.0000
26.2400 1120.0000 1.0000
26.3000 1041.0000 1.0000
26.3600 913.0000 1.0000
26.4200 1074.0000 1.0000
26.4800 1053.0000 1.0000
26.5400 1013.0000 1.0000
26.6000 1021.0000 1.0000
26.6600 1011.0000 1.0000
26.7200 1028.0000 1.0000
26.7800 1031.0000 1.0000
26.8400 980.0000 1.0000
26.9000 1004.0000 1.0000
26.9600 1034.0000 1.0000
27.0200 1081.0000 1.0000
27.0800 993.0000 1.0000
27.1400 1127.0000 1.0000
27.2000 1197.0000 1.0000
27.2600 1331.0000 1.0000
27.3200 1292.0000 1.0000
27.3800 1276.0000 1.0000
27.4400 1149.0000 1.0000
27.5000 1051.0000 1.0000
27.5600 1037.0000 1.0000
27.6200 988.0000 1.0000
27.6800 935.0000 1.0000
27.7400 946.0000 1.0000
27.8000 995.0000 1.0000
27.8600 963.0000 1.0000
27.9200 893.0000 1.0000
27.9800 889.0000 1.0000
28.0400 886.0000 1.0000
28.1000 941.0000 1.0000
28.1600 868.0000 1.0000
28.2200 884.0000 1.0000
28.2800 893.0000 1.0000
28.3400 858.0000 1.0000
28.4000 864.0000 1.0000
28.4600 882.0000 1.0000
28.5200 888.0000 1.0000
28.5800 852.0000 1.0000
28.6400 861.0000 1.0000
28.7000 838.0000 1.0000
28.7600 875.0000 1.0000
28.8200 860.0000 1.0000
28.8800 838.0000 1.0000
28.9400 818.0000 1.0000
29.0000 825.0000 1.0000
29.0600 826.0000 1.0000
29.1200 862.0000 1.0000
29.1800 826.0000 1.0000
29.2400 833.0000 1.0000
29.3000 809.0000 1.0000
29.3600 808.0000 1.0000
29.4200 860.0000 1.0000
29.4800 790.0000 1.0000
29.5400 770.0000 1.0000
29.6000 809.0000 1.0000
29.6600 780.0000 1.0000
29.7200 807.0000 1.0000
29.7800 822.0000 1.0000
29.8400 747.0000 1.0000
29.9000 786.0000 1.0000
29.9600 821.0000 1.0000
30.0200 751.0000 1.0000
30.0800 823.0000 1.0000
30.1400 772.0000 1.0000
30.2000 768.0000 1.0000
30.2600 792.0000 1.0000
30.3200 758.0000 1.0000
30.3800 768.0000 1.0000
30.4400 767.0000 1.0000
30.5000 742.0000 1.0000
30.5600 708.0000 1.0000
30.6200 748.0000 1.0000
30.6800 715.0000 1.0000
30.7400 778.0000 1.0000
30.8000 742.0000 1.0000
30.8600 694.0000 1.0000
30.9200 750.0000 1.0000
30.9800 712.0000 1.0000
31.0400 704.0000 1.0000
31.1000 703.0000 1.0000
31.1600 692.0000 1.0000
31.2200 664.0000 1.0000
31.2800 693.0000 1.0000
31.3400 685.0000 1.0000
31.4000 701.0000 1.0000
31.4600 651.0000 1.0000
31.5200 672.0000 1.0000
31.5800 694.0000 1.0000
31.6400 710.0000 1.0000
31.7000 673.0000 1.0000
31.7600 699.0000 1.0000
31.8200 689.0000 1.0000
31.8800 669.0000 1.0000
31.9400 656.0000 1.0000
32.0000 683.0000 1.0000
32.0600 617.0000 1.0000
32.1200 626.0000 1.0000
32.1800 661.0000 1.0000
32.2400 668.0000 1.0000
32.3000 641.0000 1.0000
32.3600 646.0000 1.0000
32.4200 658.0000 1.0000
32.4800 662.0000 1.0000
32.5400 602.0000 1.0000
32.6000 650.0000 1.0000
32.6600 662.0000 1.0000
32.7200 647.0000 1.0000
32.7800 634.0000 1.0000
32.8400 644.0000 1.0000
32.9000 657.0000 1.0000
32.9600 592.0000 1.0000
33.0200 622.0000 1.0000
33.0800 613.0000 1.0000
33.1400 641.0000 1.0000
33.2000 603.0000 1.0000
33.2600 605.0000 1.0000
33.3200 594.0000 1.0000
33.3800 597.0000 1.0000
33.4400 642.0000 1.0000
33.5000 597.0000 1.0000
33.5600 579.0000 1.0000
33.6200 610.0000 1.0000
33.6800 600.0000 1.0000
33.7400 550.0000 1.0000
33.8000 578.0000 1.0000
33.8600 622.0000 1.0000
33.9200 596.0000 1.0000
33.9800 594.0000 1.0000
34.0400 622.0000 1.0000
34.1000 538.0000 1.0000
34.1600 590.0000 1.0000
34.2200 608.0000 1.0000
34.2800 584.0000 1.0000
34.3400 654.0000 1.0000
34.4000 679.0000 1.0000
34.4600 823.0000 1.0000
34.5200 806.0000 1.0000
34.5800 746.0000 1.0000
34.6400 647.0000 1.0000
34.7000 621.0000 1.0000
34.7600 579.0000 1.0000
34.8200 568.0000 1.0000
34.8800 545.0000 1.0000
34.9400 561.0000 1.0000
35.0000 548.0000 1.0000
35.0600 533.0000 1.0000
35.1200 569.0000 1.0000
35.1800 544.0000 1.0000
35.2400 521.0000 1.0000
35.3000 554.0000 1.0000
35.3600 559.0000 1.0000
35.4200 534.0000 1.0000
35.4800 491.0000 1.0000
35.5400 534.0000 1.0000
35.6000 555.0000 1.0000
35.6600 497.0000 1.0000
35.7200 525.0000 1.0000
35.7800 530.0000 1.0000
35.8400 539.0000 1.0000
35.9000 522.0000 1.0000
35.9600 573.0000 1.0000
36.0200 501.0000 1.0000
36.0800 526.0000 1.0000
36.1400 522.0000 1.0000
36.2000 505.0000 1.0000
36.2600 555.0000 1.0000
36.3200 559.0000 1.0000
36.3800 624.0000 1.0000
36.4400 607.0000 1.0000
36.5000 559.0000 1.0000
36.5600 524.0000 1.0000
36.6200 504.0000 1.0000
36.6800 489.0000 1.0000
36.7400 487.0000 1.0000
36.8000 517.0000 1.0000
36.8600 476.0000 1.0000
36.9200 491.0000 1.0000
36.9800 457.0000 1.0000
37.0400 481.0000 1.0000
37.1000 508.0000 1.0000
37.1600 446.0000 1.0000
37.2200 490.0000 1.0000
37.2800 461.0000 1.0000
37.3400 454.0000 1.0000
37.4000 462.0000 1.0000
37.4600 433.0000 1.0000
37.5200 475.0000 1.0000
37.5800 442.0000 1.0000
37.6400 446.0000 1.0000
37.7000 431.0000 1.0000
37.7600 403.0000 1.0000
37.8200 450.0000 1.0000
37.8800 414.0000 1.0000
37.9400 423.0000 1.0000
38.0000 451.0000 1.0000
38.0600 451.0000 1.0000
38.1200 468.0000 1.0000
38.1800 460.0000 1.0000
38.2400 477.0000 1.0000
38.3000 532.0000 1.0000
38.3600 655.0000 1.0000
38.4200 743.0000 1.0000
38.4800 927.0000 1.0000
38.5400 978.0000 1.0000
38.6000 895.0000 1.0000
38.6600 774.0000 1.0000
38.7200 585.0000 1.0000
38.7800 506.0000 1.0000
38.8400 486.0000 1.0000
38.9000 424.0000 1.0000
38.9600 420.0000 1.0000
39.0200 421.0000 1.0000
39.0800 403.0000 1.0000
39.1400 448.0000 1.0000
39.2000 427.0000 1.0000
39.2600 401.0000 1.0000
39.3200 427.0000 1.0000
39.3800 417.0000 1.0000
39.4400 410.0000 1.0000
39.5000 399.0000 1.0000
39.5600 425.0000 1.0000
39.6200 430.0000 1.0000
39.6800 423.0000 1.0000
39.7400 393.0000 1.0000
39.8000 390.0000 1.0000
39.8600 382.0000 1.0000
39.9200 377.0000 1.0000
39.9800 381.0000 1.0000
40.0400 376.0000 1.0000
40.1000 369.0000 1.0000
40.1600 394.0000 1.0000
40.2200 389.0000 1.0000
40.2800 381.0000 1.0000
40.3400 399.0000 1.0000
40.4000 406.0000 1.0000
40.4600 337.0000 1.0000
40.5200 407.0000 1.0000
40.5800 393.0000 1.0000
40.6400 365.0000 1.0000
40.7000 329.0000 1.0000
40.7600 360.0000 1.0000
40.8200 363.0000 1.0000
40.8800 401.0000 1.0000
40.9400 358.0000 1.0000
41.0000 385.0000 1.0000
41.0600 344.0000 1.0000
41.1200 370.0000 1.0000
41.1800 344.0000 1.0000
41.2400 384.0000 1.0000
41.3000 365.0000 1.0000
41.3600 371.0000 1.0000
41.4200 357.0000 1.0000
41.4800 374.0000 1.0000
41.5400 318.0000 1.0000
41.6000 358.0000 1.0000
41.6600 345.0000 1.0000
41.7200 371.0000 1.0000
41.7800 327.0000 1.0000
41.8400 304.0000 1.0000
41.9000 342.0000 1.0000
41.9600 365.0000 1.0000
42.0200 361.0000 1.0000
42.0800 311.0000 1.0000
42.1400 361.0000 1.0000
42.2000 326.0000 1.0000
42.2600 324.0000 1.0000
42.3200 357.0000 1.0000
42.3800 365.0000 1.0000
42.4400 374.0000 1.0000
42.5000 318.0000 1.0000
42.5600 312.0000 1.0000
42.6200 363.0000 1.0000
42.6800 338.0000 1.0000
42.7400 328.0000 1.0000
42.8000 332.0000 1.0000
42.8600 315.0000 1.0000
42.9200 309.0000 1.0000
42.9800 357.0000 1.0000
43.0400 340.0000 1.0000
43.1000 296.0000 1.0000
43.1600 325.0000 1.0000
43.2200 355.0000 1.0000
43.2800 334.0000 1.0000
43.3400 334.0000 1.0000
43.4000 351.0000 1.0000
43.4600 339.0000 1.0000
43.5200 332.0000 1.0000
43.5800 310.0000 1.0000
43.6400 301.0000 1.0000
43.7000 308.0000 1.0000
43.7600 325.0000 1.0000
43.8200 324.0000 1.0000
43.8800 334.0000 1.0000
43.9400 320.0000 1.0000
44.0000 317.0000 1.0000
44.0600 304.0000 1.0000
44.1200 326.0000 1.0000
44.1800 301.0000 1.0000
44.2400 340.0000 1.0000
44.3000 304.0000 1.0000
44.3600 313.0000 1.0000
44.4200 332.0000 1.0000
44.4800 315.0000 1.0000
44.5400 363.0000 1.0000
44.6000 300.0000 1.0000
44.6600 302.0000 1.0000
44.7200 297.0000 1.0000
44.7800 310.0000 1.0000
44.8400 314.0000 1.0000
44.9000 297.0000 1.0000
44.9600 279.0000 1.0000
45.0200 269.0000 1.0000
45.0800 269.0000 1.0000
45.1400 278.0000 1.0000
45.2000 255.0000 1.0000
45.2600 306.0000 1.0000
45.3200 302.0000 1.0000
45.3800 308.0000 1.0000
45.4400 302.0000 1.0000
45.5000 304.0000 1.0000
45.5600 287.0000 1.0000
45.6200 291.0000 1.0000
45.6800 309.0000 1.0000
45.7400 301.0000 1.0000
45.8000 314.0000 1.0000
45.8600 292.0000 1.0000
45.9200 281.0000 1.0000
45.9800 295.0000 1.0000
46.0400 272.0000 1.0000
46.1000 293.0000 1.0000
46.1600 291.0000 1.0000
46.2200 276.0000 1.0000
46.2800 281.0000 1.0000
46.3400 286.0000 1.0000
46.4000 284.0000 1.0000
46.4600 289.0000 1.0000
46.5200 297.0000 1.0000
46.5800 295.0000 1.0000
46.6400 262.0000 1.0000
46.7000 279.0000 1.0000
46.7600 260.0000 1.0000
46.8200 259.0000 1.0000
46.8800 299.0000 1.0000
46.9400 310.0000 1.0000
47.0000 265.0000 1.0000
47.0600 310.0000 1.0000
47.1200 330.0000 1.0000
47.1800 285.0000 1.0000
47.2400 294.0000 1.0000
47.3000 272.0000 1.0000
47.3600 269.0000 1.0000
47.4200 268.0000 1.0000
47.4800 293.0000 1.0000
47.5400 269.0000 1.0000
47.6000 296.0000 1.0000
47.6600 268.0000 1.0000
47.7200 266.0000 1.0000
47.7800 273.0000 1.0000
47.8400 291.0000 1.0000
47.9000 286.0000 1.0000
47.9600 274.0000 1.0000
48.0200 276.0000 1.0000
48.0800 287.0000 1.0000
48.1400 272.0000 1.0000
48.2000 262.0000 1.0000
48.2600 251.0000 1.0000
48.3200 246.0000 1.0000
48.3800 267.0000 1.0000
48.4400 270.0000 1.0000
48.5000 244.0000 1.0000
48.5600 259.0000 1.0000
48.6200 281.0000 1.0000
48.6800 238.0000 1.0000
48.7400 265.0000 1.0000
48.8000 275.0000 1.0000
48.8600 241.0000 1.0000
48.9200 242.0000 1.0000
48.9800 250.0000 1.0000
49.0400 265.0000 1.0000
49.1000 267.0000 1.0000
49.1600 268.0000 1.0000
49.2200 238.0000 1.0000
49.2800 279.0000 1.0000
49.3400 258.0000 1.0000
49.4000 253.0000 1.0000
49.4600 265.0000 1.0000
49.5200 261.0000 1.0000
49.5800 253.0000 1.0000
49.6400 232.0000 1.0000
49.7000 251.0000 1.0000
49.7600 259.0000 1.0000
49.8200 260.0000 1.0000
49.8800 278.0000 1.0000
49.9400 255.0000 1.0000
50.0000 271.0000 1.0000
50.0600 274.0000 1.0000
50.1200 252.0000 1.0000
50.1800 241.0000 1.0000
50.2400 244.0000 1.0000
50.3000 235.0000 1.0000
50.3600 252.0000 1.0000
50.4200 259.0000 1.0000
50.4800 254.0000 1.0000
50.5400 263.0000 1.0000
50.6000 276.0000 1.0000
50.6600 228.0000 1.0000
50.7200 253.0000 1.0000
50.7800 236.0000 1.0000
50.8400 257.0000 1.0000
50.9000 256.0000 1.0000
50.9600 270.0000 1.0000
51.0200 261.0000 1.0000
51.0800 229.0000 1.0000
51.1400 227.0000 1.0000
51.2000 267.0000 1.0000
51.2600 241.0000 1.0000
51.3200 274.0000 1.0000
51.3800 214.0000 1.0000
51.4400 249.0000 1.0000
51.5000 222.0000 1.0000
51.5600 253.0000 1.0000
51.6200 248.0000 1.0000
51.6800 274.0000 1.0000
51.7400 250.0000 1.0000
51.8000 243.0000 1.0000
51.8600 271.0000 1.0000
51.9200 293.0000 1.0000
51.9800 313.0000 1.0000
52.0400 336.0000 1.0000
52.1000 459.0000 1.0000
52.1600 645.0000 1.0000
52.2200 1038.0000 1.0000
52.2800 1117.0000 1.0000
52.3400 913.0000 1.0000
52.4000 808.0000 1.0000
52.4600 578.0000 1.0000
52.5200 400.0000 1.0000
52.5800 390.0000 1.0000
52.6400 318.0000 1.0000
52.7000 286.0000 1.0000
52.7600 294.0000 1.0000
52.8200 270.0000 1.0000
52.8800 283.0000 1.0000
52.9400 252.0000 1.0000
53.0000 240.0000 1.0000
53.0600 259.0000 1.0000
53.1200 289.0000 1.0000
53.1800 265.0000 1.0000
53.2400 272.0000 1.0000
53.3000 238.0000 1.0000
53.3600 244.0000 1.0000
53.4200 242.0000 1.0000
53.4800 268.0000 1.0000
53.5400 222.0000 1.0000
53.6000 225.0000 1.0000
53.6600 219.0000 1.0000
53.7200 232.0000 1.0000
53.7800 227.0000 1.0000
53.8400 233.0000 1.0000
53.9000 231.0000 1.0000
53.9600 240.0000 1.0000
54.0200 228.0000 1.0000
54.0800 256.0000 1.0000
54.1400 252.0000 1.0000
54.2000 220.0000 1.0000
54.2600 232.0000 1.0000
54.3200 244.0000 1.0000
54.3800 223.0000 1.0000
54.4400 247.0000 1.0000
54.5000 238.0000 1.0000
54.5600 225.0000 1.0000
54.6200 229.0000 1.0000
54.6800 219.0000 1.0000
54.7400 246.0000 1.0000
54.8000 228.0000 1.0000
54.8600 223.0000 1.0000
54.9200 249.0000 1.0000
54.9800 256.0000 1.0000
55.0400 234.0000 1.0000
55.1000 282.0000 1.0000
55.1600 298.0000 1.0000
55.2200 289.0000 1.0000
55.2800 332.0000 1.0000
55.3400 307.0000 1.0000
55.4000 310.0000 1.0000
55.4600 268.0000 1.0000
55.5200 255.0000 1.0000
55.5800 249.0000 1.0000
55.6400 223.0000 1.0000
55.7000 243.0000 1.0000
55.7600 234.0000 1.0000
55.8200 229.0000 1.0000
55.8800 252.0000 1.0000
55.9400 250.0000 1.0000
56.0000 219.0000 1.0000
56.0600 221.0000 1.0000
56.1200 245.0000 1.0000
56.1800 270.0000 1.0000
56.2400 208.0000 1.0000
56.3000 225.0000 1.0000
56.3600 251.0000 1.0000
56.4200 232.0000 1.0000
56.4800 237.0000 1.0000
56.5400 205.0000 1.0000
56.6000 206.0000 1.0000
56.6600 221.0000 1.0000
56.7200 243.0000 1.0000
56.7800 187.0000 1.0000
56.8400 231.0000 1.0000
56.9000 235.0000 1.0000
56.9600 215.0000 1.0000
57.0200 227.0000 1.0000
57.0800 222.0000 1.0000
57.1400 207.0000 1.0000
57.2000 233.0000 1.0000
57.2600 221.0000 1.0000
57.3200 222.0000 1.0000
57.3800 245.0000 1.0000
57.4400 210.0000 1.0000
57.5000 235.0000 1.0000
57.5600 229.0000 1.0000
57.6200 195.0000 1.0000
57.6800 216.0000 1.0000
57.7400 207.0000 1.0000
57.8000 219.0000 1.0000
57.8600 230.0000 1.0000
57.9200 245.0000 1.0000
57.9800 232.0000 1.0000
58.0400 223.0000 1.0000
58.1000 213.0000 1.0000
58.1600 242.0000 1.0000
58.2200 213.0000 1.0000
58.2800 226.0000 1.0000
58.3400 202.0000 1.0000
58.4000 207.0000 1.0000
58.4600 223.0000 1.0000
58.5200 232.0000 1.0000
58.5800 208.0000 1.0000
58.6400 206.0000 1.0000
58.7000 205.0000 1.0000
58.7600 220.0000 1.0000
58.8200 202.0000 1.0000
58.8800 224.0000 1.0000
58.9400 213.0000 1.0000
59.0000 196.0000 1.0000
59.0600 203.0000 1.0000
59.1200 215.0000 1.0000
59.1800 210.0000 1.0000
59.2400 227.0000 1.0000
59.3000 230.0000 1.0000
59.3600 226.0000 1.0000
59.4200 210.0000 1.0000
59.4800 215.0000 1.0000
59.5400 224.0000 1.0000
59.6000 205.0000 1.0000
59.6600 223.0000 1.0000
59.7200 210.0000 1.0000
59.7800 267.0000 1.0000
59.8400 237.0000 1.0000
59.9000 187.0000 1.0000
59.9600 234.0000 1.0000
60.0200 246.0000 1.0000
60.0800 201.0000 1.0000
60.1400 237.0000 1.0000
60.2000 195.0000 1.0000
60.2600 226.0000 1.0000
60.3200 203.0000 1.0000
60.3800 208.0000 1.0000
60.4400 204.0000 1.0000
60.5000 213.0000 1.0000
60.5600 219.0000 1.0000
60.6200 233.0000 1.0000
60.6800 233.0000 1.0000
60.7400 205.0000 1.0000
60.8000 202.0000 1.0000
60.8600 229.0000 1.0000
60.9200 195.0000 1.0000
60.9800 212.0000 1.0000
61.0400 242.0000 1.0000
61.1000 242.0000 1.0000
61.1600 240.0000 1.0000
61.2200 233.0000 1.0000
61.2800 210.0000 1.0000
61.3400 229.0000 1.0000
61.4000 223.0000 1.0000
61.4600 213.0000 1.0000
61.5200 227.0000 1.0000
61.5800 223.0000 1.0000
61.6400 232.0000 1.0000
61.7000 222.0000 1.0000
61.7600 254.0000 1.0000
61.8200 234.0000 1.0000
61.8800 239.0000 1.0000
61.9400 242.0000 1.0000
62.0000 239.0000 1.0000
62.0600 279.0000 1.0000
62.1200 339.0000 1.0000
62.1800 373.0000 1.0000
62.2400 403.0000 1.0000
62.3000 409.0000 1.0000
62.3600 394.0000 1.0000
62.4200 366.0000 1.0000
62.4800 326.0000 1.0000
62.5400 276.0000 1.0000
62.6000 294.0000 1.0000
62.6600 261.0000 1.0000
62.7200 278.0000 1.0000
62.7800 245.0000 1.0000
62.8400 231.0000 1.0000
62.9000 225.0000 1.0000
62.9600 224.0000 1.0000
63.0200 232.0000 1.0000
63.0800 231.0000 1.0000
63.1400 238.0000 1.0000
63.2000 270.0000 1.0000
63.2600 220.0000 1.0000
63.3200 221.0000 1.0000
63.3800 238.0000 1.0000
63.4400 216.0000 1.0000
63.5000 233.0000 1.0000
63.5600 252.0000 1.0000
63.6200 206.0000 1.0000
63.6800 216.0000 1.0000
63.7400 218.0000 1.0000
63.8000 233.0000 1.0000
63.8600 242.0000 1.0000
63.9200 239.0000 1.0000
63.9800 209.0000 1.0000
64.0400 211.0000 1.0000
64.1000 195.0000 1.0000
64.1600 199.0000 1.0000
64.2200 231.0000 1.0000
64.2800 232.0000 1.0000
64.3400 256.0000 1.0000
64.4000 225.0000 1.0000
64.4600 215.0000 1.0000
64.5200 268.0000 1.0000
64.5800 277.0000 1.0000
64.6400 271.0000 1.0000
64.7000 277.0000 1.0000
64.7600 294.0000 1.0000
64.8200 267.0000 1.0000
64.8800 285.0000 1.0000
64.9400 247.0000 1.0000
65.0000 271.0000 1.0000
65.0600 258.0000 1.0000
65.1200 237.0000 1.0000
65.1800 230.0000 1.0000
65.2400 216.0000 1.0000
65.3000 222.0000 1.0000
65.3600 233.0000 1.0000
65.4200 243.0000 1.0000
65.4800 228.0000 1.0000
65.5400 241.0000 1.0000
65.6000 200.0000 1.0000
65.6600 232.0000 1.0000
65.7200 239.0000 1.0000
65.7800 244.0000 1.0000
65.8400 231.0000 1.0000
65.9000 266.0000 1.0000
65.9600 279.0000 1.0000
66.0200 320.0000 1.0000
66.0800 394.0000 1.0000
66.1400 505.0000 1.0000
66.2000 649.0000 1.0000
66.2600 674.0000 1.0000
66.3200 626.0000 1.0000
66.3800 558.0000 1.0000
66.4400 499.0000 1.0000
66.5000 445.0000 1.0000
66.5600 353.0000 1.0000
66.6200 300.0000 1.0000
66.6800 261.0000 1.0000
66.7400 280.0000 1.0000
66.8000 264.0000 1.0000
66.8600 238.0000 1.0000
66.9200 226.0000 1.0000
66.9800 219.0000 1.0000
67.0400 219.0000 1.0000
67.1000 225.0000 1.0000
67.1600 224.0000 1.0000
67.2200 200.0000 1.0000
67.2800 205.0000 1.0000
67.3400 213.0000 1.0000
67.4000 213.0000 1.0000
67.4600 199.0000 1.0000
67.5200 202.0000 1.0000
67.5800 185.0000 1.0000
67.6400 197.0000 1.0000
67.7000 214.0000 1.0000
67.7600 210.0000 1.0000
67.8200 204.0000 1.0000
67.8800 236.0000 1.0000
67.9400 197.0000 1.0000
68.0000 210.0000 1.0000
68.0600 216.0000 1.0000
68.1200 205.0000 1.0000
68.1800 207.0000 1.0000
68.2400 203.0000 1.0000
68.3000 207.0000 1.0000
68.3600 201.0000 1.0000
68.4200 227.0000 1.0000
68.4800 211.0000 1.0000
68.5400 216.0000 1.0000
68.6000 203.0000 1.0000
68.6600 206.0000 1.0000
68.7200 206.0000 1.0000
68.7800 196.0000 1.0000
68.8400 213.0000 1.0000
68.9000 204.0000 1.0000
68.9600 209.0000 1.0000
69.0200 197.0000 1.0000
69.0800 211.0000 1.0000
69.1400 200.0000 1.0000
69.2000 205.0000 1.0000
69.2600 203.0000 1.0000
69.3200 204.0000 1.0000
69.3800 189.0000 1.0000
69.4400 178.0000 1.0000
69.5000 226.0000 1.0000
69.5600 225.0000 1.0000
69.6200 197.0000 1.0000
69.6800 215.0000 1.0000
69.7400 230.0000 1.0000
69.8000 205.0000 1.0000
69.8600 202.0000 1.0000
69.9200 200.0000 1.0000
69.9800 172.0000 1.0000
70.0400 214.0000 1.0000
70.1000 205.0000 1.0000
70.1600 205.0000 1.0000
70.2200 174.0000 1.0000
70.2800 206.0000 1.0000
70.3400 204.0000 1.0000
70.4000 198.0000 1.0000
70.4600 201.0000 1.0000
70.5200 199.0000 1.0000
70.5800 172.0000 1.0000
70.6400 216.0000 1.0000
70.7000 185.0000 1.0000
70.7600 215.0000 1.0000
70.8200 207.0000 1.0000
70.8800 201.0000 1.0000
70.9400 185.0000 1.0000
71.0000 193.0000 1.0000
71.0600 211.0000 1.0000
71.1200 176.0000 1.0000
71.1800 193.0000 1.0000
71.2400 193.0000 1.0000
71.3000 194.0000 1.0000
71.3600 198.0000 1.0000
71.4200 194.0000 1.0000
71.4800 195.0000 1.0000
71.5400 208.0000 1.0000
71.6000 189.0000 1.0000
71.6600 222.0000 1.0000
71.7200 223.0000 1.0000
71.7800 208.0000 1.0000
71.8400 199.0000 1.0000
71.9000 198.0000 1.0000
71.9600 226.0000 1.0000
72.0200 191.0000 1.0000
72.0800 211.0000 1.0000
72.1400 206.0000 1.0000
72.2000 166.0000 1.0000
72.2600 179.0000 1.0000
72.3200 210.0000 1.0000
72.3800 180.0000 1.0000
72.4400 184.0000 1.0000
72.5000 238.0000 1.0000
72.5600 184.0000 1.0000
72.6200 214.0000 1.0000
72.6800 208.0000 1.0000
72.7400 203.0000 1.0000
72.8000 208.0000 1.0000
72.8600 187.0000 1.0000
72.9200 200.0000 1.0000
72.9800 187.0000 1.0000
73.0400 209.0000 1.0000
73.1000 201.0000 1.0000
73.1600 202.0000 1.0000
73.2200 199.0000 1.0000
73.2800 199.0000 1.0000
73.3400 192.0000 1.0000
73.4000 189.0000 1.0000
73.4600 194.0000 1.0000
73.5200 188.0000 1.0000
73.5800 203.0000 1.0000
73.6400 184.0000 1.0000
73.7000 219.0000 1.0000
73.7600 200.0000 1.0000
73.8200 166.0000 1.0000
73.8800 160.0000 1.0000
73.9400 194.0000 1.0000
74.0000 210.0000 1.0000
74.0600 202.0000 1.0000
74.1200 171.0000 1.0000
74.1800 188.0000 1.0000
74.2400 188.0000 1.0000
74.3000 204.0000 1.0000
74.3600 179.0000 1.0000
74.4200 177.0000 1.0000
74.4800 181.0000 1.0000
74.5400 212.0000 1.0000
74.6000 159.0000 1.0000
74.6600 199.0000 1.0000
74.7200 177.0000 1.0000
74.7800 163.0000 1.0000
74.8400 177.0000 1.0000
74.9000 186.0000 1.0000
74.9600 178.0000 1.0000
75.0200 198.0000 1.0000
75.0800 183.0000 1.0000
75.1400 195.0000 1.0000
75.2000 161.0000 1.0000
75.2600 174.0000 1.0000
75.3200 175.0000 1.0000
75.3800 202.0000 1.0000
75.4400 163.0000 1.0000
75.5000 195.0000 1.0000
75.5600 181.0000 1.0000
75.6200 177.0000 1.0000
75.6800 205.0000 1.0000
75.7400 194.0000 1.0000
75.8000 179.0000 1.0000
75.8600 167.0000 1.0000
75.9200 210.0000 1.0000
75.9800 180.0000 1.0000
76.0400 187.0000 1.0000
76.1000 192.0000 1.0000
76.1600 184.0000 1.0000
76.2200 180.0000 1.0000
76.2800 191.0000 1.0000
76.3400 206.0000 1.0000
76.4000 194.0000 1.0000
76.4600 203.0000 1.0000
76.5200 193.0000 1.0000
76.5800 205.0000 1.0000
76.6400 182.0000 1.0000
76.7000 200.0000 1.0000
76.7600 187.0000 1.0000
76.8200 171.0000 1.0000
76.8800 179.0000 1.0000
76.9400 192.0000 1.0000
77.0000 184.0000 1.0000
77.0600 198.0000 1.0000
77.1200 185.0000 1.0000
77.1800 181.0000 1.0000
77.2400 167.0000 1.0000
77.3000 198.0000 1.0000
77.3600 182.0000 1.0000
77.4200 179.0000 1.0000
77.4800 171.0000 1.0000
77.5400 178.0000 1.0000
77.6000 157.0000 1.0000
77.6600 188.0000 1.0000
77.7200 201.0000 1.0000
77.7800 169.0000 1.0000
77.8400 179.0000 1.0000
77.9000 181.0000 1.0000
77.9600 190.0000 1.0000
78.0200 200.0000 1.0000
78.0800 204.0000 1.0000
78.1400 206.0000 1.0000
78.2000 159.0000 1.0000
78.2600 199.0000 1.0000
78.3200 190.0000 1.0000
78.3800 194.0000 1.0000
78.4400 178.0000 1.0000
78.5000 209.0000 1.0000
78.5600 201.0000 1.0000
78.6200 194.0000 1.0000
78.6800 178.0000 1.0000
78.7400 242.0000 1.0000
78.8000 204.0000 1.0000
78.8600 241.0000 1.0000
78.9200 235.0000 1.0000
78.9800 304.0000 1.0000
79.0400 273.0000 1.0000
79.1000 277.0000 1.0000
79.1600 266.0000 1.0000
79.2200 245.0000 1.0000
79.2800 223.0000 1.0000
79.3400 234.0000 1.0000
79.4000 185.0000 1.0000
79.4600 197.0000 1.0000
79.5200 201.0000 1.0000
79.5800 205.0000 1.0000
79.6400 200.0000 1.0000
79.7000 183.0000 1.0000
79.7600 156.0000 1.0000
79.8200 178.0000 1.0000
79.8800 183.0000 1.0000
79.9400 182.0000 1.0000
80.0000 180.0000 1.0000
*RAS_INT_END
*RAS_TEMPERATURE_START
*RAS_TEMPERATURE_END
*RAS_DATA_END