File: Section2_75_samples/XRD/No_016_700_13.ras
*RAS_DATA_START
*RAS_HEADER_START
*DISP_FMT_X "%.2f"
*DISP_FMT_Y "%.0f"
*DISP_FULLSCALE "3780.0000000000"
*DISP_LINE_COLOR "255.0000000000"
*DISP_LINE_STYLE "0.0000000000"
*DISP_LINE_WIDTH "0.2500000000"
*DISP_NOTE "測定データ-3"
*DISP_OFFSET_Y "0.0000000000"
*DISP_PEAKSEARCH_UNIT_Y "cps"
*DISP_RANGE_BOTTOM "0.0000000000"
*DISP_RANGE_LEFT "20.0000000000"
*DISP_RANGE_LOGCUTOFF "0.0100000000"
*DISP_RANGE_RIGHT "80.0000000000"
*DISP_RANGE_TOP "3780.0000000000"
*DISP_SCALE_MODE_Y "0.0000000000"
*DISP_TAB_NAME "2θ/θ"
*DISP_TITLE_Y "強度"
*DISP_UNIT_Y "cps"
*DISP_WINDOW_NAME "MSG_MACROENGINE"
*FILE_COMMENT " "
*FILE_MD5 ""
*FILE_MEMO " "
*FILE_OPERATOR "Administrator"
*FILE_SAMPLE " "
*FILE_TYPE "RAS_RAW"
*FILE_USERGROUP "システムマネージャ"
*FILE_VERSION "1.0000000000"
*HW_ATTACHMENT_ID "ATT0025"
*HW_ATTACHMENT_NAME "標準|Standard"
*HW_COUNTER_ID-0 "CUT0025"
*HW_COUNTER_ID-1 "CUT0020"
*HW_COUNTER_ID-2 "CUT0020"
*HW_COUNTER_ID-3 "CSL0021"
*HW_COUNTER_ID-4 "CMC0021"
*HW_COUNTER_NAME-0 "D/teX Ultra|D/teX Ultra"
*HW_COUNTER_NAME-1 "None|None"
*HW_COUNTER_NAME-2 "None|None"
*HW_COUNTER_NAME-3 "BBM|BBM"
*HW_COUNTER_NAME-4 "検出器モノクロメータ|Detector monochromator"
*HW_COUNTER_SELECT_NAME "D/teX Ultra|D/teX Ultra"
*HW_GONIOMETER_ID "GON0023"
*HW_GONIOMETER_NAME "SmartLab|SmartLab"
*HW_GONIOMETER_RADIUS-0 "90.0"
*HW_GONIOMETER_RADIUS-1 "114.0"
*HW_GONIOMETER_RADIUS-2 "190.0"
*HW_GONIOMETER_RADIUS-3 "300.0"
*HW_GONIOMETER_RADIUS-4 "187.0"
*HW_GONIOMETER_RADIUS-5 "300.0"
*HW_GONIOMETER_RADIUS-6 "113.0"
*HW_GONIOMETER_RADIUS-7 "331.0"
*HW_I_OPT_ID-0 "CBO0021"
*HW_I_OPT_ID-1 "ICR0023"
*HW_I_OPT_ID-2 "ISL0021"
*HW_I_OPT_ID-3 "ISO0021"
*HW_I_OPT_ID-4 "IAD0021"
*HW_I_OPT_ID-5 "IPR0001"
*HW_I_OPT_NAME-0 "CBOユニット|CBO unit"
*HW_I_OPT_NAME-1 "標準入射光学ユニット|Standard incident optical unit"
*HW_I_OPT_NAME-2 "標準入射スリットボックス|Standard incident slit box"
*HW_I_OPT_NAME-3 "入射平行スリット|Incident parallel slit"
*HW_I_OPT_NAME-4 "長手制限スリット|Length limiting slit"
*HW_I_OPT_NAME-5 "None|None"
*HW_R_ATTENUATER_AUTOMODE "0"
*HW_R_OPT_ID-0 "RSS0021"
*HW_R_OPT_ID-1 "RCR0023"
*HW_R_OPT_ID-2 "RSO0021"
*HW_R_OPT_ID-3 "RRS0021"
*HW_R_OPT_ID-4 "ATN0021"
*HW_R_OPT_ID-5 "RFL0021"
*HW_R_OPT_ID-6 "RAD0021"
*HW_R_OPT_NAME-0 "標準受光スリットボックス1|Standard receiving slit box # 1"
*HW_R_OPT_NAME-1 "標準受光光学ユニット1|Standard receiving unit # 1"
*HW_R_OPT_NAME-2 "標準受光光学ユニット2|Standard receiving optical unit # 2"
*HW_R_OPT_NAME-3 "標準受光スリットボックス2|Standard receiving slit box # 2"
*HW_R_OPT_NAME-4 "標準アッテネータ|Standard Attenuator"
*HW_R_OPT_NAME-5 "Cu Kβ|Cu K-beta"
*HW_R_OPT_NAME-6 "調整用受光スリット|Alignment receiving slit"
*HW_SAMPLE_HOLDER_ID "SMP0023"
*HW_SAMPLE_HOLDER_NAME "標準Zステージ|Standard Z stage"
*HW_XG_CURRENT_MAX "50"
*HW_XG_CURRENT_MIN "2"
*HW_XG_CURRENT_RESOLUTION "2"
*HW_XG_CURRENT_UNIT "mA"
*HW_XG_FOCUS "1mm x 10mm"
*HW_XG_FOCUS_TYPE "Normal"
*HW_XG_ID ""
*HW_XG_NAME "3kW 封入管(ID:1200)|3kW Sealed tube(ID:1200)"
*HW_XG_TARGET_ATOMIC_NUMBER "29.0000000000"
*HW_XG_TARGET_NAME "Cu"
*HW_XG_TYPE "Hermetic"
*HW_XG_VOLTAGE_MAX "60"
*HW_XG_VOLTAGE_MIN "20"
*HW_XG_VOLTAGE_RESOLUTION "2"
*HW_XG_VOLTAGE_UNIT "kV"
*HW_XG_WATT_MAX "2"
*HW_XG_WATT_UNIT "kW"
*HW_XG_WAVE_LENGTH_ALPHA1 "1.540593"
*HW_XG_WAVE_LENGTH_ALPHA2 "1.544414"
*HW_XG_WAVE_LENGTH_BETA "1.392250"
*MEAS_COND_AXIS_NAME-0 "2θ/θ"
*MEAS_COND_AXIS_NAME-1 "2θ"
*MEAS_COND_AXIS_NAME-2 "ω"
*MEAS_COND_AXIS_NAME-3 "Z"
*MEAS_COND_AXIS_NAME-4 "2θ/ω"
*MEAS_COND_AXIS_NAME-5 "θs"
*MEAS_COND_AXIS_NAME-6 "θd"
*MEAS_COND_AXIS_NAME-7 "Ts"
*MEAS_COND_AXIS_NAME-8 "CBO選択スリット"
*MEAS_COND_AXIS_NAME-9 "M"
*MEAS_COND_AXIS_NAME-10 "入射平行スリット"
*MEAS_COND_AXIS_NAME-11 "入射スリット"
*MEAS_COND_AXIS_NAME-12 ""
*MEAS_COND_AXIS_NAME-13 "Zs"
*MEAS_COND_AXIS_NAME-14 "入射光学素子"
*MEAS_COND_AXIS_NAME-15 "長手制限スリット"
*MEAS_COND_AXIS_NAME-16 "センタースリット"
*MEAS_COND_AXIS_NAME-17 "フィルター"
*MEAS_COND_AXIS_NAME-18 "受光スリット1"
*MEAS_COND_AXIS_NAME-19 "受光スリット2"
*MEAS_COND_AXIS_NAME-20 "受光光学素子"
*MEAS_COND_AXIS_NAME-21 "受光平行スリット"
*MEAS_COND_AXIS_NAME-22 "調整用受光スリット"
*MEAS_COND_AXIS_NAME-23 ""
*MEAS_COND_AXIS_NAME-24 ""
*MEAS_COND_AXIS_NAME-25 "Zd"
*MEAS_COND_AXIS_NAME-26 "アッテネータ"
*MEAS_COND_AXIS_NAME-27 "検出器モノクロメータ"
*MEAS_COND_AXIS_NAME-28 "モノクロメータスリット"
*MEAS_COND_AXIS_NAME-29 "プライマリビーム"
*MEAS_COND_AXIS_NAME-30 "PHA"
*MEAS_COND_AXIS_NAME_INTERNAL-0 "TwoThetaTheta"
*MEAS_COND_AXIS_NAME_INTERNAL-1 "TwoTheta"
*MEAS_COND_AXIS_NAME_INTERNAL-2 "Omega"
*MEAS_COND_AXIS_NAME_INTERNAL-3 "Z"
*MEAS_COND_AXIS_NAME_INTERNAL-4 "TwoThetaOmega"
*MEAS_COND_AXIS_NAME_INTERNAL-5 "ThetaS"
*MEAS_COND_AXIS_NAME_INTERNAL-6 "ThetaD"
*MEAS_COND_AXIS_NAME_INTERNAL-7 "Ts"
*MEAS_COND_AXIS_NAME_INTERNAL-8 "CBO"
*MEAS_COND_AXIS_NAME_INTERNAL-9 "CBO-M"
*MEAS_COND_AXIS_NAME_INTERNAL-10 "IncidentSollerSlit"
*MEAS_COND_AXIS_NAME_INTERNAL-11 "IncidentSlitBox"
*MEAS_COND_AXIS_NAME_INTERNAL-12 "IncidentSlitBox-_Axis"
*MEAS_COND_AXIS_NAME_INTERNAL-13 "Zs"
*MEAS_COND_AXIS_NAME_INTERNAL-14 "IncidentMonochromator"
*MEAS_COND_AXIS_NAME_INTERNAL-15 "IncidentAxdSlit"
*MEAS_COND_AXIS_NAME_INTERNAL-16 "CenterSlit"
*MEAS_COND_AXIS_NAME_INTERNAL-17 "Filter"
*MEAS_COND_AXIS_NAME_INTERNAL-18 "ReceivingSlitBox1"
*MEAS_COND_AXIS_NAME_INTERNAL-19 "ReceivingSlitBox2"
*MEAS_COND_AXIS_NAME_INTERNAL-20 "ReceivingOptics"
*MEAS_COND_AXIS_NAME_INTERNAL-21 "ReceivingSollerSlit"
*MEAS_COND_AXIS_NAME_INTERNAL-22 "ReceivingAxdSlit"
*MEAS_COND_AXIS_NAME_INTERNAL-23 "ReceivingSlitBox1-_Axis"
*MEAS_COND_AXIS_NAME_INTERNAL-24 "ReceivingSlitBox2-_Axis"
*MEAS_COND_AXIS_NAME_INTERNAL-25 "ReceivingSlitBox2-Zd"
*MEAS_COND_AXIS_NAME_INTERNAL-26 "Attenuator"
*MEAS_COND_AXIS_NAME_INTERNAL-27 "CounterMonochromator"
*MEAS_COND_AXIS_NAME_INTERNAL-28 "CounterSlit"
*MEAS_COND_AXIS_NAME_INTERNAL-29 "IncidentPrimary"
*MEAS_COND_AXIS_NAME_INTERNAL-30 "PHA"
*MEAS_COND_AXIS_NAME_MAGICNO-0 "83951616.0000000000"
*MEAS_COND_AXIS_NAME_MAGICNO-1 "268632064.0000000000"
*MEAS_COND_AXIS_NAME_MAGICNO-2 "268500992.0000000000"
*MEAS_COND_AXIS_NAME_MAGICNO-3 "285278208.0000000000"
*MEAS_COND_AXIS_NAME_MAGICNO-4 "83951616.0000000000"
*MEAS_COND_AXIS_NAME_MAGICNO-5 "131072.0000000000"
*MEAS_COND_AXIS_NAME_MAGICNO-6 "131072.0000000000"
*MEAS_COND_AXIS_NAME_MAGICNO-7 "318898176.0000000000"
*MEAS_COND_AXIS_NAME_MAGICNO-8 "20971521.0000000000"
*MEAS_COND_AXIS_NAME_MAGICNO-9 "285343744.0000000000"
*MEAS_COND_AXIS_NAME_MAGICNO-10 "20971521.0000000000"
*MEAS_COND_AXIS_NAME_MAGICNO-11 "22020097.0000000000"
*MEAS_COND_AXIS_NAME_MAGICNO-12 "25165824.0000000000"
*MEAS_COND_AXIS_NAME_MAGICNO-13 "318898176.0000000000"
*MEAS_COND_AXIS_NAME_MAGICNO-14 "1.0000000000"
*MEAS_COND_AXIS_NAME_MAGICNO-15 "20971521.0000000000"
*MEAS_COND_AXIS_NAME_MAGICNO-16 "20971521.0000000000"
*MEAS_COND_AXIS_NAME_MAGICNO-17 "20971521.0000000000"
*MEAS_COND_AXIS_NAME_MAGICNO-18 "23068673.0000000000"
*MEAS_COND_AXIS_NAME_MAGICNO-19 "23068673.0000000000"
*MEAS_COND_AXIS_NAME_MAGICNO-20 "20971521.0000000000"
*MEAS_COND_AXIS_NAME_MAGICNO-21 "20971521.0000000000"
*MEAS_COND_AXIS_NAME_MAGICNO-22 "20971521.0000000000"
*MEAS_COND_AXIS_NAME_MAGICNO-23 "25165824.0000000000"
*MEAS_COND_AXIS_NAME_MAGICNO-24 "25165824.0000000000"
*MEAS_COND_AXIS_NAME_MAGICNO-25 "285343744.0000000000"
*MEAS_COND_AXIS_NAME_MAGICNO-26 "17301505.0000000000"
*MEAS_COND_AXIS_NAME_MAGICNO-27 "20971521.0000000000"
*MEAS_COND_AXIS_NAME_MAGICNO-28 "20971521.0000000000"
*MEAS_COND_AXIS_NAME_MAGICNO-29 "20971521.0000000000"
*MEAS_COND_AXIS_NAME_MAGICNO-30 "0.0000000000"
*MEAS_COND_AXIS_OFFSET-0 "-"
*MEAS_COND_AXIS_OFFSET-1 "-0.1081000000"
*MEAS_COND_AXIS_OFFSET-2 "0.3758000000"
*MEAS_COND_AXIS_OFFSET-3 "-"
*MEAS_COND_AXIS_OFFSET-4 "-"
*MEAS_COND_AXIS_OFFSET-5 "0.3758000000"
*MEAS_COND_AXIS_OFFSET-6 "-0.4839000000"
*MEAS_COND_AXIS_OFFSET-7 "-"
*MEAS_COND_AXIS_OFFSET-8 "-"
*MEAS_COND_AXIS_OFFSET-9 "-"
*MEAS_COND_AXIS_OFFSET-10 "-"
*MEAS_COND_AXIS_OFFSET-11 "-"
*MEAS_COND_AXIS_OFFSET-12 "-"
*MEAS_COND_AXIS_OFFSET-13 "-"
*MEAS_COND_AXIS_OFFSET-14 "-"
*MEAS_COND_AXIS_OFFSET-15 "-"
*MEAS_COND_AXIS_OFFSET-16 "-"
*MEAS_COND_AXIS_OFFSET-17 "-"
*MEAS_COND_AXIS_OFFSET-18 "-"
*MEAS_COND_AXIS_OFFSET-19 "-"
*MEAS_COND_AXIS_OFFSET-20 "-"
*MEAS_COND_AXIS_OFFSET-21 "-"
*MEAS_COND_AXIS_OFFSET-22 "-"
*MEAS_COND_AXIS_OFFSET-23 "-"
*MEAS_COND_AXIS_OFFSET-24 "-"
*MEAS_COND_AXIS_OFFSET-25 "-"
*MEAS_COND_AXIS_OFFSET-26 "-"
*MEAS_COND_AXIS_OFFSET-27 "-"
*MEAS_COND_AXIS_OFFSET-28 "-"
*MEAS_COND_AXIS_OFFSET-29 "-"
*MEAS_COND_AXIS_OFFSET-30 "-"
*MEAS_COND_AXIS_POSITION-0 "0.0000000000"
*MEAS_COND_AXIS_POSITION-1 "0.0000000000"
*MEAS_COND_AXIS_POSITION-2 "0.0000000000"
*MEAS_COND_AXIS_POSITION-3 "-0.5500000000"
*MEAS_COND_AXIS_POSITION-4 "0.0000000000"
*MEAS_COND_AXIS_POSITION-5 "0.0000000000"
*MEAS_COND_AXIS_POSITION-6 "0.0000000000"
*MEAS_COND_AXIS_POSITION-7 "-0.4278800000"
*MEAS_COND_AXIS_POSITION-8 "BB"
*MEAS_COND_AXIS_POSITION-9 "0.0000000000"
*MEAS_COND_AXIS_POSITION-10 "Soller_slit_5.0deg"
*MEAS_COND_AXIS_POSITION-11 "2/3deg"
*MEAS_COND_AXIS_POSITION-12 "2.2088000000"
*MEAS_COND_AXIS_POSITION-13 "-0.4140600000"
*MEAS_COND_AXIS_POSITION-14 "0.0000000000"
*MEAS_COND_AXIS_POSITION-15 "10.0mm"
*MEAS_COND_AXIS_POSITION-16 "None"
*MEAS_COND_AXIS_POSITION-17 "Cu_K-beta"
*MEAS_COND_AXIS_POSITION-18 "13.000mm"
*MEAS_COND_AXIS_POSITION-19 "13.000mm"
*MEAS_COND_AXIS_POSITION-20 "No_unit"
*MEAS_COND_AXIS_POSITION-21 "Soller_slit_5.0deg"
*MEAS_COND_AXIS_POSITION-22 "None"
*MEAS_COND_AXIS_POSITION-23 "13.0000000000"
*MEAS_COND_AXIS_POSITION-24 "13.0000000000"
*MEAS_COND_AXIS_POSITION-25 "0.0109400000"
*MEAS_COND_AXIS_POSITION-26 "Open"
*MEAS_COND_AXIS_POSITION-27 "None"
*MEAS_COND_AXIS_POSITION-28 "None"
*MEAS_COND_AXIS_POSITION-29 "None"
*MEAS_COND_AXIS_POSITION-30 "38.0000000000"
*MEAS_COND_AXIS_UNIT-0 "deg"
*MEAS_COND_AXIS_UNIT-1 "deg"
*MEAS_COND_AXIS_UNIT-2 "deg"
*MEAS_COND_AXIS_UNIT-3 "mm"
*MEAS_COND_AXIS_UNIT-4 "deg"
*MEAS_COND_AXIS_UNIT-5 "deg"
*MEAS_COND_AXIS_UNIT-6 "deg"
*MEAS_COND_AXIS_UNIT-7 "mm"
*MEAS_COND_AXIS_UNIT-8 ""
*MEAS_COND_AXIS_UNIT-9 "pulse"
*MEAS_COND_AXIS_UNIT-10 ""
*MEAS_COND_AXIS_UNIT-11 ""
*MEAS_COND_AXIS_UNIT-12 "mm"
*MEAS_COND_AXIS_UNIT-13 "mm"
*MEAS_COND_AXIS_UNIT-14 ""
*MEAS_COND_AXIS_UNIT-15 ""
*MEAS_COND_AXIS_UNIT-16 ""
*MEAS_COND_AXIS_UNIT-17 ""
*MEAS_COND_AXIS_UNIT-18 ""
*MEAS_COND_AXIS_UNIT-19 ""
*MEAS_COND_AXIS_UNIT-20 ""
*MEAS_COND_AXIS_UNIT-21 ""
*MEAS_COND_AXIS_UNIT-22 ""
*MEAS_COND_AXIS_UNIT-23 "mm"
*MEAS_COND_AXIS_UNIT-24 "mm"
*MEAS_COND_AXIS_UNIT-25 "mm"
*MEAS_COND_AXIS_UNIT-26 ""
*MEAS_COND_AXIS_UNIT-27 ""
*MEAS_COND_AXIS_UNIT-28 ""
*MEAS_COND_AXIS_UNIT-29 ""
*MEAS_COND_AXIS_UNIT-30 "div"
*MEAS_COND_COUNTER_CNTLOSS_CORR "0.0000000000"
*MEAS_COND_COUNTER_PHABASE "38.0000000000"
*MEAS_COND_COUNTER_PHAWINDOW "16.0000000000"
*MEAS_COND_COUNTER_PHA_UNIT "div"
*MEAS_COND_COUNTER_TAUDIFF "30.0000000000"
*MEAS_COND_COUNTER_TAUINT "0.0000000000"
*MEAS_COND_IRRADIATION_MODE "OFF"
*MEAS_COND_IRRADIATION_WIDTH ""
*MEAS_COND_OPT_ATTR "集中法"
*MEAS_COND_OPT_NAME "@集中法"
*MEAS_COND_UNSYMMETRIC_MODE "OFF"
*MEAS_COND_XG_CURRENT "30.0000000000"
*MEAS_COND_XG_VOLTAGE "40.0000000000"
*MEAS_COND_XG_WAVE_TYPE "Ka"
*MEAS_DATA_COUNT "3001.0000000000"
*MEAS_SCAN_AXIS_X "2θ/θ"
*MEAS_SCAN_AXIS_X_INTERNAL "TwoThetaTheta"
*MEAS_SCAN_END_TIME "08/27/20 12:34:21"
*MEAS_SCAN_MODE "CONTINUOUS"
*MEAS_SCAN_MONITOR "0"
*MEAS_SCAN_RESOLUTION_X "0.0002"
*MEAS_SCAN_SPEED "2.0"
*MEAS_SCAN_SPEED_UNIT "deg/min"
*MEAS_SCAN_START "20.0000000000"
*MEAS_SCAN_START_TIME "08/27/20 12:02:41"
*MEAS_SCAN_STEP "0.0200000000"
*MEAS_SCAN_STOP "80.0000000000"
*MEAS_SCAN_UNIT_X "deg"
*MEAS_SCAN_UNIT_Y "counts"
*RAS_HEADER_END
*RAS_INT_START
20.0000 1834.0000 1.0000
20.0600 1784.0000 1.0000
20.1200 1878.0000 1.0000
20.1800 1847.0000 1.0000
20.2400 1795.0000 1.0000
20.3000 1807.0000 1.0000
20.3600 1730.0000 1.0000
20.4200 1816.0000 1.0000
20.4800 1680.0000 1.0000
20.5400 1755.0000 1.0000
20.6000 1764.0000 1.0000
20.6600 1725.0000 1.0000
20.7200 1775.0000 1.0000
20.7800 1701.0000 1.0000
20.8400 1728.0000 1.0000
20.9000 1725.0000 1.0000
20.9600 1726.0000 1.0000
21.0200 1575.0000 1.0000
21.0800 1738.0000 1.0000
21.1400 1695.0000 1.0000
21.2000 1666.0000 1.0000
21.2600 1675.0000 1.0000
21.3200 1657.0000 1.0000
21.3800 1613.0000 1.0000
21.4400 1593.0000 1.0000
21.5000 1569.0000 1.0000
21.5600 1603.0000 1.0000
21.6200 1590.0000 1.0000
21.6800 1558.0000 1.0000
21.7400 1587.0000 1.0000
21.8000 1601.0000 1.0000
21.8600 1552.0000 1.0000
21.9200 1490.0000 1.0000
21.9800 1525.0000 1.0000
22.0400 1504.0000 1.0000
22.1000 1542.0000 1.0000
22.1600 1524.0000 1.0000
22.2200 1506.0000 1.0000
22.2800 1488.0000 1.0000
22.3400 1465.0000 1.0000
22.4000 1460.0000 1.0000
22.4600 1503.0000 1.0000
22.5200 1456.0000 1.0000
22.5800 1405.0000 1.0000
22.6400 1434.0000 1.0000
22.7000 1481.0000 1.0000
22.7600 1468.0000 1.0000
22.8200 1431.0000 1.0000
22.8800 1339.0000 1.0000
22.9400 1417.0000 1.0000
23.0000 1514.0000 1.0000
23.0600 1380.0000 1.0000
23.1200 1372.0000 1.0000
23.1800 1369.0000 1.0000
23.2400 1388.0000 1.0000
23.3000 1344.0000 1.0000
23.3600 1411.0000 1.0000
23.4200 1309.0000 1.0000
23.4800 1363.0000 1.0000
23.5400 1380.0000 1.0000
23.6000 1335.0000 1.0000
23.6600 1303.0000 1.0000
23.7200 1373.0000 1.0000
23.7800 1410.0000 1.0000
23.8400 1310.0000 1.0000
23.9000 1350.0000 1.0000
23.9600 1303.0000 1.0000
24.0200 1288.0000 1.0000
24.0800 1352.0000 1.0000
24.1400 1255.0000 1.0000
24.2000 1230.0000 1.0000
24.2600 1265.0000 1.0000
24.3200 1280.0000 1.0000
24.3800 1267.0000 1.0000
24.4400 1318.0000 1.0000
24.5000 1230.0000 1.0000
24.5600 1244.0000 1.0000
24.6200 1269.0000 1.0000
24.6800 1249.0000 1.0000
24.7400 1252.0000 1.0000
24.8000 1241.0000 1.0000
24.8600 1196.0000 1.0000
24.9200 1233.0000 1.0000
24.9800 1197.0000 1.0000
25.0400 1227.0000 1.0000
25.1000 1232.0000 1.0000
25.1600 1214.0000 1.0000
25.2200 1199.0000 1.0000
25.2800 1168.0000 1.0000
25.3400 1215.0000 1.0000
25.4000 1110.0000 1.0000
25.4600 1161.0000 1.0000
25.5200 1135.0000 1.0000
25.5800 1202.0000 1.0000
25.6400 1144.0000 1.0000
25.7000 1149.0000 1.0000
25.7600 1141.0000 1.0000
25.8200 1139.0000 1.0000
25.8800 1094.0000 1.0000
25.9400 1142.0000 1.0000
26.0000 1130.0000 1.0000
26.0600 1138.0000 1.0000
26.1200 1127.0000 1.0000
26.1800 1076.0000 1.0000
26.2400 1145.0000 1.0000
26.3000 1113.0000 1.0000
26.3600 1067.0000 1.0000
26.4200 1101.0000 1.0000
26.4800 1095.0000 1.0000
26.5400 1121.0000 1.0000
26.6000 1077.0000 1.0000
26.6600 1054.0000 1.0000
26.7200 1045.0000 1.0000
26.7800 1064.0000 1.0000
26.8400 1082.0000 1.0000
26.9000 1099.0000 1.0000
26.9600 1039.0000 1.0000
27.0200 1092.0000 1.0000
27.0800 1093.0000 1.0000
27.1400 1122.0000 1.0000
27.2000 1270.0000 1.0000
27.2600 1367.0000 1.0000
27.3200 1441.0000 1.0000
27.3800 1338.0000 1.0000
27.4400 1144.0000 1.0000
27.5000 1131.0000 1.0000
27.5600 1060.0000 1.0000
27.6200 1024.0000 1.0000
27.6800 977.0000 1.0000
27.7400 1047.0000 1.0000
27.8000 974.0000 1.0000
27.8600 1026.0000 1.0000
27.9200 1015.0000 1.0000
27.9800 975.0000 1.0000
28.0400 992.0000 1.0000
28.1000 969.0000 1.0000
28.1600 972.0000 1.0000
28.2200 901.0000 1.0000
28.2800 937.0000 1.0000
28.3400 951.0000 1.0000
28.4000 903.0000 1.0000
28.4600 957.0000 1.0000
28.5200 903.0000 1.0000
28.5800 949.0000 1.0000
28.6400 933.0000 1.0000
28.7000 874.0000 1.0000
28.7600 892.0000 1.0000
28.8200 881.0000 1.0000
28.8800 880.0000 1.0000
28.9400 876.0000 1.0000
29.0000 883.0000 1.0000
29.0600 876.0000 1.0000
29.1200 943.0000 1.0000
29.1800 830.0000 1.0000
29.2400 844.0000 1.0000
29.3000 861.0000 1.0000
29.3600 881.0000 1.0000
29.4200 863.0000 1.0000
29.4800 833.0000 1.0000
29.5400 853.0000 1.0000
29.6000 832.0000 1.0000
29.6600 831.0000 1.0000
29.7200 838.0000 1.0000
29.7800 827.0000 1.0000
29.8400 814.0000 1.0000
29.9000 823.0000 1.0000
29.9600 852.0000 1.0000
30.0200 865.0000 1.0000
30.0800 792.0000 1.0000
30.1400 799.0000 1.0000
30.2000 794.0000 1.0000
30.2600 760.0000 1.0000
30.3200 836.0000 1.0000
30.3800 796.0000 1.0000
30.4400 807.0000 1.0000
30.5000 769.0000 1.0000
30.5600 776.0000 1.0000
30.6200 802.0000 1.0000
30.6800 820.0000 1.0000
30.7400 777.0000 1.0000
30.8000 764.0000 1.0000
30.8600 720.0000 1.0000
30.9200 769.0000 1.0000
30.9800 760.0000 1.0000
31.0400 791.0000 1.0000
31.1000 787.0000 1.0000
31.1600 748.0000 1.0000
31.2200 776.0000 1.0000
31.2800 733.0000 1.0000
31.3400 798.0000 1.0000
31.4000 727.0000 1.0000
31.4600 710.0000 1.0000
31.5200 726.0000 1.0000
31.5800 748.0000 1.0000
31.6400 694.0000 1.0000
31.7000 694.0000 1.0000
31.7600 729.0000 1.0000
31.8200 727.0000 1.0000
31.8800 701.0000 1.0000
31.9400 716.0000 1.0000
32.0000 663.0000 1.0000
32.0600 649.0000 1.0000
32.1200 718.0000 1.0000
32.1800 677.0000 1.0000
32.2400 683.0000 1.0000
32.3000 711.0000 1.0000
32.3600 672.0000 1.0000
32.4200 688.0000 1.0000
32.4800 620.0000 1.0000
32.5400 662.0000 1.0000
32.6000 639.0000 1.0000
32.6600 651.0000 1.0000
32.7200 683.0000 1.0000
32.7800 649.0000 1.0000
32.8400 650.0000 1.0000
32.9000 636.0000 1.0000
32.9600 681.0000 1.0000
33.0200 648.0000 1.0000
33.0800 666.0000 1.0000
33.1400 697.0000 1.0000
33.2000 605.0000 1.0000
33.2600 656.0000 1.0000
33.3200 643.0000 1.0000
33.3800 641.0000 1.0000
33.4400 630.0000 1.0000
33.5000 640.0000 1.0000
33.5600 661.0000 1.0000
33.6200 615.0000 1.0000
33.6800 625.0000 1.0000
33.7400 594.0000 1.0000
33.8000 640.0000 1.0000
33.8600 608.0000 1.0000
33.9200 612.0000 1.0000
33.9800 677.0000 1.0000
34.0400 634.0000 1.0000
34.1000 628.0000 1.0000
34.1600 609.0000 1.0000
34.2200 608.0000 1.0000
34.2800 640.0000 1.0000
34.3400 665.0000 1.0000
34.4000 755.0000 1.0000
34.4600 810.0000 1.0000
34.5200 810.0000 1.0000
34.5800 803.0000 1.0000
34.6400 762.0000 1.0000
34.7000 662.0000 1.0000
34.7600 633.0000 1.0000
34.8200 639.0000 1.0000
34.8800 596.0000 1.0000
34.9400 585.0000 1.0000
35.0000 572.0000 1.0000
35.0600 604.0000 1.0000
35.1200 598.0000 1.0000
35.1800 585.0000 1.0000
35.2400 550.0000 1.0000
35.3000 580.0000 1.0000
35.3600 567.0000 1.0000
35.4200 544.0000 1.0000
35.4800 528.0000 1.0000
35.5400 544.0000 1.0000
35.6000 520.0000 1.0000
35.6600 582.0000 1.0000
35.7200 554.0000 1.0000
35.7800 537.0000 1.0000
35.8400 560.0000 1.0000
35.9000 510.0000 1.0000
35.9600 549.0000 1.0000
36.0200 574.0000 1.0000
36.0800 533.0000 1.0000
36.1400 538.0000 1.0000
36.2000 531.0000 1.0000
36.2600 565.0000 1.0000
36.3200 582.0000 1.0000
36.3800 575.0000 1.0000
36.4400 544.0000 1.0000
36.5000 542.0000 1.0000
36.5600 510.0000 1.0000
36.6200 499.0000 1.0000
36.6800 498.0000 1.0000
36.7400 516.0000 1.0000
36.8000 569.0000 1.0000
36.8600 462.0000 1.0000
36.9200 473.0000 1.0000
36.9800 450.0000 1.0000
37.0400 515.0000 1.0000
37.1000 487.0000 1.0000
37.1600 478.0000 1.0000
37.2200 483.0000 1.0000
37.2800 497.0000 1.0000
37.3400 476.0000 1.0000
37.4000 478.0000 1.0000
37.4600 452.0000 1.0000
37.5200 463.0000 1.0000
37.5800 462.0000 1.0000
37.6400 487.0000 1.0000
37.7000 460.0000 1.0000
37.7600 459.0000 1.0000
37.8200 478.0000 1.0000
37.8800 468.0000 1.0000
37.9400 463.0000 1.0000
38.0000 471.0000 1.0000
38.0600 497.0000 1.0000
38.1200 450.0000 1.0000
38.1800 506.0000 1.0000
38.2400 528.0000 1.0000
38.3000 565.0000 1.0000
38.3600 645.0000 1.0000
38.4200 788.0000 1.0000
38.4800 905.0000 1.0000
38.5400 1105.0000 1.0000
38.6000 1031.0000 1.0000
38.6600 845.0000 1.0000
38.7200 654.0000 1.0000
38.7800 588.0000 1.0000
38.8400 527.0000 1.0000
38.9000 492.0000 1.0000
38.9600 474.0000 1.0000
39.0200 449.0000 1.0000
39.0800 418.0000 1.0000
39.1400 460.0000 1.0000
39.2000 417.0000 1.0000
39.2600 400.0000 1.0000
39.3200 428.0000 1.0000
39.3800 418.0000 1.0000
39.4400 428.0000 1.0000
39.5000 419.0000 1.0000
39.5600 403.0000 1.0000
39.6200 428.0000 1.0000
39.6800 436.0000 1.0000
39.7400 420.0000 1.0000
39.8000 441.0000 1.0000
39.8600 440.0000 1.0000
39.9200 411.0000 1.0000
39.9800 366.0000 1.0000
40.0400 403.0000 1.0000
40.1000 389.0000 1.0000
40.1600 393.0000 1.0000
40.2200 420.0000 1.0000
40.2800 372.0000 1.0000
40.3400 382.0000 1.0000
40.4000 407.0000 1.0000
40.4600 390.0000 1.0000
40.5200 393.0000 1.0000
40.5800 395.0000 1.0000
40.6400 402.0000 1.0000
40.7000 374.0000 1.0000
40.7600 379.0000 1.0000
40.8200 381.0000 1.0000
40.8800 393.0000 1.0000
40.9400 390.0000 1.0000
41.0000 393.0000 1.0000
41.0600 436.0000 1.0000
41.1200 364.0000 1.0000
41.1800 370.0000 1.0000
41.2400 385.0000 1.0000
41.3000 382.0000 1.0000
41.3600 370.0000 1.0000
41.4200 367.0000 1.0000
41.4800 406.0000 1.0000
41.5400 369.0000 1.0000
41.6000 364.0000 1.0000
41.6600 383.0000 1.0000
41.7200 381.0000 1.0000
41.7800 374.0000 1.0000
41.8400 407.0000 1.0000
41.9000 377.0000 1.0000
41.9600 356.0000 1.0000
42.0200 353.0000 1.0000
42.0800 391.0000 1.0000
42.1400 370.0000 1.0000
42.2000 366.0000 1.0000
42.2600 376.0000 1.0000
42.3200 353.0000 1.0000
42.3800 378.0000 1.0000
42.4400 373.0000 1.0000
42.5000 332.0000 1.0000
42.5600 346.0000 1.0000
42.6200 352.0000 1.0000
42.6800 351.0000 1.0000
42.7400 359.0000 1.0000
42.8000 351.0000 1.0000
42.8600 327.0000 1.0000
42.9200 358.0000 1.0000
42.9800 351.0000 1.0000
43.0400 367.0000 1.0000
43.1000 379.0000 1.0000
43.1600 345.0000 1.0000
43.2200 362.0000 1.0000
43.2800 380.0000 1.0000
43.3400 374.0000 1.0000
43.4000 365.0000 1.0000
43.4600 333.0000 1.0000
43.5200 330.0000 1.0000
43.5800 311.0000 1.0000
43.6400 326.0000 1.0000
43.7000 343.0000 1.0000
43.7600 357.0000 1.0000
43.8200 353.0000 1.0000
43.8800 325.0000 1.0000
43.9400 317.0000 1.0000
44.0000 362.0000 1.0000
44.0600 332.0000 1.0000
44.1200 342.0000 1.0000
44.1800 318.0000 1.0000
44.2400 328.0000 1.0000
44.3000 332.0000 1.0000
44.3600 350.0000 1.0000
44.4200 335.0000 1.0000
44.4800 358.0000 1.0000
44.5400 292.0000 1.0000
44.6000 324.0000 1.0000
44.6600 337.0000 1.0000
44.7200 319.0000 1.0000
44.7800 314.0000 1.0000
44.8400 302.0000 1.0000
44.9000 317.0000 1.0000
44.9600 321.0000 1.0000
45.0200 281.0000 1.0000
45.0800 311.0000 1.0000
45.1400 284.0000 1.0000
45.2000 309.0000 1.0000
45.2600 303.0000 1.0000
45.3200 320.0000 1.0000
45.3800 322.0000 1.0000
45.4400 329.0000 1.0000
45.5000 333.0000 1.0000
45.5600 314.0000 1.0000
45.6200 302.0000 1.0000
45.6800 339.0000 1.0000
45.7400 336.0000 1.0000
45.8000 305.0000 1.0000
45.8600 304.0000 1.0000
45.9200 305.0000 1.0000
45.9800 287.0000 1.0000
46.0400 303.0000 1.0000
46.1000 294.0000 1.0000
46.1600 317.0000 1.0000
46.2200 334.0000 1.0000
46.2800 291.0000 1.0000
46.3400 303.0000 1.0000
46.4000 282.0000 1.0000
46.4600 294.0000 1.0000
46.5200 280.0000 1.0000
46.5800 317.0000 1.0000
46.6400 270.0000 1.0000
46.7000 290.0000 1.0000
46.7600 288.0000 1.0000
46.8200 316.0000 1.0000
46.8800 298.0000 1.0000
46.9400 315.0000 1.0000
47.0000 327.0000 1.0000
47.0600 278.0000 1.0000
47.1200 296.0000 1.0000
47.1800 295.0000 1.0000
47.2400 275.0000 1.0000
47.3000 287.0000 1.0000
47.3600 286.0000 1.0000
47.4200 323.0000 1.0000
47.4800 278.0000 1.0000
47.5400 302.0000 1.0000
47.6000 269.0000 1.0000
47.6600 293.0000 1.0000
47.7200 293.0000 1.0000
47.7800 302.0000 1.0000
47.8400 270.0000 1.0000
47.9000 306.0000 1.0000
47.9600 323.0000 1.0000
48.0200 300.0000 1.0000
48.0800 283.0000 1.0000
48.1400 320.0000 1.0000
48.2000 329.0000 1.0000
48.2600 292.0000 1.0000
48.3200 277.0000 1.0000
48.3800 264.0000 1.0000
48.4400 277.0000 1.0000
48.5000 300.0000 1.0000
48.5600 278.0000 1.0000
48.6200 277.0000 1.0000
48.6800 278.0000 1.0000
48.7400 271.0000 1.0000
48.8000 273.0000 1.0000
48.8600 257.0000 1.0000
48.9200 258.0000 1.0000
48.9800 279.0000 1.0000
49.0400 287.0000 1.0000
49.1000 254.0000 1.0000
49.1600 241.0000 1.0000
49.2200 248.0000 1.0000
49.2800 295.0000 1.0000
49.3400 301.0000 1.0000
49.4000 258.0000 1.0000
49.4600 282.0000 1.0000
49.5200 272.0000 1.0000
49.5800 275.0000 1.0000
49.6400 263.0000 1.0000
49.7000 274.0000 1.0000
49.7600 290.0000 1.0000
49.8200 246.0000 1.0000
49.8800 274.0000 1.0000
49.9400 267.0000 1.0000
50.0000 257.0000 1.0000
50.0600 274.0000 1.0000
50.1200 248.0000 1.0000
50.1800 274.0000 1.0000
50.2400 247.0000 1.0000
50.3000 270.0000 1.0000
50.3600 244.0000 1.0000
50.4200 272.0000 1.0000
50.4800 263.0000 1.0000
50.5400 262.0000 1.0000
50.6000 275.0000 1.0000
50.6600 270.0000 1.0000
50.7200 254.0000 1.0000
50.7800 253.0000 1.0000
50.8400 294.0000 1.0000
50.9000 260.0000 1.0000
50.9600 255.0000 1.0000
51.0200 264.0000 1.0000
51.0800 259.0000 1.0000
51.1400 259.0000 1.0000
51.2000 262.0000 1.0000
51.2600 258.0000 1.0000
51.3200 266.0000 1.0000
51.3800 277.0000 1.0000
51.4400 271.0000 1.0000
51.5000 250.0000 1.0000
51.5600 260.0000 1.0000
51.6200 257.0000 1.0000
51.6800 278.0000 1.0000
51.7400 249.0000 1.0000
51.8000 295.0000 1.0000
51.8600 281.0000 1.0000
51.9200 296.0000 1.0000
51.9800 334.0000 1.0000
52.0400 393.0000 1.0000
52.1000 446.0000 1.0000
52.1600 653.0000 1.0000
52.2200 1027.0000 1.0000
52.2800 1266.0000 1.0000
52.3400 1066.0000 1.0000
52.4000 960.0000 1.0000
52.4600 703.0000 1.0000
52.5200 531.0000 1.0000
52.5800 450.0000 1.0000
52.6400 338.0000 1.0000
52.7000 348.0000 1.0000
52.7600 311.0000 1.0000
52.8200 285.0000 1.0000
52.8800 265.0000 1.0000
52.9400 239.0000 1.0000
53.0000 252.0000 1.0000
53.0600 276.0000 1.0000
53.1200 256.0000 1.0000
53.1800 269.0000 1.0000
53.2400 260.0000 1.0000
53.3000 266.0000 1.0000
53.3600 250.0000 1.0000
53.4200 263.0000 1.0000
53.4800 255.0000 1.0000
53.5400 291.0000 1.0000
53.6000 234.0000 1.0000
53.6600 273.0000 1.0000
53.7200 245.0000 1.0000
53.7800 280.0000 1.0000
53.8400 280.0000 1.0000
53.9000 255.0000 1.0000
53.9600 237.0000 1.0000
54.0200 280.0000 1.0000
54.0800 253.0000 1.0000
54.1400 260.0000 1.0000
54.2000 238.0000 1.0000
54.2600 250.0000 1.0000
54.3200 267.0000 1.0000
54.3800 249.0000 1.0000
54.4400 265.0000 1.0000
54.5000 237.0000 1.0000
54.5600 248.0000 1.0000
54.6200 237.0000 1.0000
54.6800 236.0000 1.0000
54.7400 265.0000 1.0000
54.8000 280.0000 1.0000
54.8600 266.0000 1.0000
54.9200 275.0000 1.0000
54.9800 254.0000 1.0000
55.0400 247.0000 1.0000
55.1000 272.0000 1.0000
55.1600 299.0000 1.0000
55.2200 326.0000 1.0000
55.2800 341.0000 1.0000
55.3400 305.0000 1.0000
55.4000 342.0000 1.0000
55.4600 322.0000 1.0000
55.5200 306.0000 1.0000
55.5800 281.0000 1.0000
55.6400 273.0000 1.0000
55.7000 249.0000 1.0000
55.7600 246.0000 1.0000
55.8200 251.0000 1.0000
55.8800 261.0000 1.0000
55.9400 258.0000 1.0000
56.0000 267.0000 1.0000
56.0600 237.0000 1.0000
56.1200 255.0000 1.0000
56.1800 243.0000 1.0000
56.2400 239.0000 1.0000
56.3000 258.0000 1.0000
56.3600 250.0000 1.0000
56.4200 235.0000 1.0000
56.4800 261.0000 1.0000
56.5400 241.0000 1.0000
56.6000 252.0000 1.0000
56.6600 259.0000 1.0000
56.7200 263.0000 1.0000
56.7800 278.0000 1.0000
56.8400 206.0000 1.0000
56.9000 250.0000 1.0000
56.9600 234.0000 1.0000
57.0200 261.0000 1.0000
57.0800 261.0000 1.0000
57.1400 235.0000 1.0000
57.2000 212.0000 1.0000
57.2600 235.0000 1.0000
57.3200 244.0000 1.0000
57.3800 249.0000 1.0000
57.4400 223.0000 1.0000
57.5000 244.0000 1.0000
57.5600 256.0000 1.0000
57.6200 247.0000 1.0000
57.6800 236.0000 1.0000
57.7400 221.0000 1.0000
57.8000 251.0000 1.0000
57.8600 232.0000 1.0000
57.9200 243.0000 1.0000
57.9800 242.0000 1.0000
58.0400 229.0000 1.0000
58.1000 244.0000 1.0000
58.1600 223.0000 1.0000
58.2200 214.0000 1.0000
58.2800 220.0000 1.0000
58.3400 253.0000 1.0000
58.4000 251.0000 1.0000
58.4600 273.0000 1.0000
58.5200 248.0000 1.0000
58.5800 220.0000 1.0000
58.6400 267.0000 1.0000
58.7000 230.0000 1.0000
58.7600 221.0000 1.0000
58.8200 251.0000 1.0000
58.8800 241.0000 1.0000
58.9400 236.0000 1.0000
59.0000 250.0000 1.0000
59.0600 251.0000 1.0000
59.1200 210.0000 1.0000
59.1800 256.0000 1.0000
59.2400 236.0000 1.0000
59.3000 241.0000 1.0000
59.3600 242.0000 1.0000
59.4200 226.0000 1.0000
59.4800 278.0000 1.0000
59.5400 259.0000 1.0000
59.6000 241.0000 1.0000
59.6600 222.0000 1.0000
59.7200 258.0000 1.0000
59.7800 234.0000 1.0000
59.8400 234.0000 1.0000
59.9000 241.0000 1.0000
59.9600 253.0000 1.0000
60.0200 237.0000 1.0000
60.0800 242.0000 1.0000
60.1400 217.0000 1.0000
60.2000 236.0000 1.0000
60.2600 226.0000 1.0000
60.3200 232.0000 1.0000
60.3800 227.0000 1.0000
60.4400 243.0000 1.0000
60.5000 225.0000 1.0000
60.5600 261.0000 1.0000
60.6200 233.0000 1.0000
60.6800 238.0000 1.0000
60.7400 218.0000 1.0000
60.8000 224.0000 1.0000
60.8600 237.0000 1.0000
60.9200 227.0000 1.0000
60.9800 245.0000 1.0000
61.0400 260.0000 1.0000
61.1000 222.0000 1.0000
61.1600 259.0000 1.0000
61.2200 253.0000 1.0000
61.2800 250.0000 1.0000
61.3400 251.0000 1.0000
61.4000 247.0000 1.0000
61.4600 247.0000 1.0000
61.5200 278.0000 1.0000
61.5800 213.0000 1.0000
61.6400 229.0000 1.0000
61.7000 245.0000 1.0000
61.7600 260.0000 1.0000
61.8200 272.0000 1.0000
61.8800 251.0000 1.0000
61.9400 273.0000 1.0000
62.0000 284.0000 1.0000
62.0600 313.0000 1.0000
62.1200 337.0000 1.0000
62.1800 400.0000 1.0000
62.2400 438.0000 1.0000
62.3000 493.0000 1.0000
62.3600 464.0000 1.0000
62.4200 425.0000 1.0000
62.4800 372.0000 1.0000
62.5400 364.0000 1.0000
62.6000 338.0000 1.0000
62.6600 304.0000 1.0000
62.7200 284.0000 1.0000
62.7800 256.0000 1.0000
62.8400 246.0000 1.0000
62.9000 278.0000 1.0000
62.9600 263.0000 1.0000
63.0200 278.0000 1.0000
63.0800 263.0000 1.0000
63.1400 262.0000 1.0000
63.2000 248.0000 1.0000
63.2600 223.0000 1.0000
63.3200 241.0000 1.0000
63.3800 242.0000 1.0000
63.4400 239.0000 1.0000
63.5000 246.0000 1.0000
63.5600 208.0000 1.0000
63.6200 234.0000 1.0000
63.6800 235.0000 1.0000
63.7400 217.0000 1.0000
63.8000 249.0000 1.0000
63.8600 260.0000 1.0000
63.9200 253.0000 1.0000
63.9800 247.0000 1.0000
64.0400 259.0000 1.0000
64.1000 271.0000 1.0000
64.1600 225.0000 1.0000
64.2200 265.0000 1.0000
64.2800 234.0000 1.0000
64.3400 277.0000 1.0000
64.4000 227.0000 1.0000
64.4600 229.0000 1.0000
64.5200 297.0000 1.0000
64.5800 291.0000 1.0000
64.6400 293.0000 1.0000
64.7000 272.0000 1.0000
64.7600 311.0000 1.0000
64.8200 281.0000 1.0000
64.8800 288.0000 1.0000
64.9400 264.0000 1.0000
65.0000 281.0000 1.0000
65.0600 264.0000 1.0000
65.1200 250.0000 1.0000
65.1800 247.0000 1.0000
65.2400 278.0000 1.0000
65.3000 236.0000 1.0000
65.3600 246.0000 1.0000
65.4200 246.0000 1.0000
65.4800 241.0000 1.0000
65.5400 264.0000 1.0000
65.6000 245.0000 1.0000
65.6600 240.0000 1.0000
65.7200 254.0000 1.0000
65.7800 277.0000 1.0000
65.8400 290.0000 1.0000
65.9000 276.0000 1.0000
65.9600 317.0000 1.0000
66.0200 336.0000 1.0000
66.0800 399.0000 1.0000
66.1400 548.0000 1.0000
66.2000 724.0000 1.0000
66.2600 771.0000 1.0000
66.3200 700.0000 1.0000
66.3800 735.0000 1.0000
66.4400 629.0000 1.0000
66.5000 573.0000 1.0000
66.5600 459.0000 1.0000
66.6200 396.0000 1.0000
66.6800 334.0000 1.0000
66.7400 295.0000 1.0000
66.8000 300.0000 1.0000
66.8600 275.0000 1.0000
66.9200 260.0000 1.0000
66.9800 223.0000 1.0000
67.0400 282.0000 1.0000
67.1000 262.0000 1.0000
67.1600 235.0000 1.0000
67.2200 238.0000 1.0000
67.2800 266.0000 1.0000
67.3400 255.0000 1.0000
67.4000 239.0000 1.0000
67.4600 219.0000 1.0000
67.5200 268.0000 1.0000
67.5800 249.0000 1.0000
67.6400 243.0000 1.0000
67.7000 225.0000 1.0000
67.7600 234.0000 1.0000
67.8200 225.0000 1.0000
67.8800 227.0000 1.0000
67.9400 245.0000 1.0000
68.0000 242.0000 1.0000
68.0600 230.0000 1.0000
68.1200 208.0000 1.0000
68.1800 246.0000 1.0000
68.2400 222.0000 1.0000
68.3000 229.0000 1.0000
68.3600 231.0000 1.0000
68.4200 218.0000 1.0000
68.4800 212.0000 1.0000
68.5400 213.0000 1.0000
68.6000 231.0000 1.0000
68.6600 219.0000 1.0000
68.7200 227.0000 1.0000
68.7800 243.0000 1.0000
68.8400 230.0000 1.0000
68.9000 228.0000 1.0000
68.9600 187.0000 1.0000
69.0200 224.0000 1.0000
69.0800 213.0000 1.0000
69.1400 230.0000 1.0000
69.2000 230.0000 1.0000
69.2600 229.0000 1.0000
69.3200 226.0000 1.0000
69.3800 236.0000 1.0000
69.4400 211.0000 1.0000
69.5000 229.0000 1.0000
69.5600 228.0000 1.0000
69.6200 216.0000 1.0000
69.6800 214.0000 1.0000
69.7400 234.0000 1.0000
69.8000 247.0000 1.0000
69.8600 248.0000 1.0000
69.9200 215.0000 1.0000
69.9800 192.0000 1.0000
70.0400 231.0000 1.0000
70.1000 236.0000 1.0000
70.1600 231.0000 1.0000
70.2200 214.0000 1.0000
70.2800 246.0000 1.0000
70.3400 223.0000 1.0000
70.4000 219.0000 1.0000
70.4600 235.0000 1.0000
70.5200 239.0000 1.0000
70.5800 235.0000 1.0000
70.6400 241.0000 1.0000
70.7000 243.0000 1.0000
70.7600 215.0000 1.0000
70.8200 210.0000 1.0000
70.8800 252.0000 1.0000
70.9400 202.0000 1.0000
71.0000 231.0000 1.0000
71.0600 226.0000 1.0000
71.1200 210.0000 1.0000
71.1800 209.0000 1.0000
71.2400 223.0000 1.0000
71.3000 216.0000 1.0000
71.3600 224.0000 1.0000
71.4200 244.0000 1.0000
71.4800 238.0000 1.0000
71.5400 273.0000 1.0000
71.6000 245.0000 1.0000
71.6600 247.0000 1.0000
71.7200 216.0000 1.0000
71.7800 267.0000 1.0000
71.8400 229.0000 1.0000
71.9000 247.0000 1.0000
71.9600 183.0000 1.0000
72.0200 216.0000 1.0000
72.0800 212.0000 1.0000
72.1400 222.0000 1.0000
72.2000 248.0000 1.0000
72.2600 224.0000 1.0000
72.3200 213.0000 1.0000
72.3800 213.0000 1.0000
72.4400 218.0000 1.0000
72.5000 234.0000 1.0000
72.5600 219.0000 1.0000
72.6200 211.0000 1.0000
72.6800 210.0000 1.0000
72.7400 226.0000 1.0000
72.8000 223.0000 1.0000
72.8600 214.0000 1.0000
72.9200 219.0000 1.0000
72.9800 227.0000 1.0000
73.0400 206.0000 1.0000
73.1000 209.0000 1.0000
73.1600 234.0000 1.0000
73.2200 222.0000 1.0000
73.2800 215.0000 1.0000
73.3400 234.0000 1.0000
73.4000 194.0000 1.0000
73.4600 229.0000 1.0000
73.5200 215.0000 1.0000
73.5800 207.0000 1.0000
73.6400 207.0000 1.0000
73.7000 204.0000 1.0000
73.7600 221.0000 1.0000
73.8200 204.0000 1.0000
73.8800 220.0000 1.0000
73.9400 217.0000 1.0000
74.0000 188.0000 1.0000
74.0600 208.0000 1.0000
74.1200 199.0000 1.0000
74.1800 207.0000 1.0000
74.2400 218.0000 1.0000
74.3000 211.0000 1.0000
74.3600 217.0000 1.0000
74.4200 213.0000 1.0000
74.4800 219.0000 1.0000
74.5400 229.0000 1.0000
74.6000 203.0000 1.0000
74.6600 195.0000 1.0000
74.7200 210.0000 1.0000
74.7800 195.0000 1.0000
74.8400 224.0000 1.0000
74.9000 207.0000 1.0000
74.9600 228.0000 1.0000
75.0200 204.0000 1.0000
75.0800 216.0000 1.0000
75.1400 237.0000 1.0000
75.2000 205.0000 1.0000
75.2600 193.0000 1.0000
75.3200 233.0000 1.0000
75.3800 211.0000 1.0000
75.4400 209.0000 1.0000
75.5000 207.0000 1.0000
75.5600 223.0000 1.0000
75.6200 216.0000 1.0000
75.6800 249.0000 1.0000
75.7400 209.0000 1.0000
75.8000 220.0000 1.0000
75.8600 221.0000 1.0000
75.9200 230.0000 1.0000
75.9800 217.0000 1.0000
76.0400 226.0000 1.0000
76.1000 227.0000 1.0000
76.1600 211.0000 1.0000
76.2200 191.0000 1.0000
76.2800 224.0000 1.0000
76.3400 218.0000 1.0000
76.4000 202.0000 1.0000
76.4600 191.0000 1.0000
76.5200 208.0000 1.0000
76.5800 194.0000 1.0000
76.6400 206.0000 1.0000
76.7000 215.0000 1.0000
76.7600 231.0000 1.0000
76.8200 217.0000 1.0000
76.8800 215.0000 1.0000
76.9400 193.0000 1.0000
77.0000 241.0000 1.0000
77.0600 212.0000 1.0000
77.1200 231.0000 1.0000
77.1800 193.0000 1.0000
77.2400 220.0000 1.0000
77.3000 224.0000 1.0000
77.3600 190.0000 1.0000
77.4200 220.0000 1.0000
77.4800 205.0000 1.0000
77.5400 227.0000 1.0000
77.6000 185.0000 1.0000
77.6600 201.0000 1.0000
77.7200 201.0000 1.0000
77.7800 231.0000 1.0000
77.8400 238.0000 1.0000
77.9000 202.0000 1.0000
77.9600 226.0000 1.0000
78.0200 244.0000 1.0000
78.0800 215.0000 1.0000
78.1400 256.0000 1.0000
78.2000 215.0000 1.0000
78.2600 233.0000 1.0000
78.3200 230.0000 1.0000
78.3800 223.0000 1.0000
78.4400 245.0000 1.0000
78.5000 208.0000 1.0000
78.5600 210.0000 1.0000
78.6200 217.0000 1.0000
78.6800 234.0000 1.0000
78.7400 226.0000 1.0000
78.8000 250.0000 1.0000
78.8600 267.0000 1.0000
78.9200 336.0000 1.0000
78.9800 353.0000 1.0000
79.0400 313.0000 1.0000
79.1000 315.0000 1.0000
79.1600 280.0000 1.0000
79.2200 290.0000 1.0000
79.2800 273.0000 1.0000
79.3400 271.0000 1.0000
79.4000 246.0000 1.0000
79.4600 251.0000 1.0000
79.5200 223.0000 1.0000
79.5800 224.0000 1.0000
79.6400 223.0000 1.0000
79.7000 218.0000 1.0000
79.7600 202.0000 1.0000
79.8200 218.0000 1.0000
79.8800 243.0000 1.0000
79.9400 203.0000 1.0000
80.0000 208.0000 1.0000
*RAS_INT_END
*RAS_TEMPERATURE_START
*RAS_TEMPERATURE_END
*RAS_DATA_END