File: Section2_75_samples/XRD/No_029_FS1_1.ras
*RAS_DATA_START
*RAS_HEADER_START
*DISP_FMT_X "%.2f"
*DISP_FMT_Y "%.0f"
*DISP_FULLSCALE "12278.0000000000"
*DISP_LINE_COLOR "255.0000000000"
*DISP_LINE_STYLE "0.0000000000"
*DISP_LINE_WIDTH "0.2500000000"
*DISP_NOTE "測定データ-2"
*DISP_OFFSET_Y "0.0000000000"
*DISP_PEAKSEARCH_UNIT_Y "cps"
*DISP_RANGE_BOTTOM "0.0000000000"
*DISP_RANGE_LEFT "20.0000000000"
*DISP_RANGE_LOGCUTOFF "0.0100000000"
*DISP_RANGE_RIGHT "70.0000000000"
*DISP_RANGE_TOP "12278.0000000000"
*DISP_SCALE_MODE_Y "0.0000000000"
*DISP_TAB_NAME "2θ/θ"
*DISP_TITLE_Y "強度"
*DISP_UNIT_Y "cps"
*DISP_WINDOW_NAME "MSG_MACROENGINE"
*FILE_COMMENT " "
*FILE_MD5 ""
*FILE_MEMO " "
*FILE_OPERATOR "Administrator"
*FILE_SAMPLE " "
*FILE_TYPE "RAS_RAW"
*FILE_USERGROUP "システムマネージャ"
*FILE_VERSION "1.0000000000"
*HW_ATTACHMENT_ID "ATT0025"
*HW_ATTACHMENT_NAME "標準|Standard"
*HW_COUNTER_ID-0 "CUT0025"
*HW_COUNTER_ID-1 "CUT0020"
*HW_COUNTER_ID-2 "CUT0020"
*HW_COUNTER_ID-3 "CSL0021"
*HW_COUNTER_ID-4 "CMC0021"
*HW_COUNTER_NAME-0 "D/teX Ultra|D/teX Ultra"
*HW_COUNTER_NAME-1 "None|None"
*HW_COUNTER_NAME-2 "None|None"
*HW_COUNTER_NAME-3 "BBM|BBM"
*HW_COUNTER_NAME-4 "検出器モノクロメータ|Detector monochromator"
*HW_COUNTER_SELECT_NAME "D/teX Ultra|D/teX Ultra"
*HW_GONIOMETER_ID "GON0023"
*HW_GONIOMETER_NAME "SmartLab|SmartLab"
*HW_GONIOMETER_RADIUS-0 "90.0"
*HW_GONIOMETER_RADIUS-1 "114.0"
*HW_GONIOMETER_RADIUS-2 "190.0"
*HW_GONIOMETER_RADIUS-3 "300.0"
*HW_GONIOMETER_RADIUS-4 "187.0"
*HW_GONIOMETER_RADIUS-5 "300.0"
*HW_GONIOMETER_RADIUS-6 "113.0"
*HW_GONIOMETER_RADIUS-7 "331.0"
*HW_I_OPT_ID-0 "CBO0021"
*HW_I_OPT_ID-1 "ICR0023"
*HW_I_OPT_ID-2 "ISL0021"
*HW_I_OPT_ID-3 "ISO0021"
*HW_I_OPT_ID-4 "IAD0021"
*HW_I_OPT_ID-5 "IPR0001"
*HW_I_OPT_NAME-0 "CBOユニット|CBO unit"
*HW_I_OPT_NAME-1 "標準入射光学ユニット|Standard incident optical unit"
*HW_I_OPT_NAME-2 "標準入射スリットボックス|Standard incident slit box"
*HW_I_OPT_NAME-3 "入射平行スリット|Incident parallel slit"
*HW_I_OPT_NAME-4 "長手制限スリット|Length limiting slit"
*HW_I_OPT_NAME-5 "None|None"
*HW_R_ATTENUATER_AUTOMODE "0"
*HW_R_OPT_ID-0 "RSS0021"
*HW_R_OPT_ID-1 "RCR0023"
*HW_R_OPT_ID-2 "RSO0021"
*HW_R_OPT_ID-3 "RRS0021"
*HW_R_OPT_ID-4 "ATN0021"
*HW_R_OPT_ID-5 "RFL0021"
*HW_R_OPT_ID-6 "RAD0021"
*HW_R_OPT_NAME-0 "標準受光スリットボックス1|Standard receiving slit box # 1"
*HW_R_OPT_NAME-1 "標準受光光学ユニット1|Standard receiving unit # 1"
*HW_R_OPT_NAME-2 "標準受光光学ユニット2|Standard receiving optical unit # 2"
*HW_R_OPT_NAME-3 "標準受光スリットボックス2|Standard receiving slit box # 2"
*HW_R_OPT_NAME-4 "標準アッテネータ|Standard Attenuator"
*HW_R_OPT_NAME-5 "Cu Kβ|Cu K-beta"
*HW_R_OPT_NAME-6 "調整用受光スリット|Alignment receiving slit"
*HW_SAMPLE_HOLDER_ID "SMP0023"
*HW_SAMPLE_HOLDER_NAME "標準Zステージ|Standard Z stage"
*HW_XG_CURRENT_MAX "50"
*HW_XG_CURRENT_MIN "2"
*HW_XG_CURRENT_RESOLUTION "1"
*HW_XG_CURRENT_UNIT "mA"
*HW_XG_FOCUS "1mm x 10mm"
*HW_XG_FOCUS_TYPE "Normal"
*HW_XG_ID ""
*HW_XG_NAME "3kW 封入管(ID:1200)|3kW Sealed tube(ID:1200)"
*HW_XG_TARGET_ATOMIC_NUMBER "29.0000000000"
*HW_XG_TARGET_NAME "Cu"
*HW_XG_TYPE "Hermetic"
*HW_XG_VOLTAGE_MAX "60"
*HW_XG_VOLTAGE_MIN "20"
*HW_XG_VOLTAGE_RESOLUTION "1"
*HW_XG_VOLTAGE_UNIT "kV"
*HW_XG_WATT_MAX "1.500"
*HW_XG_WATT_UNIT "kW"
*HW_XG_WAVE_LENGTH_ALPHA1 "1.540593"
*HW_XG_WAVE_LENGTH_ALPHA2 "1.544414"
*HW_XG_WAVE_LENGTH_BETA "1.392250"
*MEAS_COND_AXIS_NAME-0 "2θ/θ"
*MEAS_COND_AXIS_NAME-1 "2θ"
*MEAS_COND_AXIS_NAME-2 "ω"
*MEAS_COND_AXIS_NAME-3 "Z"
*MEAS_COND_AXIS_NAME-4 "2θ/ω"
*MEAS_COND_AXIS_NAME-5 "θs"
*MEAS_COND_AXIS_NAME-6 "θd"
*MEAS_COND_AXIS_NAME-7 "Ts"
*MEAS_COND_AXIS_NAME-8 "CBO選択スリット"
*MEAS_COND_AXIS_NAME-9 "M"
*MEAS_COND_AXIS_NAME-10 "入射平行スリット"
*MEAS_COND_AXIS_NAME-11 "入射スリット"
*MEAS_COND_AXIS_NAME-12 ""
*MEAS_COND_AXIS_NAME-13 "Zs"
*MEAS_COND_AXIS_NAME-14 "入射光学素子"
*MEAS_COND_AXIS_NAME-15 "長手制限スリット"
*MEAS_COND_AXIS_NAME-16 "センタースリット"
*MEAS_COND_AXIS_NAME-17 "フィルター"
*MEAS_COND_AXIS_NAME-18 "受光スリット1"
*MEAS_COND_AXIS_NAME-19 "受光スリット2"
*MEAS_COND_AXIS_NAME-20 "受光光学素子"
*MEAS_COND_AXIS_NAME-21 "受光平行スリット"
*MEAS_COND_AXIS_NAME-22 "調整用受光スリット"
*MEAS_COND_AXIS_NAME-23 ""
*MEAS_COND_AXIS_NAME-24 ""
*MEAS_COND_AXIS_NAME-25 "Zd"
*MEAS_COND_AXIS_NAME-26 "アッテネータ"
*MEAS_COND_AXIS_NAME-27 "検出器モノクロメータ"
*MEAS_COND_AXIS_NAME-28 "モノクロメータスリット"
*MEAS_COND_AXIS_NAME-29 "プライマリビーム"
*MEAS_COND_AXIS_NAME-30 "PHA"
*MEAS_COND_AXIS_NAME_INTERNAL-0 "TwoThetaTheta"
*MEAS_COND_AXIS_NAME_INTERNAL-1 "TwoTheta"
*MEAS_COND_AXIS_NAME_INTERNAL-2 "Omega"
*MEAS_COND_AXIS_NAME_INTERNAL-3 "Z"
*MEAS_COND_AXIS_NAME_INTERNAL-4 "TwoThetaOmega"
*MEAS_COND_AXIS_NAME_INTERNAL-5 "ThetaS"
*MEAS_COND_AXIS_NAME_INTERNAL-6 "ThetaD"
*MEAS_COND_AXIS_NAME_INTERNAL-7 "Ts"
*MEAS_COND_AXIS_NAME_INTERNAL-8 "CBO"
*MEAS_COND_AXIS_NAME_INTERNAL-9 "CBO-M"
*MEAS_COND_AXIS_NAME_INTERNAL-10 "IncidentSollerSlit"
*MEAS_COND_AXIS_NAME_INTERNAL-11 "IncidentSlitBox"
*MEAS_COND_AXIS_NAME_INTERNAL-12 "IncidentSlitBox-_Axis"
*MEAS_COND_AXIS_NAME_INTERNAL-13 "Zs"
*MEAS_COND_AXIS_NAME_INTERNAL-14 "IncidentMonochromator"
*MEAS_COND_AXIS_NAME_INTERNAL-15 "IncidentAxdSlit"
*MEAS_COND_AXIS_NAME_INTERNAL-16 "CenterSlit"
*MEAS_COND_AXIS_NAME_INTERNAL-17 "Filter"
*MEAS_COND_AXIS_NAME_INTERNAL-18 "ReceivingSlitBox1"
*MEAS_COND_AXIS_NAME_INTERNAL-19 "ReceivingSlitBox2"
*MEAS_COND_AXIS_NAME_INTERNAL-20 "ReceivingOptics"
*MEAS_COND_AXIS_NAME_INTERNAL-21 "ReceivingSollerSlit"
*MEAS_COND_AXIS_NAME_INTERNAL-22 "ReceivingAxdSlit"
*MEAS_COND_AXIS_NAME_INTERNAL-23 "ReceivingSlitBox1-_Axis"
*MEAS_COND_AXIS_NAME_INTERNAL-24 "ReceivingSlitBox2-_Axis"
*MEAS_COND_AXIS_NAME_INTERNAL-25 "ReceivingSlitBox2-Zd"
*MEAS_COND_AXIS_NAME_INTERNAL-26 "Attenuator"
*MEAS_COND_AXIS_NAME_INTERNAL-27 "CounterMonochromator"
*MEAS_COND_AXIS_NAME_INTERNAL-28 "CounterSlit"
*MEAS_COND_AXIS_NAME_INTERNAL-29 "IncidentPrimary"
*MEAS_COND_AXIS_NAME_INTERNAL-30 "PHA"
*MEAS_COND_AXIS_NAME_MAGICNO-0 "83951616.0000000000"
*MEAS_COND_AXIS_NAME_MAGICNO-1 "268632064.0000000000"
*MEAS_COND_AXIS_NAME_MAGICNO-2 "268500992.0000000000"
*MEAS_COND_AXIS_NAME_MAGICNO-3 "285278208.0000000000"
*MEAS_COND_AXIS_NAME_MAGICNO-4 "83951616.0000000000"
*MEAS_COND_AXIS_NAME_MAGICNO-5 "131072.0000000000"
*MEAS_COND_AXIS_NAME_MAGICNO-6 "131072.0000000000"
*MEAS_COND_AXIS_NAME_MAGICNO-7 "318898176.0000000000"
*MEAS_COND_AXIS_NAME_MAGICNO-8 "20971521.0000000000"
*MEAS_COND_AXIS_NAME_MAGICNO-9 "285343744.0000000000"
*MEAS_COND_AXIS_NAME_MAGICNO-10 "20971521.0000000000"
*MEAS_COND_AXIS_NAME_MAGICNO-11 "22020097.0000000000"
*MEAS_COND_AXIS_NAME_MAGICNO-12 "25165824.0000000000"
*MEAS_COND_AXIS_NAME_MAGICNO-13 "318898176.0000000000"
*MEAS_COND_AXIS_NAME_MAGICNO-14 "1.0000000000"
*MEAS_COND_AXIS_NAME_MAGICNO-15 "20971521.0000000000"
*MEAS_COND_AXIS_NAME_MAGICNO-16 "20971521.0000000000"
*MEAS_COND_AXIS_NAME_MAGICNO-17 "20971521.0000000000"
*MEAS_COND_AXIS_NAME_MAGICNO-18 "23068673.0000000000"
*MEAS_COND_AXIS_NAME_MAGICNO-19 "23068673.0000000000"
*MEAS_COND_AXIS_NAME_MAGICNO-20 "20971521.0000000000"
*MEAS_COND_AXIS_NAME_MAGICNO-21 "20971521.0000000000"
*MEAS_COND_AXIS_NAME_MAGICNO-22 "20971521.0000000000"
*MEAS_COND_AXIS_NAME_MAGICNO-23 "25165824.0000000000"
*MEAS_COND_AXIS_NAME_MAGICNO-24 "25165824.0000000000"
*MEAS_COND_AXIS_NAME_MAGICNO-25 "285343744.0000000000"
*MEAS_COND_AXIS_NAME_MAGICNO-26 "17301505.0000000000"
*MEAS_COND_AXIS_NAME_MAGICNO-27 "20971521.0000000000"
*MEAS_COND_AXIS_NAME_MAGICNO-28 "20971521.0000000000"
*MEAS_COND_AXIS_NAME_MAGICNO-29 "20971521.0000000000"
*MEAS_COND_AXIS_NAME_MAGICNO-30 "0.0000000000"
*MEAS_COND_AXIS_OFFSET-0 "-"
*MEAS_COND_AXIS_OFFSET-1 "-0.1081000000"
*MEAS_COND_AXIS_OFFSET-2 "0.3758000000"
*MEAS_COND_AXIS_OFFSET-3 "-"
*MEAS_COND_AXIS_OFFSET-4 "-"
*MEAS_COND_AXIS_OFFSET-5 "0.3758000000"
*MEAS_COND_AXIS_OFFSET-6 "-0.4839000000"
*MEAS_COND_AXIS_OFFSET-7 "-"
*MEAS_COND_AXIS_OFFSET-8 "-"
*MEAS_COND_AXIS_OFFSET-9 "-"
*MEAS_COND_AXIS_OFFSET-10 "-"
*MEAS_COND_AXIS_OFFSET-11 "-"
*MEAS_COND_AXIS_OFFSET-12 "-"
*MEAS_COND_AXIS_OFFSET-13 "-"
*MEAS_COND_AXIS_OFFSET-14 "-"
*MEAS_COND_AXIS_OFFSET-15 "-"
*MEAS_COND_AXIS_OFFSET-16 "-"
*MEAS_COND_AXIS_OFFSET-17 "-"
*MEAS_COND_AXIS_OFFSET-18 "-"
*MEAS_COND_AXIS_OFFSET-19 "-"
*MEAS_COND_AXIS_OFFSET-20 "-"
*MEAS_COND_AXIS_OFFSET-21 "-"
*MEAS_COND_AXIS_OFFSET-22 "-"
*MEAS_COND_AXIS_OFFSET-23 "-"
*MEAS_COND_AXIS_OFFSET-24 "-"
*MEAS_COND_AXIS_OFFSET-25 "-"
*MEAS_COND_AXIS_OFFSET-26 "-"
*MEAS_COND_AXIS_OFFSET-27 "-"
*MEAS_COND_AXIS_OFFSET-28 "-"
*MEAS_COND_AXIS_OFFSET-29 "-"
*MEAS_COND_AXIS_OFFSET-30 "-"
*MEAS_COND_AXIS_POSITION-0 "18.9662000000"
*MEAS_COND_AXIS_POSITION-1 "18.9662000000"
*MEAS_COND_AXIS_POSITION-2 "9.4831000000"
*MEAS_COND_AXIS_POSITION-3 "-0.5500000000"
*MEAS_COND_AXIS_POSITION-4 "18.9662000000"
*MEAS_COND_AXIS_POSITION-5 "9.4831000000"
*MEAS_COND_AXIS_POSITION-6 "9.4831000000"
*MEAS_COND_AXIS_POSITION-7 "-0.4278800000"
*MEAS_COND_AXIS_POSITION-8 "BB"
*MEAS_COND_AXIS_POSITION-9 "0.0000000000"
*MEAS_COND_AXIS_POSITION-10 "Soller_slit_5.0deg"
*MEAS_COND_AXIS_POSITION-11 "2/3deg"
*MEAS_COND_AXIS_POSITION-12 "2.2088000000"
*MEAS_COND_AXIS_POSITION-13 "-0.4140600000"
*MEAS_COND_AXIS_POSITION-14 "0.0000000000"
*MEAS_COND_AXIS_POSITION-15 "10.0mm"
*MEAS_COND_AXIS_POSITION-16 "None"
*MEAS_COND_AXIS_POSITION-17 "Cu_K-beta"
*MEAS_COND_AXIS_POSITION-18 "13.000mm"
*MEAS_COND_AXIS_POSITION-19 "13.000mm"
*MEAS_COND_AXIS_POSITION-20 "No_unit"
*MEAS_COND_AXIS_POSITION-21 "Soller_slit_5.0deg"
*MEAS_COND_AXIS_POSITION-22 "None"
*MEAS_COND_AXIS_POSITION-23 "13.0000000000"
*MEAS_COND_AXIS_POSITION-24 "13.0000000000"
*MEAS_COND_AXIS_POSITION-25 "0.0109400000"
*MEAS_COND_AXIS_POSITION-26 "Open"
*MEAS_COND_AXIS_POSITION-27 "None"
*MEAS_COND_AXIS_POSITION-28 "None"
*MEAS_COND_AXIS_POSITION-29 "None"
*MEAS_COND_AXIS_POSITION-30 "38.0000000000"
*MEAS_COND_AXIS_UNIT-0 "deg"
*MEAS_COND_AXIS_UNIT-1 "deg"
*MEAS_COND_AXIS_UNIT-2 "deg"
*MEAS_COND_AXIS_UNIT-3 "mm"
*MEAS_COND_AXIS_UNIT-4 "deg"
*MEAS_COND_AXIS_UNIT-5 "deg"
*MEAS_COND_AXIS_UNIT-6 "deg"
*MEAS_COND_AXIS_UNIT-7 "mm"
*MEAS_COND_AXIS_UNIT-8 ""
*MEAS_COND_AXIS_UNIT-9 "pulse"
*MEAS_COND_AXIS_UNIT-10 ""
*MEAS_COND_AXIS_UNIT-11 ""
*MEAS_COND_AXIS_UNIT-12 "mm"
*MEAS_COND_AXIS_UNIT-13 "mm"
*MEAS_COND_AXIS_UNIT-14 ""
*MEAS_COND_AXIS_UNIT-15 ""
*MEAS_COND_AXIS_UNIT-16 ""
*MEAS_COND_AXIS_UNIT-17 ""
*MEAS_COND_AXIS_UNIT-18 ""
*MEAS_COND_AXIS_UNIT-19 ""
*MEAS_COND_AXIS_UNIT-20 ""
*MEAS_COND_AXIS_UNIT-21 ""
*MEAS_COND_AXIS_UNIT-22 ""
*MEAS_COND_AXIS_UNIT-23 "mm"
*MEAS_COND_AXIS_UNIT-24 "mm"
*MEAS_COND_AXIS_UNIT-25 "mm"
*MEAS_COND_AXIS_UNIT-26 ""
*MEAS_COND_AXIS_UNIT-27 ""
*MEAS_COND_AXIS_UNIT-28 ""
*MEAS_COND_AXIS_UNIT-29 ""
*MEAS_COND_AXIS_UNIT-30 "div"
*MEAS_COND_COUNTER_CNTLOSS_CORR "0.0000000000"
*MEAS_COND_COUNTER_PHABASE "38.0000000000"
*MEAS_COND_COUNTER_PHAWINDOW "16.0000000000"
*MEAS_COND_COUNTER_PHA_UNIT "div"
*MEAS_COND_COUNTER_TAUDIFF "30.0000000000"
*MEAS_COND_COUNTER_TAUINT "0.0000000000"
*MEAS_COND_IRRADIATION_MODE "OFF"
*MEAS_COND_IRRADIATION_WIDTH ""
*MEAS_COND_OPT_ATTR "集中法"
*MEAS_COND_OPT_NAME "@集中法"
*MEAS_COND_UNSYMMETRIC_MODE "OFF"
*MEAS_COND_XG_CURRENT "30.0000000000"
*MEAS_COND_XG_VOLTAGE "40.0000000000"
*MEAS_COND_XG_WAVE_TYPE "Ka"
*MEAS_DATA_COUNT "5001.0000000000"
*MEAS_SCAN_AXIS_X "2θ/θ"
*MEAS_SCAN_AXIS_X_INTERNAL "TwoThetaTheta"
*MEAS_SCAN_END_TIME "06/24/21 15:42:13"
*MEAS_SCAN_MODE "CONTINUOUS"
*MEAS_SCAN_MONITOR "0"
*MEAS_SCAN_RESOLUTION_X "0.0002"
*MEAS_SCAN_SPEED "1.0"
*MEAS_SCAN_SPEED_UNIT "deg/min"
*MEAS_SCAN_START "20.0000000000"
*MEAS_SCAN_START_TIME "06/24/21 14:49:22"
*MEAS_SCAN_STEP "0.0100000000"
*MEAS_SCAN_STOP "70.0000000000"
*MEAS_SCAN_UNIT_X "deg"
*MEAS_SCAN_UNIT_Y "counts"
*RAS_HEADER_END
*RAS_INT_START
20.0000 1530.0000 1.0000
20.0400 1500.0000 1.0000
20.0800 1498.0000 1.0000
20.1200 1458.0000 1.0000
20.1600 1492.0000 1.0000
20.2000 1474.0000 1.0000
20.2400 1498.0000 1.0000
20.2800 1448.0000 1.0000
20.3200 1438.0000 1.0000
20.3600 1448.0000 1.0000
20.4000 1466.0000 1.0000
20.4400 1479.0000 1.0000
20.4800 1440.0000 1.0000
20.5200 1342.0000 1.0000
20.5600 1495.0000 1.0000
20.6000 1451.0000 1.0000
20.6400 1499.0000 1.0000
20.6800 1503.0000 1.0000
20.7200 1424.0000 1.0000
20.7600 1440.0000 1.0000
20.8000 1439.0000 1.0000
20.8400 1423.0000 1.0000
20.8800 1501.0000 1.0000
20.9200 1407.0000 1.0000
20.9600 1475.0000 1.0000
21.0000 1459.0000 1.0000
21.0400 1508.0000 1.0000
21.0800 1496.0000 1.0000
21.1200 1437.0000 1.0000
21.1600 1496.0000 1.0000
21.2000 1479.0000 1.0000
21.2400 1494.0000 1.0000
21.2800 1481.0000 1.0000
21.3200 1441.0000 1.0000
21.3600 1498.0000 1.0000
21.4000 1487.0000 1.0000
21.4400 1440.0000 1.0000
21.4800 1486.0000 1.0000
21.5200 1448.0000 1.0000
21.5600 1433.0000 1.0000
21.6000 1443.0000 1.0000
21.6400 1452.0000 1.0000
21.6800 1450.0000 1.0000
21.7200 1485.0000 1.0000
21.7600 1447.0000 1.0000
21.8000 1507.0000 1.0000
21.8400 1493.0000 1.0000
21.8800 1462.0000 1.0000
21.9200 1528.0000 1.0000
21.9600 1469.0000 1.0000
22.0000 1461.0000 1.0000
22.0400 1451.0000 1.0000
22.0800 1508.0000 1.0000
22.1200 1503.0000 1.0000
22.1600 1507.0000 1.0000
22.2000 1496.0000 1.0000
22.2400 1498.0000 1.0000
22.2800 1474.0000 1.0000
22.3200 1466.0000 1.0000
22.3600 1457.0000 1.0000
22.4000 1503.0000 1.0000
22.4400 1468.0000 1.0000
22.4800 1470.0000 1.0000
22.5200 1475.0000 1.0000
22.5600 1454.0000 1.0000
22.6000 1524.0000 1.0000
22.6400 1551.0000 1.0000
22.6800 1457.0000 1.0000
22.7200 1520.0000 1.0000
22.7600 1516.0000 1.0000
22.8000 1547.0000 1.0000
22.8400 1510.0000 1.0000
22.8800 1490.0000 1.0000
22.9200 1463.0000 1.0000
22.9600 1457.0000 1.0000
23.0000 1473.0000 1.0000
23.0400 1486.0000 1.0000
23.0800 1504.0000 1.0000
23.1200 1512.0000 1.0000
23.1600 1480.0000 1.0000
23.2000 1539.0000 1.0000
23.2400 1479.0000 1.0000
23.2800 1495.0000 1.0000
23.3200 1460.0000 1.0000
23.3600 1477.0000 1.0000
23.4000 1553.0000 1.0000
23.4400 1535.0000 1.0000
23.4800 1531.0000 1.0000
23.5200 1504.0000 1.0000
23.5600 1548.0000 1.0000
23.6000 1575.0000 1.0000
23.6400 1481.0000 1.0000
23.6800 1496.0000 1.0000
23.7200 1543.0000 1.0000
23.7600 1535.0000 1.0000
23.8000 1525.0000 1.0000
23.8400 1483.0000 1.0000
23.8800 1480.0000 1.0000
23.9200 1566.0000 1.0000
23.9600 1466.0000 1.0000
24.0000 1534.0000 1.0000
24.0400 1528.0000 1.0000
24.0800 1477.0000 1.0000
24.1200 1564.0000 1.0000
24.1600 1504.0000 1.0000
24.2000 1426.0000 1.0000
24.2400 1536.0000 1.0000
24.2800 1488.0000 1.0000
24.3200 1492.0000 1.0000
24.3600 1524.0000 1.0000
24.4000 1579.0000 1.0000
24.4400 1513.0000 1.0000
24.4800 1514.0000 1.0000
24.5200 1560.0000 1.0000
24.5600 1474.0000 1.0000
24.6000 1560.0000 1.0000
24.6400 1609.0000 1.0000
24.6800 1556.0000 1.0000
24.7200 1520.0000 1.0000
24.7600 1647.0000 1.0000
24.8000 1590.0000 1.0000
24.8400 1579.0000 1.0000
24.8800 1648.0000 1.0000
24.9200 1618.0000 1.0000
24.9600 1643.0000 1.0000
25.0000 1593.0000 1.0000
25.0400 1564.0000 1.0000
25.0800 1617.0000 1.0000
25.1200 1609.0000 1.0000
25.1600 1570.0000 1.0000
25.2000 1608.0000 1.0000
25.2400 1600.0000 1.0000
25.2800 1597.0000 1.0000
25.3200 1609.0000 1.0000
25.3600 1577.0000 1.0000
25.4000 1510.0000 1.0000
25.4400 1595.0000 1.0000
25.4800 1499.0000 1.0000
25.5200 1581.0000 1.0000
25.5600 1559.0000 1.0000
25.6000 1623.0000 1.0000
25.6400 1561.0000 1.0000
25.6800 1594.0000 1.0000
25.7200 1607.0000 1.0000
25.7600 1662.0000 1.0000
25.8000 1577.0000 1.0000
25.8400 1547.0000 1.0000
25.8800 1560.0000 1.0000
25.9200 1540.0000 1.0000
25.9600 1629.0000 1.0000
26.0000 1611.0000 1.0000
26.0400 1537.0000 1.0000
26.0800 1663.0000 1.0000
26.1200 1549.0000 1.0000
26.1600 1542.0000 1.0000
26.2000 1597.0000 1.0000
26.2400 1589.0000 1.0000
26.2800 1642.0000 1.0000
26.3200 1597.0000 1.0000
26.3600 1624.0000 1.0000
26.4000 1654.0000 1.0000
26.4400 1607.0000 1.0000
26.4800 1635.0000 1.0000
26.5200 1613.0000 1.0000
26.5600 1602.0000 1.0000
26.6000 1621.0000 1.0000
26.6400 1719.0000 1.0000
26.6800 1675.0000 1.0000
26.7200 1686.0000 1.0000
26.7600 1731.0000 1.0000
26.8000 1763.0000 1.0000
26.8400 1883.0000 1.0000
26.8800 1829.0000 1.0000
26.9200 1903.0000 1.0000
26.9600 1977.0000 1.0000
27.0000 2119.0000 1.0000
27.0400 2342.0000 1.0000
27.0800 2625.0000 1.0000
27.1200 2950.0000 1.0000
27.1600 3424.0000 1.0000
27.2000 4261.0000 1.0000
27.2400 5298.0000 1.0000
27.2800 6008.0000 1.0000
27.3200 6045.0000 1.0000
27.3600 5565.0000 1.0000
27.4000 4577.0000 1.0000
27.4400 3608.0000 1.0000
27.4800 3012.0000 1.0000
27.5200 2590.0000 1.0000
27.5600 2342.0000 1.0000
27.6000 2061.0000 1.0000
27.6400 2056.0000 1.0000
27.6800 1956.0000 1.0000
27.7200 1877.0000 1.0000
27.7600 1691.0000 1.0000
27.8000 1689.0000 1.0000
27.8400 1681.0000 1.0000
27.8800 1698.0000 1.0000
27.9200 1639.0000 1.0000
27.9600 1674.0000 1.0000
28.0000 1634.0000 1.0000
28.0400 1621.0000 1.0000
28.0800 1599.0000 1.0000
28.1200 1569.0000 1.0000
28.1600 1568.0000 1.0000
28.2000 1551.0000 1.0000
28.2400 1575.0000 1.0000
28.2800 1530.0000 1.0000
28.3200 1510.0000 1.0000
28.3600 1514.0000 1.0000
28.4000 1506.0000 1.0000
28.4400 1549.0000 1.0000
28.4800 1487.0000 1.0000
28.5200 1532.0000 1.0000
28.5600 1577.0000 1.0000
28.6000 1438.0000 1.0000
28.6400 1462.0000 1.0000
28.6800 1488.0000 1.0000
28.7200 1456.0000 1.0000
28.7600 1519.0000 1.0000
28.8000 1475.0000 1.0000
28.8400 1455.0000 1.0000
28.8800 1533.0000 1.0000
28.9200 1485.0000 1.0000
28.9600 1501.0000 1.0000
29.0000 1413.0000 1.0000
29.0400 1480.0000 1.0000
29.0800 1520.0000 1.0000
29.1200 1496.0000 1.0000
29.1600 1565.0000 1.0000
29.2000 1500.0000 1.0000
29.2400 1456.0000 1.0000
29.2800 1420.0000 1.0000
29.3200 1440.0000 1.0000
29.3600 1510.0000 1.0000
29.4000 1472.0000 1.0000
29.4400 1400.0000 1.0000
29.4800 1527.0000 1.0000
29.5200 1413.0000 1.0000
29.5600 1430.0000 1.0000
29.6000 1411.0000 1.0000
29.6400 1453.0000 1.0000
29.6800 1366.0000 1.0000
29.7200 1460.0000 1.0000
29.7600 1416.0000 1.0000
29.8000 1389.0000 1.0000
29.8400 1409.0000 1.0000
29.8800 1460.0000 1.0000
29.9200 1420.0000 1.0000
29.9600 1439.0000 1.0000
30.0000 1433.0000 1.0000
30.0400 1416.0000 1.0000
30.0800 1464.0000 1.0000
30.1200 1442.0000 1.0000
30.1600 1393.0000 1.0000
30.2000 1391.0000 1.0000
30.2400 1447.0000 1.0000
30.2800 1417.0000 1.0000
30.3200 1347.0000 1.0000
30.3600 1354.0000 1.0000
30.4000 1400.0000 1.0000
30.4400 1453.0000 1.0000
30.4800 1416.0000 1.0000
30.5200 1392.0000 1.0000
30.5600 1356.0000 1.0000
30.6000 1396.0000 1.0000
30.6400 1374.0000 1.0000
30.6800 1366.0000 1.0000
30.7200 1347.0000 1.0000
30.7600 1373.0000 1.0000
30.8000 1370.0000 1.0000
30.8400 1290.0000 1.0000
30.8800 1384.0000 1.0000
30.9200 1319.0000 1.0000
30.9600 1377.0000 1.0000
31.0000 1400.0000 1.0000
31.0400 1399.0000 1.0000
31.0800 1370.0000 1.0000
31.1200 1331.0000 1.0000
31.1600 1361.0000 1.0000
31.2000 1365.0000 1.0000
31.2400 1365.0000 1.0000
31.2800 1343.0000 1.0000
31.3200 1349.0000 1.0000
31.3600 1349.0000 1.0000
31.4000 1333.0000 1.0000
31.4400 1294.0000 1.0000
31.4800 1360.0000 1.0000
31.5200 1387.0000 1.0000
31.5600 1353.0000 1.0000
31.6000 1343.0000 1.0000
31.6400 1315.0000 1.0000
31.6800 1309.0000 1.0000
31.7200 1337.0000 1.0000
31.7600 1333.0000 1.0000
31.8000 1411.0000 1.0000
31.8400 1378.0000 1.0000
31.8800 1363.0000 1.0000
31.9200 1394.0000 1.0000
31.9600 1414.0000 1.0000
32.0000 1353.0000 1.0000
32.0400 1330.0000 1.0000
32.0800 1301.0000 1.0000
32.1200 1336.0000 1.0000
32.1600 1337.0000 1.0000
32.2000 1363.0000 1.0000
32.2400 1295.0000 1.0000
32.2800 1314.0000 1.0000
32.3200 1295.0000 1.0000
32.3600 1309.0000 1.0000
32.4000 1276.0000 1.0000
32.4400 1279.0000 1.0000
32.4800 1348.0000 1.0000
32.5200 1348.0000 1.0000
32.5600 1273.0000 1.0000
32.6000 1289.0000 1.0000
32.6400 1290.0000 1.0000
32.6800 1240.0000 1.0000
32.7200 1244.0000 1.0000
32.7600 1256.0000 1.0000
32.8000 1302.0000 1.0000
32.8400 1295.0000 1.0000
32.8800 1256.0000 1.0000
32.9200 1247.0000 1.0000
32.9600 1296.0000 1.0000
33.0000 1263.0000 1.0000
33.0400 1237.0000 1.0000
33.0800 1277.0000 1.0000
33.1200 1221.0000 1.0000
33.1600 1268.0000 1.0000
33.2000 1247.0000 1.0000
33.2400 1215.0000 1.0000
33.2800 1250.0000 1.0000
33.3200 1270.0000 1.0000
33.3600 1232.0000 1.0000
33.4000 1200.0000 1.0000
33.4400 1276.0000 1.0000
33.4800 1239.0000 1.0000
33.5200 1240.0000 1.0000
33.5600 1220.0000 1.0000
33.6000 1250.0000 1.0000
33.6400 1313.0000 1.0000
33.6800 1247.0000 1.0000
33.7200 1344.0000 1.0000
33.7600 1258.0000 1.0000
33.8000 1353.0000 1.0000
33.8400 1320.0000 1.0000
33.8800 1376.0000 1.0000
33.9200 1473.0000 1.0000
33.9600 1466.0000 1.0000
34.0000 1427.0000 1.0000
34.0400 1519.0000 1.0000
34.0800 1413.0000 1.0000
34.1200 1368.0000 1.0000
34.1600 1494.0000 1.0000
34.2000 1491.0000 1.0000
34.2400 1613.0000 1.0000
34.2800 1614.0000 1.0000
34.3200 1794.0000 1.0000
34.3600 1982.0000 1.0000
34.4000 2423.0000 1.0000
34.4400 2934.0000 1.0000
34.4800 3205.0000 1.0000
34.5200 3244.0000 1.0000
34.5600 2881.0000 1.0000
34.6000 2602.0000 1.0000
34.6400 2193.0000 1.0000
34.6800 1940.0000 1.0000
34.7200 1689.0000 1.0000
34.7600 1545.0000 1.0000
34.8000 1526.0000 1.0000
34.8400 1490.0000 1.0000
34.8800 1277.0000 1.0000
34.9200 1314.0000 1.0000
34.9600 1285.0000 1.0000
35.0000 1211.0000 1.0000
35.0400 1243.0000 1.0000
35.0800 1209.0000 1.0000
35.1200 1177.0000 1.0000
35.1600 1165.0000 1.0000
35.2000 1153.0000 1.0000
35.2400 1173.0000 1.0000
35.2800 1173.0000 1.0000
35.3200 1068.0000 1.0000
35.3600 1131.0000 1.0000
35.4000 1110.0000 1.0000
35.4400 1111.0000 1.0000
35.4800 1114.0000 1.0000
35.5200 1132.0000 1.0000
35.5600 1081.0000 1.0000
35.6000 1138.0000 1.0000
35.6400 1113.0000 1.0000
35.6800 1113.0000 1.0000
35.7200 1029.0000 1.0000
35.7600 1134.0000 1.0000
35.8000 1078.0000 1.0000
35.8400 1072.0000 1.0000
35.8800 1037.0000 1.0000
35.9200 1074.0000 1.0000
35.9600 1130.0000 1.0000
36.0000 1060.0000 1.0000
36.0400 1044.0000 1.0000
36.0800 1110.0000 1.0000
36.1200 1141.0000 1.0000
36.1600 1124.0000 1.0000
36.2000 1193.0000 1.0000
36.2400 1156.0000 1.0000
36.2800 1319.0000 1.0000
36.3200 1440.0000 1.0000
36.3600 1720.0000 1.0000
36.4000 1924.0000 1.0000
36.4400 1753.0000 1.0000
36.4800 1648.0000 1.0000
36.5200 1404.0000 1.0000
36.5600 1344.0000 1.0000
36.6000 1184.0000 1.0000
36.6400 1109.0000 1.0000
36.6800 1058.0000 1.0000
36.7200 1101.0000 1.0000
36.7600 1016.0000 1.0000
36.8000 1101.0000 1.0000
36.8400 987.0000 1.0000
36.8800 1051.0000 1.0000
36.9200 1015.0000 1.0000
36.9600 1030.0000 1.0000
37.0000 1007.0000 1.0000
37.0400 1008.0000 1.0000
37.0800 968.0000 1.0000
37.1200 999.0000 1.0000
37.1600 1014.0000 1.0000
37.2000 978.0000 1.0000
37.2400 971.0000 1.0000
37.2800 1004.0000 1.0000
37.3200 947.0000 1.0000
37.3600 1041.0000 1.0000
37.4000 1010.0000 1.0000
37.4400 1004.0000 1.0000
37.4800 1040.0000 1.0000
37.5200 993.0000 1.0000
37.5600 1011.0000 1.0000
37.6000 998.0000 1.0000
37.6400 958.0000 1.0000
37.6800 997.0000 1.0000
37.7200 1010.0000 1.0000
37.7600 971.0000 1.0000
37.8000 948.0000 1.0000
37.8400 1042.0000 1.0000
37.8800 1038.0000 1.0000
37.9200 1029.0000 1.0000
37.9600 1027.0000 1.0000
38.0000 1075.0000 1.0000
38.0400 1100.0000 1.0000
38.0800 1095.0000 1.0000
38.1200 1151.0000 1.0000
38.1600 1249.0000 1.0000
38.2000 1409.0000 1.0000
38.2400 1514.0000 1.0000
38.2800 1680.0000 1.0000
38.3200 1942.0000 1.0000
38.3600 2375.0000 1.0000
38.4000 3139.0000 1.0000
38.4400 3993.0000 1.0000
38.4800 5001.0000 1.0000
38.5200 6055.0000 1.0000
38.5600 6125.0000 1.0000
38.6000 5648.0000 1.0000
38.6400 4834.0000 1.0000
38.6800 3638.0000 1.0000
38.7200 2936.0000 1.0000
38.7600 2226.0000 1.0000
38.8000 1846.0000 1.0000
38.8400 1562.0000 1.0000
38.8800 1305.0000 1.0000
38.9200 1234.0000 1.0000
38.9600 1201.0000 1.0000
39.0000 1120.0000 1.0000
39.0400 1037.0000 1.0000
39.0800 966.0000 1.0000
39.1200 924.0000 1.0000
39.1600 953.0000 1.0000
39.2000 985.0000 1.0000
39.2400 896.0000 1.0000
39.2800 909.0000 1.0000
39.3200 906.0000 1.0000
39.3600 919.0000 1.0000
39.4000 887.0000 1.0000
39.4400 895.0000 1.0000
39.4800 958.0000 1.0000
39.5200 932.0000 1.0000
39.5600 912.0000 1.0000
39.6000 931.0000 1.0000
39.6400 954.0000 1.0000
39.6800 946.0000 1.0000
39.7200 930.0000 1.0000
39.7600 908.0000 1.0000
39.8000 900.0000 1.0000
39.8400 865.0000 1.0000
39.8800 839.0000 1.0000
39.9200 907.0000 1.0000
39.9600 850.0000 1.0000
40.0000 915.0000 1.0000
40.0400 845.0000 1.0000
40.0800 872.0000 1.0000
40.1200 832.0000 1.0000
40.1600 853.0000 1.0000
40.2000 862.0000 1.0000
40.2400 835.0000 1.0000
40.2800 791.0000 1.0000
40.3200 866.0000 1.0000
40.3600 825.0000 1.0000
40.4000 848.0000 1.0000
40.4400 829.0000 1.0000
40.4800 844.0000 1.0000
40.5200 837.0000 1.0000
40.5600 854.0000 1.0000
40.6000 848.0000 1.0000
40.6400 862.0000 1.0000
40.6800 823.0000 1.0000
40.7200 803.0000 1.0000
40.7600 857.0000 1.0000
40.8000 847.0000 1.0000
40.8400 821.0000 1.0000
40.8800 796.0000 1.0000
40.9200 854.0000 1.0000
40.9600 839.0000 1.0000
41.0000 814.0000 1.0000
41.0400 838.0000 1.0000
41.0800 840.0000 1.0000
41.1200 793.0000 1.0000
41.1600 820.0000 1.0000
41.2000 827.0000 1.0000
41.2400 788.0000 1.0000
41.2800 803.0000 1.0000
41.3200 842.0000 1.0000
41.3600 825.0000 1.0000
41.4000 808.0000 1.0000
41.4400 794.0000 1.0000
41.4800 793.0000 1.0000
41.5200 798.0000 1.0000
41.5600 779.0000 1.0000
41.6000 818.0000 1.0000
41.6400 849.0000 1.0000
41.6800 845.0000 1.0000
41.7200 818.0000 1.0000
41.7600 838.0000 1.0000
41.8000 833.0000 1.0000
41.8400 805.0000 1.0000
41.8800 808.0000 1.0000
41.9200 812.0000 1.0000
41.9600 799.0000 1.0000
42.0000 777.0000 1.0000
42.0400 836.0000 1.0000
42.0800 813.0000 1.0000
42.1200 847.0000 1.0000
42.1600 842.0000 1.0000
42.2000 790.0000 1.0000
42.2400 782.0000 1.0000
42.2800 823.0000 1.0000
42.3200 791.0000 1.0000
42.3600 789.0000 1.0000
42.4000 803.0000 1.0000
42.4400 741.0000 1.0000
42.4800 811.0000 1.0000
42.5200 822.0000 1.0000
42.5600 803.0000 1.0000
42.6000 802.0000 1.0000
42.6400 757.0000 1.0000
42.6800 815.0000 1.0000
42.7200 812.0000 1.0000
42.7600 824.0000 1.0000
42.8000 806.0000 1.0000
42.8400 823.0000 1.0000
42.8800 855.0000 1.0000
42.9200 820.0000 1.0000
42.9600 830.0000 1.0000
43.0000 827.0000 1.0000
43.0400 813.0000 1.0000
43.0800 836.0000 1.0000
43.1200 865.0000 1.0000
43.1600 866.0000 1.0000
43.2000 929.0000 1.0000
43.2400 941.0000 1.0000
43.2800 862.0000 1.0000
43.3200 869.0000 1.0000
43.3600 879.0000 1.0000
43.4000 869.0000 1.0000
43.4400 826.0000 1.0000
43.4800 810.0000 1.0000
43.5200 840.0000 1.0000
43.5600 765.0000 1.0000
43.6000 787.0000 1.0000
43.6400 751.0000 1.0000
43.6800 814.0000 1.0000
43.7200 779.0000 1.0000
43.7600 813.0000 1.0000
43.8000 794.0000 1.0000
43.8400 806.0000 1.0000
43.8800 830.0000 1.0000
43.9200 753.0000 1.0000
43.9600 785.0000 1.0000
44.0000 801.0000 1.0000
44.0400 834.0000 1.0000
44.0800 803.0000 1.0000
44.1200 747.0000 1.0000
44.1600 728.0000 1.0000
44.2000 779.0000 1.0000
44.2400 785.0000 1.0000
44.2800 798.0000 1.0000
44.3200 774.0000 1.0000
44.3600 807.0000 1.0000
44.4000 805.0000 1.0000
44.4400 779.0000 1.0000
44.4800 835.0000 1.0000
44.5200 763.0000 1.0000
44.5600 766.0000 1.0000
44.6000 790.0000 1.0000
44.6400 761.0000 1.0000
44.6800 806.0000 1.0000
44.7200 810.0000 1.0000
44.7600 749.0000 1.0000
44.8000 768.0000 1.0000
44.8400 770.0000 1.0000
44.8800 743.0000 1.0000
44.9200 732.0000 1.0000
44.9600 814.0000 1.0000
45.0000 731.0000 1.0000
45.0400 775.0000 1.0000
45.0800 718.0000 1.0000
45.1200 765.0000 1.0000
45.1600 773.0000 1.0000
45.2000 792.0000 1.0000
45.2400 752.0000 1.0000
45.2800 722.0000 1.0000
45.3200 768.0000 1.0000
45.3600 723.0000 1.0000
45.4000 778.0000 1.0000
45.4400 771.0000 1.0000
45.4800 754.0000 1.0000
45.5200 760.0000 1.0000
45.5600 755.0000 1.0000
45.6000 726.0000 1.0000
45.6400 761.0000 1.0000
45.6800 769.0000 1.0000
45.7200 744.0000 1.0000
45.7600 731.0000 1.0000
45.8000 714.0000 1.0000
45.8400 738.0000 1.0000
45.8800 754.0000 1.0000
45.9200 734.0000 1.0000
45.9600 683.0000 1.0000
46.0000 751.0000 1.0000
46.0400 731.0000 1.0000
46.0800 725.0000 1.0000
46.1200 711.0000 1.0000
46.1600 727.0000 1.0000
46.2000 724.0000 1.0000
46.2400 729.0000 1.0000
46.2800 739.0000 1.0000
46.3200 768.0000 1.0000
46.3600 737.0000 1.0000
46.4000 743.0000 1.0000
46.4400 748.0000 1.0000
46.4800 734.0000 1.0000
46.5200 784.0000 1.0000
46.5600 729.0000 1.0000
46.6000 714.0000 1.0000
46.6400 756.0000 1.0000
46.6800 745.0000 1.0000
46.7200 719.0000 1.0000
46.7600 715.0000 1.0000
46.8000 738.0000 1.0000
46.8400 750.0000 1.0000
46.8800 720.0000 1.0000
46.9200 726.0000 1.0000
46.9600 748.0000 1.0000
47.0000 729.0000 1.0000
47.0400 770.0000 1.0000
47.0800 734.0000 1.0000
47.1200 737.0000 1.0000
47.1600 681.0000 1.0000
47.2000 697.0000 1.0000
47.2400 710.0000 1.0000
47.2800 740.0000 1.0000
47.3200 722.0000 1.0000
47.3600 745.0000 1.0000
47.4000 715.0000 1.0000
47.4400 719.0000 1.0000
47.4800 698.0000 1.0000
47.5200 715.0000 1.0000
47.5600 718.0000 1.0000
47.6000 735.0000 1.0000
47.6400 725.0000 1.0000
47.6800 726.0000 1.0000
47.7200 689.0000 1.0000
47.7600 693.0000 1.0000
47.8000 727.0000 1.0000
47.8400 728.0000 1.0000
47.8800 689.0000 1.0000
47.9200 705.0000 1.0000
47.9600 689.0000 1.0000
48.0000 707.0000 1.0000
48.0400 731.0000 1.0000
48.0800 669.0000 1.0000
48.1200 774.0000 1.0000
48.1600 738.0000 1.0000
48.2000 742.0000 1.0000
48.2400 755.0000 1.0000
48.2800 716.0000 1.0000
48.3200 695.0000 1.0000
48.3600 667.0000 1.0000
48.4000 729.0000 1.0000
48.4400 730.0000 1.0000
48.4800 751.0000 1.0000
48.5200 681.0000 1.0000
48.5600 734.0000 1.0000
48.6000 668.0000 1.0000
48.6400 671.0000 1.0000
48.6800 629.0000 1.0000
48.7200 686.0000 1.0000
48.7600 681.0000 1.0000
48.8000 680.0000 1.0000
48.8400 678.0000 1.0000
48.8800 753.0000 1.0000
48.9200 744.0000 1.0000
48.9600 693.0000 1.0000
49.0000 735.0000 1.0000
49.0400 681.0000 1.0000
49.0800 700.0000 1.0000
49.1200 733.0000 1.0000
49.1600 709.0000 1.0000
49.2000 692.0000 1.0000
49.2400 664.0000 1.0000
49.2800 712.0000 1.0000
49.3200 666.0000 1.0000
49.3600 691.0000 1.0000
49.4000 685.0000 1.0000
49.4400 743.0000 1.0000
49.4800 714.0000 1.0000
49.5200 717.0000 1.0000
49.5600 658.0000 1.0000
49.6000 685.0000 1.0000
49.6400 736.0000 1.0000
49.6800 713.0000 1.0000
49.7200 713.0000 1.0000
49.7600 702.0000 1.0000
49.8000 708.0000 1.0000
49.8400 688.0000 1.0000
49.8800 643.0000 1.0000
49.9200 703.0000 1.0000
49.9600 719.0000 1.0000
50.0000 681.0000 1.0000
50.0400 718.0000 1.0000
50.0800 702.0000 1.0000
50.1200 714.0000 1.0000
50.1600 738.0000 1.0000
50.2000 740.0000 1.0000
50.2400 701.0000 1.0000
50.2800 689.0000 1.0000
50.3200 707.0000 1.0000
50.3600 700.0000 1.0000
50.4000 712.0000 1.0000
50.4400 697.0000 1.0000
50.4800 680.0000 1.0000
50.5200 696.0000 1.0000
50.5600 730.0000 1.0000
50.6000 721.0000 1.0000
50.6400 709.0000 1.0000
50.6800 673.0000 1.0000
50.7200 672.0000 1.0000
50.7600 692.0000 1.0000
50.8000 714.0000 1.0000
50.8400 675.0000 1.0000
50.8800 662.0000 1.0000
50.9200 704.0000 1.0000
50.9600 706.0000 1.0000
51.0000 675.0000 1.0000
51.0400 690.0000 1.0000
51.0800 722.0000 1.0000
51.1200 688.0000 1.0000
51.1600 646.0000 1.0000
51.2000 694.0000 1.0000
51.2400 727.0000 1.0000
51.2800 697.0000 1.0000
51.3200 707.0000 1.0000
51.3600 760.0000 1.0000
51.4000 717.0000 1.0000
51.4400 676.0000 1.0000
51.4800 740.0000 1.0000
51.5200 682.0000 1.0000
51.5600 731.0000 1.0000
51.6000 761.0000 1.0000
51.6400 726.0000 1.0000
51.6800 736.0000 1.0000
51.7200 709.0000 1.0000
51.7600 771.0000 1.0000
51.8000 784.0000 1.0000
51.8400 755.0000 1.0000
51.8800 831.0000 1.0000
51.9200 897.0000 1.0000
51.9600 998.0000 1.0000
52.0000 1058.0000 1.0000
52.0400 1274.0000 1.0000
52.0800 1637.0000 1.0000
52.1200 1898.0000 1.0000
52.1600 2622.0000 1.0000
52.2000 3596.0000 1.0000
52.2400 4684.0000 1.0000
52.2800 5297.0000 1.0000
52.3200 4936.0000 1.0000
52.3600 4367.0000 1.0000
52.4000 3833.0000 1.0000
52.4400 3300.0000 1.0000
52.4800 2532.0000 1.0000
52.5200 1915.0000 1.0000
52.5600 1532.0000 1.0000
52.6000 1241.0000 1.0000
52.6400 1111.0000 1.0000
52.6800 1038.0000 1.0000
52.7200 926.0000 1.0000
52.7600 857.0000 1.0000
52.8000 828.0000 1.0000
52.8400 824.0000 1.0000
52.8800 776.0000 1.0000
52.9200 778.0000 1.0000
52.9600 763.0000 1.0000
53.0000 767.0000 1.0000
53.0400 746.0000 1.0000
53.0800 721.0000 1.0000
53.1200 684.0000 1.0000
53.1600 677.0000 1.0000
53.2000 748.0000 1.0000
53.2400 690.0000 1.0000
53.2800 745.0000 1.0000
53.3200 717.0000 1.0000
53.3600 723.0000 1.0000
53.4000 685.0000 1.0000
53.4400 716.0000 1.0000
53.4800 679.0000 1.0000
53.5200 669.0000 1.0000
53.5600 675.0000 1.0000
53.6000 679.0000 1.0000
53.6400 703.0000 1.0000
53.6800 663.0000 1.0000
53.7200 675.0000 1.0000
53.7600 678.0000 1.0000
53.8000 685.0000 1.0000
53.8400 640.0000 1.0000
53.8800 667.0000 1.0000
53.9200 714.0000 1.0000
53.9600 701.0000 1.0000
54.0000 698.0000 1.0000
54.0400 689.0000 1.0000
54.0800 633.0000 1.0000
54.1200 665.0000 1.0000
54.1600 674.0000 1.0000
54.2000 694.0000 1.0000
54.2400 672.0000 1.0000
54.2800 676.0000 1.0000
54.3200 708.0000 1.0000
54.3600 719.0000 1.0000
54.4000 694.0000 1.0000
54.4400 693.0000 1.0000
54.4800 693.0000 1.0000
54.5200 683.0000 1.0000
54.5600 680.0000 1.0000
54.6000 686.0000 1.0000
54.6400 653.0000 1.0000
54.6800 722.0000 1.0000
54.7200 713.0000 1.0000
54.7600 750.0000 1.0000
54.8000 758.0000 1.0000
54.8400 711.0000 1.0000
54.8800 760.0000 1.0000
54.9200 787.0000 1.0000
54.9600 726.0000 1.0000
55.0000 797.0000 1.0000
55.0400 727.0000 1.0000
55.0800 756.0000 1.0000
55.1200 851.0000 1.0000
55.1600 858.0000 1.0000
55.2000 929.0000 1.0000
55.2400 1015.0000 1.0000
55.2800 1077.0000 1.0000
55.3200 1060.0000 1.0000
55.3600 1007.0000 1.0000
55.4000 1004.0000 1.0000
55.4400 886.0000 1.0000
55.4800 885.0000 1.0000
55.5200 835.0000 1.0000
55.5600 808.0000 1.0000
55.6000 778.0000 1.0000
55.6400 774.0000 1.0000
55.6800 721.0000 1.0000
55.7200 694.0000 1.0000
55.7600 737.0000 1.0000
55.8000 645.0000 1.0000
55.8400 661.0000 1.0000
55.8800 683.0000 1.0000
55.9200 668.0000 1.0000
55.9600 673.0000 1.0000
56.0000 688.0000 1.0000
56.0400 656.0000 1.0000
56.0800 657.0000 1.0000
56.1200 690.0000 1.0000
56.1600 694.0000 1.0000
56.2000 634.0000 1.0000
56.2400 686.0000 1.0000
56.2800 671.0000 1.0000
56.3200 634.0000 1.0000
56.3600 679.0000 1.0000
56.4000 699.0000 1.0000
56.4400 675.0000 1.0000
56.4800 610.0000 1.0000
56.5200 655.0000 1.0000
56.5600 679.0000 1.0000
56.6000 670.0000 1.0000
56.6400 653.0000 1.0000
56.6800 647.0000 1.0000
56.7200 693.0000 1.0000
56.7600 709.0000 1.0000
56.8000 638.0000 1.0000
56.8400 628.0000 1.0000
56.8800 665.0000 1.0000
56.9200 648.0000 1.0000
56.9600 653.0000 1.0000
57.0000 643.0000 1.0000
57.0400 674.0000 1.0000
57.0800 625.0000 1.0000
57.1200 653.0000 1.0000
57.1600 641.0000 1.0000
57.2000 643.0000 1.0000
57.2400 643.0000 1.0000
57.2800 662.0000 1.0000
57.3200 652.0000 1.0000
57.3600 592.0000 1.0000
57.4000 646.0000 1.0000
57.4400 631.0000 1.0000
57.4800 656.0000 1.0000
57.5200 652.0000 1.0000
57.5600 619.0000 1.0000
57.6000 710.0000 1.0000
57.6400 667.0000 1.0000
57.6800 668.0000 1.0000
57.7200 654.0000 1.0000
57.7600 641.0000 1.0000
57.8000 647.0000 1.0000
57.8400 624.0000 1.0000
57.8800 690.0000 1.0000
57.9200 651.0000 1.0000
57.9600 682.0000 1.0000
58.0000 679.0000 1.0000
58.0400 666.0000 1.0000
58.0800 673.0000 1.0000
58.1200 645.0000 1.0000
58.1600 657.0000 1.0000
58.2000 657.0000 1.0000
58.2400 656.0000 1.0000
58.2800 713.0000 1.0000
58.3200 702.0000 1.0000
58.3600 684.0000 1.0000
58.4000 673.0000 1.0000
58.4400 654.0000 1.0000
58.4800 670.0000 1.0000
58.5200 629.0000 1.0000
58.5600 646.0000 1.0000
58.6000 633.0000 1.0000
58.6400 644.0000 1.0000
58.6800 663.0000 1.0000
58.7200 619.0000 1.0000
58.7600 640.0000 1.0000
58.8000 643.0000 1.0000
58.8400 665.0000 1.0000
58.8800 657.0000 1.0000
58.9200 642.0000 1.0000
58.9600 644.0000 1.0000
59.0000 685.0000 1.0000
59.0400 623.0000 1.0000
59.0800 615.0000 1.0000
59.1200 676.0000 1.0000
59.1600 609.0000 1.0000
59.2000 653.0000 1.0000
59.2400 627.0000 1.0000
59.2800 679.0000 1.0000
59.3200 658.0000 1.0000
59.3600 661.0000 1.0000
59.4000 656.0000 1.0000
59.4400 641.0000 1.0000
59.4800 652.0000 1.0000
59.5200 621.0000 1.0000
59.5600 643.0000 1.0000
59.6000 622.0000 1.0000
59.6400 642.0000 1.0000
59.6800 607.0000 1.0000
59.7200 647.0000 1.0000
59.7600 624.0000 1.0000
59.8000 648.0000 1.0000
59.8400 637.0000 1.0000
59.8800 630.0000 1.0000
59.9200 677.0000 1.0000
59.9600 675.0000 1.0000
60.0000 665.0000 1.0000
60.0400 662.0000 1.0000
60.0800 632.0000 1.0000
60.1200 664.0000 1.0000
60.1600 620.0000 1.0000
60.2000 661.0000 1.0000
60.2400 661.0000 1.0000
60.2800 629.0000 1.0000
60.3200 619.0000 1.0000
60.3600 678.0000 1.0000
60.4000 652.0000 1.0000
60.4400 633.0000 1.0000
60.4800 694.0000 1.0000
60.5200 636.0000 1.0000
60.5600 655.0000 1.0000
60.6000 665.0000 1.0000
60.6400 634.0000 1.0000
60.6800 639.0000 1.0000
60.7200 628.0000 1.0000
60.7600 623.0000 1.0000
60.8000 632.0000 1.0000
60.8400 649.0000 1.0000
60.8800 672.0000 1.0000
60.9200 686.0000 1.0000
60.9600 652.0000 1.0000
61.0000 628.0000 1.0000
61.0400 632.0000 1.0000
61.0800 616.0000 1.0000
61.1200 646.0000 1.0000
61.1600 628.0000 1.0000
61.2000 657.0000 1.0000
61.2400 618.0000 1.0000
61.2800 634.0000 1.0000
61.3200 621.0000 1.0000
61.3600 694.0000 1.0000
61.4000 659.0000 1.0000
61.4400 706.0000 1.0000
61.4800 674.0000 1.0000
61.5200 646.0000 1.0000
61.5600 670.0000 1.0000
61.6000 627.0000 1.0000
61.6400 664.0000 1.0000
61.6800 705.0000 1.0000
61.7200 655.0000 1.0000
61.7600 704.0000 1.0000
61.8000 706.0000 1.0000
61.8400 731.0000 1.0000
61.8800 728.0000 1.0000
61.9200 753.0000 1.0000
61.9600 743.0000 1.0000
62.0000 812.0000 1.0000
62.0400 852.0000 1.0000
62.0800 981.0000 1.0000
62.1200 1010.0000 1.0000
62.1600 1132.0000 1.0000
62.2000 1296.0000 1.0000
62.2400 1394.0000 1.0000
62.2800 1437.0000 1.0000
62.3200 1458.0000 1.0000
62.3600 1473.0000 1.0000
62.4000 1439.0000 1.0000
62.4400 1333.0000 1.0000
62.4800 1337.0000 1.0000
62.5200 1182.0000 1.0000
62.5600 1065.0000 1.0000
62.6000 971.0000 1.0000
62.6400 902.0000 1.0000
62.6800 899.0000 1.0000
62.7200 839.0000 1.0000
62.7600 790.0000 1.0000
62.8000 791.0000 1.0000
62.8400 746.0000 1.0000
62.8800 760.0000 1.0000
62.9200 710.0000 1.0000
62.9600 691.0000 1.0000
63.0000 762.0000 1.0000
63.0400 668.0000 1.0000
63.0800 725.0000 1.0000
63.1200 696.0000 1.0000
63.1600 718.0000 1.0000
63.2000 678.0000 1.0000
63.2400 675.0000 1.0000
63.2800 664.0000 1.0000
63.3200 697.0000 1.0000
63.3600 684.0000 1.0000
63.4000 651.0000 1.0000
63.4400 671.0000 1.0000
63.4800 706.0000 1.0000
63.5200 659.0000 1.0000
63.5600 638.0000 1.0000
63.6000 622.0000 1.0000
63.6400 636.0000 1.0000
63.6800 648.0000 1.0000
63.7200 634.0000 1.0000
63.7600 634.0000 1.0000
63.8000 637.0000 1.0000
63.8400 639.0000 1.0000
63.8800 657.0000 1.0000
63.9200 645.0000 1.0000
63.9600 654.0000 1.0000
64.0000 634.0000 1.0000
64.0400 660.0000 1.0000
64.0800 646.0000 1.0000
64.1200 673.0000 1.0000
64.1600 642.0000 1.0000
64.2000 666.0000 1.0000
64.2400 669.0000 1.0000
64.2800 668.0000 1.0000
64.3200 659.0000 1.0000
64.3600 606.0000 1.0000
64.4000 652.0000 1.0000
64.4400 676.0000 1.0000
64.4800 656.0000 1.0000
64.5200 704.0000 1.0000
64.5600 721.0000 1.0000
64.6000 787.0000 1.0000
64.6400 822.0000 1.0000
64.6800 869.0000 1.0000
64.7200 852.0000 1.0000
64.7600 799.0000 1.0000
64.8000 805.0000 1.0000
64.8400 817.0000 1.0000
64.8800 798.0000 1.0000
64.9200 785.0000 1.0000
64.9600 712.0000 1.0000
65.0000 671.0000 1.0000
65.0400 710.0000 1.0000
65.0800 683.0000 1.0000
65.1200 706.0000 1.0000
65.1600 690.0000 1.0000
65.2000 690.0000 1.0000
65.2400 698.0000 1.0000
65.2800 683.0000 1.0000
65.3200 652.0000 1.0000
65.3600 718.0000 1.0000
65.4000 681.0000 1.0000
65.4400 665.0000 1.0000
65.4800 674.0000 1.0000
65.5200 682.0000 1.0000
65.5600 702.0000 1.0000
65.6000 720.0000 1.0000
65.6400 666.0000 1.0000
65.6800 697.0000 1.0000
65.7200 714.0000 1.0000
65.7600 728.0000 1.0000
65.8000 738.0000 1.0000
65.8400 743.0000 1.0000
65.8800 802.0000 1.0000
65.9200 861.0000 1.0000
65.9600 920.0000 1.0000
66.0000 994.0000 1.0000
66.0400 1100.0000 1.0000
66.0800 1270.0000 1.0000
66.1200 1503.0000 1.0000
66.1600 1859.0000 1.0000
66.2000 2299.0000 1.0000
66.2400 2601.0000 1.0000
66.2800 2784.0000 1.0000
66.3200 2597.0000 1.0000
66.3600 2455.0000 1.0000
66.4000 2323.0000 1.0000
66.4400 2097.0000 1.0000
66.4800 1924.0000 1.0000
66.5200 1684.0000 1.0000
66.5600 1398.0000 1.0000
66.6000 1175.0000 1.0000
66.6400 1080.0000 1.0000
66.6800 967.0000 1.0000
66.7200 939.0000 1.0000
66.7600 855.0000 1.0000
66.8000 778.0000 1.0000
66.8400 736.0000 1.0000
66.8800 736.0000 1.0000
66.9200 679.0000 1.0000
66.9600 705.0000 1.0000
67.0000 688.0000 1.0000
67.0400 646.0000 1.0000
67.0800 644.0000 1.0000
67.1200 705.0000 1.0000
67.1600 660.0000 1.0000
67.2000 634.0000 1.0000
67.2400 633.0000 1.0000
67.2800 624.0000 1.0000
67.3200 616.0000 1.0000
67.3600 648.0000 1.0000
67.4000 631.0000 1.0000
67.4400 622.0000 1.0000
67.4800 648.0000 1.0000
67.5200 603.0000 1.0000
67.5600 619.0000 1.0000
67.6000 642.0000 1.0000
67.6400 635.0000 1.0000
67.6800 621.0000 1.0000
67.7200 586.0000 1.0000
67.7600 650.0000 1.0000
67.8000 572.0000 1.0000
67.8400 605.0000 1.0000
67.8800 625.0000 1.0000
67.9200 591.0000 1.0000
67.9600 609.0000 1.0000
68.0000 589.0000 1.0000
68.0400 623.0000 1.0000
68.0800 575.0000 1.0000
68.1200 611.0000 1.0000
68.1600 570.0000 1.0000
68.2000 633.0000 1.0000
68.2400 590.0000 1.0000
68.2800 637.0000 1.0000
68.3200 593.0000 1.0000
68.3600 599.0000 1.0000
68.4000 573.0000 1.0000
68.4400 621.0000 1.0000
68.4800 594.0000 1.0000
68.5200 583.0000 1.0000
68.5600 602.0000 1.0000
68.6000 593.0000 1.0000
68.6400 552.0000 1.0000
68.6800 594.0000 1.0000
68.7200 574.0000 1.0000
68.7600 603.0000 1.0000
68.8000 586.0000 1.0000
68.8400 610.0000 1.0000
68.8800 579.0000 1.0000
68.9200 557.0000 1.0000
68.9600 622.0000 1.0000
69.0000 600.0000 1.0000
69.0400 531.0000 1.0000
69.0800 593.0000 1.0000
69.1200 581.0000 1.0000
69.1600 598.0000 1.0000
69.2000 593.0000 1.0000
69.2400 596.0000 1.0000
69.2800 589.0000 1.0000
69.3200 629.0000 1.0000
69.3600 563.0000 1.0000
69.4000 565.0000 1.0000
69.4400 563.0000 1.0000
69.4800 588.0000 1.0000
69.5200 593.0000 1.0000
69.5600 611.0000 1.0000
69.6000 597.0000 1.0000
69.6400 576.0000 1.0000
69.6800 556.0000 1.0000
69.7200 593.0000 1.0000
69.7600 609.0000 1.0000
69.8000 562.0000 1.0000
69.8400 598.0000 1.0000
69.8800 532.0000 1.0000
69.9200 566.0000 1.0000
69.9600 540.0000 1.0000
70.0000 577.0000 1.0000
*RAS_INT_END
*RAS_TEMPERATURE_START
*RAS_TEMPERATURE_END
*RAS_DATA_END