File: Section2_75_samples/XRD/No_051_NSS1_3.ras
*RAS_DATA_START
*RAS_HEADER_START
*DISP_FMT_X "%.2f"
*DISP_FMT_Y "%.0f"
*DISP_FULLSCALE "14544.0000000000"
*DISP_LINE_COLOR "255.0000000000"
*DISP_LINE_STYLE "0.0000000000"
*DISP_LINE_WIDTH "0.2500000000"
*DISP_NOTE "測定データ-8"
*DISP_OFFSET_Y "0.0000000000"
*DISP_PEAKSEARCH_UNIT_Y "cps"
*DISP_RANGE_BOTTOM "0.0000000000"
*DISP_RANGE_LEFT "20.0000000000"
*DISP_RANGE_LOGCUTOFF "0.0100000000"
*DISP_RANGE_RIGHT "70.0000000000"
*DISP_RANGE_TOP "14544.0000000000"
*DISP_SCALE_MODE_Y "0.0000000000"
*DISP_TAB_NAME "2θ/θ"
*DISP_TITLE_Y "強度"
*DISP_UNIT_Y "cps"
*DISP_WINDOW_NAME "MSG_MACROENGINE"
*FILE_COMMENT " "
*FILE_MD5 ""
*FILE_MEMO " "
*FILE_OPERATOR "Administrator"
*FILE_SAMPLE " "
*FILE_TYPE "RAS_RAW"
*FILE_USERGROUP "システムマネージャ"
*FILE_VERSION "1.0000000000"
*HW_ATTACHMENT_ID "ATT0025"
*HW_ATTACHMENT_NAME "標準|Standard"
*HW_COUNTER_ID-0 "CUT0025"
*HW_COUNTER_ID-1 "CUT0020"
*HW_COUNTER_ID-2 "CUT0020"
*HW_COUNTER_ID-3 "CSL0021"
*HW_COUNTER_ID-4 "CMC0021"
*HW_COUNTER_NAME-0 "D/teX Ultra|D/teX Ultra"
*HW_COUNTER_NAME-1 "None|None"
*HW_COUNTER_NAME-2 "None|None"
*HW_COUNTER_NAME-3 "BBM|BBM"
*HW_COUNTER_NAME-4 "検出器モノクロメータ|Detector monochromator"
*HW_COUNTER_SELECT_NAME "D/teX Ultra|D/teX Ultra"
*HW_GONIOMETER_ID "GON0023"
*HW_GONIOMETER_NAME "SmartLab|SmartLab"
*HW_GONIOMETER_RADIUS-0 "90.0"
*HW_GONIOMETER_RADIUS-1 "114.0"
*HW_GONIOMETER_RADIUS-2 "190.0"
*HW_GONIOMETER_RADIUS-3 "300.0"
*HW_GONIOMETER_RADIUS-4 "187.0"
*HW_GONIOMETER_RADIUS-5 "300.0"
*HW_GONIOMETER_RADIUS-6 "113.0"
*HW_GONIOMETER_RADIUS-7 "331.0"
*HW_I_OPT_ID-0 "CBO0021"
*HW_I_OPT_ID-1 "ICR0023"
*HW_I_OPT_ID-2 "ISL0021"
*HW_I_OPT_ID-3 "ISO0021"
*HW_I_OPT_ID-4 "IAD0021"
*HW_I_OPT_ID-5 "IPR0001"
*HW_I_OPT_NAME-0 "CBOユニット|CBO unit"
*HW_I_OPT_NAME-1 "標準入射光学ユニット|Standard incident optical unit"
*HW_I_OPT_NAME-2 "標準入射スリットボックス|Standard incident slit box"
*HW_I_OPT_NAME-3 "入射平行スリット|Incident parallel slit"
*HW_I_OPT_NAME-4 "長手制限スリット|Length limiting slit"
*HW_I_OPT_NAME-5 "None|None"
*HW_R_ATTENUATER_AUTOMODE "0"
*HW_R_OPT_ID-0 "RSS0021"
*HW_R_OPT_ID-1 "RCR0023"
*HW_R_OPT_ID-2 "RSO0021"
*HW_R_OPT_ID-3 "RRS0021"
*HW_R_OPT_ID-4 "ATN0021"
*HW_R_OPT_ID-5 "RFL0021"
*HW_R_OPT_ID-6 "RAD0021"
*HW_R_OPT_NAME-0 "標準受光スリットボックス1|Standard receiving slit box # 1"
*HW_R_OPT_NAME-1 "標準受光光学ユニット1|Standard receiving unit # 1"
*HW_R_OPT_NAME-2 "標準受光光学ユニット2|Standard receiving optical unit # 2"
*HW_R_OPT_NAME-3 "標準受光スリットボックス2|Standard receiving slit box # 2"
*HW_R_OPT_NAME-4 "標準アッテネータ|Standard Attenuator"
*HW_R_OPT_NAME-5 "Cu Kβ|Cu K-beta"
*HW_R_OPT_NAME-6 "調整用受光スリット|Alignment receiving slit"
*HW_SAMPLE_HOLDER_ID "SMP0023"
*HW_SAMPLE_HOLDER_NAME "標準Zステージ|Standard Z stage"
*HW_XG_CURRENT_MAX "50"
*HW_XG_CURRENT_MIN "2"
*HW_XG_CURRENT_RESOLUTION "1"
*HW_XG_CURRENT_UNIT "mA"
*HW_XG_FOCUS "1mm x 10mm"
*HW_XG_FOCUS_TYPE "Normal"
*HW_XG_ID ""
*HW_XG_NAME "3kW 封入管(ID:1200)|3kW Sealed tube(ID:1200)"
*HW_XG_TARGET_ATOMIC_NUMBER "29.0000000000"
*HW_XG_TARGET_NAME "Cu"
*HW_XG_TYPE "Hermetic"
*HW_XG_VOLTAGE_MAX "60"
*HW_XG_VOLTAGE_MIN "20"
*HW_XG_VOLTAGE_RESOLUTION "1"
*HW_XG_VOLTAGE_UNIT "kV"
*HW_XG_WATT_MAX "1.500"
*HW_XG_WATT_UNIT "kW"
*HW_XG_WAVE_LENGTH_ALPHA1 "1.540593"
*HW_XG_WAVE_LENGTH_ALPHA2 "1.544414"
*HW_XG_WAVE_LENGTH_BETA "1.392250"
*MEAS_COND_AXIS_NAME-0 "2θ/θ"
*MEAS_COND_AXIS_NAME-1 "2θ"
*MEAS_COND_AXIS_NAME-2 "ω"
*MEAS_COND_AXIS_NAME-3 "Z"
*MEAS_COND_AXIS_NAME-4 "2θ/ω"
*MEAS_COND_AXIS_NAME-5 "θs"
*MEAS_COND_AXIS_NAME-6 "θd"
*MEAS_COND_AXIS_NAME-7 "Ts"
*MEAS_COND_AXIS_NAME-8 "CBO選択スリット"
*MEAS_COND_AXIS_NAME-9 "M"
*MEAS_COND_AXIS_NAME-10 "入射平行スリット"
*MEAS_COND_AXIS_NAME-11 "入射スリット"
*MEAS_COND_AXIS_NAME-12 ""
*MEAS_COND_AXIS_NAME-13 "Zs"
*MEAS_COND_AXIS_NAME-14 "入射光学素子"
*MEAS_COND_AXIS_NAME-15 "長手制限スリット"
*MEAS_COND_AXIS_NAME-16 "センタースリット"
*MEAS_COND_AXIS_NAME-17 "フィルター"
*MEAS_COND_AXIS_NAME-18 "受光スリット1"
*MEAS_COND_AXIS_NAME-19 "受光スリット2"
*MEAS_COND_AXIS_NAME-20 "受光光学素子"
*MEAS_COND_AXIS_NAME-21 "受光平行スリット"
*MEAS_COND_AXIS_NAME-22 "調整用受光スリット"
*MEAS_COND_AXIS_NAME-23 ""
*MEAS_COND_AXIS_NAME-24 ""
*MEAS_COND_AXIS_NAME-25 "Zd"
*MEAS_COND_AXIS_NAME-26 "アッテネータ"
*MEAS_COND_AXIS_NAME-27 "検出器モノクロメータ"
*MEAS_COND_AXIS_NAME-28 "モノクロメータスリット"
*MEAS_COND_AXIS_NAME-29 "プライマリビーム"
*MEAS_COND_AXIS_NAME-30 "PHA"
*MEAS_COND_AXIS_NAME_INTERNAL-0 "TwoThetaTheta"
*MEAS_COND_AXIS_NAME_INTERNAL-1 "TwoTheta"
*MEAS_COND_AXIS_NAME_INTERNAL-2 "Omega"
*MEAS_COND_AXIS_NAME_INTERNAL-3 "Z"
*MEAS_COND_AXIS_NAME_INTERNAL-4 "TwoThetaOmega"
*MEAS_COND_AXIS_NAME_INTERNAL-5 "ThetaS"
*MEAS_COND_AXIS_NAME_INTERNAL-6 "ThetaD"
*MEAS_COND_AXIS_NAME_INTERNAL-7 "Ts"
*MEAS_COND_AXIS_NAME_INTERNAL-8 "CBO"
*MEAS_COND_AXIS_NAME_INTERNAL-9 "CBO-M"
*MEAS_COND_AXIS_NAME_INTERNAL-10 "IncidentSollerSlit"
*MEAS_COND_AXIS_NAME_INTERNAL-11 "IncidentSlitBox"
*MEAS_COND_AXIS_NAME_INTERNAL-12 "IncidentSlitBox-_Axis"
*MEAS_COND_AXIS_NAME_INTERNAL-13 "Zs"
*MEAS_COND_AXIS_NAME_INTERNAL-14 "IncidentMonochromator"
*MEAS_COND_AXIS_NAME_INTERNAL-15 "IncidentAxdSlit"
*MEAS_COND_AXIS_NAME_INTERNAL-16 "CenterSlit"
*MEAS_COND_AXIS_NAME_INTERNAL-17 "Filter"
*MEAS_COND_AXIS_NAME_INTERNAL-18 "ReceivingSlitBox1"
*MEAS_COND_AXIS_NAME_INTERNAL-19 "ReceivingSlitBox2"
*MEAS_COND_AXIS_NAME_INTERNAL-20 "ReceivingOptics"
*MEAS_COND_AXIS_NAME_INTERNAL-21 "ReceivingSollerSlit"
*MEAS_COND_AXIS_NAME_INTERNAL-22 "ReceivingAxdSlit"
*MEAS_COND_AXIS_NAME_INTERNAL-23 "ReceivingSlitBox1-_Axis"
*MEAS_COND_AXIS_NAME_INTERNAL-24 "ReceivingSlitBox2-_Axis"
*MEAS_COND_AXIS_NAME_INTERNAL-25 "ReceivingSlitBox2-Zd"
*MEAS_COND_AXIS_NAME_INTERNAL-26 "Attenuator"
*MEAS_COND_AXIS_NAME_INTERNAL-27 "CounterMonochromator"
*MEAS_COND_AXIS_NAME_INTERNAL-28 "CounterSlit"
*MEAS_COND_AXIS_NAME_INTERNAL-29 "IncidentPrimary"
*MEAS_COND_AXIS_NAME_INTERNAL-30 "PHA"
*MEAS_COND_AXIS_NAME_MAGICNO-0 "83951616.0000000000"
*MEAS_COND_AXIS_NAME_MAGICNO-1 "268632064.0000000000"
*MEAS_COND_AXIS_NAME_MAGICNO-2 "268500992.0000000000"
*MEAS_COND_AXIS_NAME_MAGICNO-3 "285278208.0000000000"
*MEAS_COND_AXIS_NAME_MAGICNO-4 "83951616.0000000000"
*MEAS_COND_AXIS_NAME_MAGICNO-5 "131072.0000000000"
*MEAS_COND_AXIS_NAME_MAGICNO-6 "131072.0000000000"
*MEAS_COND_AXIS_NAME_MAGICNO-7 "318898176.0000000000"
*MEAS_COND_AXIS_NAME_MAGICNO-8 "20971521.0000000000"
*MEAS_COND_AXIS_NAME_MAGICNO-9 "285343744.0000000000"
*MEAS_COND_AXIS_NAME_MAGICNO-10 "20971521.0000000000"
*MEAS_COND_AXIS_NAME_MAGICNO-11 "22020097.0000000000"
*MEAS_COND_AXIS_NAME_MAGICNO-12 "25165824.0000000000"
*MEAS_COND_AXIS_NAME_MAGICNO-13 "318898176.0000000000"
*MEAS_COND_AXIS_NAME_MAGICNO-14 "1.0000000000"
*MEAS_COND_AXIS_NAME_MAGICNO-15 "20971521.0000000000"
*MEAS_COND_AXIS_NAME_MAGICNO-16 "20971521.0000000000"
*MEAS_COND_AXIS_NAME_MAGICNO-17 "20971521.0000000000"
*MEAS_COND_AXIS_NAME_MAGICNO-18 "23068673.0000000000"
*MEAS_COND_AXIS_NAME_MAGICNO-19 "23068673.0000000000"
*MEAS_COND_AXIS_NAME_MAGICNO-20 "20971521.0000000000"
*MEAS_COND_AXIS_NAME_MAGICNO-21 "20971521.0000000000"
*MEAS_COND_AXIS_NAME_MAGICNO-22 "20971521.0000000000"
*MEAS_COND_AXIS_NAME_MAGICNO-23 "25165824.0000000000"
*MEAS_COND_AXIS_NAME_MAGICNO-24 "25165824.0000000000"
*MEAS_COND_AXIS_NAME_MAGICNO-25 "285343744.0000000000"
*MEAS_COND_AXIS_NAME_MAGICNO-26 "17301505.0000000000"
*MEAS_COND_AXIS_NAME_MAGICNO-27 "20971521.0000000000"
*MEAS_COND_AXIS_NAME_MAGICNO-28 "20971521.0000000000"
*MEAS_COND_AXIS_NAME_MAGICNO-29 "20971521.0000000000"
*MEAS_COND_AXIS_NAME_MAGICNO-30 "0.0000000000"
*MEAS_COND_AXIS_OFFSET-0 "-"
*MEAS_COND_AXIS_OFFSET-1 "-0.1081000000"
*MEAS_COND_AXIS_OFFSET-2 "0.3758000000"
*MEAS_COND_AXIS_OFFSET-3 "-"
*MEAS_COND_AXIS_OFFSET-4 "-"
*MEAS_COND_AXIS_OFFSET-5 "0.3758000000"
*MEAS_COND_AXIS_OFFSET-6 "-0.4839000000"
*MEAS_COND_AXIS_OFFSET-7 "-"
*MEAS_COND_AXIS_OFFSET-8 "-"
*MEAS_COND_AXIS_OFFSET-9 "-"
*MEAS_COND_AXIS_OFFSET-10 "-"
*MEAS_COND_AXIS_OFFSET-11 "-"
*MEAS_COND_AXIS_OFFSET-12 "-"
*MEAS_COND_AXIS_OFFSET-13 "-"
*MEAS_COND_AXIS_OFFSET-14 "-"
*MEAS_COND_AXIS_OFFSET-15 "-"
*MEAS_COND_AXIS_OFFSET-16 "-"
*MEAS_COND_AXIS_OFFSET-17 "-"
*MEAS_COND_AXIS_OFFSET-18 "-"
*MEAS_COND_AXIS_OFFSET-19 "-"
*MEAS_COND_AXIS_OFFSET-20 "-"
*MEAS_COND_AXIS_OFFSET-21 "-"
*MEAS_COND_AXIS_OFFSET-22 "-"
*MEAS_COND_AXIS_OFFSET-23 "-"
*MEAS_COND_AXIS_OFFSET-24 "-"
*MEAS_COND_AXIS_OFFSET-25 "-"
*MEAS_COND_AXIS_OFFSET-26 "-"
*MEAS_COND_AXIS_OFFSET-27 "-"
*MEAS_COND_AXIS_OFFSET-28 "-"
*MEAS_COND_AXIS_OFFSET-29 "-"
*MEAS_COND_AXIS_OFFSET-30 "-"
*MEAS_COND_AXIS_POSITION-0 "0.0000000000"
*MEAS_COND_AXIS_POSITION-1 "0.0000000000"
*MEAS_COND_AXIS_POSITION-2 "0.0000000000"
*MEAS_COND_AXIS_POSITION-3 "-0.5500000000"
*MEAS_COND_AXIS_POSITION-4 "0.0000000000"
*MEAS_COND_AXIS_POSITION-5 "0.0000000000"
*MEAS_COND_AXIS_POSITION-6 "0.0000000000"
*MEAS_COND_AXIS_POSITION-7 "-0.4278800000"
*MEAS_COND_AXIS_POSITION-8 "BB"
*MEAS_COND_AXIS_POSITION-9 "0.0000000000"
*MEAS_COND_AXIS_POSITION-10 "Soller_slit_5.0deg"
*MEAS_COND_AXIS_POSITION-11 "2/3deg"
*MEAS_COND_AXIS_POSITION-12 "2.2088000000"
*MEAS_COND_AXIS_POSITION-13 "-0.4140600000"
*MEAS_COND_AXIS_POSITION-14 "0.0000000000"
*MEAS_COND_AXIS_POSITION-15 "10.0mm"
*MEAS_COND_AXIS_POSITION-16 "None"
*MEAS_COND_AXIS_POSITION-17 "Cu_K-beta"
*MEAS_COND_AXIS_POSITION-18 "13.000mm"
*MEAS_COND_AXIS_POSITION-19 "13.000mm"
*MEAS_COND_AXIS_POSITION-20 "No_unit"
*MEAS_COND_AXIS_POSITION-21 "Soller_slit_5.0deg"
*MEAS_COND_AXIS_POSITION-22 "None"
*MEAS_COND_AXIS_POSITION-23 "13.0000000000"
*MEAS_COND_AXIS_POSITION-24 "13.0000000000"
*MEAS_COND_AXIS_POSITION-25 "0.0109400000"
*MEAS_COND_AXIS_POSITION-26 "Open"
*MEAS_COND_AXIS_POSITION-27 "None"
*MEAS_COND_AXIS_POSITION-28 "None"
*MEAS_COND_AXIS_POSITION-29 "None"
*MEAS_COND_AXIS_POSITION-30 "38.0000000000"
*MEAS_COND_AXIS_UNIT-0 "deg"
*MEAS_COND_AXIS_UNIT-1 "deg"
*MEAS_COND_AXIS_UNIT-2 "deg"
*MEAS_COND_AXIS_UNIT-3 "mm"
*MEAS_COND_AXIS_UNIT-4 "deg"
*MEAS_COND_AXIS_UNIT-5 "deg"
*MEAS_COND_AXIS_UNIT-6 "deg"
*MEAS_COND_AXIS_UNIT-7 "mm"
*MEAS_COND_AXIS_UNIT-8 ""
*MEAS_COND_AXIS_UNIT-9 "pulse"
*MEAS_COND_AXIS_UNIT-10 ""
*MEAS_COND_AXIS_UNIT-11 ""
*MEAS_COND_AXIS_UNIT-12 "mm"
*MEAS_COND_AXIS_UNIT-13 "mm"
*MEAS_COND_AXIS_UNIT-14 ""
*MEAS_COND_AXIS_UNIT-15 ""
*MEAS_COND_AXIS_UNIT-16 ""
*MEAS_COND_AXIS_UNIT-17 ""
*MEAS_COND_AXIS_UNIT-18 ""
*MEAS_COND_AXIS_UNIT-19 ""
*MEAS_COND_AXIS_UNIT-20 ""
*MEAS_COND_AXIS_UNIT-21 ""
*MEAS_COND_AXIS_UNIT-22 ""
*MEAS_COND_AXIS_UNIT-23 "mm"
*MEAS_COND_AXIS_UNIT-24 "mm"
*MEAS_COND_AXIS_UNIT-25 "mm"
*MEAS_COND_AXIS_UNIT-26 ""
*MEAS_COND_AXIS_UNIT-27 ""
*MEAS_COND_AXIS_UNIT-28 ""
*MEAS_COND_AXIS_UNIT-29 ""
*MEAS_COND_AXIS_UNIT-30 "div"
*MEAS_COND_COUNTER_CNTLOSS_CORR "0.0000000000"
*MEAS_COND_COUNTER_PHABASE "38.0000000000"
*MEAS_COND_COUNTER_PHAWINDOW "16.0000000000"
*MEAS_COND_COUNTER_PHA_UNIT "div"
*MEAS_COND_COUNTER_TAUDIFF "30.0000000000"
*MEAS_COND_COUNTER_TAUINT "0.0000000000"
*MEAS_COND_IRRADIATION_MODE "OFF"
*MEAS_COND_IRRADIATION_WIDTH ""
*MEAS_COND_OPT_ATTR "集中法"
*MEAS_COND_OPT_NAME "@集中法"
*MEAS_COND_UNSYMMETRIC_MODE "OFF"
*MEAS_COND_XG_CURRENT "30.0000000000"
*MEAS_COND_XG_VOLTAGE "40.0000000000"
*MEAS_COND_XG_WAVE_TYPE "Ka"
*MEAS_DATA_COUNT "5001.0000000000"
*MEAS_SCAN_AXIS_X "2θ/θ"
*MEAS_SCAN_AXIS_X_INTERNAL "TwoThetaTheta"
*MEAS_SCAN_END_TIME "07/08/21 19:48:48"
*MEAS_SCAN_MODE "CONTINUOUS"
*MEAS_SCAN_MONITOR "0"
*MEAS_SCAN_RESOLUTION_X "0.0002"
*MEAS_SCAN_SPEED "1.0"
*MEAS_SCAN_SPEED_UNIT "deg/min"
*MEAS_SCAN_START "20.0000000000"
*MEAS_SCAN_START_TIME "07/08/21 18:55:55"
*MEAS_SCAN_STEP "0.0100000000"
*MEAS_SCAN_STOP "70.0000000000"
*MEAS_SCAN_UNIT_X "deg"
*MEAS_SCAN_UNIT_Y "counts"
*RAS_HEADER_END
*RAS_INT_START
20.0000 1541.0000 1.0000
20.0400 1578.0000 1.0000
20.0800 1577.0000 1.0000
20.1200 1566.0000 1.0000
20.1600 1548.0000 1.0000
20.2000 1527.0000 1.0000
20.2400 1562.0000 1.0000
20.2800 1523.0000 1.0000
20.3200 1508.0000 1.0000
20.3600 1550.0000 1.0000
20.4000 1534.0000 1.0000
20.4400 1525.0000 1.0000
20.4800 1512.0000 1.0000
20.5200 1581.0000 1.0000
20.5600 1559.0000 1.0000
20.6000 1579.0000 1.0000
20.6400 1576.0000 1.0000
20.6800 1555.0000 1.0000
20.7200 1601.0000 1.0000
20.7600 1550.0000 1.0000
20.8000 1544.0000 1.0000
20.8400 1634.0000 1.0000
20.8800 1547.0000 1.0000
20.9200 1612.0000 1.0000
20.9600 1565.0000 1.0000
21.0000 1551.0000 1.0000
21.0400 1574.0000 1.0000
21.0800 1565.0000 1.0000
21.1200 1616.0000 1.0000
21.1600 1543.0000 1.0000
21.2000 1520.0000 1.0000
21.2400 1579.0000 1.0000
21.2800 1553.0000 1.0000
21.3200 1587.0000 1.0000
21.3600 1558.0000 1.0000
21.4000 1590.0000 1.0000
21.4400 1585.0000 1.0000
21.4800 1540.0000 1.0000
21.5200 1582.0000 1.0000
21.5600 1598.0000 1.0000
21.6000 1586.0000 1.0000
21.6400 1571.0000 1.0000
21.6800 1585.0000 1.0000
21.7200 1612.0000 1.0000
21.7600 1545.0000 1.0000
21.8000 1633.0000 1.0000
21.8400 1575.0000 1.0000
21.8800 1675.0000 1.0000
21.9200 1553.0000 1.0000
21.9600 1579.0000 1.0000
22.0000 1533.0000 1.0000
22.0400 1591.0000 1.0000
22.0800 1539.0000 1.0000
22.1200 1564.0000 1.0000
22.1600 1574.0000 1.0000
22.2000 1665.0000 1.0000
22.2400 1611.0000 1.0000
22.2800 1612.0000 1.0000
22.3200 1573.0000 1.0000
22.3600 1543.0000 1.0000
22.4000 1523.0000 1.0000
22.4400 1535.0000 1.0000
22.4800 1646.0000 1.0000
22.5200 1614.0000 1.0000
22.5600 1565.0000 1.0000
22.6000 1523.0000 1.0000
22.6400 1582.0000 1.0000
22.6800 1617.0000 1.0000
22.7200 1594.0000 1.0000
22.7600 1589.0000 1.0000
22.8000 1617.0000 1.0000
22.8400 1603.0000 1.0000
22.8800 1619.0000 1.0000
22.9200 1594.0000 1.0000
22.9600 1597.0000 1.0000
23.0000 1540.0000 1.0000
23.0400 1599.0000 1.0000
23.0800 1618.0000 1.0000
23.1200 1593.0000 1.0000
23.1600 1629.0000 1.0000
23.2000 1625.0000 1.0000
23.2400 1620.0000 1.0000
23.2800 1596.0000 1.0000
23.3200 1566.0000 1.0000
23.3600 1616.0000 1.0000
23.4000 1637.0000 1.0000
23.4400 1620.0000 1.0000
23.4800 1668.0000 1.0000
23.5200 1578.0000 1.0000
23.5600 1632.0000 1.0000
23.6000 1611.0000 1.0000
23.6400 1683.0000 1.0000
23.6800 1613.0000 1.0000
23.7200 1707.0000 1.0000
23.7600 1569.0000 1.0000
23.8000 1591.0000 1.0000
23.8400 1599.0000 1.0000
23.8800 1687.0000 1.0000
23.9200 1652.0000 1.0000
23.9600 1714.0000 1.0000
24.0000 1600.0000 1.0000
24.0400 1639.0000 1.0000
24.0800 1698.0000 1.0000
24.1200 1638.0000 1.0000
24.1600 1682.0000 1.0000
24.2000 1674.0000 1.0000
24.2400 1619.0000 1.0000
24.2800 1685.0000 1.0000
24.3200 1631.0000 1.0000
24.3600 1664.0000 1.0000
24.4000 1668.0000 1.0000
24.4400 1698.0000 1.0000
24.4800 1668.0000 1.0000
24.5200 1661.0000 1.0000
24.5600 1679.0000 1.0000
24.6000 1679.0000 1.0000
24.6400 1741.0000 1.0000
24.6800 1702.0000 1.0000
24.7200 1682.0000 1.0000
24.7600 1592.0000 1.0000
24.8000 1720.0000 1.0000
24.8400 1717.0000 1.0000
24.8800 1673.0000 1.0000
24.9200 1668.0000 1.0000
24.9600 1703.0000 1.0000
25.0000 1701.0000 1.0000
25.0400 1683.0000 1.0000
25.0800 1681.0000 1.0000
25.1200 1737.0000 1.0000
25.1600 1721.0000 1.0000
25.2000 1772.0000 1.0000
25.2400 1753.0000 1.0000
25.2800 1723.0000 1.0000
25.3200 1651.0000 1.0000
25.3600 1783.0000 1.0000
25.4000 1703.0000 1.0000
25.4400 1720.0000 1.0000
25.4800 1675.0000 1.0000
25.5200 1750.0000 1.0000
25.5600 1719.0000 1.0000
25.6000 1720.0000 1.0000
25.6400 1695.0000 1.0000
25.6800 1617.0000 1.0000
25.7200 1718.0000 1.0000
25.7600 1766.0000 1.0000
25.8000 1657.0000 1.0000
25.8400 1666.0000 1.0000
25.8800 1687.0000 1.0000
25.9200 1656.0000 1.0000
25.9600 1679.0000 1.0000
26.0000 1649.0000 1.0000
26.0400 1710.0000 1.0000
26.0800 1684.0000 1.0000
26.1200 1688.0000 1.0000
26.1600 1718.0000 1.0000
26.2000 1687.0000 1.0000
26.2400 1681.0000 1.0000
26.2800 1713.0000 1.0000
26.3200 1721.0000 1.0000
26.3600 1732.0000 1.0000
26.4000 1706.0000 1.0000
26.4400 1815.0000 1.0000
26.4800 1751.0000 1.0000
26.5200 1719.0000 1.0000
26.5600 1769.0000 1.0000
26.6000 1795.0000 1.0000
26.6400 1791.0000 1.0000
26.6800 1849.0000 1.0000
26.7200 1840.0000 1.0000
26.7600 1823.0000 1.0000
26.8000 1919.0000 1.0000
26.8400 1873.0000 1.0000
26.8800 1999.0000 1.0000
26.9200 1950.0000 1.0000
26.9600 2093.0000 1.0000
27.0000 2119.0000 1.0000
27.0400 2241.0000 1.0000
27.0800 2572.0000 1.0000
27.1200 2650.0000 1.0000
27.1600 3069.0000 1.0000
27.2000 3469.0000 1.0000
27.2400 4285.0000 1.0000
27.2800 5140.0000 1.0000
27.3200 5958.0000 1.0000
27.3600 6535.0000 1.0000
27.4000 6038.0000 1.0000
27.4400 5103.0000 1.0000
27.4800 4113.0000 1.0000
27.5200 3420.0000 1.0000
27.5600 2943.0000 1.0000
27.6000 2568.0000 1.0000
27.6400 2346.0000 1.0000
27.6800 2222.0000 1.0000
27.7200 2057.0000 1.0000
27.7600 1969.0000 1.0000
27.8000 1988.0000 1.0000
27.8400 1881.0000 1.0000
27.8800 1907.0000 1.0000
27.9200 1811.0000 1.0000
27.9600 1831.0000 1.0000
28.0000 1787.0000 1.0000
28.0400 1788.0000 1.0000
28.0800 1708.0000 1.0000
28.1200 1730.0000 1.0000
28.1600 1709.0000 1.0000
28.2000 1732.0000 1.0000
28.2400 1669.0000 1.0000
28.2800 1746.0000 1.0000
28.3200 1715.0000 1.0000
28.3600 1662.0000 1.0000
28.4000 1662.0000 1.0000
28.4400 1633.0000 1.0000
28.4800 1639.0000 1.0000
28.5200 1657.0000 1.0000
28.5600 1620.0000 1.0000
28.6000 1629.0000 1.0000
28.6400 1669.0000 1.0000
28.6800 1607.0000 1.0000
28.7200 1621.0000 1.0000
28.7600 1599.0000 1.0000
28.8000 1701.0000 1.0000
28.8400 1595.0000 1.0000
28.8800 1608.0000 1.0000
28.9200 1546.0000 1.0000
28.9600 1627.0000 1.0000
29.0000 1576.0000 1.0000
29.0400 1622.0000 1.0000
29.0800 1624.0000 1.0000
29.1200 1589.0000 1.0000
29.1600 1573.0000 1.0000
29.2000 1619.0000 1.0000
29.2400 1640.0000 1.0000
29.2800 1588.0000 1.0000
29.3200 1538.0000 1.0000
29.3600 1556.0000 1.0000
29.4000 1556.0000 1.0000
29.4400 1562.0000 1.0000
29.4800 1563.0000 1.0000
29.5200 1528.0000 1.0000
29.5600 1530.0000 1.0000
29.6000 1543.0000 1.0000
29.6400 1538.0000 1.0000
29.6800 1550.0000 1.0000
29.7200 1601.0000 1.0000
29.7600 1597.0000 1.0000
29.8000 1538.0000 1.0000
29.8400 1509.0000 1.0000
29.8800 1540.0000 1.0000
29.9200 1609.0000 1.0000
29.9600 1522.0000 1.0000
30.0000 1558.0000 1.0000
30.0400 1488.0000 1.0000
30.0800 1480.0000 1.0000
30.1200 1532.0000 1.0000
30.1600 1512.0000 1.0000
30.2000 1553.0000 1.0000
30.2400 1538.0000 1.0000
30.2800 1453.0000 1.0000
30.3200 1571.0000 1.0000
30.3600 1492.0000 1.0000
30.4000 1532.0000 1.0000
30.4400 1520.0000 1.0000
30.4800 1471.0000 1.0000
30.5200 1521.0000 1.0000
30.5600 1450.0000 1.0000
30.6000 1468.0000 1.0000
30.6400 1526.0000 1.0000
30.6800 1524.0000 1.0000
30.7200 1481.0000 1.0000
30.7600 1432.0000 1.0000
30.8000 1535.0000 1.0000
30.8400 1434.0000 1.0000
30.8800 1455.0000 1.0000
30.9200 1469.0000 1.0000
30.9600 1461.0000 1.0000
31.0000 1454.0000 1.0000
31.0400 1495.0000 1.0000
31.0800 1480.0000 1.0000
31.1200 1503.0000 1.0000
31.1600 1481.0000 1.0000
31.2000 1497.0000 1.0000
31.2400 1459.0000 1.0000
31.2800 1469.0000 1.0000
31.3200 1464.0000 1.0000
31.3600 1491.0000 1.0000
31.4000 1497.0000 1.0000
31.4400 1381.0000 1.0000
31.4800 1402.0000 1.0000
31.5200 1460.0000 1.0000
31.5600 1449.0000 1.0000
31.6000 1392.0000 1.0000
31.6400 1419.0000 1.0000
31.6800 1427.0000 1.0000
31.7200 1515.0000 1.0000
31.7600 1470.0000 1.0000
31.8000 1442.0000 1.0000
31.8400 1402.0000 1.0000
31.8800 1440.0000 1.0000
31.9200 1420.0000 1.0000
31.9600 1499.0000 1.0000
32.0000 1484.0000 1.0000
32.0400 1438.0000 1.0000
32.0800 1435.0000 1.0000
32.1200 1459.0000 1.0000
32.1600 1461.0000 1.0000
32.2000 1418.0000 1.0000
32.2400 1409.0000 1.0000
32.2800 1392.0000 1.0000
32.3200 1392.0000 1.0000
32.3600 1412.0000 1.0000
32.4000 1395.0000 1.0000
32.4400 1347.0000 1.0000
32.4800 1345.0000 1.0000
32.5200 1373.0000 1.0000
32.5600 1390.0000 1.0000
32.6000 1393.0000 1.0000
32.6400 1373.0000 1.0000
32.6800 1391.0000 1.0000
32.7200 1357.0000 1.0000
32.7600 1371.0000 1.0000
32.8000 1435.0000 1.0000
32.8400 1404.0000 1.0000
32.8800 1306.0000 1.0000
32.9200 1403.0000 1.0000
32.9600 1411.0000 1.0000
33.0000 1369.0000 1.0000
33.0400 1417.0000 1.0000
33.0800 1393.0000 1.0000
33.1200 1375.0000 1.0000
33.1600 1328.0000 1.0000
33.2000 1398.0000 1.0000
33.2400 1338.0000 1.0000
33.2800 1345.0000 1.0000
33.3200 1345.0000 1.0000
33.3600 1391.0000 1.0000
33.4000 1386.0000 1.0000
33.4400 1322.0000 1.0000
33.4800 1402.0000 1.0000
33.5200 1335.0000 1.0000
33.5600 1410.0000 1.0000
33.6000 1333.0000 1.0000
33.6400 1387.0000 1.0000
33.6800 1368.0000 1.0000
33.7200 1375.0000 1.0000
33.7600 1365.0000 1.0000
33.8000 1348.0000 1.0000
33.8400 1429.0000 1.0000
33.8800 1434.0000 1.0000
33.9200 1468.0000 1.0000
33.9600 1430.0000 1.0000
34.0000 1444.0000 1.0000
34.0400 1522.0000 1.0000
34.0800 1490.0000 1.0000
34.1200 1489.0000 1.0000
34.1600 1494.0000 1.0000
34.2000 1501.0000 1.0000
34.2400 1511.0000 1.0000
34.2800 1586.0000 1.0000
34.3200 1722.0000 1.0000
34.3600 1791.0000 1.0000
34.4000 1964.0000 1.0000
34.4400 2161.0000 1.0000
34.4800 2615.0000 1.0000
34.5200 2808.0000 1.0000
34.5600 2810.0000 1.0000
34.6000 2810.0000 1.0000
34.6400 2461.0000 1.0000
34.6800 2264.0000 1.0000
34.7200 1911.0000 1.0000
34.7600 1751.0000 1.0000
34.8000 1695.0000 1.0000
34.8400 1558.0000 1.0000
34.8800 1533.0000 1.0000
34.9200 1430.0000 1.0000
34.9600 1404.0000 1.0000
35.0000 1325.0000 1.0000
35.0400 1268.0000 1.0000
35.0800 1289.0000 1.0000
35.1200 1282.0000 1.0000
35.1600 1343.0000 1.0000
35.2000 1299.0000 1.0000
35.2400 1208.0000 1.0000
35.2800 1260.0000 1.0000
35.3200 1214.0000 1.0000
35.3600 1215.0000 1.0000
35.4000 1213.0000 1.0000
35.4400 1202.0000 1.0000
35.4800 1220.0000 1.0000
35.5200 1200.0000 1.0000
35.5600 1219.0000 1.0000
35.6000 1182.0000 1.0000
35.6400 1198.0000 1.0000
35.6800 1264.0000 1.0000
35.7200 1169.0000 1.0000
35.7600 1175.0000 1.0000
35.8000 1131.0000 1.0000
35.8400 1167.0000 1.0000
35.8800 1201.0000 1.0000
35.9200 1186.0000 1.0000
35.9600 1162.0000 1.0000
36.0000 1214.0000 1.0000
36.0400 1206.0000 1.0000
36.0800 1188.0000 1.0000
36.1200 1273.0000 1.0000
36.1600 1214.0000 1.0000
36.2000 1309.0000 1.0000
36.2400 1417.0000 1.0000
36.2800 1506.0000 1.0000
36.3200 1665.0000 1.0000
36.3600 1839.0000 1.0000
36.4000 1928.0000 1.0000
36.4400 2047.0000 1.0000
36.4800 2178.0000 1.0000
36.5200 2027.0000 1.0000
36.5600 1922.0000 1.0000
36.6000 1707.0000 1.0000
36.6400 1484.0000 1.0000
36.6800 1413.0000 1.0000
36.7200 1301.0000 1.0000
36.7600 1248.0000 1.0000
36.8000 1172.0000 1.0000
36.8400 1208.0000 1.0000
36.8800 1142.0000 1.0000
36.9200 1139.0000 1.0000
36.9600 1126.0000 1.0000
37.0000 1117.0000 1.0000
37.0400 1093.0000 1.0000
37.0800 1061.0000 1.0000
37.1200 1100.0000 1.0000
37.1600 1093.0000 1.0000
37.2000 1090.0000 1.0000
37.2400 1064.0000 1.0000
37.2800 1130.0000 1.0000
37.3200 1071.0000 1.0000
37.3600 1132.0000 1.0000
37.4000 1073.0000 1.0000
37.4400 1084.0000 1.0000
37.4800 1063.0000 1.0000
37.5200 1043.0000 1.0000
37.5600 1065.0000 1.0000
37.6000 1086.0000 1.0000
37.6400 1107.0000 1.0000
37.6800 1071.0000 1.0000
37.7200 1062.0000 1.0000
37.7600 1043.0000 1.0000
37.8000 1161.0000 1.0000
37.8400 1074.0000 1.0000
37.8800 1121.0000 1.0000
37.9200 1096.0000 1.0000
37.9600 1164.0000 1.0000
38.0000 1137.0000 1.0000
38.0400 1195.0000 1.0000
38.0800 1169.0000 1.0000
38.1200 1193.0000 1.0000
38.1600 1244.0000 1.0000
38.2000 1462.0000 1.0000
38.2400 1454.0000 1.0000
38.2800 1706.0000 1.0000
38.3200 1914.0000 1.0000
38.3600 2208.0000 1.0000
38.4000 2683.0000 1.0000
38.4400 3330.0000 1.0000
38.4800 4462.0000 1.0000
38.5200 5757.0000 1.0000
38.5600 7048.0000 1.0000
38.6000 7225.0000 1.0000
38.6400 6667.0000 1.0000
38.6800 5911.0000 1.0000
38.7200 4748.0000 1.0000
38.7600 3490.0000 1.0000
38.8000 2839.0000 1.0000
38.8400 2209.0000 1.0000
38.8800 1864.0000 1.0000
38.9200 1546.0000 1.0000
38.9600 1415.0000 1.0000
39.0000 1240.0000 1.0000
39.0400 1270.0000 1.0000
39.0800 1173.0000 1.0000
39.1200 1143.0000 1.0000
39.1600 1076.0000 1.0000
39.2000 1047.0000 1.0000
39.2400 992.0000 1.0000
39.2800 1033.0000 1.0000
39.3200 979.0000 1.0000
39.3600 989.0000 1.0000
39.4000 951.0000 1.0000
39.4400 1004.0000 1.0000
39.4800 947.0000 1.0000
39.5200 1017.0000 1.0000
39.5600 996.0000 1.0000
39.6000 1047.0000 1.0000
39.6400 1035.0000 1.0000
39.6800 943.0000 1.0000
39.7200 1017.0000 1.0000
39.7600 992.0000 1.0000
39.8000 952.0000 1.0000
39.8400 952.0000 1.0000
39.8800 958.0000 1.0000
39.9200 921.0000 1.0000
39.9600 958.0000 1.0000
40.0000 901.0000 1.0000
40.0400 928.0000 1.0000
40.0800 932.0000 1.0000
40.1200 924.0000 1.0000
40.1600 937.0000 1.0000
40.2000 890.0000 1.0000
40.2400 921.0000 1.0000
40.2800 912.0000 1.0000
40.3200 888.0000 1.0000
40.3600 873.0000 1.0000
40.4000 886.0000 1.0000
40.4400 902.0000 1.0000
40.4800 931.0000 1.0000
40.5200 942.0000 1.0000
40.5600 842.0000 1.0000
40.6000 903.0000 1.0000
40.6400 923.0000 1.0000
40.6800 952.0000 1.0000
40.7200 929.0000 1.0000
40.7600 899.0000 1.0000
40.8000 880.0000 1.0000
40.8400 907.0000 1.0000
40.8800 836.0000 1.0000
40.9200 911.0000 1.0000
40.9600 900.0000 1.0000
41.0000 941.0000 1.0000
41.0400 871.0000 1.0000
41.0800 882.0000 1.0000
41.1200 887.0000 1.0000
41.1600 882.0000 1.0000
41.2000 889.0000 1.0000
41.2400 913.0000 1.0000
41.2800 865.0000 1.0000
41.3200 855.0000 1.0000
41.3600 904.0000 1.0000
41.4000 903.0000 1.0000
41.4400 864.0000 1.0000
41.4800 932.0000 1.0000
41.5200 891.0000 1.0000
41.5600 851.0000 1.0000
41.6000 900.0000 1.0000
41.6400 857.0000 1.0000
41.6800 893.0000 1.0000
41.7200 880.0000 1.0000
41.7600 845.0000 1.0000
41.8000 864.0000 1.0000
41.8400 831.0000 1.0000
41.8800 872.0000 1.0000
41.9200 880.0000 1.0000
41.9600 873.0000 1.0000
42.0000 869.0000 1.0000
42.0400 890.0000 1.0000
42.0800 875.0000 1.0000
42.1200 900.0000 1.0000
42.1600 874.0000 1.0000
42.2000 882.0000 1.0000
42.2400 871.0000 1.0000
42.2800 875.0000 1.0000
42.3200 864.0000 1.0000
42.3600 891.0000 1.0000
42.4000 838.0000 1.0000
42.4400 901.0000 1.0000
42.4800 850.0000 1.0000
42.5200 809.0000 1.0000
42.5600 825.0000 1.0000
42.6000 812.0000 1.0000
42.6400 859.0000 1.0000
42.6800 915.0000 1.0000
42.7200 906.0000 1.0000
42.7600 880.0000 1.0000
42.8000 820.0000 1.0000
42.8400 840.0000 1.0000
42.8800 852.0000 1.0000
42.9200 889.0000 1.0000
42.9600 837.0000 1.0000
43.0000 900.0000 1.0000
43.0400 852.0000 1.0000
43.0800 885.0000 1.0000
43.1200 892.0000 1.0000
43.1600 943.0000 1.0000
43.2000 921.0000 1.0000
43.2400 944.0000 1.0000
43.2800 934.0000 1.0000
43.3200 903.0000 1.0000
43.3600 960.0000 1.0000
43.4000 915.0000 1.0000
43.4400 920.0000 1.0000
43.4800 821.0000 1.0000
43.5200 824.0000 1.0000
43.5600 822.0000 1.0000
43.6000 804.0000 1.0000
43.6400 803.0000 1.0000
43.6800 845.0000 1.0000
43.7200 873.0000 1.0000
43.7600 817.0000 1.0000
43.8000 874.0000 1.0000
43.8400 864.0000 1.0000
43.8800 826.0000 1.0000
43.9200 869.0000 1.0000
43.9600 896.0000 1.0000
44.0000 853.0000 1.0000
44.0400 774.0000 1.0000
44.0800 852.0000 1.0000
44.1200 811.0000 1.0000
44.1600 840.0000 1.0000
44.2000 839.0000 1.0000
44.2400 812.0000 1.0000
44.2800 877.0000 1.0000
44.3200 859.0000 1.0000
44.3600 836.0000 1.0000
44.4000 858.0000 1.0000
44.4400 825.0000 1.0000
44.4800 837.0000 1.0000
44.5200 831.0000 1.0000
44.5600 826.0000 1.0000
44.6000 819.0000 1.0000
44.6400 817.0000 1.0000
44.6800 812.0000 1.0000
44.7200 810.0000 1.0000
44.7600 798.0000 1.0000
44.8000 834.0000 1.0000
44.8400 819.0000 1.0000
44.8800 826.0000 1.0000
44.9200 838.0000 1.0000
44.9600 829.0000 1.0000
45.0000 802.0000 1.0000
45.0400 843.0000 1.0000
45.0800 825.0000 1.0000
45.1200 794.0000 1.0000
45.1600 855.0000 1.0000
45.2000 818.0000 1.0000
45.2400 793.0000 1.0000
45.2800 821.0000 1.0000
45.3200 805.0000 1.0000
45.3600 785.0000 1.0000
45.4000 793.0000 1.0000
45.4400 827.0000 1.0000
45.4800 777.0000 1.0000
45.5200 837.0000 1.0000
45.5600 820.0000 1.0000
45.6000 783.0000 1.0000
45.6400 803.0000 1.0000
45.6800 815.0000 1.0000
45.7200 830.0000 1.0000
45.7600 812.0000 1.0000
45.8000 790.0000 1.0000
45.8400 817.0000 1.0000
45.8800 790.0000 1.0000
45.9200 805.0000 1.0000
45.9600 767.0000 1.0000
46.0000 762.0000 1.0000
46.0400 789.0000 1.0000
46.0800 792.0000 1.0000
46.1200 804.0000 1.0000
46.1600 797.0000 1.0000
46.2000 780.0000 1.0000
46.2400 793.0000 1.0000
46.2800 788.0000 1.0000
46.3200 778.0000 1.0000
46.3600 770.0000 1.0000
46.4000 785.0000 1.0000
46.4400 818.0000 1.0000
46.4800 770.0000 1.0000
46.5200 784.0000 1.0000
46.5600 794.0000 1.0000
46.6000 794.0000 1.0000
46.6400 787.0000 1.0000
46.6800 764.0000 1.0000
46.7200 784.0000 1.0000
46.7600 736.0000 1.0000
46.8000 800.0000 1.0000
46.8400 795.0000 1.0000
46.8800 793.0000 1.0000
46.9200 794.0000 1.0000
46.9600 756.0000 1.0000
47.0000 748.0000 1.0000
47.0400 787.0000 1.0000
47.0800 835.0000 1.0000
47.1200 833.0000 1.0000
47.1600 789.0000 1.0000
47.2000 782.0000 1.0000
47.2400 746.0000 1.0000
47.2800 766.0000 1.0000
47.3200 779.0000 1.0000
47.3600 776.0000 1.0000
47.4000 754.0000 1.0000
47.4400 770.0000 1.0000
47.4800 728.0000 1.0000
47.5200 769.0000 1.0000
47.5600 774.0000 1.0000
47.6000 760.0000 1.0000
47.6400 768.0000 1.0000
47.6800 732.0000 1.0000
47.7200 725.0000 1.0000
47.7600 785.0000 1.0000
47.8000 728.0000 1.0000
47.8400 764.0000 1.0000
47.8800 754.0000 1.0000
47.9200 729.0000 1.0000
47.9600 777.0000 1.0000
48.0000 772.0000 1.0000
48.0400 757.0000 1.0000
48.0800 722.0000 1.0000
48.1200 815.0000 1.0000
48.1600 786.0000 1.0000
48.2000 723.0000 1.0000
48.2400 763.0000 1.0000
48.2800 744.0000 1.0000
48.3200 762.0000 1.0000
48.3600 743.0000 1.0000
48.4000 727.0000 1.0000
48.4400 762.0000 1.0000
48.4800 778.0000 1.0000
48.5200 744.0000 1.0000
48.5600 773.0000 1.0000
48.6000 721.0000 1.0000
48.6400 725.0000 1.0000
48.6800 763.0000 1.0000
48.7200 767.0000 1.0000
48.7600 746.0000 1.0000
48.8000 709.0000 1.0000
48.8400 753.0000 1.0000
48.8800 705.0000 1.0000
48.9200 694.0000 1.0000
48.9600 703.0000 1.0000
49.0000 724.0000 1.0000
49.0400 741.0000 1.0000
49.0800 730.0000 1.0000
49.1200 716.0000 1.0000
49.1600 749.0000 1.0000
49.2000 728.0000 1.0000
49.2400 750.0000 1.0000
49.2800 762.0000 1.0000
49.3200 736.0000 1.0000
49.3600 719.0000 1.0000
49.4000 757.0000 1.0000
49.4400 798.0000 1.0000
49.4800 771.0000 1.0000
49.5200 744.0000 1.0000
49.5600 739.0000 1.0000
49.6000 739.0000 1.0000
49.6400 720.0000 1.0000
49.6800 744.0000 1.0000
49.7200 715.0000 1.0000
49.7600 716.0000 1.0000
49.8000 755.0000 1.0000
49.8400 767.0000 1.0000
49.8800 727.0000 1.0000
49.9200 724.0000 1.0000
49.9600 727.0000 1.0000
50.0000 697.0000 1.0000
50.0400 714.0000 1.0000
50.0800 722.0000 1.0000
50.1200 736.0000 1.0000
50.1600 757.0000 1.0000
50.2000 749.0000 1.0000
50.2400 760.0000 1.0000
50.2800 756.0000 1.0000
50.3200 740.0000 1.0000
50.3600 764.0000 1.0000
50.4000 738.0000 1.0000
50.4400 764.0000 1.0000
50.4800 749.0000 1.0000
50.5200 714.0000 1.0000
50.5600 767.0000 1.0000
50.6000 723.0000 1.0000
50.6400 753.0000 1.0000
50.6800 767.0000 1.0000
50.7200 769.0000 1.0000
50.7600 694.0000 1.0000
50.8000 730.0000 1.0000
50.8400 707.0000 1.0000
50.8800 721.0000 1.0000
50.9200 765.0000 1.0000
50.9600 735.0000 1.0000
51.0000 769.0000 1.0000
51.0400 773.0000 1.0000
51.0800 719.0000 1.0000
51.1200 687.0000 1.0000
51.1600 727.0000 1.0000
51.2000 744.0000 1.0000
51.2400 753.0000 1.0000
51.2800 755.0000 1.0000
51.3200 748.0000 1.0000
51.3600 733.0000 1.0000
51.4000 745.0000 1.0000
51.4400 783.0000 1.0000
51.4800 781.0000 1.0000
51.5200 740.0000 1.0000
51.5600 782.0000 1.0000
51.6000 788.0000 1.0000
51.6400 756.0000 1.0000
51.6800 774.0000 1.0000
51.7200 762.0000 1.0000
51.7600 815.0000 1.0000
51.8000 788.0000 1.0000
51.8400 814.0000 1.0000
51.8800 863.0000 1.0000
51.9200 885.0000 1.0000
51.9600 937.0000 1.0000
52.0000 969.0000 1.0000
52.0400 1103.0000 1.0000
52.0800 1265.0000 1.0000
52.1200 1494.0000 1.0000
52.1600 1860.0000 1.0000
52.2000 2345.0000 1.0000
52.2400 3292.0000 1.0000
52.2800 4393.0000 1.0000
52.3200 4700.0000 1.0000
52.3600 4323.0000 1.0000
52.4000 3874.0000 1.0000
52.4400 3619.0000 1.0000
52.4800 2999.0000 1.0000
52.5200 2241.0000 1.0000
52.5600 1743.0000 1.0000
52.6000 1416.0000 1.0000
52.6400 1242.0000 1.0000
52.6800 1111.0000 1.0000
52.7200 1045.0000 1.0000
52.7600 952.0000 1.0000
52.8000 883.0000 1.0000
52.8400 863.0000 1.0000
52.8800 786.0000 1.0000
52.9200 836.0000 1.0000
52.9600 781.0000 1.0000
53.0000 800.0000 1.0000
53.0400 766.0000 1.0000
53.0800 769.0000 1.0000
53.1200 766.0000 1.0000
53.1600 767.0000 1.0000
53.2000 782.0000 1.0000
53.2400 768.0000 1.0000
53.2800 749.0000 1.0000
53.3200 801.0000 1.0000
53.3600 765.0000 1.0000
53.4000 753.0000 1.0000
53.4400 682.0000 1.0000
53.4800 707.0000 1.0000
53.5200 749.0000 1.0000
53.5600 748.0000 1.0000
53.6000 729.0000 1.0000
53.6400 706.0000 1.0000
53.6800 708.0000 1.0000
53.7200 689.0000 1.0000
53.7600 708.0000 1.0000
53.8000 736.0000 1.0000
53.8400 709.0000 1.0000
53.8800 723.0000 1.0000
53.9200 708.0000 1.0000
53.9600 692.0000 1.0000
54.0000 747.0000 1.0000
54.0400 684.0000 1.0000
54.0800 714.0000 1.0000
54.1200 706.0000 1.0000
54.1600 724.0000 1.0000
54.2000 675.0000 1.0000
54.2400 744.0000 1.0000
54.2800 714.0000 1.0000
54.3200 676.0000 1.0000
54.3600 719.0000 1.0000
54.4000 723.0000 1.0000
54.4400 688.0000 1.0000
54.4800 710.0000 1.0000
54.5200 716.0000 1.0000
54.5600 737.0000 1.0000
54.6000 684.0000 1.0000
54.6400 695.0000 1.0000
54.6800 721.0000 1.0000
54.7200 746.0000 1.0000
54.7600 716.0000 1.0000
54.8000 748.0000 1.0000
54.8400 726.0000 1.0000
54.8800 762.0000 1.0000
54.9200 784.0000 1.0000
54.9600 772.0000 1.0000
55.0000 742.0000 1.0000
55.0400 804.0000 1.0000
55.0800 767.0000 1.0000
55.1200 851.0000 1.0000
55.1600 887.0000 1.0000
55.2000 950.0000 1.0000
55.2400 971.0000 1.0000
55.2800 1028.0000 1.0000
55.3200 1113.0000 1.0000
55.3600 1076.0000 1.0000
55.4000 1041.0000 1.0000
55.4400 1021.0000 1.0000
55.4800 941.0000 1.0000
55.5200 955.0000 1.0000
55.5600 895.0000 1.0000
55.6000 810.0000 1.0000
55.6400 767.0000 1.0000
55.6800 756.0000 1.0000
55.7200 754.0000 1.0000
55.7600 758.0000 1.0000
55.8000 753.0000 1.0000
55.8400 750.0000 1.0000
55.8800 719.0000 1.0000
55.9200 699.0000 1.0000
55.9600 678.0000 1.0000
56.0000 677.0000 1.0000
56.0400 727.0000 1.0000
56.0800 686.0000 1.0000
56.1200 715.0000 1.0000
56.1600 706.0000 1.0000
56.2000 695.0000 1.0000
56.2400 696.0000 1.0000
56.2800 681.0000 1.0000
56.3200 675.0000 1.0000
56.3600 677.0000 1.0000
56.4000 709.0000 1.0000
56.4400 674.0000 1.0000
56.4800 700.0000 1.0000
56.5200 686.0000 1.0000
56.5600 662.0000 1.0000
56.6000 651.0000 1.0000
56.6400 685.0000 1.0000
56.6800 673.0000 1.0000
56.7200 629.0000 1.0000
56.7600 692.0000 1.0000
56.8000 713.0000 1.0000
56.8400 692.0000 1.0000
56.8800 665.0000 1.0000
56.9200 692.0000 1.0000
56.9600 705.0000 1.0000
57.0000 709.0000 1.0000
57.0400 684.0000 1.0000
57.0800 703.0000 1.0000
57.1200 697.0000 1.0000
57.1600 696.0000 1.0000
57.2000 671.0000 1.0000
57.2400 667.0000 1.0000
57.2800 684.0000 1.0000
57.3200 661.0000 1.0000
57.3600 678.0000 1.0000
57.4000 652.0000 1.0000
57.4400 642.0000 1.0000
57.4800 657.0000 1.0000
57.5200 688.0000 1.0000
57.5600 689.0000 1.0000
57.6000 710.0000 1.0000
57.6400 660.0000 1.0000
57.6800 699.0000 1.0000
57.7200 644.0000 1.0000
57.7600 642.0000 1.0000
57.8000 683.0000 1.0000
57.8400 690.0000 1.0000
57.8800 695.0000 1.0000
57.9200 683.0000 1.0000
57.9600 687.0000 1.0000
58.0000 667.0000 1.0000
58.0400 645.0000 1.0000
58.0800 668.0000 1.0000
58.1200 714.0000 1.0000
58.1600 667.0000 1.0000
58.2000 764.0000 1.0000
58.2400 703.0000 1.0000
58.2800 662.0000 1.0000
58.3200 698.0000 1.0000
58.3600 665.0000 1.0000
58.4000 707.0000 1.0000
58.4400 667.0000 1.0000
58.4800 694.0000 1.0000
58.5200 682.0000 1.0000
58.5600 680.0000 1.0000
58.6000 620.0000 1.0000
58.6400 640.0000 1.0000
58.6800 670.0000 1.0000
58.7200 684.0000 1.0000
58.7600 679.0000 1.0000
58.8000 671.0000 1.0000
58.8400 669.0000 1.0000
58.8800 676.0000 1.0000
58.9200 676.0000 1.0000
58.9600 673.0000 1.0000
59.0000 700.0000 1.0000
59.0400 619.0000 1.0000
59.0800 661.0000 1.0000
59.1200 692.0000 1.0000
59.1600 675.0000 1.0000
59.2000 650.0000 1.0000
59.2400 675.0000 1.0000
59.2800 700.0000 1.0000
59.3200 668.0000 1.0000
59.3600 663.0000 1.0000
59.4000 653.0000 1.0000
59.4400 716.0000 1.0000
59.4800 672.0000 1.0000
59.5200 656.0000 1.0000
59.5600 702.0000 1.0000
59.6000 697.0000 1.0000
59.6400 672.0000 1.0000
59.6800 685.0000 1.0000
59.7200 671.0000 1.0000
59.7600 664.0000 1.0000
59.8000 686.0000 1.0000
59.8400 649.0000 1.0000
59.8800 659.0000 1.0000
59.9200 656.0000 1.0000
59.9600 664.0000 1.0000
60.0000 638.0000 1.0000
60.0400 669.0000 1.0000
60.0800 640.0000 1.0000
60.1200 640.0000 1.0000
60.1600 650.0000 1.0000
60.2000 685.0000 1.0000
60.2400 677.0000 1.0000
60.2800 699.0000 1.0000
60.3200 635.0000 1.0000
60.3600 657.0000 1.0000
60.4000 705.0000 1.0000
60.4400 661.0000 1.0000
60.4800 690.0000 1.0000
60.5200 659.0000 1.0000
60.5600 692.0000 1.0000
60.6000 634.0000 1.0000
60.6400 665.0000 1.0000
60.6800 679.0000 1.0000
60.7200 690.0000 1.0000
60.7600 678.0000 1.0000
60.8000 657.0000 1.0000
60.8400 666.0000 1.0000
60.8800 656.0000 1.0000
60.9200 672.0000 1.0000
60.9600 660.0000 1.0000
61.0000 705.0000 1.0000
61.0400 637.0000 1.0000
61.0800 641.0000 1.0000
61.1200 673.0000 1.0000
61.1600 660.0000 1.0000
61.2000 689.0000 1.0000
61.2400 657.0000 1.0000
61.2800 657.0000 1.0000
61.3200 677.0000 1.0000
61.3600 677.0000 1.0000
61.4000 702.0000 1.0000
61.4400 678.0000 1.0000
61.4800 710.0000 1.0000
61.5200 719.0000 1.0000
61.5600 665.0000 1.0000
61.6000 725.0000 1.0000
61.6400 709.0000 1.0000
61.6800 685.0000 1.0000
61.7200 715.0000 1.0000
61.7600 728.0000 1.0000
61.8000 733.0000 1.0000
61.8400 757.0000 1.0000
61.8800 771.0000 1.0000
61.9200 796.0000 1.0000
61.9600 795.0000 1.0000
62.0000 839.0000 1.0000
62.0400 925.0000 1.0000
62.0800 910.0000 1.0000
62.1200 1045.0000 1.0000
62.1600 1084.0000 1.0000
62.2000 1209.0000 1.0000
62.2400 1347.0000 1.0000
62.2800 1531.0000 1.0000
62.3200 1566.0000 1.0000
62.3600 1630.0000 1.0000
62.4000 1578.0000 1.0000
62.4400 1542.0000 1.0000
62.4800 1502.0000 1.0000
62.5200 1375.0000 1.0000
62.5600 1221.0000 1.0000
62.6000 1221.0000 1.0000
62.6400 1076.0000 1.0000
62.6800 968.0000 1.0000
62.7200 925.0000 1.0000
62.7600 841.0000 1.0000
62.8000 830.0000 1.0000
62.8400 805.0000 1.0000
62.8800 736.0000 1.0000
62.9200 763.0000 1.0000
62.9600 760.0000 1.0000
63.0000 727.0000 1.0000
63.0400 775.0000 1.0000
63.0800 720.0000 1.0000
63.1200 726.0000 1.0000
63.1600 706.0000 1.0000
63.2000 706.0000 1.0000
63.2400 701.0000 1.0000
63.2800 669.0000 1.0000
63.3200 729.0000 1.0000
63.3600 666.0000 1.0000
63.4000 708.0000 1.0000
63.4400 669.0000 1.0000
63.4800 683.0000 1.0000
63.5200 676.0000 1.0000
63.5600 705.0000 1.0000
63.6000 659.0000 1.0000
63.6400 672.0000 1.0000
63.6800 697.0000 1.0000
63.7200 662.0000 1.0000
63.7600 717.0000 1.0000
63.8000 696.0000 1.0000
63.8400 665.0000 1.0000
63.8800 634.0000 1.0000
63.9200 657.0000 1.0000
63.9600 672.0000 1.0000
64.0000 689.0000 1.0000
64.0400 668.0000 1.0000
64.0800 675.0000 1.0000
64.1200 692.0000 1.0000
64.1600 731.0000 1.0000
64.2000 694.0000 1.0000
64.2400 683.0000 1.0000
64.2800 668.0000 1.0000
64.3200 669.0000 1.0000
64.3600 689.0000 1.0000
64.4000 756.0000 1.0000
64.4400 746.0000 1.0000
64.4800 740.0000 1.0000
64.5200 744.0000 1.0000
64.5600 802.0000 1.0000
64.6000 811.0000 1.0000
64.6400 849.0000 1.0000
64.6800 892.0000 1.0000
64.7200 907.0000 1.0000
64.7600 898.0000 1.0000
64.8000 867.0000 1.0000
64.8400 905.0000 1.0000
64.8800 883.0000 1.0000
64.9200 901.0000 1.0000
64.9600 842.0000 1.0000
65.0000 740.0000 1.0000
65.0400 795.0000 1.0000
65.0800 752.0000 1.0000
65.1200 767.0000 1.0000
65.1600 759.0000 1.0000
65.2000 756.0000 1.0000
65.2400 707.0000 1.0000
65.2800 714.0000 1.0000
65.3200 708.0000 1.0000
65.3600 690.0000 1.0000
65.4000 706.0000 1.0000
65.4400 717.0000 1.0000
65.4800 687.0000 1.0000
65.5200 690.0000 1.0000
65.5600 708.0000 1.0000
65.6000 732.0000 1.0000
65.6400 728.0000 1.0000
65.6800 743.0000 1.0000
65.7200 705.0000 1.0000
65.7600 718.0000 1.0000
65.8000 719.0000 1.0000
65.8400 747.0000 1.0000
65.8800 787.0000 1.0000
65.9200 843.0000 1.0000
65.9600 876.0000 1.0000
66.0000 919.0000 1.0000
66.0400 988.0000 1.0000
66.0800 1055.0000 1.0000
66.1200 1304.0000 1.0000
66.1600 1497.0000 1.0000
66.2000 1924.0000 1.0000
66.2400 2315.0000 1.0000
66.2800 2550.0000 1.0000
66.3200 2487.0000 1.0000
66.3600 2357.0000 1.0000
66.4000 2186.0000 1.0000
66.4400 2139.0000 1.0000
66.4800 2016.0000 1.0000
66.5200 1764.0000 1.0000
66.5600 1543.0000 1.0000
66.6000 1327.0000 1.0000
66.6400 1135.0000 1.0000
66.6800 938.0000 1.0000
66.7200 949.0000 1.0000
66.7600 896.0000 1.0000
66.8000 866.0000 1.0000
66.8400 761.0000 1.0000
66.8800 719.0000 1.0000
66.9200 699.0000 1.0000
66.9600 678.0000 1.0000
67.0000 693.0000 1.0000
67.0400 635.0000 1.0000
67.0800 685.0000 1.0000
67.1200 636.0000 1.0000
67.1600 701.0000 1.0000
67.2000 652.0000 1.0000
67.2400 669.0000 1.0000
67.2800 671.0000 1.0000
67.3200 644.0000 1.0000
67.3600 610.0000 1.0000
67.4000 633.0000 1.0000
67.4400 610.0000 1.0000
67.4800 662.0000 1.0000
67.5200 595.0000 1.0000
67.5600 651.0000 1.0000
67.6000 650.0000 1.0000
67.6400 619.0000 1.0000
67.6800 608.0000 1.0000
67.7200 654.0000 1.0000
67.7600 604.0000 1.0000
67.8000 587.0000 1.0000
67.8400 641.0000 1.0000
67.8800 567.0000 1.0000
67.9200 617.0000 1.0000
67.9600 624.0000 1.0000
68.0000 595.0000 1.0000
68.0400 597.0000 1.0000
68.0800 583.0000 1.0000
68.1200 603.0000 1.0000
68.1600 618.0000 1.0000
68.2000 592.0000 1.0000
68.2400 551.0000 1.0000
68.2800 588.0000 1.0000
68.3200 602.0000 1.0000
68.3600 581.0000 1.0000
68.4000 638.0000 1.0000
68.4400 585.0000 1.0000
68.4800 596.0000 1.0000
68.5200 607.0000 1.0000
68.5600 613.0000 1.0000
68.6000 580.0000 1.0000
68.6400 621.0000 1.0000
68.6800 579.0000 1.0000
68.7200 624.0000 1.0000
68.7600 599.0000 1.0000
68.8000 613.0000 1.0000
68.8400 593.0000 1.0000
68.8800 610.0000 1.0000
68.9200 578.0000 1.0000
68.9600 611.0000 1.0000
69.0000 596.0000 1.0000
69.0400 601.0000 1.0000
69.0800 577.0000 1.0000
69.1200 581.0000 1.0000
69.1600 598.0000 1.0000
69.2000 613.0000 1.0000
69.2400 587.0000 1.0000
69.2800 576.0000 1.0000
69.3200 587.0000 1.0000
69.3600 589.0000 1.0000
69.4000 581.0000 1.0000
69.4400 571.0000 1.0000
69.4800 581.0000 1.0000
69.5200 564.0000 1.0000
69.5600 581.0000 1.0000
69.6000 579.0000 1.0000
69.6400 566.0000 1.0000
69.6800 613.0000 1.0000
69.7200 583.0000 1.0000
69.7600 555.0000 1.0000
69.8000 562.0000 1.0000
69.8400 583.0000 1.0000
69.8800 628.0000 1.0000
69.9200 578.0000 1.0000
69.9600 591.0000 1.0000
70.0000 583.0000 1.0000
*RAS_INT_END
*RAS_TEMPERATURE_START
*RAS_TEMPERATURE_END
*RAS_DATA_END