File: Section2_75_samples/XRD/No_058_NSS3_3.ras
*RAS_DATA_START
*RAS_HEADER_START
*DISP_FMT_X "%.2f"
*DISP_FMT_Y "%.0f"
*DISP_FULLSCALE "15006.0000000000"
*DISP_LINE_COLOR "255.0000000000"
*DISP_LINE_STYLE "0.0000000000"
*DISP_LINE_WIDTH "0.2500000000"
*DISP_NOTE "測定データ-2"
*DISP_OFFSET_Y "0.0000000000"
*DISP_PEAKSEARCH_UNIT_Y "cps"
*DISP_RANGE_BOTTOM "0.0000000000"
*DISP_RANGE_LEFT "20.0000000000"
*DISP_RANGE_LOGCUTOFF "0.0100000000"
*DISP_RANGE_RIGHT "70.0000000000"
*DISP_RANGE_TOP "15006.0000000000"
*DISP_SCALE_MODE_Y "0.0000000000"
*DISP_TAB_NAME "2θ/θ"
*DISP_TITLE_Y "強度"
*DISP_UNIT_Y "cps"
*DISP_WINDOW_NAME "MSG_MACROENGINE"
*FILE_COMMENT " "
*FILE_MD5 ""
*FILE_MEMO " "
*FILE_OPERATOR "Administrator"
*FILE_SAMPLE " "
*FILE_TYPE "RAS_RAW"
*FILE_USERGROUP "システムマネージャ"
*FILE_VERSION "1.0000000000"
*HW_ATTACHMENT_ID "ATT0025"
*HW_ATTACHMENT_NAME "標準|Standard"
*HW_COUNTER_ID-0 "CUT0025"
*HW_COUNTER_ID-1 "CUT0020"
*HW_COUNTER_ID-2 "CUT0020"
*HW_COUNTER_ID-3 "CSL0021"
*HW_COUNTER_ID-4 "CMC0021"
*HW_COUNTER_NAME-0 "D/teX Ultra|D/teX Ultra"
*HW_COUNTER_NAME-1 "None|None"
*HW_COUNTER_NAME-2 "None|None"
*HW_COUNTER_NAME-3 "BBM|BBM"
*HW_COUNTER_NAME-4 "検出器モノクロメータ|Detector monochromator"
*HW_COUNTER_SELECT_NAME "D/teX Ultra|D/teX Ultra"
*HW_GONIOMETER_ID "GON0023"
*HW_GONIOMETER_NAME "SmartLab|SmartLab"
*HW_GONIOMETER_RADIUS-0 "90.0"
*HW_GONIOMETER_RADIUS-1 "114.0"
*HW_GONIOMETER_RADIUS-2 "190.0"
*HW_GONIOMETER_RADIUS-3 "300.0"
*HW_GONIOMETER_RADIUS-4 "187.0"
*HW_GONIOMETER_RADIUS-5 "300.0"
*HW_GONIOMETER_RADIUS-6 "113.0"
*HW_GONIOMETER_RADIUS-7 "331.0"
*HW_I_OPT_ID-0 "CBO0021"
*HW_I_OPT_ID-1 "ICR0023"
*HW_I_OPT_ID-2 "ISL0021"
*HW_I_OPT_ID-3 "ISO0021"
*HW_I_OPT_ID-4 "IAD0021"
*HW_I_OPT_ID-5 "IPR0001"
*HW_I_OPT_NAME-0 "CBOユニット|CBO unit"
*HW_I_OPT_NAME-1 "標準入射光学ユニット|Standard incident optical unit"
*HW_I_OPT_NAME-2 "標準入射スリットボックス|Standard incident slit box"
*HW_I_OPT_NAME-3 "入射平行スリット|Incident parallel slit"
*HW_I_OPT_NAME-4 "長手制限スリット|Length limiting slit"
*HW_I_OPT_NAME-5 "None|None"
*HW_R_ATTENUATER_AUTOMODE "0"
*HW_R_OPT_ID-0 "RSS0021"
*HW_R_OPT_ID-1 "RCR0023"
*HW_R_OPT_ID-2 "RSO0021"
*HW_R_OPT_ID-3 "RRS0021"
*HW_R_OPT_ID-4 "ATN0021"
*HW_R_OPT_ID-5 "RFL0021"
*HW_R_OPT_ID-6 "RAD0021"
*HW_R_OPT_NAME-0 "標準受光スリットボックス1|Standard receiving slit box # 1"
*HW_R_OPT_NAME-1 "標準受光光学ユニット1|Standard receiving unit # 1"
*HW_R_OPT_NAME-2 "標準受光光学ユニット2|Standard receiving optical unit # 2"
*HW_R_OPT_NAME-3 "標準受光スリットボックス2|Standard receiving slit box # 2"
*HW_R_OPT_NAME-4 "標準アッテネータ|Standard Attenuator"
*HW_R_OPT_NAME-5 "Cu Kβ|Cu K-beta"
*HW_R_OPT_NAME-6 "調整用受光スリット|Alignment receiving slit"
*HW_SAMPLE_HOLDER_ID "SMP0023"
*HW_SAMPLE_HOLDER_NAME "標準Zステージ|Standard Z stage"
*HW_XG_CURRENT_MAX "50"
*HW_XG_CURRENT_MIN "2"
*HW_XG_CURRENT_RESOLUTION "1"
*HW_XG_CURRENT_UNIT "mA"
*HW_XG_FOCUS "1mm x 10mm"
*HW_XG_FOCUS_TYPE "Normal"
*HW_XG_ID ""
*HW_XG_NAME "3kW 封入管(ID:1200)|3kW Sealed tube(ID:1200)"
*HW_XG_TARGET_ATOMIC_NUMBER "29.0000000000"
*HW_XG_TARGET_NAME "Cu"
*HW_XG_TYPE "Hermetic"
*HW_XG_VOLTAGE_MAX "60"
*HW_XG_VOLTAGE_MIN "20"
*HW_XG_VOLTAGE_RESOLUTION "1"
*HW_XG_VOLTAGE_UNIT "kV"
*HW_XG_WATT_MAX "1.500"
*HW_XG_WATT_UNIT "kW"
*HW_XG_WAVE_LENGTH_ALPHA1 "1.540593"
*HW_XG_WAVE_LENGTH_ALPHA2 "1.544414"
*HW_XG_WAVE_LENGTH_BETA "1.392250"
*MEAS_COND_AXIS_NAME-0 "2θ/θ"
*MEAS_COND_AXIS_NAME-1 "2θ"
*MEAS_COND_AXIS_NAME-2 "ω"
*MEAS_COND_AXIS_NAME-3 "Z"
*MEAS_COND_AXIS_NAME-4 "2θ/ω"
*MEAS_COND_AXIS_NAME-5 "θs"
*MEAS_COND_AXIS_NAME-6 "θd"
*MEAS_COND_AXIS_NAME-7 "Ts"
*MEAS_COND_AXIS_NAME-8 "CBO選択スリット"
*MEAS_COND_AXIS_NAME-9 "M"
*MEAS_COND_AXIS_NAME-10 "入射平行スリット"
*MEAS_COND_AXIS_NAME-11 "入射スリット"
*MEAS_COND_AXIS_NAME-12 ""
*MEAS_COND_AXIS_NAME-13 "Zs"
*MEAS_COND_AXIS_NAME-14 "入射光学素子"
*MEAS_COND_AXIS_NAME-15 "長手制限スリット"
*MEAS_COND_AXIS_NAME-16 "センタースリット"
*MEAS_COND_AXIS_NAME-17 "フィルター"
*MEAS_COND_AXIS_NAME-18 "受光スリット1"
*MEAS_COND_AXIS_NAME-19 "受光スリット2"
*MEAS_COND_AXIS_NAME-20 "受光光学素子"
*MEAS_COND_AXIS_NAME-21 "受光平行スリット"
*MEAS_COND_AXIS_NAME-22 "調整用受光スリット"
*MEAS_COND_AXIS_NAME-23 ""
*MEAS_COND_AXIS_NAME-24 ""
*MEAS_COND_AXIS_NAME-25 "Zd"
*MEAS_COND_AXIS_NAME-26 "アッテネータ"
*MEAS_COND_AXIS_NAME-27 "検出器モノクロメータ"
*MEAS_COND_AXIS_NAME-28 "モノクロメータスリット"
*MEAS_COND_AXIS_NAME-29 "プライマリビーム"
*MEAS_COND_AXIS_NAME-30 "PHA"
*MEAS_COND_AXIS_NAME_INTERNAL-0 "TwoThetaTheta"
*MEAS_COND_AXIS_NAME_INTERNAL-1 "TwoTheta"
*MEAS_COND_AXIS_NAME_INTERNAL-2 "Omega"
*MEAS_COND_AXIS_NAME_INTERNAL-3 "Z"
*MEAS_COND_AXIS_NAME_INTERNAL-4 "TwoThetaOmega"
*MEAS_COND_AXIS_NAME_INTERNAL-5 "ThetaS"
*MEAS_COND_AXIS_NAME_INTERNAL-6 "ThetaD"
*MEAS_COND_AXIS_NAME_INTERNAL-7 "Ts"
*MEAS_COND_AXIS_NAME_INTERNAL-8 "CBO"
*MEAS_COND_AXIS_NAME_INTERNAL-9 "CBO-M"
*MEAS_COND_AXIS_NAME_INTERNAL-10 "IncidentSollerSlit"
*MEAS_COND_AXIS_NAME_INTERNAL-11 "IncidentSlitBox"
*MEAS_COND_AXIS_NAME_INTERNAL-12 "IncidentSlitBox-_Axis"
*MEAS_COND_AXIS_NAME_INTERNAL-13 "Zs"
*MEAS_COND_AXIS_NAME_INTERNAL-14 "IncidentMonochromator"
*MEAS_COND_AXIS_NAME_INTERNAL-15 "IncidentAxdSlit"
*MEAS_COND_AXIS_NAME_INTERNAL-16 "CenterSlit"
*MEAS_COND_AXIS_NAME_INTERNAL-17 "Filter"
*MEAS_COND_AXIS_NAME_INTERNAL-18 "ReceivingSlitBox1"
*MEAS_COND_AXIS_NAME_INTERNAL-19 "ReceivingSlitBox2"
*MEAS_COND_AXIS_NAME_INTERNAL-20 "ReceivingOptics"
*MEAS_COND_AXIS_NAME_INTERNAL-21 "ReceivingSollerSlit"
*MEAS_COND_AXIS_NAME_INTERNAL-22 "ReceivingAxdSlit"
*MEAS_COND_AXIS_NAME_INTERNAL-23 "ReceivingSlitBox1-_Axis"
*MEAS_COND_AXIS_NAME_INTERNAL-24 "ReceivingSlitBox2-_Axis"
*MEAS_COND_AXIS_NAME_INTERNAL-25 "ReceivingSlitBox2-Zd"
*MEAS_COND_AXIS_NAME_INTERNAL-26 "Attenuator"
*MEAS_COND_AXIS_NAME_INTERNAL-27 "CounterMonochromator"
*MEAS_COND_AXIS_NAME_INTERNAL-28 "CounterSlit"
*MEAS_COND_AXIS_NAME_INTERNAL-29 "IncidentPrimary"
*MEAS_COND_AXIS_NAME_INTERNAL-30 "PHA"
*MEAS_COND_AXIS_NAME_MAGICNO-0 "83951616.0000000000"
*MEAS_COND_AXIS_NAME_MAGICNO-1 "268632064.0000000000"
*MEAS_COND_AXIS_NAME_MAGICNO-2 "268500992.0000000000"
*MEAS_COND_AXIS_NAME_MAGICNO-3 "285278208.0000000000"
*MEAS_COND_AXIS_NAME_MAGICNO-4 "83951616.0000000000"
*MEAS_COND_AXIS_NAME_MAGICNO-5 "131072.0000000000"
*MEAS_COND_AXIS_NAME_MAGICNO-6 "131072.0000000000"
*MEAS_COND_AXIS_NAME_MAGICNO-7 "318898176.0000000000"
*MEAS_COND_AXIS_NAME_MAGICNO-8 "20971521.0000000000"
*MEAS_COND_AXIS_NAME_MAGICNO-9 "285343744.0000000000"
*MEAS_COND_AXIS_NAME_MAGICNO-10 "20971521.0000000000"
*MEAS_COND_AXIS_NAME_MAGICNO-11 "22020097.0000000000"
*MEAS_COND_AXIS_NAME_MAGICNO-12 "25165824.0000000000"
*MEAS_COND_AXIS_NAME_MAGICNO-13 "318898176.0000000000"
*MEAS_COND_AXIS_NAME_MAGICNO-14 "1.0000000000"
*MEAS_COND_AXIS_NAME_MAGICNO-15 "20971521.0000000000"
*MEAS_COND_AXIS_NAME_MAGICNO-16 "20971521.0000000000"
*MEAS_COND_AXIS_NAME_MAGICNO-17 "20971521.0000000000"
*MEAS_COND_AXIS_NAME_MAGICNO-18 "23068673.0000000000"
*MEAS_COND_AXIS_NAME_MAGICNO-19 "23068673.0000000000"
*MEAS_COND_AXIS_NAME_MAGICNO-20 "20971521.0000000000"
*MEAS_COND_AXIS_NAME_MAGICNO-21 "20971521.0000000000"
*MEAS_COND_AXIS_NAME_MAGICNO-22 "20971521.0000000000"
*MEAS_COND_AXIS_NAME_MAGICNO-23 "25165824.0000000000"
*MEAS_COND_AXIS_NAME_MAGICNO-24 "25165824.0000000000"
*MEAS_COND_AXIS_NAME_MAGICNO-25 "285343744.0000000000"
*MEAS_COND_AXIS_NAME_MAGICNO-26 "17301505.0000000000"
*MEAS_COND_AXIS_NAME_MAGICNO-27 "20971521.0000000000"
*MEAS_COND_AXIS_NAME_MAGICNO-28 "20971521.0000000000"
*MEAS_COND_AXIS_NAME_MAGICNO-29 "20971521.0000000000"
*MEAS_COND_AXIS_NAME_MAGICNO-30 "0.0000000000"
*MEAS_COND_AXIS_OFFSET-0 "-"
*MEAS_COND_AXIS_OFFSET-1 "-0.1081000000"
*MEAS_COND_AXIS_OFFSET-2 "0.3758000000"
*MEAS_COND_AXIS_OFFSET-3 "-"
*MEAS_COND_AXIS_OFFSET-4 "-"
*MEAS_COND_AXIS_OFFSET-5 "0.3758000000"
*MEAS_COND_AXIS_OFFSET-6 "-0.4839000000"
*MEAS_COND_AXIS_OFFSET-7 "-"
*MEAS_COND_AXIS_OFFSET-8 "-"
*MEAS_COND_AXIS_OFFSET-9 "-"
*MEAS_COND_AXIS_OFFSET-10 "-"
*MEAS_COND_AXIS_OFFSET-11 "-"
*MEAS_COND_AXIS_OFFSET-12 "-"
*MEAS_COND_AXIS_OFFSET-13 "-"
*MEAS_COND_AXIS_OFFSET-14 "-"
*MEAS_COND_AXIS_OFFSET-15 "-"
*MEAS_COND_AXIS_OFFSET-16 "-"
*MEAS_COND_AXIS_OFFSET-17 "-"
*MEAS_COND_AXIS_OFFSET-18 "-"
*MEAS_COND_AXIS_OFFSET-19 "-"
*MEAS_COND_AXIS_OFFSET-20 "-"
*MEAS_COND_AXIS_OFFSET-21 "-"
*MEAS_COND_AXIS_OFFSET-22 "-"
*MEAS_COND_AXIS_OFFSET-23 "-"
*MEAS_COND_AXIS_OFFSET-24 "-"
*MEAS_COND_AXIS_OFFSET-25 "-"
*MEAS_COND_AXIS_OFFSET-26 "-"
*MEAS_COND_AXIS_OFFSET-27 "-"
*MEAS_COND_AXIS_OFFSET-28 "-"
*MEAS_COND_AXIS_OFFSET-29 "-"
*MEAS_COND_AXIS_OFFSET-30 "-"
*MEAS_COND_AXIS_POSITION-0 "0.0000000000"
*MEAS_COND_AXIS_POSITION-1 "0.0000000000"
*MEAS_COND_AXIS_POSITION-2 "0.0000000000"
*MEAS_COND_AXIS_POSITION-3 "-0.5500000000"
*MEAS_COND_AXIS_POSITION-4 "0.0000000000"
*MEAS_COND_AXIS_POSITION-5 "0.0000000000"
*MEAS_COND_AXIS_POSITION-6 "0.0000000000"
*MEAS_COND_AXIS_POSITION-7 "-0.4278800000"
*MEAS_COND_AXIS_POSITION-8 "BB"
*MEAS_COND_AXIS_POSITION-9 "0.0000000000"
*MEAS_COND_AXIS_POSITION-10 "Soller_slit_5.0deg"
*MEAS_COND_AXIS_POSITION-11 "2/3deg"
*MEAS_COND_AXIS_POSITION-12 "2.2088000000"
*MEAS_COND_AXIS_POSITION-13 "-0.4140600000"
*MEAS_COND_AXIS_POSITION-14 "0.0000000000"
*MEAS_COND_AXIS_POSITION-15 "10.0mm"
*MEAS_COND_AXIS_POSITION-16 "None"
*MEAS_COND_AXIS_POSITION-17 "Cu_K-beta"
*MEAS_COND_AXIS_POSITION-18 "13.000mm"
*MEAS_COND_AXIS_POSITION-19 "13.000mm"
*MEAS_COND_AXIS_POSITION-20 "No_unit"
*MEAS_COND_AXIS_POSITION-21 "Soller_slit_5.0deg"
*MEAS_COND_AXIS_POSITION-22 "None"
*MEAS_COND_AXIS_POSITION-23 "13.0000000000"
*MEAS_COND_AXIS_POSITION-24 "13.0000000000"
*MEAS_COND_AXIS_POSITION-25 "0.0109400000"
*MEAS_COND_AXIS_POSITION-26 "Open"
*MEAS_COND_AXIS_POSITION-27 "None"
*MEAS_COND_AXIS_POSITION-28 "None"
*MEAS_COND_AXIS_POSITION-29 "None"
*MEAS_COND_AXIS_POSITION-30 "38.0000000000"
*MEAS_COND_AXIS_UNIT-0 "deg"
*MEAS_COND_AXIS_UNIT-1 "deg"
*MEAS_COND_AXIS_UNIT-2 "deg"
*MEAS_COND_AXIS_UNIT-3 "mm"
*MEAS_COND_AXIS_UNIT-4 "deg"
*MEAS_COND_AXIS_UNIT-5 "deg"
*MEAS_COND_AXIS_UNIT-6 "deg"
*MEAS_COND_AXIS_UNIT-7 "mm"
*MEAS_COND_AXIS_UNIT-8 ""
*MEAS_COND_AXIS_UNIT-9 "pulse"
*MEAS_COND_AXIS_UNIT-10 ""
*MEAS_COND_AXIS_UNIT-11 ""
*MEAS_COND_AXIS_UNIT-12 "mm"
*MEAS_COND_AXIS_UNIT-13 "mm"
*MEAS_COND_AXIS_UNIT-14 ""
*MEAS_COND_AXIS_UNIT-15 ""
*MEAS_COND_AXIS_UNIT-16 ""
*MEAS_COND_AXIS_UNIT-17 ""
*MEAS_COND_AXIS_UNIT-18 ""
*MEAS_COND_AXIS_UNIT-19 ""
*MEAS_COND_AXIS_UNIT-20 ""
*MEAS_COND_AXIS_UNIT-21 ""
*MEAS_COND_AXIS_UNIT-22 ""
*MEAS_COND_AXIS_UNIT-23 "mm"
*MEAS_COND_AXIS_UNIT-24 "mm"
*MEAS_COND_AXIS_UNIT-25 "mm"
*MEAS_COND_AXIS_UNIT-26 ""
*MEAS_COND_AXIS_UNIT-27 ""
*MEAS_COND_AXIS_UNIT-28 ""
*MEAS_COND_AXIS_UNIT-29 ""
*MEAS_COND_AXIS_UNIT-30 "div"
*MEAS_COND_COUNTER_CNTLOSS_CORR "0.0000000000"
*MEAS_COND_COUNTER_PHABASE "38.0000000000"
*MEAS_COND_COUNTER_PHAWINDOW "16.0000000000"
*MEAS_COND_COUNTER_PHA_UNIT "div"
*MEAS_COND_COUNTER_TAUDIFF "30.0000000000"
*MEAS_COND_COUNTER_TAUINT "0.0000000000"
*MEAS_COND_IRRADIATION_MODE "OFF"
*MEAS_COND_IRRADIATION_WIDTH ""
*MEAS_COND_OPT_ATTR "集中法"
*MEAS_COND_OPT_NAME "@集中法"
*MEAS_COND_UNSYMMETRIC_MODE "OFF"
*MEAS_COND_XG_CURRENT "30.0000000000"
*MEAS_COND_XG_VOLTAGE "40.0000000000"
*MEAS_COND_XG_WAVE_TYPE "Ka"
*MEAS_DATA_COUNT "5001.0000000000"
*MEAS_SCAN_AXIS_X "2θ/θ"
*MEAS_SCAN_AXIS_X_INTERNAL "TwoThetaTheta"
*MEAS_SCAN_END_TIME "07/14/21 12:29:16"
*MEAS_SCAN_MODE "CONTINUOUS"
*MEAS_SCAN_MONITOR "0"
*MEAS_SCAN_RESOLUTION_X "0.0002"
*MEAS_SCAN_SPEED "1.0"
*MEAS_SCAN_SPEED_UNIT "deg/min"
*MEAS_SCAN_START "20.0000000000"
*MEAS_SCAN_START_TIME "07/14/21 11:36:23"
*MEAS_SCAN_STEP "0.0100000000"
*MEAS_SCAN_STOP "70.0000000000"
*MEAS_SCAN_UNIT_X "deg"
*MEAS_SCAN_UNIT_Y "counts"
*RAS_HEADER_END
*RAS_INT_START
20.0000 1578.0000 1.0000
20.0400 1541.0000 1.0000
20.0800 1568.0000 1.0000
20.1200 1545.0000 1.0000
20.1600 1569.0000 1.0000
20.2000 1515.0000 1.0000
20.2400 1562.0000 1.0000
20.2800 1535.0000 1.0000
20.3200 1590.0000 1.0000
20.3600 1594.0000 1.0000
20.4000 1625.0000 1.0000
20.4400 1506.0000 1.0000
20.4800 1554.0000 1.0000
20.5200 1562.0000 1.0000
20.5600 1575.0000 1.0000
20.6000 1530.0000 1.0000
20.6400 1552.0000 1.0000
20.6800 1552.0000 1.0000
20.7200 1595.0000 1.0000
20.7600 1563.0000 1.0000
20.8000 1599.0000 1.0000
20.8400 1618.0000 1.0000
20.8800 1521.0000 1.0000
20.9200 1539.0000 1.0000
20.9600 1554.0000 1.0000
21.0000 1562.0000 1.0000
21.0400 1547.0000 1.0000
21.0800 1487.0000 1.0000
21.1200 1569.0000 1.0000
21.1600 1529.0000 1.0000
21.2000 1527.0000 1.0000
21.2400 1530.0000 1.0000
21.2800 1542.0000 1.0000
21.3200 1603.0000 1.0000
21.3600 1541.0000 1.0000
21.4000 1582.0000 1.0000
21.4400 1551.0000 1.0000
21.4800 1501.0000 1.0000
21.5200 1567.0000 1.0000
21.5600 1609.0000 1.0000
21.6000 1541.0000 1.0000
21.6400 1539.0000 1.0000
21.6800 1543.0000 1.0000
21.7200 1569.0000 1.0000
21.7600 1532.0000 1.0000
21.8000 1612.0000 1.0000
21.8400 1625.0000 1.0000
21.8800 1577.0000 1.0000
21.9200 1581.0000 1.0000
21.9600 1611.0000 1.0000
22.0000 1536.0000 1.0000
22.0400 1622.0000 1.0000
22.0800 1586.0000 1.0000
22.1200 1573.0000 1.0000
22.1600 1569.0000 1.0000
22.2000 1525.0000 1.0000
22.2400 1566.0000 1.0000
22.2800 1649.0000 1.0000
22.3200 1529.0000 1.0000
22.3600 1619.0000 1.0000
22.4000 1605.0000 1.0000
22.4400 1545.0000 1.0000
22.4800 1554.0000 1.0000
22.5200 1561.0000 1.0000
22.5600 1544.0000 1.0000
22.6000 1603.0000 1.0000
22.6400 1578.0000 1.0000
22.6800 1622.0000 1.0000
22.7200 1621.0000 1.0000
22.7600 1614.0000 1.0000
22.8000 1616.0000 1.0000
22.8400 1594.0000 1.0000
22.8800 1547.0000 1.0000
22.9200 1565.0000 1.0000
22.9600 1552.0000 1.0000
23.0000 1631.0000 1.0000
23.0400 1541.0000 1.0000
23.0800 1579.0000 1.0000
23.1200 1622.0000 1.0000
23.1600 1567.0000 1.0000
23.2000 1633.0000 1.0000
23.2400 1590.0000 1.0000
23.2800 1593.0000 1.0000
23.3200 1591.0000 1.0000
23.3600 1542.0000 1.0000
23.4000 1590.0000 1.0000
23.4400 1574.0000 1.0000
23.4800 1677.0000 1.0000
23.5200 1623.0000 1.0000
23.5600 1628.0000 1.0000
23.6000 1645.0000 1.0000
23.6400 1569.0000 1.0000
23.6800 1678.0000 1.0000
23.7200 1658.0000 1.0000
23.7600 1607.0000 1.0000
23.8000 1600.0000 1.0000
23.8400 1592.0000 1.0000
23.8800 1568.0000 1.0000
23.9200 1661.0000 1.0000
23.9600 1594.0000 1.0000
24.0000 1639.0000 1.0000
24.0400 1613.0000 1.0000
24.0800 1644.0000 1.0000
24.1200 1608.0000 1.0000
24.1600 1632.0000 1.0000
24.2000 1645.0000 1.0000
24.2400 1598.0000 1.0000
24.2800 1612.0000 1.0000
24.3200 1598.0000 1.0000
24.3600 1583.0000 1.0000
24.4000 1563.0000 1.0000
24.4400 1646.0000 1.0000
24.4800 1672.0000 1.0000
24.5200 1623.0000 1.0000
24.5600 1606.0000 1.0000
24.6000 1636.0000 1.0000
24.6400 1627.0000 1.0000
24.6800 1657.0000 1.0000
24.7200 1651.0000 1.0000
24.7600 1662.0000 1.0000
24.8000 1689.0000 1.0000
24.8400 1652.0000 1.0000
24.8800 1628.0000 1.0000
24.9200 1696.0000 1.0000
24.9600 1662.0000 1.0000
25.0000 1702.0000 1.0000
25.0400 1685.0000 1.0000
25.0800 1632.0000 1.0000
25.1200 1743.0000 1.0000
25.1600 1687.0000 1.0000
25.2000 1697.0000 1.0000
25.2400 1663.0000 1.0000
25.2800 1659.0000 1.0000
25.3200 1683.0000 1.0000
25.3600 1658.0000 1.0000
25.4000 1665.0000 1.0000
25.4400 1648.0000 1.0000
25.4800 1660.0000 1.0000
25.5200 1631.0000 1.0000
25.5600 1595.0000 1.0000
25.6000 1732.0000 1.0000
25.6400 1688.0000 1.0000
25.6800 1700.0000 1.0000
25.7200 1737.0000 1.0000
25.7600 1656.0000 1.0000
25.8000 1609.0000 1.0000
25.8400 1611.0000 1.0000
25.8800 1605.0000 1.0000
25.9200 1627.0000 1.0000
25.9600 1649.0000 1.0000
26.0000 1663.0000 1.0000
26.0400 1663.0000 1.0000
26.0800 1582.0000 1.0000
26.1200 1699.0000 1.0000
26.1600 1630.0000 1.0000
26.2000 1709.0000 1.0000
26.2400 1711.0000 1.0000
26.2800 1635.0000 1.0000
26.3200 1727.0000 1.0000
26.3600 1678.0000 1.0000
26.4000 1703.0000 1.0000
26.4400 1751.0000 1.0000
26.4800 1710.0000 1.0000
26.5200 1763.0000 1.0000
26.5600 1710.0000 1.0000
26.6000 1767.0000 1.0000
26.6400 1739.0000 1.0000
26.6800 1799.0000 1.0000
26.7200 1707.0000 1.0000
26.7600 1817.0000 1.0000
26.8000 1840.0000 1.0000
26.8400 1943.0000 1.0000
26.8800 1988.0000 1.0000
26.9200 2028.0000 1.0000
26.9600 2151.0000 1.0000
27.0000 2293.0000 1.0000
27.0400 2505.0000 1.0000
27.0800 2786.0000 1.0000
27.1200 3284.0000 1.0000
27.1600 3892.0000 1.0000
27.2000 4702.0000 1.0000
27.2400 5657.0000 1.0000
27.2800 6227.0000 1.0000
27.3200 6028.0000 1.0000
27.3600 5298.0000 1.0000
27.4000 4352.0000 1.0000
27.4400 3605.0000 1.0000
27.4800 2911.0000 1.0000
27.5200 2619.0000 1.0000
27.5600 2394.0000 1.0000
27.6000 2216.0000 1.0000
27.6400 2063.0000 1.0000
27.6800 1955.0000 1.0000
27.7200 1979.0000 1.0000
27.7600 1809.0000 1.0000
27.8000 1867.0000 1.0000
27.8400 1751.0000 1.0000
27.8800 1805.0000 1.0000
27.9200 1735.0000 1.0000
27.9600 1707.0000 1.0000
28.0000 1738.0000 1.0000
28.0400 1729.0000 1.0000
28.0800 1606.0000 1.0000
28.1200 1687.0000 1.0000
28.1600 1599.0000 1.0000
28.2000 1698.0000 1.0000
28.2400 1706.0000 1.0000
28.2800 1656.0000 1.0000
28.3200 1658.0000 1.0000
28.3600 1631.0000 1.0000
28.4000 1615.0000 1.0000
28.4400 1598.0000 1.0000
28.4800 1596.0000 1.0000
28.5200 1603.0000 1.0000
28.5600 1665.0000 1.0000
28.6000 1581.0000 1.0000
28.6400 1608.0000 1.0000
28.6800 1621.0000 1.0000
28.7200 1601.0000 1.0000
28.7600 1624.0000 1.0000
28.8000 1629.0000 1.0000
28.8400 1572.0000 1.0000
28.8800 1592.0000 1.0000
28.9200 1621.0000 1.0000
28.9600 1562.0000 1.0000
29.0000 1522.0000 1.0000
29.0400 1581.0000 1.0000
29.0800 1570.0000 1.0000
29.1200 1571.0000 1.0000
29.1600 1557.0000 1.0000
29.2000 1580.0000 1.0000
29.2400 1661.0000 1.0000
29.2800 1589.0000 1.0000
29.3200 1578.0000 1.0000
29.3600 1502.0000 1.0000
29.4000 1599.0000 1.0000
29.4400 1507.0000 1.0000
29.4800 1602.0000 1.0000
29.5200 1635.0000 1.0000
29.5600 1580.0000 1.0000
29.6000 1566.0000 1.0000
29.6400 1552.0000 1.0000
29.6800 1599.0000 1.0000
29.7200 1492.0000 1.0000
29.7600 1576.0000 1.0000
29.8000 1522.0000 1.0000
29.8400 1566.0000 1.0000
29.8800 1545.0000 1.0000
29.9200 1564.0000 1.0000
29.9600 1497.0000 1.0000
30.0000 1481.0000 1.0000
30.0400 1522.0000 1.0000
30.0800 1575.0000 1.0000
30.1200 1466.0000 1.0000
30.1600 1501.0000 1.0000
30.2000 1537.0000 1.0000
30.2400 1503.0000 1.0000
30.2800 1511.0000 1.0000
30.3200 1516.0000 1.0000
30.3600 1509.0000 1.0000
30.4000 1462.0000 1.0000
30.4400 1533.0000 1.0000
30.4800 1485.0000 1.0000
30.5200 1513.0000 1.0000
30.5600 1552.0000 1.0000
30.6000 1461.0000 1.0000
30.6400 1435.0000 1.0000
30.6800 1578.0000 1.0000
30.7200 1468.0000 1.0000
30.7600 1522.0000 1.0000
30.8000 1511.0000 1.0000
30.8400 1540.0000 1.0000
30.8800 1497.0000 1.0000
30.9200 1542.0000 1.0000
30.9600 1463.0000 1.0000
31.0000 1421.0000 1.0000
31.0400 1436.0000 1.0000
31.0800 1488.0000 1.0000
31.1200 1541.0000 1.0000
31.1600 1497.0000 1.0000
31.2000 1473.0000 1.0000
31.2400 1505.0000 1.0000
31.2800 1480.0000 1.0000
31.3200 1496.0000 1.0000
31.3600 1454.0000 1.0000
31.4000 1469.0000 1.0000
31.4400 1513.0000 1.0000
31.4800 1467.0000 1.0000
31.5200 1443.0000 1.0000
31.5600 1478.0000 1.0000
31.6000 1423.0000 1.0000
31.6400 1406.0000 1.0000
31.6800 1428.0000 1.0000
31.7200 1425.0000 1.0000
31.7600 1396.0000 1.0000
31.8000 1410.0000 1.0000
31.8400 1439.0000 1.0000
31.8800 1431.0000 1.0000
31.9200 1442.0000 1.0000
31.9600 1527.0000 1.0000
32.0000 1478.0000 1.0000
32.0400 1508.0000 1.0000
32.0800 1375.0000 1.0000
32.1200 1465.0000 1.0000
32.1600 1448.0000 1.0000
32.2000 1525.0000 1.0000
32.2400 1440.0000 1.0000
32.2800 1391.0000 1.0000
32.3200 1404.0000 1.0000
32.3600 1402.0000 1.0000
32.4000 1387.0000 1.0000
32.4400 1359.0000 1.0000
32.4800 1419.0000 1.0000
32.5200 1424.0000 1.0000
32.5600 1405.0000 1.0000
32.6000 1400.0000 1.0000
32.6400 1444.0000 1.0000
32.6800 1452.0000 1.0000
32.7200 1431.0000 1.0000
32.7600 1394.0000 1.0000
32.8000 1449.0000 1.0000
32.8400 1327.0000 1.0000
32.8800 1403.0000 1.0000
32.9200 1355.0000 1.0000
32.9600 1380.0000 1.0000
33.0000 1457.0000 1.0000
33.0400 1378.0000 1.0000
33.0800 1388.0000 1.0000
33.1200 1358.0000 1.0000
33.1600 1360.0000 1.0000
33.2000 1369.0000 1.0000
33.2400 1401.0000 1.0000
33.2800 1357.0000 1.0000
33.3200 1362.0000 1.0000
33.3600 1412.0000 1.0000
33.4000 1326.0000 1.0000
33.4400 1374.0000 1.0000
33.4800 1350.0000 1.0000
33.5200 1407.0000 1.0000
33.5600 1456.0000 1.0000
33.6000 1389.0000 1.0000
33.6400 1394.0000 1.0000
33.6800 1383.0000 1.0000
33.7200 1381.0000 1.0000
33.7600 1431.0000 1.0000
33.8000 1358.0000 1.0000
33.8400 1413.0000 1.0000
33.8800 1443.0000 1.0000
33.9200 1462.0000 1.0000
33.9600 1396.0000 1.0000
34.0000 1483.0000 1.0000
34.0400 1411.0000 1.0000
34.0800 1499.0000 1.0000
34.1200 1491.0000 1.0000
34.1600 1548.0000 1.0000
34.2000 1571.0000 1.0000
34.2400 1699.0000 1.0000
34.2800 1827.0000 1.0000
34.3200 1963.0000 1.0000
34.3600 2178.0000 1.0000
34.4000 2453.0000 1.0000
34.4400 2771.0000 1.0000
34.4800 2872.0000 1.0000
34.5200 2825.0000 1.0000
34.5600 2552.0000 1.0000
34.6000 2281.0000 1.0000
34.6400 2038.0000 1.0000
34.6800 1797.0000 1.0000
34.7200 1682.0000 1.0000
34.7600 1609.0000 1.0000
34.8000 1546.0000 1.0000
34.8400 1473.0000 1.0000
34.8800 1412.0000 1.0000
34.9200 1369.0000 1.0000
34.9600 1401.0000 1.0000
35.0000 1384.0000 1.0000
35.0400 1294.0000 1.0000
35.0800 1317.0000 1.0000
35.1200 1226.0000 1.0000
35.1600 1300.0000 1.0000
35.2000 1228.0000 1.0000
35.2400 1220.0000 1.0000
35.2800 1273.0000 1.0000
35.3200 1241.0000 1.0000
35.3600 1264.0000 1.0000
35.4000 1249.0000 1.0000
35.4400 1186.0000 1.0000
35.4800 1173.0000 1.0000
35.5200 1186.0000 1.0000
35.5600 1230.0000 1.0000
35.6000 1176.0000 1.0000
35.6400 1192.0000 1.0000
35.6800 1235.0000 1.0000
35.7200 1191.0000 1.0000
35.7600 1205.0000 1.0000
35.8000 1232.0000 1.0000
35.8400 1220.0000 1.0000
35.8800 1180.0000 1.0000
35.9200 1138.0000 1.0000
35.9600 1253.0000 1.0000
36.0000 1295.0000 1.0000
36.0400 1240.0000 1.0000
36.0800 1269.0000 1.0000
36.1200 1321.0000 1.0000
36.1600 1324.0000 1.0000
36.2000 1417.0000 1.0000
36.2400 1449.0000 1.0000
36.2800 1499.0000 1.0000
36.3200 1542.0000 1.0000
36.3600 1609.0000 1.0000
36.4000 1718.0000 1.0000
36.4400 1594.0000 1.0000
36.4800 1624.0000 1.0000
36.5200 1511.0000 1.0000
36.5600 1422.0000 1.0000
36.6000 1378.0000 1.0000
36.6400 1268.0000 1.0000
36.6800 1293.0000 1.0000
36.7200 1251.0000 1.0000
36.7600 1186.0000 1.0000
36.8000 1099.0000 1.0000
36.8400 1151.0000 1.0000
36.8800 1086.0000 1.0000
36.9200 1123.0000 1.0000
36.9600 1116.0000 1.0000
37.0000 1092.0000 1.0000
37.0400 1162.0000 1.0000
37.0800 1134.0000 1.0000
37.1200 1169.0000 1.0000
37.1600 1120.0000 1.0000
37.2000 1057.0000 1.0000
37.2400 1095.0000 1.0000
37.2800 1115.0000 1.0000
37.3200 1094.0000 1.0000
37.3600 1074.0000 1.0000
37.4000 1093.0000 1.0000
37.4400 1074.0000 1.0000
37.4800 1103.0000 1.0000
37.5200 1101.0000 1.0000
37.5600 1085.0000 1.0000
37.6000 1082.0000 1.0000
37.6400 1101.0000 1.0000
37.6800 1084.0000 1.0000
37.7200 1109.0000 1.0000
37.7600 1129.0000 1.0000
37.8000 1136.0000 1.0000
37.8400 1115.0000 1.0000
37.8800 1121.0000 1.0000
37.9200 1109.0000 1.0000
37.9600 1196.0000 1.0000
38.0000 1118.0000 1.0000
38.0400 1177.0000 1.0000
38.0800 1247.0000 1.0000
38.1200 1348.0000 1.0000
38.1600 1459.0000 1.0000
38.2000 1560.0000 1.0000
38.2400 1705.0000 1.0000
38.2800 2041.0000 1.0000
38.3200 2533.0000 1.0000
38.3600 3101.0000 1.0000
38.4000 4040.0000 1.0000
38.4400 5148.0000 1.0000
38.4800 6539.0000 1.0000
38.5200 7503.0000 1.0000
38.5600 7190.0000 1.0000
38.6000 6162.0000 1.0000
38.6400 5156.0000 1.0000
38.6800 3956.0000 1.0000
38.7200 3040.0000 1.0000
38.7600 2379.0000 1.0000
38.8000 1983.0000 1.0000
38.8400 1709.0000 1.0000
38.8800 1481.0000 1.0000
38.9200 1430.0000 1.0000
38.9600 1248.0000 1.0000
39.0000 1186.0000 1.0000
39.0400 1117.0000 1.0000
39.0800 1136.0000 1.0000
39.1200 1085.0000 1.0000
39.1600 1107.0000 1.0000
39.2000 1007.0000 1.0000
39.2400 997.0000 1.0000
39.2800 1020.0000 1.0000
39.3200 1003.0000 1.0000
39.3600 1049.0000 1.0000
39.4000 1028.0000 1.0000
39.4400 993.0000 1.0000
39.4800 985.0000 1.0000
39.5200 996.0000 1.0000
39.5600 1024.0000 1.0000
39.6000 1028.0000 1.0000
39.6400 1006.0000 1.0000
39.6800 1017.0000 1.0000
39.7200 1001.0000 1.0000
39.7600 969.0000 1.0000
39.8000 985.0000 1.0000
39.8400 994.0000 1.0000
39.8800 958.0000 1.0000
39.9200 967.0000 1.0000
39.9600 1014.0000 1.0000
40.0000 971.0000 1.0000
40.0400 969.0000 1.0000
40.0800 955.0000 1.0000
40.1200 946.0000 1.0000
40.1600 964.0000 1.0000
40.2000 933.0000 1.0000
40.2400 907.0000 1.0000
40.2800 934.0000 1.0000
40.3200 947.0000 1.0000
40.3600 937.0000 1.0000
40.4000 941.0000 1.0000
40.4400 928.0000 1.0000
40.4800 917.0000 1.0000
40.5200 918.0000 1.0000
40.5600 938.0000 1.0000
40.6000 895.0000 1.0000
40.6400 912.0000 1.0000
40.6800 933.0000 1.0000
40.7200 951.0000 1.0000
40.7600 873.0000 1.0000
40.8000 906.0000 1.0000
40.8400 922.0000 1.0000
40.8800 944.0000 1.0000
40.9200 945.0000 1.0000
40.9600 875.0000 1.0000
41.0000 912.0000 1.0000
41.0400 907.0000 1.0000
41.0800 892.0000 1.0000
41.1200 953.0000 1.0000
41.1600 896.0000 1.0000
41.2000 918.0000 1.0000
41.2400 890.0000 1.0000
41.2800 915.0000 1.0000
41.3200 868.0000 1.0000
41.3600 907.0000 1.0000
41.4000 916.0000 1.0000
41.4400 901.0000 1.0000
41.4800 958.0000 1.0000
41.5200 896.0000 1.0000
41.5600 891.0000 1.0000
41.6000 868.0000 1.0000
41.6400 936.0000 1.0000
41.6800 857.0000 1.0000
41.7200 919.0000 1.0000
41.7600 908.0000 1.0000
41.8000 924.0000 1.0000
41.8400 905.0000 1.0000
41.8800 904.0000 1.0000
41.9200 904.0000 1.0000
41.9600 918.0000 1.0000
42.0000 924.0000 1.0000
42.0400 920.0000 1.0000
42.0800 872.0000 1.0000
42.1200 833.0000 1.0000
42.1600 922.0000 1.0000
42.2000 872.0000 1.0000
42.2400 937.0000 1.0000
42.2800 882.0000 1.0000
42.3200 889.0000 1.0000
42.3600 854.0000 1.0000
42.4000 875.0000 1.0000
42.4400 893.0000 1.0000
42.4800 919.0000 1.0000
42.5200 851.0000 1.0000
42.5600 865.0000 1.0000
42.6000 864.0000 1.0000
42.6400 874.0000 1.0000
42.6800 855.0000 1.0000
42.7200 952.0000 1.0000
42.7600 863.0000 1.0000
42.8000 865.0000 1.0000
42.8400 920.0000 1.0000
42.8800 918.0000 1.0000
42.9200 841.0000 1.0000
42.9600 871.0000 1.0000
43.0000 852.0000 1.0000
43.0400 966.0000 1.0000
43.0800 955.0000 1.0000
43.1200 939.0000 1.0000
43.1600 951.0000 1.0000
43.2000 919.0000 1.0000
43.2400 937.0000 1.0000
43.2800 948.0000 1.0000
43.3200 932.0000 1.0000
43.3600 936.0000 1.0000
43.4000 860.0000 1.0000
43.4400 909.0000 1.0000
43.4800 951.0000 1.0000
43.5200 895.0000 1.0000
43.5600 871.0000 1.0000
43.6000 881.0000 1.0000
43.6400 847.0000 1.0000
43.6800 851.0000 1.0000
43.7200 830.0000 1.0000
43.7600 894.0000 1.0000
43.8000 838.0000 1.0000
43.8400 824.0000 1.0000
43.8800 892.0000 1.0000
43.9200 863.0000 1.0000
43.9600 838.0000 1.0000
44.0000 879.0000 1.0000
44.0400 831.0000 1.0000
44.0800 835.0000 1.0000
44.1200 876.0000 1.0000
44.1600 864.0000 1.0000
44.2000 877.0000 1.0000
44.2400 887.0000 1.0000
44.2800 859.0000 1.0000
44.3200 879.0000 1.0000
44.3600 904.0000 1.0000
44.4000 883.0000 1.0000
44.4400 880.0000 1.0000
44.4800 821.0000 1.0000
44.5200 849.0000 1.0000
44.5600 824.0000 1.0000
44.6000 824.0000 1.0000
44.6400 852.0000 1.0000
44.6800 838.0000 1.0000
44.7200 824.0000 1.0000
44.7600 783.0000 1.0000
44.8000 854.0000 1.0000
44.8400 888.0000 1.0000
44.8800 827.0000 1.0000
44.9200 801.0000 1.0000
44.9600 847.0000 1.0000
45.0000 845.0000 1.0000
45.0400 820.0000 1.0000
45.0800 871.0000 1.0000
45.1200 850.0000 1.0000
45.1600 823.0000 1.0000
45.2000 846.0000 1.0000
45.2400 826.0000 1.0000
45.2800 839.0000 1.0000
45.3200 838.0000 1.0000
45.3600 846.0000 1.0000
45.4000 817.0000 1.0000
45.4400 846.0000 1.0000
45.4800 864.0000 1.0000
45.5200 808.0000 1.0000
45.5600 828.0000 1.0000
45.6000 816.0000 1.0000
45.6400 826.0000 1.0000
45.6800 827.0000 1.0000
45.7200 825.0000 1.0000
45.7600 856.0000 1.0000
45.8000 792.0000 1.0000
45.8400 848.0000 1.0000
45.8800 797.0000 1.0000
45.9200 852.0000 1.0000
45.9600 813.0000 1.0000
46.0000 790.0000 1.0000
46.0400 835.0000 1.0000
46.0800 767.0000 1.0000
46.1200 800.0000 1.0000
46.1600 805.0000 1.0000
46.2000 795.0000 1.0000
46.2400 832.0000 1.0000
46.2800 853.0000 1.0000
46.3200 801.0000 1.0000
46.3600 845.0000 1.0000
46.4000 822.0000 1.0000
46.4400 807.0000 1.0000
46.4800 839.0000 1.0000
46.5200 791.0000 1.0000
46.5600 869.0000 1.0000
46.6000 806.0000 1.0000
46.6400 804.0000 1.0000
46.6800 823.0000 1.0000
46.7200 810.0000 1.0000
46.7600 797.0000 1.0000
46.8000 789.0000 1.0000
46.8400 830.0000 1.0000
46.8800 817.0000 1.0000
46.9200 815.0000 1.0000
46.9600 853.0000 1.0000
47.0000 900.0000 1.0000
47.0400 816.0000 1.0000
47.0800 780.0000 1.0000
47.1200 795.0000 1.0000
47.1600 818.0000 1.0000
47.2000 802.0000 1.0000
47.2400 764.0000 1.0000
47.2800 833.0000 1.0000
47.3200 802.0000 1.0000
47.3600 779.0000 1.0000
47.4000 742.0000 1.0000
47.4400 807.0000 1.0000
47.4800 775.0000 1.0000
47.5200 776.0000 1.0000
47.5600 812.0000 1.0000
47.6000 749.0000 1.0000
47.6400 794.0000 1.0000
47.6800 790.0000 1.0000
47.7200 747.0000 1.0000
47.7600 773.0000 1.0000
47.8000 774.0000 1.0000
47.8400 813.0000 1.0000
47.8800 774.0000 1.0000
47.9200 748.0000 1.0000
47.9600 747.0000 1.0000
48.0000 762.0000 1.0000
48.0400 705.0000 1.0000
48.0800 790.0000 1.0000
48.1200 785.0000 1.0000
48.1600 828.0000 1.0000
48.2000 763.0000 1.0000
48.2400 786.0000 1.0000
48.2800 766.0000 1.0000
48.3200 726.0000 1.0000
48.3600 745.0000 1.0000
48.4000 771.0000 1.0000
48.4400 807.0000 1.0000
48.4800 763.0000 1.0000
48.5200 798.0000 1.0000
48.5600 783.0000 1.0000
48.6000 808.0000 1.0000
48.6400 750.0000 1.0000
48.6800 793.0000 1.0000
48.7200 773.0000 1.0000
48.7600 755.0000 1.0000
48.8000 782.0000 1.0000
48.8400 788.0000 1.0000
48.8800 810.0000 1.0000
48.9200 769.0000 1.0000
48.9600 766.0000 1.0000
49.0000 735.0000 1.0000
49.0400 771.0000 1.0000
49.0800 737.0000 1.0000
49.1200 777.0000 1.0000
49.1600 735.0000 1.0000
49.2000 763.0000 1.0000
49.2400 753.0000 1.0000
49.2800 734.0000 1.0000
49.3200 787.0000 1.0000
49.3600 793.0000 1.0000
49.4000 740.0000 1.0000
49.4400 749.0000 1.0000
49.4800 745.0000 1.0000
49.5200 719.0000 1.0000
49.5600 750.0000 1.0000
49.6000 738.0000 1.0000
49.6400 765.0000 1.0000
49.6800 762.0000 1.0000
49.7200 753.0000 1.0000
49.7600 752.0000 1.0000
49.8000 774.0000 1.0000
49.8400 746.0000 1.0000
49.8800 816.0000 1.0000
49.9200 757.0000 1.0000
49.9600 774.0000 1.0000
50.0000 750.0000 1.0000
50.0400 774.0000 1.0000
50.0800 801.0000 1.0000
50.1200 826.0000 1.0000
50.1600 742.0000 1.0000
50.2000 747.0000 1.0000
50.2400 769.0000 1.0000
50.2800 743.0000 1.0000
50.3200 796.0000 1.0000
50.3600 808.0000 1.0000
50.4000 760.0000 1.0000
50.4400 802.0000 1.0000
50.4800 781.0000 1.0000
50.5200 745.0000 1.0000
50.5600 843.0000 1.0000
50.6000 754.0000 1.0000
50.6400 773.0000 1.0000
50.6800 767.0000 1.0000
50.7200 772.0000 1.0000
50.7600 756.0000 1.0000
50.8000 782.0000 1.0000
50.8400 787.0000 1.0000
50.8800 779.0000 1.0000
50.9200 754.0000 1.0000
50.9600 790.0000 1.0000
51.0000 777.0000 1.0000
51.0400 760.0000 1.0000
51.0800 773.0000 1.0000
51.1200 775.0000 1.0000
51.1600 770.0000 1.0000
51.2000 808.0000 1.0000
51.2400 756.0000 1.0000
51.2800 760.0000 1.0000
51.3200 786.0000 1.0000
51.3600 782.0000 1.0000
51.4000 784.0000 1.0000
51.4400 794.0000 1.0000
51.4800 763.0000 1.0000
51.5200 780.0000 1.0000
51.5600 822.0000 1.0000
51.6000 797.0000 1.0000
51.6400 786.0000 1.0000
51.6800 827.0000 1.0000
51.7200 828.0000 1.0000
51.7600 824.0000 1.0000
51.8000 852.0000 1.0000
51.8400 878.0000 1.0000
51.8800 921.0000 1.0000
51.9200 1040.0000 1.0000
51.9600 1076.0000 1.0000
52.0000 1208.0000 1.0000
52.0400 1406.0000 1.0000
52.0800 1678.0000 1.0000
52.1200 2110.0000 1.0000
52.1600 2883.0000 1.0000
52.2000 3853.0000 1.0000
52.2400 4872.0000 1.0000
52.2800 4574.0000 1.0000
52.3200 4134.0000 1.0000
52.3600 3724.0000 1.0000
52.4000 3488.0000 1.0000
52.4400 2791.0000 1.0000
52.4800 2064.0000 1.0000
52.5200 1676.0000 1.0000
52.5600 1378.0000 1.0000
52.6000 1182.0000 1.0000
52.6400 1142.0000 1.0000
52.6800 1029.0000 1.0000
52.7200 970.0000 1.0000
52.7600 958.0000 1.0000
52.8000 857.0000 1.0000
52.8400 874.0000 1.0000
52.8800 808.0000 1.0000
52.9200 879.0000 1.0000
52.9600 811.0000 1.0000
53.0000 799.0000 1.0000
53.0400 828.0000 1.0000
53.0800 756.0000 1.0000
53.1200 804.0000 1.0000
53.1600 781.0000 1.0000
53.2000 786.0000 1.0000
53.2400 783.0000 1.0000
53.2800 745.0000 1.0000
53.3200 741.0000 1.0000
53.3600 724.0000 1.0000
53.4000 764.0000 1.0000
53.4400 763.0000 1.0000
53.4800 733.0000 1.0000
53.5200 772.0000 1.0000
53.5600 762.0000 1.0000
53.6000 744.0000 1.0000
53.6400 762.0000 1.0000
53.6800 763.0000 1.0000
53.7200 740.0000 1.0000
53.7600 780.0000 1.0000
53.8000 748.0000 1.0000
53.8400 750.0000 1.0000
53.8800 709.0000 1.0000
53.9200 692.0000 1.0000
53.9600 740.0000 1.0000
54.0000 748.0000 1.0000
54.0400 785.0000 1.0000
54.0800 767.0000 1.0000
54.1200 755.0000 1.0000
54.1600 765.0000 1.0000
54.2000 759.0000 1.0000
54.2400 747.0000 1.0000
54.2800 742.0000 1.0000
54.3200 763.0000 1.0000
54.3600 725.0000 1.0000
54.4000 749.0000 1.0000
54.4400 709.0000 1.0000
54.4800 760.0000 1.0000
54.5200 786.0000 1.0000
54.5600 733.0000 1.0000
54.6000 705.0000 1.0000
54.6400 763.0000 1.0000
54.6800 743.0000 1.0000
54.7200 793.0000 1.0000
54.7600 786.0000 1.0000
54.8000 762.0000 1.0000
54.8400 775.0000 1.0000
54.8800 792.0000 1.0000
54.9200 773.0000 1.0000
54.9600 780.0000 1.0000
55.0000 805.0000 1.0000
55.0400 830.0000 1.0000
55.0800 880.0000 1.0000
55.1200 869.0000 1.0000
55.1600 961.0000 1.0000
55.2000 1057.0000 1.0000
55.2400 1109.0000 1.0000
55.2800 1105.0000 1.0000
55.3200 1109.0000 1.0000
55.3600 1079.0000 1.0000
55.4000 1020.0000 1.0000
55.4400 1014.0000 1.0000
55.4800 914.0000 1.0000
55.5200 910.0000 1.0000
55.5600 831.0000 1.0000
55.6000 792.0000 1.0000
55.6400 821.0000 1.0000
55.6800 790.0000 1.0000
55.7200 795.0000 1.0000
55.7600 758.0000 1.0000
55.8000 722.0000 1.0000
55.8400 739.0000 1.0000
55.8800 747.0000 1.0000
55.9200 761.0000 1.0000
55.9600 743.0000 1.0000
56.0000 730.0000 1.0000
56.0400 715.0000 1.0000
56.0800 700.0000 1.0000
56.1200 693.0000 1.0000
56.1600 711.0000 1.0000
56.2000 728.0000 1.0000
56.2400 718.0000 1.0000
56.2800 742.0000 1.0000
56.3200 722.0000 1.0000
56.3600 722.0000 1.0000
56.4000 740.0000 1.0000
56.4400 702.0000 1.0000
56.4800 747.0000 1.0000
56.5200 700.0000 1.0000
56.5600 711.0000 1.0000
56.6000 739.0000 1.0000
56.6400 739.0000 1.0000
56.6800 745.0000 1.0000
56.7200 742.0000 1.0000
56.7600 690.0000 1.0000
56.8000 724.0000 1.0000
56.8400 682.0000 1.0000
56.8800 703.0000 1.0000
56.9200 691.0000 1.0000
56.9600 737.0000 1.0000
57.0000 741.0000 1.0000
57.0400 730.0000 1.0000
57.0800 700.0000 1.0000
57.1200 679.0000 1.0000
57.1600 706.0000 1.0000
57.2000 702.0000 1.0000
57.2400 695.0000 1.0000
57.2800 673.0000 1.0000
57.3200 724.0000 1.0000
57.3600 727.0000 1.0000
57.4000 677.0000 1.0000
57.4400 725.0000 1.0000
57.4800 713.0000 1.0000
57.5200 645.0000 1.0000
57.5600 725.0000 1.0000
57.6000 703.0000 1.0000
57.6400 694.0000 1.0000
57.6800 751.0000 1.0000
57.7200 726.0000 1.0000
57.7600 705.0000 1.0000
57.8000 731.0000 1.0000
57.8400 714.0000 1.0000
57.8800 746.0000 1.0000
57.9200 749.0000 1.0000
57.9600 718.0000 1.0000
58.0000 734.0000 1.0000
58.0400 666.0000 1.0000
58.0800 698.0000 1.0000
58.1200 695.0000 1.0000
58.1600 684.0000 1.0000
58.2000 748.0000 1.0000
58.2400 668.0000 1.0000
58.2800 748.0000 1.0000
58.3200 725.0000 1.0000
58.3600 721.0000 1.0000
58.4000 695.0000 1.0000
58.4400 703.0000 1.0000
58.4800 692.0000 1.0000
58.5200 744.0000 1.0000
58.5600 708.0000 1.0000
58.6000 733.0000 1.0000
58.6400 766.0000 1.0000
58.6800 696.0000 1.0000
58.7200 718.0000 1.0000
58.7600 674.0000 1.0000
58.8000 751.0000 1.0000
58.8400 692.0000 1.0000
58.8800 702.0000 1.0000
58.9200 689.0000 1.0000
58.9600 709.0000 1.0000
59.0000 720.0000 1.0000
59.0400 648.0000 1.0000
59.0800 669.0000 1.0000
59.1200 665.0000 1.0000
59.1600 706.0000 1.0000
59.2000 727.0000 1.0000
59.2400 706.0000 1.0000
59.2800 718.0000 1.0000
59.3200 753.0000 1.0000
59.3600 728.0000 1.0000
59.4000 762.0000 1.0000
59.4400 710.0000 1.0000
59.4800 722.0000 1.0000
59.5200 683.0000 1.0000
59.5600 696.0000 1.0000
59.6000 660.0000 1.0000
59.6400 645.0000 1.0000
59.6800 710.0000 1.0000
59.7200 664.0000 1.0000
59.7600 701.0000 1.0000
59.8000 737.0000 1.0000
59.8400 727.0000 1.0000
59.8800 691.0000 1.0000
59.9200 676.0000 1.0000
59.9600 738.0000 1.0000
60.0000 732.0000 1.0000
60.0400 724.0000 1.0000
60.0800 664.0000 1.0000
60.1200 696.0000 1.0000
60.1600 721.0000 1.0000
60.2000 695.0000 1.0000
60.2400 731.0000 1.0000
60.2800 710.0000 1.0000
60.3200 703.0000 1.0000
60.3600 730.0000 1.0000
60.4000 697.0000 1.0000
60.4400 688.0000 1.0000
60.4800 716.0000 1.0000
60.5200 720.0000 1.0000
60.5600 692.0000 1.0000
60.6000 701.0000 1.0000
60.6400 735.0000 1.0000
60.6800 707.0000 1.0000
60.7200 721.0000 1.0000
60.7600 691.0000 1.0000
60.8000 706.0000 1.0000
60.8400 686.0000 1.0000
60.8800 714.0000 1.0000
60.9200 691.0000 1.0000
60.9600 737.0000 1.0000
61.0000 633.0000 1.0000
61.0400 668.0000 1.0000
61.0800 708.0000 1.0000
61.1200 699.0000 1.0000
61.1600 712.0000 1.0000
61.2000 692.0000 1.0000
61.2400 684.0000 1.0000
61.2800 706.0000 1.0000
61.3200 736.0000 1.0000
61.3600 732.0000 1.0000
61.4000 694.0000 1.0000
61.4400 734.0000 1.0000
61.4800 735.0000 1.0000
61.5200 738.0000 1.0000
61.5600 744.0000 1.0000
61.6000 719.0000 1.0000
61.6400 740.0000 1.0000
61.6800 735.0000 1.0000
61.7200 744.0000 1.0000
61.7600 774.0000 1.0000
61.8000 777.0000 1.0000
61.8400 815.0000 1.0000
61.8800 827.0000 1.0000
61.9200 778.0000 1.0000
61.9600 919.0000 1.0000
62.0000 930.0000 1.0000
62.0400 995.0000 1.0000
62.0800 1097.0000 1.0000
62.1200 1150.0000 1.0000
62.1600 1339.0000 1.0000
62.2000 1497.0000 1.0000
62.2400 1662.0000 1.0000
62.2800 1710.0000 1.0000
62.3200 1653.0000 1.0000
62.3600 1655.0000 1.0000
62.4000 1561.0000 1.0000
62.4400 1485.0000 1.0000
62.4800 1381.0000 1.0000
62.5200 1282.0000 1.0000
62.5600 1150.0000 1.0000
62.6000 1090.0000 1.0000
62.6400 1014.0000 1.0000
62.6800 954.0000 1.0000
62.7200 829.0000 1.0000
62.7600 845.0000 1.0000
62.8000 879.0000 1.0000
62.8400 809.0000 1.0000
62.8800 781.0000 1.0000
62.9200 791.0000 1.0000
62.9600 732.0000 1.0000
63.0000 792.0000 1.0000
63.0400 795.0000 1.0000
63.0800 765.0000 1.0000
63.1200 759.0000 1.0000
63.1600 768.0000 1.0000
63.2000 762.0000 1.0000
63.2400 780.0000 1.0000
63.2800 803.0000 1.0000
63.3200 780.0000 1.0000
63.3600 748.0000 1.0000
63.4000 739.0000 1.0000
63.4400 763.0000 1.0000
63.4800 695.0000 1.0000
63.5200 747.0000 1.0000
63.5600 742.0000 1.0000
63.6000 690.0000 1.0000
63.6400 766.0000 1.0000
63.6800 766.0000 1.0000
63.7200 711.0000 1.0000
63.7600 755.0000 1.0000
63.8000 707.0000 1.0000
63.8400 756.0000 1.0000
63.8800 750.0000 1.0000
63.9200 710.0000 1.0000
63.9600 696.0000 1.0000
64.0000 710.0000 1.0000
64.0400 747.0000 1.0000
64.0800 718.0000 1.0000
64.1200 784.0000 1.0000
64.1600 772.0000 1.0000
64.2000 766.0000 1.0000
64.2400 772.0000 1.0000
64.2800 745.0000 1.0000
64.3200 761.0000 1.0000
64.3600 805.0000 1.0000
64.4000 799.0000 1.0000
64.4400 795.0000 1.0000
64.4800 830.0000 1.0000
64.5200 809.0000 1.0000
64.5600 879.0000 1.0000
64.6000 869.0000 1.0000
64.6400 906.0000 1.0000
64.6800 921.0000 1.0000
64.7200 939.0000 1.0000
64.7600 944.0000 1.0000
64.8000 931.0000 1.0000
64.8400 909.0000 1.0000
64.8800 916.0000 1.0000
64.9200 925.0000 1.0000
64.9600 862.0000 1.0000
65.0000 838.0000 1.0000
65.0400 909.0000 1.0000
65.0800 831.0000 1.0000
65.1200 817.0000 1.0000
65.1600 804.0000 1.0000
65.2000 819.0000 1.0000
65.2400 774.0000 1.0000
65.2800 785.0000 1.0000
65.3200 813.0000 1.0000
65.3600 768.0000 1.0000
65.4000 710.0000 1.0000
65.4400 774.0000 1.0000
65.4800 791.0000 1.0000
65.5200 772.0000 1.0000
65.5600 772.0000 1.0000
65.6000 798.0000 1.0000
65.6400 814.0000 1.0000
65.6800 784.0000 1.0000
65.7200 784.0000 1.0000
65.7600 872.0000 1.0000
65.8000 812.0000 1.0000
65.8400 870.0000 1.0000
65.8800 916.0000 1.0000
65.9200 986.0000 1.0000
65.9600 956.0000 1.0000
66.0000 1123.0000 1.0000
66.0400 1216.0000 1.0000
66.0800 1407.0000 1.0000
66.1200 1753.0000 1.0000
66.1600 2117.0000 1.0000
66.2000 2527.0000 1.0000
66.2400 2656.0000 1.0000
66.2800 2605.0000 1.0000
66.3200 2394.0000 1.0000
66.3600 2292.0000 1.0000
66.4000 2245.0000 1.0000
66.4400 2020.0000 1.0000
66.4800 1778.0000 1.0000
66.5200 1585.0000 1.0000
66.5600 1290.0000 1.0000
66.6000 1188.0000 1.0000
66.6400 980.0000 1.0000
66.6800 999.0000 1.0000
66.7200 935.0000 1.0000
66.7600 870.0000 1.0000
66.8000 873.0000 1.0000
66.8400 759.0000 1.0000
66.8800 828.0000 1.0000
66.9200 752.0000 1.0000
66.9600 715.0000 1.0000
67.0000 764.0000 1.0000
67.0400 731.0000 1.0000
67.0800 715.0000 1.0000
67.1200 711.0000 1.0000
67.1600 713.0000 1.0000
67.2000 728.0000 1.0000
67.2400 666.0000 1.0000
67.2800 674.0000 1.0000
67.3200 697.0000 1.0000
67.3600 657.0000 1.0000
67.4000 699.0000 1.0000
67.4400 664.0000 1.0000
67.4800 673.0000 1.0000
67.5200 710.0000 1.0000
67.5600 664.0000 1.0000
67.6000 670.0000 1.0000
67.6400 714.0000 1.0000
67.6800 647.0000 1.0000
67.7200 643.0000 1.0000
67.7600 659.0000 1.0000
67.8000 694.0000 1.0000
67.8400 646.0000 1.0000
67.8800 643.0000 1.0000
67.9200 664.0000 1.0000
67.9600 651.0000 1.0000
68.0000 660.0000 1.0000
68.0400 697.0000 1.0000
68.0800 645.0000 1.0000
68.1200 613.0000 1.0000
68.1600 687.0000 1.0000
68.2000 638.0000 1.0000
68.2400 672.0000 1.0000
68.2800 633.0000 1.0000
68.3200 659.0000 1.0000
68.3600 656.0000 1.0000
68.4000 645.0000 1.0000
68.4400 662.0000 1.0000
68.4800 665.0000 1.0000
68.5200 664.0000 1.0000
68.5600 651.0000 1.0000
68.6000 688.0000 1.0000
68.6400 612.0000 1.0000
68.6800 685.0000 1.0000
68.7200 613.0000 1.0000
68.7600 634.0000 1.0000
68.8000 634.0000 1.0000
68.8400 650.0000 1.0000
68.8800 658.0000 1.0000
68.9200 652.0000 1.0000
68.9600 650.0000 1.0000
69.0000 616.0000 1.0000
69.0400 666.0000 1.0000
69.0800 660.0000 1.0000
69.1200 608.0000 1.0000
69.1600 640.0000 1.0000
69.2000 651.0000 1.0000
69.2400 668.0000 1.0000
69.2800 674.0000 1.0000
69.3200 650.0000 1.0000
69.3600 648.0000 1.0000
69.4000 611.0000 1.0000
69.4400 677.0000 1.0000
69.4800 653.0000 1.0000
69.5200 635.0000 1.0000
69.5600 648.0000 1.0000
69.6000 634.0000 1.0000
69.6400 674.0000 1.0000
69.6800 634.0000 1.0000
69.7200 608.0000 1.0000
69.7600 617.0000 1.0000
69.8000 598.0000 1.0000
69.8400 654.0000 1.0000
69.8800 601.0000 1.0000
69.9200 573.0000 1.0000
69.9600 664.0000 1.0000
70.0000 615.0000 1.0000
*RAS_INT_END
*RAS_TEMPERATURE_START
*RAS_TEMPERATURE_END
*RAS_DATA_END