File: Section2_75_samples/XRD/No_031_FS1_3.ras
*RAS_DATA_START
*RAS_HEADER_START
*DISP_FMT_X "%.2f"
*DISP_FMT_Y "%.0f"
*DISP_FULLSCALE "13720.0000000000"
*DISP_LINE_COLOR "255.0000000000"
*DISP_LINE_STYLE "0.0000000000"
*DISP_LINE_WIDTH "0.2500000000"
*DISP_NOTE "測定データ-4"
*DISP_OFFSET_Y "0.0000000000"
*DISP_PEAKSEARCH_UNIT_Y "cps"
*DISP_RANGE_BOTTOM "0.0000000000"
*DISP_RANGE_LEFT "20.0000000000"
*DISP_RANGE_LOGCUTOFF "0.0100000000"
*DISP_RANGE_RIGHT "70.0000000000"
*DISP_RANGE_TOP "13720.0000000000"
*DISP_SCALE_MODE_Y "0.0000000000"
*DISP_TAB_NAME "2θ/θ"
*DISP_TITLE_Y "強度"
*DISP_UNIT_Y "cps"
*DISP_WINDOW_NAME "MSG_MACROENGINE"
*FILE_COMMENT " "
*FILE_MD5 ""
*FILE_MEMO " "
*FILE_OPERATOR "Administrator"
*FILE_SAMPLE " "
*FILE_TYPE "RAS_RAW"
*FILE_USERGROUP "システムマネージャ"
*FILE_VERSION "1.0000000000"
*HW_ATTACHMENT_ID "ATT0025"
*HW_ATTACHMENT_NAME "標準|Standard"
*HW_COUNTER_ID-0 "CUT0025"
*HW_COUNTER_ID-1 "CUT0020"
*HW_COUNTER_ID-2 "CUT0020"
*HW_COUNTER_ID-3 "CSL0021"
*HW_COUNTER_ID-4 "CMC0021"
*HW_COUNTER_NAME-0 "D/teX Ultra|D/teX Ultra"
*HW_COUNTER_NAME-1 "None|None"
*HW_COUNTER_NAME-2 "None|None"
*HW_COUNTER_NAME-3 "BBM|BBM"
*HW_COUNTER_NAME-4 "検出器モノクロメータ|Detector monochromator"
*HW_COUNTER_SELECT_NAME "D/teX Ultra|D/teX Ultra"
*HW_GONIOMETER_ID "GON0023"
*HW_GONIOMETER_NAME "SmartLab|SmartLab"
*HW_GONIOMETER_RADIUS-0 "90.0"
*HW_GONIOMETER_RADIUS-1 "114.0"
*HW_GONIOMETER_RADIUS-2 "190.0"
*HW_GONIOMETER_RADIUS-3 "300.0"
*HW_GONIOMETER_RADIUS-4 "187.0"
*HW_GONIOMETER_RADIUS-5 "300.0"
*HW_GONIOMETER_RADIUS-6 "113.0"
*HW_GONIOMETER_RADIUS-7 "331.0"
*HW_I_OPT_ID-0 "CBO0021"
*HW_I_OPT_ID-1 "ICR0023"
*HW_I_OPT_ID-2 "ISL0021"
*HW_I_OPT_ID-3 "ISO0021"
*HW_I_OPT_ID-4 "IAD0021"
*HW_I_OPT_ID-5 "IPR0001"
*HW_I_OPT_NAME-0 "CBOユニット|CBO unit"
*HW_I_OPT_NAME-1 "標準入射光学ユニット|Standard incident optical unit"
*HW_I_OPT_NAME-2 "標準入射スリットボックス|Standard incident slit box"
*HW_I_OPT_NAME-3 "入射平行スリット|Incident parallel slit"
*HW_I_OPT_NAME-4 "長手制限スリット|Length limiting slit"
*HW_I_OPT_NAME-5 "None|None"
*HW_R_ATTENUATER_AUTOMODE "0"
*HW_R_OPT_ID-0 "RSS0021"
*HW_R_OPT_ID-1 "RCR0023"
*HW_R_OPT_ID-2 "RSO0021"
*HW_R_OPT_ID-3 "RRS0021"
*HW_R_OPT_ID-4 "ATN0021"
*HW_R_OPT_ID-5 "RFL0021"
*HW_R_OPT_ID-6 "RAD0021"
*HW_R_OPT_NAME-0 "標準受光スリットボックス1|Standard receiving slit box # 1"
*HW_R_OPT_NAME-1 "標準受光光学ユニット1|Standard receiving unit # 1"
*HW_R_OPT_NAME-2 "標準受光光学ユニット2|Standard receiving optical unit # 2"
*HW_R_OPT_NAME-3 "標準受光スリットボックス2|Standard receiving slit box # 2"
*HW_R_OPT_NAME-4 "標準アッテネータ|Standard Attenuator"
*HW_R_OPT_NAME-5 "Cu Kβ|Cu K-beta"
*HW_R_OPT_NAME-6 "調整用受光スリット|Alignment receiving slit"
*HW_SAMPLE_HOLDER_ID "SMP0023"
*HW_SAMPLE_HOLDER_NAME "標準Zステージ|Standard Z stage"
*HW_XG_CURRENT_MAX "50"
*HW_XG_CURRENT_MIN "2"
*HW_XG_CURRENT_RESOLUTION "1"
*HW_XG_CURRENT_UNIT "mA"
*HW_XG_FOCUS "1mm x 10mm"
*HW_XG_FOCUS_TYPE "Normal"
*HW_XG_ID ""
*HW_XG_NAME "3kW 封入管(ID:1200)|3kW Sealed tube(ID:1200)"
*HW_XG_TARGET_ATOMIC_NUMBER "29.0000000000"
*HW_XG_TARGET_NAME "Cu"
*HW_XG_TYPE "Hermetic"
*HW_XG_VOLTAGE_MAX "60"
*HW_XG_VOLTAGE_MIN "20"
*HW_XG_VOLTAGE_RESOLUTION "1"
*HW_XG_VOLTAGE_UNIT "kV"
*HW_XG_WATT_MAX "1.500"
*HW_XG_WATT_UNIT "kW"
*HW_XG_WAVE_LENGTH_ALPHA1 "1.540593"
*HW_XG_WAVE_LENGTH_ALPHA2 "1.544414"
*HW_XG_WAVE_LENGTH_BETA "1.392250"
*MEAS_COND_AXIS_NAME-0 "2θ/θ"
*MEAS_COND_AXIS_NAME-1 "2θ"
*MEAS_COND_AXIS_NAME-2 "ω"
*MEAS_COND_AXIS_NAME-3 "Z"
*MEAS_COND_AXIS_NAME-4 "2θ/ω"
*MEAS_COND_AXIS_NAME-5 "θs"
*MEAS_COND_AXIS_NAME-6 "θd"
*MEAS_COND_AXIS_NAME-7 "Ts"
*MEAS_COND_AXIS_NAME-8 "CBO選択スリット"
*MEAS_COND_AXIS_NAME-9 "M"
*MEAS_COND_AXIS_NAME-10 "入射平行スリット"
*MEAS_COND_AXIS_NAME-11 "入射スリット"
*MEAS_COND_AXIS_NAME-12 ""
*MEAS_COND_AXIS_NAME-13 "Zs"
*MEAS_COND_AXIS_NAME-14 "入射光学素子"
*MEAS_COND_AXIS_NAME-15 "長手制限スリット"
*MEAS_COND_AXIS_NAME-16 "センタースリット"
*MEAS_COND_AXIS_NAME-17 "フィルター"
*MEAS_COND_AXIS_NAME-18 "受光スリット1"
*MEAS_COND_AXIS_NAME-19 "受光スリット2"
*MEAS_COND_AXIS_NAME-20 "受光光学素子"
*MEAS_COND_AXIS_NAME-21 "受光平行スリット"
*MEAS_COND_AXIS_NAME-22 "調整用受光スリット"
*MEAS_COND_AXIS_NAME-23 ""
*MEAS_COND_AXIS_NAME-24 ""
*MEAS_COND_AXIS_NAME-25 "Zd"
*MEAS_COND_AXIS_NAME-26 "アッテネータ"
*MEAS_COND_AXIS_NAME-27 "検出器モノクロメータ"
*MEAS_COND_AXIS_NAME-28 "モノクロメータスリット"
*MEAS_COND_AXIS_NAME-29 "プライマリビーム"
*MEAS_COND_AXIS_NAME-30 "PHA"
*MEAS_COND_AXIS_NAME_INTERNAL-0 "TwoThetaTheta"
*MEAS_COND_AXIS_NAME_INTERNAL-1 "TwoTheta"
*MEAS_COND_AXIS_NAME_INTERNAL-2 "Omega"
*MEAS_COND_AXIS_NAME_INTERNAL-3 "Z"
*MEAS_COND_AXIS_NAME_INTERNAL-4 "TwoThetaOmega"
*MEAS_COND_AXIS_NAME_INTERNAL-5 "ThetaS"
*MEAS_COND_AXIS_NAME_INTERNAL-6 "ThetaD"
*MEAS_COND_AXIS_NAME_INTERNAL-7 "Ts"
*MEAS_COND_AXIS_NAME_INTERNAL-8 "CBO"
*MEAS_COND_AXIS_NAME_INTERNAL-9 "CBO-M"
*MEAS_COND_AXIS_NAME_INTERNAL-10 "IncidentSollerSlit"
*MEAS_COND_AXIS_NAME_INTERNAL-11 "IncidentSlitBox"
*MEAS_COND_AXIS_NAME_INTERNAL-12 "IncidentSlitBox-_Axis"
*MEAS_COND_AXIS_NAME_INTERNAL-13 "Zs"
*MEAS_COND_AXIS_NAME_INTERNAL-14 "IncidentMonochromator"
*MEAS_COND_AXIS_NAME_INTERNAL-15 "IncidentAxdSlit"
*MEAS_COND_AXIS_NAME_INTERNAL-16 "CenterSlit"
*MEAS_COND_AXIS_NAME_INTERNAL-17 "Filter"
*MEAS_COND_AXIS_NAME_INTERNAL-18 "ReceivingSlitBox1"
*MEAS_COND_AXIS_NAME_INTERNAL-19 "ReceivingSlitBox2"
*MEAS_COND_AXIS_NAME_INTERNAL-20 "ReceivingOptics"
*MEAS_COND_AXIS_NAME_INTERNAL-21 "ReceivingSollerSlit"
*MEAS_COND_AXIS_NAME_INTERNAL-22 "ReceivingAxdSlit"
*MEAS_COND_AXIS_NAME_INTERNAL-23 "ReceivingSlitBox1-_Axis"
*MEAS_COND_AXIS_NAME_INTERNAL-24 "ReceivingSlitBox2-_Axis"
*MEAS_COND_AXIS_NAME_INTERNAL-25 "ReceivingSlitBox2-Zd"
*MEAS_COND_AXIS_NAME_INTERNAL-26 "Attenuator"
*MEAS_COND_AXIS_NAME_INTERNAL-27 "CounterMonochromator"
*MEAS_COND_AXIS_NAME_INTERNAL-28 "CounterSlit"
*MEAS_COND_AXIS_NAME_INTERNAL-29 "IncidentPrimary"
*MEAS_COND_AXIS_NAME_INTERNAL-30 "PHA"
*MEAS_COND_AXIS_NAME_MAGICNO-0 "83951616.0000000000"
*MEAS_COND_AXIS_NAME_MAGICNO-1 "268632064.0000000000"
*MEAS_COND_AXIS_NAME_MAGICNO-2 "268500992.0000000000"
*MEAS_COND_AXIS_NAME_MAGICNO-3 "285278208.0000000000"
*MEAS_COND_AXIS_NAME_MAGICNO-4 "83951616.0000000000"
*MEAS_COND_AXIS_NAME_MAGICNO-5 "131072.0000000000"
*MEAS_COND_AXIS_NAME_MAGICNO-6 "131072.0000000000"
*MEAS_COND_AXIS_NAME_MAGICNO-7 "318898176.0000000000"
*MEAS_COND_AXIS_NAME_MAGICNO-8 "20971521.0000000000"
*MEAS_COND_AXIS_NAME_MAGICNO-9 "285343744.0000000000"
*MEAS_COND_AXIS_NAME_MAGICNO-10 "20971521.0000000000"
*MEAS_COND_AXIS_NAME_MAGICNO-11 "22020097.0000000000"
*MEAS_COND_AXIS_NAME_MAGICNO-12 "25165824.0000000000"
*MEAS_COND_AXIS_NAME_MAGICNO-13 "318898176.0000000000"
*MEAS_COND_AXIS_NAME_MAGICNO-14 "1.0000000000"
*MEAS_COND_AXIS_NAME_MAGICNO-15 "20971521.0000000000"
*MEAS_COND_AXIS_NAME_MAGICNO-16 "20971521.0000000000"
*MEAS_COND_AXIS_NAME_MAGICNO-17 "20971521.0000000000"
*MEAS_COND_AXIS_NAME_MAGICNO-18 "23068673.0000000000"
*MEAS_COND_AXIS_NAME_MAGICNO-19 "23068673.0000000000"
*MEAS_COND_AXIS_NAME_MAGICNO-20 "20971521.0000000000"
*MEAS_COND_AXIS_NAME_MAGICNO-21 "20971521.0000000000"
*MEAS_COND_AXIS_NAME_MAGICNO-22 "20971521.0000000000"
*MEAS_COND_AXIS_NAME_MAGICNO-23 "25165824.0000000000"
*MEAS_COND_AXIS_NAME_MAGICNO-24 "25165824.0000000000"
*MEAS_COND_AXIS_NAME_MAGICNO-25 "285343744.0000000000"
*MEAS_COND_AXIS_NAME_MAGICNO-26 "17301505.0000000000"
*MEAS_COND_AXIS_NAME_MAGICNO-27 "20971521.0000000000"
*MEAS_COND_AXIS_NAME_MAGICNO-28 "20971521.0000000000"
*MEAS_COND_AXIS_NAME_MAGICNO-29 "20971521.0000000000"
*MEAS_COND_AXIS_NAME_MAGICNO-30 "0.0000000000"
*MEAS_COND_AXIS_OFFSET-0 "-"
*MEAS_COND_AXIS_OFFSET-1 "-0.1081000000"
*MEAS_COND_AXIS_OFFSET-2 "0.3758000000"
*MEAS_COND_AXIS_OFFSET-3 "-"
*MEAS_COND_AXIS_OFFSET-4 "-"
*MEAS_COND_AXIS_OFFSET-5 "0.3758000000"
*MEAS_COND_AXIS_OFFSET-6 "-0.4839000000"
*MEAS_COND_AXIS_OFFSET-7 "-"
*MEAS_COND_AXIS_OFFSET-8 "-"
*MEAS_COND_AXIS_OFFSET-9 "-"
*MEAS_COND_AXIS_OFFSET-10 "-"
*MEAS_COND_AXIS_OFFSET-11 "-"
*MEAS_COND_AXIS_OFFSET-12 "-"
*MEAS_COND_AXIS_OFFSET-13 "-"
*MEAS_COND_AXIS_OFFSET-14 "-"
*MEAS_COND_AXIS_OFFSET-15 "-"
*MEAS_COND_AXIS_OFFSET-16 "-"
*MEAS_COND_AXIS_OFFSET-17 "-"
*MEAS_COND_AXIS_OFFSET-18 "-"
*MEAS_COND_AXIS_OFFSET-19 "-"
*MEAS_COND_AXIS_OFFSET-20 "-"
*MEAS_COND_AXIS_OFFSET-21 "-"
*MEAS_COND_AXIS_OFFSET-22 "-"
*MEAS_COND_AXIS_OFFSET-23 "-"
*MEAS_COND_AXIS_OFFSET-24 "-"
*MEAS_COND_AXIS_OFFSET-25 "-"
*MEAS_COND_AXIS_OFFSET-26 "-"
*MEAS_COND_AXIS_OFFSET-27 "-"
*MEAS_COND_AXIS_OFFSET-28 "-"
*MEAS_COND_AXIS_OFFSET-29 "-"
*MEAS_COND_AXIS_OFFSET-30 "-"
*MEAS_COND_AXIS_POSITION-0 "0.0000000000"
*MEAS_COND_AXIS_POSITION-1 "0.0000000000"
*MEAS_COND_AXIS_POSITION-2 "0.0000000000"
*MEAS_COND_AXIS_POSITION-3 "-0.5500000000"
*MEAS_COND_AXIS_POSITION-4 "0.0000000000"
*MEAS_COND_AXIS_POSITION-5 "0.0000000000"
*MEAS_COND_AXIS_POSITION-6 "0.0000000000"
*MEAS_COND_AXIS_POSITION-7 "-0.4278800000"
*MEAS_COND_AXIS_POSITION-8 "BB"
*MEAS_COND_AXIS_POSITION-9 "0.0000000000"
*MEAS_COND_AXIS_POSITION-10 "Soller_slit_5.0deg"
*MEAS_COND_AXIS_POSITION-11 "2/3deg"
*MEAS_COND_AXIS_POSITION-12 "2.2088000000"
*MEAS_COND_AXIS_POSITION-13 "-0.4140600000"
*MEAS_COND_AXIS_POSITION-14 "0.0000000000"
*MEAS_COND_AXIS_POSITION-15 "10.0mm"
*MEAS_COND_AXIS_POSITION-16 "None"
*MEAS_COND_AXIS_POSITION-17 "Cu_K-beta"
*MEAS_COND_AXIS_POSITION-18 "13.000mm"
*MEAS_COND_AXIS_POSITION-19 "13.000mm"
*MEAS_COND_AXIS_POSITION-20 "No_unit"
*MEAS_COND_AXIS_POSITION-21 "Soller_slit_5.0deg"
*MEAS_COND_AXIS_POSITION-22 "None"
*MEAS_COND_AXIS_POSITION-23 "13.0000000000"
*MEAS_COND_AXIS_POSITION-24 "13.0000000000"
*MEAS_COND_AXIS_POSITION-25 "0.0109400000"
*MEAS_COND_AXIS_POSITION-26 "Open"
*MEAS_COND_AXIS_POSITION-27 "None"
*MEAS_COND_AXIS_POSITION-28 "None"
*MEAS_COND_AXIS_POSITION-29 "None"
*MEAS_COND_AXIS_POSITION-30 "38.0000000000"
*MEAS_COND_AXIS_UNIT-0 "deg"
*MEAS_COND_AXIS_UNIT-1 "deg"
*MEAS_COND_AXIS_UNIT-2 "deg"
*MEAS_COND_AXIS_UNIT-3 "mm"
*MEAS_COND_AXIS_UNIT-4 "deg"
*MEAS_COND_AXIS_UNIT-5 "deg"
*MEAS_COND_AXIS_UNIT-6 "deg"
*MEAS_COND_AXIS_UNIT-7 "mm"
*MEAS_COND_AXIS_UNIT-8 ""
*MEAS_COND_AXIS_UNIT-9 "pulse"
*MEAS_COND_AXIS_UNIT-10 ""
*MEAS_COND_AXIS_UNIT-11 ""
*MEAS_COND_AXIS_UNIT-12 "mm"
*MEAS_COND_AXIS_UNIT-13 "mm"
*MEAS_COND_AXIS_UNIT-14 ""
*MEAS_COND_AXIS_UNIT-15 ""
*MEAS_COND_AXIS_UNIT-16 ""
*MEAS_COND_AXIS_UNIT-17 ""
*MEAS_COND_AXIS_UNIT-18 ""
*MEAS_COND_AXIS_UNIT-19 ""
*MEAS_COND_AXIS_UNIT-20 ""
*MEAS_COND_AXIS_UNIT-21 ""
*MEAS_COND_AXIS_UNIT-22 ""
*MEAS_COND_AXIS_UNIT-23 "mm"
*MEAS_COND_AXIS_UNIT-24 "mm"
*MEAS_COND_AXIS_UNIT-25 "mm"
*MEAS_COND_AXIS_UNIT-26 ""
*MEAS_COND_AXIS_UNIT-27 ""
*MEAS_COND_AXIS_UNIT-28 ""
*MEAS_COND_AXIS_UNIT-29 ""
*MEAS_COND_AXIS_UNIT-30 "div"
*MEAS_COND_COUNTER_CNTLOSS_CORR "0.0000000000"
*MEAS_COND_COUNTER_PHABASE "38.0000000000"
*MEAS_COND_COUNTER_PHAWINDOW "16.0000000000"
*MEAS_COND_COUNTER_PHA_UNIT "div"
*MEAS_COND_COUNTER_TAUDIFF "30.0000000000"
*MEAS_COND_COUNTER_TAUINT "0.0000000000"
*MEAS_COND_IRRADIATION_MODE "OFF"
*MEAS_COND_IRRADIATION_WIDTH ""
*MEAS_COND_OPT_ATTR "集中法"
*MEAS_COND_OPT_NAME "@集中法"
*MEAS_COND_UNSYMMETRIC_MODE "OFF"
*MEAS_COND_XG_CURRENT "30.0000000000"
*MEAS_COND_XG_VOLTAGE "40.0000000000"
*MEAS_COND_XG_WAVE_TYPE "Ka"
*MEAS_DATA_COUNT "5001.0000000000"
*MEAS_SCAN_AXIS_X "2θ/θ"
*MEAS_SCAN_AXIS_X_INTERNAL "TwoThetaTheta"
*MEAS_SCAN_END_TIME "06/24/21 18:23:21"
*MEAS_SCAN_MODE "CONTINUOUS"
*MEAS_SCAN_MONITOR "0"
*MEAS_SCAN_RESOLUTION_X "0.0002"
*MEAS_SCAN_SPEED "1.0"
*MEAS_SCAN_SPEED_UNIT "deg/min"
*MEAS_SCAN_START "20.0000000000"
*MEAS_SCAN_START_TIME "06/24/21 17:30:27"
*MEAS_SCAN_STEP "0.0100000000"
*MEAS_SCAN_STOP "70.0000000000"
*MEAS_SCAN_UNIT_X "deg"
*MEAS_SCAN_UNIT_Y "counts"
*RAS_HEADER_END
*RAS_INT_START
20.0000 1542.0000 1.0000
20.0400 1535.0000 1.0000
20.0800 1541.0000 1.0000
20.1200 1568.0000 1.0000
20.1600 1588.0000 1.0000
20.2000 1605.0000 1.0000
20.2400 1532.0000 1.0000
20.2800 1575.0000 1.0000
20.3200 1553.0000 1.0000
20.3600 1584.0000 1.0000
20.4000 1568.0000 1.0000
20.4400 1566.0000 1.0000
20.4800 1499.0000 1.0000
20.5200 1569.0000 1.0000
20.5600 1580.0000 1.0000
20.6000 1566.0000 1.0000
20.6400 1561.0000 1.0000
20.6800 1578.0000 1.0000
20.7200 1507.0000 1.0000
20.7600 1597.0000 1.0000
20.8000 1577.0000 1.0000
20.8400 1550.0000 1.0000
20.8800 1487.0000 1.0000
20.9200 1542.0000 1.0000
20.9600 1534.0000 1.0000
21.0000 1558.0000 1.0000
21.0400 1559.0000 1.0000
21.0800 1579.0000 1.0000
21.1200 1561.0000 1.0000
21.1600 1556.0000 1.0000
21.2000 1557.0000 1.0000
21.2400 1543.0000 1.0000
21.2800 1559.0000 1.0000
21.3200 1550.0000 1.0000
21.3600 1528.0000 1.0000
21.4000 1589.0000 1.0000
21.4400 1599.0000 1.0000
21.4800 1597.0000 1.0000
21.5200 1605.0000 1.0000
21.5600 1587.0000 1.0000
21.6000 1602.0000 1.0000
21.6400 1580.0000 1.0000
21.6800 1517.0000 1.0000
21.7200 1615.0000 1.0000
21.7600 1623.0000 1.0000
21.8000 1512.0000 1.0000
21.8400 1559.0000 1.0000
21.8800 1558.0000 1.0000
21.9200 1579.0000 1.0000
21.9600 1550.0000 1.0000
22.0000 1677.0000 1.0000
22.0400 1552.0000 1.0000
22.0800 1637.0000 1.0000
22.1200 1609.0000 1.0000
22.1600 1600.0000 1.0000
22.2000 1628.0000 1.0000
22.2400 1588.0000 1.0000
22.2800 1634.0000 1.0000
22.3200 1617.0000 1.0000
22.3600 1629.0000 1.0000
22.4000 1644.0000 1.0000
22.4400 1606.0000 1.0000
22.4800 1633.0000 1.0000
22.5200 1631.0000 1.0000
22.5600 1556.0000 1.0000
22.6000 1607.0000 1.0000
22.6400 1634.0000 1.0000
22.6800 1542.0000 1.0000
22.7200 1622.0000 1.0000
22.7600 1630.0000 1.0000
22.8000 1606.0000 1.0000
22.8400 1667.0000 1.0000
22.8800 1603.0000 1.0000
22.9200 1645.0000 1.0000
22.9600 1622.0000 1.0000
23.0000 1630.0000 1.0000
23.0400 1630.0000 1.0000
23.0800 1635.0000 1.0000
23.1200 1642.0000 1.0000
23.1600 1604.0000 1.0000
23.2000 1609.0000 1.0000
23.2400 1600.0000 1.0000
23.2800 1659.0000 1.0000
23.3200 1733.0000 1.0000
23.3600 1615.0000 1.0000
23.4000 1691.0000 1.0000
23.4400 1610.0000 1.0000
23.4800 1553.0000 1.0000
23.5200 1611.0000 1.0000
23.5600 1685.0000 1.0000
23.6000 1591.0000 1.0000
23.6400 1632.0000 1.0000
23.6800 1639.0000 1.0000
23.7200 1615.0000 1.0000
23.7600 1689.0000 1.0000
23.8000 1600.0000 1.0000
23.8400 1603.0000 1.0000
23.8800 1657.0000 1.0000
23.9200 1615.0000 1.0000
23.9600 1635.0000 1.0000
24.0000 1704.0000 1.0000
24.0400 1645.0000 1.0000
24.0800 1603.0000 1.0000
24.1200 1645.0000 1.0000
24.1600 1683.0000 1.0000
24.2000 1690.0000 1.0000
24.2400 1701.0000 1.0000
24.2800 1697.0000 1.0000
24.3200 1642.0000 1.0000
24.3600 1674.0000 1.0000
24.4000 1593.0000 1.0000
24.4400 1666.0000 1.0000
24.4800 1638.0000 1.0000
24.5200 1666.0000 1.0000
24.5600 1668.0000 1.0000
24.6000 1685.0000 1.0000
24.6400 1747.0000 1.0000
24.6800 1698.0000 1.0000
24.7200 1682.0000 1.0000
24.7600 1750.0000 1.0000
24.8000 1711.0000 1.0000
24.8400 1716.0000 1.0000
24.8800 1749.0000 1.0000
24.9200 1788.0000 1.0000
24.9600 1693.0000 1.0000
25.0000 1767.0000 1.0000
25.0400 1762.0000 1.0000
25.0800 1722.0000 1.0000
25.1200 1730.0000 1.0000
25.1600 1724.0000 1.0000
25.2000 1716.0000 1.0000
25.2400 1726.0000 1.0000
25.2800 1727.0000 1.0000
25.3200 1730.0000 1.0000
25.3600 1684.0000 1.0000
25.4000 1729.0000 1.0000
25.4400 1747.0000 1.0000
25.4800 1710.0000 1.0000
25.5200 1741.0000 1.0000
25.5600 1685.0000 1.0000
25.6000 1702.0000 1.0000
25.6400 1757.0000 1.0000
25.6800 1686.0000 1.0000
25.7200 1666.0000 1.0000
25.7600 1687.0000 1.0000
25.8000 1699.0000 1.0000
25.8400 1669.0000 1.0000
25.8800 1710.0000 1.0000
25.9200 1698.0000 1.0000
25.9600 1702.0000 1.0000
26.0000 1672.0000 1.0000
26.0400 1673.0000 1.0000
26.0800 1777.0000 1.0000
26.1200 1723.0000 1.0000
26.1600 1751.0000 1.0000
26.2000 1739.0000 1.0000
26.2400 1739.0000 1.0000
26.2800 1744.0000 1.0000
26.3200 1751.0000 1.0000
26.3600 1758.0000 1.0000
26.4000 1820.0000 1.0000
26.4400 1751.0000 1.0000
26.4800 1826.0000 1.0000
26.5200 1730.0000 1.0000
26.5600 1801.0000 1.0000
26.6000 1824.0000 1.0000
26.6400 1796.0000 1.0000
26.6800 1747.0000 1.0000
26.7200 1817.0000 1.0000
26.7600 1832.0000 1.0000
26.8000 1903.0000 1.0000
26.8400 1967.0000 1.0000
26.8800 2013.0000 1.0000
26.9200 2089.0000 1.0000
26.9600 2194.0000 1.0000
27.0000 2378.0000 1.0000
27.0400 2482.0000 1.0000
27.0800 2730.0000 1.0000
27.1200 3199.0000 1.0000
27.1600 3726.0000 1.0000
27.2000 4638.0000 1.0000
27.2400 5587.0000 1.0000
27.2800 6568.0000 1.0000
27.3200 6755.0000 1.0000
27.3600 6162.0000 1.0000
27.4000 5117.0000 1.0000
27.4400 4036.0000 1.0000
27.4800 3416.0000 1.0000
27.5200 2935.0000 1.0000
27.5600 2624.0000 1.0000
27.6000 2338.0000 1.0000
27.6400 2122.0000 1.0000
27.6800 2104.0000 1.0000
27.7200 1975.0000 1.0000
27.7600 1916.0000 1.0000
27.8000 1913.0000 1.0000
27.8400 1896.0000 1.0000
27.8800 1771.0000 1.0000
27.9200 1758.0000 1.0000
27.9600 1740.0000 1.0000
28.0000 1769.0000 1.0000
28.0400 1724.0000 1.0000
28.0800 1738.0000 1.0000
28.1200 1725.0000 1.0000
28.1600 1678.0000 1.0000
28.2000 1729.0000 1.0000
28.2400 1656.0000 1.0000
28.2800 1628.0000 1.0000
28.3200 1729.0000 1.0000
28.3600 1594.0000 1.0000
28.4000 1685.0000 1.0000
28.4400 1652.0000 1.0000
28.4800 1592.0000 1.0000
28.5200 1658.0000 1.0000
28.5600 1637.0000 1.0000
28.6000 1595.0000 1.0000
28.6400 1564.0000 1.0000
28.6800 1638.0000 1.0000
28.7200 1583.0000 1.0000
28.7600 1608.0000 1.0000
28.8000 1624.0000 1.0000
28.8400 1561.0000 1.0000
28.8800 1542.0000 1.0000
28.9200 1607.0000 1.0000
28.9600 1588.0000 1.0000
29.0000 1581.0000 1.0000
29.0400 1486.0000 1.0000
29.0800 1517.0000 1.0000
29.1200 1530.0000 1.0000
29.1600 1565.0000 1.0000
29.2000 1552.0000 1.0000
29.2400 1567.0000 1.0000
29.2800 1498.0000 1.0000
29.3200 1544.0000 1.0000
29.3600 1575.0000 1.0000
29.4000 1556.0000 1.0000
29.4400 1531.0000 1.0000
29.4800 1550.0000 1.0000
29.5200 1448.0000 1.0000
29.5600 1487.0000 1.0000
29.6000 1595.0000 1.0000
29.6400 1585.0000 1.0000
29.6800 1518.0000 1.0000
29.7200 1544.0000 1.0000
29.7600 1566.0000 1.0000
29.8000 1531.0000 1.0000
29.8400 1447.0000 1.0000
29.8800 1547.0000 1.0000
29.9200 1469.0000 1.0000
29.9600 1489.0000 1.0000
30.0000 1394.0000 1.0000
30.0400 1511.0000 1.0000
30.0800 1543.0000 1.0000
30.1200 1465.0000 1.0000
30.1600 1488.0000 1.0000
30.2000 1458.0000 1.0000
30.2400 1438.0000 1.0000
30.2800 1488.0000 1.0000
30.3200 1455.0000 1.0000
30.3600 1495.0000 1.0000
30.4000 1448.0000 1.0000
30.4400 1453.0000 1.0000
30.4800 1463.0000 1.0000
30.5200 1435.0000 1.0000
30.5600 1456.0000 1.0000
30.6000 1521.0000 1.0000
30.6400 1403.0000 1.0000
30.6800 1485.0000 1.0000
30.7200 1493.0000 1.0000
30.7600 1507.0000 1.0000
30.8000 1456.0000 1.0000
30.8400 1388.0000 1.0000
30.8800 1534.0000 1.0000
30.9200 1478.0000 1.0000
30.9600 1503.0000 1.0000
31.0000 1445.0000 1.0000
31.0400 1469.0000 1.0000
31.0800 1416.0000 1.0000
31.1200 1444.0000 1.0000
31.1600 1466.0000 1.0000
31.2000 1459.0000 1.0000
31.2400 1477.0000 1.0000
31.2800 1455.0000 1.0000
31.3200 1408.0000 1.0000
31.3600 1407.0000 1.0000
31.4000 1413.0000 1.0000
31.4400 1450.0000 1.0000
31.4800 1428.0000 1.0000
31.5200 1377.0000 1.0000
31.5600 1410.0000 1.0000
31.6000 1384.0000 1.0000
31.6400 1379.0000 1.0000
31.6800 1445.0000 1.0000
31.7200 1435.0000 1.0000
31.7600 1376.0000 1.0000
31.8000 1356.0000 1.0000
31.8400 1442.0000 1.0000
31.8800 1399.0000 1.0000
31.9200 1453.0000 1.0000
31.9600 1361.0000 1.0000
32.0000 1408.0000 1.0000
32.0400 1436.0000 1.0000
32.0800 1432.0000 1.0000
32.1200 1371.0000 1.0000
32.1600 1394.0000 1.0000
32.2000 1347.0000 1.0000
32.2400 1353.0000 1.0000
32.2800 1342.0000 1.0000
32.3200 1398.0000 1.0000
32.3600 1348.0000 1.0000
32.4000 1386.0000 1.0000
32.4400 1344.0000 1.0000
32.4800 1398.0000 1.0000
32.5200 1298.0000 1.0000
32.5600 1328.0000 1.0000
32.6000 1316.0000 1.0000
32.6400 1331.0000 1.0000
32.6800 1392.0000 1.0000
32.7200 1368.0000 1.0000
32.7600 1327.0000 1.0000
32.8000 1342.0000 1.0000
32.8400 1311.0000 1.0000
32.8800 1384.0000 1.0000
32.9200 1340.0000 1.0000
32.9600 1352.0000 1.0000
33.0000 1364.0000 1.0000
33.0400 1331.0000 1.0000
33.0800 1286.0000 1.0000
33.1200 1274.0000 1.0000
33.1600 1322.0000 1.0000
33.2000 1337.0000 1.0000
33.2400 1337.0000 1.0000
33.2800 1342.0000 1.0000
33.3200 1322.0000 1.0000
33.3600 1303.0000 1.0000
33.4000 1284.0000 1.0000
33.4400 1344.0000 1.0000
33.4800 1267.0000 1.0000
33.5200 1311.0000 1.0000
33.5600 1333.0000 1.0000
33.6000 1337.0000 1.0000
33.6400 1302.0000 1.0000
33.6800 1352.0000 1.0000
33.7200 1378.0000 1.0000
33.7600 1363.0000 1.0000
33.8000 1405.0000 1.0000
33.8400 1443.0000 1.0000
33.8800 1447.0000 1.0000
33.9200 1555.0000 1.0000
33.9600 1496.0000 1.0000
34.0000 1552.0000 1.0000
34.0400 1540.0000 1.0000
34.0800 1530.0000 1.0000
34.1200 1528.0000 1.0000
34.1600 1600.0000 1.0000
34.2000 1507.0000 1.0000
34.2400 1607.0000 1.0000
34.2800 1790.0000 1.0000
34.3200 1814.0000 1.0000
34.3600 2095.0000 1.0000
34.4000 2497.0000 1.0000
34.4400 2951.0000 1.0000
34.4800 3276.0000 1.0000
34.5200 3484.0000 1.0000
34.5600 3162.0000 1.0000
34.6000 2817.0000 1.0000
34.6400 2333.0000 1.0000
34.6800 2072.0000 1.0000
34.7200 1815.0000 1.0000
34.7600 1643.0000 1.0000
34.8000 1597.0000 1.0000
34.8400 1497.0000 1.0000
34.8800 1439.0000 1.0000
34.9200 1400.0000 1.0000
34.9600 1372.0000 1.0000
35.0000 1289.0000 1.0000
35.0400 1223.0000 1.0000
35.0800 1239.0000 1.0000
35.1200 1245.0000 1.0000
35.1600 1185.0000 1.0000
35.2000 1212.0000 1.0000
35.2400 1220.0000 1.0000
35.2800 1223.0000 1.0000
35.3200 1210.0000 1.0000
35.3600 1202.0000 1.0000
35.4000 1214.0000 1.0000
35.4400 1163.0000 1.0000
35.4800 1165.0000 1.0000
35.5200 1176.0000 1.0000
35.5600 1121.0000 1.0000
35.6000 1188.0000 1.0000
35.6400 1135.0000 1.0000
35.6800 1131.0000 1.0000
35.7200 1138.0000 1.0000
35.7600 1189.0000 1.0000
35.8000 1187.0000 1.0000
35.8400 1202.0000 1.0000
35.8800 1109.0000 1.0000
35.9200 1162.0000 1.0000
35.9600 1140.0000 1.0000
36.0000 1128.0000 1.0000
36.0400 1190.0000 1.0000
36.0800 1164.0000 1.0000
36.1200 1179.0000 1.0000
36.1600 1183.0000 1.0000
36.2000 1228.0000 1.0000
36.2400 1204.0000 1.0000
36.2800 1370.0000 1.0000
36.3200 1475.0000 1.0000
36.3600 1739.0000 1.0000
36.4000 2039.0000 1.0000
36.4400 1949.0000 1.0000
36.4800 1777.0000 1.0000
36.5200 1573.0000 1.0000
36.5600 1439.0000 1.0000
36.6000 1215.0000 1.0000
36.6400 1131.0000 1.0000
36.6800 1081.0000 1.0000
36.7200 1120.0000 1.0000
36.7600 1105.0000 1.0000
36.8000 1073.0000 1.0000
36.8400 1078.0000 1.0000
36.8800 1076.0000 1.0000
36.9200 1061.0000 1.0000
36.9600 1021.0000 1.0000
37.0000 1083.0000 1.0000
37.0400 1050.0000 1.0000
37.0800 1035.0000 1.0000
37.1200 1000.0000 1.0000
37.1600 1078.0000 1.0000
37.2000 1016.0000 1.0000
37.2400 1044.0000 1.0000
37.2800 1069.0000 1.0000
37.3200 1001.0000 1.0000
37.3600 1022.0000 1.0000
37.4000 1099.0000 1.0000
37.4400 1063.0000 1.0000
37.4800 1015.0000 1.0000
37.5200 1015.0000 1.0000
37.5600 1115.0000 1.0000
37.6000 1020.0000 1.0000
37.6400 1067.0000 1.0000
37.6800 1046.0000 1.0000
37.7200 988.0000 1.0000
37.7600 1077.0000 1.0000
37.8000 1064.0000 1.0000
37.8400 1088.0000 1.0000
37.8800 1071.0000 1.0000
37.9200 1066.0000 1.0000
37.9600 1077.0000 1.0000
38.0000 1116.0000 1.0000
38.0400 1153.0000 1.0000
38.0800 1161.0000 1.0000
38.1200 1234.0000 1.0000
38.1600 1307.0000 1.0000
38.2000 1517.0000 1.0000
38.2400 1449.0000 1.0000
38.2800 1704.0000 1.0000
38.3200 2075.0000 1.0000
38.3600 2456.0000 1.0000
38.4000 3109.0000 1.0000
38.4400 4207.0000 1.0000
38.4800 5392.0000 1.0000
38.5200 6426.0000 1.0000
38.5600 6470.0000 1.0000
38.6000 5961.0000 1.0000
38.6400 5056.0000 1.0000
38.6800 4024.0000 1.0000
38.7200 3027.0000 1.0000
38.7600 2446.0000 1.0000
38.8000 2030.0000 1.0000
38.8400 1673.0000 1.0000
38.8800 1413.0000 1.0000
38.9200 1307.0000 1.0000
38.9600 1211.0000 1.0000
39.0000 1097.0000 1.0000
39.0400 1075.0000 1.0000
39.0800 1038.0000 1.0000
39.1200 1069.0000 1.0000
39.1600 1014.0000 1.0000
39.2000 989.0000 1.0000
39.2400 1002.0000 1.0000
39.2800 942.0000 1.0000
39.3200 945.0000 1.0000
39.3600 939.0000 1.0000
39.4000 943.0000 1.0000
39.4400 1016.0000 1.0000
39.4800 1003.0000 1.0000
39.5200 1015.0000 1.0000
39.5600 993.0000 1.0000
39.6000 981.0000 1.0000
39.6400 958.0000 1.0000
39.6800 1021.0000 1.0000
39.7200 967.0000 1.0000
39.7600 924.0000 1.0000
39.8000 945.0000 1.0000
39.8400 938.0000 1.0000
39.8800 937.0000 1.0000
39.9200 943.0000 1.0000
39.9600 943.0000 1.0000
40.0000 899.0000 1.0000
40.0400 932.0000 1.0000
40.0800 911.0000 1.0000
40.1200 925.0000 1.0000
40.1600 905.0000 1.0000
40.2000 909.0000 1.0000
40.2400 913.0000 1.0000
40.2800 893.0000 1.0000
40.3200 889.0000 1.0000
40.3600 851.0000 1.0000
40.4000 882.0000 1.0000
40.4400 855.0000 1.0000
40.4800 942.0000 1.0000
40.5200 836.0000 1.0000
40.5600 882.0000 1.0000
40.6000 876.0000 1.0000
40.6400 890.0000 1.0000
40.6800 893.0000 1.0000
40.7200 866.0000 1.0000
40.7600 854.0000 1.0000
40.8000 901.0000 1.0000
40.8400 907.0000 1.0000
40.8800 857.0000 1.0000
40.9200 901.0000 1.0000
40.9600 834.0000 1.0000
41.0000 869.0000 1.0000
41.0400 892.0000 1.0000
41.0800 864.0000 1.0000
41.1200 842.0000 1.0000
41.1600 869.0000 1.0000
41.2000 860.0000 1.0000
41.2400 873.0000 1.0000
41.2800 861.0000 1.0000
41.3200 837.0000 1.0000
41.3600 843.0000 1.0000
41.4000 884.0000 1.0000
41.4400 910.0000 1.0000
41.4800 873.0000 1.0000
41.5200 800.0000 1.0000
41.5600 844.0000 1.0000
41.6000 859.0000 1.0000
41.6400 842.0000 1.0000
41.6800 879.0000 1.0000
41.7200 870.0000 1.0000
41.7600 861.0000 1.0000
41.8000 878.0000 1.0000
41.8400 868.0000 1.0000
41.8800 840.0000 1.0000
41.9200 865.0000 1.0000
41.9600 835.0000 1.0000
42.0000 847.0000 1.0000
42.0400 829.0000 1.0000
42.0800 854.0000 1.0000
42.1200 834.0000 1.0000
42.1600 841.0000 1.0000
42.2000 830.0000 1.0000
42.2400 846.0000 1.0000
42.2800 828.0000 1.0000
42.3200 800.0000 1.0000
42.3600 855.0000 1.0000
42.4000 822.0000 1.0000
42.4400 861.0000 1.0000
42.4800 816.0000 1.0000
42.5200 858.0000 1.0000
42.5600 884.0000 1.0000
42.6000 848.0000 1.0000
42.6400 830.0000 1.0000
42.6800 821.0000 1.0000
42.7200 845.0000 1.0000
42.7600 796.0000 1.0000
42.8000 834.0000 1.0000
42.8400 843.0000 1.0000
42.8800 809.0000 1.0000
42.9200 888.0000 1.0000
42.9600 839.0000 1.0000
43.0000 819.0000 1.0000
43.0400 891.0000 1.0000
43.0800 832.0000 1.0000
43.1200 885.0000 1.0000
43.1600 911.0000 1.0000
43.2000 988.0000 1.0000
43.2400 909.0000 1.0000
43.2800 895.0000 1.0000
43.3200 891.0000 1.0000
43.3600 896.0000 1.0000
43.4000 889.0000 1.0000
43.4400 891.0000 1.0000
43.4800 846.0000 1.0000
43.5200 827.0000 1.0000
43.5600 861.0000 1.0000
43.6000 851.0000 1.0000
43.6400 793.0000 1.0000
43.6800 815.0000 1.0000
43.7200 822.0000 1.0000
43.7600 821.0000 1.0000
43.8000 795.0000 1.0000
43.8400 821.0000 1.0000
43.8800 805.0000 1.0000
43.9200 832.0000 1.0000
43.9600 843.0000 1.0000
44.0000 840.0000 1.0000
44.0400 849.0000 1.0000
44.0800 837.0000 1.0000
44.1200 876.0000 1.0000
44.1600 768.0000 1.0000
44.2000 841.0000 1.0000
44.2400 843.0000 1.0000
44.2800 848.0000 1.0000
44.3200 839.0000 1.0000
44.3600 860.0000 1.0000
44.4000 844.0000 1.0000
44.4400 834.0000 1.0000
44.4800 822.0000 1.0000
44.5200 810.0000 1.0000
44.5600 835.0000 1.0000
44.6000 811.0000 1.0000
44.6400 805.0000 1.0000
44.6800 786.0000 1.0000
44.7200 786.0000 1.0000
44.7600 788.0000 1.0000
44.8000 831.0000 1.0000
44.8400 795.0000 1.0000
44.8800 815.0000 1.0000
44.9200 796.0000 1.0000
44.9600 806.0000 1.0000
45.0000 808.0000 1.0000
45.0400 881.0000 1.0000
45.0800 796.0000 1.0000
45.1200 831.0000 1.0000
45.1600 832.0000 1.0000
45.2000 800.0000 1.0000
45.2400 806.0000 1.0000
45.2800 841.0000 1.0000
45.3200 782.0000 1.0000
45.3600 781.0000 1.0000
45.4000 775.0000 1.0000
45.4400 838.0000 1.0000
45.4800 766.0000 1.0000
45.5200 776.0000 1.0000
45.5600 841.0000 1.0000
45.6000 783.0000 1.0000
45.6400 805.0000 1.0000
45.6800 759.0000 1.0000
45.7200 750.0000 1.0000
45.7600 777.0000 1.0000
45.8000 824.0000 1.0000
45.8400 818.0000 1.0000
45.8800 764.0000 1.0000
45.9200 823.0000 1.0000
45.9600 789.0000 1.0000
46.0000 753.0000 1.0000
46.0400 788.0000 1.0000
46.0800 787.0000 1.0000
46.1200 804.0000 1.0000
46.1600 748.0000 1.0000
46.2000 737.0000 1.0000
46.2400 785.0000 1.0000
46.2800 777.0000 1.0000
46.3200 793.0000 1.0000
46.3600 802.0000 1.0000
46.4000 816.0000 1.0000
46.4400 810.0000 1.0000
46.4800 780.0000 1.0000
46.5200 757.0000 1.0000
46.5600 819.0000 1.0000
46.6000 733.0000 1.0000
46.6400 831.0000 1.0000
46.6800 793.0000 1.0000
46.7200 799.0000 1.0000
46.7600 793.0000 1.0000
46.8000 765.0000 1.0000
46.8400 786.0000 1.0000
46.8800 775.0000 1.0000
46.9200 741.0000 1.0000
46.9600 795.0000 1.0000
47.0000 801.0000 1.0000
47.0400 836.0000 1.0000
47.0800 734.0000 1.0000
47.1200 772.0000 1.0000
47.1600 754.0000 1.0000
47.2000 729.0000 1.0000
47.2400 736.0000 1.0000
47.2800 773.0000 1.0000
47.3200 741.0000 1.0000
47.3600 762.0000 1.0000
47.4000 764.0000 1.0000
47.4400 754.0000 1.0000
47.4800 706.0000 1.0000
47.5200 810.0000 1.0000
47.5600 780.0000 1.0000
47.6000 768.0000 1.0000
47.6400 759.0000 1.0000
47.6800 782.0000 1.0000
47.7200 760.0000 1.0000
47.7600 750.0000 1.0000
47.8000 722.0000 1.0000
47.8400 813.0000 1.0000
47.8800 767.0000 1.0000
47.9200 734.0000 1.0000
47.9600 799.0000 1.0000
48.0000 746.0000 1.0000
48.0400 737.0000 1.0000
48.0800 769.0000 1.0000
48.1200 731.0000 1.0000
48.1600 747.0000 1.0000
48.2000 722.0000 1.0000
48.2400 746.0000 1.0000
48.2800 734.0000 1.0000
48.3200 710.0000 1.0000
48.3600 753.0000 1.0000
48.4000 744.0000 1.0000
48.4400 757.0000 1.0000
48.4800 705.0000 1.0000
48.5200 755.0000 1.0000
48.5600 778.0000 1.0000
48.6000 767.0000 1.0000
48.6400 722.0000 1.0000
48.6800 697.0000 1.0000
48.7200 793.0000 1.0000
48.7600 729.0000 1.0000
48.8000 714.0000 1.0000
48.8400 748.0000 1.0000
48.8800 734.0000 1.0000
48.9200 723.0000 1.0000
48.9600 741.0000 1.0000
49.0000 758.0000 1.0000
49.0400 720.0000 1.0000
49.0800 753.0000 1.0000
49.1200 756.0000 1.0000
49.1600 693.0000 1.0000
49.2000 726.0000 1.0000
49.2400 758.0000 1.0000
49.2800 738.0000 1.0000
49.3200 716.0000 1.0000
49.3600 749.0000 1.0000
49.4000 716.0000 1.0000
49.4400 731.0000 1.0000
49.4800 717.0000 1.0000
49.5200 708.0000 1.0000
49.5600 694.0000 1.0000
49.6000 763.0000 1.0000
49.6400 727.0000 1.0000
49.6800 740.0000 1.0000
49.7200 724.0000 1.0000
49.7600 695.0000 1.0000
49.8000 746.0000 1.0000
49.8400 717.0000 1.0000
49.8800 725.0000 1.0000
49.9200 726.0000 1.0000
49.9600 719.0000 1.0000
50.0000 727.0000 1.0000
50.0400 690.0000 1.0000
50.0800 760.0000 1.0000
50.1200 716.0000 1.0000
50.1600 764.0000 1.0000
50.2000 787.0000 1.0000
50.2400 758.0000 1.0000
50.2800 777.0000 1.0000
50.3200 768.0000 1.0000
50.3600 776.0000 1.0000
50.4000 764.0000 1.0000
50.4400 822.0000 1.0000
50.4800 754.0000 1.0000
50.5200 770.0000 1.0000
50.5600 733.0000 1.0000
50.6000 745.0000 1.0000
50.6400 748.0000 1.0000
50.6800 751.0000 1.0000
50.7200 738.0000 1.0000
50.7600 727.0000 1.0000
50.8000 793.0000 1.0000
50.8400 764.0000 1.0000
50.8800 737.0000 1.0000
50.9200 713.0000 1.0000
50.9600 740.0000 1.0000
51.0000 760.0000 1.0000
51.0400 713.0000 1.0000
51.0800 709.0000 1.0000
51.1200 765.0000 1.0000
51.1600 765.0000 1.0000
51.2000 772.0000 1.0000
51.2400 709.0000 1.0000
51.2800 775.0000 1.0000
51.3200 758.0000 1.0000
51.3600 794.0000 1.0000
51.4000 773.0000 1.0000
51.4400 736.0000 1.0000
51.4800 742.0000 1.0000
51.5200 792.0000 1.0000
51.5600 742.0000 1.0000
51.6000 781.0000 1.0000
51.6400 775.0000 1.0000
51.6800 782.0000 1.0000
51.7200 781.0000 1.0000
51.7600 786.0000 1.0000
51.8000 824.0000 1.0000
51.8400 846.0000 1.0000
51.8800 881.0000 1.0000
51.9200 960.0000 1.0000
51.9600 1074.0000 1.0000
52.0000 1177.0000 1.0000
52.0400 1363.0000 1.0000
52.0800 1631.0000 1.0000
52.1200 2043.0000 1.0000
52.1600 2640.0000 1.0000
52.2000 3718.0000 1.0000
52.2400 5010.0000 1.0000
52.2800 5722.0000 1.0000
52.3200 5420.0000 1.0000
52.3600 4762.0000 1.0000
52.4000 4427.0000 1.0000
52.4400 3635.0000 1.0000
52.4800 2819.0000 1.0000
52.5200 2137.0000 1.0000
52.5600 1684.0000 1.0000
52.6000 1430.0000 1.0000
52.6400 1195.0000 1.0000
52.6800 1055.0000 1.0000
52.7200 968.0000 1.0000
52.7600 910.0000 1.0000
52.8000 922.0000 1.0000
52.8400 853.0000 1.0000
52.8800 843.0000 1.0000
52.9200 831.0000 1.0000
52.9600 811.0000 1.0000
53.0000 823.0000 1.0000
53.0400 830.0000 1.0000
53.0800 787.0000 1.0000
53.1200 779.0000 1.0000
53.1600 704.0000 1.0000
53.2000 783.0000 1.0000
53.2400 733.0000 1.0000
53.2800 735.0000 1.0000
53.3200 793.0000 1.0000
53.3600 730.0000 1.0000
53.4000 744.0000 1.0000
53.4400 729.0000 1.0000
53.4800 748.0000 1.0000
53.5200 712.0000 1.0000
53.5600 725.0000 1.0000
53.6000 725.0000 1.0000
53.6400 689.0000 1.0000
53.6800 769.0000 1.0000
53.7200 709.0000 1.0000
53.7600 744.0000 1.0000
53.8000 723.0000 1.0000
53.8400 708.0000 1.0000
53.8800 721.0000 1.0000
53.9200 716.0000 1.0000
53.9600 726.0000 1.0000
54.0000 719.0000 1.0000
54.0400 705.0000 1.0000
54.0800 703.0000 1.0000
54.1200 733.0000 1.0000
54.1600 751.0000 1.0000
54.2000 762.0000 1.0000
54.2400 715.0000 1.0000
54.2800 696.0000 1.0000
54.3200 690.0000 1.0000
54.3600 735.0000 1.0000
54.4000 698.0000 1.0000
54.4400 707.0000 1.0000
54.4800 706.0000 1.0000
54.5200 747.0000 1.0000
54.5600 733.0000 1.0000
54.6000 730.0000 1.0000
54.6400 729.0000 1.0000
54.6800 745.0000 1.0000
54.7200 753.0000 1.0000
54.7600 865.0000 1.0000
54.8000 779.0000 1.0000
54.8400 737.0000 1.0000
54.8800 802.0000 1.0000
54.9200 791.0000 1.0000
54.9600 773.0000 1.0000
55.0000 784.0000 1.0000
55.0400 806.0000 1.0000
55.0800 848.0000 1.0000
55.1200 872.0000 1.0000
55.1600 863.0000 1.0000
55.2000 985.0000 1.0000
55.2400 1065.0000 1.0000
55.2800 1121.0000 1.0000
55.3200 1151.0000 1.0000
55.3600 1057.0000 1.0000
55.4000 1072.0000 1.0000
55.4400 1068.0000 1.0000
55.4800 990.0000 1.0000
55.5200 908.0000 1.0000
55.5600 849.0000 1.0000
55.6000 843.0000 1.0000
55.6400 754.0000 1.0000
55.6800 775.0000 1.0000
55.7200 728.0000 1.0000
55.7600 719.0000 1.0000
55.8000 755.0000 1.0000
55.8400 750.0000 1.0000
55.8800 707.0000 1.0000
55.9200 696.0000 1.0000
55.9600 683.0000 1.0000
56.0000 703.0000 1.0000
56.0400 758.0000 1.0000
56.0800 713.0000 1.0000
56.1200 690.0000 1.0000
56.1600 705.0000 1.0000
56.2000 713.0000 1.0000
56.2400 731.0000 1.0000
56.2800 644.0000 1.0000
56.3200 736.0000 1.0000
56.3600 686.0000 1.0000
56.4000 700.0000 1.0000
56.4400 664.0000 1.0000
56.4800 690.0000 1.0000
56.5200 708.0000 1.0000
56.5600 665.0000 1.0000
56.6000 738.0000 1.0000
56.6400 694.0000 1.0000
56.6800 725.0000 1.0000
56.7200 715.0000 1.0000
56.7600 738.0000 1.0000
56.8000 706.0000 1.0000
56.8400 692.0000 1.0000
56.8800 668.0000 1.0000
56.9200 668.0000 1.0000
56.9600 693.0000 1.0000
57.0000 636.0000 1.0000
57.0400 703.0000 1.0000
57.0800 677.0000 1.0000
57.1200 695.0000 1.0000
57.1600 667.0000 1.0000
57.2000 667.0000 1.0000
57.2400 689.0000 1.0000
57.2800 670.0000 1.0000
57.3200 688.0000 1.0000
57.3600 696.0000 1.0000
57.4000 647.0000 1.0000
57.4400 644.0000 1.0000
57.4800 685.0000 1.0000
57.5200 669.0000 1.0000
57.5600 705.0000 1.0000
57.6000 652.0000 1.0000
57.6400 687.0000 1.0000
57.6800 680.0000 1.0000
57.7200 695.0000 1.0000
57.7600 655.0000 1.0000
57.8000 687.0000 1.0000
57.8400 704.0000 1.0000
57.8800 673.0000 1.0000
57.9200 703.0000 1.0000
57.9600 663.0000 1.0000
58.0000 714.0000 1.0000
58.0400 682.0000 1.0000
58.0800 701.0000 1.0000
58.1200 703.0000 1.0000
58.1600 736.0000 1.0000
58.2000 732.0000 1.0000
58.2400 702.0000 1.0000
58.2800 725.0000 1.0000
58.3200 729.0000 1.0000
58.3600 702.0000 1.0000
58.4000 682.0000 1.0000
58.4400 750.0000 1.0000
58.4800 710.0000 1.0000
58.5200 679.0000 1.0000
58.5600 691.0000 1.0000
58.6000 658.0000 1.0000
58.6400 644.0000 1.0000
58.6800 715.0000 1.0000
58.7200 676.0000 1.0000
58.7600 707.0000 1.0000
58.8000 693.0000 1.0000
58.8400 680.0000 1.0000
58.8800 665.0000 1.0000
58.9200 710.0000 1.0000
58.9600 706.0000 1.0000
59.0000 699.0000 1.0000
59.0400 739.0000 1.0000
59.0800 678.0000 1.0000
59.1200 661.0000 1.0000
59.1600 683.0000 1.0000
59.2000 657.0000 1.0000
59.2400 733.0000 1.0000
59.2800 728.0000 1.0000
59.3200 706.0000 1.0000
59.3600 709.0000 1.0000
59.4000 710.0000 1.0000
59.4400 678.0000 1.0000
59.4800 717.0000 1.0000
59.5200 716.0000 1.0000
59.5600 675.0000 1.0000
59.6000 649.0000 1.0000
59.6400 657.0000 1.0000
59.6800 706.0000 1.0000
59.7200 682.0000 1.0000
59.7600 720.0000 1.0000
59.8000 699.0000 1.0000
59.8400 688.0000 1.0000
59.8800 686.0000 1.0000
59.9200 641.0000 1.0000
59.9600 710.0000 1.0000
60.0000 658.0000 1.0000
60.0400 720.0000 1.0000
60.0800 694.0000 1.0000
60.1200 678.0000 1.0000
60.1600 673.0000 1.0000
60.2000 700.0000 1.0000
60.2400 703.0000 1.0000
60.2800 689.0000 1.0000
60.3200 688.0000 1.0000
60.3600 688.0000 1.0000
60.4000 666.0000 1.0000
60.4400 693.0000 1.0000
60.4800 660.0000 1.0000
60.5200 683.0000 1.0000
60.5600 710.0000 1.0000
60.6000 703.0000 1.0000
60.6400 635.0000 1.0000
60.6800 676.0000 1.0000
60.7200 652.0000 1.0000
60.7600 717.0000 1.0000
60.8000 695.0000 1.0000
60.8400 659.0000 1.0000
60.8800 719.0000 1.0000
60.9200 722.0000 1.0000
60.9600 731.0000 1.0000
61.0000 656.0000 1.0000
61.0400 699.0000 1.0000
61.0800 716.0000 1.0000
61.1200 691.0000 1.0000
61.1600 706.0000 1.0000
61.2000 662.0000 1.0000
61.2400 692.0000 1.0000
61.2800 658.0000 1.0000
61.3200 700.0000 1.0000
61.3600 728.0000 1.0000
61.4000 724.0000 1.0000
61.4400 713.0000 1.0000
61.4800 696.0000 1.0000
61.5200 663.0000 1.0000
61.5600 676.0000 1.0000
61.6000 720.0000 1.0000
61.6400 742.0000 1.0000
61.6800 736.0000 1.0000
61.7200 702.0000 1.0000
61.7600 679.0000 1.0000
61.8000 720.0000 1.0000
61.8400 719.0000 1.0000
61.8800 769.0000 1.0000
61.9200 806.0000 1.0000
61.9600 793.0000 1.0000
62.0000 846.0000 1.0000
62.0400 907.0000 1.0000
62.0800 1011.0000 1.0000
62.1200 1100.0000 1.0000
62.1600 1254.0000 1.0000
62.2000 1385.0000 1.0000
62.2400 1520.0000 1.0000
62.2800 1530.0000 1.0000
62.3200 1582.0000 1.0000
62.3600 1570.0000 1.0000
62.4000 1509.0000 1.0000
62.4400 1398.0000 1.0000
62.4800 1333.0000 1.0000
62.5200 1187.0000 1.0000
62.5600 1126.0000 1.0000
62.6000 1068.0000 1.0000
62.6400 1015.0000 1.0000
62.6800 881.0000 1.0000
62.7200 834.0000 1.0000
62.7600 872.0000 1.0000
62.8000 811.0000 1.0000
62.8400 824.0000 1.0000
62.8800 748.0000 1.0000
62.9200 805.0000 1.0000
62.9600 737.0000 1.0000
63.0000 744.0000 1.0000
63.0400 738.0000 1.0000
63.0800 744.0000 1.0000
63.1200 789.0000 1.0000
63.1600 737.0000 1.0000
63.2000 778.0000 1.0000
63.2400 789.0000 1.0000
63.2800 698.0000 1.0000
63.3200 710.0000 1.0000
63.3600 741.0000 1.0000
63.4000 730.0000 1.0000
63.4400 669.0000 1.0000
63.4800 722.0000 1.0000
63.5200 691.0000 1.0000
63.5600 695.0000 1.0000
63.6000 708.0000 1.0000
63.6400 706.0000 1.0000
63.6800 671.0000 1.0000
63.7200 699.0000 1.0000
63.7600 691.0000 1.0000
63.8000 663.0000 1.0000
63.8400 668.0000 1.0000
63.8800 701.0000 1.0000
63.9200 678.0000 1.0000
63.9600 679.0000 1.0000
64.0000 664.0000 1.0000
64.0400 709.0000 1.0000
64.0800 709.0000 1.0000
64.1200 682.0000 1.0000
64.1600 672.0000 1.0000
64.2000 669.0000 1.0000
64.2400 687.0000 1.0000
64.2800 723.0000 1.0000
64.3200 693.0000 1.0000
64.3600 652.0000 1.0000
64.4000 708.0000 1.0000
64.4400 759.0000 1.0000
64.4800 752.0000 1.0000
64.5200 716.0000 1.0000
64.5600 735.0000 1.0000
64.6000 821.0000 1.0000
64.6400 871.0000 1.0000
64.6800 851.0000 1.0000
64.7200 884.0000 1.0000
64.7600 857.0000 1.0000
64.8000 867.0000 1.0000
64.8400 832.0000 1.0000
64.8800 832.0000 1.0000
64.9200 800.0000 1.0000
64.9600 732.0000 1.0000
65.0000 731.0000 1.0000
65.0400 821.0000 1.0000
65.0800 758.0000 1.0000
65.1200 760.0000 1.0000
65.1600 745.0000 1.0000
65.2000 791.0000 1.0000
65.2400 725.0000 1.0000
65.2800 717.0000 1.0000
65.3200 726.0000 1.0000
65.3600 702.0000 1.0000
65.4000 735.0000 1.0000
65.4400 719.0000 1.0000
65.4800 738.0000 1.0000
65.5200 749.0000 1.0000
65.5600 722.0000 1.0000
65.6000 755.0000 1.0000
65.6400 709.0000 1.0000
65.6800 800.0000 1.0000
65.7200 778.0000 1.0000
65.7600 791.0000 1.0000
65.8000 794.0000 1.0000
65.8400 812.0000 1.0000
65.8800 827.0000 1.0000
65.9200 873.0000 1.0000
65.9600 968.0000 1.0000
66.0000 1051.0000 1.0000
66.0400 1156.0000 1.0000
66.0800 1314.0000 1.0000
66.1200 1643.0000 1.0000
66.1600 2018.0000 1.0000
66.2000 2531.0000 1.0000
66.2400 2825.0000 1.0000
66.2800 2916.0000 1.0000
66.3200 2651.0000 1.0000
66.3600 2619.0000 1.0000
66.4000 2429.0000 1.0000
66.4400 2296.0000 1.0000
66.4800 2057.0000 1.0000
66.5200 1754.0000 1.0000
66.5600 1473.0000 1.0000
66.6000 1298.0000 1.0000
66.6400 1143.0000 1.0000
66.6800 1025.0000 1.0000
66.7200 949.0000 1.0000
66.7600 881.0000 1.0000
66.8000 862.0000 1.0000
66.8400 783.0000 1.0000
66.8800 748.0000 1.0000
66.9200 748.0000 1.0000
66.9600 740.0000 1.0000
67.0000 711.0000 1.0000
67.0400 632.0000 1.0000
67.0800 681.0000 1.0000
67.1200 705.0000 1.0000
67.1600 701.0000 1.0000
67.2000 680.0000 1.0000
67.2400 685.0000 1.0000
67.2800 675.0000 1.0000
67.3200 719.0000 1.0000
67.3600 696.0000 1.0000
67.4000 645.0000 1.0000
67.4400 668.0000 1.0000
67.4800 723.0000 1.0000
67.5200 661.0000 1.0000
67.5600 660.0000 1.0000
67.6000 655.0000 1.0000
67.6400 661.0000 1.0000
67.6800 654.0000 1.0000
67.7200 642.0000 1.0000
67.7600 637.0000 1.0000
67.8000 647.0000 1.0000
67.8400 635.0000 1.0000
67.8800 634.0000 1.0000
67.9200 625.0000 1.0000
67.9600 631.0000 1.0000
68.0000 652.0000 1.0000
68.0400 638.0000 1.0000
68.0800 686.0000 1.0000
68.1200 665.0000 1.0000
68.1600 649.0000 1.0000
68.2000 618.0000 1.0000
68.2400 643.0000 1.0000
68.2800 631.0000 1.0000
68.3200 655.0000 1.0000
68.3600 604.0000 1.0000
68.4000 597.0000 1.0000
68.4400 633.0000 1.0000
68.4800 646.0000 1.0000
68.5200 579.0000 1.0000
68.5600 621.0000 1.0000
68.6000 607.0000 1.0000
68.6400 621.0000 1.0000
68.6800 659.0000 1.0000
68.7200 617.0000 1.0000
68.7600 617.0000 1.0000
68.8000 611.0000 1.0000
68.8400 657.0000 1.0000
68.8800 590.0000 1.0000
68.9200 583.0000 1.0000
68.9600 606.0000 1.0000
69.0000 631.0000 1.0000
69.0400 606.0000 1.0000
69.0800 645.0000 1.0000
69.1200 643.0000 1.0000
69.1600 586.0000 1.0000
69.2000 599.0000 1.0000
69.2400 604.0000 1.0000
69.2800 608.0000 1.0000
69.3200 619.0000 1.0000
69.3600 615.0000 1.0000
69.4000 610.0000 1.0000
69.4400 641.0000 1.0000
69.4800 592.0000 1.0000
69.5200 611.0000 1.0000
69.5600 647.0000 1.0000
69.6000 588.0000 1.0000
69.6400 593.0000 1.0000
69.6800 631.0000 1.0000
69.7200 643.0000 1.0000
69.7600 587.0000 1.0000
69.8000 627.0000 1.0000
69.8400 557.0000 1.0000
69.8800 585.0000 1.0000
69.9200 581.0000 1.0000
69.9600 630.0000 1.0000
70.0000 560.0000 1.0000
*RAS_INT_END
*RAS_TEMPERATURE_START
*RAS_TEMPERATURE_END
*RAS_DATA_END