File: Section2_75_samples/XRD/No_064_HS1_4.ras
*RAS_DATA_START
*RAS_HEADER_START
*DISP_FMT_X "%.2f"
*DISP_FMT_Y "%.0f"
*DISP_FULLSCALE "13104.0000000000"
*DISP_LINE_COLOR "255.0000000000"
*DISP_LINE_STYLE "0.0000000000"
*DISP_LINE_WIDTH "0.2500000000"
*DISP_NOTE "測定データ-7"
*DISP_OFFSET_Y "0.0000000000"
*DISP_PEAKSEARCH_UNIT_Y "cps"
*DISP_RANGE_BOTTOM "0.0000000000"
*DISP_RANGE_LEFT "20.0000000000"
*DISP_RANGE_LOGCUTOFF "0.0100000000"
*DISP_RANGE_RIGHT "70.0000000000"
*DISP_RANGE_TOP "13104.0000000000"
*DISP_SCALE_MODE_Y "0.0000000000"
*DISP_TAB_NAME "2θ/θ"
*DISP_TITLE_Y "強度"
*DISP_UNIT_Y "cps"
*DISP_WINDOW_NAME "MSG_MACROENGINE"
*FILE_COMMENT " "
*FILE_MD5 ""
*FILE_MEMO " "
*FILE_OPERATOR "Administrator"
*FILE_SAMPLE " "
*FILE_TYPE "RAS_RAW"
*FILE_USERGROUP "システムマネージャ"
*FILE_VERSION "1.0000000000"
*HW_ATTACHMENT_ID "ATT0025"
*HW_ATTACHMENT_NAME "標準|Standard"
*HW_COUNTER_ID-0 "CUT0025"
*HW_COUNTER_ID-1 "CUT0020"
*HW_COUNTER_ID-2 "CUT0020"
*HW_COUNTER_ID-3 "CSL0021"
*HW_COUNTER_ID-4 "CMC0021"
*HW_COUNTER_NAME-0 "D/teX Ultra|D/teX Ultra"
*HW_COUNTER_NAME-1 "None|None"
*HW_COUNTER_NAME-2 "None|None"
*HW_COUNTER_NAME-3 "BBM|BBM"
*HW_COUNTER_NAME-4 "検出器モノクロメータ|Detector monochromator"
*HW_COUNTER_SELECT_NAME "D/teX Ultra|D/teX Ultra"
*HW_GONIOMETER_ID "GON0023"
*HW_GONIOMETER_NAME "SmartLab|SmartLab"
*HW_GONIOMETER_RADIUS-0 "90.0"
*HW_GONIOMETER_RADIUS-1 "114.0"
*HW_GONIOMETER_RADIUS-2 "190.0"
*HW_GONIOMETER_RADIUS-3 "300.0"
*HW_GONIOMETER_RADIUS-4 "187.0"
*HW_GONIOMETER_RADIUS-5 "300.0"
*HW_GONIOMETER_RADIUS-6 "113.0"
*HW_GONIOMETER_RADIUS-7 "331.0"
*HW_I_OPT_ID-0 "CBO0021"
*HW_I_OPT_ID-1 "ICR0023"
*HW_I_OPT_ID-2 "ISL0021"
*HW_I_OPT_ID-3 "ISO0021"
*HW_I_OPT_ID-4 "IAD0021"
*HW_I_OPT_ID-5 "IPR0001"
*HW_I_OPT_NAME-0 "CBOユニット|CBO unit"
*HW_I_OPT_NAME-1 "標準入射光学ユニット|Standard incident optical unit"
*HW_I_OPT_NAME-2 "標準入射スリットボックス|Standard incident slit box"
*HW_I_OPT_NAME-3 "入射平行スリット|Incident parallel slit"
*HW_I_OPT_NAME-4 "長手制限スリット|Length limiting slit"
*HW_I_OPT_NAME-5 "None|None"
*HW_R_ATTENUATER_AUTOMODE "0"
*HW_R_OPT_ID-0 "RSS0021"
*HW_R_OPT_ID-1 "RCR0023"
*HW_R_OPT_ID-2 "RSO0021"
*HW_R_OPT_ID-3 "RRS0021"
*HW_R_OPT_ID-4 "ATN0021"
*HW_R_OPT_ID-5 "RFL0021"
*HW_R_OPT_ID-6 "RAD0021"
*HW_R_OPT_NAME-0 "標準受光スリットボックス1|Standard receiving slit box # 1"
*HW_R_OPT_NAME-1 "標準受光光学ユニット1|Standard receiving unit # 1"
*HW_R_OPT_NAME-2 "標準受光光学ユニット2|Standard receiving optical unit # 2"
*HW_R_OPT_NAME-3 "標準受光スリットボックス2|Standard receiving slit box # 2"
*HW_R_OPT_NAME-4 "標準アッテネータ|Standard Attenuator"
*HW_R_OPT_NAME-5 "Cu Kβ|Cu K-beta"
*HW_R_OPT_NAME-6 "調整用受光スリット|Alignment receiving slit"
*HW_SAMPLE_HOLDER_ID "SMP0023"
*HW_SAMPLE_HOLDER_NAME "標準Zステージ|Standard Z stage"
*HW_XG_CURRENT_MAX "50"
*HW_XG_CURRENT_MIN "2"
*HW_XG_CURRENT_RESOLUTION "1"
*HW_XG_CURRENT_UNIT "mA"
*HW_XG_FOCUS "1mm x 10mm"
*HW_XG_FOCUS_TYPE "Normal"
*HW_XG_ID ""
*HW_XG_NAME "3kW 封入管(ID:1200)|3kW Sealed tube(ID:1200)"
*HW_XG_TARGET_ATOMIC_NUMBER "29.0000000000"
*HW_XG_TARGET_NAME "Cu"
*HW_XG_TYPE "Hermetic"
*HW_XG_VOLTAGE_MAX "60"
*HW_XG_VOLTAGE_MIN "20"
*HW_XG_VOLTAGE_RESOLUTION "1"
*HW_XG_VOLTAGE_UNIT "kV"
*HW_XG_WATT_MAX "1.500"
*HW_XG_WATT_UNIT "kW"
*HW_XG_WAVE_LENGTH_ALPHA1 "1.540593"
*HW_XG_WAVE_LENGTH_ALPHA2 "1.544414"
*HW_XG_WAVE_LENGTH_BETA "1.392250"
*MEAS_COND_AXIS_NAME-0 "2θ/θ"
*MEAS_COND_AXIS_NAME-1 "2θ"
*MEAS_COND_AXIS_NAME-2 "ω"
*MEAS_COND_AXIS_NAME-3 "Z"
*MEAS_COND_AXIS_NAME-4 "2θ/ω"
*MEAS_COND_AXIS_NAME-5 "θs"
*MEAS_COND_AXIS_NAME-6 "θd"
*MEAS_COND_AXIS_NAME-7 "Ts"
*MEAS_COND_AXIS_NAME-8 "CBO選択スリット"
*MEAS_COND_AXIS_NAME-9 "M"
*MEAS_COND_AXIS_NAME-10 "入射平行スリット"
*MEAS_COND_AXIS_NAME-11 "入射スリット"
*MEAS_COND_AXIS_NAME-12 ""
*MEAS_COND_AXIS_NAME-13 "Zs"
*MEAS_COND_AXIS_NAME-14 "入射光学素子"
*MEAS_COND_AXIS_NAME-15 "長手制限スリット"
*MEAS_COND_AXIS_NAME-16 "センタースリット"
*MEAS_COND_AXIS_NAME-17 "フィルター"
*MEAS_COND_AXIS_NAME-18 "受光スリット1"
*MEAS_COND_AXIS_NAME-19 "受光スリット2"
*MEAS_COND_AXIS_NAME-20 "受光光学素子"
*MEAS_COND_AXIS_NAME-21 "受光平行スリット"
*MEAS_COND_AXIS_NAME-22 "調整用受光スリット"
*MEAS_COND_AXIS_NAME-23 ""
*MEAS_COND_AXIS_NAME-24 ""
*MEAS_COND_AXIS_NAME-25 "Zd"
*MEAS_COND_AXIS_NAME-26 "アッテネータ"
*MEAS_COND_AXIS_NAME-27 "検出器モノクロメータ"
*MEAS_COND_AXIS_NAME-28 "モノクロメータスリット"
*MEAS_COND_AXIS_NAME-29 "プライマリビーム"
*MEAS_COND_AXIS_NAME-30 "PHA"
*MEAS_COND_AXIS_NAME_INTERNAL-0 "TwoThetaTheta"
*MEAS_COND_AXIS_NAME_INTERNAL-1 "TwoTheta"
*MEAS_COND_AXIS_NAME_INTERNAL-2 "Omega"
*MEAS_COND_AXIS_NAME_INTERNAL-3 "Z"
*MEAS_COND_AXIS_NAME_INTERNAL-4 "TwoThetaOmega"
*MEAS_COND_AXIS_NAME_INTERNAL-5 "ThetaS"
*MEAS_COND_AXIS_NAME_INTERNAL-6 "ThetaD"
*MEAS_COND_AXIS_NAME_INTERNAL-7 "Ts"
*MEAS_COND_AXIS_NAME_INTERNAL-8 "CBO"
*MEAS_COND_AXIS_NAME_INTERNAL-9 "CBO-M"
*MEAS_COND_AXIS_NAME_INTERNAL-10 "IncidentSollerSlit"
*MEAS_COND_AXIS_NAME_INTERNAL-11 "IncidentSlitBox"
*MEAS_COND_AXIS_NAME_INTERNAL-12 "IncidentSlitBox-_Axis"
*MEAS_COND_AXIS_NAME_INTERNAL-13 "Zs"
*MEAS_COND_AXIS_NAME_INTERNAL-14 "IncidentMonochromator"
*MEAS_COND_AXIS_NAME_INTERNAL-15 "IncidentAxdSlit"
*MEAS_COND_AXIS_NAME_INTERNAL-16 "CenterSlit"
*MEAS_COND_AXIS_NAME_INTERNAL-17 "Filter"
*MEAS_COND_AXIS_NAME_INTERNAL-18 "ReceivingSlitBox1"
*MEAS_COND_AXIS_NAME_INTERNAL-19 "ReceivingSlitBox2"
*MEAS_COND_AXIS_NAME_INTERNAL-20 "ReceivingOptics"
*MEAS_COND_AXIS_NAME_INTERNAL-21 "ReceivingSollerSlit"
*MEAS_COND_AXIS_NAME_INTERNAL-22 "ReceivingAxdSlit"
*MEAS_COND_AXIS_NAME_INTERNAL-23 "ReceivingSlitBox1-_Axis"
*MEAS_COND_AXIS_NAME_INTERNAL-24 "ReceivingSlitBox2-_Axis"
*MEAS_COND_AXIS_NAME_INTERNAL-25 "ReceivingSlitBox2-Zd"
*MEAS_COND_AXIS_NAME_INTERNAL-26 "Attenuator"
*MEAS_COND_AXIS_NAME_INTERNAL-27 "CounterMonochromator"
*MEAS_COND_AXIS_NAME_INTERNAL-28 "CounterSlit"
*MEAS_COND_AXIS_NAME_INTERNAL-29 "IncidentPrimary"
*MEAS_COND_AXIS_NAME_INTERNAL-30 "PHA"
*MEAS_COND_AXIS_NAME_MAGICNO-0 "83951616.0000000000"
*MEAS_COND_AXIS_NAME_MAGICNO-1 "268632064.0000000000"
*MEAS_COND_AXIS_NAME_MAGICNO-2 "268500992.0000000000"
*MEAS_COND_AXIS_NAME_MAGICNO-3 "285278208.0000000000"
*MEAS_COND_AXIS_NAME_MAGICNO-4 "83951616.0000000000"
*MEAS_COND_AXIS_NAME_MAGICNO-5 "131072.0000000000"
*MEAS_COND_AXIS_NAME_MAGICNO-6 "131072.0000000000"
*MEAS_COND_AXIS_NAME_MAGICNO-7 "318898176.0000000000"
*MEAS_COND_AXIS_NAME_MAGICNO-8 "20971521.0000000000"
*MEAS_COND_AXIS_NAME_MAGICNO-9 "285343744.0000000000"
*MEAS_COND_AXIS_NAME_MAGICNO-10 "20971521.0000000000"
*MEAS_COND_AXIS_NAME_MAGICNO-11 "22020097.0000000000"
*MEAS_COND_AXIS_NAME_MAGICNO-12 "25165824.0000000000"
*MEAS_COND_AXIS_NAME_MAGICNO-13 "318898176.0000000000"
*MEAS_COND_AXIS_NAME_MAGICNO-14 "1.0000000000"
*MEAS_COND_AXIS_NAME_MAGICNO-15 "20971521.0000000000"
*MEAS_COND_AXIS_NAME_MAGICNO-16 "20971521.0000000000"
*MEAS_COND_AXIS_NAME_MAGICNO-17 "20971521.0000000000"
*MEAS_COND_AXIS_NAME_MAGICNO-18 "23068673.0000000000"
*MEAS_COND_AXIS_NAME_MAGICNO-19 "23068673.0000000000"
*MEAS_COND_AXIS_NAME_MAGICNO-20 "20971521.0000000000"
*MEAS_COND_AXIS_NAME_MAGICNO-21 "20971521.0000000000"
*MEAS_COND_AXIS_NAME_MAGICNO-22 "20971521.0000000000"
*MEAS_COND_AXIS_NAME_MAGICNO-23 "25165824.0000000000"
*MEAS_COND_AXIS_NAME_MAGICNO-24 "25165824.0000000000"
*MEAS_COND_AXIS_NAME_MAGICNO-25 "285343744.0000000000"
*MEAS_COND_AXIS_NAME_MAGICNO-26 "17301505.0000000000"
*MEAS_COND_AXIS_NAME_MAGICNO-27 "20971521.0000000000"
*MEAS_COND_AXIS_NAME_MAGICNO-28 "20971521.0000000000"
*MEAS_COND_AXIS_NAME_MAGICNO-29 "20971521.0000000000"
*MEAS_COND_AXIS_NAME_MAGICNO-30 "0.0000000000"
*MEAS_COND_AXIS_OFFSET-0 "-"
*MEAS_COND_AXIS_OFFSET-1 "-0.1081000000"
*MEAS_COND_AXIS_OFFSET-2 "0.3758000000"
*MEAS_COND_AXIS_OFFSET-3 "-"
*MEAS_COND_AXIS_OFFSET-4 "-"
*MEAS_COND_AXIS_OFFSET-5 "0.3758000000"
*MEAS_COND_AXIS_OFFSET-6 "-0.4839000000"
*MEAS_COND_AXIS_OFFSET-7 "-"
*MEAS_COND_AXIS_OFFSET-8 "-"
*MEAS_COND_AXIS_OFFSET-9 "-"
*MEAS_COND_AXIS_OFFSET-10 "-"
*MEAS_COND_AXIS_OFFSET-11 "-"
*MEAS_COND_AXIS_OFFSET-12 "-"
*MEAS_COND_AXIS_OFFSET-13 "-"
*MEAS_COND_AXIS_OFFSET-14 "-"
*MEAS_COND_AXIS_OFFSET-15 "-"
*MEAS_COND_AXIS_OFFSET-16 "-"
*MEAS_COND_AXIS_OFFSET-17 "-"
*MEAS_COND_AXIS_OFFSET-18 "-"
*MEAS_COND_AXIS_OFFSET-19 "-"
*MEAS_COND_AXIS_OFFSET-20 "-"
*MEAS_COND_AXIS_OFFSET-21 "-"
*MEAS_COND_AXIS_OFFSET-22 "-"
*MEAS_COND_AXIS_OFFSET-23 "-"
*MEAS_COND_AXIS_OFFSET-24 "-"
*MEAS_COND_AXIS_OFFSET-25 "-"
*MEAS_COND_AXIS_OFFSET-26 "-"
*MEAS_COND_AXIS_OFFSET-27 "-"
*MEAS_COND_AXIS_OFFSET-28 "-"
*MEAS_COND_AXIS_OFFSET-29 "-"
*MEAS_COND_AXIS_OFFSET-30 "-"
*MEAS_COND_AXIS_POSITION-0 "0.0000000000"
*MEAS_COND_AXIS_POSITION-1 "0.0000000000"
*MEAS_COND_AXIS_POSITION-2 "0.0000000000"
*MEAS_COND_AXIS_POSITION-3 "-0.5500000000"
*MEAS_COND_AXIS_POSITION-4 "0.0000000000"
*MEAS_COND_AXIS_POSITION-5 "0.0000000000"
*MEAS_COND_AXIS_POSITION-6 "0.0000000000"
*MEAS_COND_AXIS_POSITION-7 "-0.4278800000"
*MEAS_COND_AXIS_POSITION-8 "BB"
*MEAS_COND_AXIS_POSITION-9 "0.0000000000"
*MEAS_COND_AXIS_POSITION-10 "Soller_slit_5.0deg"
*MEAS_COND_AXIS_POSITION-11 "2/3deg"
*MEAS_COND_AXIS_POSITION-12 "2.2088000000"
*MEAS_COND_AXIS_POSITION-13 "-0.4140600000"
*MEAS_COND_AXIS_POSITION-14 "0.0000000000"
*MEAS_COND_AXIS_POSITION-15 "10.0mm"
*MEAS_COND_AXIS_POSITION-16 "None"
*MEAS_COND_AXIS_POSITION-17 "Cu_K-beta"
*MEAS_COND_AXIS_POSITION-18 "13.000mm"
*MEAS_COND_AXIS_POSITION-19 "13.000mm"
*MEAS_COND_AXIS_POSITION-20 "No_unit"
*MEAS_COND_AXIS_POSITION-21 "Soller_slit_5.0deg"
*MEAS_COND_AXIS_POSITION-22 "None"
*MEAS_COND_AXIS_POSITION-23 "13.0000000000"
*MEAS_COND_AXIS_POSITION-24 "13.0000000000"
*MEAS_COND_AXIS_POSITION-25 "0.0109400000"
*MEAS_COND_AXIS_POSITION-26 "Open"
*MEAS_COND_AXIS_POSITION-27 "None"
*MEAS_COND_AXIS_POSITION-28 "None"
*MEAS_COND_AXIS_POSITION-29 "None"
*MEAS_COND_AXIS_POSITION-30 "38.0000000000"
*MEAS_COND_AXIS_UNIT-0 "deg"
*MEAS_COND_AXIS_UNIT-1 "deg"
*MEAS_COND_AXIS_UNIT-2 "deg"
*MEAS_COND_AXIS_UNIT-3 "mm"
*MEAS_COND_AXIS_UNIT-4 "deg"
*MEAS_COND_AXIS_UNIT-5 "deg"
*MEAS_COND_AXIS_UNIT-6 "deg"
*MEAS_COND_AXIS_UNIT-7 "mm"
*MEAS_COND_AXIS_UNIT-8 ""
*MEAS_COND_AXIS_UNIT-9 "pulse"
*MEAS_COND_AXIS_UNIT-10 ""
*MEAS_COND_AXIS_UNIT-11 ""
*MEAS_COND_AXIS_UNIT-12 "mm"
*MEAS_COND_AXIS_UNIT-13 "mm"
*MEAS_COND_AXIS_UNIT-14 ""
*MEAS_COND_AXIS_UNIT-15 ""
*MEAS_COND_AXIS_UNIT-16 ""
*MEAS_COND_AXIS_UNIT-17 ""
*MEAS_COND_AXIS_UNIT-18 ""
*MEAS_COND_AXIS_UNIT-19 ""
*MEAS_COND_AXIS_UNIT-20 ""
*MEAS_COND_AXIS_UNIT-21 ""
*MEAS_COND_AXIS_UNIT-22 ""
*MEAS_COND_AXIS_UNIT-23 "mm"
*MEAS_COND_AXIS_UNIT-24 "mm"
*MEAS_COND_AXIS_UNIT-25 "mm"
*MEAS_COND_AXIS_UNIT-26 ""
*MEAS_COND_AXIS_UNIT-27 ""
*MEAS_COND_AXIS_UNIT-28 ""
*MEAS_COND_AXIS_UNIT-29 ""
*MEAS_COND_AXIS_UNIT-30 "div"
*MEAS_COND_COUNTER_CNTLOSS_CORR "0.0000000000"
*MEAS_COND_COUNTER_PHABASE "38.0000000000"
*MEAS_COND_COUNTER_PHAWINDOW "16.0000000000"
*MEAS_COND_COUNTER_PHA_UNIT "div"
*MEAS_COND_COUNTER_TAUDIFF "30.0000000000"
*MEAS_COND_COUNTER_TAUINT "0.0000000000"
*MEAS_COND_IRRADIATION_MODE "OFF"
*MEAS_COND_IRRADIATION_WIDTH ""
*MEAS_COND_OPT_ATTR "集中法"
*MEAS_COND_OPT_NAME "@集中法"
*MEAS_COND_UNSYMMETRIC_MODE "OFF"
*MEAS_COND_XG_CURRENT "30.0000000000"
*MEAS_COND_XG_VOLTAGE "40.0000000000"
*MEAS_COND_XG_WAVE_TYPE "Ka"
*MEAS_DATA_COUNT "5001.0000000000"
*MEAS_SCAN_AXIS_X "2θ/θ"
*MEAS_SCAN_AXIS_X_INTERNAL "TwoThetaTheta"
*MEAS_SCAN_END_TIME "07/14/21 17:40:52"
*MEAS_SCAN_MODE "CONTINUOUS"
*MEAS_SCAN_MONITOR "0"
*MEAS_SCAN_RESOLUTION_X "0.0002"
*MEAS_SCAN_SPEED "1.0"
*MEAS_SCAN_SPEED_UNIT "deg/min"
*MEAS_SCAN_START "20.0000000000"
*MEAS_SCAN_START_TIME "07/14/21 16:47:59"
*MEAS_SCAN_STEP "0.0100000000"
*MEAS_SCAN_STOP "70.0000000000"
*MEAS_SCAN_UNIT_X "deg"
*MEAS_SCAN_UNIT_Y "counts"
*RAS_HEADER_END
*RAS_INT_START
20.0000 1472.0000 1.0000
20.0400 1428.0000 1.0000
20.0800 1421.0000 1.0000
20.1200 1426.0000 1.0000
20.1600 1442.0000 1.0000
20.2000 1426.0000 1.0000
20.2400 1399.0000 1.0000
20.2800 1448.0000 1.0000
20.3200 1520.0000 1.0000
20.3600 1519.0000 1.0000
20.4000 1418.0000 1.0000
20.4400 1473.0000 1.0000
20.4800 1436.0000 1.0000
20.5200 1394.0000 1.0000
20.5600 1444.0000 1.0000
20.6000 1463.0000 1.0000
20.6400 1462.0000 1.0000
20.6800 1530.0000 1.0000
20.7200 1457.0000 1.0000
20.7600 1414.0000 1.0000
20.8000 1426.0000 1.0000
20.8400 1459.0000 1.0000
20.8800 1401.0000 1.0000
20.9200 1435.0000 1.0000
20.9600 1444.0000 1.0000
21.0000 1456.0000 1.0000
21.0400 1442.0000 1.0000
21.0800 1437.0000 1.0000
21.1200 1362.0000 1.0000
21.1600 1375.0000 1.0000
21.2000 1413.0000 1.0000
21.2400 1438.0000 1.0000
21.2800 1418.0000 1.0000
21.3200 1504.0000 1.0000
21.3600 1452.0000 1.0000
21.4000 1451.0000 1.0000
21.4400 1483.0000 1.0000
21.4800 1461.0000 1.0000
21.5200 1407.0000 1.0000
21.5600 1476.0000 1.0000
21.6000 1467.0000 1.0000
21.6400 1438.0000 1.0000
21.6800 1454.0000 1.0000
21.7200 1446.0000 1.0000
21.7600 1439.0000 1.0000
21.8000 1474.0000 1.0000
21.8400 1475.0000 1.0000
21.8800 1468.0000 1.0000
21.9200 1459.0000 1.0000
21.9600 1376.0000 1.0000
22.0000 1488.0000 1.0000
22.0400 1456.0000 1.0000
22.0800 1470.0000 1.0000
22.1200 1508.0000 1.0000
22.1600 1462.0000 1.0000
22.2000 1461.0000 1.0000
22.2400 1479.0000 1.0000
22.2800 1448.0000 1.0000
22.3200 1480.0000 1.0000
22.3600 1425.0000 1.0000
22.4000 1492.0000 1.0000
22.4400 1444.0000 1.0000
22.4800 1452.0000 1.0000
22.5200 1446.0000 1.0000
22.5600 1482.0000 1.0000
22.6000 1402.0000 1.0000
22.6400 1473.0000 1.0000
22.6800 1475.0000 1.0000
22.7200 1488.0000 1.0000
22.7600 1444.0000 1.0000
22.8000 1485.0000 1.0000
22.8400 1432.0000 1.0000
22.8800 1465.0000 1.0000
22.9200 1503.0000 1.0000
22.9600 1474.0000 1.0000
23.0000 1506.0000 1.0000
23.0400 1465.0000 1.0000
23.0800 1505.0000 1.0000
23.1200 1479.0000 1.0000
23.1600 1490.0000 1.0000
23.2000 1504.0000 1.0000
23.2400 1497.0000 1.0000
23.2800 1413.0000 1.0000
23.3200 1502.0000 1.0000
23.3600 1442.0000 1.0000
23.4000 1470.0000 1.0000
23.4400 1493.0000 1.0000
23.4800 1490.0000 1.0000
23.5200 1477.0000 1.0000
23.5600 1486.0000 1.0000
23.6000 1516.0000 1.0000
23.6400 1490.0000 1.0000
23.6800 1489.0000 1.0000
23.7200 1494.0000 1.0000
23.7600 1536.0000 1.0000
23.8000 1430.0000 1.0000
23.8400 1546.0000 1.0000
23.8800 1482.0000 1.0000
23.9200 1459.0000 1.0000
23.9600 1508.0000 1.0000
24.0000 1505.0000 1.0000
24.0400 1491.0000 1.0000
24.0800 1509.0000 1.0000
24.1200 1486.0000 1.0000
24.1600 1556.0000 1.0000
24.2000 1442.0000 1.0000
24.2400 1518.0000 1.0000
24.2800 1530.0000 1.0000
24.3200 1506.0000 1.0000
24.3600 1549.0000 1.0000
24.4000 1541.0000 1.0000
24.4400 1511.0000 1.0000
24.4800 1530.0000 1.0000
24.5200 1519.0000 1.0000
24.5600 1541.0000 1.0000
24.6000 1505.0000 1.0000
24.6400 1582.0000 1.0000
24.6800 1580.0000 1.0000
24.7200 1533.0000 1.0000
24.7600 1522.0000 1.0000
24.8000 1581.0000 1.0000
24.8400 1481.0000 1.0000
24.8800 1536.0000 1.0000
24.9200 1517.0000 1.0000
24.9600 1598.0000 1.0000
25.0000 1519.0000 1.0000
25.0400 1565.0000 1.0000
25.0800 1615.0000 1.0000
25.1200 1590.0000 1.0000
25.1600 1486.0000 1.0000
25.2000 1563.0000 1.0000
25.2400 1542.0000 1.0000
25.2800 1548.0000 1.0000
25.3200 1539.0000 1.0000
25.3600 1593.0000 1.0000
25.4000 1573.0000 1.0000
25.4400 1539.0000 1.0000
25.4800 1532.0000 1.0000
25.5200 1557.0000 1.0000
25.5600 1511.0000 1.0000
25.6000 1549.0000 1.0000
25.6400 1529.0000 1.0000
25.6800 1555.0000 1.0000
25.7200 1462.0000 1.0000
25.7600 1576.0000 1.0000
25.8000 1510.0000 1.0000
25.8400 1490.0000 1.0000
25.8800 1570.0000 1.0000
25.9200 1562.0000 1.0000
25.9600 1503.0000 1.0000
26.0000 1609.0000 1.0000
26.0400 1477.0000 1.0000
26.0800 1586.0000 1.0000
26.1200 1519.0000 1.0000
26.1600 1590.0000 1.0000
26.2000 1628.0000 1.0000
26.2400 1498.0000 1.0000
26.2800 1563.0000 1.0000
26.3200 1623.0000 1.0000
26.3600 1511.0000 1.0000
26.4000 1569.0000 1.0000
26.4400 1608.0000 1.0000
26.4800 1629.0000 1.0000
26.5200 1651.0000 1.0000
26.5600 1648.0000 1.0000
26.6000 1606.0000 1.0000
26.6400 1687.0000 1.0000
26.6800 1637.0000 1.0000
26.7200 1710.0000 1.0000
26.7600 1768.0000 1.0000
26.8000 1653.0000 1.0000
26.8400 1811.0000 1.0000
26.8800 1781.0000 1.0000
26.9200 1915.0000 1.0000
26.9600 2040.0000 1.0000
27.0000 2154.0000 1.0000
27.0400 2321.0000 1.0000
27.0800 2547.0000 1.0000
27.1200 2888.0000 1.0000
27.1600 3487.0000 1.0000
27.2000 4293.0000 1.0000
27.2400 5282.0000 1.0000
27.2800 6249.0000 1.0000
27.3200 6450.0000 1.0000
27.3600 5767.0000 1.0000
27.4000 4726.0000 1.0000
27.4400 3858.0000 1.0000
27.4800 3198.0000 1.0000
27.5200 2648.0000 1.0000
27.5600 2421.0000 1.0000
27.6000 2272.0000 1.0000
27.6400 2009.0000 1.0000
27.6800 1884.0000 1.0000
27.7200 1893.0000 1.0000
27.7600 1764.0000 1.0000
27.8000 1727.0000 1.0000
27.8400 1712.0000 1.0000
27.8800 1703.0000 1.0000
27.9200 1651.0000 1.0000
27.9600 1640.0000 1.0000
28.0000 1656.0000 1.0000
28.0400 1614.0000 1.0000
28.0800 1586.0000 1.0000
28.1200 1627.0000 1.0000
28.1600 1608.0000 1.0000
28.2000 1608.0000 1.0000
28.2400 1552.0000 1.0000
28.2800 1520.0000 1.0000
28.3200 1547.0000 1.0000
28.3600 1490.0000 1.0000
28.4000 1572.0000 1.0000
28.4400 1565.0000 1.0000
28.4800 1528.0000 1.0000
28.5200 1568.0000 1.0000
28.5600 1519.0000 1.0000
28.6000 1504.0000 1.0000
28.6400 1485.0000 1.0000
28.6800 1477.0000 1.0000
28.7200 1481.0000 1.0000
28.7600 1464.0000 1.0000
28.8000 1523.0000 1.0000
28.8400 1593.0000 1.0000
28.8800 1513.0000 1.0000
28.9200 1533.0000 1.0000
28.9600 1475.0000 1.0000
29.0000 1467.0000 1.0000
29.0400 1465.0000 1.0000
29.0800 1448.0000 1.0000
29.1200 1444.0000 1.0000
29.1600 1441.0000 1.0000
29.2000 1449.0000 1.0000
29.2400 1422.0000 1.0000
29.2800 1441.0000 1.0000
29.3200 1448.0000 1.0000
29.3600 1454.0000 1.0000
29.4000 1377.0000 1.0000
29.4400 1441.0000 1.0000
29.4800 1433.0000 1.0000
29.5200 1414.0000 1.0000
29.5600 1470.0000 1.0000
29.6000 1471.0000 1.0000
29.6400 1517.0000 1.0000
29.6800 1470.0000 1.0000
29.7200 1453.0000 1.0000
29.7600 1421.0000 1.0000
29.8000 1461.0000 1.0000
29.8400 1445.0000 1.0000
29.8800 1433.0000 1.0000
29.9200 1466.0000 1.0000
29.9600 1432.0000 1.0000
30.0000 1497.0000 1.0000
30.0400 1381.0000 1.0000
30.0800 1426.0000 1.0000
30.1200 1410.0000 1.0000
30.1600 1428.0000 1.0000
30.2000 1382.0000 1.0000
30.2400 1436.0000 1.0000
30.2800 1375.0000 1.0000
30.3200 1424.0000 1.0000
30.3600 1444.0000 1.0000
30.4000 1399.0000 1.0000
30.4400 1339.0000 1.0000
30.4800 1389.0000 1.0000
30.5200 1379.0000 1.0000
30.5600 1426.0000 1.0000
30.6000 1372.0000 1.0000
30.6400 1355.0000 1.0000
30.6800 1428.0000 1.0000
30.7200 1381.0000 1.0000
30.7600 1378.0000 1.0000
30.8000 1397.0000 1.0000
30.8400 1355.0000 1.0000
30.8800 1342.0000 1.0000
30.9200 1350.0000 1.0000
30.9600 1369.0000 1.0000
31.0000 1367.0000 1.0000
31.0400 1375.0000 1.0000
31.0800 1366.0000 1.0000
31.1200 1378.0000 1.0000
31.1600 1380.0000 1.0000
31.2000 1354.0000 1.0000
31.2400 1379.0000 1.0000
31.2800 1327.0000 1.0000
31.3200 1381.0000 1.0000
31.3600 1373.0000 1.0000
31.4000 1341.0000 1.0000
31.4400 1362.0000 1.0000
31.4800 1296.0000 1.0000
31.5200 1372.0000 1.0000
31.5600 1325.0000 1.0000
31.6000 1360.0000 1.0000
31.6400 1306.0000 1.0000
31.6800 1323.0000 1.0000
31.7200 1359.0000 1.0000
31.7600 1344.0000 1.0000
31.8000 1381.0000 1.0000
31.8400 1340.0000 1.0000
31.8800 1315.0000 1.0000
31.9200 1345.0000 1.0000
31.9600 1420.0000 1.0000
32.0000 1320.0000 1.0000
32.0400 1277.0000 1.0000
32.0800 1390.0000 1.0000
32.1200 1394.0000 1.0000
32.1600 1331.0000 1.0000
32.2000 1291.0000 1.0000
32.2400 1296.0000 1.0000
32.2800 1287.0000 1.0000
32.3200 1336.0000 1.0000
32.3600 1331.0000 1.0000
32.4000 1283.0000 1.0000
32.4400 1296.0000 1.0000
32.4800 1253.0000 1.0000
32.5200 1267.0000 1.0000
32.5600 1252.0000 1.0000
32.6000 1275.0000 1.0000
32.6400 1268.0000 1.0000
32.6800 1228.0000 1.0000
32.7200 1247.0000 1.0000
32.7600 1274.0000 1.0000
32.8000 1244.0000 1.0000
32.8400 1283.0000 1.0000
32.8800 1296.0000 1.0000
32.9200 1272.0000 1.0000
32.9600 1240.0000 1.0000
33.0000 1275.0000 1.0000
33.0400 1242.0000 1.0000
33.0800 1215.0000 1.0000
33.1200 1254.0000 1.0000
33.1600 1295.0000 1.0000
33.2000 1197.0000 1.0000
33.2400 1187.0000 1.0000
33.2800 1230.0000 1.0000
33.3200 1283.0000 1.0000
33.3600 1234.0000 1.0000
33.4000 1267.0000 1.0000
33.4400 1275.0000 1.0000
33.4800 1252.0000 1.0000
33.5200 1259.0000 1.0000
33.5600 1279.0000 1.0000
33.6000 1256.0000 1.0000
33.6400 1221.0000 1.0000
33.6800 1272.0000 1.0000
33.7200 1264.0000 1.0000
33.7600 1300.0000 1.0000
33.8000 1350.0000 1.0000
33.8400 1336.0000 1.0000
33.8800 1299.0000 1.0000
33.9200 1413.0000 1.0000
33.9600 1299.0000 1.0000
34.0000 1392.0000 1.0000
34.0400 1403.0000 1.0000
34.0800 1388.0000 1.0000
34.1200 1470.0000 1.0000
34.1600 1414.0000 1.0000
34.2000 1482.0000 1.0000
34.2400 1612.0000 1.0000
34.2800 1738.0000 1.0000
34.3200 1921.0000 1.0000
34.3600 2178.0000 1.0000
34.4000 2640.0000 1.0000
34.4400 3133.0000 1.0000
34.4800 3473.0000 1.0000
34.5200 3412.0000 1.0000
34.5600 3144.0000 1.0000
34.6000 2651.0000 1.0000
34.6400 2339.0000 1.0000
34.6800 1921.0000 1.0000
34.7200 1757.0000 1.0000
34.7600 1590.0000 1.0000
34.8000 1477.0000 1.0000
34.8400 1389.0000 1.0000
34.8800 1355.0000 1.0000
34.9200 1301.0000 1.0000
34.9600 1351.0000 1.0000
35.0000 1222.0000 1.0000
35.0400 1248.0000 1.0000
35.0800 1201.0000 1.0000
35.1200 1147.0000 1.0000
35.1600 1193.0000 1.0000
35.2000 1178.0000 1.0000
35.2400 1129.0000 1.0000
35.2800 1134.0000 1.0000
35.3200 1110.0000 1.0000
35.3600 1055.0000 1.0000
35.4000 1095.0000 1.0000
35.4400 1145.0000 1.0000
35.4800 1079.0000 1.0000
35.5200 1120.0000 1.0000
35.5600 1084.0000 1.0000
35.6000 1042.0000 1.0000
35.6400 1078.0000 1.0000
35.6800 1043.0000 1.0000
35.7200 1093.0000 1.0000
35.7600 1070.0000 1.0000
35.8000 1066.0000 1.0000
35.8400 1071.0000 1.0000
35.8800 1023.0000 1.0000
35.9200 1042.0000 1.0000
35.9600 1075.0000 1.0000
36.0000 1091.0000 1.0000
36.0400 1051.0000 1.0000
36.0800 1106.0000 1.0000
36.1200 1052.0000 1.0000
36.1600 1070.0000 1.0000
36.2000 1096.0000 1.0000
36.2400 1082.0000 1.0000
36.2800 1145.0000 1.0000
36.3200 1135.0000 1.0000
36.3600 1229.0000 1.0000
36.4000 1209.0000 1.0000
36.4400 1213.0000 1.0000
36.4800 1132.0000 1.0000
36.5200 1174.0000 1.0000
36.5600 1086.0000 1.0000
36.6000 1115.0000 1.0000
36.6400 1040.0000 1.0000
36.6800 1007.0000 1.0000
36.7200 1074.0000 1.0000
36.7600 983.0000 1.0000
36.8000 980.0000 1.0000
36.8400 996.0000 1.0000
36.8800 990.0000 1.0000
36.9200 971.0000 1.0000
36.9600 1041.0000 1.0000
37.0000 975.0000 1.0000
37.0400 948.0000 1.0000
37.0800 997.0000 1.0000
37.1200 1018.0000 1.0000
37.1600 929.0000 1.0000
37.2000 921.0000 1.0000
37.2400 946.0000 1.0000
37.2800 984.0000 1.0000
37.3200 959.0000 1.0000
37.3600 933.0000 1.0000
37.4000 981.0000 1.0000
37.4400 959.0000 1.0000
37.4800 963.0000 1.0000
37.5200 993.0000 1.0000
37.5600 934.0000 1.0000
37.6000 965.0000 1.0000
37.6400 978.0000 1.0000
37.6800 950.0000 1.0000
37.7200 990.0000 1.0000
37.7600 1009.0000 1.0000
37.8000 1002.0000 1.0000
37.8400 1016.0000 1.0000
37.8800 1020.0000 1.0000
37.9200 985.0000 1.0000
37.9600 998.0000 1.0000
38.0000 1095.0000 1.0000
38.0400 1060.0000 1.0000
38.0800 1105.0000 1.0000
38.1200 1151.0000 1.0000
38.1600 1214.0000 1.0000
38.2000 1366.0000 1.0000
38.2400 1435.0000 1.0000
38.2800 1669.0000 1.0000
38.3200 1986.0000 1.0000
38.3600 2447.0000 1.0000
38.4000 3212.0000 1.0000
38.4400 4293.0000 1.0000
38.4800 5469.0000 1.0000
38.5200 6229.0000 1.0000
38.5600 6113.0000 1.0000
38.6000 5533.0000 1.0000
38.6400 4522.0000 1.0000
38.6800 3577.0000 1.0000
38.7200 2674.0000 1.0000
38.7600 2104.0000 1.0000
38.8000 1693.0000 1.0000
38.8400 1459.0000 1.0000
38.8800 1338.0000 1.0000
38.9200 1160.0000 1.0000
38.9600 1089.0000 1.0000
39.0000 1040.0000 1.0000
39.0400 998.0000 1.0000
39.0800 983.0000 1.0000
39.1200 929.0000 1.0000
39.1600 958.0000 1.0000
39.2000 927.0000 1.0000
39.2400 906.0000 1.0000
39.2800 868.0000 1.0000
39.3200 879.0000 1.0000
39.3600 930.0000 1.0000
39.4000 908.0000 1.0000
39.4400 863.0000 1.0000
39.4800 917.0000 1.0000
39.5200 958.0000 1.0000
39.5600 919.0000 1.0000
39.6000 858.0000 1.0000
39.6400 899.0000 1.0000
39.6800 910.0000 1.0000
39.7200 863.0000 1.0000
39.7600 824.0000 1.0000
39.8000 842.0000 1.0000
39.8400 905.0000 1.0000
39.8800 834.0000 1.0000
39.9200 840.0000 1.0000
39.9600 884.0000 1.0000
40.0000 799.0000 1.0000
40.0400 817.0000 1.0000
40.0800 824.0000 1.0000
40.1200 816.0000 1.0000
40.1600 808.0000 1.0000
40.2000 816.0000 1.0000
40.2400 794.0000 1.0000
40.2800 793.0000 1.0000
40.3200 805.0000 1.0000
40.3600 819.0000 1.0000
40.4000 832.0000 1.0000
40.4400 801.0000 1.0000
40.4800 794.0000 1.0000
40.5200 783.0000 1.0000
40.5600 785.0000 1.0000
40.6000 786.0000 1.0000
40.6400 754.0000 1.0000
40.6800 813.0000 1.0000
40.7200 825.0000 1.0000
40.7600 785.0000 1.0000
40.8000 777.0000 1.0000
40.8400 843.0000 1.0000
40.8800 762.0000 1.0000
40.9200 810.0000 1.0000
40.9600 776.0000 1.0000
41.0000 769.0000 1.0000
41.0400 780.0000 1.0000
41.0800 758.0000 1.0000
41.1200 813.0000 1.0000
41.1600 710.0000 1.0000
41.2000 780.0000 1.0000
41.2400 789.0000 1.0000
41.2800 744.0000 1.0000
41.3200 784.0000 1.0000
41.3600 768.0000 1.0000
41.4000 802.0000 1.0000
41.4400 772.0000 1.0000
41.4800 813.0000 1.0000
41.5200 772.0000 1.0000
41.5600 798.0000 1.0000
41.6000 825.0000 1.0000
41.6400 781.0000 1.0000
41.6800 737.0000 1.0000
41.7200 800.0000 1.0000
41.7600 753.0000 1.0000
41.8000 785.0000 1.0000
41.8400 760.0000 1.0000
41.8800 790.0000 1.0000
41.9200 805.0000 1.0000
41.9600 798.0000 1.0000
42.0000 784.0000 1.0000
42.0400 771.0000 1.0000
42.0800 773.0000 1.0000
42.1200 731.0000 1.0000
42.1600 820.0000 1.0000
42.2000 761.0000 1.0000
42.2400 779.0000 1.0000
42.2800 729.0000 1.0000
42.3200 815.0000 1.0000
42.3600 781.0000 1.0000
42.4000 784.0000 1.0000
42.4400 797.0000 1.0000
42.4800 761.0000 1.0000
42.5200 712.0000 1.0000
42.5600 748.0000 1.0000
42.6000 758.0000 1.0000
42.6400 751.0000 1.0000
42.6800 817.0000 1.0000
42.7200 765.0000 1.0000
42.7600 749.0000 1.0000
42.8000 793.0000 1.0000
42.8400 773.0000 1.0000
42.8800 784.0000 1.0000
42.9200 770.0000 1.0000
42.9600 765.0000 1.0000
43.0000 837.0000 1.0000
43.0400 750.0000 1.0000
43.0800 785.0000 1.0000
43.1200 789.0000 1.0000
43.1600 842.0000 1.0000
43.2000 821.0000 1.0000
43.2400 855.0000 1.0000
43.2800 841.0000 1.0000
43.3200 860.0000 1.0000
43.3600 834.0000 1.0000
43.4000 763.0000 1.0000
43.4400 795.0000 1.0000
43.4800 790.0000 1.0000
43.5200 744.0000 1.0000
43.5600 724.0000 1.0000
43.6000 723.0000 1.0000
43.6400 802.0000 1.0000
43.6800 753.0000 1.0000
43.7200 779.0000 1.0000
43.7600 729.0000 1.0000
43.8000 781.0000 1.0000
43.8400 723.0000 1.0000
43.8800 758.0000 1.0000
43.9200 772.0000 1.0000
43.9600 725.0000 1.0000
44.0000 751.0000 1.0000
44.0400 747.0000 1.0000
44.0800 773.0000 1.0000
44.1200 750.0000 1.0000
44.1600 734.0000 1.0000
44.2000 727.0000 1.0000
44.2400 772.0000 1.0000
44.2800 771.0000 1.0000
44.3200 722.0000 1.0000
44.3600 752.0000 1.0000
44.4000 745.0000 1.0000
44.4400 731.0000 1.0000
44.4800 805.0000 1.0000
44.5200 726.0000 1.0000
44.5600 741.0000 1.0000
44.6000 726.0000 1.0000
44.6400 706.0000 1.0000
44.6800 757.0000 1.0000
44.7200 734.0000 1.0000
44.7600 723.0000 1.0000
44.8000 720.0000 1.0000
44.8400 743.0000 1.0000
44.8800 727.0000 1.0000
44.9200 737.0000 1.0000
44.9600 700.0000 1.0000
45.0000 748.0000 1.0000
45.0400 685.0000 1.0000
45.0800 718.0000 1.0000
45.1200 710.0000 1.0000
45.1600 734.0000 1.0000
45.2000 716.0000 1.0000
45.2400 714.0000 1.0000
45.2800 703.0000 1.0000
45.3200 701.0000 1.0000
45.3600 702.0000 1.0000
45.4000 705.0000 1.0000
45.4400 716.0000 1.0000
45.4800 712.0000 1.0000
45.5200 675.0000 1.0000
45.5600 699.0000 1.0000
45.6000 670.0000 1.0000
45.6400 735.0000 1.0000
45.6800 702.0000 1.0000
45.7200 690.0000 1.0000
45.7600 698.0000 1.0000
45.8000 664.0000 1.0000
45.8400 708.0000 1.0000
45.8800 703.0000 1.0000
45.9200 734.0000 1.0000
45.9600 709.0000 1.0000
46.0000 701.0000 1.0000
46.0400 713.0000 1.0000
46.0800 681.0000 1.0000
46.1200 653.0000 1.0000
46.1600 670.0000 1.0000
46.2000 714.0000 1.0000
46.2400 701.0000 1.0000
46.2800 704.0000 1.0000
46.3200 678.0000 1.0000
46.3600 690.0000 1.0000
46.4000 689.0000 1.0000
46.4400 727.0000 1.0000
46.4800 696.0000 1.0000
46.5200 727.0000 1.0000
46.5600 708.0000 1.0000
46.6000 686.0000 1.0000
46.6400 718.0000 1.0000
46.6800 668.0000 1.0000
46.7200 705.0000 1.0000
46.7600 726.0000 1.0000
46.8000 695.0000 1.0000
46.8400 702.0000 1.0000
46.8800 677.0000 1.0000
46.9200 729.0000 1.0000
46.9600 712.0000 1.0000
47.0000 727.0000 1.0000
47.0400 681.0000 1.0000
47.0800 707.0000 1.0000
47.1200 703.0000 1.0000
47.1600 701.0000 1.0000
47.2000 681.0000 1.0000
47.2400 691.0000 1.0000
47.2800 738.0000 1.0000
47.3200 688.0000 1.0000
47.3600 664.0000 1.0000
47.4000 691.0000 1.0000
47.4400 689.0000 1.0000
47.4800 734.0000 1.0000
47.5200 665.0000 1.0000
47.5600 686.0000 1.0000
47.6000 734.0000 1.0000
47.6400 637.0000 1.0000
47.6800 646.0000 1.0000
47.7200 668.0000 1.0000
47.7600 663.0000 1.0000
47.8000 676.0000 1.0000
47.8400 674.0000 1.0000
47.8800 678.0000 1.0000
47.9200 647.0000 1.0000
47.9600 680.0000 1.0000
48.0000 677.0000 1.0000
48.0400 614.0000 1.0000
48.0800 664.0000 1.0000
48.1200 675.0000 1.0000
48.1600 644.0000 1.0000
48.2000 649.0000 1.0000
48.2400 664.0000 1.0000
48.2800 623.0000 1.0000
48.3200 653.0000 1.0000
48.3600 664.0000 1.0000
48.4000 645.0000 1.0000
48.4400 701.0000 1.0000
48.4800 673.0000 1.0000
48.5200 655.0000 1.0000
48.5600 679.0000 1.0000
48.6000 667.0000 1.0000
48.6400 638.0000 1.0000
48.6800 645.0000 1.0000
48.7200 648.0000 1.0000
48.7600 664.0000 1.0000
48.8000 640.0000 1.0000
48.8400 633.0000 1.0000
48.8800 684.0000 1.0000
48.9200 644.0000 1.0000
48.9600 672.0000 1.0000
49.0000 651.0000 1.0000
49.0400 645.0000 1.0000
49.0800 647.0000 1.0000
49.1200 657.0000 1.0000
49.1600 693.0000 1.0000
49.2000 653.0000 1.0000
49.2400 669.0000 1.0000
49.2800 631.0000 1.0000
49.3200 657.0000 1.0000
49.3600 673.0000 1.0000
49.4000 651.0000 1.0000
49.4400 652.0000 1.0000
49.4800 625.0000 1.0000
49.5200 626.0000 1.0000
49.5600 617.0000 1.0000
49.6000 649.0000 1.0000
49.6400 637.0000 1.0000
49.6800 608.0000 1.0000
49.7200 634.0000 1.0000
49.7600 670.0000 1.0000
49.8000 657.0000 1.0000
49.8400 698.0000 1.0000
49.8800 645.0000 1.0000
49.9200 679.0000 1.0000
49.9600 678.0000 1.0000
50.0000 678.0000 1.0000
50.0400 629.0000 1.0000
50.0800 657.0000 1.0000
50.1200 636.0000 1.0000
50.1600 624.0000 1.0000
50.2000 655.0000 1.0000
50.2400 683.0000 1.0000
50.2800 674.0000 1.0000
50.3200 650.0000 1.0000
50.3600 676.0000 1.0000
50.4000 697.0000 1.0000
50.4400 686.0000 1.0000
50.4800 699.0000 1.0000
50.5200 703.0000 1.0000
50.5600 630.0000 1.0000
50.6000 690.0000 1.0000
50.6400 679.0000 1.0000
50.6800 704.0000 1.0000
50.7200 671.0000 1.0000
50.7600 674.0000 1.0000
50.8000 698.0000 1.0000
50.8400 642.0000 1.0000
50.8800 722.0000 1.0000
50.9200 688.0000 1.0000
50.9600 670.0000 1.0000
51.0000 699.0000 1.0000
51.0400 666.0000 1.0000
51.0800 620.0000 1.0000
51.1200 677.0000 1.0000
51.1600 637.0000 1.0000
51.2000 682.0000 1.0000
51.2400 667.0000 1.0000
51.2800 677.0000 1.0000
51.3200 675.0000 1.0000
51.3600 703.0000 1.0000
51.4000 636.0000 1.0000
51.4400 651.0000 1.0000
51.4800 678.0000 1.0000
51.5200 701.0000 1.0000
51.5600 731.0000 1.0000
51.6000 716.0000 1.0000
51.6400 652.0000 1.0000
51.6800 722.0000 1.0000
51.7200 709.0000 1.0000
51.7600 770.0000 1.0000
51.8000 773.0000 1.0000
51.8400 793.0000 1.0000
51.8800 876.0000 1.0000
51.9200 934.0000 1.0000
51.9600 1034.0000 1.0000
52.0000 1149.0000 1.0000
52.0400 1316.0000 1.0000
52.0800 1649.0000 1.0000
52.1200 2029.0000 1.0000
52.1600 2920.0000 1.0000
52.2000 4047.0000 1.0000
52.2400 5355.0000 1.0000
52.2800 5790.0000 1.0000
52.3200 5082.0000 1.0000
52.3600 4510.0000 1.0000
52.4000 4207.0000 1.0000
52.4400 3270.0000 1.0000
52.4800 2504.0000 1.0000
52.5200 1842.0000 1.0000
52.5600 1438.0000 1.0000
52.6000 1251.0000 1.0000
52.6400 1032.0000 1.0000
52.6800 989.0000 1.0000
52.7200 894.0000 1.0000
52.7600 828.0000 1.0000
52.8000 802.0000 1.0000
52.8400 780.0000 1.0000
52.8800 769.0000 1.0000
52.9200 728.0000 1.0000
52.9600 748.0000 1.0000
53.0000 715.0000 1.0000
53.0400 662.0000 1.0000
53.0800 679.0000 1.0000
53.1200 668.0000 1.0000
53.1600 684.0000 1.0000
53.2000 639.0000 1.0000
53.2400 672.0000 1.0000
53.2800 666.0000 1.0000
53.3200 656.0000 1.0000
53.3600 694.0000 1.0000
53.4000 656.0000 1.0000
53.4400 659.0000 1.0000
53.4800 717.0000 1.0000
53.5200 636.0000 1.0000
53.5600 614.0000 1.0000
53.6000 637.0000 1.0000
53.6400 626.0000 1.0000
53.6800 673.0000 1.0000
53.7200 657.0000 1.0000
53.7600 673.0000 1.0000
53.8000 636.0000 1.0000
53.8400 633.0000 1.0000
53.8800 628.0000 1.0000
53.9200 655.0000 1.0000
53.9600 609.0000 1.0000
54.0000 631.0000 1.0000
54.0400 656.0000 1.0000
54.0800 617.0000 1.0000
54.1200 652.0000 1.0000
54.1600 702.0000 1.0000
54.2000 629.0000 1.0000
54.2400 691.0000 1.0000
54.2800 614.0000 1.0000
54.3200 659.0000 1.0000
54.3600 656.0000 1.0000
54.4000 663.0000 1.0000
54.4400 663.0000 1.0000
54.4800 643.0000 1.0000
54.5200 638.0000 1.0000
54.5600 671.0000 1.0000
54.6000 660.0000 1.0000
54.6400 637.0000 1.0000
54.6800 665.0000 1.0000
54.7200 667.0000 1.0000
54.7600 726.0000 1.0000
54.8000 673.0000 1.0000
54.8400 640.0000 1.0000
54.8800 692.0000 1.0000
54.9200 694.0000 1.0000
54.9600 728.0000 1.0000
55.0000 733.0000 1.0000
55.0400 794.0000 1.0000
55.0800 754.0000 1.0000
55.1200 797.0000 1.0000
55.1600 857.0000 1.0000
55.2000 907.0000 1.0000
55.2400 990.0000 1.0000
55.2800 989.0000 1.0000
55.3200 1048.0000 1.0000
55.3600 962.0000 1.0000
55.4000 915.0000 1.0000
55.4400 955.0000 1.0000
55.4800 813.0000 1.0000
55.5200 791.0000 1.0000
55.5600 794.0000 1.0000
55.6000 783.0000 1.0000
55.6400 729.0000 1.0000
55.6800 699.0000 1.0000
55.7200 654.0000 1.0000
55.7600 660.0000 1.0000
55.8000 679.0000 1.0000
55.8400 692.0000 1.0000
55.8800 647.0000 1.0000
55.9200 613.0000 1.0000
55.9600 658.0000 1.0000
56.0000 637.0000 1.0000
56.0400 601.0000 1.0000
56.0800 616.0000 1.0000
56.1200 622.0000 1.0000
56.1600 636.0000 1.0000
56.2000 648.0000 1.0000
56.2400 663.0000 1.0000
56.2800 604.0000 1.0000
56.3200 616.0000 1.0000
56.3600 630.0000 1.0000
56.4000 598.0000 1.0000
56.4400 600.0000 1.0000
56.4800 623.0000 1.0000
56.5200 596.0000 1.0000
56.5600 659.0000 1.0000
56.6000 613.0000 1.0000
56.6400 589.0000 1.0000
56.6800 569.0000 1.0000
56.7200 566.0000 1.0000
56.7600 596.0000 1.0000
56.8000 625.0000 1.0000
56.8400 641.0000 1.0000
56.8800 609.0000 1.0000
56.9200 600.0000 1.0000
56.9600 610.0000 1.0000
57.0000 624.0000 1.0000
57.0400 606.0000 1.0000
57.0800 616.0000 1.0000
57.1200 626.0000 1.0000
57.1600 565.0000 1.0000
57.2000 624.0000 1.0000
57.2400 634.0000 1.0000
57.2800 621.0000 1.0000
57.3200 600.0000 1.0000
57.3600 581.0000 1.0000
57.4000 588.0000 1.0000
57.4400 564.0000 1.0000
57.4800 596.0000 1.0000
57.5200 643.0000 1.0000
57.5600 623.0000 1.0000
57.6000 651.0000 1.0000
57.6400 574.0000 1.0000
57.6800 628.0000 1.0000
57.7200 591.0000 1.0000
57.7600 581.0000 1.0000
57.8000 584.0000 1.0000
57.8400 611.0000 1.0000
57.8800 614.0000 1.0000
57.9200 621.0000 1.0000
57.9600 603.0000 1.0000
58.0000 616.0000 1.0000
58.0400 619.0000 1.0000
58.0800 602.0000 1.0000
58.1200 620.0000 1.0000
58.1600 617.0000 1.0000
58.2000 596.0000 1.0000
58.2400 568.0000 1.0000
58.2800 612.0000 1.0000
58.3200 636.0000 1.0000
58.3600 621.0000 1.0000
58.4000 606.0000 1.0000
58.4400 617.0000 1.0000
58.4800 620.0000 1.0000
58.5200 630.0000 1.0000
58.5600 569.0000 1.0000
58.6000 603.0000 1.0000
58.6400 631.0000 1.0000
58.6800 642.0000 1.0000
58.7200 644.0000 1.0000
58.7600 620.0000 1.0000
58.8000 600.0000 1.0000
58.8400 599.0000 1.0000
58.8800 612.0000 1.0000
58.9200 579.0000 1.0000
58.9600 634.0000 1.0000
59.0000 554.0000 1.0000
59.0400 642.0000 1.0000
59.0800 603.0000 1.0000
59.1200 617.0000 1.0000
59.1600 595.0000 1.0000
59.2000 613.0000 1.0000
59.2400 606.0000 1.0000
59.2800 664.0000 1.0000
59.3200 611.0000 1.0000
59.3600 620.0000 1.0000
59.4000 604.0000 1.0000
59.4400 602.0000 1.0000
59.4800 621.0000 1.0000
59.5200 652.0000 1.0000
59.5600 608.0000 1.0000
59.6000 606.0000 1.0000
59.6400 593.0000 1.0000
59.6800 580.0000 1.0000
59.7200 582.0000 1.0000
59.7600 610.0000 1.0000
59.8000 619.0000 1.0000
59.8400 633.0000 1.0000
59.8800 647.0000 1.0000
59.9200 580.0000 1.0000
59.9600 585.0000 1.0000
60.0000 622.0000 1.0000
60.0400 606.0000 1.0000
60.0800 626.0000 1.0000
60.1200 626.0000 1.0000
60.1600 634.0000 1.0000
60.2000 638.0000 1.0000
60.2400 596.0000 1.0000
60.2800 610.0000 1.0000
60.3200 599.0000 1.0000
60.3600 582.0000 1.0000
60.4000 566.0000 1.0000
60.4400 640.0000 1.0000
60.4800 599.0000 1.0000
60.5200 609.0000 1.0000
60.5600 611.0000 1.0000
60.6000 632.0000 1.0000
60.6400 613.0000 1.0000
60.6800 620.0000 1.0000
60.7200 574.0000 1.0000
60.7600 595.0000 1.0000
60.8000 621.0000 1.0000
60.8400 587.0000 1.0000
60.8800 626.0000 1.0000
60.9200 587.0000 1.0000
60.9600 642.0000 1.0000
61.0000 589.0000 1.0000
61.0400 577.0000 1.0000
61.0800 574.0000 1.0000
61.1200 540.0000 1.0000
61.1600 581.0000 1.0000
61.2000 633.0000 1.0000
61.2400 609.0000 1.0000
61.2800 648.0000 1.0000
61.3200 595.0000 1.0000
61.3600 638.0000 1.0000
61.4000 660.0000 1.0000
61.4400 606.0000 1.0000
61.4800 639.0000 1.0000
61.5200 617.0000 1.0000
61.5600 614.0000 1.0000
61.6000 611.0000 1.0000
61.6400 639.0000 1.0000
61.6800 624.0000 1.0000
61.7200 636.0000 1.0000
61.7600 692.0000 1.0000
61.8000 674.0000 1.0000
61.8400 625.0000 1.0000
61.8800 723.0000 1.0000
61.9200 747.0000 1.0000
61.9600 739.0000 1.0000
62.0000 812.0000 1.0000
62.0400 830.0000 1.0000
62.0800 919.0000 1.0000
62.1200 1001.0000 1.0000
62.1600 1143.0000 1.0000
62.2000 1302.0000 1.0000
62.2400 1388.0000 1.0000
62.2800 1510.0000 1.0000
62.3200 1425.0000 1.0000
62.3600 1408.0000 1.0000
62.4000 1287.0000 1.0000
62.4400 1267.0000 1.0000
62.4800 1169.0000 1.0000
62.5200 1110.0000 1.0000
62.5600 969.0000 1.0000
62.6000 936.0000 1.0000
62.6400 857.0000 1.0000
62.6800 819.0000 1.0000
62.7200 772.0000 1.0000
62.7600 756.0000 1.0000
62.8000 688.0000 1.0000
62.8400 706.0000 1.0000
62.8800 647.0000 1.0000
62.9200 665.0000 1.0000
62.9600 657.0000 1.0000
63.0000 640.0000 1.0000
63.0400 654.0000 1.0000
63.0800 632.0000 1.0000
63.1200 646.0000 1.0000
63.1600 673.0000 1.0000
63.2000 676.0000 1.0000
63.2400 611.0000 1.0000
63.2800 642.0000 1.0000
63.3200 626.0000 1.0000
63.3600 616.0000 1.0000
63.4000 643.0000 1.0000
63.4400 616.0000 1.0000
63.4800 597.0000 1.0000
63.5200 582.0000 1.0000
63.5600 583.0000 1.0000
63.6000 606.0000 1.0000
63.6400 599.0000 1.0000
63.6800 616.0000 1.0000
63.7200 606.0000 1.0000
63.7600 614.0000 1.0000
63.8000 604.0000 1.0000
63.8400 657.0000 1.0000
63.8800 630.0000 1.0000
63.9200 612.0000 1.0000
63.9600 628.0000 1.0000
64.0000 611.0000 1.0000
64.0400 590.0000 1.0000
64.0800 584.0000 1.0000
64.1200 583.0000 1.0000
64.1600 642.0000 1.0000
64.2000 608.0000 1.0000
64.2400 628.0000 1.0000
64.2800 637.0000 1.0000
64.3200 644.0000 1.0000
64.3600 655.0000 1.0000
64.4000 615.0000 1.0000
64.4400 571.0000 1.0000
64.4800 672.0000 1.0000
64.5200 597.0000 1.0000
64.5600 633.0000 1.0000
64.6000 622.0000 1.0000
64.6400 671.0000 1.0000
64.6800 620.0000 1.0000
64.7200 696.0000 1.0000
64.7600 719.0000 1.0000
64.8000 678.0000 1.0000
64.8400 661.0000 1.0000
64.8800 617.0000 1.0000
64.9200 640.0000 1.0000
64.9600 698.0000 1.0000
65.0000 655.0000 1.0000
65.0400 622.0000 1.0000
65.0800 613.0000 1.0000
65.1200 687.0000 1.0000
65.1600 705.0000 1.0000
65.2000 662.0000 1.0000
65.2400 624.0000 1.0000
65.2800 649.0000 1.0000
65.3200 596.0000 1.0000
65.3600 615.0000 1.0000
65.4000 643.0000 1.0000
65.4400 621.0000 1.0000
65.4800 647.0000 1.0000
65.5200 673.0000 1.0000
65.5600 631.0000 1.0000
65.6000 641.0000 1.0000
65.6400 647.0000 1.0000
65.6800 695.0000 1.0000
65.7200 683.0000 1.0000
65.7600 673.0000 1.0000
65.8000 726.0000 1.0000
65.8400 696.0000 1.0000
65.8800 767.0000 1.0000
65.9200 836.0000 1.0000
65.9600 929.0000 1.0000
66.0000 1009.0000 1.0000
66.0400 1150.0000 1.0000
66.0800 1304.0000 1.0000
66.1200 1635.0000 1.0000
66.1600 2150.0000 1.0000
66.2000 2613.0000 1.0000
66.2400 2755.0000 1.0000
66.2800 2717.0000 1.0000
66.3200 2434.0000 1.0000
66.3600 2430.0000 1.0000
66.4000 2313.0000 1.0000
66.4400 2109.0000 1.0000
66.4800 1853.0000 1.0000
66.5200 1514.0000 1.0000
66.5600 1278.0000 1.0000
66.6000 1116.0000 1.0000
66.6400 975.0000 1.0000
66.6800 877.0000 1.0000
66.7200 794.0000 1.0000
66.7600 759.0000 1.0000
66.8000 698.0000 1.0000
66.8400 707.0000 1.0000
66.8800 673.0000 1.0000
66.9200 648.0000 1.0000
66.9600 634.0000 1.0000
67.0000 622.0000 1.0000
67.0400 606.0000 1.0000
67.0800 623.0000 1.0000
67.1200 625.0000 1.0000
67.1600 614.0000 1.0000
67.2000 582.0000 1.0000
67.2400 598.0000 1.0000
67.2800 584.0000 1.0000
67.3200 599.0000 1.0000
67.3600 560.0000 1.0000
67.4000 594.0000 1.0000
67.4400 580.0000 1.0000
67.4800 513.0000 1.0000
67.5200 579.0000 1.0000
67.5600 570.0000 1.0000
67.6000 557.0000 1.0000
67.6400 583.0000 1.0000
67.6800 592.0000 1.0000
67.7200 573.0000 1.0000
67.7600 528.0000 1.0000
67.8000 534.0000 1.0000
67.8400 567.0000 1.0000
67.8800 526.0000 1.0000
67.9200 545.0000 1.0000
67.9600 612.0000 1.0000
68.0000 526.0000 1.0000
68.0400 549.0000 1.0000
68.0800 549.0000 1.0000
68.1200 541.0000 1.0000
68.1600 528.0000 1.0000
68.2000 544.0000 1.0000
68.2400 566.0000 1.0000
68.2800 565.0000 1.0000
68.3200 554.0000 1.0000
68.3600 556.0000 1.0000
68.4000 566.0000 1.0000
68.4400 535.0000 1.0000
68.4800 575.0000 1.0000
68.5200 544.0000 1.0000
68.5600 541.0000 1.0000
68.6000 522.0000 1.0000
68.6400 580.0000 1.0000
68.6800 550.0000 1.0000
68.7200 543.0000 1.0000
68.7600 527.0000 1.0000
68.8000 496.0000 1.0000
68.8400 544.0000 1.0000
68.8800 556.0000 1.0000
68.9200 558.0000 1.0000
68.9600 533.0000 1.0000
69.0000 492.0000 1.0000
69.0400 519.0000 1.0000
69.0800 536.0000 1.0000
69.1200 532.0000 1.0000
69.1600 544.0000 1.0000
69.2000 528.0000 1.0000
69.2400 546.0000 1.0000
69.2800 521.0000 1.0000
69.3200 556.0000 1.0000
69.3600 510.0000 1.0000
69.4000 556.0000 1.0000
69.4400 553.0000 1.0000
69.4800 558.0000 1.0000
69.5200 533.0000 1.0000
69.5600 551.0000 1.0000
69.6000 565.0000 1.0000
69.6400 496.0000 1.0000
69.6800 529.0000 1.0000
69.7200 547.0000 1.0000
69.7600 530.0000 1.0000
69.8000 533.0000 1.0000
69.8400 520.0000 1.0000
69.8800 520.0000 1.0000
69.9200 507.0000 1.0000
69.9600 492.0000 1.0000
70.0000 520.0000 1.0000
*RAS_INT_END
*RAS_TEMPERATURE_START
*RAS_TEMPERATURE_END
*RAS_DATA_END