File: Section2_75_samples/XRD/No_008_650_12_2.ras
*RAS_DATA_START
*RAS_HEADER_START
*DISP_FMT_X "%.2f"
*DISP_FMT_Y "%.0f"
*DISP_FULLSCALE "3902.0000000000"
*DISP_LINE_COLOR "255.0000000000"
*DISP_LINE_STYLE "0.0000000000"
*DISP_LINE_WIDTH "0.2500000000"
*DISP_NOTE "測定データ-7"
*DISP_OFFSET_Y "0.0000000000"
*DISP_PEAKSEARCH_UNIT_Y "cps"
*DISP_RANGE_BOTTOM "0.0000000000"
*DISP_RANGE_LEFT "20.0000000000"
*DISP_RANGE_LOGCUTOFF "0.0100000000"
*DISP_RANGE_RIGHT "80.0000000000"
*DISP_RANGE_TOP "3902.0000000000"
*DISP_SCALE_MODE_Y "0.0000000000"
*DISP_TAB_NAME "2θ/θ"
*DISP_TITLE_Y "強度"
*DISP_UNIT_Y "cps"
*DISP_WINDOW_NAME "MSG_MACROENGINE"
*FILE_COMMENT " "
*FILE_MD5 ""
*FILE_MEMO " "
*FILE_OPERATOR "Administrator"
*FILE_SAMPLE "hematite"
*FILE_TYPE "RAS_RAW"
*FILE_USERGROUP "システムマネージャ"
*FILE_VERSION "1.0000000000"
*HW_ATTACHMENT_ID "ATT0025"
*HW_ATTACHMENT_NAME "標準|Standard"
*HW_COUNTER_ID-0 "CUT0025"
*HW_COUNTER_ID-1 "CUT0020"
*HW_COUNTER_ID-2 "CUT0020"
*HW_COUNTER_ID-3 "CSL0021"
*HW_COUNTER_ID-4 "CMC0021"
*HW_COUNTER_NAME-0 "D/teX Ultra|D/teX Ultra"
*HW_COUNTER_NAME-1 "None|None"
*HW_COUNTER_NAME-2 "None|None"
*HW_COUNTER_NAME-3 "BBM|BBM"
*HW_COUNTER_NAME-4 "検出器モノクロメータ|Detector monochromator"
*HW_COUNTER_SELECT_NAME "D/teX Ultra|D/teX Ultra"
*HW_GONIOMETER_ID "GON0023"
*HW_GONIOMETER_NAME "SmartLab|SmartLab"
*HW_GONIOMETER_RADIUS-0 "90.0"
*HW_GONIOMETER_RADIUS-1 "114.0"
*HW_GONIOMETER_RADIUS-2 "190.0"
*HW_GONIOMETER_RADIUS-3 "300.0"
*HW_GONIOMETER_RADIUS-4 "187.0"
*HW_GONIOMETER_RADIUS-5 "300.0"
*HW_GONIOMETER_RADIUS-6 "113.0"
*HW_GONIOMETER_RADIUS-7 "331.0"
*HW_I_OPT_ID-0 "CBO0021"
*HW_I_OPT_ID-1 "ICR0023"
*HW_I_OPT_ID-2 "ISL0021"
*HW_I_OPT_ID-3 "ISO0021"
*HW_I_OPT_ID-4 "IAD0021"
*HW_I_OPT_ID-5 "IPR0001"
*HW_I_OPT_NAME-0 "CBOユニット|CBO unit"
*HW_I_OPT_NAME-1 "標準入射光学ユニット|Standard incident optical unit"
*HW_I_OPT_NAME-2 "標準入射スリットボックス|Standard incident slit box"
*HW_I_OPT_NAME-3 "入射平行スリット|Incident parallel slit"
*HW_I_OPT_NAME-4 "長手制限スリット|Length limiting slit"
*HW_I_OPT_NAME-5 "None|None"
*HW_R_ATTENUATER_AUTOMODE "0"
*HW_R_OPT_ID-0 "RSS0021"
*HW_R_OPT_ID-1 "RCR0023"
*HW_R_OPT_ID-2 "RSO0021"
*HW_R_OPT_ID-3 "RRS0021"
*HW_R_OPT_ID-4 "ATN0021"
*HW_R_OPT_ID-5 "RFL0021"
*HW_R_OPT_ID-6 "RAD0021"
*HW_R_OPT_NAME-0 "標準受光スリットボックス1|Standard receiving slit box # 1"
*HW_R_OPT_NAME-1 "標準受光光学ユニット1|Standard receiving unit # 1"
*HW_R_OPT_NAME-2 "標準受光光学ユニット2|Standard receiving optical unit # 2"
*HW_R_OPT_NAME-3 "標準受光スリットボックス2|Standard receiving slit box # 2"
*HW_R_OPT_NAME-4 "標準アッテネータ|Standard Attenuator"
*HW_R_OPT_NAME-5 "Cu Kβ|Cu K-beta"
*HW_R_OPT_NAME-6 "調整用受光スリット|Alignment receiving slit"
*HW_SAMPLE_HOLDER_ID "SMP0023"
*HW_SAMPLE_HOLDER_NAME "標準Zステージ|Standard Z stage"
*HW_XG_CURRENT_MAX "50"
*HW_XG_CURRENT_MIN "2"
*HW_XG_CURRENT_RESOLUTION "2"
*HW_XG_CURRENT_UNIT "mA"
*HW_XG_FOCUS "1mm x 10mm"
*HW_XG_FOCUS_TYPE "Normal"
*HW_XG_ID ""
*HW_XG_NAME "3kW 封入管(ID:1200)|3kW Sealed tube(ID:1200)"
*HW_XG_TARGET_ATOMIC_NUMBER "29.0000000000"
*HW_XG_TARGET_NAME "Cu"
*HW_XG_TYPE "Hermetic"
*HW_XG_VOLTAGE_MAX "60"
*HW_XG_VOLTAGE_MIN "20"
*HW_XG_VOLTAGE_RESOLUTION "2"
*HW_XG_VOLTAGE_UNIT "kV"
*HW_XG_WATT_MAX "2"
*HW_XG_WATT_UNIT "kW"
*HW_XG_WAVE_LENGTH_ALPHA1 "1.540593"
*HW_XG_WAVE_LENGTH_ALPHA2 "1.544414"
*HW_XG_WAVE_LENGTH_BETA "1.392250"
*MEAS_COND_AXIS_NAME-0 "2θ/θ"
*MEAS_COND_AXIS_NAME-1 "2θ"
*MEAS_COND_AXIS_NAME-2 "ω"
*MEAS_COND_AXIS_NAME-3 "Z"
*MEAS_COND_AXIS_NAME-4 "2θ/ω"
*MEAS_COND_AXIS_NAME-5 "θs"
*MEAS_COND_AXIS_NAME-6 "θd"
*MEAS_COND_AXIS_NAME-7 "Ts"
*MEAS_COND_AXIS_NAME-8 "CBO選択スリット"
*MEAS_COND_AXIS_NAME-9 "M"
*MEAS_COND_AXIS_NAME-10 "入射平行スリット"
*MEAS_COND_AXIS_NAME-11 "入射スリット"
*MEAS_COND_AXIS_NAME-12 ""
*MEAS_COND_AXIS_NAME-13 "Zs"
*MEAS_COND_AXIS_NAME-14 "入射光学素子"
*MEAS_COND_AXIS_NAME-15 "長手制限スリット"
*MEAS_COND_AXIS_NAME-16 "センタースリット"
*MEAS_COND_AXIS_NAME-17 "フィルター"
*MEAS_COND_AXIS_NAME-18 "受光スリット1"
*MEAS_COND_AXIS_NAME-19 "受光スリット2"
*MEAS_COND_AXIS_NAME-20 "受光光学素子"
*MEAS_COND_AXIS_NAME-21 "受光平行スリット"
*MEAS_COND_AXIS_NAME-22 "調整用受光スリット"
*MEAS_COND_AXIS_NAME-23 ""
*MEAS_COND_AXIS_NAME-24 ""
*MEAS_COND_AXIS_NAME-25 "Zd"
*MEAS_COND_AXIS_NAME-26 "アッテネータ"
*MEAS_COND_AXIS_NAME-27 "検出器モノクロメータ"
*MEAS_COND_AXIS_NAME-28 "モノクロメータスリット"
*MEAS_COND_AXIS_NAME-29 "プライマリビーム"
*MEAS_COND_AXIS_NAME-30 "PHA"
*MEAS_COND_AXIS_NAME_INTERNAL-0 "TwoThetaTheta"
*MEAS_COND_AXIS_NAME_INTERNAL-1 "TwoTheta"
*MEAS_COND_AXIS_NAME_INTERNAL-2 "Omega"
*MEAS_COND_AXIS_NAME_INTERNAL-3 "Z"
*MEAS_COND_AXIS_NAME_INTERNAL-4 "TwoThetaOmega"
*MEAS_COND_AXIS_NAME_INTERNAL-5 "ThetaS"
*MEAS_COND_AXIS_NAME_INTERNAL-6 "ThetaD"
*MEAS_COND_AXIS_NAME_INTERNAL-7 "Ts"
*MEAS_COND_AXIS_NAME_INTERNAL-8 "CBO"
*MEAS_COND_AXIS_NAME_INTERNAL-9 "CBO-M"
*MEAS_COND_AXIS_NAME_INTERNAL-10 "IncidentSollerSlit"
*MEAS_COND_AXIS_NAME_INTERNAL-11 "IncidentSlitBox"
*MEAS_COND_AXIS_NAME_INTERNAL-12 "IncidentSlitBox-_Axis"
*MEAS_COND_AXIS_NAME_INTERNAL-13 "Zs"
*MEAS_COND_AXIS_NAME_INTERNAL-14 "IncidentMonochromator"
*MEAS_COND_AXIS_NAME_INTERNAL-15 "IncidentAxdSlit"
*MEAS_COND_AXIS_NAME_INTERNAL-16 "CenterSlit"
*MEAS_COND_AXIS_NAME_INTERNAL-17 "Filter"
*MEAS_COND_AXIS_NAME_INTERNAL-18 "ReceivingSlitBox1"
*MEAS_COND_AXIS_NAME_INTERNAL-19 "ReceivingSlitBox2"
*MEAS_COND_AXIS_NAME_INTERNAL-20 "ReceivingOptics"
*MEAS_COND_AXIS_NAME_INTERNAL-21 "ReceivingSollerSlit"
*MEAS_COND_AXIS_NAME_INTERNAL-22 "ReceivingAxdSlit"
*MEAS_COND_AXIS_NAME_INTERNAL-23 "ReceivingSlitBox1-_Axis"
*MEAS_COND_AXIS_NAME_INTERNAL-24 "ReceivingSlitBox2-_Axis"
*MEAS_COND_AXIS_NAME_INTERNAL-25 "ReceivingSlitBox2-Zd"
*MEAS_COND_AXIS_NAME_INTERNAL-26 "Attenuator"
*MEAS_COND_AXIS_NAME_INTERNAL-27 "CounterMonochromator"
*MEAS_COND_AXIS_NAME_INTERNAL-28 "CounterSlit"
*MEAS_COND_AXIS_NAME_INTERNAL-29 "IncidentPrimary"
*MEAS_COND_AXIS_NAME_INTERNAL-30 "PHA"
*MEAS_COND_AXIS_NAME_MAGICNO-0 "83951616.0000000000"
*MEAS_COND_AXIS_NAME_MAGICNO-1 "268632064.0000000000"
*MEAS_COND_AXIS_NAME_MAGICNO-2 "268500992.0000000000"
*MEAS_COND_AXIS_NAME_MAGICNO-3 "285278208.0000000000"
*MEAS_COND_AXIS_NAME_MAGICNO-4 "83951616.0000000000"
*MEAS_COND_AXIS_NAME_MAGICNO-5 "131072.0000000000"
*MEAS_COND_AXIS_NAME_MAGICNO-6 "131072.0000000000"
*MEAS_COND_AXIS_NAME_MAGICNO-7 "318898176.0000000000"
*MEAS_COND_AXIS_NAME_MAGICNO-8 "20971521.0000000000"
*MEAS_COND_AXIS_NAME_MAGICNO-9 "285343744.0000000000"
*MEAS_COND_AXIS_NAME_MAGICNO-10 "20971521.0000000000"
*MEAS_COND_AXIS_NAME_MAGICNO-11 "22020097.0000000000"
*MEAS_COND_AXIS_NAME_MAGICNO-12 "25165824.0000000000"
*MEAS_COND_AXIS_NAME_MAGICNO-13 "318898176.0000000000"
*MEAS_COND_AXIS_NAME_MAGICNO-14 "1.0000000000"
*MEAS_COND_AXIS_NAME_MAGICNO-15 "20971521.0000000000"
*MEAS_COND_AXIS_NAME_MAGICNO-16 "20971521.0000000000"
*MEAS_COND_AXIS_NAME_MAGICNO-17 "20971521.0000000000"
*MEAS_COND_AXIS_NAME_MAGICNO-18 "23068673.0000000000"
*MEAS_COND_AXIS_NAME_MAGICNO-19 "23068673.0000000000"
*MEAS_COND_AXIS_NAME_MAGICNO-20 "20971521.0000000000"
*MEAS_COND_AXIS_NAME_MAGICNO-21 "20971521.0000000000"
*MEAS_COND_AXIS_NAME_MAGICNO-22 "20971521.0000000000"
*MEAS_COND_AXIS_NAME_MAGICNO-23 "25165824.0000000000"
*MEAS_COND_AXIS_NAME_MAGICNO-24 "25165824.0000000000"
*MEAS_COND_AXIS_NAME_MAGICNO-25 "285343744.0000000000"
*MEAS_COND_AXIS_NAME_MAGICNO-26 "17301505.0000000000"
*MEAS_COND_AXIS_NAME_MAGICNO-27 "20971521.0000000000"
*MEAS_COND_AXIS_NAME_MAGICNO-28 "20971521.0000000000"
*MEAS_COND_AXIS_NAME_MAGICNO-29 "20971521.0000000000"
*MEAS_COND_AXIS_NAME_MAGICNO-30 "0.0000000000"
*MEAS_COND_AXIS_OFFSET-0 "-"
*MEAS_COND_AXIS_OFFSET-1 "-0.1081000000"
*MEAS_COND_AXIS_OFFSET-2 "0.3758000000"
*MEAS_COND_AXIS_OFFSET-3 "-"
*MEAS_COND_AXIS_OFFSET-4 "-"
*MEAS_COND_AXIS_OFFSET-5 "0.3758000000"
*MEAS_COND_AXIS_OFFSET-6 "-0.4839000000"
*MEAS_COND_AXIS_OFFSET-7 "-"
*MEAS_COND_AXIS_OFFSET-8 "-"
*MEAS_COND_AXIS_OFFSET-9 "-"
*MEAS_COND_AXIS_OFFSET-10 "-"
*MEAS_COND_AXIS_OFFSET-11 "-"
*MEAS_COND_AXIS_OFFSET-12 "-"
*MEAS_COND_AXIS_OFFSET-13 "-"
*MEAS_COND_AXIS_OFFSET-14 "-"
*MEAS_COND_AXIS_OFFSET-15 "-"
*MEAS_COND_AXIS_OFFSET-16 "-"
*MEAS_COND_AXIS_OFFSET-17 "-"
*MEAS_COND_AXIS_OFFSET-18 "-"
*MEAS_COND_AXIS_OFFSET-19 "-"
*MEAS_COND_AXIS_OFFSET-20 "-"
*MEAS_COND_AXIS_OFFSET-21 "-"
*MEAS_COND_AXIS_OFFSET-22 "-"
*MEAS_COND_AXIS_OFFSET-23 "-"
*MEAS_COND_AXIS_OFFSET-24 "-"
*MEAS_COND_AXIS_OFFSET-25 "-"
*MEAS_COND_AXIS_OFFSET-26 "-"
*MEAS_COND_AXIS_OFFSET-27 "-"
*MEAS_COND_AXIS_OFFSET-28 "-"
*MEAS_COND_AXIS_OFFSET-29 "-"
*MEAS_COND_AXIS_OFFSET-30 "-"
*MEAS_COND_AXIS_POSITION-0 "0.0000000000"
*MEAS_COND_AXIS_POSITION-1 "0.0000000000"
*MEAS_COND_AXIS_POSITION-2 "0.0000000000"
*MEAS_COND_AXIS_POSITION-3 "-0.5500000000"
*MEAS_COND_AXIS_POSITION-4 "0.0000000000"
*MEAS_COND_AXIS_POSITION-5 "0.0000000000"
*MEAS_COND_AXIS_POSITION-6 "0.0000000000"
*MEAS_COND_AXIS_POSITION-7 "-0.4278800000"
*MEAS_COND_AXIS_POSITION-8 "BB"
*MEAS_COND_AXIS_POSITION-9 "0.0000000000"
*MEAS_COND_AXIS_POSITION-10 "Soller_slit_5.0deg"
*MEAS_COND_AXIS_POSITION-11 "2/3deg"
*MEAS_COND_AXIS_POSITION-12 "2.2088000000"
*MEAS_COND_AXIS_POSITION-13 "-0.4140600000"
*MEAS_COND_AXIS_POSITION-14 "0.0000000000"
*MEAS_COND_AXIS_POSITION-15 "10.0mm"
*MEAS_COND_AXIS_POSITION-16 "None"
*MEAS_COND_AXIS_POSITION-17 "Cu_K-beta"
*MEAS_COND_AXIS_POSITION-18 "13.000mm"
*MEAS_COND_AXIS_POSITION-19 "13.000mm"
*MEAS_COND_AXIS_POSITION-20 "No_unit"
*MEAS_COND_AXIS_POSITION-21 "Soller_slit_5.0deg"
*MEAS_COND_AXIS_POSITION-22 "None"
*MEAS_COND_AXIS_POSITION-23 "13.0000000000"
*MEAS_COND_AXIS_POSITION-24 "13.0000000000"
*MEAS_COND_AXIS_POSITION-25 "0.0109400000"
*MEAS_COND_AXIS_POSITION-26 "Open"
*MEAS_COND_AXIS_POSITION-27 "None"
*MEAS_COND_AXIS_POSITION-28 "None"
*MEAS_COND_AXIS_POSITION-29 "None"
*MEAS_COND_AXIS_POSITION-30 "38.0000000000"
*MEAS_COND_AXIS_UNIT-0 "deg"
*MEAS_COND_AXIS_UNIT-1 "deg"
*MEAS_COND_AXIS_UNIT-2 "deg"
*MEAS_COND_AXIS_UNIT-3 "mm"
*MEAS_COND_AXIS_UNIT-4 "deg"
*MEAS_COND_AXIS_UNIT-5 "deg"
*MEAS_COND_AXIS_UNIT-6 "deg"
*MEAS_COND_AXIS_UNIT-7 "mm"
*MEAS_COND_AXIS_UNIT-8 ""
*MEAS_COND_AXIS_UNIT-9 "pulse"
*MEAS_COND_AXIS_UNIT-10 ""
*MEAS_COND_AXIS_UNIT-11 ""
*MEAS_COND_AXIS_UNIT-12 "mm"
*MEAS_COND_AXIS_UNIT-13 "mm"
*MEAS_COND_AXIS_UNIT-14 ""
*MEAS_COND_AXIS_UNIT-15 ""
*MEAS_COND_AXIS_UNIT-16 ""
*MEAS_COND_AXIS_UNIT-17 ""
*MEAS_COND_AXIS_UNIT-18 ""
*MEAS_COND_AXIS_UNIT-19 ""
*MEAS_COND_AXIS_UNIT-20 ""
*MEAS_COND_AXIS_UNIT-21 ""
*MEAS_COND_AXIS_UNIT-22 ""
*MEAS_COND_AXIS_UNIT-23 "mm"
*MEAS_COND_AXIS_UNIT-24 "mm"
*MEAS_COND_AXIS_UNIT-25 "mm"
*MEAS_COND_AXIS_UNIT-26 ""
*MEAS_COND_AXIS_UNIT-27 ""
*MEAS_COND_AXIS_UNIT-28 ""
*MEAS_COND_AXIS_UNIT-29 ""
*MEAS_COND_AXIS_UNIT-30 "div"
*MEAS_COND_COUNTER_CNTLOSS_CORR "0.0000000000"
*MEAS_COND_COUNTER_PHABASE "38.0000000000"
*MEAS_COND_COUNTER_PHAWINDOW "16.0000000000"
*MEAS_COND_COUNTER_PHA_UNIT "div"
*MEAS_COND_COUNTER_TAUDIFF "30.0000000000"
*MEAS_COND_COUNTER_TAUINT "0.0000000000"
*MEAS_COND_IRRADIATION_MODE "OFF"
*MEAS_COND_IRRADIATION_WIDTH ""
*MEAS_COND_OPT_ATTR "集中法"
*MEAS_COND_OPT_NAME "@集中法"
*MEAS_COND_UNSYMMETRIC_MODE "OFF"
*MEAS_COND_XG_CURRENT "30.0000000000"
*MEAS_COND_XG_VOLTAGE "40.0000000000"
*MEAS_COND_XG_WAVE_TYPE "Ka"
*MEAS_DATA_COUNT "3001.0000000000"
*MEAS_SCAN_AXIS_X "2θ/θ"
*MEAS_SCAN_AXIS_X_INTERNAL "TwoThetaTheta"
*MEAS_SCAN_END_TIME "08/21/20 15:31:43"
*MEAS_SCAN_MODE "CONTINUOUS"
*MEAS_SCAN_MONITOR "0"
*MEAS_SCAN_RESOLUTION_X "0.0002"
*MEAS_SCAN_SPEED "2.0"
*MEAS_SCAN_SPEED_UNIT "deg/min"
*MEAS_SCAN_START "20.0000000000"
*MEAS_SCAN_START_TIME "08/21/20 15:00:04"
*MEAS_SCAN_STEP "0.0200000000"
*MEAS_SCAN_STOP "80.0000000000"
*MEAS_SCAN_UNIT_X "deg"
*MEAS_SCAN_UNIT_Y "counts"
*RAS_HEADER_END
*RAS_INT_START
20.0000 1951.0000 1.0000
20.0600 1943.0000 1.0000
20.1200 1760.0000 1.0000
20.1800 1789.0000 1.0000
20.2400 1800.0000 1.0000
20.3000 1862.0000 1.0000
20.3600 1790.0000 1.0000
20.4200 1839.0000 1.0000
20.4800 1808.0000 1.0000
20.5400 1752.0000 1.0000
20.6000 1757.0000 1.0000
20.6600 1783.0000 1.0000
20.7200 1762.0000 1.0000
20.7800 1746.0000 1.0000
20.8400 1686.0000 1.0000
20.9000 1778.0000 1.0000
20.9600 1686.0000 1.0000
21.0200 1688.0000 1.0000
21.0800 1663.0000 1.0000
21.1400 1728.0000 1.0000
21.2000 1688.0000 1.0000
21.2600 1692.0000 1.0000
21.3200 1657.0000 1.0000
21.3800 1625.0000 1.0000
21.4400 1609.0000 1.0000
21.5000 1631.0000 1.0000
21.5600 1671.0000 1.0000
21.6200 1536.0000 1.0000
21.6800 1579.0000 1.0000
21.7400 1642.0000 1.0000
21.8000 1628.0000 1.0000
21.8600 1549.0000 1.0000
21.9200 1556.0000 1.0000
21.9800 1554.0000 1.0000
22.0400 1596.0000 1.0000
22.1000 1495.0000 1.0000
22.1600 1519.0000 1.0000
22.2200 1573.0000 1.0000
22.2800 1553.0000 1.0000
22.3400 1519.0000 1.0000
22.4000 1510.0000 1.0000
22.4600 1486.0000 1.0000
22.5200 1508.0000 1.0000
22.5800 1426.0000 1.0000
22.6400 1476.0000 1.0000
22.7000 1468.0000 1.0000
22.7600 1476.0000 1.0000
22.8200 1411.0000 1.0000
22.8800 1440.0000 1.0000
22.9400 1452.0000 1.0000
23.0000 1411.0000 1.0000
23.0600 1393.0000 1.0000
23.1200 1380.0000 1.0000
23.1800 1334.0000 1.0000
23.2400 1442.0000 1.0000
23.3000 1380.0000 1.0000
23.3600 1392.0000 1.0000
23.4200 1337.0000 1.0000
23.4800 1381.0000 1.0000
23.5400 1371.0000 1.0000
23.6000 1301.0000 1.0000
23.6600 1380.0000 1.0000
23.7200 1290.0000 1.0000
23.7800 1280.0000 1.0000
23.8400 1332.0000 1.0000
23.9000 1313.0000 1.0000
23.9600 1297.0000 1.0000
24.0200 1310.0000 1.0000
24.0800 1298.0000 1.0000
24.1400 1288.0000 1.0000
24.2000 1290.0000 1.0000
24.2600 1289.0000 1.0000
24.3200 1286.0000 1.0000
24.3800 1260.0000 1.0000
24.4400 1227.0000 1.0000
24.5000 1264.0000 1.0000
24.5600 1255.0000 1.0000
24.6200 1196.0000 1.0000
24.6800 1236.0000 1.0000
24.7400 1184.0000 1.0000
24.8000 1209.0000 1.0000
24.8600 1182.0000 1.0000
24.9200 1188.0000 1.0000
24.9800 1143.0000 1.0000
25.0400 1186.0000 1.0000
25.1000 1179.0000 1.0000
25.1600 1208.0000 1.0000
25.2200 1221.0000 1.0000
25.2800 1156.0000 1.0000
25.3400 1162.0000 1.0000
25.4000 1209.0000 1.0000
25.4600 1203.0000 1.0000
25.5200 1112.0000 1.0000
25.5800 1145.0000 1.0000
25.6400 1109.0000 1.0000
25.7000 1099.0000 1.0000
25.7600 1068.0000 1.0000
25.8200 1099.0000 1.0000
25.8800 1086.0000 1.0000
25.9400 1093.0000 1.0000
26.0000 1110.0000 1.0000
26.0600 1050.0000 1.0000
26.1200 1062.0000 1.0000
26.1800 1043.0000 1.0000
26.2400 1065.0000 1.0000
26.3000 1092.0000 1.0000
26.3600 1076.0000 1.0000
26.4200 1056.0000 1.0000
26.4800 1061.0000 1.0000
26.5400 1006.0000 1.0000
26.6000 1038.0000 1.0000
26.6600 1039.0000 1.0000
26.7200 987.0000 1.0000
26.7800 1007.0000 1.0000
26.8400 947.0000 1.0000
26.9000 1007.0000 1.0000
26.9600 1016.0000 1.0000
27.0200 1006.0000 1.0000
27.0800 1050.0000 1.0000
27.1400 969.0000 1.0000
27.2000 1005.0000 1.0000
27.2600 961.0000 1.0000
27.3200 948.0000 1.0000
27.3800 960.0000 1.0000
27.4400 977.0000 1.0000
27.5000 916.0000 1.0000
27.5600 991.0000 1.0000
27.6200 962.0000 1.0000
27.6800 973.0000 1.0000
27.7400 1020.0000 1.0000
27.8000 946.0000 1.0000
27.8600 949.0000 1.0000
27.9200 908.0000 1.0000
27.9800 882.0000 1.0000
28.0400 910.0000 1.0000
28.1000 851.0000 1.0000
28.1600 919.0000 1.0000
28.2200 923.0000 1.0000
28.2800 890.0000 1.0000
28.3400 867.0000 1.0000
28.4000 885.0000 1.0000
28.4600 890.0000 1.0000
28.5200 894.0000 1.0000
28.5800 963.0000 1.0000
28.6400 856.0000 1.0000
28.7000 831.0000 1.0000
28.7600 886.0000 1.0000
28.8200 834.0000 1.0000
28.8800 804.0000 1.0000
28.9400 855.0000 1.0000
29.0000 790.0000 1.0000
29.0600 842.0000 1.0000
29.1200 814.0000 1.0000
29.1800 811.0000 1.0000
29.2400 870.0000 1.0000
29.3000 844.0000 1.0000
29.3600 782.0000 1.0000
29.4200 812.0000 1.0000
29.4800 784.0000 1.0000
29.5400 762.0000 1.0000
29.6000 817.0000 1.0000
29.6600 800.0000 1.0000
29.7200 811.0000 1.0000
29.7800 779.0000 1.0000
29.8400 744.0000 1.0000
29.9000 814.0000 1.0000
29.9600 741.0000 1.0000
30.0200 782.0000 1.0000
30.0800 796.0000 1.0000
30.1400 741.0000 1.0000
30.2000 758.0000 1.0000
30.2600 761.0000 1.0000
30.3200 730.0000 1.0000
30.3800 761.0000 1.0000
30.4400 769.0000 1.0000
30.5000 755.0000 1.0000
30.5600 740.0000 1.0000
30.6200 729.0000 1.0000
30.6800 710.0000 1.0000
30.7400 723.0000 1.0000
30.8000 738.0000 1.0000
30.8600 746.0000 1.0000
30.9200 709.0000 1.0000
30.9800 727.0000 1.0000
31.0400 705.0000 1.0000
31.1000 710.0000 1.0000
31.1600 706.0000 1.0000
31.2200 671.0000 1.0000
31.2800 692.0000 1.0000
31.3400 693.0000 1.0000
31.4000 703.0000 1.0000
31.4600 709.0000 1.0000
31.5200 720.0000 1.0000
31.5800 683.0000 1.0000
31.6400 681.0000 1.0000
31.7000 651.0000 1.0000
31.7600 662.0000 1.0000
31.8200 657.0000 1.0000
31.8800 639.0000 1.0000
31.9400 685.0000 1.0000
32.0000 680.0000 1.0000
32.0600 663.0000 1.0000
32.1200 677.0000 1.0000
32.1800 622.0000 1.0000
32.2400 642.0000 1.0000
32.3000 636.0000 1.0000
32.3600 641.0000 1.0000
32.4200 617.0000 1.0000
32.4800 626.0000 1.0000
32.5400 623.0000 1.0000
32.6000 624.0000 1.0000
32.6600 618.0000 1.0000
32.7200 614.0000 1.0000
32.7800 626.0000 1.0000
32.8400 635.0000 1.0000
32.9000 657.0000 1.0000
32.9600 618.0000 1.0000
33.0200 600.0000 1.0000
33.0800 607.0000 1.0000
33.1400 579.0000 1.0000
33.2000 580.0000 1.0000
33.2600 613.0000 1.0000
33.3200 570.0000 1.0000
33.3800 628.0000 1.0000
33.4400 586.0000 1.0000
33.5000 553.0000 1.0000
33.5600 628.0000 1.0000
33.6200 601.0000 1.0000
33.6800 607.0000 1.0000
33.7400 586.0000 1.0000
33.8000 575.0000 1.0000
33.8600 568.0000 1.0000
33.9200 556.0000 1.0000
33.9800 546.0000 1.0000
34.0400 609.0000 1.0000
34.1000 542.0000 1.0000
34.1600 516.0000 1.0000
34.2200 557.0000 1.0000
34.2800 594.0000 1.0000
34.3400 567.0000 1.0000
34.4000 544.0000 1.0000
34.4600 565.0000 1.0000
34.5200 569.0000 1.0000
34.5800 610.0000 1.0000
34.6400 601.0000 1.0000
34.7000 530.0000 1.0000
34.7600 510.0000 1.0000
34.8200 566.0000 1.0000
34.8800 548.0000 1.0000
34.9400 549.0000 1.0000
35.0000 529.0000 1.0000
35.0600 516.0000 1.0000
35.1200 487.0000 1.0000
35.1800 498.0000 1.0000
35.2400 530.0000 1.0000
35.3000 510.0000 1.0000
35.3600 511.0000 1.0000
35.4200 529.0000 1.0000
35.4800 506.0000 1.0000
35.5400 498.0000 1.0000
35.6000 505.0000 1.0000
35.6600 495.0000 1.0000
35.7200 449.0000 1.0000
35.7800 466.0000 1.0000
35.8400 504.0000 1.0000
35.9000 505.0000 1.0000
35.9600 460.0000 1.0000
36.0200 500.0000 1.0000
36.0800 480.0000 1.0000
36.1400 466.0000 1.0000
36.2000 493.0000 1.0000
36.2600 433.0000 1.0000
36.3200 456.0000 1.0000
36.3800 462.0000 1.0000
36.4400 504.0000 1.0000
36.5000 460.0000 1.0000
36.5600 498.0000 1.0000
36.6200 468.0000 1.0000
36.6800 479.0000 1.0000
36.7400 439.0000 1.0000
36.8000 446.0000 1.0000
36.8600 476.0000 1.0000
36.9200 495.0000 1.0000
36.9800 414.0000 1.0000
37.0400 418.0000 1.0000
37.1000 452.0000 1.0000
37.1600 452.0000 1.0000
37.2200 410.0000 1.0000
37.2800 445.0000 1.0000
37.3400 428.0000 1.0000
37.4000 438.0000 1.0000
37.4600 463.0000 1.0000
37.5200 407.0000 1.0000
37.5800 464.0000 1.0000
37.6400 443.0000 1.0000
37.7000 415.0000 1.0000
37.7600 412.0000 1.0000
37.8200 432.0000 1.0000
37.8800 428.0000 1.0000
37.9400 424.0000 1.0000
38.0000 406.0000 1.0000
38.0600 406.0000 1.0000
38.1200 425.0000 1.0000
38.1800 423.0000 1.0000
38.2400 410.0000 1.0000
38.3000 441.0000 1.0000
38.3600 433.0000 1.0000
38.4200 464.0000 1.0000
38.4800 477.0000 1.0000
38.5400 524.0000 1.0000
38.6000 555.0000 1.0000
38.6600 561.0000 1.0000
38.7200 558.0000 1.0000
38.7800 479.0000 1.0000
38.8400 424.0000 1.0000
38.9000 414.0000 1.0000
38.9600 422.0000 1.0000
39.0200 400.0000 1.0000
39.0800 403.0000 1.0000
39.1400 374.0000 1.0000
39.2000 393.0000 1.0000
39.2600 390.0000 1.0000
39.3200 388.0000 1.0000
39.3800 383.0000 1.0000
39.4400 409.0000 1.0000
39.5000 363.0000 1.0000
39.5600 390.0000 1.0000
39.6200 391.0000 1.0000
39.6800 396.0000 1.0000
39.7400 369.0000 1.0000
39.8000 352.0000 1.0000
39.8600 413.0000 1.0000
39.9200 382.0000 1.0000
39.9800 382.0000 1.0000
40.0400 317.0000 1.0000
40.1000 394.0000 1.0000
40.1600 407.0000 1.0000
40.2200 371.0000 1.0000
40.2800 333.0000 1.0000
40.3400 360.0000 1.0000
40.4000 404.0000 1.0000
40.4600 360.0000 1.0000
40.5200 351.0000 1.0000
40.5800 327.0000 1.0000
40.6400 355.0000 1.0000
40.7000 331.0000 1.0000
40.7600 311.0000 1.0000
40.8200 328.0000 1.0000
40.8800 315.0000 1.0000
40.9400 334.0000 1.0000
41.0000 334.0000 1.0000
41.0600 301.0000 1.0000
41.1200 342.0000 1.0000
41.1800 327.0000 1.0000
41.2400 346.0000 1.0000
41.3000 323.0000 1.0000
41.3600 319.0000 1.0000
41.4200 325.0000 1.0000
41.4800 346.0000 1.0000
41.5400 295.0000 1.0000
41.6000 322.0000 1.0000
41.6600 311.0000 1.0000
41.7200 290.0000 1.0000
41.7800 314.0000 1.0000
41.8400 301.0000 1.0000
41.9000 299.0000 1.0000
41.9600 319.0000 1.0000
42.0200 320.0000 1.0000
42.0800 318.0000 1.0000
42.1400 330.0000 1.0000
42.2000 293.0000 1.0000
42.2600 320.0000 1.0000
42.3200 316.0000 1.0000
42.3800 278.0000 1.0000
42.4400 321.0000 1.0000
42.5000 316.0000 1.0000
42.5600 267.0000 1.0000
42.6200 277.0000 1.0000
42.6800 303.0000 1.0000
42.7400 311.0000 1.0000
42.8000 287.0000 1.0000
42.8600 276.0000 1.0000
42.9200 305.0000 1.0000
42.9800 294.0000 1.0000
43.0400 305.0000 1.0000
43.1000 310.0000 1.0000
43.1600 302.0000 1.0000
43.2200 317.0000 1.0000
43.2800 299.0000 1.0000
43.3400 291.0000 1.0000
43.4000 277.0000 1.0000
43.4600 286.0000 1.0000
43.5200 279.0000 1.0000
43.5800 301.0000 1.0000
43.6400 262.0000 1.0000
43.7000 269.0000 1.0000
43.7600 261.0000 1.0000
43.8200 265.0000 1.0000
43.8800 299.0000 1.0000
43.9400 314.0000 1.0000
44.0000 278.0000 1.0000
44.0600 280.0000 1.0000
44.1200 278.0000 1.0000
44.1800 272.0000 1.0000
44.2400 279.0000 1.0000
44.3000 289.0000 1.0000
44.3600 298.0000 1.0000
44.4200 274.0000 1.0000
44.4800 277.0000 1.0000
44.5400 301.0000 1.0000
44.6000 266.0000 1.0000
44.6600 267.0000 1.0000
44.7200 265.0000 1.0000
44.7800 277.0000 1.0000
44.8400 280.0000 1.0000
44.9000 266.0000 1.0000
44.9600 263.0000 1.0000
45.0200 261.0000 1.0000
45.0800 242.0000 1.0000
45.1400 275.0000 1.0000
45.2000 275.0000 1.0000
45.2600 266.0000 1.0000
45.3200 268.0000 1.0000
45.3800 302.0000 1.0000
45.4400 261.0000 1.0000
45.5000 263.0000 1.0000
45.5600 260.0000 1.0000
45.6200 271.0000 1.0000
45.6800 236.0000 1.0000
45.7400 261.0000 1.0000
45.8000 265.0000 1.0000
45.8600 273.0000 1.0000
45.9200 222.0000 1.0000
45.9800 260.0000 1.0000
46.0400 246.0000 1.0000
46.1000 275.0000 1.0000
46.1600 257.0000 1.0000
46.2200 247.0000 1.0000
46.2800 219.0000 1.0000
46.3400 238.0000 1.0000
46.4000 252.0000 1.0000
46.4600 233.0000 1.0000
46.5200 244.0000 1.0000
46.5800 274.0000 1.0000
46.6400 257.0000 1.0000
46.7000 273.0000 1.0000
46.7600 228.0000 1.0000
46.8200 253.0000 1.0000
46.8800 251.0000 1.0000
46.9400 237.0000 1.0000
47.0000 232.0000 1.0000
47.0600 238.0000 1.0000
47.1200 229.0000 1.0000
47.1800 240.0000 1.0000
47.2400 224.0000 1.0000
47.3000 230.0000 1.0000
47.3600 228.0000 1.0000
47.4200 233.0000 1.0000
47.4800 224.0000 1.0000
47.5400 231.0000 1.0000
47.6000 238.0000 1.0000
47.6600 223.0000 1.0000
47.7200 237.0000 1.0000
47.7800 220.0000 1.0000
47.8400 251.0000 1.0000
47.9000 246.0000 1.0000
47.9600 221.0000 1.0000
48.0200 195.0000 1.0000
48.0800 230.0000 1.0000
48.1400 231.0000 1.0000
48.2000 213.0000 1.0000
48.2600 215.0000 1.0000
48.3200 228.0000 1.0000
48.3800 211.0000 1.0000
48.4400 210.0000 1.0000
48.5000 219.0000 1.0000
48.5600 217.0000 1.0000
48.6200 223.0000 1.0000
48.6800 202.0000 1.0000
48.7400 217.0000 1.0000
48.8000 222.0000 1.0000
48.8600 212.0000 1.0000
48.9200 223.0000 1.0000
48.9800 256.0000 1.0000
49.0400 222.0000 1.0000
49.1000 227.0000 1.0000
49.1600 217.0000 1.0000
49.2200 213.0000 1.0000
49.2800 202.0000 1.0000
49.3400 202.0000 1.0000
49.4000 216.0000 1.0000
49.4600 225.0000 1.0000
49.5200 202.0000 1.0000
49.5800 228.0000 1.0000
49.6400 205.0000 1.0000
49.7000 215.0000 1.0000
49.7600 196.0000 1.0000
49.8200 193.0000 1.0000
49.8800 207.0000 1.0000
49.9400 217.0000 1.0000
50.0000 207.0000 1.0000
50.0600 204.0000 1.0000
50.1200 199.0000 1.0000
50.1800 213.0000 1.0000
50.2400 194.0000 1.0000
50.3000 187.0000 1.0000
50.3600 209.0000 1.0000
50.4200 203.0000 1.0000
50.4800 218.0000 1.0000
50.5400 197.0000 1.0000
50.6000 212.0000 1.0000
50.6600 208.0000 1.0000
50.7200 212.0000 1.0000
50.7800 205.0000 1.0000
50.8400 191.0000 1.0000
50.9000 203.0000 1.0000
50.9600 182.0000 1.0000
51.0200 195.0000 1.0000
51.0800 195.0000 1.0000
51.1400 194.0000 1.0000
51.2000 210.0000 1.0000
51.2600 205.0000 1.0000
51.3200 211.0000 1.0000
51.3800 206.0000 1.0000
51.4400 205.0000 1.0000
51.5000 191.0000 1.0000
51.5600 198.0000 1.0000
51.6200 189.0000 1.0000
51.6800 199.0000 1.0000
51.7400 209.0000 1.0000
51.8000 202.0000 1.0000
51.8600 217.0000 1.0000
51.9200 204.0000 1.0000
51.9800 203.0000 1.0000
52.0400 235.0000 1.0000
52.1000 237.0000 1.0000
52.1600 265.0000 1.0000
52.2200 351.0000 1.0000
52.2800 502.0000 1.0000
52.3400 634.0000 1.0000
52.4000 541.0000 1.0000
52.4600 480.0000 1.0000
52.5200 419.0000 1.0000
52.5800 328.0000 1.0000
52.6400 261.0000 1.0000
52.7000 243.0000 1.0000
52.7600 190.0000 1.0000
52.8200 216.0000 1.0000
52.8800 221.0000 1.0000
52.9400 220.0000 1.0000
53.0000 229.0000 1.0000
53.0600 205.0000 1.0000
53.1200 185.0000 1.0000
53.1800 203.0000 1.0000
53.2400 166.0000 1.0000
53.3000 181.0000 1.0000
53.3600 176.0000 1.0000
53.4200 188.0000 1.0000
53.4800 193.0000 1.0000
53.5400 208.0000 1.0000
53.6000 192.0000 1.0000
53.6600 211.0000 1.0000
53.7200 218.0000 1.0000
53.7800 215.0000 1.0000
53.8400 193.0000 1.0000
53.9000 182.0000 1.0000
53.9600 185.0000 1.0000
54.0200 171.0000 1.0000
54.0800 199.0000 1.0000
54.1400 195.0000 1.0000
54.2000 203.0000 1.0000
54.2600 199.0000 1.0000
54.3200 207.0000 1.0000
54.3800 193.0000 1.0000
54.4400 182.0000 1.0000
54.5000 181.0000 1.0000
54.5600 201.0000 1.0000
54.6200 177.0000 1.0000
54.6800 196.0000 1.0000
54.7400 202.0000 1.0000
54.8000 185.0000 1.0000
54.8600 185.0000 1.0000
54.9200 182.0000 1.0000
54.9800 202.0000 1.0000
55.0400 186.0000 1.0000
55.1000 167.0000 1.0000
55.1600 181.0000 1.0000
55.2200 214.0000 1.0000
55.2800 205.0000 1.0000
55.3400 217.0000 1.0000
55.4000 250.0000 1.0000
55.4600 216.0000 1.0000
55.5200 204.0000 1.0000
55.5800 201.0000 1.0000
55.6400 191.0000 1.0000
55.7000 190.0000 1.0000
55.7600 189.0000 1.0000
55.8200 181.0000 1.0000
55.8800 178.0000 1.0000
55.9400 192.0000 1.0000
56.0000 181.0000 1.0000
56.0600 161.0000 1.0000
56.1200 192.0000 1.0000
56.1800 192.0000 1.0000
56.2400 190.0000 1.0000
56.3000 156.0000 1.0000
56.3600 185.0000 1.0000
56.4200 178.0000 1.0000
56.4800 182.0000 1.0000
56.5400 171.0000 1.0000
56.6000 172.0000 1.0000
56.6600 186.0000 1.0000
56.7200 188.0000 1.0000
56.7800 189.0000 1.0000
56.8400 167.0000 1.0000
56.9000 163.0000 1.0000
56.9600 178.0000 1.0000
57.0200 180.0000 1.0000
57.0800 163.0000 1.0000
57.1400 186.0000 1.0000
57.2000 170.0000 1.0000
57.2600 162.0000 1.0000
57.3200 161.0000 1.0000
57.3800 147.0000 1.0000
57.4400 164.0000 1.0000
57.5000 163.0000 1.0000
57.5600 167.0000 1.0000
57.6200 172.0000 1.0000
57.6800 179.0000 1.0000
57.7400 195.0000 1.0000
57.8000 182.0000 1.0000
57.8600 174.0000 1.0000
57.9200 189.0000 1.0000
57.9800 179.0000 1.0000
58.0400 198.0000 1.0000
58.1000 205.0000 1.0000
58.1600 166.0000 1.0000
58.2200 171.0000 1.0000
58.2800 186.0000 1.0000
58.3400 183.0000 1.0000
58.4000 184.0000 1.0000
58.4600 168.0000 1.0000
58.5200 171.0000 1.0000
58.5800 173.0000 1.0000
58.6400 166.0000 1.0000
58.7000 176.0000 1.0000
58.7600 191.0000 1.0000
58.8200 172.0000 1.0000
58.8800 182.0000 1.0000
58.9400 165.0000 1.0000
59.0000 154.0000 1.0000
59.0600 163.0000 1.0000
59.1200 168.0000 1.0000
59.1800 160.0000 1.0000
59.2400 165.0000 1.0000
59.3000 175.0000 1.0000
59.3600 176.0000 1.0000
59.4200 160.0000 1.0000
59.4800 178.0000 1.0000
59.5400 191.0000 1.0000
59.6000 162.0000 1.0000
59.6600 170.0000 1.0000
59.7200 171.0000 1.0000
59.7800 163.0000 1.0000
59.8400 168.0000 1.0000
59.9000 138.0000 1.0000
59.9600 164.0000 1.0000
60.0200 163.0000 1.0000
60.0800 183.0000 1.0000
60.1400 154.0000 1.0000
60.2000 170.0000 1.0000
60.2600 178.0000 1.0000
60.3200 171.0000 1.0000
60.3800 173.0000 1.0000
60.4400 162.0000 1.0000
60.5000 163.0000 1.0000
60.5600 164.0000 1.0000
60.6200 167.0000 1.0000
60.6800 167.0000 1.0000
60.7400 165.0000 1.0000
60.8000 182.0000 1.0000
60.8600 170.0000 1.0000
60.9200 155.0000 1.0000
60.9800 165.0000 1.0000
61.0400 188.0000 1.0000
61.1000 170.0000 1.0000
61.1600 181.0000 1.0000
61.2200 162.0000 1.0000
61.2800 176.0000 1.0000
61.3400 184.0000 1.0000
61.4000 176.0000 1.0000
61.4600 186.0000 1.0000
61.5200 179.0000 1.0000
61.5800 179.0000 1.0000
61.6400 152.0000 1.0000
61.7000 173.0000 1.0000
61.7600 172.0000 1.0000
61.8200 185.0000 1.0000
61.8800 161.0000 1.0000
61.9400 162.0000 1.0000
62.0000 173.0000 1.0000
62.0600 179.0000 1.0000
62.1200 180.0000 1.0000
62.1800 206.0000 1.0000
62.2400 230.0000 1.0000
62.3000 235.0000 1.0000
62.3600 259.0000 1.0000
62.4200 263.0000 1.0000
62.4800 242.0000 1.0000
62.5400 258.0000 1.0000
62.6000 229.0000 1.0000
62.6600 212.0000 1.0000
62.7200 219.0000 1.0000
62.7800 178.0000 1.0000
62.8400 181.0000 1.0000
62.9000 181.0000 1.0000
62.9600 182.0000 1.0000
63.0200 182.0000 1.0000
63.0800 203.0000 1.0000
63.1400 174.0000 1.0000
63.2000 182.0000 1.0000
63.2600 167.0000 1.0000
63.3200 171.0000 1.0000
63.3800 150.0000 1.0000
63.4400 182.0000 1.0000
63.5000 187.0000 1.0000
63.5600 170.0000 1.0000
63.6200 169.0000 1.0000
63.6800 172.0000 1.0000
63.7400 162.0000 1.0000
63.8000 186.0000 1.0000
63.8600 169.0000 1.0000
63.9200 149.0000 1.0000
63.9800 161.0000 1.0000
64.0400 148.0000 1.0000
64.1000 164.0000 1.0000
64.1600 153.0000 1.0000
64.2200 161.0000 1.0000
64.2800 159.0000 1.0000
64.3400 186.0000 1.0000
64.4000 148.0000 1.0000
64.4600 170.0000 1.0000
64.5200 169.0000 1.0000
64.5800 188.0000 1.0000
64.6400 181.0000 1.0000
64.7000 181.0000 1.0000
64.7600 192.0000 1.0000
64.8200 193.0000 1.0000
64.8800 193.0000 1.0000
64.9400 180.0000 1.0000
65.0000 177.0000 1.0000
65.0600 174.0000 1.0000
65.1200 165.0000 1.0000
65.1800 171.0000 1.0000
65.2400 177.0000 1.0000
65.3000 190.0000 1.0000
65.3600 168.0000 1.0000
65.4200 168.0000 1.0000
65.4800 174.0000 1.0000
65.5400 161.0000 1.0000
65.6000 174.0000 1.0000
65.6600 190.0000 1.0000
65.7200 155.0000 1.0000
65.7800 166.0000 1.0000
65.8400 163.0000 1.0000
65.9000 189.0000 1.0000
65.9600 203.0000 1.0000
66.0200 168.0000 1.0000
66.0800 205.0000 1.0000
66.1400 253.0000 1.0000
66.2000 306.0000 1.0000
66.2600 402.0000 1.0000
66.3200 442.0000 1.0000
66.3800 422.0000 1.0000
66.4400 444.0000 1.0000
66.5000 397.0000 1.0000
66.5600 335.0000 1.0000
66.6200 301.0000 1.0000
66.6800 232.0000 1.0000
66.7400 204.0000 1.0000
66.8000 211.0000 1.0000
66.8600 208.0000 1.0000
66.9200 169.0000 1.0000
66.9800 191.0000 1.0000
67.0400 154.0000 1.0000
67.1000 159.0000 1.0000
67.1600 158.0000 1.0000
67.2200 164.0000 1.0000
67.2800 158.0000 1.0000
67.3400 168.0000 1.0000
67.4000 157.0000 1.0000
67.4600 170.0000 1.0000
67.5200 149.0000 1.0000
67.5800 161.0000 1.0000
67.6400 171.0000 1.0000
67.7000 176.0000 1.0000
67.7600 177.0000 1.0000
67.8200 168.0000 1.0000
67.8800 145.0000 1.0000
67.9400 165.0000 1.0000
68.0000 159.0000 1.0000
68.0600 139.0000 1.0000
68.1200 153.0000 1.0000
68.1800 172.0000 1.0000
68.2400 163.0000 1.0000
68.3000 152.0000 1.0000
68.3600 157.0000 1.0000
68.4200 164.0000 1.0000
68.4800 188.0000 1.0000
68.5400 173.0000 1.0000
68.6000 160.0000 1.0000
68.6600 172.0000 1.0000
68.7200 169.0000 1.0000
68.7800 172.0000 1.0000
68.8400 155.0000 1.0000
68.9000 176.0000 1.0000
68.9600 174.0000 1.0000
69.0200 139.0000 1.0000
69.0800 150.0000 1.0000
69.1400 177.0000 1.0000
69.2000 152.0000 1.0000
69.2600 138.0000 1.0000
69.3200 169.0000 1.0000
69.3800 159.0000 1.0000
69.4400 174.0000 1.0000
69.5000 135.0000 1.0000
69.5600 160.0000 1.0000
69.6200 151.0000 1.0000
69.6800 163.0000 1.0000
69.7400 145.0000 1.0000
69.8000 154.0000 1.0000
69.8600 142.0000 1.0000
69.9200 147.0000 1.0000
69.9800 143.0000 1.0000
70.0400 170.0000 1.0000
70.1000 150.0000 1.0000
70.1600 164.0000 1.0000
70.2200 153.0000 1.0000
70.2800 168.0000 1.0000
70.3400 145.0000 1.0000
70.4000 151.0000 1.0000
70.4600 144.0000 1.0000
70.5200 142.0000 1.0000
70.5800 149.0000 1.0000
70.6400 186.0000 1.0000
70.7000 143.0000 1.0000
70.7600 148.0000 1.0000
70.8200 143.0000 1.0000
70.8800 151.0000 1.0000
70.9400 154.0000 1.0000
71.0000 143.0000 1.0000
71.0600 150.0000 1.0000
71.1200 139.0000 1.0000
71.1800 139.0000 1.0000
71.2400 146.0000 1.0000
71.3000 140.0000 1.0000
71.3600 156.0000 1.0000
71.4200 161.0000 1.0000
71.4800 148.0000 1.0000
71.5400 164.0000 1.0000
71.6000 181.0000 1.0000
71.6600 154.0000 1.0000
71.7200 162.0000 1.0000
71.7800 171.0000 1.0000
71.8400 170.0000 1.0000
71.9000 153.0000 1.0000
71.9600 154.0000 1.0000
72.0200 158.0000 1.0000
72.0800 154.0000 1.0000
72.1400 148.0000 1.0000
72.2000 145.0000 1.0000
72.2600 159.0000 1.0000
72.3200 175.0000 1.0000
72.3800 141.0000 1.0000
72.4400 170.0000 1.0000
72.5000 153.0000 1.0000
72.5600 149.0000 1.0000
72.6200 153.0000 1.0000
72.6800 176.0000 1.0000
72.7400 157.0000 1.0000
72.8000 145.0000 1.0000
72.8600 131.0000 1.0000
72.9200 168.0000 1.0000
72.9800 150.0000 1.0000
73.0400 153.0000 1.0000
73.1000 143.0000 1.0000
73.1600 170.0000 1.0000
73.2200 129.0000 1.0000
73.2800 145.0000 1.0000
73.3400 171.0000 1.0000
73.4000 152.0000 1.0000
73.4600 142.0000 1.0000
73.5200 142.0000 1.0000
73.5800 146.0000 1.0000
73.6400 140.0000 1.0000
73.7000 144.0000 1.0000
73.7600 171.0000 1.0000
73.8200 124.0000 1.0000
73.8800 149.0000 1.0000
73.9400 174.0000 1.0000
74.0000 151.0000 1.0000
74.0600 134.0000 1.0000
74.1200 161.0000 1.0000
74.1800 143.0000 1.0000
74.2400 178.0000 1.0000
74.3000 152.0000 1.0000
74.3600 149.0000 1.0000
74.4200 156.0000 1.0000
74.4800 160.0000 1.0000
74.5400 151.0000 1.0000
74.6000 151.0000 1.0000
74.6600 159.0000 1.0000
74.7200 145.0000 1.0000
74.7800 152.0000 1.0000
74.8400 158.0000 1.0000
74.9000 148.0000 1.0000
74.9600 130.0000 1.0000
75.0200 141.0000 1.0000
75.0800 160.0000 1.0000
75.1400 145.0000 1.0000
75.2000 149.0000 1.0000
75.2600 146.0000 1.0000
75.3200 141.0000 1.0000
75.3800 140.0000 1.0000
75.4400 134.0000 1.0000
75.5000 139.0000 1.0000
75.5600 141.0000 1.0000
75.6200 159.0000 1.0000
75.6800 141.0000 1.0000
75.7400 144.0000 1.0000
75.8000 135.0000 1.0000
75.8600 165.0000 1.0000
75.9200 144.0000 1.0000
75.9800 158.0000 1.0000
76.0400 152.0000 1.0000
76.1000 163.0000 1.0000
76.1600 163.0000 1.0000
76.2200 179.0000 1.0000
76.2800 138.0000 1.0000
76.3400 140.0000 1.0000
76.4000 129.0000 1.0000
76.4600 132.0000 1.0000
76.5200 147.0000 1.0000
76.5800 129.0000 1.0000
76.6400 160.0000 1.0000
76.7000 150.0000 1.0000
76.7600 133.0000 1.0000
76.8200 167.0000 1.0000
76.8800 148.0000 1.0000
76.9400 137.0000 1.0000
77.0000 173.0000 1.0000
77.0600 158.0000 1.0000
77.1200 153.0000 1.0000
77.1800 152.0000 1.0000
77.2400 169.0000 1.0000
77.3000 149.0000 1.0000
77.3600 147.0000 1.0000
77.4200 145.0000 1.0000
77.4800 130.0000 1.0000
77.5400 132.0000 1.0000
77.6000 150.0000 1.0000
77.6600 152.0000 1.0000
77.7200 139.0000 1.0000
77.7800 161.0000 1.0000
77.8400 136.0000 1.0000
77.9000 156.0000 1.0000
77.9600 151.0000 1.0000
78.0200 158.0000 1.0000
78.0800 156.0000 1.0000
78.1400 141.0000 1.0000
78.2000 145.0000 1.0000
78.2600 146.0000 1.0000
78.3200 145.0000 1.0000
78.3800 159.0000 1.0000
78.4400 136.0000 1.0000
78.5000 144.0000 1.0000
78.5600 171.0000 1.0000
78.6200 159.0000 1.0000
78.6800 153.0000 1.0000
78.7400 166.0000 1.0000
78.8000 165.0000 1.0000
78.8600 190.0000 1.0000
78.9200 182.0000 1.0000
78.9800 191.0000 1.0000
79.0400 224.0000 1.0000
79.1000 217.0000 1.0000
79.1600 195.0000 1.0000
79.2200 207.0000 1.0000
79.2800 201.0000 1.0000
79.3400 188.0000 1.0000
79.4000 174.0000 1.0000
79.4600 153.0000 1.0000
79.5200 169.0000 1.0000
79.5800 169.0000 1.0000
79.6400 165.0000 1.0000
79.7000 165.0000 1.0000
79.7600 141.0000 1.0000
79.8200 144.0000 1.0000
79.8800 149.0000 1.0000
79.9400 139.0000 1.0000
80.0000 147.0000 1.0000
*RAS_INT_END
*RAS_TEMPERATURE_START
*RAS_TEMPERATURE_END
*RAS_DATA_END