File: Section2_75_samples/XRD/No_059_NSS3_4.ras
*RAS_DATA_START
*RAS_HEADER_START
*DISP_FMT_X "%.2f"
*DISP_FMT_Y "%.0f"
*DISP_FULLSCALE "15470.0000000000"
*DISP_LINE_COLOR "255.0000000000"
*DISP_LINE_STYLE "0.0000000000"
*DISP_LINE_WIDTH "0.2500000000"
*DISP_NOTE "測定データ-3"
*DISP_OFFSET_Y "0.0000000000"
*DISP_PEAKSEARCH_UNIT_Y "cps"
*DISP_RANGE_BOTTOM "0.0000000000"
*DISP_RANGE_LEFT "20.0000000000"
*DISP_RANGE_LOGCUTOFF "0.0100000000"
*DISP_RANGE_RIGHT "70.0000000000"
*DISP_RANGE_TOP "15470.0000000000"
*DISP_SCALE_MODE_Y "0.0000000000"
*DISP_TAB_NAME "2θ/θ"
*DISP_TITLE_Y "強度"
*DISP_UNIT_Y "cps"
*DISP_WINDOW_NAME "MSG_MACROENGINE"
*FILE_COMMENT " "
*FILE_MD5 ""
*FILE_MEMO " "
*FILE_OPERATOR "Administrator"
*FILE_SAMPLE " "
*FILE_TYPE "RAS_RAW"
*FILE_USERGROUP "システムマネージャ"
*FILE_VERSION "1.0000000000"
*HW_ATTACHMENT_ID "ATT0025"
*HW_ATTACHMENT_NAME "標準|Standard"
*HW_COUNTER_ID-0 "CUT0025"
*HW_COUNTER_ID-1 "CUT0020"
*HW_COUNTER_ID-2 "CUT0020"
*HW_COUNTER_ID-3 "CSL0021"
*HW_COUNTER_ID-4 "CMC0021"
*HW_COUNTER_NAME-0 "D/teX Ultra|D/teX Ultra"
*HW_COUNTER_NAME-1 "None|None"
*HW_COUNTER_NAME-2 "None|None"
*HW_COUNTER_NAME-3 "BBM|BBM"
*HW_COUNTER_NAME-4 "検出器モノクロメータ|Detector monochromator"
*HW_COUNTER_SELECT_NAME "D/teX Ultra|D/teX Ultra"
*HW_GONIOMETER_ID "GON0023"
*HW_GONIOMETER_NAME "SmartLab|SmartLab"
*HW_GONIOMETER_RADIUS-0 "90.0"
*HW_GONIOMETER_RADIUS-1 "114.0"
*HW_GONIOMETER_RADIUS-2 "190.0"
*HW_GONIOMETER_RADIUS-3 "300.0"
*HW_GONIOMETER_RADIUS-4 "187.0"
*HW_GONIOMETER_RADIUS-5 "300.0"
*HW_GONIOMETER_RADIUS-6 "113.0"
*HW_GONIOMETER_RADIUS-7 "331.0"
*HW_I_OPT_ID-0 "CBO0021"
*HW_I_OPT_ID-1 "ICR0023"
*HW_I_OPT_ID-2 "ISL0021"
*HW_I_OPT_ID-3 "ISO0021"
*HW_I_OPT_ID-4 "IAD0021"
*HW_I_OPT_ID-5 "IPR0001"
*HW_I_OPT_NAME-0 "CBOユニット|CBO unit"
*HW_I_OPT_NAME-1 "標準入射光学ユニット|Standard incident optical unit"
*HW_I_OPT_NAME-2 "標準入射スリットボックス|Standard incident slit box"
*HW_I_OPT_NAME-3 "入射平行スリット|Incident parallel slit"
*HW_I_OPT_NAME-4 "長手制限スリット|Length limiting slit"
*HW_I_OPT_NAME-5 "None|None"
*HW_R_ATTENUATER_AUTOMODE "0"
*HW_R_OPT_ID-0 "RSS0021"
*HW_R_OPT_ID-1 "RCR0023"
*HW_R_OPT_ID-2 "RSO0021"
*HW_R_OPT_ID-3 "RRS0021"
*HW_R_OPT_ID-4 "ATN0021"
*HW_R_OPT_ID-5 "RFL0021"
*HW_R_OPT_ID-6 "RAD0021"
*HW_R_OPT_NAME-0 "標準受光スリットボックス1|Standard receiving slit box # 1"
*HW_R_OPT_NAME-1 "標準受光光学ユニット1|Standard receiving unit # 1"
*HW_R_OPT_NAME-2 "標準受光光学ユニット2|Standard receiving optical unit # 2"
*HW_R_OPT_NAME-3 "標準受光スリットボックス2|Standard receiving slit box # 2"
*HW_R_OPT_NAME-4 "標準アッテネータ|Standard Attenuator"
*HW_R_OPT_NAME-5 "Cu Kβ|Cu K-beta"
*HW_R_OPT_NAME-6 "調整用受光スリット|Alignment receiving slit"
*HW_SAMPLE_HOLDER_ID "SMP0023"
*HW_SAMPLE_HOLDER_NAME "標準Zステージ|Standard Z stage"
*HW_XG_CURRENT_MAX "50"
*HW_XG_CURRENT_MIN "2"
*HW_XG_CURRENT_RESOLUTION "1"
*HW_XG_CURRENT_UNIT "mA"
*HW_XG_FOCUS "1mm x 10mm"
*HW_XG_FOCUS_TYPE "Normal"
*HW_XG_ID ""
*HW_XG_NAME "3kW 封入管(ID:1200)|3kW Sealed tube(ID:1200)"
*HW_XG_TARGET_ATOMIC_NUMBER "29.0000000000"
*HW_XG_TARGET_NAME "Cu"
*HW_XG_TYPE "Hermetic"
*HW_XG_VOLTAGE_MAX "60"
*HW_XG_VOLTAGE_MIN "20"
*HW_XG_VOLTAGE_RESOLUTION "1"
*HW_XG_VOLTAGE_UNIT "kV"
*HW_XG_WATT_MAX "1.500"
*HW_XG_WATT_UNIT "kW"
*HW_XG_WAVE_LENGTH_ALPHA1 "1.540593"
*HW_XG_WAVE_LENGTH_ALPHA2 "1.544414"
*HW_XG_WAVE_LENGTH_BETA "1.392250"
*MEAS_COND_AXIS_NAME-0 "2θ/θ"
*MEAS_COND_AXIS_NAME-1 "2θ"
*MEAS_COND_AXIS_NAME-2 "ω"
*MEAS_COND_AXIS_NAME-3 "Z"
*MEAS_COND_AXIS_NAME-4 "2θ/ω"
*MEAS_COND_AXIS_NAME-5 "θs"
*MEAS_COND_AXIS_NAME-6 "θd"
*MEAS_COND_AXIS_NAME-7 "Ts"
*MEAS_COND_AXIS_NAME-8 "CBO選択スリット"
*MEAS_COND_AXIS_NAME-9 "M"
*MEAS_COND_AXIS_NAME-10 "入射平行スリット"
*MEAS_COND_AXIS_NAME-11 "入射スリット"
*MEAS_COND_AXIS_NAME-12 ""
*MEAS_COND_AXIS_NAME-13 "Zs"
*MEAS_COND_AXIS_NAME-14 "入射光学素子"
*MEAS_COND_AXIS_NAME-15 "長手制限スリット"
*MEAS_COND_AXIS_NAME-16 "センタースリット"
*MEAS_COND_AXIS_NAME-17 "フィルター"
*MEAS_COND_AXIS_NAME-18 "受光スリット1"
*MEAS_COND_AXIS_NAME-19 "受光スリット2"
*MEAS_COND_AXIS_NAME-20 "受光光学素子"
*MEAS_COND_AXIS_NAME-21 "受光平行スリット"
*MEAS_COND_AXIS_NAME-22 "調整用受光スリット"
*MEAS_COND_AXIS_NAME-23 ""
*MEAS_COND_AXIS_NAME-24 ""
*MEAS_COND_AXIS_NAME-25 "Zd"
*MEAS_COND_AXIS_NAME-26 "アッテネータ"
*MEAS_COND_AXIS_NAME-27 "検出器モノクロメータ"
*MEAS_COND_AXIS_NAME-28 "モノクロメータスリット"
*MEAS_COND_AXIS_NAME-29 "プライマリビーム"
*MEAS_COND_AXIS_NAME-30 "PHA"
*MEAS_COND_AXIS_NAME_INTERNAL-0 "TwoThetaTheta"
*MEAS_COND_AXIS_NAME_INTERNAL-1 "TwoTheta"
*MEAS_COND_AXIS_NAME_INTERNAL-2 "Omega"
*MEAS_COND_AXIS_NAME_INTERNAL-3 "Z"
*MEAS_COND_AXIS_NAME_INTERNAL-4 "TwoThetaOmega"
*MEAS_COND_AXIS_NAME_INTERNAL-5 "ThetaS"
*MEAS_COND_AXIS_NAME_INTERNAL-6 "ThetaD"
*MEAS_COND_AXIS_NAME_INTERNAL-7 "Ts"
*MEAS_COND_AXIS_NAME_INTERNAL-8 "CBO"
*MEAS_COND_AXIS_NAME_INTERNAL-9 "CBO-M"
*MEAS_COND_AXIS_NAME_INTERNAL-10 "IncidentSollerSlit"
*MEAS_COND_AXIS_NAME_INTERNAL-11 "IncidentSlitBox"
*MEAS_COND_AXIS_NAME_INTERNAL-12 "IncidentSlitBox-_Axis"
*MEAS_COND_AXIS_NAME_INTERNAL-13 "Zs"
*MEAS_COND_AXIS_NAME_INTERNAL-14 "IncidentMonochromator"
*MEAS_COND_AXIS_NAME_INTERNAL-15 "IncidentAxdSlit"
*MEAS_COND_AXIS_NAME_INTERNAL-16 "CenterSlit"
*MEAS_COND_AXIS_NAME_INTERNAL-17 "Filter"
*MEAS_COND_AXIS_NAME_INTERNAL-18 "ReceivingSlitBox1"
*MEAS_COND_AXIS_NAME_INTERNAL-19 "ReceivingSlitBox2"
*MEAS_COND_AXIS_NAME_INTERNAL-20 "ReceivingOptics"
*MEAS_COND_AXIS_NAME_INTERNAL-21 "ReceivingSollerSlit"
*MEAS_COND_AXIS_NAME_INTERNAL-22 "ReceivingAxdSlit"
*MEAS_COND_AXIS_NAME_INTERNAL-23 "ReceivingSlitBox1-_Axis"
*MEAS_COND_AXIS_NAME_INTERNAL-24 "ReceivingSlitBox2-_Axis"
*MEAS_COND_AXIS_NAME_INTERNAL-25 "ReceivingSlitBox2-Zd"
*MEAS_COND_AXIS_NAME_INTERNAL-26 "Attenuator"
*MEAS_COND_AXIS_NAME_INTERNAL-27 "CounterMonochromator"
*MEAS_COND_AXIS_NAME_INTERNAL-28 "CounterSlit"
*MEAS_COND_AXIS_NAME_INTERNAL-29 "IncidentPrimary"
*MEAS_COND_AXIS_NAME_INTERNAL-30 "PHA"
*MEAS_COND_AXIS_NAME_MAGICNO-0 "83951616.0000000000"
*MEAS_COND_AXIS_NAME_MAGICNO-1 "268632064.0000000000"
*MEAS_COND_AXIS_NAME_MAGICNO-2 "268500992.0000000000"
*MEAS_COND_AXIS_NAME_MAGICNO-3 "285278208.0000000000"
*MEAS_COND_AXIS_NAME_MAGICNO-4 "83951616.0000000000"
*MEAS_COND_AXIS_NAME_MAGICNO-5 "131072.0000000000"
*MEAS_COND_AXIS_NAME_MAGICNO-6 "131072.0000000000"
*MEAS_COND_AXIS_NAME_MAGICNO-7 "318898176.0000000000"
*MEAS_COND_AXIS_NAME_MAGICNO-8 "20971521.0000000000"
*MEAS_COND_AXIS_NAME_MAGICNO-9 "285343744.0000000000"
*MEAS_COND_AXIS_NAME_MAGICNO-10 "20971521.0000000000"
*MEAS_COND_AXIS_NAME_MAGICNO-11 "22020097.0000000000"
*MEAS_COND_AXIS_NAME_MAGICNO-12 "25165824.0000000000"
*MEAS_COND_AXIS_NAME_MAGICNO-13 "318898176.0000000000"
*MEAS_COND_AXIS_NAME_MAGICNO-14 "1.0000000000"
*MEAS_COND_AXIS_NAME_MAGICNO-15 "20971521.0000000000"
*MEAS_COND_AXIS_NAME_MAGICNO-16 "20971521.0000000000"
*MEAS_COND_AXIS_NAME_MAGICNO-17 "20971521.0000000000"
*MEAS_COND_AXIS_NAME_MAGICNO-18 "23068673.0000000000"
*MEAS_COND_AXIS_NAME_MAGICNO-19 "23068673.0000000000"
*MEAS_COND_AXIS_NAME_MAGICNO-20 "20971521.0000000000"
*MEAS_COND_AXIS_NAME_MAGICNO-21 "20971521.0000000000"
*MEAS_COND_AXIS_NAME_MAGICNO-22 "20971521.0000000000"
*MEAS_COND_AXIS_NAME_MAGICNO-23 "25165824.0000000000"
*MEAS_COND_AXIS_NAME_MAGICNO-24 "25165824.0000000000"
*MEAS_COND_AXIS_NAME_MAGICNO-25 "285343744.0000000000"
*MEAS_COND_AXIS_NAME_MAGICNO-26 "17301505.0000000000"
*MEAS_COND_AXIS_NAME_MAGICNO-27 "20971521.0000000000"
*MEAS_COND_AXIS_NAME_MAGICNO-28 "20971521.0000000000"
*MEAS_COND_AXIS_NAME_MAGICNO-29 "20971521.0000000000"
*MEAS_COND_AXIS_NAME_MAGICNO-30 "0.0000000000"
*MEAS_COND_AXIS_OFFSET-0 "-"
*MEAS_COND_AXIS_OFFSET-1 "-0.1081000000"
*MEAS_COND_AXIS_OFFSET-2 "0.3758000000"
*MEAS_COND_AXIS_OFFSET-3 "-"
*MEAS_COND_AXIS_OFFSET-4 "-"
*MEAS_COND_AXIS_OFFSET-5 "0.3758000000"
*MEAS_COND_AXIS_OFFSET-6 "-0.4839000000"
*MEAS_COND_AXIS_OFFSET-7 "-"
*MEAS_COND_AXIS_OFFSET-8 "-"
*MEAS_COND_AXIS_OFFSET-9 "-"
*MEAS_COND_AXIS_OFFSET-10 "-"
*MEAS_COND_AXIS_OFFSET-11 "-"
*MEAS_COND_AXIS_OFFSET-12 "-"
*MEAS_COND_AXIS_OFFSET-13 "-"
*MEAS_COND_AXIS_OFFSET-14 "-"
*MEAS_COND_AXIS_OFFSET-15 "-"
*MEAS_COND_AXIS_OFFSET-16 "-"
*MEAS_COND_AXIS_OFFSET-17 "-"
*MEAS_COND_AXIS_OFFSET-18 "-"
*MEAS_COND_AXIS_OFFSET-19 "-"
*MEAS_COND_AXIS_OFFSET-20 "-"
*MEAS_COND_AXIS_OFFSET-21 "-"
*MEAS_COND_AXIS_OFFSET-22 "-"
*MEAS_COND_AXIS_OFFSET-23 "-"
*MEAS_COND_AXIS_OFFSET-24 "-"
*MEAS_COND_AXIS_OFFSET-25 "-"
*MEAS_COND_AXIS_OFFSET-26 "-"
*MEAS_COND_AXIS_OFFSET-27 "-"
*MEAS_COND_AXIS_OFFSET-28 "-"
*MEAS_COND_AXIS_OFFSET-29 "-"
*MEAS_COND_AXIS_OFFSET-30 "-"
*MEAS_COND_AXIS_POSITION-0 "0.0000000000"
*MEAS_COND_AXIS_POSITION-1 "0.0000000000"
*MEAS_COND_AXIS_POSITION-2 "0.0000000000"
*MEAS_COND_AXIS_POSITION-3 "-0.5500000000"
*MEAS_COND_AXIS_POSITION-4 "0.0000000000"
*MEAS_COND_AXIS_POSITION-5 "0.0000000000"
*MEAS_COND_AXIS_POSITION-6 "0.0000000000"
*MEAS_COND_AXIS_POSITION-7 "-0.4278800000"
*MEAS_COND_AXIS_POSITION-8 "BB"
*MEAS_COND_AXIS_POSITION-9 "0.0000000000"
*MEAS_COND_AXIS_POSITION-10 "Soller_slit_5.0deg"
*MEAS_COND_AXIS_POSITION-11 "2/3deg"
*MEAS_COND_AXIS_POSITION-12 "2.2088000000"
*MEAS_COND_AXIS_POSITION-13 "-0.4140600000"
*MEAS_COND_AXIS_POSITION-14 "0.0000000000"
*MEAS_COND_AXIS_POSITION-15 "10.0mm"
*MEAS_COND_AXIS_POSITION-16 "None"
*MEAS_COND_AXIS_POSITION-17 "Cu_K-beta"
*MEAS_COND_AXIS_POSITION-18 "13.000mm"
*MEAS_COND_AXIS_POSITION-19 "13.000mm"
*MEAS_COND_AXIS_POSITION-20 "No_unit"
*MEAS_COND_AXIS_POSITION-21 "Soller_slit_5.0deg"
*MEAS_COND_AXIS_POSITION-22 "None"
*MEAS_COND_AXIS_POSITION-23 "13.0000000000"
*MEAS_COND_AXIS_POSITION-24 "13.0000000000"
*MEAS_COND_AXIS_POSITION-25 "0.0109400000"
*MEAS_COND_AXIS_POSITION-26 "Open"
*MEAS_COND_AXIS_POSITION-27 "None"
*MEAS_COND_AXIS_POSITION-28 "None"
*MEAS_COND_AXIS_POSITION-29 "None"
*MEAS_COND_AXIS_POSITION-30 "38.0000000000"
*MEAS_COND_AXIS_UNIT-0 "deg"
*MEAS_COND_AXIS_UNIT-1 "deg"
*MEAS_COND_AXIS_UNIT-2 "deg"
*MEAS_COND_AXIS_UNIT-3 "mm"
*MEAS_COND_AXIS_UNIT-4 "deg"
*MEAS_COND_AXIS_UNIT-5 "deg"
*MEAS_COND_AXIS_UNIT-6 "deg"
*MEAS_COND_AXIS_UNIT-7 "mm"
*MEAS_COND_AXIS_UNIT-8 ""
*MEAS_COND_AXIS_UNIT-9 "pulse"
*MEAS_COND_AXIS_UNIT-10 ""
*MEAS_COND_AXIS_UNIT-11 ""
*MEAS_COND_AXIS_UNIT-12 "mm"
*MEAS_COND_AXIS_UNIT-13 "mm"
*MEAS_COND_AXIS_UNIT-14 ""
*MEAS_COND_AXIS_UNIT-15 ""
*MEAS_COND_AXIS_UNIT-16 ""
*MEAS_COND_AXIS_UNIT-17 ""
*MEAS_COND_AXIS_UNIT-18 ""
*MEAS_COND_AXIS_UNIT-19 ""
*MEAS_COND_AXIS_UNIT-20 ""
*MEAS_COND_AXIS_UNIT-21 ""
*MEAS_COND_AXIS_UNIT-22 ""
*MEAS_COND_AXIS_UNIT-23 "mm"
*MEAS_COND_AXIS_UNIT-24 "mm"
*MEAS_COND_AXIS_UNIT-25 "mm"
*MEAS_COND_AXIS_UNIT-26 ""
*MEAS_COND_AXIS_UNIT-27 ""
*MEAS_COND_AXIS_UNIT-28 ""
*MEAS_COND_AXIS_UNIT-29 ""
*MEAS_COND_AXIS_UNIT-30 "div"
*MEAS_COND_COUNTER_CNTLOSS_CORR "0.0000000000"
*MEAS_COND_COUNTER_PHABASE "38.0000000000"
*MEAS_COND_COUNTER_PHAWINDOW "16.0000000000"
*MEAS_COND_COUNTER_PHA_UNIT "div"
*MEAS_COND_COUNTER_TAUDIFF "30.0000000000"
*MEAS_COND_COUNTER_TAUINT "0.0000000000"
*MEAS_COND_IRRADIATION_MODE "OFF"
*MEAS_COND_IRRADIATION_WIDTH ""
*MEAS_COND_OPT_ATTR "集中法"
*MEAS_COND_OPT_NAME "@集中法"
*MEAS_COND_UNSYMMETRIC_MODE "OFF"
*MEAS_COND_XG_CURRENT "30.0000000000"
*MEAS_COND_XG_VOLTAGE "40.0000000000"
*MEAS_COND_XG_WAVE_TYPE "Ka"
*MEAS_DATA_COUNT "5001.0000000000"
*MEAS_SCAN_AXIS_X "2θ/θ"
*MEAS_SCAN_AXIS_X_INTERNAL "TwoThetaTheta"
*MEAS_SCAN_END_TIME "07/14/21 13:24:40"
*MEAS_SCAN_MODE "CONTINUOUS"
*MEAS_SCAN_MONITOR "0"
*MEAS_SCAN_RESOLUTION_X "0.0002"
*MEAS_SCAN_SPEED "1.0"
*MEAS_SCAN_SPEED_UNIT "deg/min"
*MEAS_SCAN_START "20.0000000000"
*MEAS_SCAN_START_TIME "07/14/21 12:31:49"
*MEAS_SCAN_STEP "0.0100000000"
*MEAS_SCAN_STOP "70.0000000000"
*MEAS_SCAN_UNIT_X "deg"
*MEAS_SCAN_UNIT_Y "counts"
*RAS_HEADER_END
*RAS_INT_START
20.0000 1716.0000 1.0000
20.0400 1691.0000 1.0000
20.0800 1623.0000 1.0000
20.1200 1707.0000 1.0000
20.1600 1712.0000 1.0000
20.2000 1685.0000 1.0000
20.2400 1690.0000 1.0000
20.2800 1757.0000 1.0000
20.3200 1705.0000 1.0000
20.3600 1705.0000 1.0000
20.4000 1680.0000 1.0000
20.4400 1689.0000 1.0000
20.4800 1736.0000 1.0000
20.5200 1694.0000 1.0000
20.5600 1652.0000 1.0000
20.6000 1693.0000 1.0000
20.6400 1692.0000 1.0000
20.6800 1694.0000 1.0000
20.7200 1701.0000 1.0000
20.7600 1704.0000 1.0000
20.8000 1691.0000 1.0000
20.8400 1669.0000 1.0000
20.8800 1676.0000 1.0000
20.9200 1659.0000 1.0000
20.9600 1683.0000 1.0000
21.0000 1740.0000 1.0000
21.0400 1651.0000 1.0000
21.0800 1736.0000 1.0000
21.1200 1746.0000 1.0000
21.1600 1685.0000 1.0000
21.2000 1632.0000 1.0000
21.2400 1671.0000 1.0000
21.2800 1694.0000 1.0000
21.3200 1721.0000 1.0000
21.3600 1731.0000 1.0000
21.4000 1668.0000 1.0000
21.4400 1692.0000 1.0000
21.4800 1736.0000 1.0000
21.5200 1681.0000 1.0000
21.5600 1705.0000 1.0000
21.6000 1731.0000 1.0000
21.6400 1788.0000 1.0000
21.6800 1675.0000 1.0000
21.7200 1673.0000 1.0000
21.7600 1709.0000 1.0000
21.8000 1664.0000 1.0000
21.8400 1718.0000 1.0000
21.8800 1692.0000 1.0000
21.9200 1687.0000 1.0000
21.9600 1756.0000 1.0000
22.0000 1710.0000 1.0000
22.0400 1713.0000 1.0000
22.0800 1668.0000 1.0000
22.1200 1701.0000 1.0000
22.1600 1675.0000 1.0000
22.2000 1675.0000 1.0000
22.2400 1721.0000 1.0000
22.2800 1741.0000 1.0000
22.3200 1777.0000 1.0000
22.3600 1727.0000 1.0000
22.4000 1754.0000 1.0000
22.4400 1698.0000 1.0000
22.4800 1748.0000 1.0000
22.5200 1754.0000 1.0000
22.5600 1764.0000 1.0000
22.6000 1730.0000 1.0000
22.6400 1730.0000 1.0000
22.6800 1725.0000 1.0000
22.7200 1734.0000 1.0000
22.7600 1772.0000 1.0000
22.8000 1712.0000 1.0000
22.8400 1677.0000 1.0000
22.8800 1748.0000 1.0000
22.9200 1722.0000 1.0000
22.9600 1742.0000 1.0000
23.0000 1739.0000 1.0000
23.0400 1731.0000 1.0000
23.0800 1745.0000 1.0000
23.1200 1752.0000 1.0000
23.1600 1754.0000 1.0000
23.2000 1743.0000 1.0000
23.2400 1734.0000 1.0000
23.2800 1750.0000 1.0000
23.3200 1744.0000 1.0000
23.3600 1834.0000 1.0000
23.4000 1740.0000 1.0000
23.4400 1776.0000 1.0000
23.4800 1778.0000 1.0000
23.5200 1730.0000 1.0000
23.5600 1712.0000 1.0000
23.6000 1799.0000 1.0000
23.6400 1715.0000 1.0000
23.6800 1807.0000 1.0000
23.7200 1755.0000 1.0000
23.7600 1695.0000 1.0000
23.8000 1738.0000 1.0000
23.8400 1797.0000 1.0000
23.8800 1710.0000 1.0000
23.9200 1789.0000 1.0000
23.9600 1836.0000 1.0000
24.0000 1746.0000 1.0000
24.0400 1715.0000 1.0000
24.0800 1740.0000 1.0000
24.1200 1724.0000 1.0000
24.1600 1811.0000 1.0000
24.2000 1754.0000 1.0000
24.2400 1786.0000 1.0000
24.2800 1771.0000 1.0000
24.3200 1729.0000 1.0000
24.3600 1822.0000 1.0000
24.4000 1853.0000 1.0000
24.4400 1815.0000 1.0000
24.4800 1754.0000 1.0000
24.5200 1732.0000 1.0000
24.5600 1680.0000 1.0000
24.6000 1750.0000 1.0000
24.6400 1825.0000 1.0000
24.6800 1787.0000 1.0000
24.7200 1780.0000 1.0000
24.7600 1849.0000 1.0000
24.8000 1733.0000 1.0000
24.8400 1834.0000 1.0000
24.8800 1780.0000 1.0000
24.9200 1873.0000 1.0000
24.9600 1819.0000 1.0000
25.0000 1817.0000 1.0000
25.0400 1854.0000 1.0000
25.0800 1819.0000 1.0000
25.1200 1850.0000 1.0000
25.1600 1891.0000 1.0000
25.2000 1848.0000 1.0000
25.2400 1817.0000 1.0000
25.2800 1813.0000 1.0000
25.3200 1834.0000 1.0000
25.3600 1813.0000 1.0000
25.4000 1800.0000 1.0000
25.4400 1773.0000 1.0000
25.4800 1796.0000 1.0000
25.5200 1778.0000 1.0000
25.5600 1834.0000 1.0000
25.6000 1782.0000 1.0000
25.6400 1808.0000 1.0000
25.6800 1843.0000 1.0000
25.7200 1824.0000 1.0000
25.7600 1794.0000 1.0000
25.8000 1829.0000 1.0000
25.8400 1840.0000 1.0000
25.8800 1740.0000 1.0000
25.9200 1759.0000 1.0000
25.9600 1805.0000 1.0000
26.0000 1871.0000 1.0000
26.0400 1840.0000 1.0000
26.0800 1787.0000 1.0000
26.1200 1837.0000 1.0000
26.1600 1844.0000 1.0000
26.2000 1838.0000 1.0000
26.2400 1826.0000 1.0000
26.2800 1828.0000 1.0000
26.3200 1860.0000 1.0000
26.3600 1870.0000 1.0000
26.4000 1896.0000 1.0000
26.4400 1877.0000 1.0000
26.4800 1995.0000 1.0000
26.5200 1868.0000 1.0000
26.5600 1875.0000 1.0000
26.6000 1927.0000 1.0000
26.6400 1924.0000 1.0000
26.6800 1968.0000 1.0000
26.7200 1985.0000 1.0000
26.7600 2027.0000 1.0000
26.8000 2020.0000 1.0000
26.8400 2003.0000 1.0000
26.8800 2077.0000 1.0000
26.9200 2188.0000 1.0000
26.9600 2345.0000 1.0000
27.0000 2457.0000 1.0000
27.0400 2715.0000 1.0000
27.0800 3066.0000 1.0000
27.1200 3496.0000 1.0000
27.1600 4224.0000 1.0000
27.2000 5036.0000 1.0000
27.2400 6221.0000 1.0000
27.2800 6715.0000 1.0000
27.3200 6540.0000 1.0000
27.3600 5661.0000 1.0000
27.4000 4458.0000 1.0000
27.4400 3624.0000 1.0000
27.4800 3130.0000 1.0000
27.5200 2704.0000 1.0000
27.5600 2558.0000 1.0000
27.6000 2400.0000 1.0000
27.6400 2223.0000 1.0000
27.6800 2087.0000 1.0000
27.7200 2100.0000 1.0000
27.7600 2019.0000 1.0000
27.8000 1991.0000 1.0000
27.8400 1930.0000 1.0000
27.8800 1882.0000 1.0000
27.9200 1834.0000 1.0000
27.9600 1843.0000 1.0000
28.0000 1831.0000 1.0000
28.0400 1809.0000 1.0000
28.0800 1867.0000 1.0000
28.1200 1831.0000 1.0000
28.1600 1777.0000 1.0000
28.2000 1700.0000 1.0000
28.2400 1746.0000 1.0000
28.2800 1676.0000 1.0000
28.3200 1811.0000 1.0000
28.3600 1745.0000 1.0000
28.4000 1731.0000 1.0000
28.4400 1678.0000 1.0000
28.4800 1743.0000 1.0000
28.5200 1631.0000 1.0000
28.5600 1722.0000 1.0000
28.6000 1660.0000 1.0000
28.6400 1741.0000 1.0000
28.6800 1704.0000 1.0000
28.7200 1743.0000 1.0000
28.7600 1739.0000 1.0000
28.8000 1735.0000 1.0000
28.8400 1701.0000 1.0000
28.8800 1690.0000 1.0000
28.9200 1642.0000 1.0000
28.9600 1699.0000 1.0000
29.0000 1605.0000 1.0000
29.0400 1619.0000 1.0000
29.0800 1657.0000 1.0000
29.1200 1699.0000 1.0000
29.1600 1659.0000 1.0000
29.2000 1653.0000 1.0000
29.2400 1609.0000 1.0000
29.2800 1624.0000 1.0000
29.3200 1655.0000 1.0000
29.3600 1691.0000 1.0000
29.4000 1691.0000 1.0000
29.4400 1658.0000 1.0000
29.4800 1645.0000 1.0000
29.5200 1583.0000 1.0000
29.5600 1650.0000 1.0000
29.6000 1653.0000 1.0000
29.6400 1626.0000 1.0000
29.6800 1679.0000 1.0000
29.7200 1635.0000 1.0000
29.7600 1579.0000 1.0000
29.8000 1566.0000 1.0000
29.8400 1597.0000 1.0000
29.8800 1646.0000 1.0000
29.9200 1631.0000 1.0000
29.9600 1646.0000 1.0000
30.0000 1537.0000 1.0000
30.0400 1619.0000 1.0000
30.0800 1671.0000 1.0000
30.1200 1606.0000 1.0000
30.1600 1607.0000 1.0000
30.2000 1617.0000 1.0000
30.2400 1622.0000 1.0000
30.2800 1600.0000 1.0000
30.3200 1554.0000 1.0000
30.3600 1572.0000 1.0000
30.4000 1563.0000 1.0000
30.4400 1532.0000 1.0000
30.4800 1549.0000 1.0000
30.5200 1563.0000 1.0000
30.5600 1550.0000 1.0000
30.6000 1543.0000 1.0000
30.6400 1561.0000 1.0000
30.6800 1577.0000 1.0000
30.7200 1628.0000 1.0000
30.7600 1596.0000 1.0000
30.8000 1603.0000 1.0000
30.8400 1542.0000 1.0000
30.8800 1506.0000 1.0000
30.9200 1597.0000 1.0000
30.9600 1500.0000 1.0000
31.0000 1579.0000 1.0000
31.0400 1566.0000 1.0000
31.0800 1539.0000 1.0000
31.1200 1512.0000 1.0000
31.1600 1522.0000 1.0000
31.2000 1508.0000 1.0000
31.2400 1496.0000 1.0000
31.2800 1497.0000 1.0000
31.3200 1459.0000 1.0000
31.3600 1529.0000 1.0000
31.4000 1508.0000 1.0000
31.4400 1484.0000 1.0000
31.4800 1478.0000 1.0000
31.5200 1475.0000 1.0000
31.5600 1464.0000 1.0000
31.6000 1469.0000 1.0000
31.6400 1491.0000 1.0000
31.6800 1487.0000 1.0000
31.7200 1460.0000 1.0000
31.7600 1487.0000 1.0000
31.8000 1509.0000 1.0000
31.8400 1483.0000 1.0000
31.8800 1559.0000 1.0000
31.9200 1569.0000 1.0000
31.9600 1571.0000 1.0000
32.0000 1540.0000 1.0000
32.0400 1537.0000 1.0000
32.0800 1522.0000 1.0000
32.1200 1517.0000 1.0000
32.1600 1488.0000 1.0000
32.2000 1473.0000 1.0000
32.2400 1480.0000 1.0000
32.2800 1477.0000 1.0000
32.3200 1489.0000 1.0000
32.3600 1495.0000 1.0000
32.4000 1431.0000 1.0000
32.4400 1483.0000 1.0000
32.4800 1434.0000 1.0000
32.5200 1489.0000 1.0000
32.5600 1403.0000 1.0000
32.6000 1428.0000 1.0000
32.6400 1483.0000 1.0000
32.6800 1455.0000 1.0000
32.7200 1434.0000 1.0000
32.7600 1449.0000 1.0000
32.8000 1454.0000 1.0000
32.8400 1433.0000 1.0000
32.8800 1442.0000 1.0000
32.9200 1424.0000 1.0000
32.9600 1416.0000 1.0000
33.0000 1438.0000 1.0000
33.0400 1414.0000 1.0000
33.0800 1435.0000 1.0000
33.1200 1441.0000 1.0000
33.1600 1360.0000 1.0000
33.2000 1423.0000 1.0000
33.2400 1443.0000 1.0000
33.2800 1399.0000 1.0000
33.3200 1448.0000 1.0000
33.3600 1389.0000 1.0000
33.4000 1380.0000 1.0000
33.4400 1418.0000 1.0000
33.4800 1369.0000 1.0000
33.5200 1387.0000 1.0000
33.5600 1388.0000 1.0000
33.6000 1436.0000 1.0000
33.6400 1400.0000 1.0000
33.6800 1397.0000 1.0000
33.7200 1452.0000 1.0000
33.7600 1474.0000 1.0000
33.8000 1469.0000 1.0000
33.8400 1498.0000 1.0000
33.8800 1476.0000 1.0000
33.9200 1512.0000 1.0000
33.9600 1511.0000 1.0000
34.0000 1515.0000 1.0000
34.0400 1494.0000 1.0000
34.0800 1525.0000 1.0000
34.1200 1509.0000 1.0000
34.1600 1529.0000 1.0000
34.2000 1644.0000 1.0000
34.2400 1647.0000 1.0000
34.2800 1849.0000 1.0000
34.3200 1960.0000 1.0000
34.3600 2189.0000 1.0000
34.4000 2561.0000 1.0000
34.4400 2963.0000 1.0000
34.4800 2983.0000 1.0000
34.5200 2929.0000 1.0000
34.5600 2628.0000 1.0000
34.6000 2354.0000 1.0000
34.6400 2097.0000 1.0000
34.6800 1977.0000 1.0000
34.7200 1731.0000 1.0000
34.7600 1653.0000 1.0000
34.8000 1614.0000 1.0000
34.8400 1550.0000 1.0000
34.8800 1455.0000 1.0000
34.9200 1537.0000 1.0000
34.9600 1369.0000 1.0000
35.0000 1415.0000 1.0000
35.0400 1456.0000 1.0000
35.0800 1422.0000 1.0000
35.1200 1318.0000 1.0000
35.1600 1323.0000 1.0000
35.2000 1318.0000 1.0000
35.2400 1326.0000 1.0000
35.2800 1354.0000 1.0000
35.3200 1297.0000 1.0000
35.3600 1292.0000 1.0000
35.4000 1251.0000 1.0000
35.4400 1335.0000 1.0000
35.4800 1270.0000 1.0000
35.5200 1244.0000 1.0000
35.5600 1272.0000 1.0000
35.6000 1293.0000 1.0000
35.6400 1247.0000 1.0000
35.6800 1323.0000 1.0000
35.7200 1279.0000 1.0000
35.7600 1291.0000 1.0000
35.8000 1197.0000 1.0000
35.8400 1313.0000 1.0000
35.8800 1305.0000 1.0000
35.9200 1364.0000 1.0000
35.9600 1218.0000 1.0000
36.0000 1249.0000 1.0000
36.0400 1344.0000 1.0000
36.0800 1407.0000 1.0000
36.1200 1453.0000 1.0000
36.1600 1396.0000 1.0000
36.2000 1488.0000 1.0000
36.2400 1594.0000 1.0000
36.2800 1659.0000 1.0000
36.3200 1762.0000 1.0000
36.3600 1780.0000 1.0000
36.4000 1824.0000 1.0000
36.4400 1735.0000 1.0000
36.4800 1646.0000 1.0000
36.5200 1639.0000 1.0000
36.5600 1582.0000 1.0000
36.6000 1442.0000 1.0000
36.6400 1374.0000 1.0000
36.6800 1403.0000 1.0000
36.7200 1301.0000 1.0000
36.7600 1294.0000 1.0000
36.8000 1257.0000 1.0000
36.8400 1219.0000 1.0000
36.8800 1225.0000 1.0000
36.9200 1239.0000 1.0000
36.9600 1189.0000 1.0000
37.0000 1190.0000 1.0000
37.0400 1196.0000 1.0000
37.0800 1166.0000 1.0000
37.1200 1176.0000 1.0000
37.1600 1144.0000 1.0000
37.2000 1268.0000 1.0000
37.2400 1150.0000 1.0000
37.2800 1133.0000 1.0000
37.3200 1186.0000 1.0000
37.3600 1161.0000 1.0000
37.4000 1201.0000 1.0000
37.4400 1211.0000 1.0000
37.4800 1224.0000 1.0000
37.5200 1123.0000 1.0000
37.5600 1165.0000 1.0000
37.6000 1243.0000 1.0000
37.6400 1162.0000 1.0000
37.6800 1150.0000 1.0000
37.7200 1140.0000 1.0000
37.7600 1103.0000 1.0000
37.8000 1198.0000 1.0000
37.8400 1240.0000 1.0000
37.8800 1227.0000 1.0000
37.9200 1231.0000 1.0000
37.9600 1233.0000 1.0000
38.0000 1195.0000 1.0000
38.0400 1262.0000 1.0000
38.0800 1338.0000 1.0000
38.1200 1353.0000 1.0000
38.1600 1514.0000 1.0000
38.2000 1584.0000 1.0000
38.2400 1852.0000 1.0000
38.2800 2156.0000 1.0000
38.3200 2543.0000 1.0000
38.3600 3077.0000 1.0000
38.4000 4136.0000 1.0000
38.4400 5483.0000 1.0000
38.4800 6976.0000 1.0000
38.5200 7735.0000 1.0000
38.5600 7281.0000 1.0000
38.6000 6606.0000 1.0000
38.6400 5322.0000 1.0000
38.6800 4201.0000 1.0000
38.7200 3176.0000 1.0000
38.7600 2468.0000 1.0000
38.8000 2161.0000 1.0000
38.8400 1744.0000 1.0000
38.8800 1548.0000 1.0000
38.9200 1395.0000 1.0000
38.9600 1328.0000 1.0000
39.0000 1284.0000 1.0000
39.0400 1204.0000 1.0000
39.0800 1160.0000 1.0000
39.1200 1112.0000 1.0000
39.1600 1148.0000 1.0000
39.2000 1101.0000 1.0000
39.2400 1085.0000 1.0000
39.2800 1041.0000 1.0000
39.3200 1122.0000 1.0000
39.3600 1014.0000 1.0000
39.4000 1059.0000 1.0000
39.4400 1045.0000 1.0000
39.4800 1080.0000 1.0000
39.5200 1081.0000 1.0000
39.5600 1075.0000 1.0000
39.6000 1053.0000 1.0000
39.6400 1089.0000 1.0000
39.6800 1077.0000 1.0000
39.7200 1081.0000 1.0000
39.7600 1037.0000 1.0000
39.8000 949.0000 1.0000
39.8400 1017.0000 1.0000
39.8800 954.0000 1.0000
39.9200 985.0000 1.0000
39.9600 1016.0000 1.0000
40.0000 989.0000 1.0000
40.0400 979.0000 1.0000
40.0800 1013.0000 1.0000
40.1200 981.0000 1.0000
40.1600 978.0000 1.0000
40.2000 1020.0000 1.0000
40.2400 1001.0000 1.0000
40.2800 917.0000 1.0000
40.3200 957.0000 1.0000
40.3600 945.0000 1.0000
40.4000 953.0000 1.0000
40.4400 967.0000 1.0000
40.4800 947.0000 1.0000
40.5200 929.0000 1.0000
40.5600 997.0000 1.0000
40.6000 937.0000 1.0000
40.6400 929.0000 1.0000
40.6800 979.0000 1.0000
40.7200 953.0000 1.0000
40.7600 949.0000 1.0000
40.8000 975.0000 1.0000
40.8400 969.0000 1.0000
40.8800 909.0000 1.0000
40.9200 913.0000 1.0000
40.9600 908.0000 1.0000
41.0000 996.0000 1.0000
41.0400 966.0000 1.0000
41.0800 894.0000 1.0000
41.1200 972.0000 1.0000
41.1600 952.0000 1.0000
41.2000 942.0000 1.0000
41.2400 987.0000 1.0000
41.2800 931.0000 1.0000
41.3200 961.0000 1.0000
41.3600 900.0000 1.0000
41.4000 944.0000 1.0000
41.4400 965.0000 1.0000
41.4800 968.0000 1.0000
41.5200 927.0000 1.0000
41.5600 948.0000 1.0000
41.6000 982.0000 1.0000
41.6400 997.0000 1.0000
41.6800 915.0000 1.0000
41.7200 945.0000 1.0000
41.7600 976.0000 1.0000
41.8000 958.0000 1.0000
41.8400 937.0000 1.0000
41.8800 931.0000 1.0000
41.9200 958.0000 1.0000
41.9600 940.0000 1.0000
42.0000 899.0000 1.0000
42.0400 968.0000 1.0000
42.0800 933.0000 1.0000
42.1200 950.0000 1.0000
42.1600 955.0000 1.0000
42.2000 920.0000 1.0000
42.2400 903.0000 1.0000
42.2800 938.0000 1.0000
42.3200 978.0000 1.0000
42.3600 960.0000 1.0000
42.4000 936.0000 1.0000
42.4400 972.0000 1.0000
42.4800 960.0000 1.0000
42.5200 966.0000 1.0000
42.5600 920.0000 1.0000
42.6000 937.0000 1.0000
42.6400 918.0000 1.0000
42.6800 943.0000 1.0000
42.7200 899.0000 1.0000
42.7600 931.0000 1.0000
42.8000 939.0000 1.0000
42.8400 941.0000 1.0000
42.8800 898.0000 1.0000
42.9200 948.0000 1.0000
42.9600 952.0000 1.0000
43.0000 982.0000 1.0000
43.0400 996.0000 1.0000
43.0800 1009.0000 1.0000
43.1200 948.0000 1.0000
43.1600 1037.0000 1.0000
43.2000 994.0000 1.0000
43.2400 1045.0000 1.0000
43.2800 1070.0000 1.0000
43.3200 977.0000 1.0000
43.3600 933.0000 1.0000
43.4000 941.0000 1.0000
43.4400 918.0000 1.0000
43.4800 942.0000 1.0000
43.5200 888.0000 1.0000
43.5600 951.0000 1.0000
43.6000 881.0000 1.0000
43.6400 932.0000 1.0000
43.6800 942.0000 1.0000
43.7200 903.0000 1.0000
43.7600 892.0000 1.0000
43.8000 934.0000 1.0000
43.8400 907.0000 1.0000
43.8800 950.0000 1.0000
43.9200 894.0000 1.0000
43.9600 870.0000 1.0000
44.0000 887.0000 1.0000
44.0400 881.0000 1.0000
44.0800 915.0000 1.0000
44.1200 932.0000 1.0000
44.1600 910.0000 1.0000
44.2000 895.0000 1.0000
44.2400 919.0000 1.0000
44.2800 868.0000 1.0000
44.3200 972.0000 1.0000
44.3600 928.0000 1.0000
44.4000 877.0000 1.0000
44.4400 914.0000 1.0000
44.4800 896.0000 1.0000
44.5200 944.0000 1.0000
44.5600 933.0000 1.0000
44.6000 846.0000 1.0000
44.6400 907.0000 1.0000
44.6800 902.0000 1.0000
44.7200 892.0000 1.0000
44.7600 888.0000 1.0000
44.8000 863.0000 1.0000
44.8400 871.0000 1.0000
44.8800 855.0000 1.0000
44.9200 864.0000 1.0000
44.9600 878.0000 1.0000
45.0000 906.0000 1.0000
45.0400 886.0000 1.0000
45.0800 857.0000 1.0000
45.1200 871.0000 1.0000
45.1600 854.0000 1.0000
45.2000 882.0000 1.0000
45.2400 922.0000 1.0000
45.2800 857.0000 1.0000
45.3200 892.0000 1.0000
45.3600 894.0000 1.0000
45.4000 884.0000 1.0000
45.4400 837.0000 1.0000
45.4800 823.0000 1.0000
45.5200 861.0000 1.0000
45.5600 861.0000 1.0000
45.6000 856.0000 1.0000
45.6400 826.0000 1.0000
45.6800 883.0000 1.0000
45.7200 885.0000 1.0000
45.7600 888.0000 1.0000
45.8000 827.0000 1.0000
45.8400 895.0000 1.0000
45.8800 860.0000 1.0000
45.9200 858.0000 1.0000
45.9600 861.0000 1.0000
46.0000 858.0000 1.0000
46.0400 870.0000 1.0000
46.0800 907.0000 1.0000
46.1200 847.0000 1.0000
46.1600 863.0000 1.0000
46.2000 803.0000 1.0000
46.2400 855.0000 1.0000
46.2800 834.0000 1.0000
46.3200 870.0000 1.0000
46.3600 811.0000 1.0000
46.4000 879.0000 1.0000
46.4400 846.0000 1.0000
46.4800 839.0000 1.0000
46.5200 838.0000 1.0000
46.5600 840.0000 1.0000
46.6000 816.0000 1.0000
46.6400 867.0000 1.0000
46.6800 856.0000 1.0000
46.7200 830.0000 1.0000
46.7600 854.0000 1.0000
46.8000 861.0000 1.0000
46.8400 834.0000 1.0000
46.8800 834.0000 1.0000
46.9200 825.0000 1.0000
46.9600 904.0000 1.0000
47.0000 837.0000 1.0000
47.0400 816.0000 1.0000
47.0800 853.0000 1.0000
47.1200 833.0000 1.0000
47.1600 843.0000 1.0000
47.2000 830.0000 1.0000
47.2400 836.0000 1.0000
47.2800 864.0000 1.0000
47.3200 863.0000 1.0000
47.3600 844.0000 1.0000
47.4000 859.0000 1.0000
47.4400 810.0000 1.0000
47.4800 839.0000 1.0000
47.5200 803.0000 1.0000
47.5600 816.0000 1.0000
47.6000 824.0000 1.0000
47.6400 799.0000 1.0000
47.6800 852.0000 1.0000
47.7200 843.0000 1.0000
47.7600 863.0000 1.0000
47.8000 829.0000 1.0000
47.8400 836.0000 1.0000
47.8800 857.0000 1.0000
47.9200 853.0000 1.0000
47.9600 812.0000 1.0000
48.0000 785.0000 1.0000
48.0400 833.0000 1.0000
48.0800 789.0000 1.0000
48.1200 834.0000 1.0000
48.1600 805.0000 1.0000
48.2000 796.0000 1.0000
48.2400 815.0000 1.0000
48.2800 839.0000 1.0000
48.3200 800.0000 1.0000
48.3600 825.0000 1.0000
48.4000 797.0000 1.0000
48.4400 839.0000 1.0000
48.4800 807.0000 1.0000
48.5200 841.0000 1.0000
48.5600 820.0000 1.0000
48.6000 786.0000 1.0000
48.6400 791.0000 1.0000
48.6800 789.0000 1.0000
48.7200 866.0000 1.0000
48.7600 788.0000 1.0000
48.8000 776.0000 1.0000
48.8400 828.0000 1.0000
48.8800 822.0000 1.0000
48.9200 796.0000 1.0000
48.9600 794.0000 1.0000
49.0000 766.0000 1.0000
49.0400 796.0000 1.0000
49.0800 822.0000 1.0000
49.1200 800.0000 1.0000
49.1600 795.0000 1.0000
49.2000 821.0000 1.0000
49.2400 792.0000 1.0000
49.2800 750.0000 1.0000
49.3200 781.0000 1.0000
49.3600 762.0000 1.0000
49.4000 813.0000 1.0000
49.4400 786.0000 1.0000
49.4800 793.0000 1.0000
49.5200 799.0000 1.0000
49.5600 769.0000 1.0000
49.6000 798.0000 1.0000
49.6400 801.0000 1.0000
49.6800 776.0000 1.0000
49.7200 806.0000 1.0000
49.7600 788.0000 1.0000
49.8000 803.0000 1.0000
49.8400 798.0000 1.0000
49.8800 816.0000 1.0000
49.9200 818.0000 1.0000
49.9600 803.0000 1.0000
50.0000 811.0000 1.0000
50.0400 807.0000 1.0000
50.0800 789.0000 1.0000
50.1200 772.0000 1.0000
50.1600 786.0000 1.0000
50.2000 805.0000 1.0000
50.2400 792.0000 1.0000
50.2800 802.0000 1.0000
50.3200 806.0000 1.0000
50.3600 823.0000 1.0000
50.4000 769.0000 1.0000
50.4400 794.0000 1.0000
50.4800 825.0000 1.0000
50.5200 779.0000 1.0000
50.5600 843.0000 1.0000
50.6000 784.0000 1.0000
50.6400 805.0000 1.0000
50.6800 792.0000 1.0000
50.7200 815.0000 1.0000
50.7600 813.0000 1.0000
50.8000 788.0000 1.0000
50.8400 813.0000 1.0000
50.8800 798.0000 1.0000
50.9200 783.0000 1.0000
50.9600 824.0000 1.0000
51.0000 784.0000 1.0000
51.0400 852.0000 1.0000
51.0800 853.0000 1.0000
51.1200 787.0000 1.0000
51.1600 787.0000 1.0000
51.2000 767.0000 1.0000
51.2400 805.0000 1.0000
51.2800 791.0000 1.0000
51.3200 792.0000 1.0000
51.3600 814.0000 1.0000
51.4000 837.0000 1.0000
51.4400 817.0000 1.0000
51.4800 796.0000 1.0000
51.5200 822.0000 1.0000
51.5600 855.0000 1.0000
51.6000 809.0000 1.0000
51.6400 853.0000 1.0000
51.6800 875.0000 1.0000
51.7200 825.0000 1.0000
51.7600 923.0000 1.0000
51.8000 908.0000 1.0000
51.8400 906.0000 1.0000
51.8800 995.0000 1.0000
51.9200 1025.0000 1.0000
51.9600 1113.0000 1.0000
52.0000 1258.0000 1.0000
52.0400 1399.0000 1.0000
52.0800 1656.0000 1.0000
52.1200 2300.0000 1.0000
52.1600 2940.0000 1.0000
52.2000 4061.0000 1.0000
52.2400 5045.0000 1.0000
52.2800 4862.0000 1.0000
52.3200 4220.0000 1.0000
52.3600 3843.0000 1.0000
52.4000 3511.0000 1.0000
52.4400 2780.0000 1.0000
52.4800 2126.0000 1.0000
52.5200 1762.0000 1.0000
52.5600 1437.0000 1.0000
52.6000 1292.0000 1.0000
52.6400 1132.0000 1.0000
52.6800 1034.0000 1.0000
52.7200 970.0000 1.0000
52.7600 977.0000 1.0000
52.8000 951.0000 1.0000
52.8400 901.0000 1.0000
52.8800 947.0000 1.0000
52.9200 850.0000 1.0000
52.9600 866.0000 1.0000
53.0000 844.0000 1.0000
53.0400 815.0000 1.0000
53.0800 818.0000 1.0000
53.1200 841.0000 1.0000
53.1600 893.0000 1.0000
53.2000 779.0000 1.0000
53.2400 811.0000 1.0000
53.2800 773.0000 1.0000
53.3200 796.0000 1.0000
53.3600 797.0000 1.0000
53.4000 805.0000 1.0000
53.4400 776.0000 1.0000
53.4800 814.0000 1.0000
53.5200 828.0000 1.0000
53.5600 814.0000 1.0000
53.6000 773.0000 1.0000
53.6400 762.0000 1.0000
53.6800 743.0000 1.0000
53.7200 810.0000 1.0000
53.7600 755.0000 1.0000
53.8000 788.0000 1.0000
53.8400 792.0000 1.0000
53.8800 796.0000 1.0000
53.9200 765.0000 1.0000
53.9600 813.0000 1.0000
54.0000 780.0000 1.0000
54.0400 754.0000 1.0000
54.0800 778.0000 1.0000
54.1200 776.0000 1.0000
54.1600 804.0000 1.0000
54.2000 786.0000 1.0000
54.2400 767.0000 1.0000
54.2800 774.0000 1.0000
54.3200 727.0000 1.0000
54.3600 768.0000 1.0000
54.4000 812.0000 1.0000
54.4400 810.0000 1.0000
54.4800 765.0000 1.0000
54.5200 758.0000 1.0000
54.5600 771.0000 1.0000
54.6000 754.0000 1.0000
54.6400 757.0000 1.0000
54.6800 766.0000 1.0000
54.7200 800.0000 1.0000
54.7600 794.0000 1.0000
54.8000 831.0000 1.0000
54.8400 796.0000 1.0000
54.8800 788.0000 1.0000
54.9200 827.0000 1.0000
54.9600 843.0000 1.0000
55.0000 853.0000 1.0000
55.0400 884.0000 1.0000
55.0800 897.0000 1.0000
55.1200 970.0000 1.0000
55.1600 1001.0000 1.0000
55.2000 1087.0000 1.0000
55.2400 1205.0000 1.0000
55.2800 1162.0000 1.0000
55.3200 1189.0000 1.0000
55.3600 1084.0000 1.0000
55.4000 1071.0000 1.0000
55.4400 1027.0000 1.0000
55.4800 959.0000 1.0000
55.5200 899.0000 1.0000
55.5600 913.0000 1.0000
55.6000 864.0000 1.0000
55.6400 802.0000 1.0000
55.6800 833.0000 1.0000
55.7200 785.0000 1.0000
55.7600 792.0000 1.0000
55.8000 788.0000 1.0000
55.8400 758.0000 1.0000
55.8800 788.0000 1.0000
55.9200 818.0000 1.0000
55.9600 783.0000 1.0000
56.0000 764.0000 1.0000
56.0400 789.0000 1.0000
56.0800 772.0000 1.0000
56.1200 740.0000 1.0000
56.1600 765.0000 1.0000
56.2000 749.0000 1.0000
56.2400 746.0000 1.0000
56.2800 757.0000 1.0000
56.3200 745.0000 1.0000
56.3600 766.0000 1.0000
56.4000 759.0000 1.0000
56.4400 764.0000 1.0000
56.4800 717.0000 1.0000
56.5200 749.0000 1.0000
56.5600 722.0000 1.0000
56.6000 742.0000 1.0000
56.6400 786.0000 1.0000
56.6800 711.0000 1.0000
56.7200 738.0000 1.0000
56.7600 746.0000 1.0000
56.8000 786.0000 1.0000
56.8400 715.0000 1.0000
56.8800 753.0000 1.0000
56.9200 771.0000 1.0000
56.9600 741.0000 1.0000
57.0000 784.0000 1.0000
57.0400 739.0000 1.0000
57.0800 797.0000 1.0000
57.1200 753.0000 1.0000
57.1600 768.0000 1.0000
57.2000 778.0000 1.0000
57.2400 769.0000 1.0000
57.2800 780.0000 1.0000
57.3200 792.0000 1.0000
57.3600 735.0000 1.0000
57.4000 718.0000 1.0000
57.4400 744.0000 1.0000
57.4800 700.0000 1.0000
57.5200 723.0000 1.0000
57.5600 762.0000 1.0000
57.6000 761.0000 1.0000
57.6400 724.0000 1.0000
57.6800 751.0000 1.0000
57.7200 764.0000 1.0000
57.7600 767.0000 1.0000
57.8000 730.0000 1.0000
57.8400 748.0000 1.0000
57.8800 738.0000 1.0000
57.9200 787.0000 1.0000
57.9600 731.0000 1.0000
58.0000 762.0000 1.0000
58.0400 746.0000 1.0000
58.0800 759.0000 1.0000
58.1200 772.0000 1.0000
58.1600 753.0000 1.0000
58.2000 792.0000 1.0000
58.2400 741.0000 1.0000
58.2800 755.0000 1.0000
58.3200 777.0000 1.0000
58.3600 737.0000 1.0000
58.4000 765.0000 1.0000
58.4400 750.0000 1.0000
58.4800 741.0000 1.0000
58.5200 769.0000 1.0000
58.5600 712.0000 1.0000
58.6000 771.0000 1.0000
58.6400 756.0000 1.0000
58.6800 731.0000 1.0000
58.7200 717.0000 1.0000
58.7600 793.0000 1.0000
58.8000 747.0000 1.0000
58.8400 756.0000 1.0000
58.8800 751.0000 1.0000
58.9200 740.0000 1.0000
58.9600 727.0000 1.0000
59.0000 761.0000 1.0000
59.0400 729.0000 1.0000
59.0800 720.0000 1.0000
59.1200 686.0000 1.0000
59.1600 750.0000 1.0000
59.2000 741.0000 1.0000
59.2400 756.0000 1.0000
59.2800 772.0000 1.0000
59.3200 720.0000 1.0000
59.3600 752.0000 1.0000
59.4000 740.0000 1.0000
59.4400 766.0000 1.0000
59.4800 714.0000 1.0000
59.5200 739.0000 1.0000
59.5600 812.0000 1.0000
59.6000 751.0000 1.0000
59.6400 722.0000 1.0000
59.6800 745.0000 1.0000
59.7200 745.0000 1.0000
59.7600 803.0000 1.0000
59.8000 749.0000 1.0000
59.8400 716.0000 1.0000
59.8800 736.0000 1.0000
59.9200 748.0000 1.0000
59.9600 707.0000 1.0000
60.0000 734.0000 1.0000
60.0400 722.0000 1.0000
60.0800 773.0000 1.0000
60.1200 725.0000 1.0000
60.1600 750.0000 1.0000
60.2000 718.0000 1.0000
60.2400 751.0000 1.0000
60.2800 781.0000 1.0000
60.3200 720.0000 1.0000
60.3600 720.0000 1.0000
60.4000 738.0000 1.0000
60.4400 743.0000 1.0000
60.4800 739.0000 1.0000
60.5200 756.0000 1.0000
60.5600 746.0000 1.0000
60.6000 744.0000 1.0000
60.6400 730.0000 1.0000
60.6800 736.0000 1.0000
60.7200 738.0000 1.0000
60.7600 764.0000 1.0000
60.8000 739.0000 1.0000
60.8400 758.0000 1.0000
60.8800 765.0000 1.0000
60.9200 739.0000 1.0000
60.9600 781.0000 1.0000
61.0000 750.0000 1.0000
61.0400 729.0000 1.0000
61.0800 731.0000 1.0000
61.1200 719.0000 1.0000
61.1600 698.0000 1.0000
61.2000 746.0000 1.0000
61.2400 770.0000 1.0000
61.2800 779.0000 1.0000
61.3200 733.0000 1.0000
61.3600 774.0000 1.0000
61.4000 756.0000 1.0000
61.4400 777.0000 1.0000
61.4800 753.0000 1.0000
61.5200 762.0000 1.0000
61.5600 755.0000 1.0000
61.6000 747.0000 1.0000
61.6400 761.0000 1.0000
61.6800 793.0000 1.0000
61.7200 795.0000 1.0000
61.7600 859.0000 1.0000
61.8000 852.0000 1.0000
61.8400 867.0000 1.0000
61.8800 874.0000 1.0000
61.9200 891.0000 1.0000
61.9600 900.0000 1.0000
62.0000 1000.0000 1.0000
62.0400 1026.0000 1.0000
62.0800 1133.0000 1.0000
62.1200 1316.0000 1.0000
62.1600 1401.0000 1.0000
62.2000 1551.0000 1.0000
62.2400 1712.0000 1.0000
62.2800 1736.0000 1.0000
62.3200 1721.0000 1.0000
62.3600 1743.0000 1.0000
62.4000 1713.0000 1.0000
62.4400 1557.0000 1.0000
62.4800 1460.0000 1.0000
62.5200 1311.0000 1.0000
62.5600 1205.0000 1.0000
62.6000 1150.0000 1.0000
62.6400 1048.0000 1.0000
62.6800 1007.0000 1.0000
62.7200 941.0000 1.0000
62.7600 880.0000 1.0000
62.8000 824.0000 1.0000
62.8400 865.0000 1.0000
62.8800 859.0000 1.0000
62.9200 847.0000 1.0000
62.9600 819.0000 1.0000
63.0000 812.0000 1.0000
63.0400 762.0000 1.0000
63.0800 811.0000 1.0000
63.1200 797.0000 1.0000
63.1600 804.0000 1.0000
63.2000 815.0000 1.0000
63.2400 713.0000 1.0000
63.2800 790.0000 1.0000
63.3200 760.0000 1.0000
63.3600 753.0000 1.0000
63.4000 821.0000 1.0000
63.4400 736.0000 1.0000
63.4800 802.0000 1.0000
63.5200 789.0000 1.0000
63.5600 719.0000 1.0000
63.6000 755.0000 1.0000
63.6400 810.0000 1.0000
63.6800 823.0000 1.0000
63.7200 763.0000 1.0000
63.7600 778.0000 1.0000
63.8000 809.0000 1.0000
63.8400 743.0000 1.0000
63.8800 758.0000 1.0000
63.9200 791.0000 1.0000
63.9600 759.0000 1.0000
64.0000 757.0000 1.0000
64.0400 800.0000 1.0000
64.0800 773.0000 1.0000
64.1200 773.0000 1.0000
64.1600 755.0000 1.0000
64.2000 801.0000 1.0000
64.2400 790.0000 1.0000
64.2800 787.0000 1.0000
64.3200 815.0000 1.0000
64.3600 800.0000 1.0000
64.4000 866.0000 1.0000
64.4400 870.0000 1.0000
64.4800 900.0000 1.0000
64.5200 881.0000 1.0000
64.5600 915.0000 1.0000
64.6000 898.0000 1.0000
64.6400 980.0000 1.0000
64.6800 941.0000 1.0000
64.7200 988.0000 1.0000
64.7600 947.0000 1.0000
64.8000 973.0000 1.0000
64.8400 1001.0000 1.0000
64.8800 932.0000 1.0000
64.9200 941.0000 1.0000
64.9600 904.0000 1.0000
65.0000 936.0000 1.0000
65.0400 871.0000 1.0000
65.0800 841.0000 1.0000
65.1200 847.0000 1.0000
65.1600 806.0000 1.0000
65.2000 854.0000 1.0000
65.2400 776.0000 1.0000
65.2800 831.0000 1.0000
65.3200 787.0000 1.0000
65.3600 798.0000 1.0000
65.4000 763.0000 1.0000
65.4400 813.0000 1.0000
65.4800 791.0000 1.0000
65.5200 812.0000 1.0000
65.5600 790.0000 1.0000
65.6000 791.0000 1.0000
65.6400 795.0000 1.0000
65.6800 849.0000 1.0000
65.7200 806.0000 1.0000
65.7600 839.0000 1.0000
65.8000 817.0000 1.0000
65.8400 903.0000 1.0000
65.8800 941.0000 1.0000
65.9200 1034.0000 1.0000
65.9600 1066.0000 1.0000
66.0000 1170.0000 1.0000
66.0400 1266.0000 1.0000
66.0800 1470.0000 1.0000
66.1200 1789.0000 1.0000
66.1600 2335.0000 1.0000
66.2000 2649.0000 1.0000
66.2400 2802.0000 1.0000
66.2800 2667.0000 1.0000
66.3200 2516.0000 1.0000
66.3600 2352.0000 1.0000
66.4000 2296.0000 1.0000
66.4400 2101.0000 1.0000
66.4800 1760.0000 1.0000
66.5200 1602.0000 1.0000
66.5600 1356.0000 1.0000
66.6000 1282.0000 1.0000
66.6400 1103.0000 1.0000
66.6800 1033.0000 1.0000
66.7200 948.0000 1.0000
66.7600 893.0000 1.0000
66.8000 851.0000 1.0000
66.8400 851.0000 1.0000
66.8800 806.0000 1.0000
66.9200 779.0000 1.0000
66.9600 816.0000 1.0000
67.0000 782.0000 1.0000
67.0400 738.0000 1.0000
67.0800 741.0000 1.0000
67.1200 752.0000 1.0000
67.1600 716.0000 1.0000
67.2000 703.0000 1.0000
67.2400 696.0000 1.0000
67.2800 757.0000 1.0000
67.3200 696.0000 1.0000
67.3600 747.0000 1.0000
67.4000 721.0000 1.0000
67.4400 720.0000 1.0000
67.4800 721.0000 1.0000
67.5200 711.0000 1.0000
67.5600 702.0000 1.0000
67.6000 709.0000 1.0000
67.6400 717.0000 1.0000
67.6800 669.0000 1.0000
67.7200 667.0000 1.0000
67.7600 665.0000 1.0000
67.8000 706.0000 1.0000
67.8400 703.0000 1.0000
67.8800 712.0000 1.0000
67.9200 656.0000 1.0000
67.9600 705.0000 1.0000
68.0000 690.0000 1.0000
68.0400 693.0000 1.0000
68.0800 708.0000 1.0000
68.1200 752.0000 1.0000
68.1600 679.0000 1.0000
68.2000 667.0000 1.0000
68.2400 683.0000 1.0000
68.2800 710.0000 1.0000
68.3200 721.0000 1.0000
68.3600 707.0000 1.0000
68.4000 654.0000 1.0000
68.4400 663.0000 1.0000
68.4800 669.0000 1.0000
68.5200 706.0000 1.0000
68.5600 700.0000 1.0000
68.6000 678.0000 1.0000
68.6400 702.0000 1.0000
68.6800 689.0000 1.0000
68.7200 699.0000 1.0000
68.7600 663.0000 1.0000
68.8000 691.0000 1.0000
68.8400 668.0000 1.0000
68.8800 694.0000 1.0000
68.9200 676.0000 1.0000
68.9600 662.0000 1.0000
69.0000 598.0000 1.0000
69.0400 684.0000 1.0000
69.0800 678.0000 1.0000
69.1200 637.0000 1.0000
69.1600 656.0000 1.0000
69.2000 660.0000 1.0000
69.2400 709.0000 1.0000
69.2800 669.0000 1.0000
69.3200 696.0000 1.0000
69.3600 674.0000 1.0000
69.4000 641.0000 1.0000
69.4400 682.0000 1.0000
69.4800 668.0000 1.0000
69.5200 680.0000 1.0000
69.5600 675.0000 1.0000
69.6000 662.0000 1.0000
69.6400 698.0000 1.0000
69.6800 680.0000 1.0000
69.7200 633.0000 1.0000
69.7600 652.0000 1.0000
69.8000 686.0000 1.0000
69.8400 683.0000 1.0000
69.8800 641.0000 1.0000
69.9200 689.0000 1.0000
69.9600 625.0000 1.0000
70.0000 632.0000 1.0000
*RAS_INT_END
*RAS_TEMPERATURE_START
*RAS_TEMPERATURE_END
*RAS_DATA_END