File: Section2_75_samples/XRD/No_028_750_18.ras
*RAS_DATA_START
*RAS_HEADER_START
*DISP_FMT_X "%.2f"
*DISP_FMT_Y "%.0f"
*DISP_FULLSCALE "3800.0000000000"
*DISP_LINE_COLOR "255.0000000000"
*DISP_LINE_STYLE "0.0000000000"
*DISP_LINE_WIDTH "0.2500000000"
*DISP_NOTE "測定データ-4"
*DISP_OFFSET_Y "0.0000000000"
*DISP_PEAKSEARCH_UNIT_Y "cps"
*DISP_RANGE_BOTTOM "0.0000000000"
*DISP_RANGE_LEFT "20.0000000000"
*DISP_RANGE_LOGCUTOFF "0.0100000000"
*DISP_RANGE_RIGHT "80.0000000000"
*DISP_RANGE_TOP "3800.0000000000"
*DISP_SCALE_MODE_Y "0.0000000000"
*DISP_TAB_NAME "2θ/θ"
*DISP_TITLE_Y "強度"
*DISP_UNIT_Y "cps"
*DISP_WINDOW_NAME "MSG_MACROENGINE"
*FILE_COMMENT " "
*FILE_MD5 ""
*FILE_MEMO " "
*FILE_OPERATOR "Administrator"
*FILE_SAMPLE " "
*FILE_TYPE "RAS_RAW"
*FILE_USERGROUP "システムマネージャ"
*FILE_VERSION "1.0000000000"
*HW_ATTACHMENT_ID "ATT0025"
*HW_ATTACHMENT_NAME "標準|Standard"
*HW_COUNTER_ID-0 "CUT0025"
*HW_COUNTER_ID-1 "CUT0020"
*HW_COUNTER_ID-2 "CUT0020"
*HW_COUNTER_ID-3 "CSL0021"
*HW_COUNTER_ID-4 "CMC0021"
*HW_COUNTER_NAME-0 "D/teX Ultra|D/teX Ultra"
*HW_COUNTER_NAME-1 "None|None"
*HW_COUNTER_NAME-2 "None|None"
*HW_COUNTER_NAME-3 "BBM|BBM"
*HW_COUNTER_NAME-4 "検出器モノクロメータ|Detector monochromator"
*HW_COUNTER_SELECT_NAME "D/teX Ultra|D/teX Ultra"
*HW_GONIOMETER_ID "GON0023"
*HW_GONIOMETER_NAME "SmartLab|SmartLab"
*HW_GONIOMETER_RADIUS-0 "90.0"
*HW_GONIOMETER_RADIUS-1 "114.0"
*HW_GONIOMETER_RADIUS-2 "190.0"
*HW_GONIOMETER_RADIUS-3 "300.0"
*HW_GONIOMETER_RADIUS-4 "187.0"
*HW_GONIOMETER_RADIUS-5 "300.0"
*HW_GONIOMETER_RADIUS-6 "113.0"
*HW_GONIOMETER_RADIUS-7 "331.0"
*HW_I_OPT_ID-0 "CBO0021"
*HW_I_OPT_ID-1 "ICR0023"
*HW_I_OPT_ID-2 "ISL0021"
*HW_I_OPT_ID-3 "ISO0021"
*HW_I_OPT_ID-4 "IAD0021"
*HW_I_OPT_ID-5 "IPR0001"
*HW_I_OPT_NAME-0 "CBOユニット|CBO unit"
*HW_I_OPT_NAME-1 "標準入射光学ユニット|Standard incident optical unit"
*HW_I_OPT_NAME-2 "標準入射スリットボックス|Standard incident slit box"
*HW_I_OPT_NAME-3 "入射平行スリット|Incident parallel slit"
*HW_I_OPT_NAME-4 "長手制限スリット|Length limiting slit"
*HW_I_OPT_NAME-5 "None|None"
*HW_R_ATTENUATER_AUTOMODE "0"
*HW_R_OPT_ID-0 "RSS0021"
*HW_R_OPT_ID-1 "RCR0023"
*HW_R_OPT_ID-2 "RSO0021"
*HW_R_OPT_ID-3 "RRS0021"
*HW_R_OPT_ID-4 "ATN0021"
*HW_R_OPT_ID-5 "RFL0021"
*HW_R_OPT_ID-6 "RAD0021"
*HW_R_OPT_NAME-0 "標準受光スリットボックス1|Standard receiving slit box # 1"
*HW_R_OPT_NAME-1 "標準受光光学ユニット1|Standard receiving unit # 1"
*HW_R_OPT_NAME-2 "標準受光光学ユニット2|Standard receiving optical unit # 2"
*HW_R_OPT_NAME-3 "標準受光スリットボックス2|Standard receiving slit box # 2"
*HW_R_OPT_NAME-4 "標準アッテネータ|Standard Attenuator"
*HW_R_OPT_NAME-5 "Cu Kβ|Cu K-beta"
*HW_R_OPT_NAME-6 "調整用受光スリット|Alignment receiving slit"
*HW_SAMPLE_HOLDER_ID "SMP0023"
*HW_SAMPLE_HOLDER_NAME "標準Zステージ|Standard Z stage"
*HW_XG_CURRENT_MAX "50"
*HW_XG_CURRENT_MIN "2"
*HW_XG_CURRENT_RESOLUTION "2"
*HW_XG_CURRENT_UNIT "mA"
*HW_XG_FOCUS "1mm x 10mm"
*HW_XG_FOCUS_TYPE "Normal"
*HW_XG_ID ""
*HW_XG_NAME "3kW 封入管(ID:1200)|3kW Sealed tube(ID:1200)"
*HW_XG_TARGET_ATOMIC_NUMBER "29.0000000000"
*HW_XG_TARGET_NAME "Cu"
*HW_XG_TYPE "Hermetic"
*HW_XG_VOLTAGE_MAX "60"
*HW_XG_VOLTAGE_MIN "20"
*HW_XG_VOLTAGE_RESOLUTION "2"
*HW_XG_VOLTAGE_UNIT "kV"
*HW_XG_WATT_MAX "2"
*HW_XG_WATT_UNIT "kW"
*HW_XG_WAVE_LENGTH_ALPHA1 "1.540593"
*HW_XG_WAVE_LENGTH_ALPHA2 "1.544414"
*HW_XG_WAVE_LENGTH_BETA "1.392250"
*MEAS_COND_AXIS_NAME-0 "2θ/θ"
*MEAS_COND_AXIS_NAME-1 "2θ"
*MEAS_COND_AXIS_NAME-2 "ω"
*MEAS_COND_AXIS_NAME-3 "Z"
*MEAS_COND_AXIS_NAME-4 "2θ/ω"
*MEAS_COND_AXIS_NAME-5 "θs"
*MEAS_COND_AXIS_NAME-6 "θd"
*MEAS_COND_AXIS_NAME-7 "Ts"
*MEAS_COND_AXIS_NAME-8 "CBO選択スリット"
*MEAS_COND_AXIS_NAME-9 "M"
*MEAS_COND_AXIS_NAME-10 "入射平行スリット"
*MEAS_COND_AXIS_NAME-11 "入射スリット"
*MEAS_COND_AXIS_NAME-12 ""
*MEAS_COND_AXIS_NAME-13 "Zs"
*MEAS_COND_AXIS_NAME-14 "入射光学素子"
*MEAS_COND_AXIS_NAME-15 "長手制限スリット"
*MEAS_COND_AXIS_NAME-16 "センタースリット"
*MEAS_COND_AXIS_NAME-17 "フィルター"
*MEAS_COND_AXIS_NAME-18 "受光スリット1"
*MEAS_COND_AXIS_NAME-19 "受光スリット2"
*MEAS_COND_AXIS_NAME-20 "受光光学素子"
*MEAS_COND_AXIS_NAME-21 "受光平行スリット"
*MEAS_COND_AXIS_NAME-22 "調整用受光スリット"
*MEAS_COND_AXIS_NAME-23 ""
*MEAS_COND_AXIS_NAME-24 ""
*MEAS_COND_AXIS_NAME-25 "Zd"
*MEAS_COND_AXIS_NAME-26 "アッテネータ"
*MEAS_COND_AXIS_NAME-27 "検出器モノクロメータ"
*MEAS_COND_AXIS_NAME-28 "モノクロメータスリット"
*MEAS_COND_AXIS_NAME-29 "プライマリビーム"
*MEAS_COND_AXIS_NAME-30 "PHA"
*MEAS_COND_AXIS_NAME_INTERNAL-0 "TwoThetaTheta"
*MEAS_COND_AXIS_NAME_INTERNAL-1 "TwoTheta"
*MEAS_COND_AXIS_NAME_INTERNAL-2 "Omega"
*MEAS_COND_AXIS_NAME_INTERNAL-3 "Z"
*MEAS_COND_AXIS_NAME_INTERNAL-4 "TwoThetaOmega"
*MEAS_COND_AXIS_NAME_INTERNAL-5 "ThetaS"
*MEAS_COND_AXIS_NAME_INTERNAL-6 "ThetaD"
*MEAS_COND_AXIS_NAME_INTERNAL-7 "Ts"
*MEAS_COND_AXIS_NAME_INTERNAL-8 "CBO"
*MEAS_COND_AXIS_NAME_INTERNAL-9 "CBO-M"
*MEAS_COND_AXIS_NAME_INTERNAL-10 "IncidentSollerSlit"
*MEAS_COND_AXIS_NAME_INTERNAL-11 "IncidentSlitBox"
*MEAS_COND_AXIS_NAME_INTERNAL-12 "IncidentSlitBox-_Axis"
*MEAS_COND_AXIS_NAME_INTERNAL-13 "Zs"
*MEAS_COND_AXIS_NAME_INTERNAL-14 "IncidentMonochromator"
*MEAS_COND_AXIS_NAME_INTERNAL-15 "IncidentAxdSlit"
*MEAS_COND_AXIS_NAME_INTERNAL-16 "CenterSlit"
*MEAS_COND_AXIS_NAME_INTERNAL-17 "Filter"
*MEAS_COND_AXIS_NAME_INTERNAL-18 "ReceivingSlitBox1"
*MEAS_COND_AXIS_NAME_INTERNAL-19 "ReceivingSlitBox2"
*MEAS_COND_AXIS_NAME_INTERNAL-20 "ReceivingOptics"
*MEAS_COND_AXIS_NAME_INTERNAL-21 "ReceivingSollerSlit"
*MEAS_COND_AXIS_NAME_INTERNAL-22 "ReceivingAxdSlit"
*MEAS_COND_AXIS_NAME_INTERNAL-23 "ReceivingSlitBox1-_Axis"
*MEAS_COND_AXIS_NAME_INTERNAL-24 "ReceivingSlitBox2-_Axis"
*MEAS_COND_AXIS_NAME_INTERNAL-25 "ReceivingSlitBox2-Zd"
*MEAS_COND_AXIS_NAME_INTERNAL-26 "Attenuator"
*MEAS_COND_AXIS_NAME_INTERNAL-27 "CounterMonochromator"
*MEAS_COND_AXIS_NAME_INTERNAL-28 "CounterSlit"
*MEAS_COND_AXIS_NAME_INTERNAL-29 "IncidentPrimary"
*MEAS_COND_AXIS_NAME_INTERNAL-30 "PHA"
*MEAS_COND_AXIS_NAME_MAGICNO-0 "83951616.0000000000"
*MEAS_COND_AXIS_NAME_MAGICNO-1 "268632064.0000000000"
*MEAS_COND_AXIS_NAME_MAGICNO-2 "268500992.0000000000"
*MEAS_COND_AXIS_NAME_MAGICNO-3 "285278208.0000000000"
*MEAS_COND_AXIS_NAME_MAGICNO-4 "83951616.0000000000"
*MEAS_COND_AXIS_NAME_MAGICNO-5 "131072.0000000000"
*MEAS_COND_AXIS_NAME_MAGICNO-6 "131072.0000000000"
*MEAS_COND_AXIS_NAME_MAGICNO-7 "318898176.0000000000"
*MEAS_COND_AXIS_NAME_MAGICNO-8 "20971521.0000000000"
*MEAS_COND_AXIS_NAME_MAGICNO-9 "285343744.0000000000"
*MEAS_COND_AXIS_NAME_MAGICNO-10 "20971521.0000000000"
*MEAS_COND_AXIS_NAME_MAGICNO-11 "22020097.0000000000"
*MEAS_COND_AXIS_NAME_MAGICNO-12 "25165824.0000000000"
*MEAS_COND_AXIS_NAME_MAGICNO-13 "318898176.0000000000"
*MEAS_COND_AXIS_NAME_MAGICNO-14 "1.0000000000"
*MEAS_COND_AXIS_NAME_MAGICNO-15 "20971521.0000000000"
*MEAS_COND_AXIS_NAME_MAGICNO-16 "20971521.0000000000"
*MEAS_COND_AXIS_NAME_MAGICNO-17 "20971521.0000000000"
*MEAS_COND_AXIS_NAME_MAGICNO-18 "23068673.0000000000"
*MEAS_COND_AXIS_NAME_MAGICNO-19 "23068673.0000000000"
*MEAS_COND_AXIS_NAME_MAGICNO-20 "20971521.0000000000"
*MEAS_COND_AXIS_NAME_MAGICNO-21 "20971521.0000000000"
*MEAS_COND_AXIS_NAME_MAGICNO-22 "20971521.0000000000"
*MEAS_COND_AXIS_NAME_MAGICNO-23 "25165824.0000000000"
*MEAS_COND_AXIS_NAME_MAGICNO-24 "25165824.0000000000"
*MEAS_COND_AXIS_NAME_MAGICNO-25 "285343744.0000000000"
*MEAS_COND_AXIS_NAME_MAGICNO-26 "17301505.0000000000"
*MEAS_COND_AXIS_NAME_MAGICNO-27 "20971521.0000000000"
*MEAS_COND_AXIS_NAME_MAGICNO-28 "20971521.0000000000"
*MEAS_COND_AXIS_NAME_MAGICNO-29 "20971521.0000000000"
*MEAS_COND_AXIS_NAME_MAGICNO-30 "0.0000000000"
*MEAS_COND_AXIS_OFFSET-0 "-"
*MEAS_COND_AXIS_OFFSET-1 "-0.1081000000"
*MEAS_COND_AXIS_OFFSET-2 "0.3758000000"
*MEAS_COND_AXIS_OFFSET-3 "-"
*MEAS_COND_AXIS_OFFSET-4 "-"
*MEAS_COND_AXIS_OFFSET-5 "0.3758000000"
*MEAS_COND_AXIS_OFFSET-6 "-0.4839000000"
*MEAS_COND_AXIS_OFFSET-7 "-"
*MEAS_COND_AXIS_OFFSET-8 "-"
*MEAS_COND_AXIS_OFFSET-9 "-"
*MEAS_COND_AXIS_OFFSET-10 "-"
*MEAS_COND_AXIS_OFFSET-11 "-"
*MEAS_COND_AXIS_OFFSET-12 "-"
*MEAS_COND_AXIS_OFFSET-13 "-"
*MEAS_COND_AXIS_OFFSET-14 "-"
*MEAS_COND_AXIS_OFFSET-15 "-"
*MEAS_COND_AXIS_OFFSET-16 "-"
*MEAS_COND_AXIS_OFFSET-17 "-"
*MEAS_COND_AXIS_OFFSET-18 "-"
*MEAS_COND_AXIS_OFFSET-19 "-"
*MEAS_COND_AXIS_OFFSET-20 "-"
*MEAS_COND_AXIS_OFFSET-21 "-"
*MEAS_COND_AXIS_OFFSET-22 "-"
*MEAS_COND_AXIS_OFFSET-23 "-"
*MEAS_COND_AXIS_OFFSET-24 "-"
*MEAS_COND_AXIS_OFFSET-25 "-"
*MEAS_COND_AXIS_OFFSET-26 "-"
*MEAS_COND_AXIS_OFFSET-27 "-"
*MEAS_COND_AXIS_OFFSET-28 "-"
*MEAS_COND_AXIS_OFFSET-29 "-"
*MEAS_COND_AXIS_OFFSET-30 "-"
*MEAS_COND_AXIS_POSITION-0 "0.0000000000"
*MEAS_COND_AXIS_POSITION-1 "0.0000000000"
*MEAS_COND_AXIS_POSITION-2 "0.0000000000"
*MEAS_COND_AXIS_POSITION-3 "-0.5500000000"
*MEAS_COND_AXIS_POSITION-4 "0.0000000000"
*MEAS_COND_AXIS_POSITION-5 "0.0000000000"
*MEAS_COND_AXIS_POSITION-6 "0.0000000000"
*MEAS_COND_AXIS_POSITION-7 "-0.4278800000"
*MEAS_COND_AXIS_POSITION-8 "BB"
*MEAS_COND_AXIS_POSITION-9 "0.0000000000"
*MEAS_COND_AXIS_POSITION-10 "Soller_slit_5.0deg"
*MEAS_COND_AXIS_POSITION-11 "2/3deg"
*MEAS_COND_AXIS_POSITION-12 "2.2088000000"
*MEAS_COND_AXIS_POSITION-13 "-0.4140600000"
*MEAS_COND_AXIS_POSITION-14 "0.0000000000"
*MEAS_COND_AXIS_POSITION-15 "10.0mm"
*MEAS_COND_AXIS_POSITION-16 "None"
*MEAS_COND_AXIS_POSITION-17 "Cu_K-beta"
*MEAS_COND_AXIS_POSITION-18 "13.000mm"
*MEAS_COND_AXIS_POSITION-19 "13.000mm"
*MEAS_COND_AXIS_POSITION-20 "No_unit"
*MEAS_COND_AXIS_POSITION-21 "Soller_slit_5.0deg"
*MEAS_COND_AXIS_POSITION-22 "None"
*MEAS_COND_AXIS_POSITION-23 "13.0000000000"
*MEAS_COND_AXIS_POSITION-24 "13.0000000000"
*MEAS_COND_AXIS_POSITION-25 "0.0109400000"
*MEAS_COND_AXIS_POSITION-26 "Open"
*MEAS_COND_AXIS_POSITION-27 "None"
*MEAS_COND_AXIS_POSITION-28 "None"
*MEAS_COND_AXIS_POSITION-29 "None"
*MEAS_COND_AXIS_POSITION-30 "38.0000000000"
*MEAS_COND_AXIS_UNIT-0 "deg"
*MEAS_COND_AXIS_UNIT-1 "deg"
*MEAS_COND_AXIS_UNIT-2 "deg"
*MEAS_COND_AXIS_UNIT-3 "mm"
*MEAS_COND_AXIS_UNIT-4 "deg"
*MEAS_COND_AXIS_UNIT-5 "deg"
*MEAS_COND_AXIS_UNIT-6 "deg"
*MEAS_COND_AXIS_UNIT-7 "mm"
*MEAS_COND_AXIS_UNIT-8 ""
*MEAS_COND_AXIS_UNIT-9 "pulse"
*MEAS_COND_AXIS_UNIT-10 ""
*MEAS_COND_AXIS_UNIT-11 ""
*MEAS_COND_AXIS_UNIT-12 "mm"
*MEAS_COND_AXIS_UNIT-13 "mm"
*MEAS_COND_AXIS_UNIT-14 ""
*MEAS_COND_AXIS_UNIT-15 ""
*MEAS_COND_AXIS_UNIT-16 ""
*MEAS_COND_AXIS_UNIT-17 ""
*MEAS_COND_AXIS_UNIT-18 ""
*MEAS_COND_AXIS_UNIT-19 ""
*MEAS_COND_AXIS_UNIT-20 ""
*MEAS_COND_AXIS_UNIT-21 ""
*MEAS_COND_AXIS_UNIT-22 ""
*MEAS_COND_AXIS_UNIT-23 "mm"
*MEAS_COND_AXIS_UNIT-24 "mm"
*MEAS_COND_AXIS_UNIT-25 "mm"
*MEAS_COND_AXIS_UNIT-26 ""
*MEAS_COND_AXIS_UNIT-27 ""
*MEAS_COND_AXIS_UNIT-28 ""
*MEAS_COND_AXIS_UNIT-29 ""
*MEAS_COND_AXIS_UNIT-30 "div"
*MEAS_COND_COUNTER_CNTLOSS_CORR "0.0000000000"
*MEAS_COND_COUNTER_PHABASE "38.0000000000"
*MEAS_COND_COUNTER_PHAWINDOW "16.0000000000"
*MEAS_COND_COUNTER_PHA_UNIT "div"
*MEAS_COND_COUNTER_TAUDIFF "30.0000000000"
*MEAS_COND_COUNTER_TAUINT "0.0000000000"
*MEAS_COND_IRRADIATION_MODE "OFF"
*MEAS_COND_IRRADIATION_WIDTH ""
*MEAS_COND_OPT_ATTR "集中法"
*MEAS_COND_OPT_NAME "@集中法"
*MEAS_COND_UNSYMMETRIC_MODE "OFF"
*MEAS_COND_XG_CURRENT "30.0000000000"
*MEAS_COND_XG_VOLTAGE "40.0000000000"
*MEAS_COND_XG_WAVE_TYPE "Ka"
*MEAS_DATA_COUNT "3001.0000000000"
*MEAS_SCAN_AXIS_X "2θ/θ"
*MEAS_SCAN_AXIS_X_INTERNAL "TwoThetaTheta"
*MEAS_SCAN_END_TIME "09/04/20 12:07:14"
*MEAS_SCAN_MODE "CONTINUOUS"
*MEAS_SCAN_MONITOR "0"
*MEAS_SCAN_RESOLUTION_X "0.0002"
*MEAS_SCAN_SPEED "2.0"
*MEAS_SCAN_SPEED_UNIT "deg/min"
*MEAS_SCAN_START "20.0000000000"
*MEAS_SCAN_START_TIME "09/04/20 11:35:34"
*MEAS_SCAN_STEP "0.0200000000"
*MEAS_SCAN_STOP "80.0000000000"
*MEAS_SCAN_UNIT_X "deg"
*MEAS_SCAN_UNIT_Y "counts"
*RAS_HEADER_END
*RAS_INT_START
20.0000 1853.0000 1.0000
20.0600 1847.0000 1.0000
20.1200 1857.0000 1.0000
20.1800 1871.0000 1.0000
20.2400 1826.0000 1.0000
20.3000 1818.0000 1.0000
20.3600 1865.0000 1.0000
20.4200 1884.0000 1.0000
20.4800 1800.0000 1.0000
20.5400 1798.0000 1.0000
20.6000 1722.0000 1.0000
20.6600 1738.0000 1.0000
20.7200 1750.0000 1.0000
20.7800 1736.0000 1.0000
20.8400 1807.0000 1.0000
20.9000 1800.0000 1.0000
20.9600 1782.0000 1.0000
21.0200 1749.0000 1.0000
21.0800 1713.0000 1.0000
21.1400 1649.0000 1.0000
21.2000 1622.0000 1.0000
21.2600 1679.0000 1.0000
21.3200 1632.0000 1.0000
21.3800 1664.0000 1.0000
21.4400 1659.0000 1.0000
21.5000 1604.0000 1.0000
21.5600 1632.0000 1.0000
21.6200 1638.0000 1.0000
21.6800 1631.0000 1.0000
21.7400 1597.0000 1.0000
21.8000 1555.0000 1.0000
21.8600 1645.0000 1.0000
21.9200 1637.0000 1.0000
21.9800 1553.0000 1.0000
22.0400 1589.0000 1.0000
22.1000 1606.0000 1.0000
22.1600 1584.0000 1.0000
22.2200 1613.0000 1.0000
22.2800 1506.0000 1.0000
22.3400 1569.0000 1.0000
22.4000 1514.0000 1.0000
22.4600 1483.0000 1.0000
22.5200 1474.0000 1.0000
22.5800 1458.0000 1.0000
22.6400 1506.0000 1.0000
22.7000 1452.0000 1.0000
22.7600 1517.0000 1.0000
22.8200 1459.0000 1.0000
22.8800 1433.0000 1.0000
22.9400 1517.0000 1.0000
23.0000 1427.0000 1.0000
23.0600 1464.0000 1.0000
23.1200 1463.0000 1.0000
23.1800 1416.0000 1.0000
23.2400 1397.0000 1.0000
23.3000 1363.0000 1.0000
23.3600 1444.0000 1.0000
23.4200 1343.0000 1.0000
23.4800 1421.0000 1.0000
23.5400 1385.0000 1.0000
23.6000 1399.0000 1.0000
23.6600 1356.0000 1.0000
23.7200 1424.0000 1.0000
23.7800 1382.0000 1.0000
23.8400 1366.0000 1.0000
23.9000 1347.0000 1.0000
23.9600 1394.0000 1.0000
24.0200 1320.0000 1.0000
24.0800 1310.0000 1.0000
24.1400 1351.0000 1.0000
24.2000 1364.0000 1.0000
24.2600 1315.0000 1.0000
24.3200 1313.0000 1.0000
24.3800 1291.0000 1.0000
24.4400 1286.0000 1.0000
24.5000 1274.0000 1.0000
24.5600 1228.0000 1.0000
24.6200 1286.0000 1.0000
24.6800 1220.0000 1.0000
24.7400 1265.0000 1.0000
24.8000 1295.0000 1.0000
24.8600 1227.0000 1.0000
24.9200 1232.0000 1.0000
24.9800 1254.0000 1.0000
25.0400 1267.0000 1.0000
25.1000 1220.0000 1.0000
25.1600 1216.0000 1.0000
25.2200 1152.0000 1.0000
25.2800 1126.0000 1.0000
25.3400 1217.0000 1.0000
25.4000 1225.0000 1.0000
25.4600 1163.0000 1.0000
25.5200 1194.0000 1.0000
25.5800 1193.0000 1.0000
25.6400 1098.0000 1.0000
25.7000 1171.0000 1.0000
25.7600 1240.0000 1.0000
25.8200 1115.0000 1.0000
25.8800 1152.0000 1.0000
25.9400 1080.0000 1.0000
26.0000 1117.0000 1.0000
26.0600 1157.0000 1.0000
26.1200 1106.0000 1.0000
26.1800 1074.0000 1.0000
26.2400 1098.0000 1.0000
26.3000 1072.0000 1.0000
26.3600 1089.0000 1.0000
26.4200 1088.0000 1.0000
26.4800 1076.0000 1.0000
26.5400 1111.0000 1.0000
26.6000 1100.0000 1.0000
26.6600 1089.0000 1.0000
26.7200 1077.0000 1.0000
26.7800 1101.0000 1.0000
26.8400 1088.0000 1.0000
26.9000 1034.0000 1.0000
26.9600 1065.0000 1.0000
27.0200 1052.0000 1.0000
27.0800 1093.0000 1.0000
27.1400 1064.0000 1.0000
27.2000 1087.0000 1.0000
27.2600 1069.0000 1.0000
27.3200 1161.0000 1.0000
27.3800 1140.0000 1.0000
27.4400 1064.0000 1.0000
27.5000 1038.0000 1.0000
27.5600 1053.0000 1.0000
27.6200 1010.0000 1.0000
27.6800 973.0000 1.0000
27.7400 983.0000 1.0000
27.8000 1007.0000 1.0000
27.8600 971.0000 1.0000
27.9200 997.0000 1.0000
27.9800 999.0000 1.0000
28.0400 979.0000 1.0000
28.1000 938.0000 1.0000
28.1600 943.0000 1.0000
28.2200 959.0000 1.0000
28.2800 905.0000 1.0000
28.3400 951.0000 1.0000
28.4000 917.0000 1.0000
28.4600 938.0000 1.0000
28.5200 946.0000 1.0000
28.5800 883.0000 1.0000
28.6400 958.0000 1.0000
28.7000 930.0000 1.0000
28.7600 943.0000 1.0000
28.8200 896.0000 1.0000
28.8800 872.0000 1.0000
28.9400 855.0000 1.0000
29.0000 865.0000 1.0000
29.0600 866.0000 1.0000
29.1200 865.0000 1.0000
29.1800 897.0000 1.0000
29.2400 846.0000 1.0000
29.3000 876.0000 1.0000
29.3600 890.0000 1.0000
29.4200 813.0000 1.0000
29.4800 863.0000 1.0000
29.5400 858.0000 1.0000
29.6000 850.0000 1.0000
29.6600 773.0000 1.0000
29.7200 863.0000 1.0000
29.7800 797.0000 1.0000
29.8400 847.0000 1.0000
29.9000 838.0000 1.0000
29.9600 807.0000 1.0000
30.0200 845.0000 1.0000
30.0800 830.0000 1.0000
30.1400 861.0000 1.0000
30.2000 771.0000 1.0000
30.2600 809.0000 1.0000
30.3200 799.0000 1.0000
30.3800 746.0000 1.0000
30.4400 770.0000 1.0000
30.5000 806.0000 1.0000
30.5600 797.0000 1.0000
30.6200 768.0000 1.0000
30.6800 750.0000 1.0000
30.7400 807.0000 1.0000
30.8000 811.0000 1.0000
30.8600 785.0000 1.0000
30.9200 766.0000 1.0000
30.9800 768.0000 1.0000
31.0400 733.0000 1.0000
31.1000 731.0000 1.0000
31.1600 750.0000 1.0000
31.2200 751.0000 1.0000
31.2800 723.0000 1.0000
31.3400 705.0000 1.0000
31.4000 681.0000 1.0000
31.4600 745.0000 1.0000
31.5200 684.0000 1.0000
31.5800 708.0000 1.0000
31.6400 740.0000 1.0000
31.7000 682.0000 1.0000
31.7600 731.0000 1.0000
31.8200 696.0000 1.0000
31.8800 746.0000 1.0000
31.9400 662.0000 1.0000
32.0000 701.0000 1.0000
32.0600 699.0000 1.0000
32.1200 690.0000 1.0000
32.1800 650.0000 1.0000
32.2400 708.0000 1.0000
32.3000 692.0000 1.0000
32.3600 718.0000 1.0000
32.4200 652.0000 1.0000
32.4800 679.0000 1.0000
32.5400 645.0000 1.0000
32.6000 622.0000 1.0000
32.6600 682.0000 1.0000
32.7200 644.0000 1.0000
32.7800 638.0000 1.0000
32.8400 625.0000 1.0000
32.9000 642.0000 1.0000
32.9600 680.0000 1.0000
33.0200 621.0000 1.0000
33.0800 610.0000 1.0000
33.1400 656.0000 1.0000
33.2000 646.0000 1.0000
33.2600 683.0000 1.0000
33.3200 638.0000 1.0000
33.3800 613.0000 1.0000
33.4400 640.0000 1.0000
33.5000 628.0000 1.0000
33.5600 592.0000 1.0000
33.6200 614.0000 1.0000
33.6800 613.0000 1.0000
33.7400 590.0000 1.0000
33.8000 652.0000 1.0000
33.8600 583.0000 1.0000
33.9200 584.0000 1.0000
33.9800 622.0000 1.0000
34.0400 659.0000 1.0000
34.1000 608.0000 1.0000
34.1600 575.0000 1.0000
34.2200 600.0000 1.0000
34.2800 572.0000 1.0000
34.3400 657.0000 1.0000
34.4000 630.0000 1.0000
34.4600 703.0000 1.0000
34.5200 758.0000 1.0000
34.5800 669.0000 1.0000
34.6400 659.0000 1.0000
34.7000 609.0000 1.0000
34.7600 605.0000 1.0000
34.8200 594.0000 1.0000
34.8800 569.0000 1.0000
34.9400 553.0000 1.0000
35.0000 536.0000 1.0000
35.0600 585.0000 1.0000
35.1200 578.0000 1.0000
35.1800 553.0000 1.0000
35.2400 545.0000 1.0000
35.3000 541.0000 1.0000
35.3600 556.0000 1.0000
35.4200 537.0000 1.0000
35.4800 501.0000 1.0000
35.5400 515.0000 1.0000
35.6000 498.0000 1.0000
35.6600 546.0000 1.0000
35.7200 522.0000 1.0000
35.7800 532.0000 1.0000
35.8400 493.0000 1.0000
35.9000 504.0000 1.0000
35.9600 519.0000 1.0000
36.0200 537.0000 1.0000
36.0800 497.0000 1.0000
36.1400 539.0000 1.0000
36.2000 520.0000 1.0000
36.2600 494.0000 1.0000
36.3200 540.0000 1.0000
36.3800 520.0000 1.0000
36.4400 526.0000 1.0000
36.5000 553.0000 1.0000
36.5600 519.0000 1.0000
36.6200 458.0000 1.0000
36.6800 491.0000 1.0000
36.7400 483.0000 1.0000
36.8000 447.0000 1.0000
36.8600 490.0000 1.0000
36.9200 464.0000 1.0000
36.9800 475.0000 1.0000
37.0400 471.0000 1.0000
37.1000 460.0000 1.0000
37.1600 491.0000 1.0000
37.2200 490.0000 1.0000
37.2800 455.0000 1.0000
37.3400 441.0000 1.0000
37.4000 453.0000 1.0000
37.4600 460.0000 1.0000
37.5200 490.0000 1.0000
37.5800 430.0000 1.0000
37.6400 483.0000 1.0000
37.7000 428.0000 1.0000
37.7600 444.0000 1.0000
37.8200 451.0000 1.0000
37.8800 469.0000 1.0000
37.9400 428.0000 1.0000
38.0000 471.0000 1.0000
38.0600 434.0000 1.0000
38.1200 422.0000 1.0000
38.1800 431.0000 1.0000
38.2400 458.0000 1.0000
38.3000 464.0000 1.0000
38.3600 495.0000 1.0000
38.4200 584.0000 1.0000
38.4800 624.0000 1.0000
38.5400 727.0000 1.0000
38.6000 693.0000 1.0000
38.6600 616.0000 1.0000
38.7200 526.0000 1.0000
38.7800 483.0000 1.0000
38.8400 440.0000 1.0000
38.9000 431.0000 1.0000
38.9600 440.0000 1.0000
39.0200 420.0000 1.0000
39.0800 412.0000 1.0000
39.1400 424.0000 1.0000
39.2000 419.0000 1.0000
39.2600 418.0000 1.0000
39.3200 410.0000 1.0000
39.3800 390.0000 1.0000
39.4400 401.0000 1.0000
39.5000 401.0000 1.0000
39.5600 388.0000 1.0000
39.6200 380.0000 1.0000
39.6800 382.0000 1.0000
39.7400 376.0000 1.0000
39.8000 402.0000 1.0000
39.8600 387.0000 1.0000
39.9200 394.0000 1.0000
39.9800 400.0000 1.0000
40.0400 407.0000 1.0000
40.1000 406.0000 1.0000
40.1600 365.0000 1.0000
40.2200 394.0000 1.0000
40.2800 421.0000 1.0000
40.3400 393.0000 1.0000
40.4000 380.0000 1.0000
40.4600 335.0000 1.0000
40.5200 351.0000 1.0000
40.5800 384.0000 1.0000
40.6400 378.0000 1.0000
40.7000 361.0000 1.0000
40.7600 378.0000 1.0000
40.8200 360.0000 1.0000
40.8800 337.0000 1.0000
40.9400 343.0000 1.0000
41.0000 339.0000 1.0000
41.0600 353.0000 1.0000
41.1200 335.0000 1.0000
41.1800 322.0000 1.0000
41.2400 341.0000 1.0000
41.3000 356.0000 1.0000
41.3600 351.0000 1.0000
41.4200 363.0000 1.0000
41.4800 376.0000 1.0000
41.5400 333.0000 1.0000
41.6000 349.0000 1.0000
41.6600 329.0000 1.0000
41.7200 363.0000 1.0000
41.7800 357.0000 1.0000
41.8400 307.0000 1.0000
41.9000 367.0000 1.0000
41.9600 324.0000 1.0000
42.0200 318.0000 1.0000
42.0800 323.0000 1.0000
42.1400 323.0000 1.0000
42.2000 326.0000 1.0000
42.2600 348.0000 1.0000
42.3200 321.0000 1.0000
42.3800 307.0000 1.0000
42.4400 308.0000 1.0000
42.5000 349.0000 1.0000
42.5600 336.0000 1.0000
42.6200 311.0000 1.0000
42.6800 335.0000 1.0000
42.7400 300.0000 1.0000
42.8000 343.0000 1.0000
42.8600 309.0000 1.0000
42.9200 311.0000 1.0000
42.9800 317.0000 1.0000
43.0400 325.0000 1.0000
43.1000 341.0000 1.0000
43.1600 326.0000 1.0000
43.2200 315.0000 1.0000
43.2800 349.0000 1.0000
43.3400 330.0000 1.0000
43.4000 309.0000 1.0000
43.4600 320.0000 1.0000
43.5200 322.0000 1.0000
43.5800 331.0000 1.0000
43.6400 328.0000 1.0000
43.7000 283.0000 1.0000
43.7600 291.0000 1.0000
43.8200 285.0000 1.0000
43.8800 290.0000 1.0000
43.9400 293.0000 1.0000
44.0000 286.0000 1.0000
44.0600 317.0000 1.0000
44.1200 317.0000 1.0000
44.1800 306.0000 1.0000
44.2400 319.0000 1.0000
44.3000 289.0000 1.0000
44.3600 262.0000 1.0000
44.4200 312.0000 1.0000
44.4800 325.0000 1.0000
44.5400 294.0000 1.0000
44.6000 284.0000 1.0000
44.6600 290.0000 1.0000
44.7200 295.0000 1.0000
44.7800 283.0000 1.0000
44.8400 269.0000 1.0000
44.9000 298.0000 1.0000
44.9600 292.0000 1.0000
45.0200 281.0000 1.0000
45.0800 286.0000 1.0000
45.1400 296.0000 1.0000
45.2000 282.0000 1.0000
45.2600 289.0000 1.0000
45.3200 283.0000 1.0000
45.3800 290.0000 1.0000
45.4400 248.0000 1.0000
45.5000 266.0000 1.0000
45.5600 279.0000 1.0000
45.6200 253.0000 1.0000
45.6800 300.0000 1.0000
45.7400 278.0000 1.0000
45.8000 282.0000 1.0000
45.8600 325.0000 1.0000
45.9200 299.0000 1.0000
45.9800 290.0000 1.0000
46.0400 259.0000 1.0000
46.1000 269.0000 1.0000
46.1600 250.0000 1.0000
46.2200 270.0000 1.0000
46.2800 257.0000 1.0000
46.3400 269.0000 1.0000
46.4000 275.0000 1.0000
46.4600 237.0000 1.0000
46.5200 280.0000 1.0000
46.5800 270.0000 1.0000
46.6400 263.0000 1.0000
46.7000 265.0000 1.0000
46.7600 276.0000 1.0000
46.8200 281.0000 1.0000
46.8800 264.0000 1.0000
46.9400 247.0000 1.0000
47.0000 246.0000 1.0000
47.0600 269.0000 1.0000
47.1200 277.0000 1.0000
47.1800 258.0000 1.0000
47.2400 266.0000 1.0000
47.3000 262.0000 1.0000
47.3600 273.0000 1.0000
47.4200 263.0000 1.0000
47.4800 238.0000 1.0000
47.5400 264.0000 1.0000
47.6000 267.0000 1.0000
47.6600 252.0000 1.0000
47.7200 262.0000 1.0000
47.7800 280.0000 1.0000
47.8400 247.0000 1.0000
47.9000 249.0000 1.0000
47.9600 244.0000 1.0000
48.0200 263.0000 1.0000
48.0800 255.0000 1.0000
48.1400 251.0000 1.0000
48.2000 232.0000 1.0000
48.2600 256.0000 1.0000
48.3200 245.0000 1.0000
48.3800 256.0000 1.0000
48.4400 255.0000 1.0000
48.5000 246.0000 1.0000
48.5600 255.0000 1.0000
48.6200 240.0000 1.0000
48.6800 231.0000 1.0000
48.7400 260.0000 1.0000
48.8000 245.0000 1.0000
48.8600 231.0000 1.0000
48.9200 217.0000 1.0000
48.9800 255.0000 1.0000
49.0400 255.0000 1.0000
49.1000 232.0000 1.0000
49.1600 267.0000 1.0000
49.2200 259.0000 1.0000
49.2800 238.0000 1.0000
49.3400 233.0000 1.0000
49.4000 218.0000 1.0000
49.4600 232.0000 1.0000
49.5200 243.0000 1.0000
49.5800 218.0000 1.0000
49.6400 228.0000 1.0000
49.7000 248.0000 1.0000
49.7600 253.0000 1.0000
49.8200 248.0000 1.0000
49.8800 240.0000 1.0000
49.9400 256.0000 1.0000
50.0000 270.0000 1.0000
50.0600 243.0000 1.0000
50.1200 254.0000 1.0000
50.1800 219.0000 1.0000
50.2400 256.0000 1.0000
50.3000 225.0000 1.0000
50.3600 216.0000 1.0000
50.4200 216.0000 1.0000
50.4800 231.0000 1.0000
50.5400 244.0000 1.0000
50.6000 228.0000 1.0000
50.6600 240.0000 1.0000
50.7200 219.0000 1.0000
50.7800 225.0000 1.0000
50.8400 220.0000 1.0000
50.9000 240.0000 1.0000
50.9600 241.0000 1.0000
51.0200 240.0000 1.0000
51.0800 247.0000 1.0000
51.1400 231.0000 1.0000
51.2000 229.0000 1.0000
51.2600 240.0000 1.0000
51.3200 234.0000 1.0000
51.3800 237.0000 1.0000
51.4400 227.0000 1.0000
51.5000 219.0000 1.0000
51.5600 245.0000 1.0000
51.6200 216.0000 1.0000
51.6800 221.0000 1.0000
51.7400 258.0000 1.0000
51.8000 252.0000 1.0000
51.8600 241.0000 1.0000
51.9200 243.0000 1.0000
51.9800 254.0000 1.0000
52.0400 275.0000 1.0000
52.1000 330.0000 1.0000
52.1600 404.0000 1.0000
52.2200 589.0000 1.0000
52.2800 710.0000 1.0000
52.3400 673.0000 1.0000
52.4000 593.0000 1.0000
52.4600 487.0000 1.0000
52.5200 381.0000 1.0000
52.5800 305.0000 1.0000
52.6400 282.0000 1.0000
52.7000 249.0000 1.0000
52.7600 245.0000 1.0000
52.8200 221.0000 1.0000
52.8800 251.0000 1.0000
52.9400 222.0000 1.0000
53.0000 212.0000 1.0000
53.0600 221.0000 1.0000
53.1200 236.0000 1.0000
53.1800 227.0000 1.0000
53.2400 208.0000 1.0000
53.3000 204.0000 1.0000
53.3600 224.0000 1.0000
53.4200 211.0000 1.0000
53.4800 199.0000 1.0000
53.5400 214.0000 1.0000
53.6000 197.0000 1.0000
53.6600 210.0000 1.0000
53.7200 211.0000 1.0000
53.7800 220.0000 1.0000
53.8400 196.0000 1.0000
53.9000 222.0000 1.0000
53.9600 205.0000 1.0000
54.0200 198.0000 1.0000
54.0800 189.0000 1.0000
54.1400 206.0000 1.0000
54.2000 218.0000 1.0000
54.2600 202.0000 1.0000
54.3200 186.0000 1.0000
54.3800 216.0000 1.0000
54.4400 209.0000 1.0000
54.5000 177.0000 1.0000
54.5600 206.0000 1.0000
54.6200 202.0000 1.0000
54.6800 193.0000 1.0000
54.7400 206.0000 1.0000
54.8000 211.0000 1.0000
54.8600 206.0000 1.0000
54.9200 246.0000 1.0000
54.9800 201.0000 1.0000
55.0400 213.0000 1.0000
55.1000 211.0000 1.0000
55.1600 216.0000 1.0000
55.2200 217.0000 1.0000
55.2800 264.0000 1.0000
55.3400 296.0000 1.0000
55.4000 248.0000 1.0000
55.4600 252.0000 1.0000
55.5200 228.0000 1.0000
55.5800 249.0000 1.0000
55.6400 220.0000 1.0000
55.7000 220.0000 1.0000
55.7600 209.0000 1.0000
55.8200 202.0000 1.0000
55.8800 200.0000 1.0000
55.9400 211.0000 1.0000
56.0000 176.0000 1.0000
56.0600 197.0000 1.0000
56.1200 196.0000 1.0000
56.1800 212.0000 1.0000
56.2400 200.0000 1.0000
56.3000 192.0000 1.0000
56.3600 190.0000 1.0000
56.4200 226.0000 1.0000
56.4800 196.0000 1.0000
56.5400 185.0000 1.0000
56.6000 195.0000 1.0000
56.6600 193.0000 1.0000
56.7200 220.0000 1.0000
56.7800 197.0000 1.0000
56.8400 185.0000 1.0000
56.9000 217.0000 1.0000
56.9600 188.0000 1.0000
57.0200 175.0000 1.0000
57.0800 203.0000 1.0000
57.1400 206.0000 1.0000
57.2000 192.0000 1.0000
57.2600 225.0000 1.0000
57.3200 186.0000 1.0000
57.3800 196.0000 1.0000
57.4400 211.0000 1.0000
57.5000 191.0000 1.0000
57.5600 203.0000 1.0000
57.6200 210.0000 1.0000
57.6800 214.0000 1.0000
57.7400 197.0000 1.0000
57.8000 194.0000 1.0000
57.8600 212.0000 1.0000
57.9200 172.0000 1.0000
57.9800 174.0000 1.0000
58.0400 192.0000 1.0000
58.1000 200.0000 1.0000
58.1600 203.0000 1.0000
58.2200 180.0000 1.0000
58.2800 185.0000 1.0000
58.3400 201.0000 1.0000
58.4000 211.0000 1.0000
58.4600 205.0000 1.0000
58.5200 202.0000 1.0000
58.5800 193.0000 1.0000
58.6400 204.0000 1.0000
58.7000 188.0000 1.0000
58.7600 198.0000 1.0000
58.8200 201.0000 1.0000
58.8800 200.0000 1.0000
58.9400 186.0000 1.0000
59.0000 190.0000 1.0000
59.0600 198.0000 1.0000
59.1200 179.0000 1.0000
59.1800 190.0000 1.0000
59.2400 202.0000 1.0000
59.3000 202.0000 1.0000
59.3600 194.0000 1.0000
59.4200 195.0000 1.0000
59.4800 198.0000 1.0000
59.5400 205.0000 1.0000
59.6000 193.0000 1.0000
59.6600 184.0000 1.0000
59.7200 199.0000 1.0000
59.7800 182.0000 1.0000
59.8400 194.0000 1.0000
59.9000 185.0000 1.0000
59.9600 193.0000 1.0000
60.0200 184.0000 1.0000
60.0800 173.0000 1.0000
60.1400 207.0000 1.0000
60.2000 176.0000 1.0000
60.2600 190.0000 1.0000
60.3200 220.0000 1.0000
60.3800 193.0000 1.0000
60.4400 198.0000 1.0000
60.5000 180.0000 1.0000
60.5600 190.0000 1.0000
60.6200 180.0000 1.0000
60.6800 199.0000 1.0000
60.7400 194.0000 1.0000
60.8000 231.0000 1.0000
60.8600 171.0000 1.0000
60.9200 210.0000 1.0000
60.9800 192.0000 1.0000
61.0400 185.0000 1.0000
61.1000 185.0000 1.0000
61.1600 206.0000 1.0000
61.2200 209.0000 1.0000
61.2800 162.0000 1.0000
61.3400 200.0000 1.0000
61.4000 197.0000 1.0000
61.4600 186.0000 1.0000
61.5200 196.0000 1.0000
61.5800 192.0000 1.0000
61.6400 191.0000 1.0000
61.7000 176.0000 1.0000
61.7600 200.0000 1.0000
61.8200 199.0000 1.0000
61.8800 211.0000 1.0000
61.9400 227.0000 1.0000
62.0000 196.0000 1.0000
62.0600 225.0000 1.0000
62.1200 243.0000 1.0000
62.1800 274.0000 1.0000
62.2400 318.0000 1.0000
62.3000 314.0000 1.0000
62.3600 307.0000 1.0000
62.4200 293.0000 1.0000
62.4800 294.0000 1.0000
62.5400 253.0000 1.0000
62.6000 251.0000 1.0000
62.6600 251.0000 1.0000
62.7200 220.0000 1.0000
62.7800 209.0000 1.0000
62.8400 198.0000 1.0000
62.9000 178.0000 1.0000
62.9600 222.0000 1.0000
63.0200 205.0000 1.0000
63.0800 197.0000 1.0000
63.1400 199.0000 1.0000
63.2000 206.0000 1.0000
63.2600 199.0000 1.0000
63.3200 182.0000 1.0000
63.3800 172.0000 1.0000
63.4400 188.0000 1.0000
63.5000 187.0000 1.0000
63.5600 197.0000 1.0000
63.6200 183.0000 1.0000
63.6800 184.0000 1.0000
63.7400 188.0000 1.0000
63.8000 188.0000 1.0000
63.8600 194.0000 1.0000
63.9200 202.0000 1.0000
63.9800 191.0000 1.0000
64.0400 172.0000 1.0000
64.1000 203.0000 1.0000
64.1600 211.0000 1.0000
64.2200 200.0000 1.0000
64.2800 192.0000 1.0000
64.3400 188.0000 1.0000
64.4000 186.0000 1.0000
64.4600 195.0000 1.0000
64.5200 199.0000 1.0000
64.5800 199.0000 1.0000
64.6400 208.0000 1.0000
64.7000 245.0000 1.0000
64.7600 205.0000 1.0000
64.8200 227.0000 1.0000
64.8800 232.0000 1.0000
64.9400 192.0000 1.0000
65.0000 204.0000 1.0000
65.0600 205.0000 1.0000
65.1200 217.0000 1.0000
65.1800 213.0000 1.0000
65.2400 225.0000 1.0000
65.3000 207.0000 1.0000
65.3600 213.0000 1.0000
65.4200 222.0000 1.0000
65.4800 179.0000 1.0000
65.5400 224.0000 1.0000
65.6000 198.0000 1.0000
65.6600 219.0000 1.0000
65.7200 195.0000 1.0000
65.7800 206.0000 1.0000
65.8400 206.0000 1.0000
65.9000 185.0000 1.0000
65.9600 195.0000 1.0000
66.0200 243.0000 1.0000
66.0800 272.0000 1.0000
66.1400 330.0000 1.0000
66.2000 408.0000 1.0000
66.2600 508.0000 1.0000
66.3200 501.0000 1.0000
66.3800 458.0000 1.0000
66.4400 457.0000 1.0000
66.5000 372.0000 1.0000
66.5600 360.0000 1.0000
66.6200 289.0000 1.0000
66.6800 238.0000 1.0000
66.7400 203.0000 1.0000
66.8000 229.0000 1.0000
66.8600 180.0000 1.0000
66.9200 198.0000 1.0000
66.9800 214.0000 1.0000
67.0400 190.0000 1.0000
67.1000 213.0000 1.0000
67.1600 196.0000 1.0000
67.2200 152.0000 1.0000
67.2800 187.0000 1.0000
67.3400 200.0000 1.0000
67.4000 209.0000 1.0000
67.4600 184.0000 1.0000
67.5200 189.0000 1.0000
67.5800 176.0000 1.0000
67.6400 184.0000 1.0000
67.7000 200.0000 1.0000
67.7600 188.0000 1.0000
67.8200 184.0000 1.0000
67.8800 173.0000 1.0000
67.9400 169.0000 1.0000
68.0000 173.0000 1.0000
68.0600 177.0000 1.0000
68.1200 182.0000 1.0000
68.1800 168.0000 1.0000
68.2400 184.0000 1.0000
68.3000 178.0000 1.0000
68.3600 179.0000 1.0000
68.4200 168.0000 1.0000
68.4800 173.0000 1.0000
68.5400 185.0000 1.0000
68.6000 183.0000 1.0000
68.6600 198.0000 1.0000
68.7200 184.0000 1.0000
68.7800 168.0000 1.0000
68.8400 168.0000 1.0000
68.9000 180.0000 1.0000
68.9600 209.0000 1.0000
69.0200 174.0000 1.0000
69.0800 184.0000 1.0000
69.1400 187.0000 1.0000
69.2000 199.0000 1.0000
69.2600 174.0000 1.0000
69.3200 178.0000 1.0000
69.3800 192.0000 1.0000
69.4400 204.0000 1.0000
69.5000 183.0000 1.0000
69.5600 177.0000 1.0000
69.6200 188.0000 1.0000
69.6800 205.0000 1.0000
69.7400 180.0000 1.0000
69.8000 175.0000 1.0000
69.8600 193.0000 1.0000
69.9200 176.0000 1.0000
69.9800 175.0000 1.0000
70.0400 172.0000 1.0000
70.1000 168.0000 1.0000
70.1600 182.0000 1.0000
70.2200 172.0000 1.0000
70.2800 178.0000 1.0000
70.3400 175.0000 1.0000
70.4000 164.0000 1.0000
70.4600 172.0000 1.0000
70.5200 165.0000 1.0000
70.5800 167.0000 1.0000
70.6400 185.0000 1.0000
70.7000 168.0000 1.0000
70.7600 180.0000 1.0000
70.8200 180.0000 1.0000
70.8800 187.0000 1.0000
70.9400 164.0000 1.0000
71.0000 155.0000 1.0000
71.0600 174.0000 1.0000
71.1200 149.0000 1.0000
71.1800 192.0000 1.0000
71.2400 163.0000 1.0000
71.3000 195.0000 1.0000
71.3600 186.0000 1.0000
71.4200 180.0000 1.0000
71.4800 186.0000 1.0000
71.5400 191.0000 1.0000
71.6000 185.0000 1.0000
71.6600 187.0000 1.0000
71.7200 186.0000 1.0000
71.7800 201.0000 1.0000
71.8400 173.0000 1.0000
71.9000 183.0000 1.0000
71.9600 191.0000 1.0000
72.0200 174.0000 1.0000
72.0800 156.0000 1.0000
72.1400 194.0000 1.0000
72.2000 192.0000 1.0000
72.2600 158.0000 1.0000
72.3200 180.0000 1.0000
72.3800 163.0000 1.0000
72.4400 167.0000 1.0000
72.5000 166.0000 1.0000
72.5600 166.0000 1.0000
72.6200 165.0000 1.0000
72.6800 168.0000 1.0000
72.7400 177.0000 1.0000
72.8000 156.0000 1.0000
72.8600 152.0000 1.0000
72.9200 178.0000 1.0000
72.9800 153.0000 1.0000
73.0400 178.0000 1.0000
73.1000 190.0000 1.0000
73.1600 176.0000 1.0000
73.2200 168.0000 1.0000
73.2800 145.0000 1.0000
73.3400 159.0000 1.0000
73.4000 154.0000 1.0000
73.4600 168.0000 1.0000
73.5200 154.0000 1.0000
73.5800 177.0000 1.0000
73.6400 183.0000 1.0000
73.7000 181.0000 1.0000
73.7600 156.0000 1.0000
73.8200 155.0000 1.0000
73.8800 177.0000 1.0000
73.9400 169.0000 1.0000
74.0000 179.0000 1.0000
74.0600 163.0000 1.0000
74.1200 180.0000 1.0000
74.1800 194.0000 1.0000
74.2400 190.0000 1.0000
74.3000 168.0000 1.0000
74.3600 172.0000 1.0000
74.4200 178.0000 1.0000
74.4800 174.0000 1.0000
74.5400 162.0000 1.0000
74.6000 178.0000 1.0000
74.6600 164.0000 1.0000
74.7200 168.0000 1.0000
74.7800 178.0000 1.0000
74.8400 173.0000 1.0000
74.9000 168.0000 1.0000
74.9600 174.0000 1.0000
75.0200 178.0000 1.0000
75.0800 151.0000 1.0000
75.1400 178.0000 1.0000
75.2000 170.0000 1.0000
75.2600 160.0000 1.0000
75.3200 167.0000 1.0000
75.3800 160.0000 1.0000
75.4400 185.0000 1.0000
75.5000 161.0000 1.0000
75.5600 172.0000 1.0000
75.6200 155.0000 1.0000
75.6800 163.0000 1.0000
75.7400 139.0000 1.0000
75.8000 166.0000 1.0000
75.8600 164.0000 1.0000
75.9200 149.0000 1.0000
75.9800 166.0000 1.0000
76.0400 172.0000 1.0000
76.1000 177.0000 1.0000
76.1600 166.0000 1.0000
76.2200 164.0000 1.0000
76.2800 179.0000 1.0000
76.3400 197.0000 1.0000
76.4000 170.0000 1.0000
76.4600 174.0000 1.0000
76.5200 176.0000 1.0000
76.5800 176.0000 1.0000
76.6400 166.0000 1.0000
76.7000 192.0000 1.0000
76.7600 173.0000 1.0000
76.8200 159.0000 1.0000
76.8800 160.0000 1.0000
76.9400 173.0000 1.0000
77.0000 154.0000 1.0000
77.0600 175.0000 1.0000
77.1200 159.0000 1.0000
77.1800 156.0000 1.0000
77.2400 160.0000 1.0000
77.3000 153.0000 1.0000
77.3600 167.0000 1.0000
77.4200 187.0000 1.0000
77.4800 154.0000 1.0000
77.5400 154.0000 1.0000
77.6000 183.0000 1.0000
77.6600 171.0000 1.0000
77.7200 155.0000 1.0000
77.7800 160.0000 1.0000
77.8400 175.0000 1.0000
77.9000 151.0000 1.0000
77.9600 172.0000 1.0000
78.0200 174.0000 1.0000
78.0800 188.0000 1.0000
78.1400 176.0000 1.0000
78.2000 179.0000 1.0000
78.2600 156.0000 1.0000
78.3200 156.0000 1.0000
78.3800 175.0000 1.0000
78.4400 176.0000 1.0000
78.5000 165.0000 1.0000
78.5600 172.0000 1.0000
78.6200 165.0000 1.0000
78.6800 167.0000 1.0000
78.7400 186.0000 1.0000
78.8000 214.0000 1.0000
78.8600 213.0000 1.0000
78.9200 235.0000 1.0000
78.9800 244.0000 1.0000
79.0400 228.0000 1.0000
79.1000 242.0000 1.0000
79.1600 249.0000 1.0000
79.2200 219.0000 1.0000
79.2800 220.0000 1.0000
79.3400 185.0000 1.0000
79.4000 211.0000 1.0000
79.4600 181.0000 1.0000
79.5200 191.0000 1.0000
79.5800 172.0000 1.0000
79.6400 154.0000 1.0000
79.7000 160.0000 1.0000
79.7600 175.0000 1.0000
79.8200 175.0000 1.0000
79.8800 175.0000 1.0000
79.9400 161.0000 1.0000
80.0000 166.0000 1.0000
*RAS_INT_END
*RAS_TEMPERATURE_START
*RAS_TEMPERATURE_END
*RAS_DATA_END