File: Section2_75_samples/XRD/No_066_HS2_2.ras
*RAS_DATA_START
*RAS_HEADER_START
*DISP_FMT_X "%.2f"
*DISP_FMT_Y "%.0f"
*DISP_FULLSCALE "12510.0000000000"
*DISP_LINE_COLOR "255.0000000000"
*DISP_LINE_STYLE "0.0000000000"
*DISP_LINE_WIDTH "0.2500000000"
*DISP_NOTE "測定データ-9"
*DISP_OFFSET_Y "0.0000000000"
*DISP_PEAKSEARCH_UNIT_Y "cps"
*DISP_RANGE_BOTTOM "0.0000000000"
*DISP_RANGE_LEFT "20.0000000000"
*DISP_RANGE_LOGCUTOFF "0.0100000000"
*DISP_RANGE_RIGHT "70.0000000000"
*DISP_RANGE_TOP "12510.0000000000"
*DISP_SCALE_MODE_Y "0.0000000000"
*DISP_TAB_NAME "2θ/θ"
*DISP_TITLE_Y "強度"
*DISP_UNIT_Y "cps"
*DISP_WINDOW_NAME "MSG_MACROENGINE"
*FILE_COMMENT " "
*FILE_MD5 ""
*FILE_MEMO " "
*FILE_OPERATOR "Administrator"
*FILE_SAMPLE " "
*FILE_TYPE "RAS_RAW"
*FILE_USERGROUP "システムマネージャ"
*FILE_VERSION "1.0000000000"
*HW_ATTACHMENT_ID "ATT0025"
*HW_ATTACHMENT_NAME "標準|Standard"
*HW_COUNTER_ID-0 "CUT0025"
*HW_COUNTER_ID-1 "CUT0020"
*HW_COUNTER_ID-2 "CUT0020"
*HW_COUNTER_ID-3 "CSL0021"
*HW_COUNTER_ID-4 "CMC0021"
*HW_COUNTER_NAME-0 "D/teX Ultra|D/teX Ultra"
*HW_COUNTER_NAME-1 "None|None"
*HW_COUNTER_NAME-2 "None|None"
*HW_COUNTER_NAME-3 "BBM|BBM"
*HW_COUNTER_NAME-4 "検出器モノクロメータ|Detector monochromator"
*HW_COUNTER_SELECT_NAME "D/teX Ultra|D/teX Ultra"
*HW_GONIOMETER_ID "GON0023"
*HW_GONIOMETER_NAME "SmartLab|SmartLab"
*HW_GONIOMETER_RADIUS-0 "90.0"
*HW_GONIOMETER_RADIUS-1 "114.0"
*HW_GONIOMETER_RADIUS-2 "190.0"
*HW_GONIOMETER_RADIUS-3 "300.0"
*HW_GONIOMETER_RADIUS-4 "187.0"
*HW_GONIOMETER_RADIUS-5 "300.0"
*HW_GONIOMETER_RADIUS-6 "113.0"
*HW_GONIOMETER_RADIUS-7 "331.0"
*HW_I_OPT_ID-0 "CBO0021"
*HW_I_OPT_ID-1 "ICR0023"
*HW_I_OPT_ID-2 "ISL0021"
*HW_I_OPT_ID-3 "ISO0021"
*HW_I_OPT_ID-4 "IAD0021"
*HW_I_OPT_ID-5 "IPR0001"
*HW_I_OPT_NAME-0 "CBOユニット|CBO unit"
*HW_I_OPT_NAME-1 "標準入射光学ユニット|Standard incident optical unit"
*HW_I_OPT_NAME-2 "標準入射スリットボックス|Standard incident slit box"
*HW_I_OPT_NAME-3 "入射平行スリット|Incident parallel slit"
*HW_I_OPT_NAME-4 "長手制限スリット|Length limiting slit"
*HW_I_OPT_NAME-5 "None|None"
*HW_R_ATTENUATER_AUTOMODE "0"
*HW_R_OPT_ID-0 "RSS0021"
*HW_R_OPT_ID-1 "RCR0023"
*HW_R_OPT_ID-2 "RSO0021"
*HW_R_OPT_ID-3 "RRS0021"
*HW_R_OPT_ID-4 "ATN0021"
*HW_R_OPT_ID-5 "RFL0021"
*HW_R_OPT_ID-6 "RAD0021"
*HW_R_OPT_NAME-0 "標準受光スリットボックス1|Standard receiving slit box # 1"
*HW_R_OPT_NAME-1 "標準受光光学ユニット1|Standard receiving unit # 1"
*HW_R_OPT_NAME-2 "標準受光光学ユニット2|Standard receiving optical unit # 2"
*HW_R_OPT_NAME-3 "標準受光スリットボックス2|Standard receiving slit box # 2"
*HW_R_OPT_NAME-4 "標準アッテネータ|Standard Attenuator"
*HW_R_OPT_NAME-5 "Cu Kβ|Cu K-beta"
*HW_R_OPT_NAME-6 "調整用受光スリット|Alignment receiving slit"
*HW_SAMPLE_HOLDER_ID "SMP0023"
*HW_SAMPLE_HOLDER_NAME "標準Zステージ|Standard Z stage"
*HW_XG_CURRENT_MAX "50"
*HW_XG_CURRENT_MIN "2"
*HW_XG_CURRENT_RESOLUTION "1"
*HW_XG_CURRENT_UNIT "mA"
*HW_XG_FOCUS "1mm x 10mm"
*HW_XG_FOCUS_TYPE "Normal"
*HW_XG_ID ""
*HW_XG_NAME "3kW 封入管(ID:1200)|3kW Sealed tube(ID:1200)"
*HW_XG_TARGET_ATOMIC_NUMBER "29.0000000000"
*HW_XG_TARGET_NAME "Cu"
*HW_XG_TYPE "Hermetic"
*HW_XG_VOLTAGE_MAX "60"
*HW_XG_VOLTAGE_MIN "20"
*HW_XG_VOLTAGE_RESOLUTION "1"
*HW_XG_VOLTAGE_UNIT "kV"
*HW_XG_WATT_MAX "1.500"
*HW_XG_WATT_UNIT "kW"
*HW_XG_WAVE_LENGTH_ALPHA1 "1.540593"
*HW_XG_WAVE_LENGTH_ALPHA2 "1.544414"
*HW_XG_WAVE_LENGTH_BETA "1.392250"
*MEAS_COND_AXIS_NAME-0 "2θ/θ"
*MEAS_COND_AXIS_NAME-1 "2θ"
*MEAS_COND_AXIS_NAME-2 "ω"
*MEAS_COND_AXIS_NAME-3 "Z"
*MEAS_COND_AXIS_NAME-4 "2θ/ω"
*MEAS_COND_AXIS_NAME-5 "θs"
*MEAS_COND_AXIS_NAME-6 "θd"
*MEAS_COND_AXIS_NAME-7 "Ts"
*MEAS_COND_AXIS_NAME-8 "CBO選択スリット"
*MEAS_COND_AXIS_NAME-9 "M"
*MEAS_COND_AXIS_NAME-10 "入射平行スリット"
*MEAS_COND_AXIS_NAME-11 "入射スリット"
*MEAS_COND_AXIS_NAME-12 ""
*MEAS_COND_AXIS_NAME-13 "Zs"
*MEAS_COND_AXIS_NAME-14 "入射光学素子"
*MEAS_COND_AXIS_NAME-15 "長手制限スリット"
*MEAS_COND_AXIS_NAME-16 "センタースリット"
*MEAS_COND_AXIS_NAME-17 "フィルター"
*MEAS_COND_AXIS_NAME-18 "受光スリット1"
*MEAS_COND_AXIS_NAME-19 "受光スリット2"
*MEAS_COND_AXIS_NAME-20 "受光光学素子"
*MEAS_COND_AXIS_NAME-21 "受光平行スリット"
*MEAS_COND_AXIS_NAME-22 "調整用受光スリット"
*MEAS_COND_AXIS_NAME-23 ""
*MEAS_COND_AXIS_NAME-24 ""
*MEAS_COND_AXIS_NAME-25 "Zd"
*MEAS_COND_AXIS_NAME-26 "アッテネータ"
*MEAS_COND_AXIS_NAME-27 "検出器モノクロメータ"
*MEAS_COND_AXIS_NAME-28 "モノクロメータスリット"
*MEAS_COND_AXIS_NAME-29 "プライマリビーム"
*MEAS_COND_AXIS_NAME-30 "PHA"
*MEAS_COND_AXIS_NAME_INTERNAL-0 "TwoThetaTheta"
*MEAS_COND_AXIS_NAME_INTERNAL-1 "TwoTheta"
*MEAS_COND_AXIS_NAME_INTERNAL-2 "Omega"
*MEAS_COND_AXIS_NAME_INTERNAL-3 "Z"
*MEAS_COND_AXIS_NAME_INTERNAL-4 "TwoThetaOmega"
*MEAS_COND_AXIS_NAME_INTERNAL-5 "ThetaS"
*MEAS_COND_AXIS_NAME_INTERNAL-6 "ThetaD"
*MEAS_COND_AXIS_NAME_INTERNAL-7 "Ts"
*MEAS_COND_AXIS_NAME_INTERNAL-8 "CBO"
*MEAS_COND_AXIS_NAME_INTERNAL-9 "CBO-M"
*MEAS_COND_AXIS_NAME_INTERNAL-10 "IncidentSollerSlit"
*MEAS_COND_AXIS_NAME_INTERNAL-11 "IncidentSlitBox"
*MEAS_COND_AXIS_NAME_INTERNAL-12 "IncidentSlitBox-_Axis"
*MEAS_COND_AXIS_NAME_INTERNAL-13 "Zs"
*MEAS_COND_AXIS_NAME_INTERNAL-14 "IncidentMonochromator"
*MEAS_COND_AXIS_NAME_INTERNAL-15 "IncidentAxdSlit"
*MEAS_COND_AXIS_NAME_INTERNAL-16 "CenterSlit"
*MEAS_COND_AXIS_NAME_INTERNAL-17 "Filter"
*MEAS_COND_AXIS_NAME_INTERNAL-18 "ReceivingSlitBox1"
*MEAS_COND_AXIS_NAME_INTERNAL-19 "ReceivingSlitBox2"
*MEAS_COND_AXIS_NAME_INTERNAL-20 "ReceivingOptics"
*MEAS_COND_AXIS_NAME_INTERNAL-21 "ReceivingSollerSlit"
*MEAS_COND_AXIS_NAME_INTERNAL-22 "ReceivingAxdSlit"
*MEAS_COND_AXIS_NAME_INTERNAL-23 "ReceivingSlitBox1-_Axis"
*MEAS_COND_AXIS_NAME_INTERNAL-24 "ReceivingSlitBox2-_Axis"
*MEAS_COND_AXIS_NAME_INTERNAL-25 "ReceivingSlitBox2-Zd"
*MEAS_COND_AXIS_NAME_INTERNAL-26 "Attenuator"
*MEAS_COND_AXIS_NAME_INTERNAL-27 "CounterMonochromator"
*MEAS_COND_AXIS_NAME_INTERNAL-28 "CounterSlit"
*MEAS_COND_AXIS_NAME_INTERNAL-29 "IncidentPrimary"
*MEAS_COND_AXIS_NAME_INTERNAL-30 "PHA"
*MEAS_COND_AXIS_NAME_MAGICNO-0 "83951616.0000000000"
*MEAS_COND_AXIS_NAME_MAGICNO-1 "268632064.0000000000"
*MEAS_COND_AXIS_NAME_MAGICNO-2 "268500992.0000000000"
*MEAS_COND_AXIS_NAME_MAGICNO-3 "285278208.0000000000"
*MEAS_COND_AXIS_NAME_MAGICNO-4 "83951616.0000000000"
*MEAS_COND_AXIS_NAME_MAGICNO-5 "131072.0000000000"
*MEAS_COND_AXIS_NAME_MAGICNO-6 "131072.0000000000"
*MEAS_COND_AXIS_NAME_MAGICNO-7 "318898176.0000000000"
*MEAS_COND_AXIS_NAME_MAGICNO-8 "20971521.0000000000"
*MEAS_COND_AXIS_NAME_MAGICNO-9 "285343744.0000000000"
*MEAS_COND_AXIS_NAME_MAGICNO-10 "20971521.0000000000"
*MEAS_COND_AXIS_NAME_MAGICNO-11 "22020097.0000000000"
*MEAS_COND_AXIS_NAME_MAGICNO-12 "25165824.0000000000"
*MEAS_COND_AXIS_NAME_MAGICNO-13 "318898176.0000000000"
*MEAS_COND_AXIS_NAME_MAGICNO-14 "1.0000000000"
*MEAS_COND_AXIS_NAME_MAGICNO-15 "20971521.0000000000"
*MEAS_COND_AXIS_NAME_MAGICNO-16 "20971521.0000000000"
*MEAS_COND_AXIS_NAME_MAGICNO-17 "20971521.0000000000"
*MEAS_COND_AXIS_NAME_MAGICNO-18 "23068673.0000000000"
*MEAS_COND_AXIS_NAME_MAGICNO-19 "23068673.0000000000"
*MEAS_COND_AXIS_NAME_MAGICNO-20 "20971521.0000000000"
*MEAS_COND_AXIS_NAME_MAGICNO-21 "20971521.0000000000"
*MEAS_COND_AXIS_NAME_MAGICNO-22 "20971521.0000000000"
*MEAS_COND_AXIS_NAME_MAGICNO-23 "25165824.0000000000"
*MEAS_COND_AXIS_NAME_MAGICNO-24 "25165824.0000000000"
*MEAS_COND_AXIS_NAME_MAGICNO-25 "285343744.0000000000"
*MEAS_COND_AXIS_NAME_MAGICNO-26 "17301505.0000000000"
*MEAS_COND_AXIS_NAME_MAGICNO-27 "20971521.0000000000"
*MEAS_COND_AXIS_NAME_MAGICNO-28 "20971521.0000000000"
*MEAS_COND_AXIS_NAME_MAGICNO-29 "20971521.0000000000"
*MEAS_COND_AXIS_NAME_MAGICNO-30 "0.0000000000"
*MEAS_COND_AXIS_OFFSET-0 "-"
*MEAS_COND_AXIS_OFFSET-1 "-0.1081000000"
*MEAS_COND_AXIS_OFFSET-2 "0.3758000000"
*MEAS_COND_AXIS_OFFSET-3 "-"
*MEAS_COND_AXIS_OFFSET-4 "-"
*MEAS_COND_AXIS_OFFSET-5 "0.3758000000"
*MEAS_COND_AXIS_OFFSET-6 "-0.4839000000"
*MEAS_COND_AXIS_OFFSET-7 "-"
*MEAS_COND_AXIS_OFFSET-8 "-"
*MEAS_COND_AXIS_OFFSET-9 "-"
*MEAS_COND_AXIS_OFFSET-10 "-"
*MEAS_COND_AXIS_OFFSET-11 "-"
*MEAS_COND_AXIS_OFFSET-12 "-"
*MEAS_COND_AXIS_OFFSET-13 "-"
*MEAS_COND_AXIS_OFFSET-14 "-"
*MEAS_COND_AXIS_OFFSET-15 "-"
*MEAS_COND_AXIS_OFFSET-16 "-"
*MEAS_COND_AXIS_OFFSET-17 "-"
*MEAS_COND_AXIS_OFFSET-18 "-"
*MEAS_COND_AXIS_OFFSET-19 "-"
*MEAS_COND_AXIS_OFFSET-20 "-"
*MEAS_COND_AXIS_OFFSET-21 "-"
*MEAS_COND_AXIS_OFFSET-22 "-"
*MEAS_COND_AXIS_OFFSET-23 "-"
*MEAS_COND_AXIS_OFFSET-24 "-"
*MEAS_COND_AXIS_OFFSET-25 "-"
*MEAS_COND_AXIS_OFFSET-26 "-"
*MEAS_COND_AXIS_OFFSET-27 "-"
*MEAS_COND_AXIS_OFFSET-28 "-"
*MEAS_COND_AXIS_OFFSET-29 "-"
*MEAS_COND_AXIS_OFFSET-30 "-"
*MEAS_COND_AXIS_POSITION-0 "0.0000000000"
*MEAS_COND_AXIS_POSITION-1 "0.0000000000"
*MEAS_COND_AXIS_POSITION-2 "0.0000000000"
*MEAS_COND_AXIS_POSITION-3 "-0.5500000000"
*MEAS_COND_AXIS_POSITION-4 "0.0000000000"
*MEAS_COND_AXIS_POSITION-5 "0.0000000000"
*MEAS_COND_AXIS_POSITION-6 "0.0000000000"
*MEAS_COND_AXIS_POSITION-7 "-0.4278800000"
*MEAS_COND_AXIS_POSITION-8 "BB"
*MEAS_COND_AXIS_POSITION-9 "0.0000000000"
*MEAS_COND_AXIS_POSITION-10 "Soller_slit_5.0deg"
*MEAS_COND_AXIS_POSITION-11 "2/3deg"
*MEAS_COND_AXIS_POSITION-12 "2.2088000000"
*MEAS_COND_AXIS_POSITION-13 "-0.4140600000"
*MEAS_COND_AXIS_POSITION-14 "0.0000000000"
*MEAS_COND_AXIS_POSITION-15 "10.0mm"
*MEAS_COND_AXIS_POSITION-16 "None"
*MEAS_COND_AXIS_POSITION-17 "Cu_K-beta"
*MEAS_COND_AXIS_POSITION-18 "13.000mm"
*MEAS_COND_AXIS_POSITION-19 "13.000mm"
*MEAS_COND_AXIS_POSITION-20 "No_unit"
*MEAS_COND_AXIS_POSITION-21 "Soller_slit_5.0deg"
*MEAS_COND_AXIS_POSITION-22 "None"
*MEAS_COND_AXIS_POSITION-23 "13.0000000000"
*MEAS_COND_AXIS_POSITION-24 "13.0000000000"
*MEAS_COND_AXIS_POSITION-25 "0.0109400000"
*MEAS_COND_AXIS_POSITION-26 "Open"
*MEAS_COND_AXIS_POSITION-27 "None"
*MEAS_COND_AXIS_POSITION-28 "None"
*MEAS_COND_AXIS_POSITION-29 "None"
*MEAS_COND_AXIS_POSITION-30 "38.0000000000"
*MEAS_COND_AXIS_UNIT-0 "deg"
*MEAS_COND_AXIS_UNIT-1 "deg"
*MEAS_COND_AXIS_UNIT-2 "deg"
*MEAS_COND_AXIS_UNIT-3 "mm"
*MEAS_COND_AXIS_UNIT-4 "deg"
*MEAS_COND_AXIS_UNIT-5 "deg"
*MEAS_COND_AXIS_UNIT-6 "deg"
*MEAS_COND_AXIS_UNIT-7 "mm"
*MEAS_COND_AXIS_UNIT-8 ""
*MEAS_COND_AXIS_UNIT-9 "pulse"
*MEAS_COND_AXIS_UNIT-10 ""
*MEAS_COND_AXIS_UNIT-11 ""
*MEAS_COND_AXIS_UNIT-12 "mm"
*MEAS_COND_AXIS_UNIT-13 "mm"
*MEAS_COND_AXIS_UNIT-14 ""
*MEAS_COND_AXIS_UNIT-15 ""
*MEAS_COND_AXIS_UNIT-16 ""
*MEAS_COND_AXIS_UNIT-17 ""
*MEAS_COND_AXIS_UNIT-18 ""
*MEAS_COND_AXIS_UNIT-19 ""
*MEAS_COND_AXIS_UNIT-20 ""
*MEAS_COND_AXIS_UNIT-21 ""
*MEAS_COND_AXIS_UNIT-22 ""
*MEAS_COND_AXIS_UNIT-23 "mm"
*MEAS_COND_AXIS_UNIT-24 "mm"
*MEAS_COND_AXIS_UNIT-25 "mm"
*MEAS_COND_AXIS_UNIT-26 ""
*MEAS_COND_AXIS_UNIT-27 ""
*MEAS_COND_AXIS_UNIT-28 ""
*MEAS_COND_AXIS_UNIT-29 ""
*MEAS_COND_AXIS_UNIT-30 "div"
*MEAS_COND_COUNTER_CNTLOSS_CORR "0.0000000000"
*MEAS_COND_COUNTER_PHABASE "38.0000000000"
*MEAS_COND_COUNTER_PHAWINDOW "16.0000000000"
*MEAS_COND_COUNTER_PHA_UNIT "div"
*MEAS_COND_COUNTER_TAUDIFF "30.0000000000"
*MEAS_COND_COUNTER_TAUINT "0.0000000000"
*MEAS_COND_IRRADIATION_MODE "OFF"
*MEAS_COND_IRRADIATION_WIDTH ""
*MEAS_COND_OPT_ATTR "集中法"
*MEAS_COND_OPT_NAME "@集中法"
*MEAS_COND_UNSYMMETRIC_MODE "OFF"
*MEAS_COND_XG_CURRENT "30.0000000000"
*MEAS_COND_XG_VOLTAGE "40.0000000000"
*MEAS_COND_XG_WAVE_TYPE "Ka"
*MEAS_DATA_COUNT "5001.0000000000"
*MEAS_SCAN_AXIS_X "2θ/θ"
*MEAS_SCAN_AXIS_X_INTERNAL "TwoThetaTheta"
*MEAS_SCAN_END_TIME "07/14/21 19:32:50"
*MEAS_SCAN_MODE "CONTINUOUS"
*MEAS_SCAN_MONITOR "0"
*MEAS_SCAN_RESOLUTION_X "0.0002"
*MEAS_SCAN_SPEED "1.0"
*MEAS_SCAN_SPEED_UNIT "deg/min"
*MEAS_SCAN_START "20.0000000000"
*MEAS_SCAN_START_TIME "07/14/21 18:39:56"
*MEAS_SCAN_STEP "0.0100000000"
*MEAS_SCAN_STOP "70.0000000000"
*MEAS_SCAN_UNIT_X "deg"
*MEAS_SCAN_UNIT_Y "counts"
*RAS_HEADER_END
*RAS_INT_START
20.0000 1258.0000 1.0000
20.0400 1323.0000 1.0000
20.0800 1301.0000 1.0000
20.1200 1281.0000 1.0000
20.1600 1323.0000 1.0000
20.2000 1309.0000 1.0000
20.2400 1255.0000 1.0000
20.2800 1303.0000 1.0000
20.3200 1338.0000 1.0000
20.3600 1370.0000 1.0000
20.4000 1256.0000 1.0000
20.4400 1306.0000 1.0000
20.4800 1340.0000 1.0000
20.5200 1281.0000 1.0000
20.5600 1283.0000 1.0000
20.6000 1267.0000 1.0000
20.6400 1318.0000 1.0000
20.6800 1306.0000 1.0000
20.7200 1310.0000 1.0000
20.7600 1330.0000 1.0000
20.8000 1306.0000 1.0000
20.8400 1290.0000 1.0000
20.8800 1321.0000 1.0000
20.9200 1275.0000 1.0000
20.9600 1303.0000 1.0000
21.0000 1273.0000 1.0000
21.0400 1303.0000 1.0000
21.0800 1245.0000 1.0000
21.1200 1315.0000 1.0000
21.1600 1364.0000 1.0000
21.2000 1339.0000 1.0000
21.2400 1285.0000 1.0000
21.2800 1301.0000 1.0000
21.3200 1346.0000 1.0000
21.3600 1362.0000 1.0000
21.4000 1319.0000 1.0000
21.4400 1329.0000 1.0000
21.4800 1286.0000 1.0000
21.5200 1370.0000 1.0000
21.5600 1278.0000 1.0000
21.6000 1270.0000 1.0000
21.6400 1383.0000 1.0000
21.6800 1361.0000 1.0000
21.7200 1310.0000 1.0000
21.7600 1302.0000 1.0000
21.8000 1307.0000 1.0000
21.8400 1311.0000 1.0000
21.8800 1341.0000 1.0000
21.9200 1320.0000 1.0000
21.9600 1322.0000 1.0000
22.0000 1344.0000 1.0000
22.0400 1356.0000 1.0000
22.0800 1380.0000 1.0000
22.1200 1341.0000 1.0000
22.1600 1366.0000 1.0000
22.2000 1417.0000 1.0000
22.2400 1326.0000 1.0000
22.2800 1372.0000 1.0000
22.3200 1305.0000 1.0000
22.3600 1355.0000 1.0000
22.4000 1340.0000 1.0000
22.4400 1378.0000 1.0000
22.4800 1324.0000 1.0000
22.5200 1409.0000 1.0000
22.5600 1305.0000 1.0000
22.6000 1333.0000 1.0000
22.6400 1408.0000 1.0000
22.6800 1417.0000 1.0000
22.7200 1397.0000 1.0000
22.7600 1421.0000 1.0000
22.8000 1317.0000 1.0000
22.8400 1297.0000 1.0000
22.8800 1360.0000 1.0000
22.9200 1420.0000 1.0000
22.9600 1387.0000 1.0000
23.0000 1366.0000 1.0000
23.0400 1432.0000 1.0000
23.0800 1386.0000 1.0000
23.1200 1382.0000 1.0000
23.1600 1411.0000 1.0000
23.2000 1349.0000 1.0000
23.2400 1389.0000 1.0000
23.2800 1385.0000 1.0000
23.3200 1338.0000 1.0000
23.3600 1356.0000 1.0000
23.4000 1330.0000 1.0000
23.4400 1381.0000 1.0000
23.4800 1336.0000 1.0000
23.5200 1384.0000 1.0000
23.5600 1369.0000 1.0000
23.6000 1350.0000 1.0000
23.6400 1315.0000 1.0000
23.6800 1428.0000 1.0000
23.7200 1398.0000 1.0000
23.7600 1402.0000 1.0000
23.8000 1377.0000 1.0000
23.8400 1425.0000 1.0000
23.8800 1360.0000 1.0000
23.9200 1346.0000 1.0000
23.9600 1337.0000 1.0000
24.0000 1398.0000 1.0000
24.0400 1435.0000 1.0000
24.0800 1417.0000 1.0000
24.1200 1388.0000 1.0000
24.1600 1405.0000 1.0000
24.2000 1409.0000 1.0000
24.2400 1419.0000 1.0000
24.2800 1391.0000 1.0000
24.3200 1421.0000 1.0000
24.3600 1391.0000 1.0000
24.4000 1358.0000 1.0000
24.4400 1389.0000 1.0000
24.4800 1392.0000 1.0000
24.5200 1369.0000 1.0000
24.5600 1470.0000 1.0000
24.6000 1389.0000 1.0000
24.6400 1499.0000 1.0000
24.6800 1458.0000 1.0000
24.7200 1461.0000 1.0000
24.7600 1407.0000 1.0000
24.8000 1419.0000 1.0000
24.8400 1471.0000 1.0000
24.8800 1422.0000 1.0000
24.9200 1415.0000 1.0000
24.9600 1394.0000 1.0000
25.0000 1405.0000 1.0000
25.0400 1433.0000 1.0000
25.0800 1476.0000 1.0000
25.1200 1485.0000 1.0000
25.1600 1461.0000 1.0000
25.2000 1430.0000 1.0000
25.2400 1484.0000 1.0000
25.2800 1436.0000 1.0000
25.3200 1418.0000 1.0000
25.3600 1385.0000 1.0000
25.4000 1498.0000 1.0000
25.4400 1427.0000 1.0000
25.4800 1451.0000 1.0000
25.5200 1426.0000 1.0000
25.5600 1405.0000 1.0000
25.6000 1409.0000 1.0000
25.6400 1414.0000 1.0000
25.6800 1472.0000 1.0000
25.7200 1444.0000 1.0000
25.7600 1427.0000 1.0000
25.8000 1491.0000 1.0000
25.8400 1377.0000 1.0000
25.8800 1403.0000 1.0000
25.9200 1432.0000 1.0000
25.9600 1443.0000 1.0000
26.0000 1433.0000 1.0000
26.0400 1482.0000 1.0000
26.0800 1439.0000 1.0000
26.1200 1449.0000 1.0000
26.1600 1455.0000 1.0000
26.2000 1467.0000 1.0000
26.2400 1483.0000 1.0000
26.2800 1465.0000 1.0000
26.3200 1467.0000 1.0000
26.3600 1485.0000 1.0000
26.4000 1485.0000 1.0000
26.4400 1469.0000 1.0000
26.4800 1531.0000 1.0000
26.5200 1528.0000 1.0000
26.5600 1461.0000 1.0000
26.6000 1523.0000 1.0000
26.6400 1608.0000 1.0000
26.6800 1541.0000 1.0000
26.7200 1547.0000 1.0000
26.7600 1597.0000 1.0000
26.8000 1623.0000 1.0000
26.8400 1676.0000 1.0000
26.8800 1662.0000 1.0000
26.9200 1771.0000 1.0000
26.9600 1911.0000 1.0000
27.0000 2034.0000 1.0000
27.0400 2274.0000 1.0000
27.0800 2559.0000 1.0000
27.1200 2984.0000 1.0000
27.1600 3579.0000 1.0000
27.2000 4475.0000 1.0000
27.2400 5560.0000 1.0000
27.2800 6074.0000 1.0000
27.3200 5897.0000 1.0000
27.3600 4968.0000 1.0000
27.4000 4049.0000 1.0000
27.4400 3173.0000 1.0000
27.4800 2713.0000 1.0000
27.5200 2303.0000 1.0000
27.5600 2087.0000 1.0000
27.6000 1859.0000 1.0000
27.6400 1826.0000 1.0000
27.6800 1724.0000 1.0000
27.7200 1715.0000 1.0000
27.7600 1628.0000 1.0000
27.8000 1541.0000 1.0000
27.8400 1574.0000 1.0000
27.8800 1446.0000 1.0000
27.9200 1514.0000 1.0000
27.9600 1426.0000 1.0000
28.0000 1458.0000 1.0000
28.0400 1412.0000 1.0000
28.0800 1444.0000 1.0000
28.1200 1389.0000 1.0000
28.1600 1376.0000 1.0000
28.2000 1329.0000 1.0000
28.2400 1392.0000 1.0000
28.2800 1366.0000 1.0000
28.3200 1399.0000 1.0000
28.3600 1385.0000 1.0000
28.4000 1314.0000 1.0000
28.4400 1320.0000 1.0000
28.4800 1377.0000 1.0000
28.5200 1277.0000 1.0000
28.5600 1346.0000 1.0000
28.6000 1325.0000 1.0000
28.6400 1342.0000 1.0000
28.6800 1300.0000 1.0000
28.7200 1318.0000 1.0000
28.7600 1334.0000 1.0000
28.8000 1333.0000 1.0000
28.8400 1288.0000 1.0000
28.8800 1307.0000 1.0000
28.9200 1334.0000 1.0000
28.9600 1278.0000 1.0000
29.0000 1265.0000 1.0000
29.0400 1281.0000 1.0000
29.0800 1349.0000 1.0000
29.1200 1350.0000 1.0000
29.1600 1346.0000 1.0000
29.2000 1267.0000 1.0000
29.2400 1295.0000 1.0000
29.2800 1244.0000 1.0000
29.3200 1358.0000 1.0000
29.3600 1259.0000 1.0000
29.4000 1225.0000 1.0000
29.4400 1242.0000 1.0000
29.4800 1250.0000 1.0000
29.5200 1237.0000 1.0000
29.5600 1264.0000 1.0000
29.6000 1299.0000 1.0000
29.6400 1284.0000 1.0000
29.6800 1258.0000 1.0000
29.7200 1270.0000 1.0000
29.7600 1234.0000 1.0000
29.8000 1253.0000 1.0000
29.8400 1192.0000 1.0000
29.8800 1217.0000 1.0000
29.9200 1210.0000 1.0000
29.9600 1257.0000 1.0000
30.0000 1289.0000 1.0000
30.0400 1274.0000 1.0000
30.0800 1270.0000 1.0000
30.1200 1225.0000 1.0000
30.1600 1198.0000 1.0000
30.2000 1165.0000 1.0000
30.2400 1233.0000 1.0000
30.2800 1180.0000 1.0000
30.3200 1232.0000 1.0000
30.3600 1198.0000 1.0000
30.4000 1177.0000 1.0000
30.4400 1209.0000 1.0000
30.4800 1167.0000 1.0000
30.5200 1239.0000 1.0000
30.5600 1193.0000 1.0000
30.6000 1290.0000 1.0000
30.6400 1174.0000 1.0000
30.6800 1197.0000 1.0000
30.7200 1178.0000 1.0000
30.7600 1190.0000 1.0000
30.8000 1199.0000 1.0000
30.8400 1178.0000 1.0000
30.8800 1171.0000 1.0000
30.9200 1180.0000 1.0000
30.9600 1207.0000 1.0000
31.0000 1169.0000 1.0000
31.0400 1195.0000 1.0000
31.0800 1151.0000 1.0000
31.1200 1191.0000 1.0000
31.1600 1132.0000 1.0000
31.2000 1145.0000 1.0000
31.2400 1152.0000 1.0000
31.2800 1140.0000 1.0000
31.3200 1192.0000 1.0000
31.3600 1146.0000 1.0000
31.4000 1081.0000 1.0000
31.4400 1187.0000 1.0000
31.4800 1123.0000 1.0000
31.5200 1174.0000 1.0000
31.5600 1155.0000 1.0000
31.6000 1117.0000 1.0000
31.6400 1137.0000 1.0000
31.6800 1150.0000 1.0000
31.7200 1105.0000 1.0000
31.7600 1183.0000 1.0000
31.8000 1081.0000 1.0000
31.8400 1099.0000 1.0000
31.8800 1154.0000 1.0000
31.9200 1153.0000 1.0000
31.9600 1190.0000 1.0000
32.0000 1137.0000 1.0000
32.0400 1221.0000 1.0000
32.0800 1190.0000 1.0000
32.1200 1156.0000 1.0000
32.1600 1084.0000 1.0000
32.2000 1101.0000 1.0000
32.2400 1124.0000 1.0000
32.2800 1138.0000 1.0000
32.3200 1130.0000 1.0000
32.3600 1131.0000 1.0000
32.4000 1143.0000 1.0000
32.4400 1169.0000 1.0000
32.4800 1135.0000 1.0000
32.5200 1118.0000 1.0000
32.5600 1170.0000 1.0000
32.6000 1138.0000 1.0000
32.6400 1123.0000 1.0000
32.6800 1070.0000 1.0000
32.7200 1108.0000 1.0000
32.7600 1086.0000 1.0000
32.8000 1082.0000 1.0000
32.8400 1011.0000 1.0000
32.8800 1108.0000 1.0000
32.9200 1091.0000 1.0000
32.9600 1061.0000 1.0000
33.0000 1071.0000 1.0000
33.0400 1123.0000 1.0000
33.0800 1060.0000 1.0000
33.1200 1061.0000 1.0000
33.1600 1086.0000 1.0000
33.2000 1070.0000 1.0000
33.2400 1094.0000 1.0000
33.2800 1054.0000 1.0000
33.3200 1086.0000 1.0000
33.3600 1091.0000 1.0000
33.4000 1084.0000 1.0000
33.4400 1051.0000 1.0000
33.4800 1034.0000 1.0000
33.5200 1058.0000 1.0000
33.5600 1060.0000 1.0000
33.6000 1018.0000 1.0000
33.6400 1044.0000 1.0000
33.6800 1100.0000 1.0000
33.7200 1119.0000 1.0000
33.7600 1099.0000 1.0000
33.8000 1081.0000 1.0000
33.8400 1092.0000 1.0000
33.8800 1099.0000 1.0000
33.9200 1143.0000 1.0000
33.9600 1125.0000 1.0000
34.0000 1160.0000 1.0000
34.0400 1165.0000 1.0000
34.0800 1156.0000 1.0000
34.1200 1225.0000 1.0000
34.1600 1298.0000 1.0000
34.2000 1315.0000 1.0000
34.2400 1346.0000 1.0000
34.2800 1495.0000 1.0000
34.3200 1646.0000 1.0000
34.3600 1927.0000 1.0000
34.4000 2354.0000 1.0000
34.4400 2687.0000 1.0000
34.4800 3026.0000 1.0000
34.5200 2802.0000 1.0000
34.5600 2604.0000 1.0000
34.6000 2123.0000 1.0000
34.6400 1849.0000 1.0000
34.6800 1562.0000 1.0000
34.7200 1447.0000 1.0000
34.7600 1324.0000 1.0000
34.8000 1234.0000 1.0000
34.8400 1165.0000 1.0000
34.8800 1200.0000 1.0000
34.9200 1101.0000 1.0000
34.9600 1060.0000 1.0000
35.0000 1020.0000 1.0000
35.0400 1017.0000 1.0000
35.0800 1024.0000 1.0000
35.1200 1009.0000 1.0000
35.1600 1039.0000 1.0000
35.2000 982.0000 1.0000
35.2400 944.0000 1.0000
35.2800 938.0000 1.0000
35.3200 926.0000 1.0000
35.3600 904.0000 1.0000
35.4000 881.0000 1.0000
35.4400 975.0000 1.0000
35.4800 891.0000 1.0000
35.5200 887.0000 1.0000
35.5600 897.0000 1.0000
35.6000 884.0000 1.0000
35.6400 971.0000 1.0000
35.6800 906.0000 1.0000
35.7200 895.0000 1.0000
35.7600 980.0000 1.0000
35.8000 899.0000 1.0000
35.8400 911.0000 1.0000
35.8800 891.0000 1.0000
35.9200 890.0000 1.0000
35.9600 869.0000 1.0000
36.0000 891.0000 1.0000
36.0400 895.0000 1.0000
36.0800 913.0000 1.0000
36.1200 866.0000 1.0000
36.1600 906.0000 1.0000
36.2000 922.0000 1.0000
36.2400 915.0000 1.0000
36.2800 924.0000 1.0000
36.3200 940.0000 1.0000
36.3600 962.0000 1.0000
36.4000 984.0000 1.0000
36.4400 916.0000 1.0000
36.4800 923.0000 1.0000
36.5200 937.0000 1.0000
36.5600 900.0000 1.0000
36.6000 883.0000 1.0000
36.6400 887.0000 1.0000
36.6800 852.0000 1.0000
36.7200 886.0000 1.0000
36.7600 792.0000 1.0000
36.8000 850.0000 1.0000
36.8400 840.0000 1.0000
36.8800 848.0000 1.0000
36.9200 855.0000 1.0000
36.9600 803.0000 1.0000
37.0000 837.0000 1.0000
37.0400 806.0000 1.0000
37.0800 835.0000 1.0000
37.1200 841.0000 1.0000
37.1600 812.0000 1.0000
37.2000 811.0000 1.0000
37.2400 784.0000 1.0000
37.2800 843.0000 1.0000
37.3200 819.0000 1.0000
37.3600 810.0000 1.0000
37.4000 795.0000 1.0000
37.4400 809.0000 1.0000
37.4800 806.0000 1.0000
37.5200 813.0000 1.0000
37.5600 833.0000 1.0000
37.6000 809.0000 1.0000
37.6400 832.0000 1.0000
37.6800 875.0000 1.0000
37.7200 818.0000 1.0000
37.7600 894.0000 1.0000
37.8000 823.0000 1.0000
37.8400 847.0000 1.0000
37.8800 866.0000 1.0000
37.9200 879.0000 1.0000
37.9600 828.0000 1.0000
38.0000 881.0000 1.0000
38.0400 935.0000 1.0000
38.0800 966.0000 1.0000
38.1200 1000.0000 1.0000
38.1600 1056.0000 1.0000
38.2000 1164.0000 1.0000
38.2400 1384.0000 1.0000
38.2800 1571.0000 1.0000
38.3200 1835.0000 1.0000
38.3600 2340.0000 1.0000
38.4000 3090.0000 1.0000
38.4400 4143.0000 1.0000
38.4800 5010.0000 1.0000
38.5200 5196.0000 1.0000
38.5600 5037.0000 1.0000
38.6000 4292.0000 1.0000
38.6400 3559.0000 1.0000
38.6800 2799.0000 1.0000
38.7200 2062.0000 1.0000
38.7600 1651.0000 1.0000
38.8000 1374.0000 1.0000
38.8400 1157.0000 1.0000
38.8800 1042.0000 1.0000
38.9200 965.0000 1.0000
38.9600 865.0000 1.0000
39.0000 835.0000 1.0000
39.0400 833.0000 1.0000
39.0800 804.0000 1.0000
39.1200 838.0000 1.0000
39.1600 779.0000 1.0000
39.2000 768.0000 1.0000
39.2400 740.0000 1.0000
39.2800 737.0000 1.0000
39.3200 799.0000 1.0000
39.3600 749.0000 1.0000
39.4000 774.0000 1.0000
39.4400 775.0000 1.0000
39.4800 767.0000 1.0000
39.5200 797.0000 1.0000
39.5600 786.0000 1.0000
39.6000 803.0000 1.0000
39.6400 800.0000 1.0000
39.6800 783.0000 1.0000
39.7200 739.0000 1.0000
39.7600 722.0000 1.0000
39.8000 683.0000 1.0000
39.8400 696.0000 1.0000
39.8800 679.0000 1.0000
39.9200 679.0000 1.0000
39.9600 702.0000 1.0000
40.0000 703.0000 1.0000
40.0400 705.0000 1.0000
40.0800 669.0000 1.0000
40.1200 666.0000 1.0000
40.1600 639.0000 1.0000
40.2000 662.0000 1.0000
40.2400 660.0000 1.0000
40.2800 679.0000 1.0000
40.3200 673.0000 1.0000
40.3600 653.0000 1.0000
40.4000 639.0000 1.0000
40.4400 675.0000 1.0000
40.4800 659.0000 1.0000
40.5200 702.0000 1.0000
40.5600 675.0000 1.0000
40.6000 631.0000 1.0000
40.6400 656.0000 1.0000
40.6800 703.0000 1.0000
40.7200 701.0000 1.0000
40.7600 660.0000 1.0000
40.8000 685.0000 1.0000
40.8400 635.0000 1.0000
40.8800 683.0000 1.0000
40.9200 617.0000 1.0000
40.9600 680.0000 1.0000
41.0000 649.0000 1.0000
41.0400 661.0000 1.0000
41.0800 696.0000 1.0000
41.1200 638.0000 1.0000
41.1600 645.0000 1.0000
41.2000 675.0000 1.0000
41.2400 633.0000 1.0000
41.2800 667.0000 1.0000
41.3200 663.0000 1.0000
41.3600 637.0000 1.0000
41.4000 634.0000 1.0000
41.4400 641.0000 1.0000
41.4800 607.0000 1.0000
41.5200 648.0000 1.0000
41.5600 677.0000 1.0000
41.6000 666.0000 1.0000
41.6400 642.0000 1.0000
41.6800 662.0000 1.0000
41.7200 643.0000 1.0000
41.7600 671.0000 1.0000
41.8000 648.0000 1.0000
41.8400 655.0000 1.0000
41.8800 663.0000 1.0000
41.9200 626.0000 1.0000
41.9600 665.0000 1.0000
42.0000 678.0000 1.0000
42.0400 655.0000 1.0000
42.0800 638.0000 1.0000
42.1200 686.0000 1.0000
42.1600 653.0000 1.0000
42.2000 646.0000 1.0000
42.2400 652.0000 1.0000
42.2800 707.0000 1.0000
42.3200 635.0000 1.0000
42.3600 652.0000 1.0000
42.4000 691.0000 1.0000
42.4400 664.0000 1.0000
42.4800 671.0000 1.0000
42.5200 614.0000 1.0000
42.5600 619.0000 1.0000
42.6000 662.0000 1.0000
42.6400 641.0000 1.0000
42.6800 692.0000 1.0000
42.7200 618.0000 1.0000
42.7600 641.0000 1.0000
42.8000 584.0000 1.0000
42.8400 652.0000 1.0000
42.8800 635.0000 1.0000
42.9200 640.0000 1.0000
42.9600 639.0000 1.0000
43.0000 640.0000 1.0000
43.0400 669.0000 1.0000
43.0800 670.0000 1.0000
43.1200 676.0000 1.0000
43.1600 707.0000 1.0000
43.2000 703.0000 1.0000
43.2400 689.0000 1.0000
43.2800 689.0000 1.0000
43.3200 695.0000 1.0000
43.3600 651.0000 1.0000
43.4000 671.0000 1.0000
43.4400 631.0000 1.0000
43.4800 653.0000 1.0000
43.5200 648.0000 1.0000
43.5600 616.0000 1.0000
43.6000 668.0000 1.0000
43.6400 622.0000 1.0000
43.6800 626.0000 1.0000
43.7200 623.0000 1.0000
43.7600 653.0000 1.0000
43.8000 665.0000 1.0000
43.8400 615.0000 1.0000
43.8800 627.0000 1.0000
43.9200 603.0000 1.0000
43.9600 627.0000 1.0000
44.0000 649.0000 1.0000
44.0400 642.0000 1.0000
44.0800 602.0000 1.0000
44.1200 675.0000 1.0000
44.1600 615.0000 1.0000
44.2000 583.0000 1.0000
44.2400 599.0000 1.0000
44.2800 634.0000 1.0000
44.3200 603.0000 1.0000
44.3600 608.0000 1.0000
44.4000 623.0000 1.0000
44.4400 625.0000 1.0000
44.4800 615.0000 1.0000
44.5200 597.0000 1.0000
44.5600 610.0000 1.0000
44.6000 611.0000 1.0000
44.6400 626.0000 1.0000
44.6800 640.0000 1.0000
44.7200 616.0000 1.0000
44.7600 598.0000 1.0000
44.8000 597.0000 1.0000
44.8400 574.0000 1.0000
44.8800 599.0000 1.0000
44.9200 594.0000 1.0000
44.9600 587.0000 1.0000
45.0000 616.0000 1.0000
45.0400 633.0000 1.0000
45.0800 607.0000 1.0000
45.1200 622.0000 1.0000
45.1600 576.0000 1.0000
45.2000 591.0000 1.0000
45.2400 610.0000 1.0000
45.2800 632.0000 1.0000
45.3200 630.0000 1.0000
45.3600 580.0000 1.0000
45.4000 592.0000 1.0000
45.4400 574.0000 1.0000
45.4800 615.0000 1.0000
45.5200 568.0000 1.0000
45.5600 596.0000 1.0000
45.6000 582.0000 1.0000
45.6400 565.0000 1.0000
45.6800 602.0000 1.0000
45.7200 610.0000 1.0000
45.7600 576.0000 1.0000
45.8000 597.0000 1.0000
45.8400 590.0000 1.0000
45.8800 619.0000 1.0000
45.9200 579.0000 1.0000
45.9600 577.0000 1.0000
46.0000 553.0000 1.0000
46.0400 612.0000 1.0000
46.0800 565.0000 1.0000
46.1200 605.0000 1.0000
46.1600 587.0000 1.0000
46.2000 589.0000 1.0000
46.2400 624.0000 1.0000
46.2800 587.0000 1.0000
46.3200 615.0000 1.0000
46.3600 585.0000 1.0000
46.4000 590.0000 1.0000
46.4400 596.0000 1.0000
46.4800 596.0000 1.0000
46.5200 580.0000 1.0000
46.5600 563.0000 1.0000
46.6000 564.0000 1.0000
46.6400 582.0000 1.0000
46.6800 592.0000 1.0000
46.7200 575.0000 1.0000
46.7600 558.0000 1.0000
46.8000 569.0000 1.0000
46.8400 545.0000 1.0000
46.8800 638.0000 1.0000
46.9200 578.0000 1.0000
46.9600 569.0000 1.0000
47.0000 590.0000 1.0000
47.0400 622.0000 1.0000
47.0800 591.0000 1.0000
47.1200 566.0000 1.0000
47.1600 568.0000 1.0000
47.2000 613.0000 1.0000
47.2400 579.0000 1.0000
47.2800 533.0000 1.0000
47.3200 573.0000 1.0000
47.3600 543.0000 1.0000
47.4000 546.0000 1.0000
47.4400 560.0000 1.0000
47.4800 616.0000 1.0000
47.5200 597.0000 1.0000
47.5600 575.0000 1.0000
47.6000 545.0000 1.0000
47.6400 600.0000 1.0000
47.6800 547.0000 1.0000
47.7200 518.0000 1.0000
47.7600 556.0000 1.0000
47.8000 554.0000 1.0000
47.8400 570.0000 1.0000
47.8800 572.0000 1.0000
47.9200 549.0000 1.0000
47.9600 567.0000 1.0000
48.0000 557.0000 1.0000
48.0400 531.0000 1.0000
48.0800 534.0000 1.0000
48.1200 533.0000 1.0000
48.1600 562.0000 1.0000
48.2000 585.0000 1.0000
48.2400 562.0000 1.0000
48.2800 521.0000 1.0000
48.3200 570.0000 1.0000
48.3600 550.0000 1.0000
48.4000 537.0000 1.0000
48.4400 562.0000 1.0000
48.4800 565.0000 1.0000
48.5200 540.0000 1.0000
48.5600 562.0000 1.0000
48.6000 535.0000 1.0000
48.6400 539.0000 1.0000
48.6800 524.0000 1.0000
48.7200 524.0000 1.0000
48.7600 525.0000 1.0000
48.8000 520.0000 1.0000
48.8400 552.0000 1.0000
48.8800 548.0000 1.0000
48.9200 506.0000 1.0000
48.9600 549.0000 1.0000
49.0000 543.0000 1.0000
49.0400 544.0000 1.0000
49.0800 505.0000 1.0000
49.1200 525.0000 1.0000
49.1600 523.0000 1.0000
49.2000 540.0000 1.0000
49.2400 553.0000 1.0000
49.2800 527.0000 1.0000
49.3200 477.0000 1.0000
49.3600 568.0000 1.0000
49.4000 559.0000 1.0000
49.4400 506.0000 1.0000
49.4800 533.0000 1.0000
49.5200 535.0000 1.0000
49.5600 519.0000 1.0000
49.6000 563.0000 1.0000
49.6400 559.0000 1.0000
49.6800 572.0000 1.0000
49.7200 532.0000 1.0000
49.7600 509.0000 1.0000
49.8000 519.0000 1.0000
49.8400 547.0000 1.0000
49.8800 537.0000 1.0000
49.9200 523.0000 1.0000
49.9600 567.0000 1.0000
50.0000 528.0000 1.0000
50.0400 534.0000 1.0000
50.0800 491.0000 1.0000
50.1200 473.0000 1.0000
50.1600 521.0000 1.0000
50.2000 516.0000 1.0000
50.2400 525.0000 1.0000
50.2800 529.0000 1.0000
50.3200 546.0000 1.0000
50.3600 520.0000 1.0000
50.4000 542.0000 1.0000
50.4400 555.0000 1.0000
50.4800 522.0000 1.0000
50.5200 567.0000 1.0000
50.5600 535.0000 1.0000
50.6000 537.0000 1.0000
50.6400 544.0000 1.0000
50.6800 537.0000 1.0000
50.7200 539.0000 1.0000
50.7600 555.0000 1.0000
50.8000 530.0000 1.0000
50.8400 502.0000 1.0000
50.8800 549.0000 1.0000
50.9200 551.0000 1.0000
50.9600 524.0000 1.0000
51.0000 559.0000 1.0000
51.0400 566.0000 1.0000
51.0800 524.0000 1.0000
51.1200 548.0000 1.0000
51.1600 535.0000 1.0000
51.2000 556.0000 1.0000
51.2400 552.0000 1.0000
51.2800 533.0000 1.0000
51.3200 538.0000 1.0000
51.3600 505.0000 1.0000
51.4000 563.0000 1.0000
51.4400 557.0000 1.0000
51.4800 553.0000 1.0000
51.5200 573.0000 1.0000
51.5600 536.0000 1.0000
51.6000 520.0000 1.0000
51.6400 556.0000 1.0000
51.6800 569.0000 1.0000
51.7200 592.0000 1.0000
51.7600 595.0000 1.0000
51.8000 606.0000 1.0000
51.8400 638.0000 1.0000
51.8800 692.0000 1.0000
51.9200 752.0000 1.0000
51.9600 867.0000 1.0000
52.0000 948.0000 1.0000
52.0400 1124.0000 1.0000
52.0800 1366.0000 1.0000
52.1200 1859.0000 1.0000
52.1600 2603.0000 1.0000
52.2000 3591.0000 1.0000
52.2400 4235.0000 1.0000
52.2800 4125.0000 1.0000
52.3200 3687.0000 1.0000
52.3600 3329.0000 1.0000
52.4000 2940.0000 1.0000
52.4400 2275.0000 1.0000
52.4800 1641.0000 1.0000
52.5200 1259.0000 1.0000
52.5600 995.0000 1.0000
52.6000 904.0000 1.0000
52.6400 772.0000 1.0000
52.6800 755.0000 1.0000
52.7200 676.0000 1.0000
52.7600 652.0000 1.0000
52.8000 628.0000 1.0000
52.8400 586.0000 1.0000
52.8800 610.0000 1.0000
52.9200 587.0000 1.0000
52.9600 544.0000 1.0000
53.0000 541.0000 1.0000
53.0400 581.0000 1.0000
53.0800 557.0000 1.0000
53.1200 568.0000 1.0000
53.1600 546.0000 1.0000
53.2000 513.0000 1.0000
53.2400 546.0000 1.0000
53.2800 561.0000 1.0000
53.3200 556.0000 1.0000
53.3600 542.0000 1.0000
53.4000 557.0000 1.0000
53.4400 542.0000 1.0000
53.4800 547.0000 1.0000
53.5200 501.0000 1.0000
53.5600 510.0000 1.0000
53.6000 514.0000 1.0000
53.6400 521.0000 1.0000
53.6800 517.0000 1.0000
53.7200 506.0000 1.0000
53.7600 463.0000 1.0000
53.8000 480.0000 1.0000
53.8400 500.0000 1.0000
53.8800 477.0000 1.0000
53.9200 482.0000 1.0000
53.9600 504.0000 1.0000
54.0000 507.0000 1.0000
54.0400 557.0000 1.0000
54.0800 498.0000 1.0000
54.1200 526.0000 1.0000
54.1600 500.0000 1.0000
54.2000 487.0000 1.0000
54.2400 525.0000 1.0000
54.2800 538.0000 1.0000
54.3200 536.0000 1.0000
54.3600 538.0000 1.0000
54.4000 518.0000 1.0000
54.4400 527.0000 1.0000
54.4800 505.0000 1.0000
54.5200 534.0000 1.0000
54.5600 520.0000 1.0000
54.6000 510.0000 1.0000
54.6400 509.0000 1.0000
54.6800 526.0000 1.0000
54.7200 526.0000 1.0000
54.7600 521.0000 1.0000
54.8000 505.0000 1.0000
54.8400 529.0000 1.0000
54.8800 506.0000 1.0000
54.9200 531.0000 1.0000
54.9600 531.0000 1.0000
55.0000 573.0000 1.0000
55.0400 592.0000 1.0000
55.0800 659.0000 1.0000
55.1200 618.0000 1.0000
55.1600 672.0000 1.0000
55.2000 775.0000 1.0000
55.2400 801.0000 1.0000
55.2800 808.0000 1.0000
55.3200 760.0000 1.0000
55.3600 741.0000 1.0000
55.4000 724.0000 1.0000
55.4400 699.0000 1.0000
55.4800 646.0000 1.0000
55.5200 617.0000 1.0000
55.5600 630.0000 1.0000
55.6000 619.0000 1.0000
55.6400 557.0000 1.0000
55.6800 560.0000 1.0000
55.7200 511.0000 1.0000
55.7600 535.0000 1.0000
55.8000 525.0000 1.0000
55.8400 516.0000 1.0000
55.8800 532.0000 1.0000
55.9200 514.0000 1.0000
55.9600 529.0000 1.0000
56.0000 494.0000 1.0000
56.0400 498.0000 1.0000
56.0800 532.0000 1.0000
56.1200 460.0000 1.0000
56.1600 497.0000 1.0000
56.2000 475.0000 1.0000
56.2400 524.0000 1.0000
56.2800 475.0000 1.0000
56.3200 482.0000 1.0000
56.3600 467.0000 1.0000
56.4000 477.0000 1.0000
56.4400 491.0000 1.0000
56.4800 448.0000 1.0000
56.5200 529.0000 1.0000
56.5600 493.0000 1.0000
56.6000 449.0000 1.0000
56.6400 489.0000 1.0000
56.6800 460.0000 1.0000
56.7200 468.0000 1.0000
56.7600 482.0000 1.0000
56.8000 468.0000 1.0000
56.8400 493.0000 1.0000
56.8800 477.0000 1.0000
56.9200 481.0000 1.0000
56.9600 528.0000 1.0000
57.0000 464.0000 1.0000
57.0400 489.0000 1.0000
57.0800 477.0000 1.0000
57.1200 516.0000 1.0000
57.1600 515.0000 1.0000
57.2000 452.0000 1.0000
57.2400 491.0000 1.0000
57.2800 486.0000 1.0000
57.3200 452.0000 1.0000
57.3600 442.0000 1.0000
57.4000 468.0000 1.0000
57.4400 491.0000 1.0000
57.4800 460.0000 1.0000
57.5200 467.0000 1.0000
57.5600 489.0000 1.0000
57.6000 470.0000 1.0000
57.6400 473.0000 1.0000
57.6800 477.0000 1.0000
57.7200 481.0000 1.0000
57.7600 479.0000 1.0000
57.8000 499.0000 1.0000
57.8400 480.0000 1.0000
57.8800 506.0000 1.0000
57.9200 509.0000 1.0000
57.9600 485.0000 1.0000
58.0000 451.0000 1.0000
58.0400 511.0000 1.0000
58.0800 459.0000 1.0000
58.1200 500.0000 1.0000
58.1600 474.0000 1.0000
58.2000 455.0000 1.0000
58.2400 489.0000 1.0000
58.2800 501.0000 1.0000
58.3200 460.0000 1.0000
58.3600 460.0000 1.0000
58.4000 511.0000 1.0000
58.4400 493.0000 1.0000
58.4800 509.0000 1.0000
58.5200 459.0000 1.0000
58.5600 488.0000 1.0000
58.6000 453.0000 1.0000
58.6400 469.0000 1.0000
58.6800 502.0000 1.0000
58.7200 469.0000 1.0000
58.7600 490.0000 1.0000
58.8000 464.0000 1.0000
58.8400 525.0000 1.0000
58.8800 472.0000 1.0000
58.9200 460.0000 1.0000
58.9600 465.0000 1.0000
59.0000 447.0000 1.0000
59.0400 472.0000 1.0000
59.0800 455.0000 1.0000
59.1200 462.0000 1.0000
59.1600 434.0000 1.0000
59.2000 471.0000 1.0000
59.2400 476.0000 1.0000
59.2800 520.0000 1.0000
59.3200 492.0000 1.0000
59.3600 470.0000 1.0000
59.4000 524.0000 1.0000
59.4400 488.0000 1.0000
59.4800 468.0000 1.0000
59.5200 459.0000 1.0000
59.5600 481.0000 1.0000
59.6000 456.0000 1.0000
59.6400 458.0000 1.0000
59.6800 474.0000 1.0000
59.7200 512.0000 1.0000
59.7600 449.0000 1.0000
59.8000 481.0000 1.0000
59.8400 457.0000 1.0000
59.8800 527.0000 1.0000
59.9200 452.0000 1.0000
59.9600 480.0000 1.0000
60.0000 428.0000 1.0000
60.0400 467.0000 1.0000
60.0800 480.0000 1.0000
60.1200 447.0000 1.0000
60.1600 478.0000 1.0000
60.2000 460.0000 1.0000
60.2400 472.0000 1.0000
60.2800 475.0000 1.0000
60.3200 464.0000 1.0000
60.3600 494.0000 1.0000
60.4000 450.0000 1.0000
60.4400 497.0000 1.0000
60.4800 454.0000 1.0000
60.5200 461.0000 1.0000
60.5600 500.0000 1.0000
60.6000 482.0000 1.0000
60.6400 506.0000 1.0000
60.6800 464.0000 1.0000
60.7200 441.0000 1.0000
60.7600 440.0000 1.0000
60.8000 499.0000 1.0000
60.8400 465.0000 1.0000
60.8800 464.0000 1.0000
60.9200 452.0000 1.0000
60.9600 488.0000 1.0000
61.0000 479.0000 1.0000
61.0400 481.0000 1.0000
61.0800 497.0000 1.0000
61.1200 479.0000 1.0000
61.1600 485.0000 1.0000
61.2000 489.0000 1.0000
61.2400 466.0000 1.0000
61.2800 496.0000 1.0000
61.3200 474.0000 1.0000
61.3600 455.0000 1.0000
61.4000 468.0000 1.0000
61.4400 478.0000 1.0000
61.4800 503.0000 1.0000
61.5200 474.0000 1.0000
61.5600 513.0000 1.0000
61.6000 488.0000 1.0000
61.6400 478.0000 1.0000
61.6800 477.0000 1.0000
61.7200 515.0000 1.0000
61.7600 512.0000 1.0000
61.8000 517.0000 1.0000
61.8400 497.0000 1.0000
61.8800 499.0000 1.0000
61.9200 588.0000 1.0000
61.9600 578.0000 1.0000
62.0000 628.0000 1.0000
62.0400 708.0000 1.0000
62.0800 747.0000 1.0000
62.1200 816.0000 1.0000
62.1600 916.0000 1.0000
62.2000 1002.0000 1.0000
62.2400 1091.0000 1.0000
62.2800 1086.0000 1.0000
62.3200 1067.0000 1.0000
62.3600 1001.0000 1.0000
62.4000 987.0000 1.0000
62.4400 968.0000 1.0000
62.4800 913.0000 1.0000
62.5200 799.0000 1.0000
62.5600 733.0000 1.0000
62.6000 721.0000 1.0000
62.6400 627.0000 1.0000
62.6800 633.0000 1.0000
62.7200 547.0000 1.0000
62.7600 550.0000 1.0000
62.8000 529.0000 1.0000
62.8400 500.0000 1.0000
62.8800 517.0000 1.0000
62.9200 525.0000 1.0000
62.9600 505.0000 1.0000
63.0000 499.0000 1.0000
63.0400 510.0000 1.0000
63.0800 495.0000 1.0000
63.1200 512.0000 1.0000
63.1600 467.0000 1.0000
63.2000 477.0000 1.0000
63.2400 494.0000 1.0000
63.2800 499.0000 1.0000
63.3200 454.0000 1.0000
63.3600 463.0000 1.0000
63.4000 448.0000 1.0000
63.4400 498.0000 1.0000
63.4800 469.0000 1.0000
63.5200 457.0000 1.0000
63.5600 431.0000 1.0000
63.6000 485.0000 1.0000
63.6400 461.0000 1.0000
63.6800 478.0000 1.0000
63.7200 455.0000 1.0000
63.7600 434.0000 1.0000
63.8000 476.0000 1.0000
63.8400 459.0000 1.0000
63.8800 461.0000 1.0000
63.9200 477.0000 1.0000
63.9600 489.0000 1.0000
64.0000 492.0000 1.0000
64.0400 432.0000 1.0000
64.0800 487.0000 1.0000
64.1200 455.0000 1.0000
64.1600 473.0000 1.0000
64.2000 468.0000 1.0000
64.2400 458.0000 1.0000
64.2800 441.0000 1.0000
64.3200 484.0000 1.0000
64.3600 471.0000 1.0000
64.4000 458.0000 1.0000
64.4400 472.0000 1.0000
64.4800 433.0000 1.0000
64.5200 494.0000 1.0000
64.5600 509.0000 1.0000
64.6000 451.0000 1.0000
64.6400 477.0000 1.0000
64.6800 488.0000 1.0000
64.7200 502.0000 1.0000
64.7600 490.0000 1.0000
64.8000 537.0000 1.0000
64.8400 488.0000 1.0000
64.8800 514.0000 1.0000
64.9200 493.0000 1.0000
64.9600 498.0000 1.0000
65.0000 490.0000 1.0000
65.0400 484.0000 1.0000
65.0800 516.0000 1.0000
65.1200 498.0000 1.0000
65.1600 446.0000 1.0000
65.2000 491.0000 1.0000
65.2400 527.0000 1.0000
65.2800 480.0000 1.0000
65.3200 485.0000 1.0000
65.3600 494.0000 1.0000
65.4000 478.0000 1.0000
65.4400 459.0000 1.0000
65.4800 519.0000 1.0000
65.5200 466.0000 1.0000
65.5600 497.0000 1.0000
65.6000 472.0000 1.0000
65.6400 492.0000 1.0000
65.6800 497.0000 1.0000
65.7200 490.0000 1.0000
65.7600 510.0000 1.0000
65.8000 536.0000 1.0000
65.8400 544.0000 1.0000
65.8800 552.0000 1.0000
65.9200 595.0000 1.0000
65.9600 674.0000 1.0000
66.0000 753.0000 1.0000
66.0400 858.0000 1.0000
66.0800 1039.0000 1.0000
66.1200 1324.0000 1.0000
66.1600 1637.0000 1.0000
66.2000 1983.0000 1.0000
66.2400 1929.0000 1.0000
66.2800 1876.0000 1.0000
66.3200 1731.0000 1.0000
66.3600 1598.0000 1.0000
66.4000 1565.0000 1.0000
66.4400 1414.0000 1.0000
66.4800 1115.0000 1.0000
66.5200 999.0000 1.0000
66.5600 906.0000 1.0000
66.6000 709.0000 1.0000
66.6400 692.0000 1.0000
66.6800 616.0000 1.0000
66.7200 586.0000 1.0000
66.7600 542.0000 1.0000
66.8000 485.0000 1.0000
66.8400 512.0000 1.0000
66.8800 499.0000 1.0000
66.9200 487.0000 1.0000
66.9600 443.0000 1.0000
67.0000 408.0000 1.0000
67.0400 489.0000 1.0000
67.0800 436.0000 1.0000
67.1200 457.0000 1.0000
67.1600 452.0000 1.0000
67.2000 492.0000 1.0000
67.2400 445.0000 1.0000
67.2800 435.0000 1.0000
67.3200 471.0000 1.0000
67.3600 420.0000 1.0000
67.4000 460.0000 1.0000
67.4400 454.0000 1.0000
67.4800 451.0000 1.0000
67.5200 437.0000 1.0000
67.5600 390.0000 1.0000
67.6000 441.0000 1.0000
67.6400 418.0000 1.0000
67.6800 447.0000 1.0000
67.7200 410.0000 1.0000
67.7600 440.0000 1.0000
67.8000 394.0000 1.0000
67.8400 429.0000 1.0000
67.8800 423.0000 1.0000
67.9200 421.0000 1.0000
67.9600 438.0000 1.0000
68.0000 402.0000 1.0000
68.0400 434.0000 1.0000
68.0800 432.0000 1.0000
68.1200 439.0000 1.0000
68.1600 402.0000 1.0000
68.2000 415.0000 1.0000
68.2400 403.0000 1.0000
68.2800 397.0000 1.0000
68.3200 424.0000 1.0000
68.3600 428.0000 1.0000
68.4000 427.0000 1.0000
68.4400 433.0000 1.0000
68.4800 435.0000 1.0000
68.5200 416.0000 1.0000
68.5600 426.0000 1.0000
68.6000 426.0000 1.0000
68.6400 392.0000 1.0000
68.6800 448.0000 1.0000
68.7200 422.0000 1.0000
68.7600 390.0000 1.0000
68.8000 415.0000 1.0000
68.8400 420.0000 1.0000
68.8800 393.0000 1.0000
68.9200 385.0000 1.0000
68.9600 419.0000 1.0000
69.0000 398.0000 1.0000
69.0400 408.0000 1.0000
69.0800 394.0000 1.0000
69.1200 380.0000 1.0000
69.1600 421.0000 1.0000
69.2000 401.0000 1.0000
69.2400 402.0000 1.0000
69.2800 401.0000 1.0000
69.3200 387.0000 1.0000
69.3600 397.0000 1.0000
69.4000 379.0000 1.0000
69.4400 404.0000 1.0000
69.4800 412.0000 1.0000
69.5200 419.0000 1.0000
69.5600 416.0000 1.0000
69.6000 372.0000 1.0000
69.6400 399.0000 1.0000
69.6800 390.0000 1.0000
69.7200 386.0000 1.0000
69.7600 384.0000 1.0000
69.8000 398.0000 1.0000
69.8400 384.0000 1.0000
69.8800 421.0000 1.0000
69.9200 387.0000 1.0000
69.9600 402.0000 1.0000
70.0000 376.0000 1.0000
*RAS_INT_END
*RAS_TEMPERATURE_START
*RAS_TEMPERATURE_END
*RAS_DATA_END