File: Section2_75_samples/XRD/No_057_NSS3_2.ras
*RAS_DATA_START
*RAS_HEADER_START
*DISP_FMT_X "%.2f"
*DISP_FMT_Y "%.0f"
*DISP_FULLSCALE "15742.0000000000"
*DISP_LINE_COLOR "255.0000000000"
*DISP_LINE_STYLE "0.0000000000"
*DISP_LINE_WIDTH "0.2500000000"
*DISP_NOTE "測定データ-13"
*DISP_OFFSET_Y "0.0000000000"
*DISP_PEAKSEARCH_UNIT_Y "cps"
*DISP_RANGE_BOTTOM "0.0000000000"
*DISP_RANGE_LEFT "20.0000000000"
*DISP_RANGE_LOGCUTOFF "0.0100000000"
*DISP_RANGE_RIGHT "70.0000000000"
*DISP_RANGE_TOP "15742.0000000000"
*DISP_SCALE_MODE_Y "0.0000000000"
*DISP_TAB_NAME "2θ/θ"
*DISP_TITLE_Y "強度"
*DISP_UNIT_Y "cps"
*DISP_WINDOW_NAME "MSG_MACROENGINE"
*FILE_COMMENT " "
*FILE_MD5 ""
*FILE_MEMO " "
*FILE_OPERATOR "Administrator"
*FILE_SAMPLE " "
*FILE_TYPE "RAS_RAW"
*FILE_USERGROUP "システムマネージャ"
*FILE_VERSION "1.0000000000"
*HW_ATTACHMENT_ID "ATT0025"
*HW_ATTACHMENT_NAME "標準|Standard"
*HW_COUNTER_ID-0 "CUT0025"
*HW_COUNTER_ID-1 "CUT0020"
*HW_COUNTER_ID-2 "CUT0020"
*HW_COUNTER_ID-3 "CSL0021"
*HW_COUNTER_ID-4 "CMC0021"
*HW_COUNTER_NAME-0 "D/teX Ultra|D/teX Ultra"
*HW_COUNTER_NAME-1 "None|None"
*HW_COUNTER_NAME-2 "None|None"
*HW_COUNTER_NAME-3 "BBM|BBM"
*HW_COUNTER_NAME-4 "検出器モノクロメータ|Detector monochromator"
*HW_COUNTER_SELECT_NAME "D/teX Ultra|D/teX Ultra"
*HW_GONIOMETER_ID "GON0023"
*HW_GONIOMETER_NAME "SmartLab|SmartLab"
*HW_GONIOMETER_RADIUS-0 "90.0"
*HW_GONIOMETER_RADIUS-1 "114.0"
*HW_GONIOMETER_RADIUS-2 "190.0"
*HW_GONIOMETER_RADIUS-3 "300.0"
*HW_GONIOMETER_RADIUS-4 "187.0"
*HW_GONIOMETER_RADIUS-5 "300.0"
*HW_GONIOMETER_RADIUS-6 "113.0"
*HW_GONIOMETER_RADIUS-7 "331.0"
*HW_I_OPT_ID-0 "CBO0021"
*HW_I_OPT_ID-1 "ICR0023"
*HW_I_OPT_ID-2 "ISL0021"
*HW_I_OPT_ID-3 "ISO0021"
*HW_I_OPT_ID-4 "IAD0021"
*HW_I_OPT_ID-5 "IPR0001"
*HW_I_OPT_NAME-0 "CBOユニット|CBO unit"
*HW_I_OPT_NAME-1 "標準入射光学ユニット|Standard incident optical unit"
*HW_I_OPT_NAME-2 "標準入射スリットボックス|Standard incident slit box"
*HW_I_OPT_NAME-3 "入射平行スリット|Incident parallel slit"
*HW_I_OPT_NAME-4 "長手制限スリット|Length limiting slit"
*HW_I_OPT_NAME-5 "None|None"
*HW_R_ATTENUATER_AUTOMODE "0"
*HW_R_OPT_ID-0 "RSS0021"
*HW_R_OPT_ID-1 "RCR0023"
*HW_R_OPT_ID-2 "RSO0021"
*HW_R_OPT_ID-3 "RRS0021"
*HW_R_OPT_ID-4 "ATN0021"
*HW_R_OPT_ID-5 "RFL0021"
*HW_R_OPT_ID-6 "RAD0021"
*HW_R_OPT_NAME-0 "標準受光スリットボックス1|Standard receiving slit box # 1"
*HW_R_OPT_NAME-1 "標準受光光学ユニット1|Standard receiving unit # 1"
*HW_R_OPT_NAME-2 "標準受光光学ユニット2|Standard receiving optical unit # 2"
*HW_R_OPT_NAME-3 "標準受光スリットボックス2|Standard receiving slit box # 2"
*HW_R_OPT_NAME-4 "標準アッテネータ|Standard Attenuator"
*HW_R_OPT_NAME-5 "Cu Kβ|Cu K-beta"
*HW_R_OPT_NAME-6 "調整用受光スリット|Alignment receiving slit"
*HW_SAMPLE_HOLDER_ID "SMP0023"
*HW_SAMPLE_HOLDER_NAME "標準Zステージ|Standard Z stage"
*HW_XG_CURRENT_MAX "50"
*HW_XG_CURRENT_MIN "2"
*HW_XG_CURRENT_RESOLUTION "1"
*HW_XG_CURRENT_UNIT "mA"
*HW_XG_FOCUS "1mm x 10mm"
*HW_XG_FOCUS_TYPE "Normal"
*HW_XG_ID ""
*HW_XG_NAME "3kW 封入管(ID:1200)|3kW Sealed tube(ID:1200)"
*HW_XG_TARGET_ATOMIC_NUMBER "29.0000000000"
*HW_XG_TARGET_NAME "Cu"
*HW_XG_TYPE "Hermetic"
*HW_XG_VOLTAGE_MAX "60"
*HW_XG_VOLTAGE_MIN "20"
*HW_XG_VOLTAGE_RESOLUTION "1"
*HW_XG_VOLTAGE_UNIT "kV"
*HW_XG_WATT_MAX "1.500"
*HW_XG_WATT_UNIT "kW"
*HW_XG_WAVE_LENGTH_ALPHA1 "1.540593"
*HW_XG_WAVE_LENGTH_ALPHA2 "1.544414"
*HW_XG_WAVE_LENGTH_BETA "1.392250"
*MEAS_COND_AXIS_NAME-0 "2θ/θ"
*MEAS_COND_AXIS_NAME-1 "2θ"
*MEAS_COND_AXIS_NAME-2 "ω"
*MEAS_COND_AXIS_NAME-3 "Z"
*MEAS_COND_AXIS_NAME-4 "2θ/ω"
*MEAS_COND_AXIS_NAME-5 "θs"
*MEAS_COND_AXIS_NAME-6 "θd"
*MEAS_COND_AXIS_NAME-7 "Ts"
*MEAS_COND_AXIS_NAME-8 "CBO選択スリット"
*MEAS_COND_AXIS_NAME-9 "M"
*MEAS_COND_AXIS_NAME-10 "入射平行スリット"
*MEAS_COND_AXIS_NAME-11 "入射スリット"
*MEAS_COND_AXIS_NAME-12 ""
*MEAS_COND_AXIS_NAME-13 "Zs"
*MEAS_COND_AXIS_NAME-14 "入射光学素子"
*MEAS_COND_AXIS_NAME-15 "長手制限スリット"
*MEAS_COND_AXIS_NAME-16 "センタースリット"
*MEAS_COND_AXIS_NAME-17 "フィルター"
*MEAS_COND_AXIS_NAME-18 "受光スリット1"
*MEAS_COND_AXIS_NAME-19 "受光スリット2"
*MEAS_COND_AXIS_NAME-20 "受光光学素子"
*MEAS_COND_AXIS_NAME-21 "受光平行スリット"
*MEAS_COND_AXIS_NAME-22 "調整用受光スリット"
*MEAS_COND_AXIS_NAME-23 ""
*MEAS_COND_AXIS_NAME-24 ""
*MEAS_COND_AXIS_NAME-25 "Zd"
*MEAS_COND_AXIS_NAME-26 "アッテネータ"
*MEAS_COND_AXIS_NAME-27 "検出器モノクロメータ"
*MEAS_COND_AXIS_NAME-28 "モノクロメータスリット"
*MEAS_COND_AXIS_NAME-29 "プライマリビーム"
*MEAS_COND_AXIS_NAME-30 "PHA"
*MEAS_COND_AXIS_NAME_INTERNAL-0 "TwoThetaTheta"
*MEAS_COND_AXIS_NAME_INTERNAL-1 "TwoTheta"
*MEAS_COND_AXIS_NAME_INTERNAL-2 "Omega"
*MEAS_COND_AXIS_NAME_INTERNAL-3 "Z"
*MEAS_COND_AXIS_NAME_INTERNAL-4 "TwoThetaOmega"
*MEAS_COND_AXIS_NAME_INTERNAL-5 "ThetaS"
*MEAS_COND_AXIS_NAME_INTERNAL-6 "ThetaD"
*MEAS_COND_AXIS_NAME_INTERNAL-7 "Ts"
*MEAS_COND_AXIS_NAME_INTERNAL-8 "CBO"
*MEAS_COND_AXIS_NAME_INTERNAL-9 "CBO-M"
*MEAS_COND_AXIS_NAME_INTERNAL-10 "IncidentSollerSlit"
*MEAS_COND_AXIS_NAME_INTERNAL-11 "IncidentSlitBox"
*MEAS_COND_AXIS_NAME_INTERNAL-12 "IncidentSlitBox-_Axis"
*MEAS_COND_AXIS_NAME_INTERNAL-13 "Zs"
*MEAS_COND_AXIS_NAME_INTERNAL-14 "IncidentMonochromator"
*MEAS_COND_AXIS_NAME_INTERNAL-15 "IncidentAxdSlit"
*MEAS_COND_AXIS_NAME_INTERNAL-16 "CenterSlit"
*MEAS_COND_AXIS_NAME_INTERNAL-17 "Filter"
*MEAS_COND_AXIS_NAME_INTERNAL-18 "ReceivingSlitBox1"
*MEAS_COND_AXIS_NAME_INTERNAL-19 "ReceivingSlitBox2"
*MEAS_COND_AXIS_NAME_INTERNAL-20 "ReceivingOptics"
*MEAS_COND_AXIS_NAME_INTERNAL-21 "ReceivingSollerSlit"
*MEAS_COND_AXIS_NAME_INTERNAL-22 "ReceivingAxdSlit"
*MEAS_COND_AXIS_NAME_INTERNAL-23 "ReceivingSlitBox1-_Axis"
*MEAS_COND_AXIS_NAME_INTERNAL-24 "ReceivingSlitBox2-_Axis"
*MEAS_COND_AXIS_NAME_INTERNAL-25 "ReceivingSlitBox2-Zd"
*MEAS_COND_AXIS_NAME_INTERNAL-26 "Attenuator"
*MEAS_COND_AXIS_NAME_INTERNAL-27 "CounterMonochromator"
*MEAS_COND_AXIS_NAME_INTERNAL-28 "CounterSlit"
*MEAS_COND_AXIS_NAME_INTERNAL-29 "IncidentPrimary"
*MEAS_COND_AXIS_NAME_INTERNAL-30 "PHA"
*MEAS_COND_AXIS_NAME_MAGICNO-0 "83951616.0000000000"
*MEAS_COND_AXIS_NAME_MAGICNO-1 "268632064.0000000000"
*MEAS_COND_AXIS_NAME_MAGICNO-2 "268500992.0000000000"
*MEAS_COND_AXIS_NAME_MAGICNO-3 "285278208.0000000000"
*MEAS_COND_AXIS_NAME_MAGICNO-4 "83951616.0000000000"
*MEAS_COND_AXIS_NAME_MAGICNO-5 "131072.0000000000"
*MEAS_COND_AXIS_NAME_MAGICNO-6 "131072.0000000000"
*MEAS_COND_AXIS_NAME_MAGICNO-7 "318898176.0000000000"
*MEAS_COND_AXIS_NAME_MAGICNO-8 "20971521.0000000000"
*MEAS_COND_AXIS_NAME_MAGICNO-9 "285343744.0000000000"
*MEAS_COND_AXIS_NAME_MAGICNO-10 "20971521.0000000000"
*MEAS_COND_AXIS_NAME_MAGICNO-11 "22020097.0000000000"
*MEAS_COND_AXIS_NAME_MAGICNO-12 "25165824.0000000000"
*MEAS_COND_AXIS_NAME_MAGICNO-13 "318898176.0000000000"
*MEAS_COND_AXIS_NAME_MAGICNO-14 "1.0000000000"
*MEAS_COND_AXIS_NAME_MAGICNO-15 "20971521.0000000000"
*MEAS_COND_AXIS_NAME_MAGICNO-16 "20971521.0000000000"
*MEAS_COND_AXIS_NAME_MAGICNO-17 "20971521.0000000000"
*MEAS_COND_AXIS_NAME_MAGICNO-18 "23068673.0000000000"
*MEAS_COND_AXIS_NAME_MAGICNO-19 "23068673.0000000000"
*MEAS_COND_AXIS_NAME_MAGICNO-20 "20971521.0000000000"
*MEAS_COND_AXIS_NAME_MAGICNO-21 "20971521.0000000000"
*MEAS_COND_AXIS_NAME_MAGICNO-22 "20971521.0000000000"
*MEAS_COND_AXIS_NAME_MAGICNO-23 "25165824.0000000000"
*MEAS_COND_AXIS_NAME_MAGICNO-24 "25165824.0000000000"
*MEAS_COND_AXIS_NAME_MAGICNO-25 "285343744.0000000000"
*MEAS_COND_AXIS_NAME_MAGICNO-26 "17301505.0000000000"
*MEAS_COND_AXIS_NAME_MAGICNO-27 "20971521.0000000000"
*MEAS_COND_AXIS_NAME_MAGICNO-28 "20971521.0000000000"
*MEAS_COND_AXIS_NAME_MAGICNO-29 "20971521.0000000000"
*MEAS_COND_AXIS_NAME_MAGICNO-30 "0.0000000000"
*MEAS_COND_AXIS_OFFSET-0 "-"
*MEAS_COND_AXIS_OFFSET-1 "-0.1081000000"
*MEAS_COND_AXIS_OFFSET-2 "0.3758000000"
*MEAS_COND_AXIS_OFFSET-3 "-"
*MEAS_COND_AXIS_OFFSET-4 "-"
*MEAS_COND_AXIS_OFFSET-5 "0.3758000000"
*MEAS_COND_AXIS_OFFSET-6 "-0.4839000000"
*MEAS_COND_AXIS_OFFSET-7 "-"
*MEAS_COND_AXIS_OFFSET-8 "-"
*MEAS_COND_AXIS_OFFSET-9 "-"
*MEAS_COND_AXIS_OFFSET-10 "-"
*MEAS_COND_AXIS_OFFSET-11 "-"
*MEAS_COND_AXIS_OFFSET-12 "-"
*MEAS_COND_AXIS_OFFSET-13 "-"
*MEAS_COND_AXIS_OFFSET-14 "-"
*MEAS_COND_AXIS_OFFSET-15 "-"
*MEAS_COND_AXIS_OFFSET-16 "-"
*MEAS_COND_AXIS_OFFSET-17 "-"
*MEAS_COND_AXIS_OFFSET-18 "-"
*MEAS_COND_AXIS_OFFSET-19 "-"
*MEAS_COND_AXIS_OFFSET-20 "-"
*MEAS_COND_AXIS_OFFSET-21 "-"
*MEAS_COND_AXIS_OFFSET-22 "-"
*MEAS_COND_AXIS_OFFSET-23 "-"
*MEAS_COND_AXIS_OFFSET-24 "-"
*MEAS_COND_AXIS_OFFSET-25 "-"
*MEAS_COND_AXIS_OFFSET-26 "-"
*MEAS_COND_AXIS_OFFSET-27 "-"
*MEAS_COND_AXIS_OFFSET-28 "-"
*MEAS_COND_AXIS_OFFSET-29 "-"
*MEAS_COND_AXIS_OFFSET-30 "-"
*MEAS_COND_AXIS_POSITION-0 "0.0000000000"
*MEAS_COND_AXIS_POSITION-1 "0.0000000000"
*MEAS_COND_AXIS_POSITION-2 "0.0000000000"
*MEAS_COND_AXIS_POSITION-3 "-0.5500000000"
*MEAS_COND_AXIS_POSITION-4 "0.0000000000"
*MEAS_COND_AXIS_POSITION-5 "0.0000000000"
*MEAS_COND_AXIS_POSITION-6 "0.0000000000"
*MEAS_COND_AXIS_POSITION-7 "-0.4278800000"
*MEAS_COND_AXIS_POSITION-8 "BB"
*MEAS_COND_AXIS_POSITION-9 "0.0000000000"
*MEAS_COND_AXIS_POSITION-10 "Soller_slit_5.0deg"
*MEAS_COND_AXIS_POSITION-11 "2/3deg"
*MEAS_COND_AXIS_POSITION-12 "2.2088000000"
*MEAS_COND_AXIS_POSITION-13 "-0.4140600000"
*MEAS_COND_AXIS_POSITION-14 "0.0000000000"
*MEAS_COND_AXIS_POSITION-15 "10.0mm"
*MEAS_COND_AXIS_POSITION-16 "None"
*MEAS_COND_AXIS_POSITION-17 "Cu_K-beta"
*MEAS_COND_AXIS_POSITION-18 "13.000mm"
*MEAS_COND_AXIS_POSITION-19 "13.000mm"
*MEAS_COND_AXIS_POSITION-20 "No_unit"
*MEAS_COND_AXIS_POSITION-21 "Soller_slit_5.0deg"
*MEAS_COND_AXIS_POSITION-22 "None"
*MEAS_COND_AXIS_POSITION-23 "13.0000000000"
*MEAS_COND_AXIS_POSITION-24 "13.0000000000"
*MEAS_COND_AXIS_POSITION-25 "0.0109400000"
*MEAS_COND_AXIS_POSITION-26 "Open"
*MEAS_COND_AXIS_POSITION-27 "None"
*MEAS_COND_AXIS_POSITION-28 "None"
*MEAS_COND_AXIS_POSITION-29 "None"
*MEAS_COND_AXIS_POSITION-30 "38.0000000000"
*MEAS_COND_AXIS_UNIT-0 "deg"
*MEAS_COND_AXIS_UNIT-1 "deg"
*MEAS_COND_AXIS_UNIT-2 "deg"
*MEAS_COND_AXIS_UNIT-3 "mm"
*MEAS_COND_AXIS_UNIT-4 "deg"
*MEAS_COND_AXIS_UNIT-5 "deg"
*MEAS_COND_AXIS_UNIT-6 "deg"
*MEAS_COND_AXIS_UNIT-7 "mm"
*MEAS_COND_AXIS_UNIT-8 ""
*MEAS_COND_AXIS_UNIT-9 "pulse"
*MEAS_COND_AXIS_UNIT-10 ""
*MEAS_COND_AXIS_UNIT-11 ""
*MEAS_COND_AXIS_UNIT-12 "mm"
*MEAS_COND_AXIS_UNIT-13 "mm"
*MEAS_COND_AXIS_UNIT-14 ""
*MEAS_COND_AXIS_UNIT-15 ""
*MEAS_COND_AXIS_UNIT-16 ""
*MEAS_COND_AXIS_UNIT-17 ""
*MEAS_COND_AXIS_UNIT-18 ""
*MEAS_COND_AXIS_UNIT-19 ""
*MEAS_COND_AXIS_UNIT-20 ""
*MEAS_COND_AXIS_UNIT-21 ""
*MEAS_COND_AXIS_UNIT-22 ""
*MEAS_COND_AXIS_UNIT-23 "mm"
*MEAS_COND_AXIS_UNIT-24 "mm"
*MEAS_COND_AXIS_UNIT-25 "mm"
*MEAS_COND_AXIS_UNIT-26 ""
*MEAS_COND_AXIS_UNIT-27 ""
*MEAS_COND_AXIS_UNIT-28 ""
*MEAS_COND_AXIS_UNIT-29 ""
*MEAS_COND_AXIS_UNIT-30 "div"
*MEAS_COND_COUNTER_CNTLOSS_CORR "0.0000000000"
*MEAS_COND_COUNTER_PHABASE "38.0000000000"
*MEAS_COND_COUNTER_PHAWINDOW "16.0000000000"
*MEAS_COND_COUNTER_PHA_UNIT "div"
*MEAS_COND_COUNTER_TAUDIFF "30.0000000000"
*MEAS_COND_COUNTER_TAUINT "0.0000000000"
*MEAS_COND_IRRADIATION_MODE "OFF"
*MEAS_COND_IRRADIATION_WIDTH ""
*MEAS_COND_OPT_ATTR "集中法"
*MEAS_COND_OPT_NAME "@集中法"
*MEAS_COND_UNSYMMETRIC_MODE "OFF"
*MEAS_COND_XG_CURRENT "30.0000000000"
*MEAS_COND_XG_VOLTAGE "40.0000000000"
*MEAS_COND_XG_WAVE_TYPE "Ka"
*MEAS_DATA_COUNT "5001.0000000000"
*MEAS_SCAN_AXIS_X "2θ/θ"
*MEAS_SCAN_AXIS_X_INTERNAL "TwoThetaTheta"
*MEAS_SCAN_END_TIME "07/12/21 19:56:46"
*MEAS_SCAN_MODE "CONTINUOUS"
*MEAS_SCAN_MONITOR "0"
*MEAS_SCAN_RESOLUTION_X "0.0002"
*MEAS_SCAN_SPEED "1.0"
*MEAS_SCAN_SPEED_UNIT "deg/min"
*MEAS_SCAN_START "20.0000000000"
*MEAS_SCAN_START_TIME "07/12/21 19:03:53"
*MEAS_SCAN_STEP "0.0100000000"
*MEAS_SCAN_STOP "70.0000000000"
*MEAS_SCAN_UNIT_X "deg"
*MEAS_SCAN_UNIT_Y "counts"
*RAS_HEADER_END
*RAS_INT_START
20.0000 1704.0000 1.0000
20.0400 1678.0000 1.0000
20.0800 1788.0000 1.0000
20.1200 1741.0000 1.0000
20.1600 1772.0000 1.0000
20.2000 1694.0000 1.0000
20.2400 1706.0000 1.0000
20.2800 1752.0000 1.0000
20.3200 1701.0000 1.0000
20.3600 1723.0000 1.0000
20.4000 1772.0000 1.0000
20.4400 1806.0000 1.0000
20.4800 1750.0000 1.0000
20.5200 1670.0000 1.0000
20.5600 1750.0000 1.0000
20.6000 1714.0000 1.0000
20.6400 1730.0000 1.0000
20.6800 1724.0000 1.0000
20.7200 1758.0000 1.0000
20.7600 1787.0000 1.0000
20.8000 1771.0000 1.0000
20.8400 1808.0000 1.0000
20.8800 1737.0000 1.0000
20.9200 1757.0000 1.0000
20.9600 1768.0000 1.0000
21.0000 1761.0000 1.0000
21.0400 1741.0000 1.0000
21.0800 1741.0000 1.0000
21.1200 1702.0000 1.0000
21.1600 1678.0000 1.0000
21.2000 1803.0000 1.0000
21.2400 1810.0000 1.0000
21.2800 1730.0000 1.0000
21.3200 1720.0000 1.0000
21.3600 1711.0000 1.0000
21.4000 1772.0000 1.0000
21.4400 1697.0000 1.0000
21.4800 1735.0000 1.0000
21.5200 1811.0000 1.0000
21.5600 1762.0000 1.0000
21.6000 1782.0000 1.0000
21.6400 1731.0000 1.0000
21.6800 1802.0000 1.0000
21.7200 1668.0000 1.0000
21.7600 1691.0000 1.0000
21.8000 1770.0000 1.0000
21.8400 1772.0000 1.0000
21.8800 1736.0000 1.0000
21.9200 1737.0000 1.0000
21.9600 1721.0000 1.0000
22.0000 1745.0000 1.0000
22.0400 1750.0000 1.0000
22.0800 1775.0000 1.0000
22.1200 1748.0000 1.0000
22.1600 1724.0000 1.0000
22.2000 1734.0000 1.0000
22.2400 1818.0000 1.0000
22.2800 1803.0000 1.0000
22.3200 1750.0000 1.0000
22.3600 1804.0000 1.0000
22.4000 1738.0000 1.0000
22.4400 1815.0000 1.0000
22.4800 1785.0000 1.0000
22.5200 1753.0000 1.0000
22.5600 1803.0000 1.0000
22.6000 1804.0000 1.0000
22.6400 1752.0000 1.0000
22.6800 1824.0000 1.0000
22.7200 1787.0000 1.0000
22.7600 1781.0000 1.0000
22.8000 1798.0000 1.0000
22.8400 1759.0000 1.0000
22.8800 1757.0000 1.0000
22.9200 1735.0000 1.0000
22.9600 1763.0000 1.0000
23.0000 1752.0000 1.0000
23.0400 1793.0000 1.0000
23.0800 1845.0000 1.0000
23.1200 1715.0000 1.0000
23.1600 1701.0000 1.0000
23.2000 1779.0000 1.0000
23.2400 1828.0000 1.0000
23.2800 1773.0000 1.0000
23.3200 1821.0000 1.0000
23.3600 1788.0000 1.0000
23.4000 1774.0000 1.0000
23.4400 1809.0000 1.0000
23.4800 1789.0000 1.0000
23.5200 1774.0000 1.0000
23.5600 1847.0000 1.0000
23.6000 1786.0000 1.0000
23.6400 1856.0000 1.0000
23.6800 1767.0000 1.0000
23.7200 1856.0000 1.0000
23.7600 1792.0000 1.0000
23.8000 1772.0000 1.0000
23.8400 1754.0000 1.0000
23.8800 1841.0000 1.0000
23.9200 1767.0000 1.0000
23.9600 1807.0000 1.0000
24.0000 1731.0000 1.0000
24.0400 1817.0000 1.0000
24.0800 1806.0000 1.0000
24.1200 1841.0000 1.0000
24.1600 1804.0000 1.0000
24.2000 1822.0000 1.0000
24.2400 1754.0000 1.0000
24.2800 1818.0000 1.0000
24.3200 1843.0000 1.0000
24.3600 1782.0000 1.0000
24.4000 1869.0000 1.0000
24.4400 1816.0000 1.0000
24.4800 1809.0000 1.0000
24.5200 1882.0000 1.0000
24.5600 1895.0000 1.0000
24.6000 1871.0000 1.0000
24.6400 1913.0000 1.0000
24.6800 1888.0000 1.0000
24.7200 1855.0000 1.0000
24.7600 1871.0000 1.0000
24.8000 1787.0000 1.0000
24.8400 1877.0000 1.0000
24.8800 1837.0000 1.0000
24.9200 1873.0000 1.0000
24.9600 1861.0000 1.0000
25.0000 1855.0000 1.0000
25.0400 1891.0000 1.0000
25.0800 1889.0000 1.0000
25.1200 1831.0000 1.0000
25.1600 1877.0000 1.0000
25.2000 1929.0000 1.0000
25.2400 1912.0000 1.0000
25.2800 1918.0000 1.0000
25.3200 1810.0000 1.0000
25.3600 1863.0000 1.0000
25.4000 1955.0000 1.0000
25.4400 1859.0000 1.0000
25.4800 1825.0000 1.0000
25.5200 1911.0000 1.0000
25.5600 1895.0000 1.0000
25.6000 1837.0000 1.0000
25.6400 1820.0000 1.0000
25.6800 1809.0000 1.0000
25.7200 1984.0000 1.0000
25.7600 1817.0000 1.0000
25.8000 1903.0000 1.0000
25.8400 1837.0000 1.0000
25.8800 1832.0000 1.0000
25.9200 1976.0000 1.0000
25.9600 1856.0000 1.0000
26.0000 1857.0000 1.0000
26.0400 1886.0000 1.0000
26.0800 1871.0000 1.0000
26.1200 1904.0000 1.0000
26.1600 1896.0000 1.0000
26.2000 1901.0000 1.0000
26.2400 1908.0000 1.0000
26.2800 1806.0000 1.0000
26.3200 1930.0000 1.0000
26.3600 1855.0000 1.0000
26.4000 1912.0000 1.0000
26.4400 1963.0000 1.0000
26.4800 1966.0000 1.0000
26.5200 1963.0000 1.0000
26.5600 2060.0000 1.0000
26.6000 2056.0000 1.0000
26.6400 2026.0000 1.0000
26.6800 1974.0000 1.0000
26.7200 2030.0000 1.0000
26.7600 2056.0000 1.0000
26.8000 2118.0000 1.0000
26.8400 2191.0000 1.0000
26.8800 2196.0000 1.0000
26.9200 2394.0000 1.0000
26.9600 2413.0000 1.0000
27.0000 2545.0000 1.0000
27.0400 2849.0000 1.0000
27.0800 3273.0000 1.0000
27.1200 3576.0000 1.0000
27.1600 4498.0000 1.0000
27.2000 5520.0000 1.0000
27.2400 6619.0000 1.0000
27.2800 7213.0000 1.0000
27.3200 6639.0000 1.0000
27.3600 5649.0000 1.0000
27.4000 4528.0000 1.0000
27.4400 3705.0000 1.0000
27.4800 3267.0000 1.0000
27.5200 2840.0000 1.0000
27.5600 2573.0000 1.0000
27.6000 2429.0000 1.0000
27.6400 2278.0000 1.0000
27.6800 2196.0000 1.0000
27.7200 2176.0000 1.0000
27.7600 2079.0000 1.0000
27.8000 1966.0000 1.0000
27.8400 1995.0000 1.0000
27.8800 1918.0000 1.0000
27.9200 1943.0000 1.0000
27.9600 1857.0000 1.0000
28.0000 1874.0000 1.0000
28.0400 1845.0000 1.0000
28.0800 1824.0000 1.0000
28.1200 1819.0000 1.0000
28.1600 1833.0000 1.0000
28.2000 1865.0000 1.0000
28.2400 1774.0000 1.0000
28.2800 1804.0000 1.0000
28.3200 1874.0000 1.0000
28.3600 1858.0000 1.0000
28.4000 1803.0000 1.0000
28.4400 1746.0000 1.0000
28.4800 1795.0000 1.0000
28.5200 1727.0000 1.0000
28.5600 1775.0000 1.0000
28.6000 1754.0000 1.0000
28.6400 1740.0000 1.0000
28.6800 1745.0000 1.0000
28.7200 1725.0000 1.0000
28.7600 1679.0000 1.0000
28.8000 1739.0000 1.0000
28.8400 1688.0000 1.0000
28.8800 1709.0000 1.0000
28.9200 1698.0000 1.0000
28.9600 1715.0000 1.0000
29.0000 1736.0000 1.0000
29.0400 1714.0000 1.0000
29.0800 1695.0000 1.0000
29.1200 1654.0000 1.0000
29.1600 1663.0000 1.0000
29.2000 1690.0000 1.0000
29.2400 1695.0000 1.0000
29.2800 1701.0000 1.0000
29.3200 1671.0000 1.0000
29.3600 1724.0000 1.0000
29.4000 1703.0000 1.0000
29.4400 1619.0000 1.0000
29.4800 1679.0000 1.0000
29.5200 1711.0000 1.0000
29.5600 1611.0000 1.0000
29.6000 1677.0000 1.0000
29.6400 1659.0000 1.0000
29.6800 1636.0000 1.0000
29.7200 1675.0000 1.0000
29.7600 1680.0000 1.0000
29.8000 1685.0000 1.0000
29.8400 1600.0000 1.0000
29.8800 1683.0000 1.0000
29.9200 1633.0000 1.0000
29.9600 1653.0000 1.0000
30.0000 1633.0000 1.0000
30.0400 1691.0000 1.0000
30.0800 1653.0000 1.0000
30.1200 1590.0000 1.0000
30.1600 1584.0000 1.0000
30.2000 1648.0000 1.0000
30.2400 1555.0000 1.0000
30.2800 1613.0000 1.0000
30.3200 1629.0000 1.0000
30.3600 1616.0000 1.0000
30.4000 1555.0000 1.0000
30.4400 1575.0000 1.0000
30.4800 1620.0000 1.0000
30.5200 1605.0000 1.0000
30.5600 1608.0000 1.0000
30.6000 1629.0000 1.0000
30.6400 1591.0000 1.0000
30.6800 1583.0000 1.0000
30.7200 1602.0000 1.0000
30.7600 1619.0000 1.0000
30.8000 1587.0000 1.0000
30.8400 1583.0000 1.0000
30.8800 1582.0000 1.0000
30.9200 1569.0000 1.0000
30.9600 1591.0000 1.0000
31.0000 1630.0000 1.0000
31.0400 1555.0000 1.0000
31.0800 1605.0000 1.0000
31.1200 1601.0000 1.0000
31.1600 1546.0000 1.0000
31.2000 1592.0000 1.0000
31.2400 1534.0000 1.0000
31.2800 1562.0000 1.0000
31.3200 1495.0000 1.0000
31.3600 1514.0000 1.0000
31.4000 1572.0000 1.0000
31.4400 1500.0000 1.0000
31.4800 1500.0000 1.0000
31.5200 1525.0000 1.0000
31.5600 1512.0000 1.0000
31.6000 1487.0000 1.0000
31.6400 1521.0000 1.0000
31.6800 1506.0000 1.0000
31.7200 1537.0000 1.0000
31.7600 1522.0000 1.0000
31.8000 1543.0000 1.0000
31.8400 1523.0000 1.0000
31.8800 1522.0000 1.0000
31.9200 1567.0000 1.0000
31.9600 1563.0000 1.0000
32.0000 1537.0000 1.0000
32.0400 1562.0000 1.0000
32.0800 1564.0000 1.0000
32.1200 1516.0000 1.0000
32.1600 1479.0000 1.0000
32.2000 1516.0000 1.0000
32.2400 1508.0000 1.0000
32.2800 1532.0000 1.0000
32.3200 1487.0000 1.0000
32.3600 1497.0000 1.0000
32.4000 1530.0000 1.0000
32.4400 1524.0000 1.0000
32.4800 1516.0000 1.0000
32.5200 1454.0000 1.0000
32.5600 1524.0000 1.0000
32.6000 1444.0000 1.0000
32.6400 1514.0000 1.0000
32.6800 1425.0000 1.0000
32.7200 1468.0000 1.0000
32.7600 1449.0000 1.0000
32.8000 1477.0000 1.0000
32.8400 1504.0000 1.0000
32.8800 1433.0000 1.0000
32.9200 1492.0000 1.0000
32.9600 1437.0000 1.0000
33.0000 1469.0000 1.0000
33.0400 1409.0000 1.0000
33.0800 1448.0000 1.0000
33.1200 1477.0000 1.0000
33.1600 1457.0000 1.0000
33.2000 1492.0000 1.0000
33.2400 1384.0000 1.0000
33.2800 1455.0000 1.0000
33.3200 1446.0000 1.0000
33.3600 1418.0000 1.0000
33.4000 1433.0000 1.0000
33.4400 1438.0000 1.0000
33.4800 1448.0000 1.0000
33.5200 1409.0000 1.0000
33.5600 1486.0000 1.0000
33.6000 1473.0000 1.0000
33.6400 1478.0000 1.0000
33.6800 1491.0000 1.0000
33.7200 1488.0000 1.0000
33.7600 1474.0000 1.0000
33.8000 1474.0000 1.0000
33.8400 1521.0000 1.0000
33.8800 1499.0000 1.0000
33.9200 1497.0000 1.0000
33.9600 1535.0000 1.0000
34.0000 1636.0000 1.0000
34.0400 1517.0000 1.0000
34.0800 1584.0000 1.0000
34.1200 1600.0000 1.0000
34.1600 1664.0000 1.0000
34.2000 1797.0000 1.0000
34.2400 1851.0000 1.0000
34.2800 1914.0000 1.0000
34.3200 2068.0000 1.0000
34.3600 2291.0000 1.0000
34.4000 2725.0000 1.0000
34.4400 2992.0000 1.0000
34.4800 3077.0000 1.0000
34.5200 2947.0000 1.0000
34.5600 2630.0000 1.0000
34.6000 2439.0000 1.0000
34.6400 2128.0000 1.0000
34.6800 1967.0000 1.0000
34.7200 1768.0000 1.0000
34.7600 1732.0000 1.0000
34.8000 1654.0000 1.0000
34.8400 1532.0000 1.0000
34.8800 1496.0000 1.0000
34.9200 1421.0000 1.0000
34.9600 1369.0000 1.0000
35.0000 1352.0000 1.0000
35.0400 1353.0000 1.0000
35.0800 1309.0000 1.0000
35.1200 1335.0000 1.0000
35.1600 1325.0000 1.0000
35.2000 1288.0000 1.0000
35.2400 1327.0000 1.0000
35.2800 1294.0000 1.0000
35.3200 1296.0000 1.0000
35.3600 1299.0000 1.0000
35.4000 1284.0000 1.0000
35.4400 1265.0000 1.0000
35.4800 1341.0000 1.0000
35.5200 1294.0000 1.0000
35.5600 1254.0000 1.0000
35.6000 1272.0000 1.0000
35.6400 1246.0000 1.0000
35.6800 1272.0000 1.0000
35.7200 1322.0000 1.0000
35.7600 1256.0000 1.0000
35.8000 1288.0000 1.0000
35.8400 1242.0000 1.0000
35.8800 1311.0000 1.0000
35.9200 1264.0000 1.0000
35.9600 1297.0000 1.0000
36.0000 1321.0000 1.0000
36.0400 1350.0000 1.0000
36.0800 1335.0000 1.0000
36.1200 1414.0000 1.0000
36.1600 1464.0000 1.0000
36.2000 1578.0000 1.0000
36.2400 1715.0000 1.0000
36.2800 1749.0000 1.0000
36.3200 1947.0000 1.0000
36.3600 2104.0000 1.0000
36.4000 2063.0000 1.0000
36.4400 2046.0000 1.0000
36.4800 1948.0000 1.0000
36.5200 1736.0000 1.0000
36.5600 1714.0000 1.0000
36.6000 1526.0000 1.0000
36.6400 1417.0000 1.0000
36.6800 1317.0000 1.0000
36.7200 1275.0000 1.0000
36.7600 1265.0000 1.0000
36.8000 1252.0000 1.0000
36.8400 1174.0000 1.0000
36.8800 1241.0000 1.0000
36.9200 1205.0000 1.0000
36.9600 1160.0000 1.0000
37.0000 1172.0000 1.0000
37.0400 1184.0000 1.0000
37.0800 1159.0000 1.0000
37.1200 1238.0000 1.0000
37.1600 1163.0000 1.0000
37.2000 1156.0000 1.0000
37.2400 1187.0000 1.0000
37.2800 1220.0000 1.0000
37.3200 1170.0000 1.0000
37.3600 1162.0000 1.0000
37.4000 1183.0000 1.0000
37.4400 1155.0000 1.0000
37.4800 1151.0000 1.0000
37.5200 1232.0000 1.0000
37.5600 1151.0000 1.0000
37.6000 1175.0000 1.0000
37.6400 1172.0000 1.0000
37.6800 1138.0000 1.0000
37.7200 1154.0000 1.0000
37.7600 1145.0000 1.0000
37.8000 1175.0000 1.0000
37.8400 1154.0000 1.0000
37.8800 1207.0000 1.0000
37.9200 1226.0000 1.0000
37.9600 1203.0000 1.0000
38.0000 1303.0000 1.0000
38.0400 1266.0000 1.0000
38.0800 1343.0000 1.0000
38.1200 1368.0000 1.0000
38.1600 1574.0000 1.0000
38.2000 1680.0000 1.0000
38.2400 1869.0000 1.0000
38.2800 2184.0000 1.0000
38.3200 2655.0000 1.0000
38.3600 3296.0000 1.0000
38.4000 4407.0000 1.0000
38.4400 5762.0000 1.0000
38.4800 7179.0000 1.0000
38.5200 7787.0000 1.0000
38.5600 7364.0000 1.0000
38.6000 6515.0000 1.0000
38.6400 5204.0000 1.0000
38.6800 4015.0000 1.0000
38.7200 3080.0000 1.0000
38.7600 2497.0000 1.0000
38.8000 2032.0000 1.0000
38.8400 1695.0000 1.0000
38.8800 1481.0000 1.0000
38.9200 1428.0000 1.0000
38.9600 1278.0000 1.0000
39.0000 1267.0000 1.0000
39.0400 1158.0000 1.0000
39.0800 1144.0000 1.0000
39.1200 1147.0000 1.0000
39.1600 1113.0000 1.0000
39.2000 1127.0000 1.0000
39.2400 1085.0000 1.0000
39.2800 1050.0000 1.0000
39.3200 1083.0000 1.0000
39.3600 1041.0000 1.0000
39.4000 1062.0000 1.0000
39.4400 1083.0000 1.0000
39.4800 1049.0000 1.0000
39.5200 1083.0000 1.0000
39.5600 1097.0000 1.0000
39.6000 1086.0000 1.0000
39.6400 1091.0000 1.0000
39.6800 1003.0000 1.0000
39.7200 1057.0000 1.0000
39.7600 1047.0000 1.0000
39.8000 1042.0000 1.0000
39.8400 1076.0000 1.0000
39.8800 1006.0000 1.0000
39.9200 1043.0000 1.0000
39.9600 1001.0000 1.0000
40.0000 987.0000 1.0000
40.0400 941.0000 1.0000
40.0800 934.0000 1.0000
40.1200 967.0000 1.0000
40.1600 992.0000 1.0000
40.2000 1019.0000 1.0000
40.2400 951.0000 1.0000
40.2800 989.0000 1.0000
40.3200 998.0000 1.0000
40.3600 951.0000 1.0000
40.4000 995.0000 1.0000
40.4400 953.0000 1.0000
40.4800 946.0000 1.0000
40.5200 948.0000 1.0000
40.5600 959.0000 1.0000
40.6000 951.0000 1.0000
40.6400 977.0000 1.0000
40.6800 1017.0000 1.0000
40.7200 970.0000 1.0000
40.7600 926.0000 1.0000
40.8000 1001.0000 1.0000
40.8400 991.0000 1.0000
40.8800 963.0000 1.0000
40.9200 970.0000 1.0000
40.9600 966.0000 1.0000
41.0000 955.0000 1.0000
41.0400 973.0000 1.0000
41.0800 936.0000 1.0000
41.1200 933.0000 1.0000
41.1600 941.0000 1.0000
41.2000 947.0000 1.0000
41.2400 922.0000 1.0000
41.2800 943.0000 1.0000
41.3200 961.0000 1.0000
41.3600 981.0000 1.0000
41.4000 929.0000 1.0000
41.4400 964.0000 1.0000
41.4800 987.0000 1.0000
41.5200 1014.0000 1.0000
41.5600 924.0000 1.0000
41.6000 926.0000 1.0000
41.6400 1005.0000 1.0000
41.6800 864.0000 1.0000
41.7200 941.0000 1.0000
41.7600 935.0000 1.0000
41.8000 951.0000 1.0000
41.8400 957.0000 1.0000
41.8800 958.0000 1.0000
41.9200 966.0000 1.0000
41.9600 945.0000 1.0000
42.0000 993.0000 1.0000
42.0400 905.0000 1.0000
42.0800 882.0000 1.0000
42.1200 925.0000 1.0000
42.1600 924.0000 1.0000
42.2000 893.0000 1.0000
42.2400 964.0000 1.0000
42.2800 939.0000 1.0000
42.3200 929.0000 1.0000
42.3600 915.0000 1.0000
42.4000 896.0000 1.0000
42.4400 966.0000 1.0000
42.4800 889.0000 1.0000
42.5200 974.0000 1.0000
42.5600 888.0000 1.0000
42.6000 918.0000 1.0000
42.6400 888.0000 1.0000
42.6800 928.0000 1.0000
42.7200 941.0000 1.0000
42.7600 952.0000 1.0000
42.8000 957.0000 1.0000
42.8400 961.0000 1.0000
42.8800 901.0000 1.0000
42.9200 906.0000 1.0000
42.9600 987.0000 1.0000
43.0000 920.0000 1.0000
43.0400 957.0000 1.0000
43.0800 959.0000 1.0000
43.1200 1002.0000 1.0000
43.1600 985.0000 1.0000
43.2000 999.0000 1.0000
43.2400 1031.0000 1.0000
43.2800 980.0000 1.0000
43.3200 1007.0000 1.0000
43.3600 991.0000 1.0000
43.4000 917.0000 1.0000
43.4400 902.0000 1.0000
43.4800 959.0000 1.0000
43.5200 848.0000 1.0000
43.5600 944.0000 1.0000
43.6000 945.0000 1.0000
43.6400 912.0000 1.0000
43.6800 894.0000 1.0000
43.7200 902.0000 1.0000
43.7600 941.0000 1.0000
43.8000 893.0000 1.0000
43.8400 898.0000 1.0000
43.8800 911.0000 1.0000
43.9200 913.0000 1.0000
43.9600 939.0000 1.0000
44.0000 913.0000 1.0000
44.0400 896.0000 1.0000
44.0800 922.0000 1.0000
44.1200 900.0000 1.0000
44.1600 899.0000 1.0000
44.2000 876.0000 1.0000
44.2400 861.0000 1.0000
44.2800 896.0000 1.0000
44.3200 861.0000 1.0000
44.3600 930.0000 1.0000
44.4000 878.0000 1.0000
44.4400 890.0000 1.0000
44.4800 870.0000 1.0000
44.5200 849.0000 1.0000
44.5600 880.0000 1.0000
44.6000 883.0000 1.0000
44.6400 884.0000 1.0000
44.6800 869.0000 1.0000
44.7200 856.0000 1.0000
44.7600 885.0000 1.0000
44.8000 843.0000 1.0000
44.8400 884.0000 1.0000
44.8800 880.0000 1.0000
44.9200 836.0000 1.0000
44.9600 854.0000 1.0000
45.0000 882.0000 1.0000
45.0400 854.0000 1.0000
45.0800 830.0000 1.0000
45.1200 897.0000 1.0000
45.1600 886.0000 1.0000
45.2000 853.0000 1.0000
45.2400 847.0000 1.0000
45.2800 884.0000 1.0000
45.3200 907.0000 1.0000
45.3600 823.0000 1.0000
45.4000 859.0000 1.0000
45.4400 844.0000 1.0000
45.4800 865.0000 1.0000
45.5200 876.0000 1.0000
45.5600 834.0000 1.0000
45.6000 867.0000 1.0000
45.6400 849.0000 1.0000
45.6800 847.0000 1.0000
45.7200 846.0000 1.0000
45.7600 861.0000 1.0000
45.8000 854.0000 1.0000
45.8400 853.0000 1.0000
45.8800 891.0000 1.0000
45.9200 848.0000 1.0000
45.9600 850.0000 1.0000
46.0000 890.0000 1.0000
46.0400 827.0000 1.0000
46.0800 861.0000 1.0000
46.1200 856.0000 1.0000
46.1600 854.0000 1.0000
46.2000 854.0000 1.0000
46.2400 853.0000 1.0000
46.2800 849.0000 1.0000
46.3200 859.0000 1.0000
46.3600 850.0000 1.0000
46.4000 848.0000 1.0000
46.4400 882.0000 1.0000
46.4800 848.0000 1.0000
46.5200 834.0000 1.0000
46.5600 864.0000 1.0000
46.6000 852.0000 1.0000
46.6400 828.0000 1.0000
46.6800 876.0000 1.0000
46.7200 849.0000 1.0000
46.7600 826.0000 1.0000
46.8000 809.0000 1.0000
46.8400 829.0000 1.0000
46.8800 860.0000 1.0000
46.9200 854.0000 1.0000
46.9600 858.0000 1.0000
47.0000 880.0000 1.0000
47.0400 892.0000 1.0000
47.0800 840.0000 1.0000
47.1200 818.0000 1.0000
47.1600 840.0000 1.0000
47.2000 815.0000 1.0000
47.2400 832.0000 1.0000
47.2800 834.0000 1.0000
47.3200 821.0000 1.0000
47.3600 761.0000 1.0000
47.4000 835.0000 1.0000
47.4400 834.0000 1.0000
47.4800 823.0000 1.0000
47.5200 804.0000 1.0000
47.5600 842.0000 1.0000
47.6000 829.0000 1.0000
47.6400 822.0000 1.0000
47.6800 766.0000 1.0000
47.7200 772.0000 1.0000
47.7600 795.0000 1.0000
47.8000 825.0000 1.0000
47.8400 851.0000 1.0000
47.8800 786.0000 1.0000
47.9200 797.0000 1.0000
47.9600 767.0000 1.0000
48.0000 829.0000 1.0000
48.0400 820.0000 1.0000
48.0800 797.0000 1.0000
48.1200 818.0000 1.0000
48.1600 783.0000 1.0000
48.2000 806.0000 1.0000
48.2400 807.0000 1.0000
48.2800 771.0000 1.0000
48.3200 803.0000 1.0000
48.3600 801.0000 1.0000
48.4000 782.0000 1.0000
48.4400 845.0000 1.0000
48.4800 818.0000 1.0000
48.5200 844.0000 1.0000
48.5600 780.0000 1.0000
48.6000 803.0000 1.0000
48.6400 795.0000 1.0000
48.6800 781.0000 1.0000
48.7200 825.0000 1.0000
48.7600 796.0000 1.0000
48.8000 791.0000 1.0000
48.8400 800.0000 1.0000
48.8800 786.0000 1.0000
48.9200 757.0000 1.0000
48.9600 803.0000 1.0000
49.0000 802.0000 1.0000
49.0400 755.0000 1.0000
49.0800 799.0000 1.0000
49.1200 767.0000 1.0000
49.1600 818.0000 1.0000
49.2000 766.0000 1.0000
49.2400 776.0000 1.0000
49.2800 819.0000 1.0000
49.3200 762.0000 1.0000
49.3600 769.0000 1.0000
49.4000 746.0000 1.0000
49.4400 765.0000 1.0000
49.4800 768.0000 1.0000
49.5200 760.0000 1.0000
49.5600 768.0000 1.0000
49.6000 800.0000 1.0000
49.6400 782.0000 1.0000
49.6800 742.0000 1.0000
49.7200 751.0000 1.0000
49.7600 802.0000 1.0000
49.8000 805.0000 1.0000
49.8400 762.0000 1.0000
49.8800 768.0000 1.0000
49.9200 816.0000 1.0000
49.9600 803.0000 1.0000
50.0000 816.0000 1.0000
50.0400 829.0000 1.0000
50.0800 797.0000 1.0000
50.1200 742.0000 1.0000
50.1600 820.0000 1.0000
50.2000 806.0000 1.0000
50.2400 778.0000 1.0000
50.2800 829.0000 1.0000
50.3200 816.0000 1.0000
50.3600 822.0000 1.0000
50.4000 802.0000 1.0000
50.4400 790.0000 1.0000
50.4800 808.0000 1.0000
50.5200 808.0000 1.0000
50.5600 780.0000 1.0000
50.6000 817.0000 1.0000
50.6400 846.0000 1.0000
50.6800 771.0000 1.0000
50.7200 749.0000 1.0000
50.7600 861.0000 1.0000
50.8000 860.0000 1.0000
50.8400 823.0000 1.0000
50.8800 834.0000 1.0000
50.9200 778.0000 1.0000
50.9600 788.0000 1.0000
51.0000 767.0000 1.0000
51.0400 786.0000 1.0000
51.0800 762.0000 1.0000
51.1200 777.0000 1.0000
51.1600 784.0000 1.0000
51.2000 800.0000 1.0000
51.2400 818.0000 1.0000
51.2800 778.0000 1.0000
51.3200 787.0000 1.0000
51.3600 816.0000 1.0000
51.4000 826.0000 1.0000
51.4400 770.0000 1.0000
51.4800 783.0000 1.0000
51.5200 806.0000 1.0000
51.5600 839.0000 1.0000
51.6000 819.0000 1.0000
51.6400 855.0000 1.0000
51.6800 860.0000 1.0000
51.7200 851.0000 1.0000
51.7600 834.0000 1.0000
51.8000 905.0000 1.0000
51.8400 915.0000 1.0000
51.8800 990.0000 1.0000
51.9200 1083.0000 1.0000
51.9600 1127.0000 1.0000
52.0000 1241.0000 1.0000
52.0400 1500.0000 1.0000
52.0800 1752.0000 1.0000
52.1200 2331.0000 1.0000
52.1600 3153.0000 1.0000
52.2000 4370.0000 1.0000
52.2400 5040.0000 1.0000
52.2800 4791.0000 1.0000
52.3200 4332.0000 1.0000
52.3600 4032.0000 1.0000
52.4000 3411.0000 1.0000
52.4400 2678.0000 1.0000
52.4800 2035.0000 1.0000
52.5200 1657.0000 1.0000
52.5600 1471.0000 1.0000
52.6000 1196.0000 1.0000
52.6400 1129.0000 1.0000
52.6800 1007.0000 1.0000
52.7200 979.0000 1.0000
52.7600 954.0000 1.0000
52.8000 925.0000 1.0000
52.8400 915.0000 1.0000
52.8800 845.0000 1.0000
52.9200 847.0000 1.0000
52.9600 873.0000 1.0000
53.0000 828.0000 1.0000
53.0400 818.0000 1.0000
53.0800 837.0000 1.0000
53.1200 825.0000 1.0000
53.1600 782.0000 1.0000
53.2000 785.0000 1.0000
53.2400 767.0000 1.0000
53.2800 803.0000 1.0000
53.3200 795.0000 1.0000
53.3600 814.0000 1.0000
53.4000 755.0000 1.0000
53.4400 783.0000 1.0000
53.4800 758.0000 1.0000
53.5200 754.0000 1.0000
53.5600 778.0000 1.0000
53.6000 743.0000 1.0000
53.6400 784.0000 1.0000
53.6800 816.0000 1.0000
53.7200 752.0000 1.0000
53.7600 809.0000 1.0000
53.8000 728.0000 1.0000
53.8400 739.0000 1.0000
53.8800 737.0000 1.0000
53.9200 794.0000 1.0000
53.9600 760.0000 1.0000
54.0000 698.0000 1.0000
54.0400 784.0000 1.0000
54.0800 773.0000 1.0000
54.1200 768.0000 1.0000
54.1600 777.0000 1.0000
54.2000 754.0000 1.0000
54.2400 709.0000 1.0000
54.2800 803.0000 1.0000
54.3200 737.0000 1.0000
54.3600 770.0000 1.0000
54.4000 746.0000 1.0000
54.4400 798.0000 1.0000
54.4800 742.0000 1.0000
54.5200 755.0000 1.0000
54.5600 818.0000 1.0000
54.6000 733.0000 1.0000
54.6400 800.0000 1.0000
54.6800 791.0000 1.0000
54.7200 759.0000 1.0000
54.7600 826.0000 1.0000
54.8000 770.0000 1.0000
54.8400 814.0000 1.0000
54.8800 838.0000 1.0000
54.9200 824.0000 1.0000
54.9600 815.0000 1.0000
55.0000 870.0000 1.0000
55.0400 854.0000 1.0000
55.0800 903.0000 1.0000
55.1200 918.0000 1.0000
55.1600 1007.0000 1.0000
55.2000 1077.0000 1.0000
55.2400 1112.0000 1.0000
55.2800 1198.0000 1.0000
55.3200 1154.0000 1.0000
55.3600 1057.0000 1.0000
55.4000 1121.0000 1.0000
55.4400 1020.0000 1.0000
55.4800 966.0000 1.0000
55.5200 959.0000 1.0000
55.5600 899.0000 1.0000
55.6000 881.0000 1.0000
55.6400 839.0000 1.0000
55.6800 802.0000 1.0000
55.7200 791.0000 1.0000
55.7600 759.0000 1.0000
55.8000 788.0000 1.0000
55.8400 730.0000 1.0000
55.8800 801.0000 1.0000
55.9200 760.0000 1.0000
55.9600 760.0000 1.0000
56.0000 749.0000 1.0000
56.0400 744.0000 1.0000
56.0800 759.0000 1.0000
56.1200 748.0000 1.0000
56.1600 731.0000 1.0000
56.2000 752.0000 1.0000
56.2400 705.0000 1.0000
56.2800 741.0000 1.0000
56.3200 716.0000 1.0000
56.3600 752.0000 1.0000
56.4000 723.0000 1.0000
56.4400 720.0000 1.0000
56.4800 726.0000 1.0000
56.5200 765.0000 1.0000
56.5600 745.0000 1.0000
56.6000 729.0000 1.0000
56.6400 757.0000 1.0000
56.6800 750.0000 1.0000
56.7200 715.0000 1.0000
56.7600 690.0000 1.0000
56.8000 730.0000 1.0000
56.8400 762.0000 1.0000
56.8800 792.0000 1.0000
56.9200 741.0000 1.0000
56.9600 753.0000 1.0000
57.0000 736.0000 1.0000
57.0400 738.0000 1.0000
57.0800 770.0000 1.0000
57.1200 703.0000 1.0000
57.1600 755.0000 1.0000
57.2000 714.0000 1.0000
57.2400 771.0000 1.0000
57.2800 801.0000 1.0000
57.3200 768.0000 1.0000
57.3600 752.0000 1.0000
57.4000 755.0000 1.0000
57.4400 733.0000 1.0000
57.4800 763.0000 1.0000
57.5200 702.0000 1.0000
57.5600 686.0000 1.0000
57.6000 689.0000 1.0000
57.6400 741.0000 1.0000
57.6800 749.0000 1.0000
57.7200 719.0000 1.0000
57.7600 703.0000 1.0000
57.8000 716.0000 1.0000
57.8400 735.0000 1.0000
57.8800 738.0000 1.0000
57.9200 714.0000 1.0000
57.9600 741.0000 1.0000
58.0000 721.0000 1.0000
58.0400 798.0000 1.0000
58.0800 770.0000 1.0000
58.1200 754.0000 1.0000
58.1600 760.0000 1.0000
58.2000 723.0000 1.0000
58.2400 708.0000 1.0000
58.2800 745.0000 1.0000
58.3200 746.0000 1.0000
58.3600 734.0000 1.0000
58.4000 704.0000 1.0000
58.4400 761.0000 1.0000
58.4800 715.0000 1.0000
58.5200 751.0000 1.0000
58.5600 726.0000 1.0000
58.6000 768.0000 1.0000
58.6400 761.0000 1.0000
58.6800 766.0000 1.0000
58.7200 727.0000 1.0000
58.7600 705.0000 1.0000
58.8000 745.0000 1.0000
58.8400 743.0000 1.0000
58.8800 687.0000 1.0000
58.9200 761.0000 1.0000
58.9600 728.0000 1.0000
59.0000 710.0000 1.0000
59.0400 726.0000 1.0000
59.0800 704.0000 1.0000
59.1200 727.0000 1.0000
59.1600 708.0000 1.0000
59.2000 713.0000 1.0000
59.2400 701.0000 1.0000
59.2800 756.0000 1.0000
59.3200 724.0000 1.0000
59.3600 708.0000 1.0000
59.4000 751.0000 1.0000
59.4400 735.0000 1.0000
59.4800 718.0000 1.0000
59.5200 691.0000 1.0000
59.5600 720.0000 1.0000
59.6000 721.0000 1.0000
59.6400 692.0000 1.0000
59.6800 721.0000 1.0000
59.7200 733.0000 1.0000
59.7600 710.0000 1.0000
59.8000 715.0000 1.0000
59.8400 778.0000 1.0000
59.8800 745.0000 1.0000
59.9200 702.0000 1.0000
59.9600 737.0000 1.0000
60.0000 751.0000 1.0000
60.0400 714.0000 1.0000
60.0800 720.0000 1.0000
60.1200 696.0000 1.0000
60.1600 699.0000 1.0000
60.2000 702.0000 1.0000
60.2400 752.0000 1.0000
60.2800 762.0000 1.0000
60.3200 762.0000 1.0000
60.3600 745.0000 1.0000
60.4000 717.0000 1.0000
60.4400 706.0000 1.0000
60.4800 779.0000 1.0000
60.5200 748.0000 1.0000
60.5600 709.0000 1.0000
60.6000 740.0000 1.0000
60.6400 692.0000 1.0000
60.6800 667.0000 1.0000
60.7200 739.0000 1.0000
60.7600 741.0000 1.0000
60.8000 727.0000 1.0000
60.8400 745.0000 1.0000
60.8800 734.0000 1.0000
60.9200 730.0000 1.0000
60.9600 723.0000 1.0000
61.0000 711.0000 1.0000
61.0400 695.0000 1.0000
61.0800 692.0000 1.0000
61.1200 744.0000 1.0000
61.1600 723.0000 1.0000
61.2000 728.0000 1.0000
61.2400 730.0000 1.0000
61.2800 714.0000 1.0000
61.3200 704.0000 1.0000
61.3600 723.0000 1.0000
61.4000 700.0000 1.0000
61.4400 753.0000 1.0000
61.4800 749.0000 1.0000
61.5200 773.0000 1.0000
61.5600 771.0000 1.0000
61.6000 729.0000 1.0000
61.6400 747.0000 1.0000
61.6800 763.0000 1.0000
61.7200 755.0000 1.0000
61.7600 792.0000 1.0000
61.8000 825.0000 1.0000
61.8400 829.0000 1.0000
61.8800 802.0000 1.0000
61.9200 862.0000 1.0000
61.9600 912.0000 1.0000
62.0000 921.0000 1.0000
62.0400 1035.0000 1.0000
62.0800 1107.0000 1.0000
62.1200 1329.0000 1.0000
62.1600 1366.0000 1.0000
62.2000 1607.0000 1.0000
62.2400 1677.0000 1.0000
62.2800 1798.0000 1.0000
62.3200 1753.0000 1.0000
62.3600 1654.0000 1.0000
62.4000 1592.0000 1.0000
62.4400 1493.0000 1.0000
62.4800 1443.0000 1.0000
62.5200 1280.0000 1.0000
62.5600 1206.0000 1.0000
62.6000 1067.0000 1.0000
62.6400 1027.0000 1.0000
62.6800 949.0000 1.0000
62.7200 879.0000 1.0000
62.7600 879.0000 1.0000
62.8000 889.0000 1.0000
62.8400 797.0000 1.0000
62.8800 798.0000 1.0000
62.9200 802.0000 1.0000
62.9600 786.0000 1.0000
63.0000 791.0000 1.0000
63.0400 768.0000 1.0000
63.0800 810.0000 1.0000
63.1200 752.0000 1.0000
63.1600 764.0000 1.0000
63.2000 773.0000 1.0000
63.2400 711.0000 1.0000
63.2800 793.0000 1.0000
63.3200 729.0000 1.0000
63.3600 736.0000 1.0000
63.4000 751.0000 1.0000
63.4400 738.0000 1.0000
63.4800 769.0000 1.0000
63.5200 755.0000 1.0000
63.5600 751.0000 1.0000
63.6000 751.0000 1.0000
63.6400 701.0000 1.0000
63.6800 786.0000 1.0000
63.7200 752.0000 1.0000
63.7600 738.0000 1.0000
63.8000 756.0000 1.0000
63.8400 727.0000 1.0000
63.8800 768.0000 1.0000
63.9200 713.0000 1.0000
63.9600 745.0000 1.0000
64.0000 772.0000 1.0000
64.0400 718.0000 1.0000
64.0800 774.0000 1.0000
64.1200 736.0000 1.0000
64.1600 764.0000 1.0000
64.2000 760.0000 1.0000
64.2400 773.0000 1.0000
64.2800 733.0000 1.0000
64.3200 749.0000 1.0000
64.3600 846.0000 1.0000
64.4000 810.0000 1.0000
64.4400 829.0000 1.0000
64.4800 818.0000 1.0000
64.5200 861.0000 1.0000
64.5600 916.0000 1.0000
64.6000 973.0000 1.0000
64.6400 945.0000 1.0000
64.6800 995.0000 1.0000
64.7200 946.0000 1.0000
64.7600 1025.0000 1.0000
64.8000 940.0000 1.0000
64.8400 946.0000 1.0000
64.8800 898.0000 1.0000
64.9200 911.0000 1.0000
64.9600 921.0000 1.0000
65.0000 860.0000 1.0000
65.0400 826.0000 1.0000
65.0800 827.0000 1.0000
65.1200 821.0000 1.0000
65.1600 793.0000 1.0000
65.2000 791.0000 1.0000
65.2400 740.0000 1.0000
65.2800 754.0000 1.0000
65.3200 769.0000 1.0000
65.3600 739.0000 1.0000
65.4000 745.0000 1.0000
65.4400 773.0000 1.0000
65.4800 726.0000 1.0000
65.5200 798.0000 1.0000
65.5600 747.0000 1.0000
65.6000 754.0000 1.0000
65.6400 801.0000 1.0000
65.6800 788.0000 1.0000
65.7200 856.0000 1.0000
65.7600 811.0000 1.0000
65.8000 800.0000 1.0000
65.8400 838.0000 1.0000
65.8800 882.0000 1.0000
65.9200 959.0000 1.0000
65.9600 1015.0000 1.0000
66.0000 1068.0000 1.0000
66.0400 1277.0000 1.0000
66.0800 1527.0000 1.0000
66.1200 1759.0000 1.0000
66.1600 2217.0000 1.0000
66.2000 2708.0000 1.0000
66.2400 2727.0000 1.0000
66.2800 2505.0000 1.0000
66.3200 2497.0000 1.0000
66.3600 2354.0000 1.0000
66.4000 2267.0000 1.0000
66.4400 2086.0000 1.0000
66.4800 1790.0000 1.0000
66.5200 1520.0000 1.0000
66.5600 1317.0000 1.0000
66.6000 1132.0000 1.0000
66.6400 1058.0000 1.0000
66.6800 991.0000 1.0000
66.7200 954.0000 1.0000
66.7600 824.0000 1.0000
66.8000 831.0000 1.0000
66.8400 802.0000 1.0000
66.8800 743.0000 1.0000
66.9200 729.0000 1.0000
66.9600 757.0000 1.0000
67.0000 737.0000 1.0000
67.0400 715.0000 1.0000
67.0800 709.0000 1.0000
67.1200 695.0000 1.0000
67.1600 693.0000 1.0000
67.2000 709.0000 1.0000
67.2400 715.0000 1.0000
67.2800 683.0000 1.0000
67.3200 710.0000 1.0000
67.3600 703.0000 1.0000
67.4000 697.0000 1.0000
67.4400 704.0000 1.0000
67.4800 689.0000 1.0000
67.5200 665.0000 1.0000
67.5600 660.0000 1.0000
67.6000 710.0000 1.0000
67.6400 690.0000 1.0000
67.6800 667.0000 1.0000
67.7200 675.0000 1.0000
67.7600 685.0000 1.0000
67.8000 688.0000 1.0000
67.8400 664.0000 1.0000
67.8800 652.0000 1.0000
67.9200 669.0000 1.0000
67.9600 665.0000 1.0000
68.0000 677.0000 1.0000
68.0400 666.0000 1.0000
68.0800 645.0000 1.0000
68.1200 665.0000 1.0000
68.1600 684.0000 1.0000
68.2000 668.0000 1.0000
68.2400 676.0000 1.0000
68.2800 627.0000 1.0000
68.3200 653.0000 1.0000
68.3600 658.0000 1.0000
68.4000 667.0000 1.0000
68.4400 682.0000 1.0000
68.4800 642.0000 1.0000
68.5200 673.0000 1.0000
68.5600 681.0000 1.0000
68.6000 607.0000 1.0000
68.6400 629.0000 1.0000
68.6800 692.0000 1.0000
68.7200 635.0000 1.0000
68.7600 609.0000 1.0000
68.8000 644.0000 1.0000
68.8400 651.0000 1.0000
68.8800 657.0000 1.0000
68.9200 650.0000 1.0000
68.9600 661.0000 1.0000
69.0000 630.0000 1.0000
69.0400 639.0000 1.0000
69.0800 655.0000 1.0000
69.1200 660.0000 1.0000
69.1600 621.0000 1.0000
69.2000 622.0000 1.0000
69.2400 654.0000 1.0000
69.2800 625.0000 1.0000
69.3200 659.0000 1.0000
69.3600 640.0000 1.0000
69.4000 652.0000 1.0000
69.4400 628.0000 1.0000
69.4800 659.0000 1.0000
69.5200 586.0000 1.0000
69.5600 681.0000 1.0000
69.6000 596.0000 1.0000
69.6400 628.0000 1.0000
69.6800 657.0000 1.0000
69.7200 627.0000 1.0000
69.7600 628.0000 1.0000
69.8000 649.0000 1.0000
69.8400 656.0000 1.0000
69.8800 636.0000 1.0000
69.9200 632.0000 1.0000
69.9600 653.0000 1.0000
70.0000 592.0000 1.0000
*RAS_INT_END
*RAS_TEMPERATURE_START
*RAS_TEMPERATURE_END
*RAS_DATA_END