File: Section2_75_samples/XRD/No_013_650_17.ras
*RAS_DATA_START
*RAS_HEADER_START
*DISP_FMT_X "%.2f"
*DISP_FMT_Y "%.0f"
*DISP_FULLSCALE "3960.0000000000"
*DISP_LINE_COLOR "255.0000000000"
*DISP_LINE_STYLE "0.0000000000"
*DISP_LINE_WIDTH "0.2500000000"
*DISP_NOTE "測定データ-6"
*DISP_OFFSET_Y "0.0000000000"
*DISP_PEAKSEARCH_UNIT_Y "cps"
*DISP_RANGE_BOTTOM "0.0000000000"
*DISP_RANGE_LEFT "20.0000000000"
*DISP_RANGE_LOGCUTOFF "0.0100000000"
*DISP_RANGE_RIGHT "80.0000000000"
*DISP_RANGE_TOP "3960.0000000000"
*DISP_SCALE_MODE_Y "0.0000000000"
*DISP_TAB_NAME "2θ/θ"
*DISP_TITLE_Y "強度"
*DISP_UNIT_Y "cps"
*DISP_WINDOW_NAME "MSG_MACROENGINE"
*FILE_COMMENT " "
*FILE_MD5 ""
*FILE_MEMO " "
*FILE_OPERATOR "Administrator"
*FILE_SAMPLE " "
*FILE_TYPE "RAS_RAW"
*FILE_USERGROUP "システムマネージャ"
*FILE_VERSION "1.0000000000"
*HW_ATTACHMENT_ID "ATT0025"
*HW_ATTACHMENT_NAME "標準|Standard"
*HW_COUNTER_ID-0 "CUT0025"
*HW_COUNTER_ID-1 "CUT0020"
*HW_COUNTER_ID-2 "CUT0020"
*HW_COUNTER_ID-3 "CSL0021"
*HW_COUNTER_ID-4 "CMC0021"
*HW_COUNTER_NAME-0 "D/teX Ultra|D/teX Ultra"
*HW_COUNTER_NAME-1 "None|None"
*HW_COUNTER_NAME-2 "None|None"
*HW_COUNTER_NAME-3 "BBM|BBM"
*HW_COUNTER_NAME-4 "検出器モノクロメータ|Detector monochromator"
*HW_COUNTER_SELECT_NAME "D/teX Ultra|D/teX Ultra"
*HW_GONIOMETER_ID "GON0023"
*HW_GONIOMETER_NAME "SmartLab|SmartLab"
*HW_GONIOMETER_RADIUS-0 "90.0"
*HW_GONIOMETER_RADIUS-1 "114.0"
*HW_GONIOMETER_RADIUS-2 "190.0"
*HW_GONIOMETER_RADIUS-3 "300.0"
*HW_GONIOMETER_RADIUS-4 "187.0"
*HW_GONIOMETER_RADIUS-5 "300.0"
*HW_GONIOMETER_RADIUS-6 "113.0"
*HW_GONIOMETER_RADIUS-7 "331.0"
*HW_I_OPT_ID-0 "CBO0021"
*HW_I_OPT_ID-1 "ICR0023"
*HW_I_OPT_ID-2 "ISL0021"
*HW_I_OPT_ID-3 "ISO0021"
*HW_I_OPT_ID-4 "IAD0021"
*HW_I_OPT_ID-5 "IPR0001"
*HW_I_OPT_NAME-0 "CBOユニット|CBO unit"
*HW_I_OPT_NAME-1 "標準入射光学ユニット|Standard incident optical unit"
*HW_I_OPT_NAME-2 "標準入射スリットボックス|Standard incident slit box"
*HW_I_OPT_NAME-3 "入射平行スリット|Incident parallel slit"
*HW_I_OPT_NAME-4 "長手制限スリット|Length limiting slit"
*HW_I_OPT_NAME-5 "None|None"
*HW_R_ATTENUATER_AUTOMODE "0"
*HW_R_OPT_ID-0 "RSS0021"
*HW_R_OPT_ID-1 "RCR0023"
*HW_R_OPT_ID-2 "RSO0021"
*HW_R_OPT_ID-3 "RRS0021"
*HW_R_OPT_ID-4 "ATN0021"
*HW_R_OPT_ID-5 "RFL0021"
*HW_R_OPT_ID-6 "RAD0021"
*HW_R_OPT_NAME-0 "標準受光スリットボックス1|Standard receiving slit box # 1"
*HW_R_OPT_NAME-1 "標準受光光学ユニット1|Standard receiving unit # 1"
*HW_R_OPT_NAME-2 "標準受光光学ユニット2|Standard receiving optical unit # 2"
*HW_R_OPT_NAME-3 "標準受光スリットボックス2|Standard receiving slit box # 2"
*HW_R_OPT_NAME-4 "標準アッテネータ|Standard Attenuator"
*HW_R_OPT_NAME-5 "Cu Kβ|Cu K-beta"
*HW_R_OPT_NAME-6 "調整用受光スリット|Alignment receiving slit"
*HW_SAMPLE_HOLDER_ID "SMP0023"
*HW_SAMPLE_HOLDER_NAME "標準Zステージ|Standard Z stage"
*HW_XG_CURRENT_MAX "50"
*HW_XG_CURRENT_MIN "2"
*HW_XG_CURRENT_RESOLUTION "2"
*HW_XG_CURRENT_UNIT "mA"
*HW_XG_FOCUS "1mm x 10mm"
*HW_XG_FOCUS_TYPE "Normal"
*HW_XG_ID ""
*HW_XG_NAME "3kW 封入管(ID:1200)|3kW Sealed tube(ID:1200)"
*HW_XG_TARGET_ATOMIC_NUMBER "29.0000000000"
*HW_XG_TARGET_NAME "Cu"
*HW_XG_TYPE "Hermetic"
*HW_XG_VOLTAGE_MAX "60"
*HW_XG_VOLTAGE_MIN "20"
*HW_XG_VOLTAGE_RESOLUTION "2"
*HW_XG_VOLTAGE_UNIT "kV"
*HW_XG_WATT_MAX "2"
*HW_XG_WATT_UNIT "kW"
*HW_XG_WAVE_LENGTH_ALPHA1 "1.540593"
*HW_XG_WAVE_LENGTH_ALPHA2 "1.544414"
*HW_XG_WAVE_LENGTH_BETA "1.392250"
*MEAS_COND_AXIS_NAME-0 "2θ/θ"
*MEAS_COND_AXIS_NAME-1 "2θ"
*MEAS_COND_AXIS_NAME-2 "ω"
*MEAS_COND_AXIS_NAME-3 "Z"
*MEAS_COND_AXIS_NAME-4 "2θ/ω"
*MEAS_COND_AXIS_NAME-5 "θs"
*MEAS_COND_AXIS_NAME-6 "θd"
*MEAS_COND_AXIS_NAME-7 "Ts"
*MEAS_COND_AXIS_NAME-8 "CBO選択スリット"
*MEAS_COND_AXIS_NAME-9 "M"
*MEAS_COND_AXIS_NAME-10 "入射平行スリット"
*MEAS_COND_AXIS_NAME-11 "入射スリット"
*MEAS_COND_AXIS_NAME-12 ""
*MEAS_COND_AXIS_NAME-13 "Zs"
*MEAS_COND_AXIS_NAME-14 "入射光学素子"
*MEAS_COND_AXIS_NAME-15 "長手制限スリット"
*MEAS_COND_AXIS_NAME-16 "センタースリット"
*MEAS_COND_AXIS_NAME-17 "フィルター"
*MEAS_COND_AXIS_NAME-18 "受光スリット1"
*MEAS_COND_AXIS_NAME-19 "受光スリット2"
*MEAS_COND_AXIS_NAME-20 "受光光学素子"
*MEAS_COND_AXIS_NAME-21 "受光平行スリット"
*MEAS_COND_AXIS_NAME-22 "調整用受光スリット"
*MEAS_COND_AXIS_NAME-23 ""
*MEAS_COND_AXIS_NAME-24 ""
*MEAS_COND_AXIS_NAME-25 "Zd"
*MEAS_COND_AXIS_NAME-26 "アッテネータ"
*MEAS_COND_AXIS_NAME-27 "検出器モノクロメータ"
*MEAS_COND_AXIS_NAME-28 "モノクロメータスリット"
*MEAS_COND_AXIS_NAME-29 "プライマリビーム"
*MEAS_COND_AXIS_NAME-30 "PHA"
*MEAS_COND_AXIS_NAME_INTERNAL-0 "TwoThetaTheta"
*MEAS_COND_AXIS_NAME_INTERNAL-1 "TwoTheta"
*MEAS_COND_AXIS_NAME_INTERNAL-2 "Omega"
*MEAS_COND_AXIS_NAME_INTERNAL-3 "Z"
*MEAS_COND_AXIS_NAME_INTERNAL-4 "TwoThetaOmega"
*MEAS_COND_AXIS_NAME_INTERNAL-5 "ThetaS"
*MEAS_COND_AXIS_NAME_INTERNAL-6 "ThetaD"
*MEAS_COND_AXIS_NAME_INTERNAL-7 "Ts"
*MEAS_COND_AXIS_NAME_INTERNAL-8 "CBO"
*MEAS_COND_AXIS_NAME_INTERNAL-9 "CBO-M"
*MEAS_COND_AXIS_NAME_INTERNAL-10 "IncidentSollerSlit"
*MEAS_COND_AXIS_NAME_INTERNAL-11 "IncidentSlitBox"
*MEAS_COND_AXIS_NAME_INTERNAL-12 "IncidentSlitBox-_Axis"
*MEAS_COND_AXIS_NAME_INTERNAL-13 "Zs"
*MEAS_COND_AXIS_NAME_INTERNAL-14 "IncidentMonochromator"
*MEAS_COND_AXIS_NAME_INTERNAL-15 "IncidentAxdSlit"
*MEAS_COND_AXIS_NAME_INTERNAL-16 "CenterSlit"
*MEAS_COND_AXIS_NAME_INTERNAL-17 "Filter"
*MEAS_COND_AXIS_NAME_INTERNAL-18 "ReceivingSlitBox1"
*MEAS_COND_AXIS_NAME_INTERNAL-19 "ReceivingSlitBox2"
*MEAS_COND_AXIS_NAME_INTERNAL-20 "ReceivingOptics"
*MEAS_COND_AXIS_NAME_INTERNAL-21 "ReceivingSollerSlit"
*MEAS_COND_AXIS_NAME_INTERNAL-22 "ReceivingAxdSlit"
*MEAS_COND_AXIS_NAME_INTERNAL-23 "ReceivingSlitBox1-_Axis"
*MEAS_COND_AXIS_NAME_INTERNAL-24 "ReceivingSlitBox2-_Axis"
*MEAS_COND_AXIS_NAME_INTERNAL-25 "ReceivingSlitBox2-Zd"
*MEAS_COND_AXIS_NAME_INTERNAL-26 "Attenuator"
*MEAS_COND_AXIS_NAME_INTERNAL-27 "CounterMonochromator"
*MEAS_COND_AXIS_NAME_INTERNAL-28 "CounterSlit"
*MEAS_COND_AXIS_NAME_INTERNAL-29 "IncidentPrimary"
*MEAS_COND_AXIS_NAME_INTERNAL-30 "PHA"
*MEAS_COND_AXIS_NAME_MAGICNO-0 "83951616.0000000000"
*MEAS_COND_AXIS_NAME_MAGICNO-1 "268632064.0000000000"
*MEAS_COND_AXIS_NAME_MAGICNO-2 "268500992.0000000000"
*MEAS_COND_AXIS_NAME_MAGICNO-3 "285278208.0000000000"
*MEAS_COND_AXIS_NAME_MAGICNO-4 "83951616.0000000000"
*MEAS_COND_AXIS_NAME_MAGICNO-5 "131072.0000000000"
*MEAS_COND_AXIS_NAME_MAGICNO-6 "131072.0000000000"
*MEAS_COND_AXIS_NAME_MAGICNO-7 "318898176.0000000000"
*MEAS_COND_AXIS_NAME_MAGICNO-8 "20971521.0000000000"
*MEAS_COND_AXIS_NAME_MAGICNO-9 "285343744.0000000000"
*MEAS_COND_AXIS_NAME_MAGICNO-10 "20971521.0000000000"
*MEAS_COND_AXIS_NAME_MAGICNO-11 "22020097.0000000000"
*MEAS_COND_AXIS_NAME_MAGICNO-12 "25165824.0000000000"
*MEAS_COND_AXIS_NAME_MAGICNO-13 "318898176.0000000000"
*MEAS_COND_AXIS_NAME_MAGICNO-14 "1.0000000000"
*MEAS_COND_AXIS_NAME_MAGICNO-15 "20971521.0000000000"
*MEAS_COND_AXIS_NAME_MAGICNO-16 "20971521.0000000000"
*MEAS_COND_AXIS_NAME_MAGICNO-17 "20971521.0000000000"
*MEAS_COND_AXIS_NAME_MAGICNO-18 "23068673.0000000000"
*MEAS_COND_AXIS_NAME_MAGICNO-19 "23068673.0000000000"
*MEAS_COND_AXIS_NAME_MAGICNO-20 "20971521.0000000000"
*MEAS_COND_AXIS_NAME_MAGICNO-21 "20971521.0000000000"
*MEAS_COND_AXIS_NAME_MAGICNO-22 "20971521.0000000000"
*MEAS_COND_AXIS_NAME_MAGICNO-23 "25165824.0000000000"
*MEAS_COND_AXIS_NAME_MAGICNO-24 "25165824.0000000000"
*MEAS_COND_AXIS_NAME_MAGICNO-25 "285343744.0000000000"
*MEAS_COND_AXIS_NAME_MAGICNO-26 "17301505.0000000000"
*MEAS_COND_AXIS_NAME_MAGICNO-27 "20971521.0000000000"
*MEAS_COND_AXIS_NAME_MAGICNO-28 "20971521.0000000000"
*MEAS_COND_AXIS_NAME_MAGICNO-29 "20971521.0000000000"
*MEAS_COND_AXIS_NAME_MAGICNO-30 "0.0000000000"
*MEAS_COND_AXIS_OFFSET-0 "-"
*MEAS_COND_AXIS_OFFSET-1 "-0.1081000000"
*MEAS_COND_AXIS_OFFSET-2 "0.3758000000"
*MEAS_COND_AXIS_OFFSET-3 "-"
*MEAS_COND_AXIS_OFFSET-4 "-"
*MEAS_COND_AXIS_OFFSET-5 "0.3758000000"
*MEAS_COND_AXIS_OFFSET-6 "-0.4839000000"
*MEAS_COND_AXIS_OFFSET-7 "-"
*MEAS_COND_AXIS_OFFSET-8 "-"
*MEAS_COND_AXIS_OFFSET-9 "-"
*MEAS_COND_AXIS_OFFSET-10 "-"
*MEAS_COND_AXIS_OFFSET-11 "-"
*MEAS_COND_AXIS_OFFSET-12 "-"
*MEAS_COND_AXIS_OFFSET-13 "-"
*MEAS_COND_AXIS_OFFSET-14 "-"
*MEAS_COND_AXIS_OFFSET-15 "-"
*MEAS_COND_AXIS_OFFSET-16 "-"
*MEAS_COND_AXIS_OFFSET-17 "-"
*MEAS_COND_AXIS_OFFSET-18 "-"
*MEAS_COND_AXIS_OFFSET-19 "-"
*MEAS_COND_AXIS_OFFSET-20 "-"
*MEAS_COND_AXIS_OFFSET-21 "-"
*MEAS_COND_AXIS_OFFSET-22 "-"
*MEAS_COND_AXIS_OFFSET-23 "-"
*MEAS_COND_AXIS_OFFSET-24 "-"
*MEAS_COND_AXIS_OFFSET-25 "-"
*MEAS_COND_AXIS_OFFSET-26 "-"
*MEAS_COND_AXIS_OFFSET-27 "-"
*MEAS_COND_AXIS_OFFSET-28 "-"
*MEAS_COND_AXIS_OFFSET-29 "-"
*MEAS_COND_AXIS_OFFSET-30 "-"
*MEAS_COND_AXIS_POSITION-0 "0.0000000000"
*MEAS_COND_AXIS_POSITION-1 "0.0000000000"
*MEAS_COND_AXIS_POSITION-2 "0.0000000000"
*MEAS_COND_AXIS_POSITION-3 "-0.5500000000"
*MEAS_COND_AXIS_POSITION-4 "0.0000000000"
*MEAS_COND_AXIS_POSITION-5 "0.0000000000"
*MEAS_COND_AXIS_POSITION-6 "0.0000000000"
*MEAS_COND_AXIS_POSITION-7 "-0.4278800000"
*MEAS_COND_AXIS_POSITION-8 "BB"
*MEAS_COND_AXIS_POSITION-9 "0.0000000000"
*MEAS_COND_AXIS_POSITION-10 "Soller_slit_5.0deg"
*MEAS_COND_AXIS_POSITION-11 "2/3deg"
*MEAS_COND_AXIS_POSITION-12 "2.2088000000"
*MEAS_COND_AXIS_POSITION-13 "-0.4140600000"
*MEAS_COND_AXIS_POSITION-14 "0.0000000000"
*MEAS_COND_AXIS_POSITION-15 "10.0mm"
*MEAS_COND_AXIS_POSITION-16 "None"
*MEAS_COND_AXIS_POSITION-17 "Cu_K-beta"
*MEAS_COND_AXIS_POSITION-18 "13.000mm"
*MEAS_COND_AXIS_POSITION-19 "13.000mm"
*MEAS_COND_AXIS_POSITION-20 "No_unit"
*MEAS_COND_AXIS_POSITION-21 "Soller_slit_5.0deg"
*MEAS_COND_AXIS_POSITION-22 "None"
*MEAS_COND_AXIS_POSITION-23 "13.0000000000"
*MEAS_COND_AXIS_POSITION-24 "13.0000000000"
*MEAS_COND_AXIS_POSITION-25 "0.0109400000"
*MEAS_COND_AXIS_POSITION-26 "Open"
*MEAS_COND_AXIS_POSITION-27 "None"
*MEAS_COND_AXIS_POSITION-28 "None"
*MEAS_COND_AXIS_POSITION-29 "None"
*MEAS_COND_AXIS_POSITION-30 "38.0000000000"
*MEAS_COND_AXIS_UNIT-0 "deg"
*MEAS_COND_AXIS_UNIT-1 "deg"
*MEAS_COND_AXIS_UNIT-2 "deg"
*MEAS_COND_AXIS_UNIT-3 "mm"
*MEAS_COND_AXIS_UNIT-4 "deg"
*MEAS_COND_AXIS_UNIT-5 "deg"
*MEAS_COND_AXIS_UNIT-6 "deg"
*MEAS_COND_AXIS_UNIT-7 "mm"
*MEAS_COND_AXIS_UNIT-8 ""
*MEAS_COND_AXIS_UNIT-9 "pulse"
*MEAS_COND_AXIS_UNIT-10 ""
*MEAS_COND_AXIS_UNIT-11 ""
*MEAS_COND_AXIS_UNIT-12 "mm"
*MEAS_COND_AXIS_UNIT-13 "mm"
*MEAS_COND_AXIS_UNIT-14 ""
*MEAS_COND_AXIS_UNIT-15 ""
*MEAS_COND_AXIS_UNIT-16 ""
*MEAS_COND_AXIS_UNIT-17 ""
*MEAS_COND_AXIS_UNIT-18 ""
*MEAS_COND_AXIS_UNIT-19 ""
*MEAS_COND_AXIS_UNIT-20 ""
*MEAS_COND_AXIS_UNIT-21 ""
*MEAS_COND_AXIS_UNIT-22 ""
*MEAS_COND_AXIS_UNIT-23 "mm"
*MEAS_COND_AXIS_UNIT-24 "mm"
*MEAS_COND_AXIS_UNIT-25 "mm"
*MEAS_COND_AXIS_UNIT-26 ""
*MEAS_COND_AXIS_UNIT-27 ""
*MEAS_COND_AXIS_UNIT-28 ""
*MEAS_COND_AXIS_UNIT-29 ""
*MEAS_COND_AXIS_UNIT-30 "div"
*MEAS_COND_COUNTER_CNTLOSS_CORR "0.0000000000"
*MEAS_COND_COUNTER_PHABASE "38.0000000000"
*MEAS_COND_COUNTER_PHAWINDOW "16.0000000000"
*MEAS_COND_COUNTER_PHA_UNIT "div"
*MEAS_COND_COUNTER_TAUDIFF "30.0000000000"
*MEAS_COND_COUNTER_TAUINT "0.0000000000"
*MEAS_COND_IRRADIATION_MODE "OFF"
*MEAS_COND_IRRADIATION_WIDTH ""
*MEAS_COND_OPT_ATTR "集中法"
*MEAS_COND_OPT_NAME "@集中法"
*MEAS_COND_UNSYMMETRIC_MODE "OFF"
*MEAS_COND_XG_CURRENT "30.0000000000"
*MEAS_COND_XG_VOLTAGE "40.0000000000"
*MEAS_COND_XG_WAVE_TYPE "Ka"
*MEAS_DATA_COUNT "3001.0000000000"
*MEAS_SCAN_AXIS_X "2θ/θ"
*MEAS_SCAN_AXIS_X_INTERNAL "TwoThetaTheta"
*MEAS_SCAN_END_TIME "09/02/20 15:22:29"
*MEAS_SCAN_MODE "CONTINUOUS"
*MEAS_SCAN_MONITOR "0"
*MEAS_SCAN_RESOLUTION_X "0.0002"
*MEAS_SCAN_SPEED "2.0"
*MEAS_SCAN_SPEED_UNIT "deg/min"
*MEAS_SCAN_START "20.0000000000"
*MEAS_SCAN_START_TIME "09/02/20 14:50:49"
*MEAS_SCAN_STEP "0.0200000000"
*MEAS_SCAN_STOP "80.0000000000"
*MEAS_SCAN_UNIT_X "deg"
*MEAS_SCAN_UNIT_Y "counts"
*RAS_HEADER_END
*RAS_INT_START
20.0000 1915.0000 1.0000
20.0600 1919.0000 1.0000
20.1200 1929.0000 1.0000
20.1800 1860.0000 1.0000
20.2400 1959.0000 1.0000
20.3000 1910.0000 1.0000
20.3600 1900.0000 1.0000
20.4200 1912.0000 1.0000
20.4800 1899.0000 1.0000
20.5400 1857.0000 1.0000
20.6000 1824.0000 1.0000
20.6600 1884.0000 1.0000
20.7200 1862.0000 1.0000
20.7800 1844.0000 1.0000
20.8400 1775.0000 1.0000
20.9000 1795.0000 1.0000
20.9600 1795.0000 1.0000
21.0200 1783.0000 1.0000
21.0800 1818.0000 1.0000
21.1400 1827.0000 1.0000
21.2000 1856.0000 1.0000
21.2600 1714.0000 1.0000
21.3200 1793.0000 1.0000
21.3800 1699.0000 1.0000
21.4400 1742.0000 1.0000
21.5000 1773.0000 1.0000
21.5600 1720.0000 1.0000
21.6200 1731.0000 1.0000
21.6800 1676.0000 1.0000
21.7400 1665.0000 1.0000
21.8000 1628.0000 1.0000
21.8600 1690.0000 1.0000
21.9200 1705.0000 1.0000
21.9800 1704.0000 1.0000
22.0400 1640.0000 1.0000
22.1000 1654.0000 1.0000
22.1600 1688.0000 1.0000
22.2200 1732.0000 1.0000
22.2800 1635.0000 1.0000
22.3400 1582.0000 1.0000
22.4000 1613.0000 1.0000
22.4600 1592.0000 1.0000
22.5200 1645.0000 1.0000
22.5800 1525.0000 1.0000
22.6400 1605.0000 1.0000
22.7000 1583.0000 1.0000
22.7600 1605.0000 1.0000
22.8200 1572.0000 1.0000
22.8800 1574.0000 1.0000
22.9400 1472.0000 1.0000
23.0000 1584.0000 1.0000
23.0600 1495.0000 1.0000
23.1200 1525.0000 1.0000
23.1800 1478.0000 1.0000
23.2400 1554.0000 1.0000
23.3000 1487.0000 1.0000
23.3600 1471.0000 1.0000
23.4200 1522.0000 1.0000
23.4800 1474.0000 1.0000
23.5400 1457.0000 1.0000
23.6000 1441.0000 1.0000
23.6600 1414.0000 1.0000
23.7200 1473.0000 1.0000
23.7800 1433.0000 1.0000
23.8400 1377.0000 1.0000
23.9000 1426.0000 1.0000
23.9600 1392.0000 1.0000
24.0200 1377.0000 1.0000
24.0800 1367.0000 1.0000
24.1400 1407.0000 1.0000
24.2000 1400.0000 1.0000
24.2600 1349.0000 1.0000
24.3200 1353.0000 1.0000
24.3800 1355.0000 1.0000
24.4400 1402.0000 1.0000
24.5000 1344.0000 1.0000
24.5600 1360.0000 1.0000
24.6200 1329.0000 1.0000
24.6800 1348.0000 1.0000
24.7400 1358.0000 1.0000
24.8000 1305.0000 1.0000
24.8600 1312.0000 1.0000
24.9200 1393.0000 1.0000
24.9800 1340.0000 1.0000
25.0400 1316.0000 1.0000
25.1000 1352.0000 1.0000
25.1600 1334.0000 1.0000
25.2200 1329.0000 1.0000
25.2800 1310.0000 1.0000
25.3400 1302.0000 1.0000
25.4000 1283.0000 1.0000
25.4600 1263.0000 1.0000
25.5200 1259.0000 1.0000
25.5800 1211.0000 1.0000
25.6400 1290.0000 1.0000
25.7000 1284.0000 1.0000
25.7600 1249.0000 1.0000
25.8200 1204.0000 1.0000
25.8800 1243.0000 1.0000
25.9400 1172.0000 1.0000
26.0000 1267.0000 1.0000
26.0600 1234.0000 1.0000
26.1200 1225.0000 1.0000
26.1800 1234.0000 1.0000
26.2400 1226.0000 1.0000
26.3000 1242.0000 1.0000
26.3600 1147.0000 1.0000
26.4200 1170.0000 1.0000
26.4800 1183.0000 1.0000
26.5400 1152.0000 1.0000
26.6000 1176.0000 1.0000
26.6600 1183.0000 1.0000
26.7200 1196.0000 1.0000
26.7800 1142.0000 1.0000
26.8400 1196.0000 1.0000
26.9000 1106.0000 1.0000
26.9600 1161.0000 1.0000
27.0200 1214.0000 1.0000
27.0800 1204.0000 1.0000
27.1400 1315.0000 1.0000
27.2000 1366.0000 1.0000
27.2600 1616.0000 1.0000
27.3200 1640.0000 1.0000
27.3800 1474.0000 1.0000
27.4400 1313.0000 1.0000
27.5000 1248.0000 1.0000
27.5600 1193.0000 1.0000
27.6200 1135.0000 1.0000
27.6800 1094.0000 1.0000
27.7400 1073.0000 1.0000
27.8000 1061.0000 1.0000
27.8600 1056.0000 1.0000
27.9200 1107.0000 1.0000
27.9800 1094.0000 1.0000
28.0400 1086.0000 1.0000
28.1000 1056.0000 1.0000
28.1600 1075.0000 1.0000
28.2200 1119.0000 1.0000
28.2800 1028.0000 1.0000
28.3400 1051.0000 1.0000
28.4000 940.0000 1.0000
28.4600 1009.0000 1.0000
28.5200 1055.0000 1.0000
28.5800 1029.0000 1.0000
28.6400 976.0000 1.0000
28.7000 971.0000 1.0000
28.7600 982.0000 1.0000
28.8200 1012.0000 1.0000
28.8800 973.0000 1.0000
28.9400 949.0000 1.0000
29.0000 969.0000 1.0000
29.0600 979.0000 1.0000
29.1200 937.0000 1.0000
29.1800 963.0000 1.0000
29.2400 938.0000 1.0000
29.3000 980.0000 1.0000
29.3600 964.0000 1.0000
29.4200 942.0000 1.0000
29.4800 957.0000 1.0000
29.5400 954.0000 1.0000
29.6000 951.0000 1.0000
29.6600 1004.0000 1.0000
29.7200 957.0000 1.0000
29.7800 948.0000 1.0000
29.8400 909.0000 1.0000
29.9000 910.0000 1.0000
29.9600 909.0000 1.0000
30.0200 876.0000 1.0000
30.0800 880.0000 1.0000
30.1400 901.0000 1.0000
30.2000 916.0000 1.0000
30.2600 925.0000 1.0000
30.3200 860.0000 1.0000
30.3800 850.0000 1.0000
30.4400 863.0000 1.0000
30.5000 862.0000 1.0000
30.5600 835.0000 1.0000
30.6200 838.0000 1.0000
30.6800 825.0000 1.0000
30.7400 832.0000 1.0000
30.8000 852.0000 1.0000
30.8600 876.0000 1.0000
30.9200 813.0000 1.0000
30.9800 873.0000 1.0000
31.0400 880.0000 1.0000
31.1000 846.0000 1.0000
31.1600 827.0000 1.0000
31.2200 820.0000 1.0000
31.2800 837.0000 1.0000
31.3400 792.0000 1.0000
31.4000 832.0000 1.0000
31.4600 805.0000 1.0000
31.5200 796.0000 1.0000
31.5800 815.0000 1.0000
31.6400 806.0000 1.0000
31.7000 805.0000 1.0000
31.7600 823.0000 1.0000
31.8200 791.0000 1.0000
31.8800 848.0000 1.0000
31.9400 833.0000 1.0000
32.0000 796.0000 1.0000
32.0600 815.0000 1.0000
32.1200 795.0000 1.0000
32.1800 797.0000 1.0000
32.2400 766.0000 1.0000
32.3000 747.0000 1.0000
32.3600 762.0000 1.0000
32.4200 742.0000 1.0000
32.4800 762.0000 1.0000
32.5400 742.0000 1.0000
32.6000 767.0000 1.0000
32.6600 749.0000 1.0000
32.7200 776.0000 1.0000
32.7800 761.0000 1.0000
32.8400 721.0000 1.0000
32.9000 771.0000 1.0000
32.9600 721.0000 1.0000
33.0200 730.0000 1.0000
33.0800 746.0000 1.0000
33.1400 747.0000 1.0000
33.2000 737.0000 1.0000
33.2600 747.0000 1.0000
33.3200 732.0000 1.0000
33.3800 734.0000 1.0000
33.4400 752.0000 1.0000
33.5000 691.0000 1.0000
33.5600 695.0000 1.0000
33.6200 683.0000 1.0000
33.6800 724.0000 1.0000
33.7400 739.0000 1.0000
33.8000 687.0000 1.0000
33.8600 749.0000 1.0000
33.9200 730.0000 1.0000
33.9800 750.0000 1.0000
34.0400 675.0000 1.0000
34.1000 732.0000 1.0000
34.1600 759.0000 1.0000
34.2200 718.0000 1.0000
34.2800 735.0000 1.0000
34.3400 797.0000 1.0000
34.4000 916.0000 1.0000
34.4600 978.0000 1.0000
34.5200 941.0000 1.0000
34.5800 861.0000 1.0000
34.6400 771.0000 1.0000
34.7000 776.0000 1.0000
34.7600 726.0000 1.0000
34.8200 645.0000 1.0000
34.8800 633.0000 1.0000
34.9400 661.0000 1.0000
35.0000 679.0000 1.0000
35.0600 601.0000 1.0000
35.1200 678.0000 1.0000
35.1800 661.0000 1.0000
35.2400 669.0000 1.0000
35.3000 621.0000 1.0000
35.3600 613.0000 1.0000
35.4200 600.0000 1.0000
35.4800 612.0000 1.0000
35.5400 664.0000 1.0000
35.6000 637.0000 1.0000
35.6600 618.0000 1.0000
35.7200 605.0000 1.0000
35.7800 638.0000 1.0000
35.8400 634.0000 1.0000
35.9000 592.0000 1.0000
35.9600 574.0000 1.0000
36.0200 576.0000 1.0000
36.0800 606.0000 1.0000
36.1400 601.0000 1.0000
36.2000 629.0000 1.0000
36.2600 700.0000 1.0000
36.3200 689.0000 1.0000
36.3800 717.0000 1.0000
36.4400 702.0000 1.0000
36.5000 721.0000 1.0000
36.5600 646.0000 1.0000
36.6200 622.0000 1.0000
36.6800 567.0000 1.0000
36.7400 559.0000 1.0000
36.8000 554.0000 1.0000
36.8600 546.0000 1.0000
36.9200 576.0000 1.0000
36.9800 567.0000 1.0000
37.0400 606.0000 1.0000
37.1000 574.0000 1.0000
37.1600 521.0000 1.0000
37.2200 536.0000 1.0000
37.2800 551.0000 1.0000
37.3400 540.0000 1.0000
37.4000 558.0000 1.0000
37.4600 516.0000 1.0000
37.5200 571.0000 1.0000
37.5800 540.0000 1.0000
37.6400 520.0000 1.0000
37.7000 553.0000 1.0000
37.7600 545.0000 1.0000
37.8200 505.0000 1.0000
37.8800 526.0000 1.0000
37.9400 533.0000 1.0000
38.0000 506.0000 1.0000
38.0600 514.0000 1.0000
38.1200 546.0000 1.0000
38.1800 568.0000 1.0000
38.2400 582.0000 1.0000
38.3000 614.0000 1.0000
38.3600 720.0000 1.0000
38.4200 915.0000 1.0000
38.4800 1140.0000 1.0000
38.5400 1216.0000 1.0000
38.6000 1111.0000 1.0000
38.6600 869.0000 1.0000
38.7200 746.0000 1.0000
38.7800 585.0000 1.0000
38.8400 569.0000 1.0000
38.9000 504.0000 1.0000
38.9600 520.0000 1.0000
39.0200 535.0000 1.0000
39.0800 522.0000 1.0000
39.1400 488.0000 1.0000
39.2000 518.0000 1.0000
39.2600 504.0000 1.0000
39.3200 476.0000 1.0000
39.3800 528.0000 1.0000
39.4400 526.0000 1.0000
39.5000 481.0000 1.0000
39.5600 498.0000 1.0000
39.6200 474.0000 1.0000
39.6800 527.0000 1.0000
39.7400 449.0000 1.0000
39.8000 493.0000 1.0000
39.8600 421.0000 1.0000
39.9200 457.0000 1.0000
39.9800 447.0000 1.0000
40.0400 463.0000 1.0000
40.1000 457.0000 1.0000
40.1600 492.0000 1.0000
40.2200 465.0000 1.0000
40.2800 436.0000 1.0000
40.3400 455.0000 1.0000
40.4000 441.0000 1.0000
40.4600 481.0000 1.0000
40.5200 440.0000 1.0000
40.5800 449.0000 1.0000
40.6400 419.0000 1.0000
40.7000 456.0000 1.0000
40.7600 435.0000 1.0000
40.8200 469.0000 1.0000
40.8800 443.0000 1.0000
40.9400 451.0000 1.0000
41.0000 423.0000 1.0000
41.0600 425.0000 1.0000
41.1200 451.0000 1.0000
41.1800 420.0000 1.0000
41.2400 413.0000 1.0000
41.3000 447.0000 1.0000
41.3600 414.0000 1.0000
41.4200 396.0000 1.0000
41.4800 412.0000 1.0000
41.5400 430.0000 1.0000
41.6000 435.0000 1.0000
41.6600 421.0000 1.0000
41.7200 444.0000 1.0000
41.7800 453.0000 1.0000
41.8400 432.0000 1.0000
41.9000 419.0000 1.0000
41.9600 431.0000 1.0000
42.0200 414.0000 1.0000
42.0800 413.0000 1.0000
42.1400 433.0000 1.0000
42.2000 404.0000 1.0000
42.2600 414.0000 1.0000
42.3200 409.0000 1.0000
42.3800 396.0000 1.0000
42.4400 412.0000 1.0000
42.5000 401.0000 1.0000
42.5600 393.0000 1.0000
42.6200 441.0000 1.0000
42.6800 378.0000 1.0000
42.7400 420.0000 1.0000
42.8000 439.0000 1.0000
42.8600 390.0000 1.0000
42.9200 403.0000 1.0000
42.9800 401.0000 1.0000
43.0400 383.0000 1.0000
43.1000 397.0000 1.0000
43.1600 406.0000 1.0000
43.2200 420.0000 1.0000
43.2800 404.0000 1.0000
43.3400 421.0000 1.0000
43.4000 414.0000 1.0000
43.4600 410.0000 1.0000
43.5200 384.0000 1.0000
43.5800 389.0000 1.0000
43.6400 378.0000 1.0000
43.7000 368.0000 1.0000
43.7600 353.0000 1.0000
43.8200 420.0000 1.0000
43.8800 382.0000 1.0000
43.9400 417.0000 1.0000
44.0000 391.0000 1.0000
44.0600 343.0000 1.0000
44.1200 374.0000 1.0000
44.1800 394.0000 1.0000
44.2400 385.0000 1.0000
44.3000 391.0000 1.0000
44.3600 407.0000 1.0000
44.4200 364.0000 1.0000
44.4800 351.0000 1.0000
44.5400 395.0000 1.0000
44.6000 376.0000 1.0000
44.6600 378.0000 1.0000
44.7200 349.0000 1.0000
44.7800 359.0000 1.0000
44.8400 384.0000 1.0000
44.9000 366.0000 1.0000
44.9600 350.0000 1.0000
45.0200 332.0000 1.0000
45.0800 366.0000 1.0000
45.1400 343.0000 1.0000
45.2000 377.0000 1.0000
45.2600 368.0000 1.0000
45.3200 388.0000 1.0000
45.3800 354.0000 1.0000
45.4400 356.0000 1.0000
45.5000 335.0000 1.0000
45.5600 352.0000 1.0000
45.6200 348.0000 1.0000
45.6800 376.0000 1.0000
45.7400 361.0000 1.0000
45.8000 363.0000 1.0000
45.8600 358.0000 1.0000
45.9200 354.0000 1.0000
45.9800 371.0000 1.0000
46.0400 335.0000 1.0000
46.1000 350.0000 1.0000
46.1600 339.0000 1.0000
46.2200 319.0000 1.0000
46.2800 353.0000 1.0000
46.3400 327.0000 1.0000
46.4000 342.0000 1.0000
46.4600 373.0000 1.0000
46.5200 343.0000 1.0000
46.5800 346.0000 1.0000
46.6400 303.0000 1.0000
46.7000 383.0000 1.0000
46.7600 308.0000 1.0000
46.8200 385.0000 1.0000
46.8800 333.0000 1.0000
46.9400 351.0000 1.0000
47.0000 374.0000 1.0000
47.0600 325.0000 1.0000
47.1200 334.0000 1.0000
47.1800 356.0000 1.0000
47.2400 337.0000 1.0000
47.3000 325.0000 1.0000
47.3600 328.0000 1.0000
47.4200 335.0000 1.0000
47.4800 357.0000 1.0000
47.5400 322.0000 1.0000
47.6000 326.0000 1.0000
47.6600 352.0000 1.0000
47.7200 308.0000 1.0000
47.7800 365.0000 1.0000
47.8400 352.0000 1.0000
47.9000 349.0000 1.0000
47.9600 336.0000 1.0000
48.0200 310.0000 1.0000
48.0800 349.0000 1.0000
48.1400 316.0000 1.0000
48.2000 329.0000 1.0000
48.2600 308.0000 1.0000
48.3200 313.0000 1.0000
48.3800 334.0000 1.0000
48.4400 317.0000 1.0000
48.5000 341.0000 1.0000
48.5600 353.0000 1.0000
48.6200 295.0000 1.0000
48.6800 352.0000 1.0000
48.7400 336.0000 1.0000
48.8000 329.0000 1.0000
48.8600 330.0000 1.0000
48.9200 316.0000 1.0000
48.9800 329.0000 1.0000
49.0400 319.0000 1.0000
49.1000 304.0000 1.0000
49.1600 308.0000 1.0000
49.2200 356.0000 1.0000
49.2800 322.0000 1.0000
49.3400 358.0000 1.0000
49.4000 326.0000 1.0000
49.4600 312.0000 1.0000
49.5200 315.0000 1.0000
49.5800 298.0000 1.0000
49.6400 308.0000 1.0000
49.7000 327.0000 1.0000
49.7600 317.0000 1.0000
49.8200 311.0000 1.0000
49.8800 303.0000 1.0000
49.9400 328.0000 1.0000
50.0000 305.0000 1.0000
50.0600 325.0000 1.0000
50.1200 328.0000 1.0000
50.1800 317.0000 1.0000
50.2400 328.0000 1.0000
50.3000 317.0000 1.0000
50.3600 309.0000 1.0000
50.4200 325.0000 1.0000
50.4800 321.0000 1.0000
50.5400 315.0000 1.0000
50.6000 286.0000 1.0000
50.6600 313.0000 1.0000
50.7200 286.0000 1.0000
50.7800 323.0000 1.0000
50.8400 336.0000 1.0000
50.9000 335.0000 1.0000
50.9600 294.0000 1.0000
51.0200 312.0000 1.0000
51.0800 333.0000 1.0000
51.1400 305.0000 1.0000
51.2000 296.0000 1.0000
51.2600 313.0000 1.0000
51.3200 296.0000 1.0000
51.3800 336.0000 1.0000
51.4400 280.0000 1.0000
51.5000 295.0000 1.0000
51.5600 319.0000 1.0000
51.6200 326.0000 1.0000
51.6800 329.0000 1.0000
51.7400 329.0000 1.0000
51.8000 330.0000 1.0000
51.8600 331.0000 1.0000
51.9200 324.0000 1.0000
51.9800 375.0000 1.0000
52.0400 459.0000 1.0000
52.1000 609.0000 1.0000
52.1600 891.0000 1.0000
52.2200 1363.0000 1.0000
52.2800 1397.0000 1.0000
52.3400 1226.0000 1.0000
52.4000 1088.0000 1.0000
52.4600 750.0000 1.0000
52.5200 549.0000 1.0000
52.5800 494.0000 1.0000
52.6400 419.0000 1.0000
52.7000 361.0000 1.0000
52.7600 352.0000 1.0000
52.8200 368.0000 1.0000
52.8800 374.0000 1.0000
52.9400 344.0000 1.0000
53.0000 348.0000 1.0000
53.0600 339.0000 1.0000
53.1200 335.0000 1.0000
53.1800 304.0000 1.0000
53.2400 313.0000 1.0000
53.3000 327.0000 1.0000
53.3600 294.0000 1.0000
53.4200 326.0000 1.0000
53.4800 303.0000 1.0000
53.5400 316.0000 1.0000
53.6000 287.0000 1.0000
53.6600 282.0000 1.0000
53.7200 321.0000 1.0000
53.7800 290.0000 1.0000
53.8400 283.0000 1.0000
53.9000 279.0000 1.0000
53.9600 283.0000 1.0000
54.0200 281.0000 1.0000
54.0800 277.0000 1.0000
54.1400 292.0000 1.0000
54.2000 314.0000 1.0000
54.2600 306.0000 1.0000
54.3200 283.0000 1.0000
54.3800 334.0000 1.0000
54.4400 289.0000 1.0000
54.5000 321.0000 1.0000
54.5600 298.0000 1.0000
54.6200 297.0000 1.0000
54.6800 310.0000 1.0000
54.7400 325.0000 1.0000
54.8000 305.0000 1.0000
54.8600 315.0000 1.0000
54.9200 302.0000 1.0000
54.9800 294.0000 1.0000
55.0400 340.0000 1.0000
55.1000 335.0000 1.0000
55.1600 364.0000 1.0000
55.2200 367.0000 1.0000
55.2800 389.0000 1.0000
55.3400 380.0000 1.0000
55.4000 361.0000 1.0000
55.4600 361.0000 1.0000
55.5200 309.0000 1.0000
55.5800 321.0000 1.0000
55.6400 292.0000 1.0000
55.7000 286.0000 1.0000
55.7600 305.0000 1.0000
55.8200 292.0000 1.0000
55.8800 265.0000 1.0000
55.9400 278.0000 1.0000
56.0000 299.0000 1.0000
56.0600 297.0000 1.0000
56.1200 308.0000 1.0000
56.1800 261.0000 1.0000
56.2400 284.0000 1.0000
56.3000 265.0000 1.0000
56.3600 284.0000 1.0000
56.4200 285.0000 1.0000
56.4800 309.0000 1.0000
56.5400 297.0000 1.0000
56.6000 296.0000 1.0000
56.6600 260.0000 1.0000
56.7200 300.0000 1.0000
56.7800 310.0000 1.0000
56.8400 281.0000 1.0000
56.9000 285.0000 1.0000
56.9600 297.0000 1.0000
57.0200 283.0000 1.0000
57.0800 295.0000 1.0000
57.1400 290.0000 1.0000
57.2000 303.0000 1.0000
57.2600 287.0000 1.0000
57.3200 292.0000 1.0000
57.3800 287.0000 1.0000
57.4400 284.0000 1.0000
57.5000 299.0000 1.0000
57.5600 308.0000 1.0000
57.6200 271.0000 1.0000
57.6800 302.0000 1.0000
57.7400 273.0000 1.0000
57.8000 292.0000 1.0000
57.8600 291.0000 1.0000
57.9200 280.0000 1.0000
57.9800 271.0000 1.0000
58.0400 268.0000 1.0000
58.1000 275.0000 1.0000
58.1600 285.0000 1.0000
58.2200 299.0000 1.0000
58.2800 274.0000 1.0000
58.3400 319.0000 1.0000
58.4000 303.0000 1.0000
58.4600 276.0000 1.0000
58.5200 264.0000 1.0000
58.5800 259.0000 1.0000
58.6400 267.0000 1.0000
58.7000 272.0000 1.0000
58.7600 269.0000 1.0000
58.8200 277.0000 1.0000
58.8800 282.0000 1.0000
58.9400 283.0000 1.0000
59.0000 267.0000 1.0000
59.0600 300.0000 1.0000
59.1200 283.0000 1.0000
59.1800 296.0000 1.0000
59.2400 266.0000 1.0000
59.3000 286.0000 1.0000
59.3600 265.0000 1.0000
59.4200 268.0000 1.0000
59.4800 284.0000 1.0000
59.5400 303.0000 1.0000
59.6000 260.0000 1.0000
59.6600 297.0000 1.0000
59.7200 302.0000 1.0000
59.7800 302.0000 1.0000
59.8400 268.0000 1.0000
59.9000 282.0000 1.0000
59.9600 253.0000 1.0000
60.0200 279.0000 1.0000
60.0800 270.0000 1.0000
60.1400 260.0000 1.0000
60.2000 292.0000 1.0000
60.2600 301.0000 1.0000
60.3200 267.0000 1.0000
60.3800 242.0000 1.0000
60.4400 252.0000 1.0000
60.5000 282.0000 1.0000
60.5600 297.0000 1.0000
60.6200 271.0000 1.0000
60.6800 261.0000 1.0000
60.7400 258.0000 1.0000
60.8000 260.0000 1.0000
60.8600 284.0000 1.0000
60.9200 301.0000 1.0000
60.9800 312.0000 1.0000
61.0400 259.0000 1.0000
61.1000 288.0000 1.0000
61.1600 289.0000 1.0000
61.2200 258.0000 1.0000
61.2800 269.0000 1.0000
61.3400 296.0000 1.0000
61.4000 284.0000 1.0000
61.4600 282.0000 1.0000
61.5200 288.0000 1.0000
61.5800 279.0000 1.0000
61.6400 284.0000 1.0000
61.7000 300.0000 1.0000
61.7600 294.0000 1.0000
61.8200 297.0000 1.0000
61.8800 319.0000 1.0000
61.9400 304.0000 1.0000
62.0000 324.0000 1.0000
62.0600 380.0000 1.0000
62.1200 410.0000 1.0000
62.1800 455.0000 1.0000
62.2400 482.0000 1.0000
62.3000 511.0000 1.0000
62.3600 536.0000 1.0000
62.4200 463.0000 1.0000
62.4800 436.0000 1.0000
62.5400 396.0000 1.0000
62.6000 372.0000 1.0000
62.6600 359.0000 1.0000
62.7200 346.0000 1.0000
62.7800 331.0000 1.0000
62.8400 317.0000 1.0000
62.9000 299.0000 1.0000
62.9600 297.0000 1.0000
63.0200 270.0000 1.0000
63.0800 296.0000 1.0000
63.1400 325.0000 1.0000
63.2000 282.0000 1.0000
63.2600 279.0000 1.0000
63.3200 293.0000 1.0000
63.3800 313.0000 1.0000
63.4400 306.0000 1.0000
63.5000 289.0000 1.0000
63.5600 268.0000 1.0000
63.6200 312.0000 1.0000
63.6800 319.0000 1.0000
63.7400 276.0000 1.0000
63.8000 290.0000 1.0000
63.8600 289.0000 1.0000
63.9200 279.0000 1.0000
63.9800 267.0000 1.0000
64.0400 301.0000 1.0000
64.1000 274.0000 1.0000
64.1600 281.0000 1.0000
64.2200 300.0000 1.0000
64.2800 284.0000 1.0000
64.3400 297.0000 1.0000
64.4000 319.0000 1.0000
64.4600 316.0000 1.0000
64.5200 322.0000 1.0000
64.5800 346.0000 1.0000
64.6400 373.0000 1.0000
64.7000 380.0000 1.0000
64.7600 328.0000 1.0000
64.8200 348.0000 1.0000
64.8800 366.0000 1.0000
64.9400 321.0000 1.0000
65.0000 290.0000 1.0000
65.0600 326.0000 1.0000
65.1200 293.0000 1.0000
65.1800 298.0000 1.0000
65.2400 326.0000 1.0000
65.3000 306.0000 1.0000
65.3600 290.0000 1.0000
65.4200 278.0000 1.0000
65.4800 277.0000 1.0000
65.5400 305.0000 1.0000
65.6000 288.0000 1.0000
65.6600 291.0000 1.0000
65.7200 319.0000 1.0000
65.7800 330.0000 1.0000
65.8400 329.0000 1.0000
65.9000 380.0000 1.0000
65.9600 393.0000 1.0000
66.0200 400.0000 1.0000
66.0800 538.0000 1.0000
66.1400 706.0000 1.0000
66.2000 893.0000 1.0000
66.2600 851.0000 1.0000
66.3200 859.0000 1.0000
66.3800 754.0000 1.0000
66.4400 663.0000 1.0000
66.5000 554.0000 1.0000
66.5600 482.0000 1.0000
66.6200 393.0000 1.0000
66.6800 344.0000 1.0000
66.7400 331.0000 1.0000
66.8000 332.0000 1.0000
66.8600 306.0000 1.0000
66.9200 294.0000 1.0000
66.9800 302.0000 1.0000
67.0400 284.0000 1.0000
67.1000 282.0000 1.0000
67.1600 301.0000 1.0000
67.2200 289.0000 1.0000
67.2800 286.0000 1.0000
67.3400 269.0000 1.0000
67.4000 284.0000 1.0000
67.4600 310.0000 1.0000
67.5200 273.0000 1.0000
67.5800 278.0000 1.0000
67.6400 274.0000 1.0000
67.7000 287.0000 1.0000
67.7600 303.0000 1.0000
67.8200 280.0000 1.0000
67.8800 286.0000 1.0000
67.9400 251.0000 1.0000
68.0000 279.0000 1.0000
68.0600 288.0000 1.0000
68.1200 277.0000 1.0000
68.1800 299.0000 1.0000
68.2400 274.0000 1.0000
68.3000 274.0000 1.0000
68.3600 258.0000 1.0000
68.4200 260.0000 1.0000
68.4800 294.0000 1.0000
68.5400 266.0000 1.0000
68.6000 272.0000 1.0000
68.6600 249.0000 1.0000
68.7200 264.0000 1.0000
68.7800 232.0000 1.0000
68.8400 273.0000 1.0000
68.9000 257.0000 1.0000
68.9600 256.0000 1.0000
69.0200 265.0000 1.0000
69.0800 267.0000 1.0000
69.1400 272.0000 1.0000
69.2000 266.0000 1.0000
69.2600 281.0000 1.0000
69.3200 266.0000 1.0000
69.3800 276.0000 1.0000
69.4400 263.0000 1.0000
69.5000 282.0000 1.0000
69.5600 262.0000 1.0000
69.6200 255.0000 1.0000
69.6800 254.0000 1.0000
69.7400 245.0000 1.0000
69.8000 277.0000 1.0000
69.8600 268.0000 1.0000
69.9200 262.0000 1.0000
69.9800 271.0000 1.0000
70.0400 266.0000 1.0000
70.1000 249.0000 1.0000
70.1600 257.0000 1.0000
70.2200 266.0000 1.0000
70.2800 242.0000 1.0000
70.3400 263.0000 1.0000
70.4000 287.0000 1.0000
70.4600 263.0000 1.0000
70.5200 278.0000 1.0000
70.5800 249.0000 1.0000
70.6400 278.0000 1.0000
70.7000 248.0000 1.0000
70.7600 267.0000 1.0000
70.8200 277.0000 1.0000
70.8800 252.0000 1.0000
70.9400 263.0000 1.0000
71.0000 269.0000 1.0000
71.0600 248.0000 1.0000
71.1200 247.0000 1.0000
71.1800 267.0000 1.0000
71.2400 302.0000 1.0000
71.3000 263.0000 1.0000
71.3600 279.0000 1.0000
71.4200 288.0000 1.0000
71.4800 304.0000 1.0000
71.5400 304.0000 1.0000
71.6000 298.0000 1.0000
71.6600 283.0000 1.0000
71.7200 278.0000 1.0000
71.7800 267.0000 1.0000
71.8400 290.0000 1.0000
71.9000 264.0000 1.0000
71.9600 252.0000 1.0000
72.0200 268.0000 1.0000
72.0800 234.0000 1.0000
72.1400 270.0000 1.0000
72.2000 269.0000 1.0000
72.2600 248.0000 1.0000
72.3200 264.0000 1.0000
72.3800 240.0000 1.0000
72.4400 277.0000 1.0000
72.5000 249.0000 1.0000
72.5600 249.0000 1.0000
72.6200 268.0000 1.0000
72.6800 243.0000 1.0000
72.7400 259.0000 1.0000
72.8000 264.0000 1.0000
72.8600 256.0000 1.0000
72.9200 235.0000 1.0000
72.9800 226.0000 1.0000
73.0400 270.0000 1.0000
73.1000 253.0000 1.0000
73.1600 277.0000 1.0000
73.2200 245.0000 1.0000
73.2800 247.0000 1.0000
73.3400 269.0000 1.0000
73.4000 245.0000 1.0000
73.4600 254.0000 1.0000
73.5200 271.0000 1.0000
73.5800 283.0000 1.0000
73.6400 246.0000 1.0000
73.7000 236.0000 1.0000
73.7600 262.0000 1.0000
73.8200 254.0000 1.0000
73.8800 232.0000 1.0000
73.9400 246.0000 1.0000
74.0000 221.0000 1.0000
74.0600 278.0000 1.0000
74.1200 271.0000 1.0000
74.1800 255.0000 1.0000
74.2400 285.0000 1.0000
74.3000 246.0000 1.0000
74.3600 264.0000 1.0000
74.4200 252.0000 1.0000
74.4800 234.0000 1.0000
74.5400 229.0000 1.0000
74.6000 256.0000 1.0000
74.6600 229.0000 1.0000
74.7200 241.0000 1.0000
74.7800 256.0000 1.0000
74.8400 262.0000 1.0000
74.9000 253.0000 1.0000
74.9600 239.0000 1.0000
75.0200 226.0000 1.0000
75.0800 228.0000 1.0000
75.1400 246.0000 1.0000
75.2000 250.0000 1.0000
75.2600 240.0000 1.0000
75.3200 271.0000 1.0000
75.3800 268.0000 1.0000
75.4400 276.0000 1.0000
75.5000 246.0000 1.0000
75.5600 276.0000 1.0000
75.6200 272.0000 1.0000
75.6800 233.0000 1.0000
75.7400 252.0000 1.0000
75.8000 251.0000 1.0000
75.8600 230.0000 1.0000
75.9200 223.0000 1.0000
75.9800 259.0000 1.0000
76.0400 254.0000 1.0000
76.1000 236.0000 1.0000
76.1600 265.0000 1.0000
76.2200 233.0000 1.0000
76.2800 246.0000 1.0000
76.3400 281.0000 1.0000
76.4000 290.0000 1.0000
76.4600 239.0000 1.0000
76.5200 269.0000 1.0000
76.5800 258.0000 1.0000
76.6400 247.0000 1.0000
76.7000 244.0000 1.0000
76.7600 266.0000 1.0000
76.8200 248.0000 1.0000
76.8800 263.0000 1.0000
76.9400 251.0000 1.0000
77.0000 259.0000 1.0000
77.0600 244.0000 1.0000
77.1200 265.0000 1.0000
77.1800 229.0000 1.0000
77.2400 239.0000 1.0000
77.3000 274.0000 1.0000
77.3600 238.0000 1.0000
77.4200 241.0000 1.0000
77.4800 272.0000 1.0000
77.5400 256.0000 1.0000
77.6000 230.0000 1.0000
77.6600 252.0000 1.0000
77.7200 243.0000 1.0000
77.7800 269.0000 1.0000
77.8400 252.0000 1.0000
77.9000 246.0000 1.0000
77.9600 234.0000 1.0000
78.0200 266.0000 1.0000
78.0800 223.0000 1.0000
78.1400 247.0000 1.0000
78.2000 250.0000 1.0000
78.2600 270.0000 1.0000
78.3200 241.0000 1.0000
78.3800 255.0000 1.0000
78.4400 246.0000 1.0000
78.5000 248.0000 1.0000
78.5600 243.0000 1.0000
78.6200 263.0000 1.0000
78.6800 281.0000 1.0000
78.7400 279.0000 1.0000
78.8000 306.0000 1.0000
78.8600 356.0000 1.0000
78.9200 397.0000 1.0000
78.9800 400.0000 1.0000
79.0400 357.0000 1.0000
79.1000 329.0000 1.0000
79.1600 331.0000 1.0000
79.2200 317.0000 1.0000
79.2800 325.0000 1.0000
79.3400 283.0000 1.0000
79.4000 277.0000 1.0000
79.4600 271.0000 1.0000
79.5200 265.0000 1.0000
79.5800 237.0000 1.0000
79.6400 283.0000 1.0000
79.7000 267.0000 1.0000
79.7600 269.0000 1.0000
79.8200 233.0000 1.0000
79.8800 274.0000 1.0000
79.9400 214.0000 1.0000
80.0000 253.0000 1.0000
*RAS_INT_END
*RAS_TEMPERATURE_START
*RAS_TEMPERATURE_END
*RAS_DATA_END