File: Section2_75_samples/XRD/No_050_NSS1_2.ras
*RAS_DATA_START
*RAS_HEADER_START
*DISP_FMT_X "%.2f"
*DISP_FMT_Y "%.0f"
*DISP_FULLSCALE "15334.0000000000"
*DISP_LINE_COLOR "255.0000000000"
*DISP_LINE_STYLE "0.0000000000"
*DISP_LINE_WIDTH "0.2500000000"
*DISP_NOTE "測定データ-7"
*DISP_OFFSET_Y "0.0000000000"
*DISP_PEAKSEARCH_UNIT_Y "cps"
*DISP_RANGE_BOTTOM "0.0000000000"
*DISP_RANGE_LEFT "20.0000000000"
*DISP_RANGE_LOGCUTOFF "0.0100000000"
*DISP_RANGE_RIGHT "70.0000000000"
*DISP_RANGE_TOP "15334.0000000000"
*DISP_SCALE_MODE_Y "0.0000000000"
*DISP_TAB_NAME "2θ/θ"
*DISP_TITLE_Y "強度"
*DISP_UNIT_Y "cps"
*DISP_WINDOW_NAME "MSG_MACROENGINE"
*FILE_COMMENT " "
*FILE_MD5 ""
*FILE_MEMO " "
*FILE_OPERATOR "Administrator"
*FILE_SAMPLE " "
*FILE_TYPE "RAS_RAW"
*FILE_USERGROUP "システムマネージャ"
*FILE_VERSION "1.0000000000"
*HW_ATTACHMENT_ID "ATT0025"
*HW_ATTACHMENT_NAME "標準|Standard"
*HW_COUNTER_ID-0 "CUT0025"
*HW_COUNTER_ID-1 "CUT0020"
*HW_COUNTER_ID-2 "CUT0020"
*HW_COUNTER_ID-3 "CSL0021"
*HW_COUNTER_ID-4 "CMC0021"
*HW_COUNTER_NAME-0 "D/teX Ultra|D/teX Ultra"
*HW_COUNTER_NAME-1 "None|None"
*HW_COUNTER_NAME-2 "None|None"
*HW_COUNTER_NAME-3 "BBM|BBM"
*HW_COUNTER_NAME-4 "検出器モノクロメータ|Detector monochromator"
*HW_COUNTER_SELECT_NAME "D/teX Ultra|D/teX Ultra"
*HW_GONIOMETER_ID "GON0023"
*HW_GONIOMETER_NAME "SmartLab|SmartLab"
*HW_GONIOMETER_RADIUS-0 "90.0"
*HW_GONIOMETER_RADIUS-1 "114.0"
*HW_GONIOMETER_RADIUS-2 "190.0"
*HW_GONIOMETER_RADIUS-3 "300.0"
*HW_GONIOMETER_RADIUS-4 "187.0"
*HW_GONIOMETER_RADIUS-5 "300.0"
*HW_GONIOMETER_RADIUS-6 "113.0"
*HW_GONIOMETER_RADIUS-7 "331.0"
*HW_I_OPT_ID-0 "CBO0021"
*HW_I_OPT_ID-1 "ICR0023"
*HW_I_OPT_ID-2 "ISL0021"
*HW_I_OPT_ID-3 "ISO0021"
*HW_I_OPT_ID-4 "IAD0021"
*HW_I_OPT_ID-5 "IPR0001"
*HW_I_OPT_NAME-0 "CBOユニット|CBO unit"
*HW_I_OPT_NAME-1 "標準入射光学ユニット|Standard incident optical unit"
*HW_I_OPT_NAME-2 "標準入射スリットボックス|Standard incident slit box"
*HW_I_OPT_NAME-3 "入射平行スリット|Incident parallel slit"
*HW_I_OPT_NAME-4 "長手制限スリット|Length limiting slit"
*HW_I_OPT_NAME-5 "None|None"
*HW_R_ATTENUATER_AUTOMODE "0"
*HW_R_OPT_ID-0 "RSS0021"
*HW_R_OPT_ID-1 "RCR0023"
*HW_R_OPT_ID-2 "RSO0021"
*HW_R_OPT_ID-3 "RRS0021"
*HW_R_OPT_ID-4 "ATN0021"
*HW_R_OPT_ID-5 "RFL0021"
*HW_R_OPT_ID-6 "RAD0021"
*HW_R_OPT_NAME-0 "標準受光スリットボックス1|Standard receiving slit box # 1"
*HW_R_OPT_NAME-1 "標準受光光学ユニット1|Standard receiving unit # 1"
*HW_R_OPT_NAME-2 "標準受光光学ユニット2|Standard receiving optical unit # 2"
*HW_R_OPT_NAME-3 "標準受光スリットボックス2|Standard receiving slit box # 2"
*HW_R_OPT_NAME-4 "標準アッテネータ|Standard Attenuator"
*HW_R_OPT_NAME-5 "Cu Kβ|Cu K-beta"
*HW_R_OPT_NAME-6 "調整用受光スリット|Alignment receiving slit"
*HW_SAMPLE_HOLDER_ID "SMP0023"
*HW_SAMPLE_HOLDER_NAME "標準Zステージ|Standard Z stage"
*HW_XG_CURRENT_MAX "50"
*HW_XG_CURRENT_MIN "2"
*HW_XG_CURRENT_RESOLUTION "1"
*HW_XG_CURRENT_UNIT "mA"
*HW_XG_FOCUS "1mm x 10mm"
*HW_XG_FOCUS_TYPE "Normal"
*HW_XG_ID ""
*HW_XG_NAME "3kW 封入管(ID:1200)|3kW Sealed tube(ID:1200)"
*HW_XG_TARGET_ATOMIC_NUMBER "29.0000000000"
*HW_XG_TARGET_NAME "Cu"
*HW_XG_TYPE "Hermetic"
*HW_XG_VOLTAGE_MAX "60"
*HW_XG_VOLTAGE_MIN "20"
*HW_XG_VOLTAGE_RESOLUTION "1"
*HW_XG_VOLTAGE_UNIT "kV"
*HW_XG_WATT_MAX "1.500"
*HW_XG_WATT_UNIT "kW"
*HW_XG_WAVE_LENGTH_ALPHA1 "1.540593"
*HW_XG_WAVE_LENGTH_ALPHA2 "1.544414"
*HW_XG_WAVE_LENGTH_BETA "1.392250"
*MEAS_COND_AXIS_NAME-0 "2θ/θ"
*MEAS_COND_AXIS_NAME-1 "2θ"
*MEAS_COND_AXIS_NAME-2 "ω"
*MEAS_COND_AXIS_NAME-3 "Z"
*MEAS_COND_AXIS_NAME-4 "2θ/ω"
*MEAS_COND_AXIS_NAME-5 "θs"
*MEAS_COND_AXIS_NAME-6 "θd"
*MEAS_COND_AXIS_NAME-7 "Ts"
*MEAS_COND_AXIS_NAME-8 "CBO選択スリット"
*MEAS_COND_AXIS_NAME-9 "M"
*MEAS_COND_AXIS_NAME-10 "入射平行スリット"
*MEAS_COND_AXIS_NAME-11 "入射スリット"
*MEAS_COND_AXIS_NAME-12 ""
*MEAS_COND_AXIS_NAME-13 "Zs"
*MEAS_COND_AXIS_NAME-14 "入射光学素子"
*MEAS_COND_AXIS_NAME-15 "長手制限スリット"
*MEAS_COND_AXIS_NAME-16 "センタースリット"
*MEAS_COND_AXIS_NAME-17 "フィルター"
*MEAS_COND_AXIS_NAME-18 "受光スリット1"
*MEAS_COND_AXIS_NAME-19 "受光スリット2"
*MEAS_COND_AXIS_NAME-20 "受光光学素子"
*MEAS_COND_AXIS_NAME-21 "受光平行スリット"
*MEAS_COND_AXIS_NAME-22 "調整用受光スリット"
*MEAS_COND_AXIS_NAME-23 ""
*MEAS_COND_AXIS_NAME-24 ""
*MEAS_COND_AXIS_NAME-25 "Zd"
*MEAS_COND_AXIS_NAME-26 "アッテネータ"
*MEAS_COND_AXIS_NAME-27 "検出器モノクロメータ"
*MEAS_COND_AXIS_NAME-28 "モノクロメータスリット"
*MEAS_COND_AXIS_NAME-29 "プライマリビーム"
*MEAS_COND_AXIS_NAME-30 "PHA"
*MEAS_COND_AXIS_NAME_INTERNAL-0 "TwoThetaTheta"
*MEAS_COND_AXIS_NAME_INTERNAL-1 "TwoTheta"
*MEAS_COND_AXIS_NAME_INTERNAL-2 "Omega"
*MEAS_COND_AXIS_NAME_INTERNAL-3 "Z"
*MEAS_COND_AXIS_NAME_INTERNAL-4 "TwoThetaOmega"
*MEAS_COND_AXIS_NAME_INTERNAL-5 "ThetaS"
*MEAS_COND_AXIS_NAME_INTERNAL-6 "ThetaD"
*MEAS_COND_AXIS_NAME_INTERNAL-7 "Ts"
*MEAS_COND_AXIS_NAME_INTERNAL-8 "CBO"
*MEAS_COND_AXIS_NAME_INTERNAL-9 "CBO-M"
*MEAS_COND_AXIS_NAME_INTERNAL-10 "IncidentSollerSlit"
*MEAS_COND_AXIS_NAME_INTERNAL-11 "IncidentSlitBox"
*MEAS_COND_AXIS_NAME_INTERNAL-12 "IncidentSlitBox-_Axis"
*MEAS_COND_AXIS_NAME_INTERNAL-13 "Zs"
*MEAS_COND_AXIS_NAME_INTERNAL-14 "IncidentMonochromator"
*MEAS_COND_AXIS_NAME_INTERNAL-15 "IncidentAxdSlit"
*MEAS_COND_AXIS_NAME_INTERNAL-16 "CenterSlit"
*MEAS_COND_AXIS_NAME_INTERNAL-17 "Filter"
*MEAS_COND_AXIS_NAME_INTERNAL-18 "ReceivingSlitBox1"
*MEAS_COND_AXIS_NAME_INTERNAL-19 "ReceivingSlitBox2"
*MEAS_COND_AXIS_NAME_INTERNAL-20 "ReceivingOptics"
*MEAS_COND_AXIS_NAME_INTERNAL-21 "ReceivingSollerSlit"
*MEAS_COND_AXIS_NAME_INTERNAL-22 "ReceivingAxdSlit"
*MEAS_COND_AXIS_NAME_INTERNAL-23 "ReceivingSlitBox1-_Axis"
*MEAS_COND_AXIS_NAME_INTERNAL-24 "ReceivingSlitBox2-_Axis"
*MEAS_COND_AXIS_NAME_INTERNAL-25 "ReceivingSlitBox2-Zd"
*MEAS_COND_AXIS_NAME_INTERNAL-26 "Attenuator"
*MEAS_COND_AXIS_NAME_INTERNAL-27 "CounterMonochromator"
*MEAS_COND_AXIS_NAME_INTERNAL-28 "CounterSlit"
*MEAS_COND_AXIS_NAME_INTERNAL-29 "IncidentPrimary"
*MEAS_COND_AXIS_NAME_INTERNAL-30 "PHA"
*MEAS_COND_AXIS_NAME_MAGICNO-0 "83951616.0000000000"
*MEAS_COND_AXIS_NAME_MAGICNO-1 "268632064.0000000000"
*MEAS_COND_AXIS_NAME_MAGICNO-2 "268500992.0000000000"
*MEAS_COND_AXIS_NAME_MAGICNO-3 "285278208.0000000000"
*MEAS_COND_AXIS_NAME_MAGICNO-4 "83951616.0000000000"
*MEAS_COND_AXIS_NAME_MAGICNO-5 "131072.0000000000"
*MEAS_COND_AXIS_NAME_MAGICNO-6 "131072.0000000000"
*MEAS_COND_AXIS_NAME_MAGICNO-7 "318898176.0000000000"
*MEAS_COND_AXIS_NAME_MAGICNO-8 "20971521.0000000000"
*MEAS_COND_AXIS_NAME_MAGICNO-9 "285343744.0000000000"
*MEAS_COND_AXIS_NAME_MAGICNO-10 "20971521.0000000000"
*MEAS_COND_AXIS_NAME_MAGICNO-11 "22020097.0000000000"
*MEAS_COND_AXIS_NAME_MAGICNO-12 "25165824.0000000000"
*MEAS_COND_AXIS_NAME_MAGICNO-13 "318898176.0000000000"
*MEAS_COND_AXIS_NAME_MAGICNO-14 "1.0000000000"
*MEAS_COND_AXIS_NAME_MAGICNO-15 "20971521.0000000000"
*MEAS_COND_AXIS_NAME_MAGICNO-16 "20971521.0000000000"
*MEAS_COND_AXIS_NAME_MAGICNO-17 "20971521.0000000000"
*MEAS_COND_AXIS_NAME_MAGICNO-18 "23068673.0000000000"
*MEAS_COND_AXIS_NAME_MAGICNO-19 "23068673.0000000000"
*MEAS_COND_AXIS_NAME_MAGICNO-20 "20971521.0000000000"
*MEAS_COND_AXIS_NAME_MAGICNO-21 "20971521.0000000000"
*MEAS_COND_AXIS_NAME_MAGICNO-22 "20971521.0000000000"
*MEAS_COND_AXIS_NAME_MAGICNO-23 "25165824.0000000000"
*MEAS_COND_AXIS_NAME_MAGICNO-24 "25165824.0000000000"
*MEAS_COND_AXIS_NAME_MAGICNO-25 "285343744.0000000000"
*MEAS_COND_AXIS_NAME_MAGICNO-26 "17301505.0000000000"
*MEAS_COND_AXIS_NAME_MAGICNO-27 "20971521.0000000000"
*MEAS_COND_AXIS_NAME_MAGICNO-28 "20971521.0000000000"
*MEAS_COND_AXIS_NAME_MAGICNO-29 "20971521.0000000000"
*MEAS_COND_AXIS_NAME_MAGICNO-30 "0.0000000000"
*MEAS_COND_AXIS_OFFSET-0 "-"
*MEAS_COND_AXIS_OFFSET-1 "-0.1081000000"
*MEAS_COND_AXIS_OFFSET-2 "0.3758000000"
*MEAS_COND_AXIS_OFFSET-3 "-"
*MEAS_COND_AXIS_OFFSET-4 "-"
*MEAS_COND_AXIS_OFFSET-5 "0.3758000000"
*MEAS_COND_AXIS_OFFSET-6 "-0.4839000000"
*MEAS_COND_AXIS_OFFSET-7 "-"
*MEAS_COND_AXIS_OFFSET-8 "-"
*MEAS_COND_AXIS_OFFSET-9 "-"
*MEAS_COND_AXIS_OFFSET-10 "-"
*MEAS_COND_AXIS_OFFSET-11 "-"
*MEAS_COND_AXIS_OFFSET-12 "-"
*MEAS_COND_AXIS_OFFSET-13 "-"
*MEAS_COND_AXIS_OFFSET-14 "-"
*MEAS_COND_AXIS_OFFSET-15 "-"
*MEAS_COND_AXIS_OFFSET-16 "-"
*MEAS_COND_AXIS_OFFSET-17 "-"
*MEAS_COND_AXIS_OFFSET-18 "-"
*MEAS_COND_AXIS_OFFSET-19 "-"
*MEAS_COND_AXIS_OFFSET-20 "-"
*MEAS_COND_AXIS_OFFSET-21 "-"
*MEAS_COND_AXIS_OFFSET-22 "-"
*MEAS_COND_AXIS_OFFSET-23 "-"
*MEAS_COND_AXIS_OFFSET-24 "-"
*MEAS_COND_AXIS_OFFSET-25 "-"
*MEAS_COND_AXIS_OFFSET-26 "-"
*MEAS_COND_AXIS_OFFSET-27 "-"
*MEAS_COND_AXIS_OFFSET-28 "-"
*MEAS_COND_AXIS_OFFSET-29 "-"
*MEAS_COND_AXIS_OFFSET-30 "-"
*MEAS_COND_AXIS_POSITION-0 "0.0000000000"
*MEAS_COND_AXIS_POSITION-1 "0.0000000000"
*MEAS_COND_AXIS_POSITION-2 "0.0000000000"
*MEAS_COND_AXIS_POSITION-3 "-0.5500000000"
*MEAS_COND_AXIS_POSITION-4 "0.0000000000"
*MEAS_COND_AXIS_POSITION-5 "0.0000000000"
*MEAS_COND_AXIS_POSITION-6 "0.0000000000"
*MEAS_COND_AXIS_POSITION-7 "-0.4278800000"
*MEAS_COND_AXIS_POSITION-8 "BB"
*MEAS_COND_AXIS_POSITION-9 "0.0000000000"
*MEAS_COND_AXIS_POSITION-10 "Soller_slit_5.0deg"
*MEAS_COND_AXIS_POSITION-11 "2/3deg"
*MEAS_COND_AXIS_POSITION-12 "2.2088000000"
*MEAS_COND_AXIS_POSITION-13 "-0.4140600000"
*MEAS_COND_AXIS_POSITION-14 "0.0000000000"
*MEAS_COND_AXIS_POSITION-15 "10.0mm"
*MEAS_COND_AXIS_POSITION-16 "None"
*MEAS_COND_AXIS_POSITION-17 "Cu_K-beta"
*MEAS_COND_AXIS_POSITION-18 "13.000mm"
*MEAS_COND_AXIS_POSITION-19 "13.000mm"
*MEAS_COND_AXIS_POSITION-20 "No_unit"
*MEAS_COND_AXIS_POSITION-21 "Soller_slit_5.0deg"
*MEAS_COND_AXIS_POSITION-22 "None"
*MEAS_COND_AXIS_POSITION-23 "13.0000000000"
*MEAS_COND_AXIS_POSITION-24 "13.0000000000"
*MEAS_COND_AXIS_POSITION-25 "0.0109400000"
*MEAS_COND_AXIS_POSITION-26 "Open"
*MEAS_COND_AXIS_POSITION-27 "None"
*MEAS_COND_AXIS_POSITION-28 "None"
*MEAS_COND_AXIS_POSITION-29 "None"
*MEAS_COND_AXIS_POSITION-30 "38.0000000000"
*MEAS_COND_AXIS_UNIT-0 "deg"
*MEAS_COND_AXIS_UNIT-1 "deg"
*MEAS_COND_AXIS_UNIT-2 "deg"
*MEAS_COND_AXIS_UNIT-3 "mm"
*MEAS_COND_AXIS_UNIT-4 "deg"
*MEAS_COND_AXIS_UNIT-5 "deg"
*MEAS_COND_AXIS_UNIT-6 "deg"
*MEAS_COND_AXIS_UNIT-7 "mm"
*MEAS_COND_AXIS_UNIT-8 ""
*MEAS_COND_AXIS_UNIT-9 "pulse"
*MEAS_COND_AXIS_UNIT-10 ""
*MEAS_COND_AXIS_UNIT-11 ""
*MEAS_COND_AXIS_UNIT-12 "mm"
*MEAS_COND_AXIS_UNIT-13 "mm"
*MEAS_COND_AXIS_UNIT-14 ""
*MEAS_COND_AXIS_UNIT-15 ""
*MEAS_COND_AXIS_UNIT-16 ""
*MEAS_COND_AXIS_UNIT-17 ""
*MEAS_COND_AXIS_UNIT-18 ""
*MEAS_COND_AXIS_UNIT-19 ""
*MEAS_COND_AXIS_UNIT-20 ""
*MEAS_COND_AXIS_UNIT-21 ""
*MEAS_COND_AXIS_UNIT-22 ""
*MEAS_COND_AXIS_UNIT-23 "mm"
*MEAS_COND_AXIS_UNIT-24 "mm"
*MEAS_COND_AXIS_UNIT-25 "mm"
*MEAS_COND_AXIS_UNIT-26 ""
*MEAS_COND_AXIS_UNIT-27 ""
*MEAS_COND_AXIS_UNIT-28 ""
*MEAS_COND_AXIS_UNIT-29 ""
*MEAS_COND_AXIS_UNIT-30 "div"
*MEAS_COND_COUNTER_CNTLOSS_CORR "0.0000000000"
*MEAS_COND_COUNTER_PHABASE "38.0000000000"
*MEAS_COND_COUNTER_PHAWINDOW "16.0000000000"
*MEAS_COND_COUNTER_PHA_UNIT "div"
*MEAS_COND_COUNTER_TAUDIFF "30.0000000000"
*MEAS_COND_COUNTER_TAUINT "0.0000000000"
*MEAS_COND_IRRADIATION_MODE "OFF"
*MEAS_COND_IRRADIATION_WIDTH ""
*MEAS_COND_OPT_ATTR "集中法"
*MEAS_COND_OPT_NAME "@集中法"
*MEAS_COND_UNSYMMETRIC_MODE "OFF"
*MEAS_COND_XG_CURRENT "30.0000000000"
*MEAS_COND_XG_VOLTAGE "40.0000000000"
*MEAS_COND_XG_WAVE_TYPE "Ka"
*MEAS_DATA_COUNT "5001.0000000000"
*MEAS_SCAN_AXIS_X "2θ/θ"
*MEAS_SCAN_AXIS_X_INTERNAL "TwoThetaTheta"
*MEAS_SCAN_END_TIME "07/08/21 18:54:36"
*MEAS_SCAN_MODE "CONTINUOUS"
*MEAS_SCAN_MONITOR "0"
*MEAS_SCAN_RESOLUTION_X "0.0002"
*MEAS_SCAN_SPEED "1.0"
*MEAS_SCAN_SPEED_UNIT "deg/min"
*MEAS_SCAN_START "20.0000000000"
*MEAS_SCAN_START_TIME "07/08/21 18:01:42"
*MEAS_SCAN_STEP "0.0100000000"
*MEAS_SCAN_STOP "70.0000000000"
*MEAS_SCAN_UNIT_X "deg"
*MEAS_SCAN_UNIT_Y "counts"
*RAS_HEADER_END
*RAS_INT_START
20.0000 1729.0000 1.0000
20.0400 1577.0000 1.0000
20.0800 1762.0000 1.0000
20.1200 1690.0000 1.0000
20.1600 1674.0000 1.0000
20.2000 1710.0000 1.0000
20.2400 1711.0000 1.0000
20.2800 1769.0000 1.0000
20.3200 1671.0000 1.0000
20.3600 1693.0000 1.0000
20.4000 1658.0000 1.0000
20.4400 1685.0000 1.0000
20.4800 1623.0000 1.0000
20.5200 1703.0000 1.0000
20.5600 1656.0000 1.0000
20.6000 1611.0000 1.0000
20.6400 1738.0000 1.0000
20.6800 1745.0000 1.0000
20.7200 1656.0000 1.0000
20.7600 1621.0000 1.0000
20.8000 1725.0000 1.0000
20.8400 1632.0000 1.0000
20.8800 1674.0000 1.0000
20.9200 1751.0000 1.0000
20.9600 1636.0000 1.0000
21.0000 1678.0000 1.0000
21.0400 1721.0000 1.0000
21.0800 1666.0000 1.0000
21.1200 1643.0000 1.0000
21.1600 1713.0000 1.0000
21.2000 1680.0000 1.0000
21.2400 1707.0000 1.0000
21.2800 1710.0000 1.0000
21.3200 1686.0000 1.0000
21.3600 1652.0000 1.0000
21.4000 1673.0000 1.0000
21.4400 1699.0000 1.0000
21.4800 1738.0000 1.0000
21.5200 1694.0000 1.0000
21.5600 1719.0000 1.0000
21.6000 1660.0000 1.0000
21.6400 1710.0000 1.0000
21.6800 1688.0000 1.0000
21.7200 1742.0000 1.0000
21.7600 1682.0000 1.0000
21.8000 1702.0000 1.0000
21.8400 1763.0000 1.0000
21.8800 1690.0000 1.0000
21.9200 1712.0000 1.0000
21.9600 1720.0000 1.0000
22.0000 1701.0000 1.0000
22.0400 1739.0000 1.0000
22.0800 1672.0000 1.0000
22.1200 1720.0000 1.0000
22.1600 1722.0000 1.0000
22.2000 1722.0000 1.0000
22.2400 1720.0000 1.0000
22.2800 1664.0000 1.0000
22.3200 1667.0000 1.0000
22.3600 1754.0000 1.0000
22.4000 1765.0000 1.0000
22.4400 1762.0000 1.0000
22.4800 1759.0000 1.0000
22.5200 1779.0000 1.0000
22.5600 1831.0000 1.0000
22.6000 1762.0000 1.0000
22.6400 1717.0000 1.0000
22.6800 1720.0000 1.0000
22.7200 1745.0000 1.0000
22.7600 1732.0000 1.0000
22.8000 1798.0000 1.0000
22.8400 1761.0000 1.0000
22.8800 1716.0000 1.0000
22.9200 1787.0000 1.0000
22.9600 1774.0000 1.0000
23.0000 1767.0000 1.0000
23.0400 1744.0000 1.0000
23.0800 1769.0000 1.0000
23.1200 1756.0000 1.0000
23.1600 1748.0000 1.0000
23.2000 1747.0000 1.0000
23.2400 1728.0000 1.0000
23.2800 1723.0000 1.0000
23.3200 1729.0000 1.0000
23.3600 1771.0000 1.0000
23.4000 1810.0000 1.0000
23.4400 1759.0000 1.0000
23.4800 1877.0000 1.0000
23.5200 1695.0000 1.0000
23.5600 1733.0000 1.0000
23.6000 1778.0000 1.0000
23.6400 1712.0000 1.0000
23.6800 1816.0000 1.0000
23.7200 1726.0000 1.0000
23.7600 1706.0000 1.0000
23.8000 1742.0000 1.0000
23.8400 1742.0000 1.0000
23.8800 1763.0000 1.0000
23.9200 1797.0000 1.0000
23.9600 1793.0000 1.0000
24.0000 1781.0000 1.0000
24.0400 1746.0000 1.0000
24.0800 1766.0000 1.0000
24.1200 1759.0000 1.0000
24.1600 1834.0000 1.0000
24.2000 1816.0000 1.0000
24.2400 1760.0000 1.0000
24.2800 1788.0000 1.0000
24.3200 1861.0000 1.0000
24.3600 1824.0000 1.0000
24.4000 1761.0000 1.0000
24.4400 1806.0000 1.0000
24.4800 1758.0000 1.0000
24.5200 1752.0000 1.0000
24.5600 1844.0000 1.0000
24.6000 1775.0000 1.0000
24.6400 1813.0000 1.0000
24.6800 1803.0000 1.0000
24.7200 1872.0000 1.0000
24.7600 1867.0000 1.0000
24.8000 1838.0000 1.0000
24.8400 1843.0000 1.0000
24.8800 1893.0000 1.0000
24.9200 1837.0000 1.0000
24.9600 1833.0000 1.0000
25.0000 1795.0000 1.0000
25.0400 1931.0000 1.0000
25.0800 1911.0000 1.0000
25.1200 1874.0000 1.0000
25.1600 1838.0000 1.0000
25.2000 1910.0000 1.0000
25.2400 1824.0000 1.0000
25.2800 1846.0000 1.0000
25.3200 1861.0000 1.0000
25.3600 1888.0000 1.0000
25.4000 1834.0000 1.0000
25.4400 1833.0000 1.0000
25.4800 1818.0000 1.0000
25.5200 1795.0000 1.0000
25.5600 1833.0000 1.0000
25.6000 1910.0000 1.0000
25.6400 1830.0000 1.0000
25.6800 1804.0000 1.0000
25.7200 1824.0000 1.0000
25.7600 1835.0000 1.0000
25.8000 1826.0000 1.0000
25.8400 1865.0000 1.0000
25.8800 1806.0000 1.0000
25.9200 1858.0000 1.0000
25.9600 1807.0000 1.0000
26.0000 1806.0000 1.0000
26.0400 1826.0000 1.0000
26.0800 1877.0000 1.0000
26.1200 1811.0000 1.0000
26.1600 1823.0000 1.0000
26.2000 1872.0000 1.0000
26.2400 1866.0000 1.0000
26.2800 1890.0000 1.0000
26.3200 1955.0000 1.0000
26.3600 1897.0000 1.0000
26.4000 1949.0000 1.0000
26.4400 1883.0000 1.0000
26.4800 1909.0000 1.0000
26.5200 1882.0000 1.0000
26.5600 1970.0000 1.0000
26.6000 1886.0000 1.0000
26.6400 1971.0000 1.0000
26.6800 1953.0000 1.0000
26.7200 1977.0000 1.0000
26.7600 1993.0000 1.0000
26.8000 2036.0000 1.0000
26.8400 2062.0000 1.0000
26.8800 2046.0000 1.0000
26.9200 2207.0000 1.0000
26.9600 2279.0000 1.0000
27.0000 2379.0000 1.0000
27.0400 2593.0000 1.0000
27.0800 2772.0000 1.0000
27.1200 3168.0000 1.0000
27.1600 3511.0000 1.0000
27.2000 4193.0000 1.0000
27.2400 5094.0000 1.0000
27.2800 6207.0000 1.0000
27.3200 6852.0000 1.0000
27.3600 6670.0000 1.0000
27.4000 5861.0000 1.0000
27.4400 4703.0000 1.0000
27.4800 3923.0000 1.0000
27.5200 3256.0000 1.0000
27.5600 2822.0000 1.0000
27.6000 2620.0000 1.0000
27.6400 2325.0000 1.0000
27.6800 2195.0000 1.0000
27.7200 2195.0000 1.0000
27.7600 2101.0000 1.0000
27.8000 2040.0000 1.0000
27.8400 1958.0000 1.0000
27.8800 1949.0000 1.0000
27.9200 1975.0000 1.0000
27.9600 1898.0000 1.0000
28.0000 1814.0000 1.0000
28.0400 1822.0000 1.0000
28.0800 1763.0000 1.0000
28.1200 1885.0000 1.0000
28.1600 1798.0000 1.0000
28.2000 1761.0000 1.0000
28.2400 1787.0000 1.0000
28.2800 1785.0000 1.0000
28.3200 1859.0000 1.0000
28.3600 1740.0000 1.0000
28.4000 1783.0000 1.0000
28.4400 1690.0000 1.0000
28.4800 1631.0000 1.0000
28.5200 1736.0000 1.0000
28.5600 1715.0000 1.0000
28.6000 1714.0000 1.0000
28.6400 1765.0000 1.0000
28.6800 1652.0000 1.0000
28.7200 1678.0000 1.0000
28.7600 1693.0000 1.0000
28.8000 1711.0000 1.0000
28.8400 1716.0000 1.0000
28.8800 1695.0000 1.0000
28.9200 1668.0000 1.0000
28.9600 1684.0000 1.0000
29.0000 1675.0000 1.0000
29.0400 1708.0000 1.0000
29.0800 1745.0000 1.0000
29.1200 1733.0000 1.0000
29.1600 1726.0000 1.0000
29.2000 1668.0000 1.0000
29.2400 1609.0000 1.0000
29.2800 1672.0000 1.0000
29.3200 1678.0000 1.0000
29.3600 1686.0000 1.0000
29.4000 1635.0000 1.0000
29.4400 1674.0000 1.0000
29.4800 1654.0000 1.0000
29.5200 1629.0000 1.0000
29.5600 1657.0000 1.0000
29.6000 1622.0000 1.0000
29.6400 1614.0000 1.0000
29.6800 1608.0000 1.0000
29.7200 1596.0000 1.0000
29.7600 1596.0000 1.0000
29.8000 1603.0000 1.0000
29.8400 1564.0000 1.0000
29.8800 1594.0000 1.0000
29.9200 1588.0000 1.0000
29.9600 1574.0000 1.0000
30.0000 1637.0000 1.0000
30.0400 1673.0000 1.0000
30.0800 1651.0000 1.0000
30.1200 1600.0000 1.0000
30.1600 1589.0000 1.0000
30.2000 1638.0000 1.0000
30.2400 1554.0000 1.0000
30.2800 1593.0000 1.0000
30.3200 1562.0000 1.0000
30.3600 1610.0000 1.0000
30.4000 1576.0000 1.0000
30.4400 1606.0000 1.0000
30.4800 1567.0000 1.0000
30.5200 1535.0000 1.0000
30.5600 1596.0000 1.0000
30.6000 1565.0000 1.0000
30.6400 1580.0000 1.0000
30.6800 1484.0000 1.0000
30.7200 1569.0000 1.0000
30.7600 1549.0000 1.0000
30.8000 1530.0000 1.0000
30.8400 1593.0000 1.0000
30.8800 1590.0000 1.0000
30.9200 1505.0000 1.0000
30.9600 1525.0000 1.0000
31.0000 1503.0000 1.0000
31.0400 1525.0000 1.0000
31.0800 1523.0000 1.0000
31.1200 1595.0000 1.0000
31.1600 1550.0000 1.0000
31.2000 1554.0000 1.0000
31.2400 1539.0000 1.0000
31.2800 1542.0000 1.0000
31.3200 1543.0000 1.0000
31.3600 1456.0000 1.0000
31.4000 1535.0000 1.0000
31.4400 1509.0000 1.0000
31.4800 1487.0000 1.0000
31.5200 1461.0000 1.0000
31.5600 1507.0000 1.0000
31.6000 1495.0000 1.0000
31.6400 1598.0000 1.0000
31.6800 1478.0000 1.0000
31.7200 1509.0000 1.0000
31.7600 1465.0000 1.0000
31.8000 1505.0000 1.0000
31.8400 1478.0000 1.0000
31.8800 1553.0000 1.0000
31.9200 1531.0000 1.0000
31.9600 1593.0000 1.0000
32.0000 1511.0000 1.0000
32.0400 1521.0000 1.0000
32.0800 1495.0000 1.0000
32.1200 1500.0000 1.0000
32.1600 1482.0000 1.0000
32.2000 1414.0000 1.0000
32.2400 1465.0000 1.0000
32.2800 1462.0000 1.0000
32.3200 1480.0000 1.0000
32.3600 1488.0000 1.0000
32.4000 1449.0000 1.0000
32.4400 1394.0000 1.0000
32.4800 1506.0000 1.0000
32.5200 1447.0000 1.0000
32.5600 1445.0000 1.0000
32.6000 1476.0000 1.0000
32.6400 1471.0000 1.0000
32.6800 1441.0000 1.0000
32.7200 1458.0000 1.0000
32.7600 1458.0000 1.0000
32.8000 1468.0000 1.0000
32.8400 1432.0000 1.0000
32.8800 1441.0000 1.0000
32.9200 1432.0000 1.0000
32.9600 1402.0000 1.0000
33.0000 1425.0000 1.0000
33.0400 1421.0000 1.0000
33.0800 1420.0000 1.0000
33.1200 1427.0000 1.0000
33.1600 1397.0000 1.0000
33.2000 1425.0000 1.0000
33.2400 1374.0000 1.0000
33.2800 1367.0000 1.0000
33.3200 1368.0000 1.0000
33.3600 1450.0000 1.0000
33.4000 1417.0000 1.0000
33.4400 1382.0000 1.0000
33.4800 1394.0000 1.0000
33.5200 1410.0000 1.0000
33.5600 1433.0000 1.0000
33.6000 1470.0000 1.0000
33.6400 1385.0000 1.0000
33.6800 1374.0000 1.0000
33.7200 1439.0000 1.0000
33.7600 1474.0000 1.0000
33.8000 1474.0000 1.0000
33.8400 1471.0000 1.0000
33.8800 1480.0000 1.0000
33.9200 1498.0000 1.0000
33.9600 1498.0000 1.0000
34.0000 1545.0000 1.0000
34.0400 1526.0000 1.0000
34.0800 1544.0000 1.0000
34.1200 1515.0000 1.0000
34.1600 1588.0000 1.0000
34.2000 1565.0000 1.0000
34.2400 1665.0000 1.0000
34.2800 1724.0000 1.0000
34.3200 1792.0000 1.0000
34.3600 2014.0000 1.0000
34.4000 2192.0000 1.0000
34.4400 2525.0000 1.0000
34.4800 2915.0000 1.0000
34.5200 2888.0000 1.0000
34.5600 2933.0000 1.0000
34.6000 2668.0000 1.0000
34.6400 2445.0000 1.0000
34.6800 2038.0000 1.0000
34.7200 1876.0000 1.0000
34.7600 1784.0000 1.0000
34.8000 1704.0000 1.0000
34.8400 1595.0000 1.0000
34.8800 1537.0000 1.0000
34.9200 1445.0000 1.0000
34.9600 1447.0000 1.0000
35.0000 1373.0000 1.0000
35.0400 1342.0000 1.0000
35.0800 1403.0000 1.0000
35.1200 1285.0000 1.0000
35.1600 1321.0000 1.0000
35.2000 1312.0000 1.0000
35.2400 1297.0000 1.0000
35.2800 1324.0000 1.0000
35.3200 1292.0000 1.0000
35.3600 1245.0000 1.0000
35.4000 1282.0000 1.0000
35.4400 1298.0000 1.0000
35.4800 1249.0000 1.0000
35.5200 1263.0000 1.0000
35.5600 1217.0000 1.0000
35.6000 1212.0000 1.0000
35.6400 1221.0000 1.0000
35.6800 1268.0000 1.0000
35.7200 1307.0000 1.0000
35.7600 1272.0000 1.0000
35.8000 1240.0000 1.0000
35.8400 1225.0000 1.0000
35.8800 1226.0000 1.0000
35.9200 1274.0000 1.0000
35.9600 1264.0000 1.0000
36.0000 1276.0000 1.0000
36.0400 1333.0000 1.0000
36.0800 1296.0000 1.0000
36.1200 1353.0000 1.0000
36.1600 1384.0000 1.0000
36.2000 1456.0000 1.0000
36.2400 1538.0000 1.0000
36.2800 1637.0000 1.0000
36.3200 1808.0000 1.0000
36.3600 1952.0000 1.0000
36.4000 2099.0000 1.0000
36.4400 1997.0000 1.0000
36.4800 1954.0000 1.0000
36.5200 1929.0000 1.0000
36.5600 1787.0000 1.0000
36.6000 1575.0000 1.0000
36.6400 1487.0000 1.0000
36.6800 1420.0000 1.0000
36.7200 1297.0000 1.0000
36.7600 1262.0000 1.0000
36.8000 1219.0000 1.0000
36.8400 1185.0000 1.0000
36.8800 1209.0000 1.0000
36.9200 1181.0000 1.0000
36.9600 1127.0000 1.0000
37.0000 1175.0000 1.0000
37.0400 1183.0000 1.0000
37.0800 1171.0000 1.0000
37.1200 1135.0000 1.0000
37.1600 1159.0000 1.0000
37.2000 1164.0000 1.0000
37.2400 1160.0000 1.0000
37.2800 1104.0000 1.0000
37.3200 1149.0000 1.0000
37.3600 1106.0000 1.0000
37.4000 1177.0000 1.0000
37.4400 1196.0000 1.0000
37.4800 1197.0000 1.0000
37.5200 1097.0000 1.0000
37.5600 1143.0000 1.0000
37.6000 1119.0000 1.0000
37.6400 1160.0000 1.0000
37.6800 1143.0000 1.0000
37.7200 1182.0000 1.0000
37.7600 1119.0000 1.0000
37.8000 1175.0000 1.0000
37.8400 1161.0000 1.0000
37.8800 1191.0000 1.0000
37.9200 1138.0000 1.0000
37.9600 1236.0000 1.0000
38.0000 1209.0000 1.0000
38.0400 1216.0000 1.0000
38.0800 1275.0000 1.0000
38.1200 1358.0000 1.0000
38.1600 1406.0000 1.0000
38.2000 1500.0000 1.0000
38.2400 1671.0000 1.0000
38.2800 1886.0000 1.0000
38.3200 2148.0000 1.0000
38.3600 2638.0000 1.0000
38.4000 3176.0000 1.0000
38.4400 4093.0000 1.0000
38.4800 5802.0000 1.0000
38.5200 7017.0000 1.0000
38.5600 7623.0000 1.0000
38.6000 7176.0000 1.0000
38.6400 6338.0000 1.0000
38.6800 5301.0000 1.0000
38.7200 4056.0000 1.0000
38.7600 3083.0000 1.0000
38.8000 2469.0000 1.0000
38.8400 2037.0000 1.0000
38.8800 1785.0000 1.0000
38.9200 1494.0000 1.0000
38.9600 1327.0000 1.0000
39.0000 1227.0000 1.0000
39.0400 1244.0000 1.0000
39.0800 1173.0000 1.0000
39.1200 1138.0000 1.0000
39.1600 1146.0000 1.0000
39.2000 1110.0000 1.0000
39.2400 1055.0000 1.0000
39.2800 1040.0000 1.0000
39.3200 1096.0000 1.0000
39.3600 1070.0000 1.0000
39.4000 1112.0000 1.0000
39.4400 1029.0000 1.0000
39.4800 1088.0000 1.0000
39.5200 1064.0000 1.0000
39.5600 1057.0000 1.0000
39.6000 1045.0000 1.0000
39.6400 1083.0000 1.0000
39.6800 1058.0000 1.0000
39.7200 1031.0000 1.0000
39.7600 1049.0000 1.0000
39.8000 1055.0000 1.0000
39.8400 1023.0000 1.0000
39.8800 995.0000 1.0000
39.9200 1044.0000 1.0000
39.9600 963.0000 1.0000
40.0000 964.0000 1.0000
40.0400 939.0000 1.0000
40.0800 930.0000 1.0000
40.1200 966.0000 1.0000
40.1600 994.0000 1.0000
40.2000 947.0000 1.0000
40.2400 959.0000 1.0000
40.2800 1002.0000 1.0000
40.3200 937.0000 1.0000
40.3600 974.0000 1.0000
40.4000 903.0000 1.0000
40.4400 975.0000 1.0000
40.4800 995.0000 1.0000
40.5200 955.0000 1.0000
40.5600 942.0000 1.0000
40.6000 944.0000 1.0000
40.6400 928.0000 1.0000
40.6800 931.0000 1.0000
40.7200 863.0000 1.0000
40.7600 935.0000 1.0000
40.8000 937.0000 1.0000
40.8400 926.0000 1.0000
40.8800 925.0000 1.0000
40.9200 973.0000 1.0000
40.9600 914.0000 1.0000
41.0000 952.0000 1.0000
41.0400 973.0000 1.0000
41.0800 909.0000 1.0000
41.1200 922.0000 1.0000
41.1600 996.0000 1.0000
41.2000 916.0000 1.0000
41.2400 955.0000 1.0000
41.2800 972.0000 1.0000
41.3200 944.0000 1.0000
41.3600 944.0000 1.0000
41.4000 947.0000 1.0000
41.4400 878.0000 1.0000
41.4800 984.0000 1.0000
41.5200 918.0000 1.0000
41.5600 936.0000 1.0000
41.6000 978.0000 1.0000
41.6400 927.0000 1.0000
41.6800 937.0000 1.0000
41.7200 971.0000 1.0000
41.7600 921.0000 1.0000
41.8000 972.0000 1.0000
41.8400 956.0000 1.0000
41.8800 943.0000 1.0000
41.9200 910.0000 1.0000
41.9600 896.0000 1.0000
42.0000 923.0000 1.0000
42.0400 901.0000 1.0000
42.0800 911.0000 1.0000
42.1200 938.0000 1.0000
42.1600 843.0000 1.0000
42.2000 908.0000 1.0000
42.2400 882.0000 1.0000
42.2800 881.0000 1.0000
42.3200 917.0000 1.0000
42.3600 862.0000 1.0000
42.4000 884.0000 1.0000
42.4400 892.0000 1.0000
42.4800 903.0000 1.0000
42.5200 910.0000 1.0000
42.5600 931.0000 1.0000
42.6000 883.0000 1.0000
42.6400 902.0000 1.0000
42.6800 948.0000 1.0000
42.7200 881.0000 1.0000
42.7600 881.0000 1.0000
42.8000 923.0000 1.0000
42.8400 913.0000 1.0000
42.8800 944.0000 1.0000
42.9200 940.0000 1.0000
42.9600 871.0000 1.0000
43.0000 912.0000 1.0000
43.0400 904.0000 1.0000
43.0800 883.0000 1.0000
43.1200 970.0000 1.0000
43.1600 952.0000 1.0000
43.2000 1023.0000 1.0000
43.2400 991.0000 1.0000
43.2800 985.0000 1.0000
43.3200 1001.0000 1.0000
43.3600 996.0000 1.0000
43.4000 1032.0000 1.0000
43.4400 940.0000 1.0000
43.4800 880.0000 1.0000
43.5200 915.0000 1.0000
43.5600 902.0000 1.0000
43.6000 919.0000 1.0000
43.6400 907.0000 1.0000
43.6800 888.0000 1.0000
43.7200 880.0000 1.0000
43.7600 940.0000 1.0000
43.8000 911.0000 1.0000
43.8400 899.0000 1.0000
43.8800 909.0000 1.0000
43.9200 875.0000 1.0000
43.9600 899.0000 1.0000
44.0000 912.0000 1.0000
44.0400 885.0000 1.0000
44.0800 904.0000 1.0000
44.1200 891.0000 1.0000
44.1600 892.0000 1.0000
44.2000 887.0000 1.0000
44.2400 889.0000 1.0000
44.2800 871.0000 1.0000
44.3200 872.0000 1.0000
44.3600 902.0000 1.0000
44.4000 886.0000 1.0000
44.4400 905.0000 1.0000
44.4800 875.0000 1.0000
44.5200 850.0000 1.0000
44.5600 866.0000 1.0000
44.6000 821.0000 1.0000
44.6400 871.0000 1.0000
44.6800 862.0000 1.0000
44.7200 837.0000 1.0000
44.7600 907.0000 1.0000
44.8000 891.0000 1.0000
44.8400 870.0000 1.0000
44.8800 869.0000 1.0000
44.9200 873.0000 1.0000
44.9600 889.0000 1.0000
45.0000 849.0000 1.0000
45.0400 890.0000 1.0000
45.0800 856.0000 1.0000
45.1200 847.0000 1.0000
45.1600 858.0000 1.0000
45.2000 895.0000 1.0000
45.2400 827.0000 1.0000
45.2800 856.0000 1.0000
45.3200 881.0000 1.0000
45.3600 817.0000 1.0000
45.4000 818.0000 1.0000
45.4400 882.0000 1.0000
45.4800 844.0000 1.0000
45.5200 839.0000 1.0000
45.5600 837.0000 1.0000
45.6000 856.0000 1.0000
45.6400 832.0000 1.0000
45.6800 879.0000 1.0000
45.7200 871.0000 1.0000
45.7600 822.0000 1.0000
45.8000 826.0000 1.0000
45.8400 862.0000 1.0000
45.8800 851.0000 1.0000
45.9200 817.0000 1.0000
45.9600 801.0000 1.0000
46.0000 866.0000 1.0000
46.0400 813.0000 1.0000
46.0800 841.0000 1.0000
46.1200 855.0000 1.0000
46.1600 807.0000 1.0000
46.2000 852.0000 1.0000
46.2400 797.0000 1.0000
46.2800 860.0000 1.0000
46.3200 781.0000 1.0000
46.3600 811.0000 1.0000
46.4000 835.0000 1.0000
46.4400 825.0000 1.0000
46.4800 832.0000 1.0000
46.5200 840.0000 1.0000
46.5600 840.0000 1.0000
46.6000 833.0000 1.0000
46.6400 750.0000 1.0000
46.6800 787.0000 1.0000
46.7200 846.0000 1.0000
46.7600 810.0000 1.0000
46.8000 840.0000 1.0000
46.8400 841.0000 1.0000
46.8800 891.0000 1.0000
46.9200 843.0000 1.0000
46.9600 828.0000 1.0000
47.0000 880.0000 1.0000
47.0400 874.0000 1.0000
47.0800 818.0000 1.0000
47.1200 899.0000 1.0000
47.1600 849.0000 1.0000
47.2000 844.0000 1.0000
47.2400 830.0000 1.0000
47.2800 842.0000 1.0000
47.3200 829.0000 1.0000
47.3600 860.0000 1.0000
47.4000 795.0000 1.0000
47.4400 863.0000 1.0000
47.4800 801.0000 1.0000
47.5200 837.0000 1.0000
47.5600 754.0000 1.0000
47.6000 817.0000 1.0000
47.6400 787.0000 1.0000
47.6800 830.0000 1.0000
47.7200 810.0000 1.0000
47.7600 812.0000 1.0000
47.8000 772.0000 1.0000
47.8400 804.0000 1.0000
47.8800 800.0000 1.0000
47.9200 769.0000 1.0000
47.9600 784.0000 1.0000
48.0000 821.0000 1.0000
48.0400 803.0000 1.0000
48.0800 805.0000 1.0000
48.1200 829.0000 1.0000
48.1600 880.0000 1.0000
48.2000 774.0000 1.0000
48.2400 810.0000 1.0000
48.2800 830.0000 1.0000
48.3200 756.0000 1.0000
48.3600 760.0000 1.0000
48.4000 799.0000 1.0000
48.4400 815.0000 1.0000
48.4800 744.0000 1.0000
48.5200 812.0000 1.0000
48.5600 788.0000 1.0000
48.6000 822.0000 1.0000
48.6400 787.0000 1.0000
48.6800 825.0000 1.0000
48.7200 786.0000 1.0000
48.7600 784.0000 1.0000
48.8000 753.0000 1.0000
48.8400 764.0000 1.0000
48.8800 808.0000 1.0000
48.9200 836.0000 1.0000
48.9600 798.0000 1.0000
49.0000 775.0000 1.0000
49.0400 787.0000 1.0000
49.0800 743.0000 1.0000
49.1200 795.0000 1.0000
49.1600 812.0000 1.0000
49.2000 812.0000 1.0000
49.2400 789.0000 1.0000
49.2800 738.0000 1.0000
49.3200 789.0000 1.0000
49.3600 786.0000 1.0000
49.4000 809.0000 1.0000
49.4400 787.0000 1.0000
49.4800 792.0000 1.0000
49.5200 792.0000 1.0000
49.5600 753.0000 1.0000
49.6000 719.0000 1.0000
49.6400 789.0000 1.0000
49.6800 774.0000 1.0000
49.7200 770.0000 1.0000
49.7600 793.0000 1.0000
49.8000 749.0000 1.0000
49.8400 756.0000 1.0000
49.8800 782.0000 1.0000
49.9200 786.0000 1.0000
49.9600 786.0000 1.0000
50.0000 782.0000 1.0000
50.0400 789.0000 1.0000
50.0800 801.0000 1.0000
50.1200 764.0000 1.0000
50.1600 766.0000 1.0000
50.2000 763.0000 1.0000
50.2400 802.0000 1.0000
50.2800 782.0000 1.0000
50.3200 772.0000 1.0000
50.3600 745.0000 1.0000
50.4000 778.0000 1.0000
50.4400 844.0000 1.0000
50.4800 806.0000 1.0000
50.5200 822.0000 1.0000
50.5600 781.0000 1.0000
50.6000 795.0000 1.0000
50.6400 797.0000 1.0000
50.6800 751.0000 1.0000
50.7200 787.0000 1.0000
50.7600 786.0000 1.0000
50.8000 800.0000 1.0000
50.8400 770.0000 1.0000
50.8800 809.0000 1.0000
50.9200 747.0000 1.0000
50.9600 803.0000 1.0000
51.0000 822.0000 1.0000
51.0400 808.0000 1.0000
51.0800 797.0000 1.0000
51.1200 763.0000 1.0000
51.1600 790.0000 1.0000
51.2000 751.0000 1.0000
51.2400 772.0000 1.0000
51.2800 834.0000 1.0000
51.3200 814.0000 1.0000
51.3600 779.0000 1.0000
51.4000 799.0000 1.0000
51.4400 808.0000 1.0000
51.4800 793.0000 1.0000
51.5200 762.0000 1.0000
51.5600 791.0000 1.0000
51.6000 813.0000 1.0000
51.6400 804.0000 1.0000
51.6800 821.0000 1.0000
51.7200 864.0000 1.0000
51.7600 840.0000 1.0000
51.8000 873.0000 1.0000
51.8400 853.0000 1.0000
51.8800 889.0000 1.0000
51.9200 975.0000 1.0000
51.9600 1033.0000 1.0000
52.0000 1138.0000 1.0000
52.0400 1321.0000 1.0000
52.0800 1449.0000 1.0000
52.1200 1751.0000 1.0000
52.1600 2304.0000 1.0000
52.2000 3072.0000 1.0000
52.2400 4275.0000 1.0000
52.2800 4931.0000 1.0000
52.3200 4624.0000 1.0000
52.3600 4095.0000 1.0000
52.4000 3771.0000 1.0000
52.4400 3241.0000 1.0000
52.4800 2555.0000 1.0000
52.5200 1937.0000 1.0000
52.5600 1630.0000 1.0000
52.6000 1274.0000 1.0000
52.6400 1153.0000 1.0000
52.6800 1079.0000 1.0000
52.7200 1001.0000 1.0000
52.7600 942.0000 1.0000
52.8000 927.0000 1.0000
52.8400 849.0000 1.0000
52.8800 872.0000 1.0000
52.9200 872.0000 1.0000
52.9600 816.0000 1.0000
53.0000 838.0000 1.0000
53.0400 832.0000 1.0000
53.0800 813.0000 1.0000
53.1200 796.0000 1.0000
53.1600 777.0000 1.0000
53.2000 809.0000 1.0000
53.2400 820.0000 1.0000
53.2800 803.0000 1.0000
53.3200 805.0000 1.0000
53.3600 758.0000 1.0000
53.4000 780.0000 1.0000
53.4400 776.0000 1.0000
53.4800 761.0000 1.0000
53.5200 771.0000 1.0000
53.5600 729.0000 1.0000
53.6000 755.0000 1.0000
53.6400 780.0000 1.0000
53.6800 779.0000 1.0000
53.7200 776.0000 1.0000
53.7600 755.0000 1.0000
53.8000 766.0000 1.0000
53.8400 782.0000 1.0000
53.8800 775.0000 1.0000
53.9200 766.0000 1.0000
53.9600 778.0000 1.0000
54.0000 792.0000 1.0000
54.0400 746.0000 1.0000
54.0800 796.0000 1.0000
54.1200 750.0000 1.0000
54.1600 756.0000 1.0000
54.2000 781.0000 1.0000
54.2400 751.0000 1.0000
54.2800 771.0000 1.0000
54.3200 754.0000 1.0000
54.3600 788.0000 1.0000
54.4000 766.0000 1.0000
54.4400 751.0000 1.0000
54.4800 737.0000 1.0000
54.5200 760.0000 1.0000
54.5600 789.0000 1.0000
54.6000 742.0000 1.0000
54.6400 749.0000 1.0000
54.6800 791.0000 1.0000
54.7200 772.0000 1.0000
54.7600 803.0000 1.0000
54.8000 782.0000 1.0000
54.8400 854.0000 1.0000
54.8800 783.0000 1.0000
54.9200 780.0000 1.0000
54.9600 844.0000 1.0000
55.0000 776.0000 1.0000
55.0400 827.0000 1.0000
55.0800 846.0000 1.0000
55.1200 853.0000 1.0000
55.1600 951.0000 1.0000
55.2000 979.0000 1.0000
55.2400 1081.0000 1.0000
55.2800 1139.0000 1.0000
55.3200 1168.0000 1.0000
55.3600 1168.0000 1.0000
55.4000 1036.0000 1.0000
55.4400 1010.0000 1.0000
55.4800 982.0000 1.0000
55.5200 986.0000 1.0000
55.5600 892.0000 1.0000
55.6000 852.0000 1.0000
55.6400 834.0000 1.0000
55.6800 799.0000 1.0000
55.7200 755.0000 1.0000
55.7600 750.0000 1.0000
55.8000 761.0000 1.0000
55.8400 769.0000 1.0000
55.8800 791.0000 1.0000
55.9200 773.0000 1.0000
55.9600 724.0000 1.0000
56.0000 750.0000 1.0000
56.0400 778.0000 1.0000
56.0800 768.0000 1.0000
56.1200 761.0000 1.0000
56.1600 776.0000 1.0000
56.2000 742.0000 1.0000
56.2400 702.0000 1.0000
56.2800 724.0000 1.0000
56.3200 718.0000 1.0000
56.3600 719.0000 1.0000
56.4000 729.0000 1.0000
56.4400 710.0000 1.0000
56.4800 713.0000 1.0000
56.5200 682.0000 1.0000
56.5600 707.0000 1.0000
56.6000 741.0000 1.0000
56.6400 688.0000 1.0000
56.6800 708.0000 1.0000
56.7200 684.0000 1.0000
56.7600 722.0000 1.0000
56.8000 728.0000 1.0000
56.8400 734.0000 1.0000
56.8800 691.0000 1.0000
56.9200 726.0000 1.0000
56.9600 767.0000 1.0000
57.0000 741.0000 1.0000
57.0400 734.0000 1.0000
57.0800 749.0000 1.0000
57.1200 721.0000 1.0000
57.1600 778.0000 1.0000
57.2000 719.0000 1.0000
57.2400 705.0000 1.0000
57.2800 733.0000 1.0000
57.3200 729.0000 1.0000
57.3600 736.0000 1.0000
57.4000 728.0000 1.0000
57.4400 724.0000 1.0000
57.4800 741.0000 1.0000
57.5200 715.0000 1.0000
57.5600 742.0000 1.0000
57.6000 715.0000 1.0000
57.6400 750.0000 1.0000
57.6800 729.0000 1.0000
57.7200 705.0000 1.0000
57.7600 722.0000 1.0000
57.8000 747.0000 1.0000
57.8400 696.0000 1.0000
57.8800 716.0000 1.0000
57.9200 705.0000 1.0000
57.9600 681.0000 1.0000
58.0000 711.0000 1.0000
58.0400 769.0000 1.0000
58.0800 694.0000 1.0000
58.1200 724.0000 1.0000
58.1600 743.0000 1.0000
58.2000 738.0000 1.0000
58.2400 719.0000 1.0000
58.2800 715.0000 1.0000
58.3200 761.0000 1.0000
58.3600 714.0000 1.0000
58.4000 671.0000 1.0000
58.4400 747.0000 1.0000
58.4800 737.0000 1.0000
58.5200 757.0000 1.0000
58.5600 685.0000 1.0000
58.6000 751.0000 1.0000
58.6400 718.0000 1.0000
58.6800 724.0000 1.0000
58.7200 720.0000 1.0000
58.7600 690.0000 1.0000
58.8000 706.0000 1.0000
58.8400 716.0000 1.0000
58.8800 723.0000 1.0000
58.9200 713.0000 1.0000
58.9600 718.0000 1.0000
59.0000 717.0000 1.0000
59.0400 688.0000 1.0000
59.0800 724.0000 1.0000
59.1200 701.0000 1.0000
59.1600 785.0000 1.0000
59.2000 722.0000 1.0000
59.2400 741.0000 1.0000
59.2800 713.0000 1.0000
59.3200 755.0000 1.0000
59.3600 723.0000 1.0000
59.4000 699.0000 1.0000
59.4400 720.0000 1.0000
59.4800 756.0000 1.0000
59.5200 692.0000 1.0000
59.5600 672.0000 1.0000
59.6000 721.0000 1.0000
59.6400 729.0000 1.0000
59.6800 719.0000 1.0000
59.7200 705.0000 1.0000
59.7600 698.0000 1.0000
59.8000 696.0000 1.0000
59.8400 713.0000 1.0000
59.8800 714.0000 1.0000
59.9200 707.0000 1.0000
59.9600 764.0000 1.0000
60.0000 728.0000 1.0000
60.0400 753.0000 1.0000
60.0800 726.0000 1.0000
60.1200 700.0000 1.0000
60.1600 726.0000 1.0000
60.2000 704.0000 1.0000
60.2400 717.0000 1.0000
60.2800 706.0000 1.0000
60.3200 685.0000 1.0000
60.3600 717.0000 1.0000
60.4000 721.0000 1.0000
60.4400 736.0000 1.0000
60.4800 690.0000 1.0000
60.5200 748.0000 1.0000
60.5600 733.0000 1.0000
60.6000 701.0000 1.0000
60.6400 724.0000 1.0000
60.6800 703.0000 1.0000
60.7200 703.0000 1.0000
60.7600 686.0000 1.0000
60.8000 734.0000 1.0000
60.8400 723.0000 1.0000
60.8800 756.0000 1.0000
60.9200 698.0000 1.0000
60.9600 733.0000 1.0000
61.0000 692.0000 1.0000
61.0400 681.0000 1.0000
61.0800 704.0000 1.0000
61.1200 706.0000 1.0000
61.1600 789.0000 1.0000
61.2000 693.0000 1.0000
61.2400 687.0000 1.0000
61.2800 693.0000 1.0000
61.3200 703.0000 1.0000
61.3600 731.0000 1.0000
61.4000 716.0000 1.0000
61.4400 705.0000 1.0000
61.4800 708.0000 1.0000
61.5200 726.0000 1.0000
61.5600 754.0000 1.0000
61.6000 706.0000 1.0000
61.6400 746.0000 1.0000
61.6800 744.0000 1.0000
61.7200 753.0000 1.0000
61.7600 745.0000 1.0000
61.8000 773.0000 1.0000
61.8400 777.0000 1.0000
61.8800 788.0000 1.0000
61.9200 865.0000 1.0000
61.9600 826.0000 1.0000
62.0000 861.0000 1.0000
62.0400 969.0000 1.0000
62.0800 1024.0000 1.0000
62.1200 1118.0000 1.0000
62.1600 1238.0000 1.0000
62.2000 1415.0000 1.0000
62.2400 1585.0000 1.0000
62.2800 1643.0000 1.0000
62.3200 1697.0000 1.0000
62.3600 1671.0000 1.0000
62.4000 1579.0000 1.0000
62.4400 1482.0000 1.0000
62.4800 1412.0000 1.0000
62.5200 1335.0000 1.0000
62.5600 1231.0000 1.0000
62.6000 1139.0000 1.0000
62.6400 1050.0000 1.0000
62.6800 957.0000 1.0000
62.7200 956.0000 1.0000
62.7600 904.0000 1.0000
62.8000 821.0000 1.0000
62.8400 834.0000 1.0000
62.8800 882.0000 1.0000
62.9200 820.0000 1.0000
62.9600 817.0000 1.0000
63.0000 794.0000 1.0000
63.0400 817.0000 1.0000
63.0800 780.0000 1.0000
63.1200 736.0000 1.0000
63.1600 733.0000 1.0000
63.2000 758.0000 1.0000
63.2400 741.0000 1.0000
63.2800 738.0000 1.0000
63.3200 774.0000 1.0000
63.3600 760.0000 1.0000
63.4000 707.0000 1.0000
63.4400 735.0000 1.0000
63.4800 706.0000 1.0000
63.5200 704.0000 1.0000
63.5600 753.0000 1.0000
63.6000 735.0000 1.0000
63.6400 733.0000 1.0000
63.6800 757.0000 1.0000
63.7200 753.0000 1.0000
63.7600 742.0000 1.0000
63.8000 731.0000 1.0000
63.8400 766.0000 1.0000
63.8800 754.0000 1.0000
63.9200 813.0000 1.0000
63.9600 729.0000 1.0000
64.0000 721.0000 1.0000
64.0400 745.0000 1.0000
64.0800 760.0000 1.0000
64.1200 757.0000 1.0000
64.1600 753.0000 1.0000
64.2000 770.0000 1.0000
64.2400 748.0000 1.0000
64.2800 787.0000 1.0000
64.3200 753.0000 1.0000
64.3600 730.0000 1.0000
64.4000 795.0000 1.0000
64.4400 824.0000 1.0000
64.4800 813.0000 1.0000
64.5200 859.0000 1.0000
64.5600 903.0000 1.0000
64.6000 949.0000 1.0000
64.6400 953.0000 1.0000
64.6800 998.0000 1.0000
64.7200 1013.0000 1.0000
64.7600 983.0000 1.0000
64.8000 994.0000 1.0000
64.8400 970.0000 1.0000
64.8800 960.0000 1.0000
64.9200 882.0000 1.0000
64.9600 895.0000 1.0000
65.0000 851.0000 1.0000
65.0400 872.0000 1.0000
65.0800 829.0000 1.0000
65.1200 816.0000 1.0000
65.1600 784.0000 1.0000
65.2000 813.0000 1.0000
65.2400 766.0000 1.0000
65.2800 755.0000 1.0000
65.3200 815.0000 1.0000
65.3600 766.0000 1.0000
65.4000 749.0000 1.0000
65.4400 714.0000 1.0000
65.4800 790.0000 1.0000
65.5200 745.0000 1.0000
65.5600 765.0000 1.0000
65.6000 771.0000 1.0000
65.6400 760.0000 1.0000
65.6800 770.0000 1.0000
65.7200 798.0000 1.0000
65.7600 787.0000 1.0000
65.8000 765.0000 1.0000
65.8400 832.0000 1.0000
65.8800 893.0000 1.0000
65.9200 920.0000 1.0000
65.9600 977.0000 1.0000
66.0000 1011.0000 1.0000
66.0400 1199.0000 1.0000
66.0800 1266.0000 1.0000
66.1200 1558.0000 1.0000
66.1600 1879.0000 1.0000
66.2000 2222.0000 1.0000
66.2400 2611.0000 1.0000
66.2800 2635.0000 1.0000
66.3200 2554.0000 1.0000
66.3600 2319.0000 1.0000
66.4000 2177.0000 1.0000
66.4400 2168.0000 1.0000
66.4800 1963.0000 1.0000
66.5200 1656.0000 1.0000
66.5600 1429.0000 1.0000
66.6000 1225.0000 1.0000
66.6400 1062.0000 1.0000
66.6800 1023.0000 1.0000
66.7200 934.0000 1.0000
66.7600 902.0000 1.0000
66.8000 845.0000 1.0000
66.8400 837.0000 1.0000
66.8800 759.0000 1.0000
66.9200 769.0000 1.0000
66.9600 787.0000 1.0000
67.0000 745.0000 1.0000
67.0400 771.0000 1.0000
67.0800 723.0000 1.0000
67.1200 708.0000 1.0000
67.1600 715.0000 1.0000
67.2000 691.0000 1.0000
67.2400 696.0000 1.0000
67.2800 677.0000 1.0000
67.3200 648.0000 1.0000
67.3600 685.0000 1.0000
67.4000 680.0000 1.0000
67.4400 681.0000 1.0000
67.4800 722.0000 1.0000
67.5200 685.0000 1.0000
67.5600 661.0000 1.0000
67.6000 636.0000 1.0000
67.6400 637.0000 1.0000
67.6800 674.0000 1.0000
67.7200 626.0000 1.0000
67.7600 654.0000 1.0000
67.8000 662.0000 1.0000
67.8400 692.0000 1.0000
67.8800 641.0000 1.0000
67.9200 612.0000 1.0000
67.9600 668.0000 1.0000
68.0000 641.0000 1.0000
68.0400 637.0000 1.0000
68.0800 622.0000 1.0000
68.1200 642.0000 1.0000
68.1600 625.0000 1.0000
68.2000 692.0000 1.0000
68.2400 665.0000 1.0000
68.2800 638.0000 1.0000
68.3200 628.0000 1.0000
68.3600 670.0000 1.0000
68.4000 645.0000 1.0000
68.4400 635.0000 1.0000
68.4800 636.0000 1.0000
68.5200 630.0000 1.0000
68.5600 618.0000 1.0000
68.6000 599.0000 1.0000
68.6400 672.0000 1.0000
68.6800 600.0000 1.0000
68.7200 619.0000 1.0000
68.7600 629.0000 1.0000
68.8000 635.0000 1.0000
68.8400 640.0000 1.0000
68.8800 678.0000 1.0000
68.9200 616.0000 1.0000
68.9600 640.0000 1.0000
69.0000 615.0000 1.0000
69.0400 637.0000 1.0000
69.0800 623.0000 1.0000
69.1200 625.0000 1.0000
69.1600 625.0000 1.0000
69.2000 617.0000 1.0000
69.2400 639.0000 1.0000
69.2800 629.0000 1.0000
69.3200 629.0000 1.0000
69.3600 623.0000 1.0000
69.4000 628.0000 1.0000
69.4400 671.0000 1.0000
69.4800 638.0000 1.0000
69.5200 655.0000 1.0000
69.5600 621.0000 1.0000
69.6000 620.0000 1.0000
69.6400 627.0000 1.0000
69.6800 623.0000 1.0000
69.7200 638.0000 1.0000
69.7600 613.0000 1.0000
69.8000 655.0000 1.0000
69.8400 659.0000 1.0000
69.8800 598.0000 1.0000
69.9200 619.0000 1.0000
69.9600 605.0000 1.0000
70.0000 603.0000 1.0000
*RAS_INT_END
*RAS_TEMPERATURE_START
*RAS_TEMPERATURE_END
*RAS_DATA_END