File: Section2_75_samples/XRD/No_069_VS1_2.ras
*RAS_DATA_START
*RAS_HEADER_START
*DISP_FMT_X "%.2f"
*DISP_FMT_Y "%.0f"
*DISP_FULLSCALE "15152.0000000000"
*DISP_LINE_COLOR "255.0000000000"
*DISP_LINE_STYLE "0.0000000000"
*DISP_LINE_WIDTH "0.2500000000"
*DISP_NOTE "測定データ-4"
*DISP_OFFSET_Y "0.0000000000"
*DISP_PEAKSEARCH_UNIT_Y "cps"
*DISP_RANGE_BOTTOM "0.0000000000"
*DISP_RANGE_LEFT "20.0000000000"
*DISP_RANGE_LOGCUTOFF "0.0100000000"
*DISP_RANGE_RIGHT "70.0000000000"
*DISP_RANGE_TOP "15152.0000000000"
*DISP_SCALE_MODE_Y "0.0000000000"
*DISP_TAB_NAME "2θ/θ"
*DISP_TITLE_Y "強度"
*DISP_UNIT_Y "cps"
*DISP_WINDOW_NAME "MSG_MACROENGINE"
*FILE_COMMENT " "
*FILE_MD5 ""
*FILE_MEMO " "
*FILE_OPERATOR "Administrator"
*FILE_SAMPLE " "
*FILE_TYPE "RAS_RAW"
*FILE_USERGROUP "システムマネージャ"
*FILE_VERSION "1.0000000000"
*HW_ATTACHMENT_ID "ATT0025"
*HW_ATTACHMENT_NAME "標準|Standard"
*HW_COUNTER_ID-0 "CUT0025"
*HW_COUNTER_ID-1 "CUT0020"
*HW_COUNTER_ID-2 "CUT0020"
*HW_COUNTER_ID-3 "CSL0021"
*HW_COUNTER_ID-4 "CMC0021"
*HW_COUNTER_NAME-0 "D/teX Ultra|D/teX Ultra"
*HW_COUNTER_NAME-1 "None|None"
*HW_COUNTER_NAME-2 "None|None"
*HW_COUNTER_NAME-3 "BBM|BBM"
*HW_COUNTER_NAME-4 "検出器モノクロメータ|Detector monochromator"
*HW_COUNTER_SELECT_NAME "D/teX Ultra|D/teX Ultra"
*HW_GONIOMETER_ID "GON0023"
*HW_GONIOMETER_NAME "SmartLab|SmartLab"
*HW_GONIOMETER_RADIUS-0 "90.0"
*HW_GONIOMETER_RADIUS-1 "114.0"
*HW_GONIOMETER_RADIUS-2 "190.0"
*HW_GONIOMETER_RADIUS-3 "300.0"
*HW_GONIOMETER_RADIUS-4 "187.0"
*HW_GONIOMETER_RADIUS-5 "300.0"
*HW_GONIOMETER_RADIUS-6 "113.0"
*HW_GONIOMETER_RADIUS-7 "331.0"
*HW_I_OPT_ID-0 "CBO0021"
*HW_I_OPT_ID-1 "ICR0023"
*HW_I_OPT_ID-2 "ISL0021"
*HW_I_OPT_ID-3 "ISO0021"
*HW_I_OPT_ID-4 "IAD0021"
*HW_I_OPT_ID-5 "IPR0001"
*HW_I_OPT_NAME-0 "CBOユニット|CBO unit"
*HW_I_OPT_NAME-1 "標準入射光学ユニット|Standard incident optical unit"
*HW_I_OPT_NAME-2 "標準入射スリットボックス|Standard incident slit box"
*HW_I_OPT_NAME-3 "入射平行スリット|Incident parallel slit"
*HW_I_OPT_NAME-4 "長手制限スリット|Length limiting slit"
*HW_I_OPT_NAME-5 "None|None"
*HW_R_ATTENUATER_AUTOMODE "0"
*HW_R_OPT_ID-0 "RSS0021"
*HW_R_OPT_ID-1 "RCR0023"
*HW_R_OPT_ID-2 "RSO0021"
*HW_R_OPT_ID-3 "RRS0021"
*HW_R_OPT_ID-4 "ATN0021"
*HW_R_OPT_ID-5 "RFL0021"
*HW_R_OPT_ID-6 "RAD0021"
*HW_R_OPT_NAME-0 "標準受光スリットボックス1|Standard receiving slit box # 1"
*HW_R_OPT_NAME-1 "標準受光光学ユニット1|Standard receiving unit # 1"
*HW_R_OPT_NAME-2 "標準受光光学ユニット2|Standard receiving optical unit # 2"
*HW_R_OPT_NAME-3 "標準受光スリットボックス2|Standard receiving slit box # 2"
*HW_R_OPT_NAME-4 "標準アッテネータ|Standard Attenuator"
*HW_R_OPT_NAME-5 "Cu Kβ|Cu K-beta"
*HW_R_OPT_NAME-6 "調整用受光スリット|Alignment receiving slit"
*HW_SAMPLE_HOLDER_ID "SMP0023"
*HW_SAMPLE_HOLDER_NAME "標準Zステージ|Standard Z stage"
*HW_XG_CURRENT_MAX "50"
*HW_XG_CURRENT_MIN "2"
*HW_XG_CURRENT_RESOLUTION "1"
*HW_XG_CURRENT_UNIT "mA"
*HW_XG_FOCUS "1mm x 10mm"
*HW_XG_FOCUS_TYPE "Normal"
*HW_XG_ID ""
*HW_XG_NAME "3kW 封入管(ID:1200)|3kW Sealed tube(ID:1200)"
*HW_XG_TARGET_ATOMIC_NUMBER "29.0000000000"
*HW_XG_TARGET_NAME "Cu"
*HW_XG_TYPE "Hermetic"
*HW_XG_VOLTAGE_MAX "60"
*HW_XG_VOLTAGE_MIN "20"
*HW_XG_VOLTAGE_RESOLUTION "1"
*HW_XG_VOLTAGE_UNIT "kV"
*HW_XG_WATT_MAX "1.500"
*HW_XG_WATT_UNIT "kW"
*HW_XG_WAVE_LENGTH_ALPHA1 "1.540593"
*HW_XG_WAVE_LENGTH_ALPHA2 "1.544414"
*HW_XG_WAVE_LENGTH_BETA "1.392250"
*MEAS_COND_AXIS_NAME-0 "2θ/θ"
*MEAS_COND_AXIS_NAME-1 "2θ"
*MEAS_COND_AXIS_NAME-2 "ω"
*MEAS_COND_AXIS_NAME-3 "Z"
*MEAS_COND_AXIS_NAME-4 "2θ/ω"
*MEAS_COND_AXIS_NAME-5 "θs"
*MEAS_COND_AXIS_NAME-6 "θd"
*MEAS_COND_AXIS_NAME-7 "Ts"
*MEAS_COND_AXIS_NAME-8 "CBO選択スリット"
*MEAS_COND_AXIS_NAME-9 "M"
*MEAS_COND_AXIS_NAME-10 "入射平行スリット"
*MEAS_COND_AXIS_NAME-11 "入射スリット"
*MEAS_COND_AXIS_NAME-12 ""
*MEAS_COND_AXIS_NAME-13 "Zs"
*MEAS_COND_AXIS_NAME-14 "入射光学素子"
*MEAS_COND_AXIS_NAME-15 "長手制限スリット"
*MEAS_COND_AXIS_NAME-16 "センタースリット"
*MEAS_COND_AXIS_NAME-17 "フィルター"
*MEAS_COND_AXIS_NAME-18 "受光スリット1"
*MEAS_COND_AXIS_NAME-19 "受光スリット2"
*MEAS_COND_AXIS_NAME-20 "受光光学素子"
*MEAS_COND_AXIS_NAME-21 "受光平行スリット"
*MEAS_COND_AXIS_NAME-22 "調整用受光スリット"
*MEAS_COND_AXIS_NAME-23 ""
*MEAS_COND_AXIS_NAME-24 ""
*MEAS_COND_AXIS_NAME-25 "Zd"
*MEAS_COND_AXIS_NAME-26 "アッテネータ"
*MEAS_COND_AXIS_NAME-27 "検出器モノクロメータ"
*MEAS_COND_AXIS_NAME-28 "モノクロメータスリット"
*MEAS_COND_AXIS_NAME-29 "プライマリビーム"
*MEAS_COND_AXIS_NAME-30 "PHA"
*MEAS_COND_AXIS_NAME_INTERNAL-0 "TwoThetaTheta"
*MEAS_COND_AXIS_NAME_INTERNAL-1 "TwoTheta"
*MEAS_COND_AXIS_NAME_INTERNAL-2 "Omega"
*MEAS_COND_AXIS_NAME_INTERNAL-3 "Z"
*MEAS_COND_AXIS_NAME_INTERNAL-4 "TwoThetaOmega"
*MEAS_COND_AXIS_NAME_INTERNAL-5 "ThetaS"
*MEAS_COND_AXIS_NAME_INTERNAL-6 "ThetaD"
*MEAS_COND_AXIS_NAME_INTERNAL-7 "Ts"
*MEAS_COND_AXIS_NAME_INTERNAL-8 "CBO"
*MEAS_COND_AXIS_NAME_INTERNAL-9 "CBO-M"
*MEAS_COND_AXIS_NAME_INTERNAL-10 "IncidentSollerSlit"
*MEAS_COND_AXIS_NAME_INTERNAL-11 "IncidentSlitBox"
*MEAS_COND_AXIS_NAME_INTERNAL-12 "IncidentSlitBox-_Axis"
*MEAS_COND_AXIS_NAME_INTERNAL-13 "Zs"
*MEAS_COND_AXIS_NAME_INTERNAL-14 "IncidentMonochromator"
*MEAS_COND_AXIS_NAME_INTERNAL-15 "IncidentAxdSlit"
*MEAS_COND_AXIS_NAME_INTERNAL-16 "CenterSlit"
*MEAS_COND_AXIS_NAME_INTERNAL-17 "Filter"
*MEAS_COND_AXIS_NAME_INTERNAL-18 "ReceivingSlitBox1"
*MEAS_COND_AXIS_NAME_INTERNAL-19 "ReceivingSlitBox2"
*MEAS_COND_AXIS_NAME_INTERNAL-20 "ReceivingOptics"
*MEAS_COND_AXIS_NAME_INTERNAL-21 "ReceivingSollerSlit"
*MEAS_COND_AXIS_NAME_INTERNAL-22 "ReceivingAxdSlit"
*MEAS_COND_AXIS_NAME_INTERNAL-23 "ReceivingSlitBox1-_Axis"
*MEAS_COND_AXIS_NAME_INTERNAL-24 "ReceivingSlitBox2-_Axis"
*MEAS_COND_AXIS_NAME_INTERNAL-25 "ReceivingSlitBox2-Zd"
*MEAS_COND_AXIS_NAME_INTERNAL-26 "Attenuator"
*MEAS_COND_AXIS_NAME_INTERNAL-27 "CounterMonochromator"
*MEAS_COND_AXIS_NAME_INTERNAL-28 "CounterSlit"
*MEAS_COND_AXIS_NAME_INTERNAL-29 "IncidentPrimary"
*MEAS_COND_AXIS_NAME_INTERNAL-30 "PHA"
*MEAS_COND_AXIS_NAME_MAGICNO-0 "83951616.0000000000"
*MEAS_COND_AXIS_NAME_MAGICNO-1 "268632064.0000000000"
*MEAS_COND_AXIS_NAME_MAGICNO-2 "268500992.0000000000"
*MEAS_COND_AXIS_NAME_MAGICNO-3 "285278208.0000000000"
*MEAS_COND_AXIS_NAME_MAGICNO-4 "83951616.0000000000"
*MEAS_COND_AXIS_NAME_MAGICNO-5 "131072.0000000000"
*MEAS_COND_AXIS_NAME_MAGICNO-6 "131072.0000000000"
*MEAS_COND_AXIS_NAME_MAGICNO-7 "318898176.0000000000"
*MEAS_COND_AXIS_NAME_MAGICNO-8 "20971521.0000000000"
*MEAS_COND_AXIS_NAME_MAGICNO-9 "285343744.0000000000"
*MEAS_COND_AXIS_NAME_MAGICNO-10 "20971521.0000000000"
*MEAS_COND_AXIS_NAME_MAGICNO-11 "22020097.0000000000"
*MEAS_COND_AXIS_NAME_MAGICNO-12 "25165824.0000000000"
*MEAS_COND_AXIS_NAME_MAGICNO-13 "318898176.0000000000"
*MEAS_COND_AXIS_NAME_MAGICNO-14 "1.0000000000"
*MEAS_COND_AXIS_NAME_MAGICNO-15 "20971521.0000000000"
*MEAS_COND_AXIS_NAME_MAGICNO-16 "20971521.0000000000"
*MEAS_COND_AXIS_NAME_MAGICNO-17 "20971521.0000000000"
*MEAS_COND_AXIS_NAME_MAGICNO-18 "23068673.0000000000"
*MEAS_COND_AXIS_NAME_MAGICNO-19 "23068673.0000000000"
*MEAS_COND_AXIS_NAME_MAGICNO-20 "20971521.0000000000"
*MEAS_COND_AXIS_NAME_MAGICNO-21 "20971521.0000000000"
*MEAS_COND_AXIS_NAME_MAGICNO-22 "20971521.0000000000"
*MEAS_COND_AXIS_NAME_MAGICNO-23 "25165824.0000000000"
*MEAS_COND_AXIS_NAME_MAGICNO-24 "25165824.0000000000"
*MEAS_COND_AXIS_NAME_MAGICNO-25 "285343744.0000000000"
*MEAS_COND_AXIS_NAME_MAGICNO-26 "17301505.0000000000"
*MEAS_COND_AXIS_NAME_MAGICNO-27 "20971521.0000000000"
*MEAS_COND_AXIS_NAME_MAGICNO-28 "20971521.0000000000"
*MEAS_COND_AXIS_NAME_MAGICNO-29 "20971521.0000000000"
*MEAS_COND_AXIS_NAME_MAGICNO-30 "0.0000000000"
*MEAS_COND_AXIS_OFFSET-0 "-"
*MEAS_COND_AXIS_OFFSET-1 "-0.1081000000"
*MEAS_COND_AXIS_OFFSET-2 "0.3758000000"
*MEAS_COND_AXIS_OFFSET-3 "-"
*MEAS_COND_AXIS_OFFSET-4 "-"
*MEAS_COND_AXIS_OFFSET-5 "0.3758000000"
*MEAS_COND_AXIS_OFFSET-6 "-0.4839000000"
*MEAS_COND_AXIS_OFFSET-7 "-"
*MEAS_COND_AXIS_OFFSET-8 "-"
*MEAS_COND_AXIS_OFFSET-9 "-"
*MEAS_COND_AXIS_OFFSET-10 "-"
*MEAS_COND_AXIS_OFFSET-11 "-"
*MEAS_COND_AXIS_OFFSET-12 "-"
*MEAS_COND_AXIS_OFFSET-13 "-"
*MEAS_COND_AXIS_OFFSET-14 "-"
*MEAS_COND_AXIS_OFFSET-15 "-"
*MEAS_COND_AXIS_OFFSET-16 "-"
*MEAS_COND_AXIS_OFFSET-17 "-"
*MEAS_COND_AXIS_OFFSET-18 "-"
*MEAS_COND_AXIS_OFFSET-19 "-"
*MEAS_COND_AXIS_OFFSET-20 "-"
*MEAS_COND_AXIS_OFFSET-21 "-"
*MEAS_COND_AXIS_OFFSET-22 "-"
*MEAS_COND_AXIS_OFFSET-23 "-"
*MEAS_COND_AXIS_OFFSET-24 "-"
*MEAS_COND_AXIS_OFFSET-25 "-"
*MEAS_COND_AXIS_OFFSET-26 "-"
*MEAS_COND_AXIS_OFFSET-27 "-"
*MEAS_COND_AXIS_OFFSET-28 "-"
*MEAS_COND_AXIS_OFFSET-29 "-"
*MEAS_COND_AXIS_OFFSET-30 "-"
*MEAS_COND_AXIS_POSITION-0 "0.0000000000"
*MEAS_COND_AXIS_POSITION-1 "0.0000000000"
*MEAS_COND_AXIS_POSITION-2 "0.0000000000"
*MEAS_COND_AXIS_POSITION-3 "-0.5500000000"
*MEAS_COND_AXIS_POSITION-4 "0.0000000000"
*MEAS_COND_AXIS_POSITION-5 "0.0000000000"
*MEAS_COND_AXIS_POSITION-6 "0.0000000000"
*MEAS_COND_AXIS_POSITION-7 "-0.4278800000"
*MEAS_COND_AXIS_POSITION-8 "BB"
*MEAS_COND_AXIS_POSITION-9 "0.0000000000"
*MEAS_COND_AXIS_POSITION-10 "Soller_slit_5.0deg"
*MEAS_COND_AXIS_POSITION-11 "2/3deg"
*MEAS_COND_AXIS_POSITION-12 "2.2088000000"
*MEAS_COND_AXIS_POSITION-13 "-0.4140600000"
*MEAS_COND_AXIS_POSITION-14 "0.0000000000"
*MEAS_COND_AXIS_POSITION-15 "10.0mm"
*MEAS_COND_AXIS_POSITION-16 "None"
*MEAS_COND_AXIS_POSITION-17 "Cu_K-beta"
*MEAS_COND_AXIS_POSITION-18 "10.036mm"
*MEAS_COND_AXIS_POSITION-19 "13.000mm"
*MEAS_COND_AXIS_POSITION-20 "No_unit"
*MEAS_COND_AXIS_POSITION-21 "Soller_slit_5.0deg"
*MEAS_COND_AXIS_POSITION-22 "None"
*MEAS_COND_AXIS_POSITION-23 "10.0363000000"
*MEAS_COND_AXIS_POSITION-24 "13.0000000000"
*MEAS_COND_AXIS_POSITION-25 "0.0109400000"
*MEAS_COND_AXIS_POSITION-26 "Open"
*MEAS_COND_AXIS_POSITION-27 "None"
*MEAS_COND_AXIS_POSITION-28 "None"
*MEAS_COND_AXIS_POSITION-29 "None"
*MEAS_COND_AXIS_POSITION-30 "38.0000000000"
*MEAS_COND_AXIS_UNIT-0 "deg"
*MEAS_COND_AXIS_UNIT-1 "deg"
*MEAS_COND_AXIS_UNIT-2 "deg"
*MEAS_COND_AXIS_UNIT-3 "mm"
*MEAS_COND_AXIS_UNIT-4 "deg"
*MEAS_COND_AXIS_UNIT-5 "deg"
*MEAS_COND_AXIS_UNIT-6 "deg"
*MEAS_COND_AXIS_UNIT-7 "mm"
*MEAS_COND_AXIS_UNIT-8 ""
*MEAS_COND_AXIS_UNIT-9 "pulse"
*MEAS_COND_AXIS_UNIT-10 ""
*MEAS_COND_AXIS_UNIT-11 ""
*MEAS_COND_AXIS_UNIT-12 "mm"
*MEAS_COND_AXIS_UNIT-13 "mm"
*MEAS_COND_AXIS_UNIT-14 ""
*MEAS_COND_AXIS_UNIT-15 ""
*MEAS_COND_AXIS_UNIT-16 ""
*MEAS_COND_AXIS_UNIT-17 ""
*MEAS_COND_AXIS_UNIT-18 ""
*MEAS_COND_AXIS_UNIT-19 ""
*MEAS_COND_AXIS_UNIT-20 ""
*MEAS_COND_AXIS_UNIT-21 ""
*MEAS_COND_AXIS_UNIT-22 ""
*MEAS_COND_AXIS_UNIT-23 "mm"
*MEAS_COND_AXIS_UNIT-24 "mm"
*MEAS_COND_AXIS_UNIT-25 "mm"
*MEAS_COND_AXIS_UNIT-26 ""
*MEAS_COND_AXIS_UNIT-27 ""
*MEAS_COND_AXIS_UNIT-28 ""
*MEAS_COND_AXIS_UNIT-29 ""
*MEAS_COND_AXIS_UNIT-30 "div"
*MEAS_COND_COUNTER_CNTLOSS_CORR "0.0000000000"
*MEAS_COND_COUNTER_PHABASE "38.0000000000"
*MEAS_COND_COUNTER_PHAWINDOW "16.0000000000"
*MEAS_COND_COUNTER_PHA_UNIT "div"
*MEAS_COND_COUNTER_TAUDIFF "30.0000000000"
*MEAS_COND_COUNTER_TAUINT "0.0000000000"
*MEAS_COND_IRRADIATION_MODE "OFF"
*MEAS_COND_IRRADIATION_WIDTH ""
*MEAS_COND_OPT_ATTR "集中法"
*MEAS_COND_OPT_NAME "@集中法"
*MEAS_COND_UNSYMMETRIC_MODE "OFF"
*MEAS_COND_XG_CURRENT "30.0000000000"
*MEAS_COND_XG_VOLTAGE "40.0000000000"
*MEAS_COND_XG_WAVE_TYPE "Ka"
*MEAS_DATA_COUNT "5001.0000000000"
*MEAS_SCAN_AXIS_X "2θ/θ"
*MEAS_SCAN_AXIS_X_INTERNAL "TwoThetaTheta"
*MEAS_SCAN_END_TIME "07/15/21 15:00:52"
*MEAS_SCAN_MODE "CONTINUOUS"
*MEAS_SCAN_MONITOR "0"
*MEAS_SCAN_RESOLUTION_X "0.0002"
*MEAS_SCAN_SPEED "1.0"
*MEAS_SCAN_SPEED_UNIT "deg/min"
*MEAS_SCAN_START "20.0000000000"
*MEAS_SCAN_START_TIME "07/15/21 14:07:59"
*MEAS_SCAN_STEP "0.0100000000"
*MEAS_SCAN_STOP "70.0000000000"
*MEAS_SCAN_UNIT_X "deg"
*MEAS_SCAN_UNIT_Y "counts"
*RAS_HEADER_END
*RAS_INT_START
20.0000 1304.0000 1.0000
20.0400 1186.0000 1.0000
20.0800 1208.0000 1.0000
20.1200 1247.0000 1.0000
20.1600 1233.0000 1.0000
20.2000 1238.0000 1.0000
20.2400 1293.0000 1.0000
20.2800 1245.0000 1.0000
20.3200 1256.0000 1.0000
20.3600 1225.0000 1.0000
20.4000 1244.0000 1.0000
20.4400 1278.0000 1.0000
20.4800 1250.0000 1.0000
20.5200 1237.0000 1.0000
20.5600 1228.0000 1.0000
20.6000 1241.0000 1.0000
20.6400 1223.0000 1.0000
20.6800 1174.0000 1.0000
20.7200 1242.0000 1.0000
20.7600 1298.0000 1.0000
20.8000 1291.0000 1.0000
20.8400 1252.0000 1.0000
20.8800 1272.0000 1.0000
20.9200 1360.0000 1.0000
20.9600 1296.0000 1.0000
21.0000 1251.0000 1.0000
21.0400 1212.0000 1.0000
21.0800 1265.0000 1.0000
21.1200 1186.0000 1.0000
21.1600 1307.0000 1.0000
21.2000 1251.0000 1.0000
21.2400 1285.0000 1.0000
21.2800 1262.0000 1.0000
21.3200 1286.0000 1.0000
21.3600 1274.0000 1.0000
21.4000 1203.0000 1.0000
21.4400 1310.0000 1.0000
21.4800 1187.0000 1.0000
21.5200 1295.0000 1.0000
21.5600 1330.0000 1.0000
21.6000 1302.0000 1.0000
21.6400 1339.0000 1.0000
21.6800 1295.0000 1.0000
21.7200 1284.0000 1.0000
21.7600 1284.0000 1.0000
21.8000 1302.0000 1.0000
21.8400 1324.0000 1.0000
21.8800 1329.0000 1.0000
21.9200 1278.0000 1.0000
21.9600 1299.0000 1.0000
22.0000 1253.0000 1.0000
22.0400 1288.0000 1.0000
22.0800 1295.0000 1.0000
22.1200 1242.0000 1.0000
22.1600 1268.0000 1.0000
22.2000 1325.0000 1.0000
22.2400 1287.0000 1.0000
22.2800 1312.0000 1.0000
22.3200 1282.0000 1.0000
22.3600 1267.0000 1.0000
22.4000 1294.0000 1.0000
22.4400 1326.0000 1.0000
22.4800 1298.0000 1.0000
22.5200 1349.0000 1.0000
22.5600 1332.0000 1.0000
22.6000 1334.0000 1.0000
22.6400 1323.0000 1.0000
22.6800 1324.0000 1.0000
22.7200 1272.0000 1.0000
22.7600 1292.0000 1.0000
22.8000 1322.0000 1.0000
22.8400 1337.0000 1.0000
22.8800 1292.0000 1.0000
22.9200 1323.0000 1.0000
22.9600 1308.0000 1.0000
23.0000 1352.0000 1.0000
23.0400 1336.0000 1.0000
23.0800 1364.0000 1.0000
23.1200 1290.0000 1.0000
23.1600 1305.0000 1.0000
23.2000 1297.0000 1.0000
23.2400 1352.0000 1.0000
23.2800 1318.0000 1.0000
23.3200 1356.0000 1.0000
23.3600 1315.0000 1.0000
23.4000 1332.0000 1.0000
23.4400 1304.0000 1.0000
23.4800 1357.0000 1.0000
23.5200 1361.0000 1.0000
23.5600 1330.0000 1.0000
23.6000 1349.0000 1.0000
23.6400 1326.0000 1.0000
23.6800 1328.0000 1.0000
23.7200 1291.0000 1.0000
23.7600 1352.0000 1.0000
23.8000 1367.0000 1.0000
23.8400 1306.0000 1.0000
23.8800 1313.0000 1.0000
23.9200 1358.0000 1.0000
23.9600 1340.0000 1.0000
24.0000 1317.0000 1.0000
24.0400 1332.0000 1.0000
24.0800 1365.0000 1.0000
24.1200 1372.0000 1.0000
24.1600 1405.0000 1.0000
24.2000 1362.0000 1.0000
24.2400 1355.0000 1.0000
24.2800 1405.0000 1.0000
24.3200 1352.0000 1.0000
24.3600 1372.0000 1.0000
24.4000 1360.0000 1.0000
24.4400 1405.0000 1.0000
24.4800 1353.0000 1.0000
24.5200 1410.0000 1.0000
24.5600 1455.0000 1.0000
24.6000 1419.0000 1.0000
24.6400 1402.0000 1.0000
24.6800 1395.0000 1.0000
24.7200 1423.0000 1.0000
24.7600 1403.0000 1.0000
24.8000 1439.0000 1.0000
24.8400 1425.0000 1.0000
24.8800 1456.0000 1.0000
24.9200 1457.0000 1.0000
24.9600 1461.0000 1.0000
25.0000 1470.0000 1.0000
25.0400 1459.0000 1.0000
25.0800 1506.0000 1.0000
25.1200 1461.0000 1.0000
25.1600 1429.0000 1.0000
25.2000 1449.0000 1.0000
25.2400 1398.0000 1.0000
25.2800 1403.0000 1.0000
25.3200 1411.0000 1.0000
25.3600 1442.0000 1.0000
25.4000 1394.0000 1.0000
25.4400 1489.0000 1.0000
25.4800 1378.0000 1.0000
25.5200 1439.0000 1.0000
25.5600 1371.0000 1.0000
25.6000 1375.0000 1.0000
25.6400 1402.0000 1.0000
25.6800 1399.0000 1.0000
25.7200 1401.0000 1.0000
25.7600 1486.0000 1.0000
25.8000 1392.0000 1.0000
25.8400 1391.0000 1.0000
25.8800 1405.0000 1.0000
25.9200 1407.0000 1.0000
25.9600 1424.0000 1.0000
26.0000 1397.0000 1.0000
26.0400 1475.0000 1.0000
26.0800 1340.0000 1.0000
26.1200 1386.0000 1.0000
26.1600 1446.0000 1.0000
26.2000 1415.0000 1.0000
26.2400 1490.0000 1.0000
26.2800 1506.0000 1.0000
26.3200 1437.0000 1.0000
26.3600 1463.0000 1.0000
26.4000 1464.0000 1.0000
26.4400 1501.0000 1.0000
26.4800 1535.0000 1.0000
26.5200 1516.0000 1.0000
26.5600 1508.0000 1.0000
26.6000 1512.0000 1.0000
26.6400 1591.0000 1.0000
26.6800 1558.0000 1.0000
26.7200 1557.0000 1.0000
26.7600 1697.0000 1.0000
26.8000 1618.0000 1.0000
26.8400 1722.0000 1.0000
26.8800 1806.0000 1.0000
26.9200 1823.0000 1.0000
26.9600 1988.0000 1.0000
27.0000 2093.0000 1.0000
27.0400 2377.0000 1.0000
27.0800 2644.0000 1.0000
27.1200 3130.0000 1.0000
27.1600 3717.0000 1.0000
27.2000 4820.0000 1.0000
27.2400 5881.0000 1.0000
27.2800 6380.0000 1.0000
27.3200 5965.0000 1.0000
27.3600 5082.0000 1.0000
27.4000 3927.0000 1.0000
27.4400 3240.0000 1.0000
27.4800 2764.0000 1.0000
27.5200 2437.0000 1.0000
27.5600 2124.0000 1.0000
27.6000 1975.0000 1.0000
27.6400 1890.0000 1.0000
27.6800 1830.0000 1.0000
27.7200 1783.0000 1.0000
27.7600 1653.0000 1.0000
27.8000 1601.0000 1.0000
27.8400 1615.0000 1.0000
27.8800 1535.0000 1.0000
27.9200 1586.0000 1.0000
27.9600 1587.0000 1.0000
28.0000 1542.0000 1.0000
28.0400 1529.0000 1.0000
28.0800 1489.0000 1.0000
28.1200 1500.0000 1.0000
28.1600 1444.0000 1.0000
28.2000 1474.0000 1.0000
28.2400 1461.0000 1.0000
28.2800 1453.0000 1.0000
28.3200 1438.0000 1.0000
28.3600 1449.0000 1.0000
28.4000 1467.0000 1.0000
28.4400 1392.0000 1.0000
28.4800 1441.0000 1.0000
28.5200 1460.0000 1.0000
28.5600 1441.0000 1.0000
28.6000 1443.0000 1.0000
28.6400 1402.0000 1.0000
28.6800 1487.0000 1.0000
28.7200 1443.0000 1.0000
28.7600 1425.0000 1.0000
28.8000 1378.0000 1.0000
28.8400 1442.0000 1.0000
28.8800 1492.0000 1.0000
28.9200 1354.0000 1.0000
28.9600 1390.0000 1.0000
29.0000 1398.0000 1.0000
29.0400 1416.0000 1.0000
29.0800 1344.0000 1.0000
29.1200 1409.0000 1.0000
29.1600 1350.0000 1.0000
29.2000 1387.0000 1.0000
29.2400 1359.0000 1.0000
29.2800 1375.0000 1.0000
29.3200 1432.0000 1.0000
29.3600 1359.0000 1.0000
29.4000 1396.0000 1.0000
29.4400 1382.0000 1.0000
29.4800 1374.0000 1.0000
29.5200 1385.0000 1.0000
29.5600 1371.0000 1.0000
29.6000 1344.0000 1.0000
29.6400 1332.0000 1.0000
29.6800 1392.0000 1.0000
29.7200 1339.0000 1.0000
29.7600 1277.0000 1.0000
29.8000 1355.0000 1.0000
29.8400 1296.0000 1.0000
29.8800 1342.0000 1.0000
29.9200 1489.0000 1.0000
29.9600 1333.0000 1.0000
30.0000 1300.0000 1.0000
30.0400 1391.0000 1.0000
30.0800 1351.0000 1.0000
30.1200 1309.0000 1.0000
30.1600 1369.0000 1.0000
30.2000 1321.0000 1.0000
30.2400 1362.0000 1.0000
30.2800 1342.0000 1.0000
30.3200 1338.0000 1.0000
30.3600 1340.0000 1.0000
30.4000 1318.0000 1.0000
30.4400 1344.0000 1.0000
30.4800 1324.0000 1.0000
30.5200 1301.0000 1.0000
30.5600 1262.0000 1.0000
30.6000 1353.0000 1.0000
30.6400 1320.0000 1.0000
30.6800 1375.0000 1.0000
30.7200 1337.0000 1.0000
30.7600 1265.0000 1.0000
30.8000 1282.0000 1.0000
30.8400 1341.0000 1.0000
30.8800 1273.0000 1.0000
30.9200 1333.0000 1.0000
30.9600 1312.0000 1.0000
31.0000 1329.0000 1.0000
31.0400 1291.0000 1.0000
31.0800 1299.0000 1.0000
31.1200 1345.0000 1.0000
31.1600 1284.0000 1.0000
31.2000 1264.0000 1.0000
31.2400 1279.0000 1.0000
31.2800 1309.0000 1.0000
31.3200 1306.0000 1.0000
31.3600 1297.0000 1.0000
31.4000 1269.0000 1.0000
31.4400 1312.0000 1.0000
31.4800 1315.0000 1.0000
31.5200 1272.0000 1.0000
31.5600 1259.0000 1.0000
31.6000 1279.0000 1.0000
31.6400 1274.0000 1.0000
31.6800 1227.0000 1.0000
31.7200 1263.0000 1.0000
31.7600 1266.0000 1.0000
31.8000 1261.0000 1.0000
31.8400 1290.0000 1.0000
31.8800 1261.0000 1.0000
31.9200 1332.0000 1.0000
31.9600 1268.0000 1.0000
32.0000 1314.0000 1.0000
32.0400 1253.0000 1.0000
32.0800 1237.0000 1.0000
32.1200 1243.0000 1.0000
32.1600 1255.0000 1.0000
32.2000 1269.0000 1.0000
32.2400 1227.0000 1.0000
32.2800 1212.0000 1.0000
32.3200 1215.0000 1.0000
32.3600 1251.0000 1.0000
32.4000 1214.0000 1.0000
32.4400 1194.0000 1.0000
32.4800 1184.0000 1.0000
32.5200 1175.0000 1.0000
32.5600 1204.0000 1.0000
32.6000 1260.0000 1.0000
32.6400 1207.0000 1.0000
32.6800 1214.0000 1.0000
32.7200 1206.0000 1.0000
32.7600 1250.0000 1.0000
32.8000 1162.0000 1.0000
32.8400 1214.0000 1.0000
32.8800 1226.0000 1.0000
32.9200 1196.0000 1.0000
32.9600 1210.0000 1.0000
33.0000 1184.0000 1.0000
33.0400 1235.0000 1.0000
33.0800 1221.0000 1.0000
33.1200 1232.0000 1.0000
33.1600 1183.0000 1.0000
33.2000 1152.0000 1.0000
33.2400 1165.0000 1.0000
33.2800 1225.0000 1.0000
33.3200 1241.0000 1.0000
33.3600 1199.0000 1.0000
33.4000 1213.0000 1.0000
33.4400 1163.0000 1.0000
33.4800 1211.0000 1.0000
33.5200 1210.0000 1.0000
33.5600 1238.0000 1.0000
33.6000 1192.0000 1.0000
33.6400 1222.0000 1.0000
33.6800 1228.0000 1.0000
33.7200 1290.0000 1.0000
33.7600 1214.0000 1.0000
33.8000 1307.0000 1.0000
33.8400 1296.0000 1.0000
33.8800 1306.0000 1.0000
33.9200 1314.0000 1.0000
33.9600 1343.0000 1.0000
34.0000 1321.0000 1.0000
34.0400 1345.0000 1.0000
34.0800 1373.0000 1.0000
34.1200 1420.0000 1.0000
34.1600 1395.0000 1.0000
34.2000 1440.0000 1.0000
34.2400 1582.0000 1.0000
34.2800 1689.0000 1.0000
34.3200 1841.0000 1.0000
34.3600 2135.0000 1.0000
34.4000 2476.0000 1.0000
34.4400 2779.0000 1.0000
34.4800 2912.0000 1.0000
34.5200 2674.0000 1.0000
34.5600 2376.0000 1.0000
34.6000 2044.0000 1.0000
34.6400 1805.0000 1.0000
34.6800 1631.0000 1.0000
34.7200 1579.0000 1.0000
34.7600 1431.0000 1.0000
34.8000 1302.0000 1.0000
34.8400 1328.0000 1.0000
34.8800 1280.0000 1.0000
34.9200 1140.0000 1.0000
34.9600 1265.0000 1.0000
35.0000 1195.0000 1.0000
35.0400 1127.0000 1.0000
35.0800 1133.0000 1.0000
35.1200 1166.0000 1.0000
35.1600 1098.0000 1.0000
35.2000 1096.0000 1.0000
35.2400 1093.0000 1.0000
35.2800 1115.0000 1.0000
35.3200 1109.0000 1.0000
35.3600 1107.0000 1.0000
35.4000 1091.0000 1.0000
35.4400 1049.0000 1.0000
35.4800 1119.0000 1.0000
35.5200 1056.0000 1.0000
35.5600 1022.0000 1.0000
35.6000 986.0000 1.0000
35.6400 1022.0000 1.0000
35.6800 998.0000 1.0000
35.7200 1023.0000 1.0000
35.7600 978.0000 1.0000
35.8000 1048.0000 1.0000
35.8400 1008.0000 1.0000
35.8800 1044.0000 1.0000
35.9200 1029.0000 1.0000
35.9600 1030.0000 1.0000
36.0000 1034.0000 1.0000
36.0400 1036.0000 1.0000
36.0800 1052.0000 1.0000
36.1200 1097.0000 1.0000
36.1600 1086.0000 1.0000
36.2000 1179.0000 1.0000
36.2400 1189.0000 1.0000
36.2800 1186.0000 1.0000
36.3200 1308.0000 1.0000
36.3600 1319.0000 1.0000
36.4000 1345.0000 1.0000
36.4400 1310.0000 1.0000
36.4800 1279.0000 1.0000
36.5200 1203.0000 1.0000
36.5600 1154.0000 1.0000
36.6000 1050.0000 1.0000
36.6400 1055.0000 1.0000
36.6800 1033.0000 1.0000
36.7200 1008.0000 1.0000
36.7600 1014.0000 1.0000
36.8000 955.0000 1.0000
36.8400 1005.0000 1.0000
36.8800 977.0000 1.0000
36.9200 992.0000 1.0000
36.9600 977.0000 1.0000
37.0000 991.0000 1.0000
37.0400 941.0000 1.0000
37.0800 952.0000 1.0000
37.1200 903.0000 1.0000
37.1600 952.0000 1.0000
37.2000 947.0000 1.0000
37.2400 955.0000 1.0000
37.2800 971.0000 1.0000
37.3200 981.0000 1.0000
37.3600 943.0000 1.0000
37.4000 957.0000 1.0000
37.4400 949.0000 1.0000
37.4800 968.0000 1.0000
37.5200 980.0000 1.0000
37.5600 915.0000 1.0000
37.6000 936.0000 1.0000
37.6400 963.0000 1.0000
37.6800 975.0000 1.0000
37.7200 1050.0000 1.0000
37.7600 998.0000 1.0000
37.8000 985.0000 1.0000
37.8400 986.0000 1.0000
37.8800 999.0000 1.0000
37.9200 1024.0000 1.0000
37.9600 1016.0000 1.0000
38.0000 1091.0000 1.0000
38.0400 1065.0000 1.0000
38.0800 1156.0000 1.0000
38.1200 1247.0000 1.0000
38.1600 1396.0000 1.0000
38.2000 1511.0000 1.0000
38.2400 1769.0000 1.0000
38.2800 2085.0000 1.0000
38.3200 2581.0000 1.0000
38.3600 3292.0000 1.0000
38.4000 4549.0000 1.0000
38.4400 5986.0000 1.0000
38.4800 7121.0000 1.0000
38.5200 7467.0000 1.0000
38.5600 6972.0000 1.0000
38.6000 6027.0000 1.0000
38.6400 4689.0000 1.0000
38.6800 3558.0000 1.0000
38.7200 2738.0000 1.0000
38.7600 2090.0000 1.0000
38.8000 1717.0000 1.0000
38.8400 1459.0000 1.0000
38.8800 1303.0000 1.0000
38.9200 1142.0000 1.0000
38.9600 1068.0000 1.0000
39.0000 965.0000 1.0000
39.0400 953.0000 1.0000
39.0800 971.0000 1.0000
39.1200 964.0000 1.0000
39.1600 921.0000 1.0000
39.2000 881.0000 1.0000
39.2400 911.0000 1.0000
39.2800 869.0000 1.0000
39.3200 868.0000 1.0000
39.3600 885.0000 1.0000
39.4000 855.0000 1.0000
39.4400 844.0000 1.0000
39.4800 923.0000 1.0000
39.5200 898.0000 1.0000
39.5600 865.0000 1.0000
39.6000 895.0000 1.0000
39.6400 925.0000 1.0000
39.6800 864.0000 1.0000
39.7200 859.0000 1.0000
39.7600 810.0000 1.0000
39.8000 859.0000 1.0000
39.8400 851.0000 1.0000
39.8800 871.0000 1.0000
39.9200 842.0000 1.0000
39.9600 797.0000 1.0000
40.0000 819.0000 1.0000
40.0400 799.0000 1.0000
40.0800 775.0000 1.0000
40.1200 802.0000 1.0000
40.1600 847.0000 1.0000
40.2000 801.0000 1.0000
40.2400 801.0000 1.0000
40.2800 770.0000 1.0000
40.3200 822.0000 1.0000
40.3600 785.0000 1.0000
40.4000 804.0000 1.0000
40.4400 773.0000 1.0000
40.4800 805.0000 1.0000
40.5200 780.0000 1.0000
40.5600 717.0000 1.0000
40.6000 762.0000 1.0000
40.6400 804.0000 1.0000
40.6800 809.0000 1.0000
40.7200 796.0000 1.0000
40.7600 779.0000 1.0000
40.8000 805.0000 1.0000
40.8400 775.0000 1.0000
40.8800 756.0000 1.0000
40.9200 768.0000 1.0000
40.9600 757.0000 1.0000
41.0000 774.0000 1.0000
41.0400 809.0000 1.0000
41.0800 753.0000 1.0000
41.1200 755.0000 1.0000
41.1600 759.0000 1.0000
41.2000 740.0000 1.0000
41.2400 784.0000 1.0000
41.2800 758.0000 1.0000
41.3200 761.0000 1.0000
41.3600 752.0000 1.0000
41.4000 786.0000 1.0000
41.4400 785.0000 1.0000
41.4800 767.0000 1.0000
41.5200 792.0000 1.0000
41.5600 796.0000 1.0000
41.6000 795.0000 1.0000
41.6400 784.0000 1.0000
41.6800 804.0000 1.0000
41.7200 760.0000 1.0000
41.7600 779.0000 1.0000
41.8000 800.0000 1.0000
41.8400 801.0000 1.0000
41.8800 786.0000 1.0000
41.9200 772.0000 1.0000
41.9600 743.0000 1.0000
42.0000 784.0000 1.0000
42.0400 751.0000 1.0000
42.0800 767.0000 1.0000
42.1200 747.0000 1.0000
42.1600 783.0000 1.0000
42.2000 745.0000 1.0000
42.2400 754.0000 1.0000
42.2800 764.0000 1.0000
42.3200 809.0000 1.0000
42.3600 742.0000 1.0000
42.4000 751.0000 1.0000
42.4400 746.0000 1.0000
42.4800 772.0000 1.0000
42.5200 772.0000 1.0000
42.5600 774.0000 1.0000
42.6000 765.0000 1.0000
42.6400 759.0000 1.0000
42.6800 744.0000 1.0000
42.7200 756.0000 1.0000
42.7600 760.0000 1.0000
42.8000 778.0000 1.0000
42.8400 742.0000 1.0000
42.8800 780.0000 1.0000
42.9200 778.0000 1.0000
42.9600 720.0000 1.0000
43.0000 781.0000 1.0000
43.0400 781.0000 1.0000
43.0800 746.0000 1.0000
43.1200 815.0000 1.0000
43.1600 831.0000 1.0000
43.2000 838.0000 1.0000
43.2400 864.0000 1.0000
43.2800 830.0000 1.0000
43.3200 822.0000 1.0000
43.3600 744.0000 1.0000
43.4000 789.0000 1.0000
43.4400 759.0000 1.0000
43.4800 764.0000 1.0000
43.5200 746.0000 1.0000
43.5600 758.0000 1.0000
43.6000 769.0000 1.0000
43.6400 755.0000 1.0000
43.6800 729.0000 1.0000
43.7200 720.0000 1.0000
43.7600 718.0000 1.0000
43.8000 737.0000 1.0000
43.8400 753.0000 1.0000
43.8800 745.0000 1.0000
43.9200 723.0000 1.0000
43.9600 732.0000 1.0000
44.0000 681.0000 1.0000
44.0400 726.0000 1.0000
44.0800 756.0000 1.0000
44.1200 696.0000 1.0000
44.1600 719.0000 1.0000
44.2000 733.0000 1.0000
44.2400 706.0000 1.0000
44.2800 707.0000 1.0000
44.3200 724.0000 1.0000
44.3600 725.0000 1.0000
44.4000 717.0000 1.0000
44.4400 718.0000 1.0000
44.4800 762.0000 1.0000
44.5200 717.0000 1.0000
44.5600 733.0000 1.0000
44.6000 702.0000 1.0000
44.6400 656.0000 1.0000
44.6800 734.0000 1.0000
44.7200 722.0000 1.0000
44.7600 703.0000 1.0000
44.8000 694.0000 1.0000
44.8400 727.0000 1.0000
44.8800 716.0000 1.0000
44.9200 673.0000 1.0000
44.9600 684.0000 1.0000
45.0000 670.0000 1.0000
45.0400 744.0000 1.0000
45.0800 746.0000 1.0000
45.1200 675.0000 1.0000
45.1600 695.0000 1.0000
45.2000 712.0000 1.0000
45.2400 693.0000 1.0000
45.2800 670.0000 1.0000
45.3200 708.0000 1.0000
45.3600 683.0000 1.0000
45.4000 700.0000 1.0000
45.4400 699.0000 1.0000
45.4800 682.0000 1.0000
45.5200 696.0000 1.0000
45.5600 711.0000 1.0000
45.6000 724.0000 1.0000
45.6400 685.0000 1.0000
45.6800 718.0000 1.0000
45.7200 714.0000 1.0000
45.7600 703.0000 1.0000
45.8000 714.0000 1.0000
45.8400 648.0000 1.0000
45.8800 694.0000 1.0000
45.9200 745.0000 1.0000
45.9600 708.0000 1.0000
46.0000 710.0000 1.0000
46.0400 698.0000 1.0000
46.0800 701.0000 1.0000
46.1200 706.0000 1.0000
46.1600 663.0000 1.0000
46.2000 684.0000 1.0000
46.2400 730.0000 1.0000
46.2800 679.0000 1.0000
46.3200 684.0000 1.0000
46.3600 710.0000 1.0000
46.4000 674.0000 1.0000
46.4400 687.0000 1.0000
46.4800 698.0000 1.0000
46.5200 675.0000 1.0000
46.5600 699.0000 1.0000
46.6000 732.0000 1.0000
46.6400 728.0000 1.0000
46.6800 706.0000 1.0000
46.7200 681.0000 1.0000
46.7600 651.0000 1.0000
46.8000 653.0000 1.0000
46.8400 660.0000 1.0000
46.8800 682.0000 1.0000
46.9200 675.0000 1.0000
46.9600 716.0000 1.0000
47.0000 725.0000 1.0000
47.0400 692.0000 1.0000
47.0800 707.0000 1.0000
47.1200 693.0000 1.0000
47.1600 673.0000 1.0000
47.2000 679.0000 1.0000
47.2400 688.0000 1.0000
47.2800 669.0000 1.0000
47.3200 688.0000 1.0000
47.3600 679.0000 1.0000
47.4000 703.0000 1.0000
47.4400 691.0000 1.0000
47.4800 638.0000 1.0000
47.5200 666.0000 1.0000
47.5600 658.0000 1.0000
47.6000 662.0000 1.0000
47.6400 661.0000 1.0000
47.6800 655.0000 1.0000
47.7200 707.0000 1.0000
47.7600 702.0000 1.0000
47.8000 657.0000 1.0000
47.8400 673.0000 1.0000
47.8800 658.0000 1.0000
47.9200 687.0000 1.0000
47.9600 674.0000 1.0000
48.0000 647.0000 1.0000
48.0400 696.0000 1.0000
48.0800 648.0000 1.0000
48.1200 644.0000 1.0000
48.1600 667.0000 1.0000
48.2000 674.0000 1.0000
48.2400 649.0000 1.0000
48.2800 700.0000 1.0000
48.3200 670.0000 1.0000
48.3600 680.0000 1.0000
48.4000 676.0000 1.0000
48.4400 703.0000 1.0000
48.4800 673.0000 1.0000
48.5200 656.0000 1.0000
48.5600 663.0000 1.0000
48.6000 673.0000 1.0000
48.6400 661.0000 1.0000
48.6800 645.0000 1.0000
48.7200 654.0000 1.0000
48.7600 667.0000 1.0000
48.8000 680.0000 1.0000
48.8400 672.0000 1.0000
48.8800 662.0000 1.0000
48.9200 671.0000 1.0000
48.9600 716.0000 1.0000
49.0000 642.0000 1.0000
49.0400 674.0000 1.0000
49.0800 654.0000 1.0000
49.1200 653.0000 1.0000
49.1600 658.0000 1.0000
49.2000 646.0000 1.0000
49.2400 673.0000 1.0000
49.2800 639.0000 1.0000
49.3200 632.0000 1.0000
49.3600 666.0000 1.0000
49.4000 646.0000 1.0000
49.4400 628.0000 1.0000
49.4800 633.0000 1.0000
49.5200 645.0000 1.0000
49.5600 617.0000 1.0000
49.6000 610.0000 1.0000
49.6400 691.0000 1.0000
49.6800 655.0000 1.0000
49.7200 661.0000 1.0000
49.7600 651.0000 1.0000
49.8000 606.0000 1.0000
49.8400 646.0000 1.0000
49.8800 705.0000 1.0000
49.9200 658.0000 1.0000
49.9600 721.0000 1.0000
50.0000 652.0000 1.0000
50.0400 620.0000 1.0000
50.0800 659.0000 1.0000
50.1200 687.0000 1.0000
50.1600 643.0000 1.0000
50.2000 698.0000 1.0000
50.2400 668.0000 1.0000
50.2800 644.0000 1.0000
50.3200 662.0000 1.0000
50.3600 697.0000 1.0000
50.4000 704.0000 1.0000
50.4400 688.0000 1.0000
50.4800 702.0000 1.0000
50.5200 701.0000 1.0000
50.5600 689.0000 1.0000
50.6000 668.0000 1.0000
50.6400 676.0000 1.0000
50.6800 678.0000 1.0000
50.7200 660.0000 1.0000
50.7600 671.0000 1.0000
50.8000 658.0000 1.0000
50.8400 658.0000 1.0000
50.8800 672.0000 1.0000
50.9200 622.0000 1.0000
50.9600 671.0000 1.0000
51.0000 677.0000 1.0000
51.0400 687.0000 1.0000
51.0800 691.0000 1.0000
51.1200 665.0000 1.0000
51.1600 673.0000 1.0000
51.2000 673.0000 1.0000
51.2400 640.0000 1.0000
51.2800 670.0000 1.0000
51.3200 674.0000 1.0000
51.3600 679.0000 1.0000
51.4000 683.0000 1.0000
51.4400 687.0000 1.0000
51.4800 729.0000 1.0000
51.5200 665.0000 1.0000
51.5600 699.0000 1.0000
51.6000 728.0000 1.0000
51.6400 676.0000 1.0000
51.6800 700.0000 1.0000
51.7200 699.0000 1.0000
51.7600 732.0000 1.0000
51.8000 772.0000 1.0000
51.8400 794.0000 1.0000
51.8800 854.0000 1.0000
51.9200 909.0000 1.0000
51.9600 1064.0000 1.0000
52.0000 1192.0000 1.0000
52.0400 1455.0000 1.0000
52.0800 1847.0000 1.0000
52.1200 2413.0000 1.0000
52.1600 3396.0000 1.0000
52.2000 4423.0000 1.0000
52.2400 4887.0000 1.0000
52.2800 4577.0000 1.0000
52.3200 3950.0000 1.0000
52.3600 3770.0000 1.0000
52.4000 3201.0000 1.0000
52.4400 2371.0000 1.0000
52.4800 1711.0000 1.0000
52.5200 1435.0000 1.0000
52.5600 1242.0000 1.0000
52.6000 1070.0000 1.0000
52.6400 983.0000 1.0000
52.6800 948.0000 1.0000
52.7200 874.0000 1.0000
52.7600 778.0000 1.0000
52.8000 774.0000 1.0000
52.8400 774.0000 1.0000
52.8800 710.0000 1.0000
52.9200 694.0000 1.0000
52.9600 687.0000 1.0000
53.0000 690.0000 1.0000
53.0400 695.0000 1.0000
53.0800 691.0000 1.0000
53.1200 671.0000 1.0000
53.1600 663.0000 1.0000
53.2000 690.0000 1.0000
53.2400 686.0000 1.0000
53.2800 678.0000 1.0000
53.3200 708.0000 1.0000
53.3600 670.0000 1.0000
53.4000 677.0000 1.0000
53.4400 679.0000 1.0000
53.4800 688.0000 1.0000
53.5200 636.0000 1.0000
53.5600 660.0000 1.0000
53.6000 632.0000 1.0000
53.6400 643.0000 1.0000
53.6800 647.0000 1.0000
53.7200 629.0000 1.0000
53.7600 654.0000 1.0000
53.8000 624.0000 1.0000
53.8400 687.0000 1.0000
53.8800 667.0000 1.0000
53.9200 705.0000 1.0000
53.9600 648.0000 1.0000
54.0000 623.0000 1.0000
54.0400 649.0000 1.0000
54.0800 659.0000 1.0000
54.1200 626.0000 1.0000
54.1600 663.0000 1.0000
54.2000 641.0000 1.0000
54.2400 662.0000 1.0000
54.2800 609.0000 1.0000
54.3200 687.0000 1.0000
54.3600 687.0000 1.0000
54.4000 656.0000 1.0000
54.4400 688.0000 1.0000
54.4800 662.0000 1.0000
54.5200 673.0000 1.0000
54.5600 648.0000 1.0000
54.6000 649.0000 1.0000
54.6400 679.0000 1.0000
54.6800 626.0000 1.0000
54.7200 708.0000 1.0000
54.7600 697.0000 1.0000
54.8000 696.0000 1.0000
54.8400 745.0000 1.0000
54.8800 690.0000 1.0000
54.9200 736.0000 1.0000
54.9600 719.0000 1.0000
55.0000 758.0000 1.0000
55.0400 791.0000 1.0000
55.0800 814.0000 1.0000
55.1200 796.0000 1.0000
55.1600 935.0000 1.0000
55.2000 951.0000 1.0000
55.2400 1054.0000 1.0000
55.2800 1043.0000 1.0000
55.3200 1039.0000 1.0000
55.3600 933.0000 1.0000
55.4000 955.0000 1.0000
55.4400 899.0000 1.0000
55.4800 876.0000 1.0000
55.5200 750.0000 1.0000
55.5600 773.0000 1.0000
55.6000 718.0000 1.0000
55.6400 673.0000 1.0000
55.6800 690.0000 1.0000
55.7200 672.0000 1.0000
55.7600 665.0000 1.0000
55.8000 632.0000 1.0000
55.8400 660.0000 1.0000
55.8800 631.0000 1.0000
55.9200 643.0000 1.0000
55.9600 609.0000 1.0000
56.0000 620.0000 1.0000
56.0400 645.0000 1.0000
56.0800 649.0000 1.0000
56.1200 638.0000 1.0000
56.1600 646.0000 1.0000
56.2000 646.0000 1.0000
56.2400 633.0000 1.0000
56.2800 608.0000 1.0000
56.3200 621.0000 1.0000
56.3600 634.0000 1.0000
56.4000 617.0000 1.0000
56.4400 625.0000 1.0000
56.4800 640.0000 1.0000
56.5200 661.0000 1.0000
56.5600 625.0000 1.0000
56.6000 605.0000 1.0000
56.6400 603.0000 1.0000
56.6800 610.0000 1.0000
56.7200 646.0000 1.0000
56.7600 629.0000 1.0000
56.8000 634.0000 1.0000
56.8400 641.0000 1.0000
56.8800 635.0000 1.0000
56.9200 630.0000 1.0000
56.9600 631.0000 1.0000
57.0000 619.0000 1.0000
57.0400 647.0000 1.0000
57.0800 671.0000 1.0000
57.1200 599.0000 1.0000
57.1600 597.0000 1.0000
57.2000 612.0000 1.0000
57.2400 642.0000 1.0000
57.2800 598.0000 1.0000
57.3200 601.0000 1.0000
57.3600 614.0000 1.0000
57.4000 625.0000 1.0000
57.4400 618.0000 1.0000
57.4800 615.0000 1.0000
57.5200 629.0000 1.0000
57.5600 632.0000 1.0000
57.6000 636.0000 1.0000
57.6400 606.0000 1.0000
57.6800 653.0000 1.0000
57.7200 631.0000 1.0000
57.7600 609.0000 1.0000
57.8000 621.0000 1.0000
57.8400 629.0000 1.0000
57.8800 601.0000 1.0000
57.9200 593.0000 1.0000
57.9600 606.0000 1.0000
58.0000 669.0000 1.0000
58.0400 626.0000 1.0000
58.0800 666.0000 1.0000
58.1200 581.0000 1.0000
58.1600 617.0000 1.0000
58.2000 633.0000 1.0000
58.2400 653.0000 1.0000
58.2800 654.0000 1.0000
58.3200 612.0000 1.0000
58.3600 638.0000 1.0000
58.4000 664.0000 1.0000
58.4400 630.0000 1.0000
58.4800 603.0000 1.0000
58.5200 624.0000 1.0000
58.5600 630.0000 1.0000
58.6000 640.0000 1.0000
58.6400 574.0000 1.0000
58.6800 591.0000 1.0000
58.7200 623.0000 1.0000
58.7600 642.0000 1.0000
58.8000 600.0000 1.0000
58.8400 673.0000 1.0000
58.8800 578.0000 1.0000
58.9200 643.0000 1.0000
58.9600 606.0000 1.0000
59.0000 635.0000 1.0000
59.0400 598.0000 1.0000
59.0800 663.0000 1.0000
59.1200 605.0000 1.0000
59.1600 614.0000 1.0000
59.2000 617.0000 1.0000
59.2400 627.0000 1.0000
59.2800 639.0000 1.0000
59.3200 601.0000 1.0000
59.3600 680.0000 1.0000
59.4000 628.0000 1.0000
59.4400 592.0000 1.0000
59.4800 612.0000 1.0000
59.5200 657.0000 1.0000
59.5600 645.0000 1.0000
59.6000 634.0000 1.0000
59.6400 605.0000 1.0000
59.6800 646.0000 1.0000
59.7200 625.0000 1.0000
59.7600 635.0000 1.0000
59.8000 621.0000 1.0000
59.8400 616.0000 1.0000
59.8800 625.0000 1.0000
59.9200 604.0000 1.0000
59.9600 626.0000 1.0000
60.0000 622.0000 1.0000
60.0400 618.0000 1.0000
60.0800 623.0000 1.0000
60.1200 626.0000 1.0000
60.1600 601.0000 1.0000
60.2000 595.0000 1.0000
60.2400 651.0000 1.0000
60.2800 634.0000 1.0000
60.3200 677.0000 1.0000
60.3600 616.0000 1.0000
60.4000 598.0000 1.0000
60.4400 619.0000 1.0000
60.4800 636.0000 1.0000
60.5200 625.0000 1.0000
60.5600 573.0000 1.0000
60.6000 618.0000 1.0000
60.6400 638.0000 1.0000
60.6800 629.0000 1.0000
60.7200 644.0000 1.0000
60.7600 617.0000 1.0000
60.8000 613.0000 1.0000
60.8400 630.0000 1.0000
60.8800 632.0000 1.0000
60.9200 654.0000 1.0000
60.9600 644.0000 1.0000
61.0000 630.0000 1.0000
61.0400 646.0000 1.0000
61.0800 626.0000 1.0000
61.1200 621.0000 1.0000
61.1600 644.0000 1.0000
61.2000 611.0000 1.0000
61.2400 611.0000 1.0000
61.2800 660.0000 1.0000
61.3200 621.0000 1.0000
61.3600 625.0000 1.0000
61.4000 603.0000 1.0000
61.4400 669.0000 1.0000
61.4800 600.0000 1.0000
61.5200 652.0000 1.0000
61.5600 633.0000 1.0000
61.6000 661.0000 1.0000
61.6400 648.0000 1.0000
61.6800 701.0000 1.0000
61.7200 652.0000 1.0000
61.7600 675.0000 1.0000
61.8000 719.0000 1.0000
61.8400 728.0000 1.0000
61.8800 753.0000 1.0000
61.9200 796.0000 1.0000
61.9600 799.0000 1.0000
62.0000 915.0000 1.0000
62.0400 932.0000 1.0000
62.0800 1096.0000 1.0000
62.1200 1200.0000 1.0000
62.1600 1444.0000 1.0000
62.2000 1486.0000 1.0000
62.2400 1571.0000 1.0000
62.2800 1585.0000 1.0000
62.3200 1566.0000 1.0000
62.3600 1515.0000 1.0000
62.4000 1448.0000 1.0000
62.4400 1329.0000 1.0000
62.4800 1242.0000 1.0000
62.5200 1130.0000 1.0000
62.5600 1076.0000 1.0000
62.6000 923.0000 1.0000
62.6400 893.0000 1.0000
62.6800 838.0000 1.0000
62.7200 787.0000 1.0000
62.7600 789.0000 1.0000
62.8000 719.0000 1.0000
62.8400 698.0000 1.0000
62.8800 672.0000 1.0000
62.9200 675.0000 1.0000
62.9600 711.0000 1.0000
63.0000 736.0000 1.0000
63.0400 715.0000 1.0000
63.0800 677.0000 1.0000
63.1200 660.0000 1.0000
63.1600 696.0000 1.0000
63.2000 644.0000 1.0000
63.2400 704.0000 1.0000
63.2800 660.0000 1.0000
63.3200 615.0000 1.0000
63.3600 631.0000 1.0000
63.4000 665.0000 1.0000
63.4400 624.0000 1.0000
63.4800 599.0000 1.0000
63.5200 652.0000 1.0000
63.5600 621.0000 1.0000
63.6000 631.0000 1.0000
63.6400 640.0000 1.0000
63.6800 629.0000 1.0000
63.7200 638.0000 1.0000
63.7600 664.0000 1.0000
63.8000 641.0000 1.0000
63.8400 660.0000 1.0000
63.8800 600.0000 1.0000
63.9200 620.0000 1.0000
63.9600 612.0000 1.0000
64.0000 646.0000 1.0000
64.0400 645.0000 1.0000
64.0800 662.0000 1.0000
64.1200 607.0000 1.0000
64.1600 639.0000 1.0000
64.2000 659.0000 1.0000
64.2400 611.0000 1.0000
64.2800 672.0000 1.0000
64.3200 591.0000 1.0000
64.3600 649.0000 1.0000
64.4000 623.0000 1.0000
64.4400 696.0000 1.0000
64.4800 639.0000 1.0000
64.5200 668.0000 1.0000
64.5600 705.0000 1.0000
64.6000 674.0000 1.0000
64.6400 665.0000 1.0000
64.6800 741.0000 1.0000
64.7200 706.0000 1.0000
64.7600 725.0000 1.0000
64.8000 677.0000 1.0000
64.8400 688.0000 1.0000
64.8800 694.0000 1.0000
64.9200 669.0000 1.0000
64.9600 653.0000 1.0000
65.0000 699.0000 1.0000
65.0400 691.0000 1.0000
65.0800 711.0000 1.0000
65.1200 678.0000 1.0000
65.1600 635.0000 1.0000
65.2000 670.0000 1.0000
65.2400 633.0000 1.0000
65.2800 664.0000 1.0000
65.3200 679.0000 1.0000
65.3600 679.0000 1.0000
65.4000 674.0000 1.0000
65.4400 657.0000 1.0000
65.4800 691.0000 1.0000
65.5200 696.0000 1.0000
65.5600 644.0000 1.0000
65.6000 690.0000 1.0000
65.6400 643.0000 1.0000
65.6800 678.0000 1.0000
65.7200 741.0000 1.0000
65.7600 764.0000 1.0000
65.8000 772.0000 1.0000
65.8400 775.0000 1.0000
65.8800 826.0000 1.0000
65.9200 892.0000 1.0000
65.9600 999.0000 1.0000
66.0000 1134.0000 1.0000
66.0400 1329.0000 1.0000
66.0800 1562.0000 1.0000
66.1200 2012.0000 1.0000
66.1600 2380.0000 1.0000
66.2000 2626.0000 1.0000
66.2400 2581.0000 1.0000
66.2800 2470.0000 1.0000
66.3200 2300.0000 1.0000
66.3600 2233.0000 1.0000
66.4000 2035.0000 1.0000
66.4400 1782.0000 1.0000
66.4800 1519.0000 1.0000
66.5200 1309.0000 1.0000
66.5600 1156.0000 1.0000
66.6000 1044.0000 1.0000
66.6400 907.0000 1.0000
66.6800 845.0000 1.0000
66.7200 822.0000 1.0000
66.7600 761.0000 1.0000
66.8000 725.0000 1.0000
66.8400 710.0000 1.0000
66.8800 704.0000 1.0000
66.9200 650.0000 1.0000
66.9600 635.0000 1.0000
67.0000 673.0000 1.0000
67.0400 642.0000 1.0000
67.0800 633.0000 1.0000
67.1200 654.0000 1.0000
67.1600 648.0000 1.0000
67.2000 626.0000 1.0000
67.2400 624.0000 1.0000
67.2800 595.0000 1.0000
67.3200 572.0000 1.0000
67.3600 604.0000 1.0000
67.4000 588.0000 1.0000
67.4400 597.0000 1.0000
67.4800 618.0000 1.0000
67.5200 592.0000 1.0000
67.5600 599.0000 1.0000
67.6000 578.0000 1.0000
67.6400 606.0000 1.0000
67.6800 655.0000 1.0000
67.7200 604.0000 1.0000
67.7600 546.0000 1.0000
67.8000 609.0000 1.0000
67.8400 595.0000 1.0000
67.8800 555.0000 1.0000
67.9200 549.0000 1.0000
67.9600 551.0000 1.0000
68.0000 568.0000 1.0000
68.0400 583.0000 1.0000
68.0800 564.0000 1.0000
68.1200 585.0000 1.0000
68.1600 553.0000 1.0000
68.2000 577.0000 1.0000
68.2400 566.0000 1.0000
68.2800 598.0000 1.0000
68.3200 550.0000 1.0000
68.3600 574.0000 1.0000
68.4000 564.0000 1.0000
68.4400 539.0000 1.0000
68.4800 597.0000 1.0000
68.5200 569.0000 1.0000
68.5600 566.0000 1.0000
68.6000 556.0000 1.0000
68.6400 580.0000 1.0000
68.6800 588.0000 1.0000
68.7200 559.0000 1.0000
68.7600 542.0000 1.0000
68.8000 595.0000 1.0000
68.8400 535.0000 1.0000
68.8800 536.0000 1.0000
68.9200 550.0000 1.0000
68.9600 554.0000 1.0000
69.0000 586.0000 1.0000
69.0400 523.0000 1.0000
69.0800 580.0000 1.0000
69.1200 562.0000 1.0000
69.1600 534.0000 1.0000
69.2000 541.0000 1.0000
69.2400 541.0000 1.0000
69.2800 549.0000 1.0000
69.3200 526.0000 1.0000
69.3600 585.0000 1.0000
69.4000 521.0000 1.0000
69.4400 578.0000 1.0000
69.4800 553.0000 1.0000
69.5200 580.0000 1.0000
69.5600 559.0000 1.0000
69.6000 551.0000 1.0000
69.6400 538.0000 1.0000
69.6800 556.0000 1.0000
69.7200 555.0000 1.0000
69.7600 559.0000 1.0000
69.8000 570.0000 1.0000
69.8400 591.0000 1.0000
69.8800 511.0000 1.0000
69.9200 543.0000 1.0000
69.9600 544.0000 1.0000
70.0000 566.0000 1.0000
*RAS_INT_END
*RAS_TEMPERATURE_START
*RAS_TEMPERATURE_END
*RAS_DATA_END