File: Section2_75_samples/XRD/No_018_700_15.ras
*RAS_DATA_START
*RAS_HEADER_START
*DISP_FMT_X "%.2f"
*DISP_FMT_Y "%.0f"
*DISP_FULLSCALE "2768.0000000000"
*DISP_LINE_COLOR "255.0000000000"
*DISP_LINE_STYLE "0.0000000000"
*DISP_LINE_WIDTH "0.2500000000"
*DISP_NOTE "測定データ-11"
*DISP_OFFSET_Y "0.0000000000"
*DISP_PEAKSEARCH_UNIT_Y "cps"
*DISP_RANGE_BOTTOM "0.0000000000"
*DISP_RANGE_LEFT "20.0000000000"
*DISP_RANGE_LOGCUTOFF "0.0100000000"
*DISP_RANGE_RIGHT "80.0000000000"
*DISP_RANGE_TOP "2768.0000000000"
*DISP_SCALE_MODE_Y "0.0000000000"
*DISP_TAB_NAME "2θ/θ"
*DISP_TITLE_Y "強度"
*DISP_UNIT_Y "cps"
*DISP_WINDOW_NAME "MSG_MACROENGINE"
*FILE_COMMENT " "
*FILE_MD5 ""
*FILE_MEMO " "
*FILE_OPERATOR "Administrator"
*FILE_SAMPLE " "
*FILE_TYPE "RAS_RAW"
*FILE_USERGROUP "システムマネージャ"
*FILE_VERSION "1.0000000000"
*HW_ATTACHMENT_ID "ATT0025"
*HW_ATTACHMENT_NAME "標準|Standard"
*HW_COUNTER_ID-0 "CUT0025"
*HW_COUNTER_ID-1 "CUT0020"
*HW_COUNTER_ID-2 "CUT0020"
*HW_COUNTER_ID-3 "CSL0021"
*HW_COUNTER_ID-4 "CMC0021"
*HW_COUNTER_NAME-0 "D/teX Ultra|D/teX Ultra"
*HW_COUNTER_NAME-1 "None|None"
*HW_COUNTER_NAME-2 "None|None"
*HW_COUNTER_NAME-3 "BBM|BBM"
*HW_COUNTER_NAME-4 "検出器モノクロメータ|Detector monochromator"
*HW_COUNTER_SELECT_NAME "D/teX Ultra|D/teX Ultra"
*HW_GONIOMETER_ID "GON0023"
*HW_GONIOMETER_NAME "SmartLab|SmartLab"
*HW_GONIOMETER_RADIUS-0 "90.0"
*HW_GONIOMETER_RADIUS-1 "114.0"
*HW_GONIOMETER_RADIUS-2 "190.0"
*HW_GONIOMETER_RADIUS-3 "300.0"
*HW_GONIOMETER_RADIUS-4 "187.0"
*HW_GONIOMETER_RADIUS-5 "300.0"
*HW_GONIOMETER_RADIUS-6 "113.0"
*HW_GONIOMETER_RADIUS-7 "331.0"
*HW_I_OPT_ID-0 "CBO0021"
*HW_I_OPT_ID-1 "ICR0023"
*HW_I_OPT_ID-2 "ISL0021"
*HW_I_OPT_ID-3 "ISO0021"
*HW_I_OPT_ID-4 "IAD0021"
*HW_I_OPT_ID-5 "IPR0001"
*HW_I_OPT_NAME-0 "CBOユニット|CBO unit"
*HW_I_OPT_NAME-1 "標準入射光学ユニット|Standard incident optical unit"
*HW_I_OPT_NAME-2 "標準入射スリットボックス|Standard incident slit box"
*HW_I_OPT_NAME-3 "入射平行スリット|Incident parallel slit"
*HW_I_OPT_NAME-4 "長手制限スリット|Length limiting slit"
*HW_I_OPT_NAME-5 "None|None"
*HW_R_ATTENUATER_AUTOMODE "0"
*HW_R_OPT_ID-0 "RSS0021"
*HW_R_OPT_ID-1 "RCR0023"
*HW_R_OPT_ID-2 "RSO0021"
*HW_R_OPT_ID-3 "RRS0021"
*HW_R_OPT_ID-4 "ATN0021"
*HW_R_OPT_ID-5 "RFL0021"
*HW_R_OPT_ID-6 "RAD0021"
*HW_R_OPT_NAME-0 "標準受光スリットボックス1|Standard receiving slit box # 1"
*HW_R_OPT_NAME-1 "標準受光光学ユニット1|Standard receiving unit # 1"
*HW_R_OPT_NAME-2 "標準受光光学ユニット2|Standard receiving optical unit # 2"
*HW_R_OPT_NAME-3 "標準受光スリットボックス2|Standard receiving slit box # 2"
*HW_R_OPT_NAME-4 "標準アッテネータ|Standard Attenuator"
*HW_R_OPT_NAME-5 "Cu Kβ|Cu K-beta"
*HW_R_OPT_NAME-6 "調整用受光スリット|Alignment receiving slit"
*HW_SAMPLE_HOLDER_ID "SMP0023"
*HW_SAMPLE_HOLDER_NAME "標準Zステージ|Standard Z stage"
*HW_XG_CURRENT_MAX "50"
*HW_XG_CURRENT_MIN "2"
*HW_XG_CURRENT_RESOLUTION "2"
*HW_XG_CURRENT_UNIT "mA"
*HW_XG_FOCUS "1mm x 10mm"
*HW_XG_FOCUS_TYPE "Normal"
*HW_XG_ID ""
*HW_XG_NAME "3kW 封入管(ID:1200)|3kW Sealed tube(ID:1200)"
*HW_XG_TARGET_ATOMIC_NUMBER "29.0000000000"
*HW_XG_TARGET_NAME "Cu"
*HW_XG_TYPE "Hermetic"
*HW_XG_VOLTAGE_MAX "60"
*HW_XG_VOLTAGE_MIN "20"
*HW_XG_VOLTAGE_RESOLUTION "2"
*HW_XG_VOLTAGE_UNIT "kV"
*HW_XG_WATT_MAX "2"
*HW_XG_WATT_UNIT "kW"
*HW_XG_WAVE_LENGTH_ALPHA1 "1.540593"
*HW_XG_WAVE_LENGTH_ALPHA2 "1.544414"
*HW_XG_WAVE_LENGTH_BETA "1.392250"
*MEAS_COND_AXIS_NAME-0 "2θ/θ"
*MEAS_COND_AXIS_NAME-1 "2θ"
*MEAS_COND_AXIS_NAME-2 "ω"
*MEAS_COND_AXIS_NAME-3 "Z"
*MEAS_COND_AXIS_NAME-4 "2θ/ω"
*MEAS_COND_AXIS_NAME-5 "θs"
*MEAS_COND_AXIS_NAME-6 "θd"
*MEAS_COND_AXIS_NAME-7 "Ts"
*MEAS_COND_AXIS_NAME-8 "CBO選択スリット"
*MEAS_COND_AXIS_NAME-9 "M"
*MEAS_COND_AXIS_NAME-10 "入射平行スリット"
*MEAS_COND_AXIS_NAME-11 "入射スリット"
*MEAS_COND_AXIS_NAME-12 ""
*MEAS_COND_AXIS_NAME-13 "Zs"
*MEAS_COND_AXIS_NAME-14 "入射光学素子"
*MEAS_COND_AXIS_NAME-15 "長手制限スリット"
*MEAS_COND_AXIS_NAME-16 "センタースリット"
*MEAS_COND_AXIS_NAME-17 "フィルター"
*MEAS_COND_AXIS_NAME-18 "受光スリット1"
*MEAS_COND_AXIS_NAME-19 "受光スリット2"
*MEAS_COND_AXIS_NAME-20 "受光光学素子"
*MEAS_COND_AXIS_NAME-21 "受光平行スリット"
*MEAS_COND_AXIS_NAME-22 "調整用受光スリット"
*MEAS_COND_AXIS_NAME-23 ""
*MEAS_COND_AXIS_NAME-24 ""
*MEAS_COND_AXIS_NAME-25 "Zd"
*MEAS_COND_AXIS_NAME-26 "アッテネータ"
*MEAS_COND_AXIS_NAME-27 "検出器モノクロメータ"
*MEAS_COND_AXIS_NAME-28 "モノクロメータスリット"
*MEAS_COND_AXIS_NAME-29 "プライマリビーム"
*MEAS_COND_AXIS_NAME-30 "PHA"
*MEAS_COND_AXIS_NAME_INTERNAL-0 "TwoThetaTheta"
*MEAS_COND_AXIS_NAME_INTERNAL-1 "TwoTheta"
*MEAS_COND_AXIS_NAME_INTERNAL-2 "Omega"
*MEAS_COND_AXIS_NAME_INTERNAL-3 "Z"
*MEAS_COND_AXIS_NAME_INTERNAL-4 "TwoThetaOmega"
*MEAS_COND_AXIS_NAME_INTERNAL-5 "ThetaS"
*MEAS_COND_AXIS_NAME_INTERNAL-6 "ThetaD"
*MEAS_COND_AXIS_NAME_INTERNAL-7 "Ts"
*MEAS_COND_AXIS_NAME_INTERNAL-8 "CBO"
*MEAS_COND_AXIS_NAME_INTERNAL-9 "CBO-M"
*MEAS_COND_AXIS_NAME_INTERNAL-10 "IncidentSollerSlit"
*MEAS_COND_AXIS_NAME_INTERNAL-11 "IncidentSlitBox"
*MEAS_COND_AXIS_NAME_INTERNAL-12 "IncidentSlitBox-_Axis"
*MEAS_COND_AXIS_NAME_INTERNAL-13 "Zs"
*MEAS_COND_AXIS_NAME_INTERNAL-14 "IncidentMonochromator"
*MEAS_COND_AXIS_NAME_INTERNAL-15 "IncidentAxdSlit"
*MEAS_COND_AXIS_NAME_INTERNAL-16 "CenterSlit"
*MEAS_COND_AXIS_NAME_INTERNAL-17 "Filter"
*MEAS_COND_AXIS_NAME_INTERNAL-18 "ReceivingSlitBox1"
*MEAS_COND_AXIS_NAME_INTERNAL-19 "ReceivingSlitBox2"
*MEAS_COND_AXIS_NAME_INTERNAL-20 "ReceivingOptics"
*MEAS_COND_AXIS_NAME_INTERNAL-21 "ReceivingSollerSlit"
*MEAS_COND_AXIS_NAME_INTERNAL-22 "ReceivingAxdSlit"
*MEAS_COND_AXIS_NAME_INTERNAL-23 "ReceivingSlitBox1-_Axis"
*MEAS_COND_AXIS_NAME_INTERNAL-24 "ReceivingSlitBox2-_Axis"
*MEAS_COND_AXIS_NAME_INTERNAL-25 "ReceivingSlitBox2-Zd"
*MEAS_COND_AXIS_NAME_INTERNAL-26 "Attenuator"
*MEAS_COND_AXIS_NAME_INTERNAL-27 "CounterMonochromator"
*MEAS_COND_AXIS_NAME_INTERNAL-28 "CounterSlit"
*MEAS_COND_AXIS_NAME_INTERNAL-29 "IncidentPrimary"
*MEAS_COND_AXIS_NAME_INTERNAL-30 "PHA"
*MEAS_COND_AXIS_NAME_MAGICNO-0 "83951616.0000000000"
*MEAS_COND_AXIS_NAME_MAGICNO-1 "268632064.0000000000"
*MEAS_COND_AXIS_NAME_MAGICNO-2 "268500992.0000000000"
*MEAS_COND_AXIS_NAME_MAGICNO-3 "285278208.0000000000"
*MEAS_COND_AXIS_NAME_MAGICNO-4 "83951616.0000000000"
*MEAS_COND_AXIS_NAME_MAGICNO-5 "131072.0000000000"
*MEAS_COND_AXIS_NAME_MAGICNO-6 "131072.0000000000"
*MEAS_COND_AXIS_NAME_MAGICNO-7 "318898176.0000000000"
*MEAS_COND_AXIS_NAME_MAGICNO-8 "20971521.0000000000"
*MEAS_COND_AXIS_NAME_MAGICNO-9 "285343744.0000000000"
*MEAS_COND_AXIS_NAME_MAGICNO-10 "20971521.0000000000"
*MEAS_COND_AXIS_NAME_MAGICNO-11 "22020097.0000000000"
*MEAS_COND_AXIS_NAME_MAGICNO-12 "25165824.0000000000"
*MEAS_COND_AXIS_NAME_MAGICNO-13 "318898176.0000000000"
*MEAS_COND_AXIS_NAME_MAGICNO-14 "1.0000000000"
*MEAS_COND_AXIS_NAME_MAGICNO-15 "20971521.0000000000"
*MEAS_COND_AXIS_NAME_MAGICNO-16 "20971521.0000000000"
*MEAS_COND_AXIS_NAME_MAGICNO-17 "20971521.0000000000"
*MEAS_COND_AXIS_NAME_MAGICNO-18 "23068673.0000000000"
*MEAS_COND_AXIS_NAME_MAGICNO-19 "23068673.0000000000"
*MEAS_COND_AXIS_NAME_MAGICNO-20 "20971521.0000000000"
*MEAS_COND_AXIS_NAME_MAGICNO-21 "20971521.0000000000"
*MEAS_COND_AXIS_NAME_MAGICNO-22 "20971521.0000000000"
*MEAS_COND_AXIS_NAME_MAGICNO-23 "25165824.0000000000"
*MEAS_COND_AXIS_NAME_MAGICNO-24 "25165824.0000000000"
*MEAS_COND_AXIS_NAME_MAGICNO-25 "285343744.0000000000"
*MEAS_COND_AXIS_NAME_MAGICNO-26 "17301505.0000000000"
*MEAS_COND_AXIS_NAME_MAGICNO-27 "20971521.0000000000"
*MEAS_COND_AXIS_NAME_MAGICNO-28 "20971521.0000000000"
*MEAS_COND_AXIS_NAME_MAGICNO-29 "20971521.0000000000"
*MEAS_COND_AXIS_NAME_MAGICNO-30 "0.0000000000"
*MEAS_COND_AXIS_OFFSET-0 "-"
*MEAS_COND_AXIS_OFFSET-1 "-0.1081000000"
*MEAS_COND_AXIS_OFFSET-2 "0.3758000000"
*MEAS_COND_AXIS_OFFSET-3 "-"
*MEAS_COND_AXIS_OFFSET-4 "-"
*MEAS_COND_AXIS_OFFSET-5 "0.3758000000"
*MEAS_COND_AXIS_OFFSET-6 "-0.4839000000"
*MEAS_COND_AXIS_OFFSET-7 "-"
*MEAS_COND_AXIS_OFFSET-8 "-"
*MEAS_COND_AXIS_OFFSET-9 "-"
*MEAS_COND_AXIS_OFFSET-10 "-"
*MEAS_COND_AXIS_OFFSET-11 "-"
*MEAS_COND_AXIS_OFFSET-12 "-"
*MEAS_COND_AXIS_OFFSET-13 "-"
*MEAS_COND_AXIS_OFFSET-14 "-"
*MEAS_COND_AXIS_OFFSET-15 "-"
*MEAS_COND_AXIS_OFFSET-16 "-"
*MEAS_COND_AXIS_OFFSET-17 "-"
*MEAS_COND_AXIS_OFFSET-18 "-"
*MEAS_COND_AXIS_OFFSET-19 "-"
*MEAS_COND_AXIS_OFFSET-20 "-"
*MEAS_COND_AXIS_OFFSET-21 "-"
*MEAS_COND_AXIS_OFFSET-22 "-"
*MEAS_COND_AXIS_OFFSET-23 "-"
*MEAS_COND_AXIS_OFFSET-24 "-"
*MEAS_COND_AXIS_OFFSET-25 "-"
*MEAS_COND_AXIS_OFFSET-26 "-"
*MEAS_COND_AXIS_OFFSET-27 "-"
*MEAS_COND_AXIS_OFFSET-28 "-"
*MEAS_COND_AXIS_OFFSET-29 "-"
*MEAS_COND_AXIS_OFFSET-30 "-"
*MEAS_COND_AXIS_POSITION-0 "0.0000000000"
*MEAS_COND_AXIS_POSITION-1 "0.0000000000"
*MEAS_COND_AXIS_POSITION-2 "0.0000000000"
*MEAS_COND_AXIS_POSITION-3 "-0.5500000000"
*MEAS_COND_AXIS_POSITION-4 "0.0000000000"
*MEAS_COND_AXIS_POSITION-5 "0.0000000000"
*MEAS_COND_AXIS_POSITION-6 "0.0000000000"
*MEAS_COND_AXIS_POSITION-7 "-0.4278800000"
*MEAS_COND_AXIS_POSITION-8 "BB"
*MEAS_COND_AXIS_POSITION-9 "0.0000000000"
*MEAS_COND_AXIS_POSITION-10 "Soller_slit_5.0deg"
*MEAS_COND_AXIS_POSITION-11 "2/3deg"
*MEAS_COND_AXIS_POSITION-12 "2.2088000000"
*MEAS_COND_AXIS_POSITION-13 "-0.4140600000"
*MEAS_COND_AXIS_POSITION-14 "0.0000000000"
*MEAS_COND_AXIS_POSITION-15 "10.0mm"
*MEAS_COND_AXIS_POSITION-16 "None"
*MEAS_COND_AXIS_POSITION-17 "Cu_K-beta"
*MEAS_COND_AXIS_POSITION-18 "13.000mm"
*MEAS_COND_AXIS_POSITION-19 "13.000mm"
*MEAS_COND_AXIS_POSITION-20 "No_unit"
*MEAS_COND_AXIS_POSITION-21 "Soller_slit_5.0deg"
*MEAS_COND_AXIS_POSITION-22 "None"
*MEAS_COND_AXIS_POSITION-23 "13.0000000000"
*MEAS_COND_AXIS_POSITION-24 "13.0000000000"
*MEAS_COND_AXIS_POSITION-25 "0.0109400000"
*MEAS_COND_AXIS_POSITION-26 "Open"
*MEAS_COND_AXIS_POSITION-27 "None"
*MEAS_COND_AXIS_POSITION-28 "None"
*MEAS_COND_AXIS_POSITION-29 "None"
*MEAS_COND_AXIS_POSITION-30 "38.0000000000"
*MEAS_COND_AXIS_UNIT-0 "deg"
*MEAS_COND_AXIS_UNIT-1 "deg"
*MEAS_COND_AXIS_UNIT-2 "deg"
*MEAS_COND_AXIS_UNIT-3 "mm"
*MEAS_COND_AXIS_UNIT-4 "deg"
*MEAS_COND_AXIS_UNIT-5 "deg"
*MEAS_COND_AXIS_UNIT-6 "deg"
*MEAS_COND_AXIS_UNIT-7 "mm"
*MEAS_COND_AXIS_UNIT-8 ""
*MEAS_COND_AXIS_UNIT-9 "pulse"
*MEAS_COND_AXIS_UNIT-10 ""
*MEAS_COND_AXIS_UNIT-11 ""
*MEAS_COND_AXIS_UNIT-12 "mm"
*MEAS_COND_AXIS_UNIT-13 "mm"
*MEAS_COND_AXIS_UNIT-14 ""
*MEAS_COND_AXIS_UNIT-15 ""
*MEAS_COND_AXIS_UNIT-16 ""
*MEAS_COND_AXIS_UNIT-17 ""
*MEAS_COND_AXIS_UNIT-18 ""
*MEAS_COND_AXIS_UNIT-19 ""
*MEAS_COND_AXIS_UNIT-20 ""
*MEAS_COND_AXIS_UNIT-21 ""
*MEAS_COND_AXIS_UNIT-22 ""
*MEAS_COND_AXIS_UNIT-23 "mm"
*MEAS_COND_AXIS_UNIT-24 "mm"
*MEAS_COND_AXIS_UNIT-25 "mm"
*MEAS_COND_AXIS_UNIT-26 ""
*MEAS_COND_AXIS_UNIT-27 ""
*MEAS_COND_AXIS_UNIT-28 ""
*MEAS_COND_AXIS_UNIT-29 ""
*MEAS_COND_AXIS_UNIT-30 "div"
*MEAS_COND_COUNTER_CNTLOSS_CORR "0.0000000000"
*MEAS_COND_COUNTER_PHABASE "38.0000000000"
*MEAS_COND_COUNTER_PHAWINDOW "16.0000000000"
*MEAS_COND_COUNTER_PHA_UNIT "div"
*MEAS_COND_COUNTER_TAUDIFF "30.0000000000"
*MEAS_COND_COUNTER_TAUINT "0.0000000000"
*MEAS_COND_IRRADIATION_MODE "OFF"
*MEAS_COND_IRRADIATION_WIDTH ""
*MEAS_COND_OPT_ATTR "集中法"
*MEAS_COND_OPT_NAME "@集中法"
*MEAS_COND_UNSYMMETRIC_MODE "OFF"
*MEAS_COND_XG_CURRENT "30.0000000000"
*MEAS_COND_XG_VOLTAGE "40.0000000000"
*MEAS_COND_XG_WAVE_TYPE "Ka"
*MEAS_DATA_COUNT "3001.0000000000"
*MEAS_SCAN_AXIS_X "2θ/θ"
*MEAS_SCAN_AXIS_X_INTERNAL "TwoThetaTheta"
*MEAS_SCAN_END_TIME "08/27/20 17:27:45"
*MEAS_SCAN_MODE "CONTINUOUS"
*MEAS_SCAN_MONITOR "0"
*MEAS_SCAN_RESOLUTION_X "0.0002"
*MEAS_SCAN_SPEED "2.0"
*MEAS_SCAN_SPEED_UNIT "deg/min"
*MEAS_SCAN_START "20.0000000000"
*MEAS_SCAN_START_TIME "08/27/20 16:56:05"
*MEAS_SCAN_STEP "0.0200000000"
*MEAS_SCAN_STOP "80.0000000000"
*MEAS_SCAN_UNIT_X "deg"
*MEAS_SCAN_UNIT_Y "counts"
*RAS_HEADER_END
*RAS_INT_START
20.0000 1384.0000 1.0000
20.0600 1309.0000 1.0000
20.1200 1272.0000 1.0000
20.1800 1255.0000 1.0000
20.2400 1233.0000 1.0000
20.3000 1307.0000 1.0000
20.3600 1232.0000 1.0000
20.4200 1252.0000 1.0000
20.4800 1214.0000 1.0000
20.5400 1222.0000 1.0000
20.6000 1219.0000 1.0000
20.6600 1150.0000 1.0000
20.7200 1195.0000 1.0000
20.7800 1218.0000 1.0000
20.8400 1277.0000 1.0000
20.9000 1154.0000 1.0000
20.9600 1153.0000 1.0000
21.0200 1225.0000 1.0000
21.0800 1196.0000 1.0000
21.1400 1188.0000 1.0000
21.2000 1144.0000 1.0000
21.2600 1203.0000 1.0000
21.3200 1164.0000 1.0000
21.3800 1133.0000 1.0000
21.4400 1121.0000 1.0000
21.5000 1163.0000 1.0000
21.5600 1140.0000 1.0000
21.6200 1151.0000 1.0000
21.6800 1132.0000 1.0000
21.7400 1079.0000 1.0000
21.8000 1091.0000 1.0000
21.8600 1105.0000 1.0000
21.9200 1140.0000 1.0000
21.9800 1104.0000 1.0000
22.0400 1128.0000 1.0000
22.1000 1088.0000 1.0000
22.1600 1082.0000 1.0000
22.2200 1100.0000 1.0000
22.2800 1113.0000 1.0000
22.3400 1002.0000 1.0000
22.4000 1061.0000 1.0000
22.4600 1060.0000 1.0000
22.5200 1066.0000 1.0000
22.5800 953.0000 1.0000
22.6400 1077.0000 1.0000
22.7000 1041.0000 1.0000
22.7600 1055.0000 1.0000
22.8200 1041.0000 1.0000
22.8800 1050.0000 1.0000
22.9400 1035.0000 1.0000
23.0000 1049.0000 1.0000
23.0600 968.0000 1.0000
23.1200 961.0000 1.0000
23.1800 979.0000 1.0000
23.2400 1018.0000 1.0000
23.3000 928.0000 1.0000
23.3600 986.0000 1.0000
23.4200 1032.0000 1.0000
23.4800 971.0000 1.0000
23.5400 969.0000 1.0000
23.6000 999.0000 1.0000
23.6600 951.0000 1.0000
23.7200 1000.0000 1.0000
23.7800 919.0000 1.0000
23.8400 983.0000 1.0000
23.9000 899.0000 1.0000
23.9600 936.0000 1.0000
24.0200 984.0000 1.0000
24.0800 953.0000 1.0000
24.1400 919.0000 1.0000
24.2000 918.0000 1.0000
24.2600 940.0000 1.0000
24.3200 970.0000 1.0000
24.3800 947.0000 1.0000
24.4400 897.0000 1.0000
24.5000 968.0000 1.0000
24.5600 820.0000 1.0000
24.6200 918.0000 1.0000
24.6800 980.0000 1.0000
24.7400 951.0000 1.0000
24.8000 868.0000 1.0000
24.8600 856.0000 1.0000
24.9200 872.0000 1.0000
24.9800 860.0000 1.0000
25.0400 803.0000 1.0000
25.1000 845.0000 1.0000
25.1600 864.0000 1.0000
25.2200 870.0000 1.0000
25.2800 847.0000 1.0000
25.3400 872.0000 1.0000
25.4000 793.0000 1.0000
25.4600 845.0000 1.0000
25.5200 890.0000 1.0000
25.5800 803.0000 1.0000
25.6400 791.0000 1.0000
25.7000 822.0000 1.0000
25.7600 807.0000 1.0000
25.8200 821.0000 1.0000
25.8800 826.0000 1.0000
25.9400 809.0000 1.0000
26.0000 769.0000 1.0000
26.0600 822.0000 1.0000
26.1200 729.0000 1.0000
26.1800 768.0000 1.0000
26.2400 802.0000 1.0000
26.3000 739.0000 1.0000
26.3600 811.0000 1.0000
26.4200 731.0000 1.0000
26.4800 818.0000 1.0000
26.5400 792.0000 1.0000
26.6000 768.0000 1.0000
26.6600 730.0000 1.0000
26.7200 800.0000 1.0000
26.7800 768.0000 1.0000
26.8400 734.0000 1.0000
26.9000 734.0000 1.0000
26.9600 775.0000 1.0000
27.0200 787.0000 1.0000
27.0800 810.0000 1.0000
27.1400 832.0000 1.0000
27.2000 894.0000 1.0000
27.2600 941.0000 1.0000
27.3200 1014.0000 1.0000
27.3800 942.0000 1.0000
27.4400 817.0000 1.0000
27.5000 791.0000 1.0000
27.5600 744.0000 1.0000
27.6200 744.0000 1.0000
27.6800 780.0000 1.0000
27.7400 718.0000 1.0000
27.8000 693.0000 1.0000
27.8600 681.0000 1.0000
27.9200 706.0000 1.0000
27.9800 704.0000 1.0000
28.0400 740.0000 1.0000
28.1000 755.0000 1.0000
28.1600 674.0000 1.0000
28.2200 686.0000 1.0000
28.2800 710.0000 1.0000
28.3400 634.0000 1.0000
28.4000 684.0000 1.0000
28.4600 691.0000 1.0000
28.5200 696.0000 1.0000
28.5800 599.0000 1.0000
28.6400 675.0000 1.0000
28.7000 647.0000 1.0000
28.7600 638.0000 1.0000
28.8200 599.0000 1.0000
28.8800 622.0000 1.0000
28.9400 633.0000 1.0000
29.0000 634.0000 1.0000
29.0600 654.0000 1.0000
29.1200 633.0000 1.0000
29.1800 643.0000 1.0000
29.2400 609.0000 1.0000
29.3000 599.0000 1.0000
29.3600 647.0000 1.0000
29.4200 630.0000 1.0000
29.4800 644.0000 1.0000
29.5400 638.0000 1.0000
29.6000 637.0000 1.0000
29.6600 584.0000 1.0000
29.7200 603.0000 1.0000
29.7800 652.0000 1.0000
29.8400 578.0000 1.0000
29.9000 612.0000 1.0000
29.9600 584.0000 1.0000
30.0200 557.0000 1.0000
30.0800 603.0000 1.0000
30.1400 599.0000 1.0000
30.2000 571.0000 1.0000
30.2600 598.0000 1.0000
30.3200 568.0000 1.0000
30.3800 593.0000 1.0000
30.4400 587.0000 1.0000
30.5000 584.0000 1.0000
30.5600 583.0000 1.0000
30.6200 567.0000 1.0000
30.6800 543.0000 1.0000
30.7400 537.0000 1.0000
30.8000 575.0000 1.0000
30.8600 549.0000 1.0000
30.9200 518.0000 1.0000
30.9800 565.0000 1.0000
31.0400 539.0000 1.0000
31.1000 559.0000 1.0000
31.1600 544.0000 1.0000
31.2200 511.0000 1.0000
31.2800 542.0000 1.0000
31.3400 537.0000 1.0000
31.4000 523.0000 1.0000
31.4600 534.0000 1.0000
31.5200 527.0000 1.0000
31.5800 491.0000 1.0000
31.6400 541.0000 1.0000
31.7000 534.0000 1.0000
31.7600 527.0000 1.0000
31.8200 577.0000 1.0000
31.8800 510.0000 1.0000
31.9400 537.0000 1.0000
32.0000 512.0000 1.0000
32.0600 500.0000 1.0000
32.1200 521.0000 1.0000
32.1800 488.0000 1.0000
32.2400 500.0000 1.0000
32.3000 478.0000 1.0000
32.3600 493.0000 1.0000
32.4200 527.0000 1.0000
32.4800 495.0000 1.0000
32.5400 526.0000 1.0000
32.6000 509.0000 1.0000
32.6600 459.0000 1.0000
32.7200 498.0000 1.0000
32.7800 480.0000 1.0000
32.8400 469.0000 1.0000
32.9000 500.0000 1.0000
32.9600 482.0000 1.0000
33.0200 489.0000 1.0000
33.0800 507.0000 1.0000
33.1400 484.0000 1.0000
33.2000 422.0000 1.0000
33.2600 480.0000 1.0000
33.3200 448.0000 1.0000
33.3800 482.0000 1.0000
33.4400 464.0000 1.0000
33.5000 452.0000 1.0000
33.5600 449.0000 1.0000
33.6200 453.0000 1.0000
33.6800 468.0000 1.0000
33.7400 450.0000 1.0000
33.8000 452.0000 1.0000
33.8600 477.0000 1.0000
33.9200 443.0000 1.0000
33.9800 450.0000 1.0000
34.0400 485.0000 1.0000
34.1000 438.0000 1.0000
34.1600 426.0000 1.0000
34.2200 462.0000 1.0000
34.2800 443.0000 1.0000
34.3400 502.0000 1.0000
34.4000 500.0000 1.0000
34.4600 533.0000 1.0000
34.5200 545.0000 1.0000
34.5800 578.0000 1.0000
34.6400 503.0000 1.0000
34.7000 461.0000 1.0000
34.7600 432.0000 1.0000
34.8200 431.0000 1.0000
34.8800 459.0000 1.0000
34.9400 385.0000 1.0000
35.0000 407.0000 1.0000
35.0600 416.0000 1.0000
35.1200 437.0000 1.0000
35.1800 378.0000 1.0000
35.2400 406.0000 1.0000
35.3000 414.0000 1.0000
35.3600 413.0000 1.0000
35.4200 410.0000 1.0000
35.4800 408.0000 1.0000
35.5400 384.0000 1.0000
35.6000 381.0000 1.0000
35.6600 341.0000 1.0000
35.7200 415.0000 1.0000
35.7800 390.0000 1.0000
35.8400 388.0000 1.0000
35.9000 423.0000 1.0000
35.9600 400.0000 1.0000
36.0200 383.0000 1.0000
36.0800 372.0000 1.0000
36.1400 412.0000 1.0000
36.2000 378.0000 1.0000
36.2600 429.0000 1.0000
36.3200 417.0000 1.0000
36.3800 457.0000 1.0000
36.4400 437.0000 1.0000
36.5000 413.0000 1.0000
36.5600 379.0000 1.0000
36.6200 386.0000 1.0000
36.6800 417.0000 1.0000
36.7400 368.0000 1.0000
36.8000 379.0000 1.0000
36.8600 380.0000 1.0000
36.9200 351.0000 1.0000
36.9800 388.0000 1.0000
37.0400 357.0000 1.0000
37.1000 343.0000 1.0000
37.1600 327.0000 1.0000
37.2200 351.0000 1.0000
37.2800 325.0000 1.0000
37.3400 325.0000 1.0000
37.4000 377.0000 1.0000
37.4600 355.0000 1.0000
37.5200 346.0000 1.0000
37.5800 337.0000 1.0000
37.6400 326.0000 1.0000
37.7000 340.0000 1.0000
37.7600 369.0000 1.0000
37.8200 351.0000 1.0000
37.8800 327.0000 1.0000
37.9400 350.0000 1.0000
38.0000 345.0000 1.0000
38.0600 325.0000 1.0000
38.1200 345.0000 1.0000
38.1800 356.0000 1.0000
38.2400 353.0000 1.0000
38.3000 376.0000 1.0000
38.3600 416.0000 1.0000
38.4200 503.0000 1.0000
38.4800 624.0000 1.0000
38.5400 684.0000 1.0000
38.6000 659.0000 1.0000
38.6600 579.0000 1.0000
38.7200 480.0000 1.0000
38.7800 421.0000 1.0000
38.8400 346.0000 1.0000
38.9000 376.0000 1.0000
38.9600 310.0000 1.0000
39.0200 309.0000 1.0000
39.0800 327.0000 1.0000
39.1400 328.0000 1.0000
39.2000 329.0000 1.0000
39.2600 328.0000 1.0000
39.3200 281.0000 1.0000
39.3800 332.0000 1.0000
39.4400 309.0000 1.0000
39.5000 313.0000 1.0000
39.5600 342.0000 1.0000
39.6200 303.0000 1.0000
39.6800 310.0000 1.0000
39.7400 288.0000 1.0000
39.8000 270.0000 1.0000
39.8600 302.0000 1.0000
39.9200 288.0000 1.0000
39.9800 290.0000 1.0000
40.0400 277.0000 1.0000
40.1000 290.0000 1.0000
40.1600 296.0000 1.0000
40.2200 270.0000 1.0000
40.2800 303.0000 1.0000
40.3400 289.0000 1.0000
40.4000 302.0000 1.0000
40.4600 272.0000 1.0000
40.5200 294.0000 1.0000
40.5800 263.0000 1.0000
40.6400 267.0000 1.0000
40.7000 305.0000 1.0000
40.7600 279.0000 1.0000
40.8200 278.0000 1.0000
40.8800 270.0000 1.0000
40.9400 266.0000 1.0000
41.0000 279.0000 1.0000
41.0600 268.0000 1.0000
41.1200 280.0000 1.0000
41.1800 266.0000 1.0000
41.2400 257.0000 1.0000
41.3000 279.0000 1.0000
41.3600 267.0000 1.0000
41.4200 277.0000 1.0000
41.4800 274.0000 1.0000
41.5400 260.0000 1.0000
41.6000 279.0000 1.0000
41.6600 248.0000 1.0000
41.7200 273.0000 1.0000
41.7800 286.0000 1.0000
41.8400 271.0000 1.0000
41.9000 263.0000 1.0000
41.9600 240.0000 1.0000
42.0200 267.0000 1.0000
42.0800 265.0000 1.0000
42.1400 256.0000 1.0000
42.2000 250.0000 1.0000
42.2600 263.0000 1.0000
42.3200 259.0000 1.0000
42.3800 257.0000 1.0000
42.4400 238.0000 1.0000
42.5000 236.0000 1.0000
42.5600 231.0000 1.0000
42.6200 274.0000 1.0000
42.6800 252.0000 1.0000
42.7400 262.0000 1.0000
42.8000 249.0000 1.0000
42.8600 237.0000 1.0000
42.9200 250.0000 1.0000
42.9800 241.0000 1.0000
43.0400 258.0000 1.0000
43.1000 243.0000 1.0000
43.1600 243.0000 1.0000
43.2200 256.0000 1.0000
43.2800 259.0000 1.0000
43.3400 265.0000 1.0000
43.4000 249.0000 1.0000
43.4600 268.0000 1.0000
43.5200 199.0000 1.0000
43.5800 256.0000 1.0000
43.6400 240.0000 1.0000
43.7000 226.0000 1.0000
43.7600 246.0000 1.0000
43.8200 264.0000 1.0000
43.8800 246.0000 1.0000
43.9400 228.0000 1.0000
44.0000 216.0000 1.0000
44.0600 239.0000 1.0000
44.1200 232.0000 1.0000
44.1800 230.0000 1.0000
44.2400 245.0000 1.0000
44.3000 246.0000 1.0000
44.3600 243.0000 1.0000
44.4200 249.0000 1.0000
44.4800 252.0000 1.0000
44.5400 225.0000 1.0000
44.6000 230.0000 1.0000
44.6600 214.0000 1.0000
44.7200 212.0000 1.0000
44.7800 237.0000 1.0000
44.8400 260.0000 1.0000
44.9000 246.0000 1.0000
44.9600 226.0000 1.0000
45.0200 205.0000 1.0000
45.0800 217.0000 1.0000
45.1400 226.0000 1.0000
45.2000 232.0000 1.0000
45.2600 231.0000 1.0000
45.3200 236.0000 1.0000
45.3800 215.0000 1.0000
45.4400 202.0000 1.0000
45.5000 206.0000 1.0000
45.5600 216.0000 1.0000
45.6200 222.0000 1.0000
45.6800 215.0000 1.0000
45.7400 206.0000 1.0000
45.8000 224.0000 1.0000
45.8600 200.0000 1.0000
45.9200 236.0000 1.0000
45.9800 224.0000 1.0000
46.0400 226.0000 1.0000
46.1000 223.0000 1.0000
46.1600 233.0000 1.0000
46.2200 220.0000 1.0000
46.2800 225.0000 1.0000
46.3400 213.0000 1.0000
46.4000 221.0000 1.0000
46.4600 208.0000 1.0000
46.5200 231.0000 1.0000
46.5800 222.0000 1.0000
46.6400 211.0000 1.0000
46.7000 218.0000 1.0000
46.7600 221.0000 1.0000
46.8200 220.0000 1.0000
46.8800 208.0000 1.0000
46.9400 214.0000 1.0000
47.0000 203.0000 1.0000
47.0600 192.0000 1.0000
47.1200 215.0000 1.0000
47.1800 205.0000 1.0000
47.2400 215.0000 1.0000
47.3000 187.0000 1.0000
47.3600 204.0000 1.0000
47.4200 218.0000 1.0000
47.4800 195.0000 1.0000
47.5400 184.0000 1.0000
47.6000 205.0000 1.0000
47.6600 203.0000 1.0000
47.7200 210.0000 1.0000
47.7800 213.0000 1.0000
47.8400 208.0000 1.0000
47.9000 212.0000 1.0000
47.9600 181.0000 1.0000
48.0200 213.0000 1.0000
48.0800 185.0000 1.0000
48.1400 203.0000 1.0000
48.2000 178.0000 1.0000
48.2600 189.0000 1.0000
48.3200 194.0000 1.0000
48.3800 176.0000 1.0000
48.4400 167.0000 1.0000
48.5000 208.0000 1.0000
48.5600 203.0000 1.0000
48.6200 214.0000 1.0000
48.6800 195.0000 1.0000
48.7400 174.0000 1.0000
48.8000 197.0000 1.0000
48.8600 185.0000 1.0000
48.9200 197.0000 1.0000
48.9800 213.0000 1.0000
49.0400 214.0000 1.0000
49.1000 188.0000 1.0000
49.1600 191.0000 1.0000
49.2200 174.0000 1.0000
49.2800 197.0000 1.0000
49.3400 176.0000 1.0000
49.4000 207.0000 1.0000
49.4600 191.0000 1.0000
49.5200 185.0000 1.0000
49.5800 194.0000 1.0000
49.6400 176.0000 1.0000
49.7000 181.0000 1.0000
49.7600 221.0000 1.0000
49.8200 196.0000 1.0000
49.8800 204.0000 1.0000
49.9400 187.0000 1.0000
50.0000 193.0000 1.0000
50.0600 212.0000 1.0000
50.1200 181.0000 1.0000
50.1800 194.0000 1.0000
50.2400 197.0000 1.0000
50.3000 210.0000 1.0000
50.3600 181.0000 1.0000
50.4200 193.0000 1.0000
50.4800 186.0000 1.0000
50.5400 208.0000 1.0000
50.6000 182.0000 1.0000
50.6600 217.0000 1.0000
50.7200 195.0000 1.0000
50.7800 206.0000 1.0000
50.8400 194.0000 1.0000
50.9000 190.0000 1.0000
50.9600 193.0000 1.0000
51.0200 187.0000 1.0000
51.0800 186.0000 1.0000
51.1400 184.0000 1.0000
51.2000 177.0000 1.0000
51.2600 187.0000 1.0000
51.3200 190.0000 1.0000
51.3800 206.0000 1.0000
51.4400 164.0000 1.0000
51.5000 179.0000 1.0000
51.5600 185.0000 1.0000
51.6200 194.0000 1.0000
51.6800 178.0000 1.0000
51.7400 193.0000 1.0000
51.8000 184.0000 1.0000
51.8600 185.0000 1.0000
51.9200 185.0000 1.0000
51.9800 204.0000 1.0000
52.0400 212.0000 1.0000
52.1000 282.0000 1.0000
52.1600 428.0000 1.0000
52.2200 580.0000 1.0000
52.2800 741.0000 1.0000
52.3400 690.0000 1.0000
52.4000 537.0000 1.0000
52.4600 461.0000 1.0000
52.5200 347.0000 1.0000
52.5800 291.0000 1.0000
52.6400 243.0000 1.0000
52.7000 235.0000 1.0000
52.7600 211.0000 1.0000
52.8200 177.0000 1.0000
52.8800 185.0000 1.0000
52.9400 190.0000 1.0000
53.0000 198.0000 1.0000
53.0600 188.0000 1.0000
53.1200 173.0000 1.0000
53.1800 186.0000 1.0000
53.2400 191.0000 1.0000
53.3000 154.0000 1.0000
53.3600 171.0000 1.0000
53.4200 195.0000 1.0000
53.4800 181.0000 1.0000
53.5400 156.0000 1.0000
53.6000 173.0000 1.0000
53.6600 178.0000 1.0000
53.7200 182.0000 1.0000
53.7800 163.0000 1.0000
53.8400 180.0000 1.0000
53.9000 179.0000 1.0000
53.9600 165.0000 1.0000
54.0200 194.0000 1.0000
54.0800 167.0000 1.0000
54.1400 180.0000 1.0000
54.2000 181.0000 1.0000
54.2600 171.0000 1.0000
54.3200 168.0000 1.0000
54.3800 178.0000 1.0000
54.4400 189.0000 1.0000
54.5000 159.0000 1.0000
54.5600 186.0000 1.0000
54.6200 195.0000 1.0000
54.6800 171.0000 1.0000
54.7400 178.0000 1.0000
54.8000 180.0000 1.0000
54.8600 181.0000 1.0000
54.9200 181.0000 1.0000
54.9800 165.0000 1.0000
55.0400 181.0000 1.0000
55.1000 196.0000 1.0000
55.1600 219.0000 1.0000
55.2200 240.0000 1.0000
55.2800 243.0000 1.0000
55.3400 228.0000 1.0000
55.4000 213.0000 1.0000
55.4600 217.0000 1.0000
55.5200 195.0000 1.0000
55.5800 201.0000 1.0000
55.6400 175.0000 1.0000
55.7000 197.0000 1.0000
55.7600 166.0000 1.0000
55.8200 170.0000 1.0000
55.8800 151.0000 1.0000
55.9400 162.0000 1.0000
56.0000 177.0000 1.0000
56.0600 168.0000 1.0000
56.1200 177.0000 1.0000
56.1800 161.0000 1.0000
56.2400 165.0000 1.0000
56.3000 167.0000 1.0000
56.3600 172.0000 1.0000
56.4200 160.0000 1.0000
56.4800 175.0000 1.0000
56.5400 159.0000 1.0000
56.6000 178.0000 1.0000
56.6600 153.0000 1.0000
56.7200 172.0000 1.0000
56.7800 175.0000 1.0000
56.8400 185.0000 1.0000
56.9000 173.0000 1.0000
56.9600 162.0000 1.0000
57.0200 163.0000 1.0000
57.0800 171.0000 1.0000
57.1400 157.0000 1.0000
57.2000 160.0000 1.0000
57.2600 150.0000 1.0000
57.3200 170.0000 1.0000
57.3800 171.0000 1.0000
57.4400 157.0000 1.0000
57.5000 191.0000 1.0000
57.5600 169.0000 1.0000
57.6200 162.0000 1.0000
57.6800 143.0000 1.0000
57.7400 190.0000 1.0000
57.8000 162.0000 1.0000
57.8600 156.0000 1.0000
57.9200 170.0000 1.0000
57.9800 165.0000 1.0000
58.0400 157.0000 1.0000
58.1000 172.0000 1.0000
58.1600 151.0000 1.0000
58.2200 159.0000 1.0000
58.2800 152.0000 1.0000
58.3400 168.0000 1.0000
58.4000 182.0000 1.0000
58.4600 165.0000 1.0000
58.5200 178.0000 1.0000
58.5800 197.0000 1.0000
58.6400 150.0000 1.0000
58.7000 166.0000 1.0000
58.7600 177.0000 1.0000
58.8200 161.0000 1.0000
58.8800 181.0000 1.0000
58.9400 168.0000 1.0000
59.0000 164.0000 1.0000
59.0600 155.0000 1.0000
59.1200 158.0000 1.0000
59.1800 142.0000 1.0000
59.2400 149.0000 1.0000
59.3000 155.0000 1.0000
59.3600 159.0000 1.0000
59.4200 156.0000 1.0000
59.4800 149.0000 1.0000
59.5400 171.0000 1.0000
59.6000 167.0000 1.0000
59.6600 172.0000 1.0000
59.7200 137.0000 1.0000
59.7800 149.0000 1.0000
59.8400 172.0000 1.0000
59.9000 146.0000 1.0000
59.9600 179.0000 1.0000
60.0200 159.0000 1.0000
60.0800 155.0000 1.0000
60.1400 160.0000 1.0000
60.2000 152.0000 1.0000
60.2600 146.0000 1.0000
60.3200 175.0000 1.0000
60.3800 146.0000 1.0000
60.4400 177.0000 1.0000
60.5000 187.0000 1.0000
60.5600 166.0000 1.0000
60.6200 160.0000 1.0000
60.6800 155.0000 1.0000
60.7400 174.0000 1.0000
60.8000 171.0000 1.0000
60.8600 174.0000 1.0000
60.9200 179.0000 1.0000
60.9800 144.0000 1.0000
61.0400 146.0000 1.0000
61.1000 180.0000 1.0000
61.1600 149.0000 1.0000
61.2200 152.0000 1.0000
61.2800 154.0000 1.0000
61.3400 156.0000 1.0000
61.4000 157.0000 1.0000
61.4600 166.0000 1.0000
61.5200 167.0000 1.0000
61.5800 186.0000 1.0000
61.6400 173.0000 1.0000
61.7000 180.0000 1.0000
61.7600 170.0000 1.0000
61.8200 165.0000 1.0000
61.8800 173.0000 1.0000
61.9400 188.0000 1.0000
62.0000 161.0000 1.0000
62.0600 194.0000 1.0000
62.1200 210.0000 1.0000
62.1800 217.0000 1.0000
62.2400 284.0000 1.0000
62.3000 289.0000 1.0000
62.3600 274.0000 1.0000
62.4200 295.0000 1.0000
62.4800 229.0000 1.0000
62.5400 202.0000 1.0000
62.6000 219.0000 1.0000
62.6600 201.0000 1.0000
62.7200 159.0000 1.0000
62.7800 185.0000 1.0000
62.8400 186.0000 1.0000
62.9000 159.0000 1.0000
62.9600 169.0000 1.0000
63.0200 167.0000 1.0000
63.0800 191.0000 1.0000
63.1400 167.0000 1.0000
63.2000 167.0000 1.0000
63.2600 181.0000 1.0000
63.3200 181.0000 1.0000
63.3800 170.0000 1.0000
63.4400 144.0000 1.0000
63.5000 181.0000 1.0000
63.5600 156.0000 1.0000
63.6200 177.0000 1.0000
63.6800 162.0000 1.0000
63.7400 167.0000 1.0000
63.8000 178.0000 1.0000
63.8600 156.0000 1.0000
63.9200 165.0000 1.0000
63.9800 139.0000 1.0000
64.0400 168.0000 1.0000
64.1000 165.0000 1.0000
64.1600 160.0000 1.0000
64.2200 153.0000 1.0000
64.2800 151.0000 1.0000
64.3400 181.0000 1.0000
64.4000 155.0000 1.0000
64.4600 193.0000 1.0000
64.5200 187.0000 1.0000
64.5800 181.0000 1.0000
64.6400 212.0000 1.0000
64.7000 256.0000 1.0000
64.7600 190.0000 1.0000
64.8200 220.0000 1.0000
64.8800 183.0000 1.0000
64.9400 198.0000 1.0000
65.0000 184.0000 1.0000
65.0600 183.0000 1.0000
65.1200 164.0000 1.0000
65.1800 148.0000 1.0000
65.2400 174.0000 1.0000
65.3000 176.0000 1.0000
65.3600 163.0000 1.0000
65.4200 152.0000 1.0000
65.4800 164.0000 1.0000
65.5400 156.0000 1.0000
65.6000 165.0000 1.0000
65.6600 156.0000 1.0000
65.7200 177.0000 1.0000
65.7800 176.0000 1.0000
65.8400 154.0000 1.0000
65.9000 181.0000 1.0000
65.9600 167.0000 1.0000
66.0200 219.0000 1.0000
66.0800 250.0000 1.0000
66.1400 321.0000 1.0000
66.2000 421.0000 1.0000
66.2600 456.0000 1.0000
66.3200 442.0000 1.0000
66.3800 423.0000 1.0000
66.4400 366.0000 1.0000
66.5000 359.0000 1.0000
66.5600 271.0000 1.0000
66.6200 247.0000 1.0000
66.6800 223.0000 1.0000
66.7400 207.0000 1.0000
66.8000 187.0000 1.0000
66.8600 169.0000 1.0000
66.9200 178.0000 1.0000
66.9800 172.0000 1.0000
67.0400 172.0000 1.0000
67.1000 151.0000 1.0000
67.1600 152.0000 1.0000
67.2200 159.0000 1.0000
67.2800 138.0000 1.0000
67.3400 172.0000 1.0000
67.4000 169.0000 1.0000
67.4600 139.0000 1.0000
67.5200 163.0000 1.0000
67.5800 165.0000 1.0000
67.6400 145.0000 1.0000
67.7000 156.0000 1.0000
67.7600 144.0000 1.0000
67.8200 145.0000 1.0000
67.8800 166.0000 1.0000
67.9400 143.0000 1.0000
68.0000 144.0000 1.0000
68.0600 144.0000 1.0000
68.1200 136.0000 1.0000
68.1800 153.0000 1.0000
68.2400 152.0000 1.0000
68.3000 145.0000 1.0000
68.3600 148.0000 1.0000
68.4200 164.0000 1.0000
68.4800 148.0000 1.0000
68.5400 166.0000 1.0000
68.6000 151.0000 1.0000
68.6600 145.0000 1.0000
68.7200 135.0000 1.0000
68.7800 153.0000 1.0000
68.8400 146.0000 1.0000
68.9000 135.0000 1.0000
68.9600 157.0000 1.0000
69.0200 161.0000 1.0000
69.0800 172.0000 1.0000
69.1400 158.0000 1.0000
69.2000 146.0000 1.0000
69.2600 172.0000 1.0000
69.3200 146.0000 1.0000
69.3800 146.0000 1.0000
69.4400 162.0000 1.0000
69.5000 162.0000 1.0000
69.5600 135.0000 1.0000
69.6200 139.0000 1.0000
69.6800 132.0000 1.0000
69.7400 151.0000 1.0000
69.8000 137.0000 1.0000
69.8600 143.0000 1.0000
69.9200 168.0000 1.0000
69.9800 171.0000 1.0000
70.0400 124.0000 1.0000
70.1000 142.0000 1.0000
70.1600 145.0000 1.0000
70.2200 155.0000 1.0000
70.2800 119.0000 1.0000
70.3400 141.0000 1.0000
70.4000 132.0000 1.0000
70.4600 147.0000 1.0000
70.5200 126.0000 1.0000
70.5800 158.0000 1.0000
70.6400 156.0000 1.0000
70.7000 141.0000 1.0000
70.7600 161.0000 1.0000
70.8200 146.0000 1.0000
70.8800 162.0000 1.0000
70.9400 141.0000 1.0000
71.0000 132.0000 1.0000
71.0600 144.0000 1.0000
71.1200 158.0000 1.0000
71.1800 154.0000 1.0000
71.2400 151.0000 1.0000
71.3000 160.0000 1.0000
71.3600 133.0000 1.0000
71.4200 156.0000 1.0000
71.4800 156.0000 1.0000
71.5400 154.0000 1.0000
71.6000 158.0000 1.0000
71.6600 165.0000 1.0000
71.7200 130.0000 1.0000
71.7800 174.0000 1.0000
71.8400 160.0000 1.0000
71.9000 174.0000 1.0000
71.9600 150.0000 1.0000
72.0200 160.0000 1.0000
72.0800 150.0000 1.0000
72.1400 137.0000 1.0000
72.2000 123.0000 1.0000
72.2600 149.0000 1.0000
72.3200 135.0000 1.0000
72.3800 142.0000 1.0000
72.4400 151.0000 1.0000
72.5000 136.0000 1.0000
72.5600 147.0000 1.0000
72.6200 166.0000 1.0000
72.6800 145.0000 1.0000
72.7400 166.0000 1.0000
72.8000 144.0000 1.0000
72.8600 129.0000 1.0000
72.9200 133.0000 1.0000
72.9800 146.0000 1.0000
73.0400 161.0000 1.0000
73.1000 143.0000 1.0000
73.1600 152.0000 1.0000
73.2200 155.0000 1.0000
73.2800 137.0000 1.0000
73.3400 133.0000 1.0000
73.4000 140.0000 1.0000
73.4600 129.0000 1.0000
73.5200 148.0000 1.0000
73.5800 139.0000 1.0000
73.6400 159.0000 1.0000
73.7000 143.0000 1.0000
73.7600 147.0000 1.0000
73.8200 146.0000 1.0000
73.8800 146.0000 1.0000
73.9400 154.0000 1.0000
74.0000 151.0000 1.0000
74.0600 146.0000 1.0000
74.1200 136.0000 1.0000
74.1800 111.0000 1.0000
74.2400 152.0000 1.0000
74.3000 144.0000 1.0000
74.3600 127.0000 1.0000
74.4200 135.0000 1.0000
74.4800 145.0000 1.0000
74.5400 126.0000 1.0000
74.6000 131.0000 1.0000
74.6600 145.0000 1.0000
74.7200 148.0000 1.0000
74.7800 142.0000 1.0000
74.8400 144.0000 1.0000
74.9000 138.0000 1.0000
74.9600 115.0000 1.0000
75.0200 138.0000 1.0000
75.0800 141.0000 1.0000
75.1400 140.0000 1.0000
75.2000 150.0000 1.0000
75.2600 141.0000 1.0000
75.3200 141.0000 1.0000
75.3800 133.0000 1.0000
75.4400 138.0000 1.0000
75.5000 123.0000 1.0000
75.5600 137.0000 1.0000
75.6200 154.0000 1.0000
75.6800 151.0000 1.0000
75.7400 140.0000 1.0000
75.8000 139.0000 1.0000
75.8600 121.0000 1.0000
75.9200 162.0000 1.0000
75.9800 155.0000 1.0000
76.0400 151.0000 1.0000
76.1000 169.0000 1.0000
76.1600 136.0000 1.0000
76.2200 145.0000 1.0000
76.2800 144.0000 1.0000
76.3400 137.0000 1.0000
76.4000 141.0000 1.0000
76.4600 124.0000 1.0000
76.5200 137.0000 1.0000
76.5800 137.0000 1.0000
76.6400 120.0000 1.0000
76.7000 133.0000 1.0000
76.7600 150.0000 1.0000
76.8200 144.0000 1.0000
76.8800 137.0000 1.0000
76.9400 135.0000 1.0000
77.0000 139.0000 1.0000
77.0600 135.0000 1.0000
77.1200 140.0000 1.0000
77.1800 135.0000 1.0000
77.2400 144.0000 1.0000
77.3000 125.0000 1.0000
77.3600 134.0000 1.0000
77.4200 134.0000 1.0000
77.4800 124.0000 1.0000
77.5400 130.0000 1.0000
77.6000 147.0000 1.0000
77.6600 140.0000 1.0000
77.7200 124.0000 1.0000
77.7800 138.0000 1.0000
77.8400 154.0000 1.0000
77.9000 117.0000 1.0000
77.9600 118.0000 1.0000
78.0200 122.0000 1.0000
78.0800 122.0000 1.0000
78.1400 127.0000 1.0000
78.2000 146.0000 1.0000
78.2600 119.0000 1.0000
78.3200 144.0000 1.0000
78.3800 133.0000 1.0000
78.4400 143.0000 1.0000
78.5000 152.0000 1.0000
78.5600 141.0000 1.0000
78.6200 128.0000 1.0000
78.6800 156.0000 1.0000
78.7400 132.0000 1.0000
78.8000 151.0000 1.0000
78.8600 203.0000 1.0000
78.9200 176.0000 1.0000
78.9800 181.0000 1.0000
79.0400 174.0000 1.0000
79.1000 188.0000 1.0000
79.1600 203.0000 1.0000
79.2200 190.0000 1.0000
79.2800 183.0000 1.0000
79.3400 177.0000 1.0000
79.4000 143.0000 1.0000
79.4600 170.0000 1.0000
79.5200 136.0000 1.0000
79.5800 156.0000 1.0000
79.6400 142.0000 1.0000
79.7000 141.0000 1.0000
79.7600 130.0000 1.0000
79.8200 137.0000 1.0000
79.8800 149.0000 1.0000
79.9400 130.0000 1.0000
80.0000 153.0000 1.0000
*RAS_INT_END
*RAS_TEMPERATURE_START
*RAS_TEMPERATURE_END
*RAS_DATA_END