File: Section2_75_samples/XRD/No_032_FS1_4.ras
*RAS_DATA_START
*RAS_HEADER_START
*DISP_FMT_X "%.2f"
*DISP_FMT_Y "%.0f"
*DISP_FULLSCALE "13380.0000000000"
*DISP_LINE_COLOR "255.0000000000"
*DISP_LINE_STYLE "0.0000000000"
*DISP_LINE_WIDTH "0.2500000000"
*DISP_NOTE "測定データ-1"
*DISP_OFFSET_Y "0.0000000000"
*DISP_PEAKSEARCH_UNIT_Y "cps"
*DISP_RANGE_BOTTOM "0.0000000000"
*DISP_RANGE_LEFT "20.0000000000"
*DISP_RANGE_LOGCUTOFF "0.0100000000"
*DISP_RANGE_RIGHT "70.0000000000"
*DISP_RANGE_TOP "13380.0000000000"
*DISP_SCALE_MODE_Y "0.0000000000"
*DISP_TAB_NAME "2θ/θ"
*DISP_TITLE_Y "強度"
*DISP_UNIT_Y "cps"
*DISP_WINDOW_NAME "MSG_MACROENGINE"
*FILE_COMMENT " "
*FILE_MD5 ""
*FILE_MEMO " "
*FILE_OPERATOR "Administrator"
*FILE_SAMPLE " "
*FILE_TYPE "RAS_RAW"
*FILE_USERGROUP "システムマネージャ"
*FILE_VERSION "1.0000000000"
*HW_ATTACHMENT_ID "ATT0025"
*HW_ATTACHMENT_NAME "標準|Standard"
*HW_COUNTER_ID-0 "CUT0025"
*HW_COUNTER_ID-1 "CUT0020"
*HW_COUNTER_ID-2 "CUT0020"
*HW_COUNTER_ID-3 "CSL0021"
*HW_COUNTER_ID-4 "CMC0021"
*HW_COUNTER_NAME-0 "D/teX Ultra|D/teX Ultra"
*HW_COUNTER_NAME-1 "None|None"
*HW_COUNTER_NAME-2 "None|None"
*HW_COUNTER_NAME-3 "BBM|BBM"
*HW_COUNTER_NAME-4 "検出器モノクロメータ|Detector monochromator"
*HW_COUNTER_SELECT_NAME "D/teX Ultra|D/teX Ultra"
*HW_GONIOMETER_ID "GON0023"
*HW_GONIOMETER_NAME "SmartLab|SmartLab"
*HW_GONIOMETER_RADIUS-0 "90.0"
*HW_GONIOMETER_RADIUS-1 "114.0"
*HW_GONIOMETER_RADIUS-2 "190.0"
*HW_GONIOMETER_RADIUS-3 "300.0"
*HW_GONIOMETER_RADIUS-4 "187.0"
*HW_GONIOMETER_RADIUS-5 "300.0"
*HW_GONIOMETER_RADIUS-6 "113.0"
*HW_GONIOMETER_RADIUS-7 "331.0"
*HW_I_OPT_ID-0 "CBO0021"
*HW_I_OPT_ID-1 "ICR0023"
*HW_I_OPT_ID-2 "ISL0021"
*HW_I_OPT_ID-3 "ISO0021"
*HW_I_OPT_ID-4 "IAD0021"
*HW_I_OPT_ID-5 "IPR0001"
*HW_I_OPT_NAME-0 "CBOユニット|CBO unit"
*HW_I_OPT_NAME-1 "標準入射光学ユニット|Standard incident optical unit"
*HW_I_OPT_NAME-2 "標準入射スリットボックス|Standard incident slit box"
*HW_I_OPT_NAME-3 "入射平行スリット|Incident parallel slit"
*HW_I_OPT_NAME-4 "長手制限スリット|Length limiting slit"
*HW_I_OPT_NAME-5 "None|None"
*HW_R_ATTENUATER_AUTOMODE "0"
*HW_R_OPT_ID-0 "RSS0021"
*HW_R_OPT_ID-1 "RCR0023"
*HW_R_OPT_ID-2 "RSO0021"
*HW_R_OPT_ID-3 "RRS0021"
*HW_R_OPT_ID-4 "ATN0021"
*HW_R_OPT_ID-5 "RFL0021"
*HW_R_OPT_ID-6 "RAD0021"
*HW_R_OPT_NAME-0 "標準受光スリットボックス1|Standard receiving slit box # 1"
*HW_R_OPT_NAME-1 "標準受光光学ユニット1|Standard receiving unit # 1"
*HW_R_OPT_NAME-2 "標準受光光学ユニット2|Standard receiving optical unit # 2"
*HW_R_OPT_NAME-3 "標準受光スリットボックス2|Standard receiving slit box # 2"
*HW_R_OPT_NAME-4 "標準アッテネータ|Standard Attenuator"
*HW_R_OPT_NAME-5 "Cu Kβ|Cu K-beta"
*HW_R_OPT_NAME-6 "調整用受光スリット|Alignment receiving slit"
*HW_SAMPLE_HOLDER_ID "SMP0023"
*HW_SAMPLE_HOLDER_NAME "標準Zステージ|Standard Z stage"
*HW_XG_CURRENT_MAX "50"
*HW_XG_CURRENT_MIN "2"
*HW_XG_CURRENT_RESOLUTION "1"
*HW_XG_CURRENT_UNIT "mA"
*HW_XG_FOCUS "1mm x 10mm"
*HW_XG_FOCUS_TYPE "Normal"
*HW_XG_ID ""
*HW_XG_NAME "3kW 封入管(ID:1200)|3kW Sealed tube(ID:1200)"
*HW_XG_TARGET_ATOMIC_NUMBER "29.0000000000"
*HW_XG_TARGET_NAME "Cu"
*HW_XG_TYPE "Hermetic"
*HW_XG_VOLTAGE_MAX "60"
*HW_XG_VOLTAGE_MIN "20"
*HW_XG_VOLTAGE_RESOLUTION "1"
*HW_XG_VOLTAGE_UNIT "kV"
*HW_XG_WATT_MAX "1.500"
*HW_XG_WATT_UNIT "kW"
*HW_XG_WAVE_LENGTH_ALPHA1 "1.540593"
*HW_XG_WAVE_LENGTH_ALPHA2 "1.544414"
*HW_XG_WAVE_LENGTH_BETA "1.392250"
*MEAS_COND_AXIS_NAME-0 "2θ/θ"
*MEAS_COND_AXIS_NAME-1 "2θ"
*MEAS_COND_AXIS_NAME-2 "ω"
*MEAS_COND_AXIS_NAME-3 "Z"
*MEAS_COND_AXIS_NAME-4 "2θ/ω"
*MEAS_COND_AXIS_NAME-5 "θs"
*MEAS_COND_AXIS_NAME-6 "θd"
*MEAS_COND_AXIS_NAME-7 "Ts"
*MEAS_COND_AXIS_NAME-8 "CBO選択スリット"
*MEAS_COND_AXIS_NAME-9 "M"
*MEAS_COND_AXIS_NAME-10 "入射平行スリット"
*MEAS_COND_AXIS_NAME-11 "入射スリット"
*MEAS_COND_AXIS_NAME-12 ""
*MEAS_COND_AXIS_NAME-13 "Zs"
*MEAS_COND_AXIS_NAME-14 "入射光学素子"
*MEAS_COND_AXIS_NAME-15 "長手制限スリット"
*MEAS_COND_AXIS_NAME-16 "センタースリット"
*MEAS_COND_AXIS_NAME-17 "フィルター"
*MEAS_COND_AXIS_NAME-18 "受光スリット1"
*MEAS_COND_AXIS_NAME-19 "受光スリット2"
*MEAS_COND_AXIS_NAME-20 "受光光学素子"
*MEAS_COND_AXIS_NAME-21 "受光平行スリット"
*MEAS_COND_AXIS_NAME-22 "調整用受光スリット"
*MEAS_COND_AXIS_NAME-23 ""
*MEAS_COND_AXIS_NAME-24 ""
*MEAS_COND_AXIS_NAME-25 "Zd"
*MEAS_COND_AXIS_NAME-26 "アッテネータ"
*MEAS_COND_AXIS_NAME-27 "検出器モノクロメータ"
*MEAS_COND_AXIS_NAME-28 "モノクロメータスリット"
*MEAS_COND_AXIS_NAME-29 "プライマリビーム"
*MEAS_COND_AXIS_NAME-30 "PHA"
*MEAS_COND_AXIS_NAME_INTERNAL-0 "TwoThetaTheta"
*MEAS_COND_AXIS_NAME_INTERNAL-1 "TwoTheta"
*MEAS_COND_AXIS_NAME_INTERNAL-2 "Omega"
*MEAS_COND_AXIS_NAME_INTERNAL-3 "Z"
*MEAS_COND_AXIS_NAME_INTERNAL-4 "TwoThetaOmega"
*MEAS_COND_AXIS_NAME_INTERNAL-5 "ThetaS"
*MEAS_COND_AXIS_NAME_INTERNAL-6 "ThetaD"
*MEAS_COND_AXIS_NAME_INTERNAL-7 "Ts"
*MEAS_COND_AXIS_NAME_INTERNAL-8 "CBO"
*MEAS_COND_AXIS_NAME_INTERNAL-9 "CBO-M"
*MEAS_COND_AXIS_NAME_INTERNAL-10 "IncidentSollerSlit"
*MEAS_COND_AXIS_NAME_INTERNAL-11 "IncidentSlitBox"
*MEAS_COND_AXIS_NAME_INTERNAL-12 "IncidentSlitBox-_Axis"
*MEAS_COND_AXIS_NAME_INTERNAL-13 "Zs"
*MEAS_COND_AXIS_NAME_INTERNAL-14 "IncidentMonochromator"
*MEAS_COND_AXIS_NAME_INTERNAL-15 "IncidentAxdSlit"
*MEAS_COND_AXIS_NAME_INTERNAL-16 "CenterSlit"
*MEAS_COND_AXIS_NAME_INTERNAL-17 "Filter"
*MEAS_COND_AXIS_NAME_INTERNAL-18 "ReceivingSlitBox1"
*MEAS_COND_AXIS_NAME_INTERNAL-19 "ReceivingSlitBox2"
*MEAS_COND_AXIS_NAME_INTERNAL-20 "ReceivingOptics"
*MEAS_COND_AXIS_NAME_INTERNAL-21 "ReceivingSollerSlit"
*MEAS_COND_AXIS_NAME_INTERNAL-22 "ReceivingAxdSlit"
*MEAS_COND_AXIS_NAME_INTERNAL-23 "ReceivingSlitBox1-_Axis"
*MEAS_COND_AXIS_NAME_INTERNAL-24 "ReceivingSlitBox2-_Axis"
*MEAS_COND_AXIS_NAME_INTERNAL-25 "ReceivingSlitBox2-Zd"
*MEAS_COND_AXIS_NAME_INTERNAL-26 "Attenuator"
*MEAS_COND_AXIS_NAME_INTERNAL-27 "CounterMonochromator"
*MEAS_COND_AXIS_NAME_INTERNAL-28 "CounterSlit"
*MEAS_COND_AXIS_NAME_INTERNAL-29 "IncidentPrimary"
*MEAS_COND_AXIS_NAME_INTERNAL-30 "PHA"
*MEAS_COND_AXIS_NAME_MAGICNO-0 "83951616.0000000000"
*MEAS_COND_AXIS_NAME_MAGICNO-1 "268632064.0000000000"
*MEAS_COND_AXIS_NAME_MAGICNO-2 "268500992.0000000000"
*MEAS_COND_AXIS_NAME_MAGICNO-3 "285278208.0000000000"
*MEAS_COND_AXIS_NAME_MAGICNO-4 "83951616.0000000000"
*MEAS_COND_AXIS_NAME_MAGICNO-5 "131072.0000000000"
*MEAS_COND_AXIS_NAME_MAGICNO-6 "131072.0000000000"
*MEAS_COND_AXIS_NAME_MAGICNO-7 "318898176.0000000000"
*MEAS_COND_AXIS_NAME_MAGICNO-8 "20971521.0000000000"
*MEAS_COND_AXIS_NAME_MAGICNO-9 "285343744.0000000000"
*MEAS_COND_AXIS_NAME_MAGICNO-10 "20971521.0000000000"
*MEAS_COND_AXIS_NAME_MAGICNO-11 "22020097.0000000000"
*MEAS_COND_AXIS_NAME_MAGICNO-12 "25165824.0000000000"
*MEAS_COND_AXIS_NAME_MAGICNO-13 "318898176.0000000000"
*MEAS_COND_AXIS_NAME_MAGICNO-14 "1.0000000000"
*MEAS_COND_AXIS_NAME_MAGICNO-15 "20971521.0000000000"
*MEAS_COND_AXIS_NAME_MAGICNO-16 "20971521.0000000000"
*MEAS_COND_AXIS_NAME_MAGICNO-17 "20971521.0000000000"
*MEAS_COND_AXIS_NAME_MAGICNO-18 "23068673.0000000000"
*MEAS_COND_AXIS_NAME_MAGICNO-19 "23068673.0000000000"
*MEAS_COND_AXIS_NAME_MAGICNO-20 "20971521.0000000000"
*MEAS_COND_AXIS_NAME_MAGICNO-21 "20971521.0000000000"
*MEAS_COND_AXIS_NAME_MAGICNO-22 "20971521.0000000000"
*MEAS_COND_AXIS_NAME_MAGICNO-23 "25165824.0000000000"
*MEAS_COND_AXIS_NAME_MAGICNO-24 "25165824.0000000000"
*MEAS_COND_AXIS_NAME_MAGICNO-25 "285343744.0000000000"
*MEAS_COND_AXIS_NAME_MAGICNO-26 "17301505.0000000000"
*MEAS_COND_AXIS_NAME_MAGICNO-27 "20971521.0000000000"
*MEAS_COND_AXIS_NAME_MAGICNO-28 "20971521.0000000000"
*MEAS_COND_AXIS_NAME_MAGICNO-29 "20971521.0000000000"
*MEAS_COND_AXIS_NAME_MAGICNO-30 "0.0000000000"
*MEAS_COND_AXIS_OFFSET-0 "-"
*MEAS_COND_AXIS_OFFSET-1 "-0.1081000000"
*MEAS_COND_AXIS_OFFSET-2 "0.3758000000"
*MEAS_COND_AXIS_OFFSET-3 "-"
*MEAS_COND_AXIS_OFFSET-4 "-"
*MEAS_COND_AXIS_OFFSET-5 "0.3758000000"
*MEAS_COND_AXIS_OFFSET-6 "-0.4839000000"
*MEAS_COND_AXIS_OFFSET-7 "-"
*MEAS_COND_AXIS_OFFSET-8 "-"
*MEAS_COND_AXIS_OFFSET-9 "-"
*MEAS_COND_AXIS_OFFSET-10 "-"
*MEAS_COND_AXIS_OFFSET-11 "-"
*MEAS_COND_AXIS_OFFSET-12 "-"
*MEAS_COND_AXIS_OFFSET-13 "-"
*MEAS_COND_AXIS_OFFSET-14 "-"
*MEAS_COND_AXIS_OFFSET-15 "-"
*MEAS_COND_AXIS_OFFSET-16 "-"
*MEAS_COND_AXIS_OFFSET-17 "-"
*MEAS_COND_AXIS_OFFSET-18 "-"
*MEAS_COND_AXIS_OFFSET-19 "-"
*MEAS_COND_AXIS_OFFSET-20 "-"
*MEAS_COND_AXIS_OFFSET-21 "-"
*MEAS_COND_AXIS_OFFSET-22 "-"
*MEAS_COND_AXIS_OFFSET-23 "-"
*MEAS_COND_AXIS_OFFSET-24 "-"
*MEAS_COND_AXIS_OFFSET-25 "-"
*MEAS_COND_AXIS_OFFSET-26 "-"
*MEAS_COND_AXIS_OFFSET-27 "-"
*MEAS_COND_AXIS_OFFSET-28 "-"
*MEAS_COND_AXIS_OFFSET-29 "-"
*MEAS_COND_AXIS_OFFSET-30 "-"
*MEAS_COND_AXIS_POSITION-0 "0.0000000000"
*MEAS_COND_AXIS_POSITION-1 "0.0000000000"
*MEAS_COND_AXIS_POSITION-2 "0.0000000000"
*MEAS_COND_AXIS_POSITION-3 "-0.5500000000"
*MEAS_COND_AXIS_POSITION-4 "0.0000000000"
*MEAS_COND_AXIS_POSITION-5 "0.0000000000"
*MEAS_COND_AXIS_POSITION-6 "0.0000000000"
*MEAS_COND_AXIS_POSITION-7 "-0.4278800000"
*MEAS_COND_AXIS_POSITION-8 "BB"
*MEAS_COND_AXIS_POSITION-9 "0.0000000000"
*MEAS_COND_AXIS_POSITION-10 "Soller_slit_5.0deg"
*MEAS_COND_AXIS_POSITION-11 "2/3deg"
*MEAS_COND_AXIS_POSITION-12 "2.2088000000"
*MEAS_COND_AXIS_POSITION-13 "-0.4140600000"
*MEAS_COND_AXIS_POSITION-14 "0.0000000000"
*MEAS_COND_AXIS_POSITION-15 "10.0mm"
*MEAS_COND_AXIS_POSITION-16 "None"
*MEAS_COND_AXIS_POSITION-17 "Cu_K-beta"
*MEAS_COND_AXIS_POSITION-18 "13.000mm"
*MEAS_COND_AXIS_POSITION-19 "13.000mm"
*MEAS_COND_AXIS_POSITION-20 "No_unit"
*MEAS_COND_AXIS_POSITION-21 "Soller_slit_5.0deg"
*MEAS_COND_AXIS_POSITION-22 "None"
*MEAS_COND_AXIS_POSITION-23 "13.0000000000"
*MEAS_COND_AXIS_POSITION-24 "13.0000000000"
*MEAS_COND_AXIS_POSITION-25 "0.0109400000"
*MEAS_COND_AXIS_POSITION-26 "Open"
*MEAS_COND_AXIS_POSITION-27 "None"
*MEAS_COND_AXIS_POSITION-28 "None"
*MEAS_COND_AXIS_POSITION-29 "None"
*MEAS_COND_AXIS_POSITION-30 "38.0000000000"
*MEAS_COND_AXIS_UNIT-0 "deg"
*MEAS_COND_AXIS_UNIT-1 "deg"
*MEAS_COND_AXIS_UNIT-2 "deg"
*MEAS_COND_AXIS_UNIT-3 "mm"
*MEAS_COND_AXIS_UNIT-4 "deg"
*MEAS_COND_AXIS_UNIT-5 "deg"
*MEAS_COND_AXIS_UNIT-6 "deg"
*MEAS_COND_AXIS_UNIT-7 "mm"
*MEAS_COND_AXIS_UNIT-8 ""
*MEAS_COND_AXIS_UNIT-9 "pulse"
*MEAS_COND_AXIS_UNIT-10 ""
*MEAS_COND_AXIS_UNIT-11 ""
*MEAS_COND_AXIS_UNIT-12 "mm"
*MEAS_COND_AXIS_UNIT-13 "mm"
*MEAS_COND_AXIS_UNIT-14 ""
*MEAS_COND_AXIS_UNIT-15 ""
*MEAS_COND_AXIS_UNIT-16 ""
*MEAS_COND_AXIS_UNIT-17 ""
*MEAS_COND_AXIS_UNIT-18 ""
*MEAS_COND_AXIS_UNIT-19 ""
*MEAS_COND_AXIS_UNIT-20 ""
*MEAS_COND_AXIS_UNIT-21 ""
*MEAS_COND_AXIS_UNIT-22 ""
*MEAS_COND_AXIS_UNIT-23 "mm"
*MEAS_COND_AXIS_UNIT-24 "mm"
*MEAS_COND_AXIS_UNIT-25 "mm"
*MEAS_COND_AXIS_UNIT-26 ""
*MEAS_COND_AXIS_UNIT-27 ""
*MEAS_COND_AXIS_UNIT-28 ""
*MEAS_COND_AXIS_UNIT-29 ""
*MEAS_COND_AXIS_UNIT-30 "div"
*MEAS_COND_COUNTER_CNTLOSS_CORR "0.0000000000"
*MEAS_COND_COUNTER_PHABASE "38.0000000000"
*MEAS_COND_COUNTER_PHAWINDOW "16.0000000000"
*MEAS_COND_COUNTER_PHA_UNIT "div"
*MEAS_COND_COUNTER_TAUDIFF "30.0000000000"
*MEAS_COND_COUNTER_TAUINT "0.0000000000"
*MEAS_COND_IRRADIATION_MODE "OFF"
*MEAS_COND_IRRADIATION_WIDTH ""
*MEAS_COND_OPT_ATTR "集中法"
*MEAS_COND_OPT_NAME "@集中法"
*MEAS_COND_UNSYMMETRIC_MODE "OFF"
*MEAS_COND_XG_CURRENT "30.0000000000"
*MEAS_COND_XG_VOLTAGE "40.0000000000"
*MEAS_COND_XG_WAVE_TYPE "Ka"
*MEAS_DATA_COUNT "5001.0000000000"
*MEAS_SCAN_AXIS_X "2θ/θ"
*MEAS_SCAN_AXIS_X_INTERNAL "TwoThetaTheta"
*MEAS_SCAN_END_TIME "06/30/21 12:25:16"
*MEAS_SCAN_MODE "CONTINUOUS"
*MEAS_SCAN_MONITOR "0"
*MEAS_SCAN_RESOLUTION_X "0.0002"
*MEAS_SCAN_SPEED "1.0"
*MEAS_SCAN_SPEED_UNIT "deg/min"
*MEAS_SCAN_START "20.0000000000"
*MEAS_SCAN_START_TIME "06/30/21 11:32:23"
*MEAS_SCAN_STEP "0.0100000000"
*MEAS_SCAN_STOP "70.0000000000"
*MEAS_SCAN_UNIT_X "deg"
*MEAS_SCAN_UNIT_Y "counts"
*RAS_HEADER_END
*RAS_INT_START
20.0000 1511.0000 1.0000
20.0400 1654.0000 1.0000
20.0800 1609.0000 1.0000
20.1200 1603.0000 1.0000
20.1600 1649.0000 1.0000
20.2000 1631.0000 1.0000
20.2400 1632.0000 1.0000
20.2800 1596.0000 1.0000
20.3200 1596.0000 1.0000
20.3600 1606.0000 1.0000
20.4000 1599.0000 1.0000
20.4400 1626.0000 1.0000
20.4800 1662.0000 1.0000
20.5200 1581.0000 1.0000
20.5600 1675.0000 1.0000
20.6000 1651.0000 1.0000
20.6400 1654.0000 1.0000
20.6800 1639.0000 1.0000
20.7200 1649.0000 1.0000
20.7600 1645.0000 1.0000
20.8000 1661.0000 1.0000
20.8400 1605.0000 1.0000
20.8800 1641.0000 1.0000
20.9200 1613.0000 1.0000
20.9600 1616.0000 1.0000
21.0000 1642.0000 1.0000
21.0400 1592.0000 1.0000
21.0800 1635.0000 1.0000
21.1200 1678.0000 1.0000
21.1600 1654.0000 1.0000
21.2000 1601.0000 1.0000
21.2400 1628.0000 1.0000
21.2800 1664.0000 1.0000
21.3200 1619.0000 1.0000
21.3600 1627.0000 1.0000
21.4000 1658.0000 1.0000
21.4400 1611.0000 1.0000
21.4800 1619.0000 1.0000
21.5200 1717.0000 1.0000
21.5600 1596.0000 1.0000
21.6000 1524.0000 1.0000
21.6400 1636.0000 1.0000
21.6800 1637.0000 1.0000
21.7200 1683.0000 1.0000
21.7600 1587.0000 1.0000
21.8000 1684.0000 1.0000
21.8400 1636.0000 1.0000
21.8800 1576.0000 1.0000
21.9200 1579.0000 1.0000
21.9600 1626.0000 1.0000
22.0000 1664.0000 1.0000
22.0400 1750.0000 1.0000
22.0800 1652.0000 1.0000
22.1200 1660.0000 1.0000
22.1600 1621.0000 1.0000
22.2000 1615.0000 1.0000
22.2400 1737.0000 1.0000
22.2800 1632.0000 1.0000
22.3200 1665.0000 1.0000
22.3600 1666.0000 1.0000
22.4000 1596.0000 1.0000
22.4400 1740.0000 1.0000
22.4800 1631.0000 1.0000
22.5200 1657.0000 1.0000
22.5600 1629.0000 1.0000
22.6000 1631.0000 1.0000
22.6400 1634.0000 1.0000
22.6800 1638.0000 1.0000
22.7200 1720.0000 1.0000
22.7600 1646.0000 1.0000
22.8000 1673.0000 1.0000
22.8400 1693.0000 1.0000
22.8800 1703.0000 1.0000
22.9200 1686.0000 1.0000
22.9600 1682.0000 1.0000
23.0000 1692.0000 1.0000
23.0400 1752.0000 1.0000
23.0800 1702.0000 1.0000
23.1200 1613.0000 1.0000
23.1600 1617.0000 1.0000
23.2000 1738.0000 1.0000
23.2400 1695.0000 1.0000
23.2800 1689.0000 1.0000
23.3200 1664.0000 1.0000
23.3600 1660.0000 1.0000
23.4000 1749.0000 1.0000
23.4400 1718.0000 1.0000
23.4800 1682.0000 1.0000
23.5200 1646.0000 1.0000
23.5600 1639.0000 1.0000
23.6000 1710.0000 1.0000
23.6400 1682.0000 1.0000
23.6800 1687.0000 1.0000
23.7200 1673.0000 1.0000
23.7600 1680.0000 1.0000
23.8000 1669.0000 1.0000
23.8400 1638.0000 1.0000
23.8800 1690.0000 1.0000
23.9200 1733.0000 1.0000
23.9600 1755.0000 1.0000
24.0000 1700.0000 1.0000
24.0400 1701.0000 1.0000
24.0800 1659.0000 1.0000
24.1200 1678.0000 1.0000
24.1600 1678.0000 1.0000
24.2000 1640.0000 1.0000
24.2400 1745.0000 1.0000
24.2800 1732.0000 1.0000
24.3200 1718.0000 1.0000
24.3600 1713.0000 1.0000
24.4000 1765.0000 1.0000
24.4400 1746.0000 1.0000
24.4800 1655.0000 1.0000
24.5200 1667.0000 1.0000
24.5600 1783.0000 1.0000
24.6000 1729.0000 1.0000
24.6400 1752.0000 1.0000
24.6800 1765.0000 1.0000
24.7200 1705.0000 1.0000
24.7600 1675.0000 1.0000
24.8000 1686.0000 1.0000
24.8400 1697.0000 1.0000
24.8800 1767.0000 1.0000
24.9200 1796.0000 1.0000
24.9600 1770.0000 1.0000
25.0000 1762.0000 1.0000
25.0400 1740.0000 1.0000
25.0800 1819.0000 1.0000
25.1200 1781.0000 1.0000
25.1600 1716.0000 1.0000
25.2000 1743.0000 1.0000
25.2400 1803.0000 1.0000
25.2800 1805.0000 1.0000
25.3200 1699.0000 1.0000
25.3600 1736.0000 1.0000
25.4000 1732.0000 1.0000
25.4400 1725.0000 1.0000
25.4800 1730.0000 1.0000
25.5200 1800.0000 1.0000
25.5600 1718.0000 1.0000
25.6000 1739.0000 1.0000
25.6400 1750.0000 1.0000
25.6800 1773.0000 1.0000
25.7200 1749.0000 1.0000
25.7600 1739.0000 1.0000
25.8000 1675.0000 1.0000
25.8400 1764.0000 1.0000
25.8800 1684.0000 1.0000
25.9200 1749.0000 1.0000
25.9600 1755.0000 1.0000
26.0000 1761.0000 1.0000
26.0400 1777.0000 1.0000
26.0800 1715.0000 1.0000
26.1200 1804.0000 1.0000
26.1600 1743.0000 1.0000
26.2000 1782.0000 1.0000
26.2400 1807.0000 1.0000
26.2800 1728.0000 1.0000
26.3200 1816.0000 1.0000
26.3600 1785.0000 1.0000
26.4000 1807.0000 1.0000
26.4400 1858.0000 1.0000
26.4800 1827.0000 1.0000
26.5200 1831.0000 1.0000
26.5600 1856.0000 1.0000
26.6000 1832.0000 1.0000
26.6400 1868.0000 1.0000
26.6800 1877.0000 1.0000
26.7200 1896.0000 1.0000
26.7600 1842.0000 1.0000
26.8000 1955.0000 1.0000
26.8400 1913.0000 1.0000
26.8800 2036.0000 1.0000
26.9200 2067.0000 1.0000
26.9600 2164.0000 1.0000
27.0000 2399.0000 1.0000
27.0400 2585.0000 1.0000
27.0800 2725.0000 1.0000
27.1200 3240.0000 1.0000
27.1600 3814.0000 1.0000
27.2000 4709.0000 1.0000
27.2400 5825.0000 1.0000
27.2800 6456.0000 1.0000
27.3200 6539.0000 1.0000
27.3600 5990.0000 1.0000
27.4000 4866.0000 1.0000
27.4400 3928.0000 1.0000
27.4800 3210.0000 1.0000
27.5200 2846.0000 1.0000
27.5600 2613.0000 1.0000
27.6000 2373.0000 1.0000
27.6400 2265.0000 1.0000
27.6800 2058.0000 1.0000
27.7200 2030.0000 1.0000
27.7600 1971.0000 1.0000
27.8000 1902.0000 1.0000
27.8400 1868.0000 1.0000
27.8800 1867.0000 1.0000
27.9200 1791.0000 1.0000
27.9600 1869.0000 1.0000
28.0000 1809.0000 1.0000
28.0400 1752.0000 1.0000
28.0800 1758.0000 1.0000
28.1200 1675.0000 1.0000
28.1600 1684.0000 1.0000
28.2000 1736.0000 1.0000
28.2400 1705.0000 1.0000
28.2800 1705.0000 1.0000
28.3200 1678.0000 1.0000
28.3600 1646.0000 1.0000
28.4000 1658.0000 1.0000
28.4400 1660.0000 1.0000
28.4800 1613.0000 1.0000
28.5200 1650.0000 1.0000
28.5600 1623.0000 1.0000
28.6000 1651.0000 1.0000
28.6400 1600.0000 1.0000
28.6800 1601.0000 1.0000
28.7200 1676.0000 1.0000
28.7600 1636.0000 1.0000
28.8000 1638.0000 1.0000
28.8400 1646.0000 1.0000
28.8800 1660.0000 1.0000
28.9200 1605.0000 1.0000
28.9600 1623.0000 1.0000
29.0000 1646.0000 1.0000
29.0400 1600.0000 1.0000
29.0800 1617.0000 1.0000
29.1200 1615.0000 1.0000
29.1600 1641.0000 1.0000
29.2000 1698.0000 1.0000
29.2400 1609.0000 1.0000
29.2800 1607.0000 1.0000
29.3200 1514.0000 1.0000
29.3600 1569.0000 1.0000
29.4000 1577.0000 1.0000
29.4400 1552.0000 1.0000
29.4800 1536.0000 1.0000
29.5200 1564.0000 1.0000
29.5600 1551.0000 1.0000
29.6000 1560.0000 1.0000
29.6400 1540.0000 1.0000
29.6800 1526.0000 1.0000
29.7200 1559.0000 1.0000
29.7600 1549.0000 1.0000
29.8000 1589.0000 1.0000
29.8400 1550.0000 1.0000
29.8800 1590.0000 1.0000
29.9200 1536.0000 1.0000
29.9600 1487.0000 1.0000
30.0000 1534.0000 1.0000
30.0400 1526.0000 1.0000
30.0800 1532.0000 1.0000
30.1200 1506.0000 1.0000
30.1600 1510.0000 1.0000
30.2000 1528.0000 1.0000
30.2400 1551.0000 1.0000
30.2800 1478.0000 1.0000
30.3200 1582.0000 1.0000
30.3600 1520.0000 1.0000
30.4000 1499.0000 1.0000
30.4400 1534.0000 1.0000
30.4800 1516.0000 1.0000
30.5200 1500.0000 1.0000
30.5600 1485.0000 1.0000
30.6000 1488.0000 1.0000
30.6400 1451.0000 1.0000
30.6800 1474.0000 1.0000
30.7200 1489.0000 1.0000
30.7600 1426.0000 1.0000
30.8000 1544.0000 1.0000
30.8400 1531.0000 1.0000
30.8800 1480.0000 1.0000
30.9200 1412.0000 1.0000
30.9600 1514.0000 1.0000
31.0000 1505.0000 1.0000
31.0400 1502.0000 1.0000
31.0800 1467.0000 1.0000
31.1200 1464.0000 1.0000
31.1600 1453.0000 1.0000
31.2000 1486.0000 1.0000
31.2400 1412.0000 1.0000
31.2800 1461.0000 1.0000
31.3200 1458.0000 1.0000
31.3600 1424.0000 1.0000
31.4000 1411.0000 1.0000
31.4400 1481.0000 1.0000
31.4800 1443.0000 1.0000
31.5200 1440.0000 1.0000
31.5600 1407.0000 1.0000
31.6000 1395.0000 1.0000
31.6400 1411.0000 1.0000
31.6800 1379.0000 1.0000
31.7200 1480.0000 1.0000
31.7600 1441.0000 1.0000
31.8000 1467.0000 1.0000
31.8400 1446.0000 1.0000
31.8800 1467.0000 1.0000
31.9200 1503.0000 1.0000
31.9600 1382.0000 1.0000
32.0000 1376.0000 1.0000
32.0400 1518.0000 1.0000
32.0800 1535.0000 1.0000
32.1200 1385.0000 1.0000
32.1600 1419.0000 1.0000
32.2000 1419.0000 1.0000
32.2400 1449.0000 1.0000
32.2800 1448.0000 1.0000
32.3200 1402.0000 1.0000
32.3600 1373.0000 1.0000
32.4000 1436.0000 1.0000
32.4400 1471.0000 1.0000
32.4800 1369.0000 1.0000
32.5200 1409.0000 1.0000
32.5600 1439.0000 1.0000
32.6000 1435.0000 1.0000
32.6400 1436.0000 1.0000
32.6800 1418.0000 1.0000
32.7200 1412.0000 1.0000
32.7600 1437.0000 1.0000
32.8000 1333.0000 1.0000
32.8400 1379.0000 1.0000
32.8800 1417.0000 1.0000
32.9200 1403.0000 1.0000
32.9600 1427.0000 1.0000
33.0000 1331.0000 1.0000
33.0400 1337.0000 1.0000
33.0800 1387.0000 1.0000
33.1200 1318.0000 1.0000
33.1600 1350.0000 1.0000
33.2000 1358.0000 1.0000
33.2400 1351.0000 1.0000
33.2800 1369.0000 1.0000
33.3200 1356.0000 1.0000
33.3600 1395.0000 1.0000
33.4000 1315.0000 1.0000
33.4400 1330.0000 1.0000
33.4800 1324.0000 1.0000
33.5200 1367.0000 1.0000
33.5600 1399.0000 1.0000
33.6000 1371.0000 1.0000
33.6400 1349.0000 1.0000
33.6800 1442.0000 1.0000
33.7200 1418.0000 1.0000
33.7600 1322.0000 1.0000
33.8000 1422.0000 1.0000
33.8400 1432.0000 1.0000
33.8800 1484.0000 1.0000
33.9200 1546.0000 1.0000
33.9600 1622.0000 1.0000
34.0000 1556.0000 1.0000
34.0400 1550.0000 1.0000
34.0800 1457.0000 1.0000
34.1200 1426.0000 1.0000
34.1600 1544.0000 1.0000
34.2000 1606.0000 1.0000
34.2400 1755.0000 1.0000
34.2800 1881.0000 1.0000
34.3200 1961.0000 1.0000
34.3600 2180.0000 1.0000
34.4000 2563.0000 1.0000
34.4400 3085.0000 1.0000
34.4800 3438.0000 1.0000
34.5200 3274.0000 1.0000
34.5600 3113.0000 1.0000
34.6000 2670.0000 1.0000
34.6400 2251.0000 1.0000
34.6800 2067.0000 1.0000
34.7200 1854.0000 1.0000
34.7600 1673.0000 1.0000
34.8000 1591.0000 1.0000
34.8400 1540.0000 1.0000
34.8800 1431.0000 1.0000
34.9200 1438.0000 1.0000
34.9600 1320.0000 1.0000
35.0000 1360.0000 1.0000
35.0400 1314.0000 1.0000
35.0800 1277.0000 1.0000
35.1200 1336.0000 1.0000
35.1600 1279.0000 1.0000
35.2000 1286.0000 1.0000
35.2400 1278.0000 1.0000
35.2800 1209.0000 1.0000
35.3200 1167.0000 1.0000
35.3600 1252.0000 1.0000
35.4000 1234.0000 1.0000
35.4400 1154.0000 1.0000
35.4800 1216.0000 1.0000
35.5200 1195.0000 1.0000
35.5600 1206.0000 1.0000
35.6000 1179.0000 1.0000
35.6400 1192.0000 1.0000
35.6800 1171.0000 1.0000
35.7200 1182.0000 1.0000
35.7600 1203.0000 1.0000
35.8000 1157.0000 1.0000
35.8400 1162.0000 1.0000
35.8800 1166.0000 1.0000
35.9200 1182.0000 1.0000
35.9600 1185.0000 1.0000
36.0000 1185.0000 1.0000
36.0400 1180.0000 1.0000
36.0800 1206.0000 1.0000
36.1200 1204.0000 1.0000
36.1600 1175.0000 1.0000
36.2000 1220.0000 1.0000
36.2400 1323.0000 1.0000
36.2800 1377.0000 1.0000
36.3200 1549.0000 1.0000
36.3600 1876.0000 1.0000
36.4000 2041.0000 1.0000
36.4400 1959.0000 1.0000
36.4800 1825.0000 1.0000
36.5200 1560.0000 1.0000
36.5600 1378.0000 1.0000
36.6000 1254.0000 1.0000
36.6400 1193.0000 1.0000
36.6800 1137.0000 1.0000
36.7200 1086.0000 1.0000
36.7600 1102.0000 1.0000
36.8000 1034.0000 1.0000
36.8400 1057.0000 1.0000
36.8800 1114.0000 1.0000
36.9200 1114.0000 1.0000
36.9600 1085.0000 1.0000
37.0000 1041.0000 1.0000
37.0400 1072.0000 1.0000
37.0800 1036.0000 1.0000
37.1200 1026.0000 1.0000
37.1600 1074.0000 1.0000
37.2000 1093.0000 1.0000
37.2400 1065.0000 1.0000
37.2800 1007.0000 1.0000
37.3200 1087.0000 1.0000
37.3600 1065.0000 1.0000
37.4000 1072.0000 1.0000
37.4400 1042.0000 1.0000
37.4800 1027.0000 1.0000
37.5200 1047.0000 1.0000
37.5600 1050.0000 1.0000
37.6000 1137.0000 1.0000
37.6400 1038.0000 1.0000
37.6800 1006.0000 1.0000
37.7200 1075.0000 1.0000
37.7600 1049.0000 1.0000
37.8000 1035.0000 1.0000
37.8400 1110.0000 1.0000
37.8800 1073.0000 1.0000
37.9200 1078.0000 1.0000
37.9600 1162.0000 1.0000
38.0000 1077.0000 1.0000
38.0400 1205.0000 1.0000
38.0800 1177.0000 1.0000
38.1200 1254.0000 1.0000
38.1600 1318.0000 1.0000
38.2000 1474.0000 1.0000
38.2400 1582.0000 1.0000
38.2800 1807.0000 1.0000
38.3200 2140.0000 1.0000
38.3600 2567.0000 1.0000
38.4000 3420.0000 1.0000
38.4400 4324.0000 1.0000
38.4800 5459.0000 1.0000
38.5200 6156.0000 1.0000
38.5600 6319.0000 1.0000
38.6000 5952.0000 1.0000
38.6400 4933.0000 1.0000
38.6800 3890.0000 1.0000
38.7200 3073.0000 1.0000
38.7600 2309.0000 1.0000
38.8000 1915.0000 1.0000
38.8400 1629.0000 1.0000
38.8800 1440.0000 1.0000
38.9200 1310.0000 1.0000
38.9600 1207.0000 1.0000
39.0000 1123.0000 1.0000
39.0400 1064.0000 1.0000
39.0800 1068.0000 1.0000
39.1200 1047.0000 1.0000
39.1600 1012.0000 1.0000
39.2000 1046.0000 1.0000
39.2400 939.0000 1.0000
39.2800 1020.0000 1.0000
39.3200 949.0000 1.0000
39.3600 977.0000 1.0000
39.4000 985.0000 1.0000
39.4400 936.0000 1.0000
39.4800 1038.0000 1.0000
39.5200 1057.0000 1.0000
39.5600 977.0000 1.0000
39.6000 1009.0000 1.0000
39.6400 1037.0000 1.0000
39.6800 986.0000 1.0000
39.7200 982.0000 1.0000
39.7600 994.0000 1.0000
39.8000 979.0000 1.0000
39.8400 923.0000 1.0000
39.8800 938.0000 1.0000
39.9200 929.0000 1.0000
39.9600 917.0000 1.0000
40.0000 903.0000 1.0000
40.0400 940.0000 1.0000
40.0800 930.0000 1.0000
40.1200 882.0000 1.0000
40.1600 937.0000 1.0000
40.2000 962.0000 1.0000
40.2400 883.0000 1.0000
40.2800 875.0000 1.0000
40.3200 887.0000 1.0000
40.3600 895.0000 1.0000
40.4000 868.0000 1.0000
40.4400 917.0000 1.0000
40.4800 849.0000 1.0000
40.5200 910.0000 1.0000
40.5600 867.0000 1.0000
40.6000 902.0000 1.0000
40.6400 870.0000 1.0000
40.6800 871.0000 1.0000
40.7200 907.0000 1.0000
40.7600 922.0000 1.0000
40.8000 870.0000 1.0000
40.8400 879.0000 1.0000
40.8800 890.0000 1.0000
40.9200 876.0000 1.0000
40.9600 929.0000 1.0000
41.0000 849.0000 1.0000
41.0400 887.0000 1.0000
41.0800 861.0000 1.0000
41.1200 857.0000 1.0000
41.1600 881.0000 1.0000
41.2000 884.0000 1.0000
41.2400 874.0000 1.0000
41.2800 857.0000 1.0000
41.3200 915.0000 1.0000
41.3600 901.0000 1.0000
41.4000 899.0000 1.0000
41.4400 847.0000 1.0000
41.4800 916.0000 1.0000
41.5200 848.0000 1.0000
41.5600 917.0000 1.0000
41.6000 880.0000 1.0000
41.6400 898.0000 1.0000
41.6800 920.0000 1.0000
41.7200 885.0000 1.0000
41.7600 903.0000 1.0000
41.8000 874.0000 1.0000
41.8400 903.0000 1.0000
41.8800 919.0000 1.0000
41.9200 865.0000 1.0000
41.9600 860.0000 1.0000
42.0000 871.0000 1.0000
42.0400 951.0000 1.0000
42.0800 905.0000 1.0000
42.1200 841.0000 1.0000
42.1600 861.0000 1.0000
42.2000 816.0000 1.0000
42.2400 879.0000 1.0000
42.2800 835.0000 1.0000
42.3200 854.0000 1.0000
42.3600 876.0000 1.0000
42.4000 897.0000 1.0000
42.4400 828.0000 1.0000
42.4800 840.0000 1.0000
42.5200 874.0000 1.0000
42.5600 876.0000 1.0000
42.6000 876.0000 1.0000
42.6400 788.0000 1.0000
42.6800 852.0000 1.0000
42.7200 870.0000 1.0000
42.7600 856.0000 1.0000
42.8000 914.0000 1.0000
42.8400 822.0000 1.0000
42.8800 888.0000 1.0000
42.9200 888.0000 1.0000
42.9600 884.0000 1.0000
43.0000 907.0000 1.0000
43.0400 899.0000 1.0000
43.0800 904.0000 1.0000
43.1200 925.0000 1.0000
43.1600 936.0000 1.0000
43.2000 900.0000 1.0000
43.2400 960.0000 1.0000
43.2800 951.0000 1.0000
43.3200 958.0000 1.0000
43.3600 884.0000 1.0000
43.4000 859.0000 1.0000
43.4400 857.0000 1.0000
43.4800 920.0000 1.0000
43.5200 833.0000 1.0000
43.5600 881.0000 1.0000
43.6000 852.0000 1.0000
43.6400 866.0000 1.0000
43.6800 873.0000 1.0000
43.7200 876.0000 1.0000
43.7600 801.0000 1.0000
43.8000 867.0000 1.0000
43.8400 846.0000 1.0000
43.8800 825.0000 1.0000
43.9200 845.0000 1.0000
43.9600 834.0000 1.0000
44.0000 844.0000 1.0000
44.0400 855.0000 1.0000
44.0800 852.0000 1.0000
44.1200 883.0000 1.0000
44.1600 853.0000 1.0000
44.2000 875.0000 1.0000
44.2400 875.0000 1.0000
44.2800 870.0000 1.0000
44.3200 856.0000 1.0000
44.3600 865.0000 1.0000
44.4000 848.0000 1.0000
44.4400 840.0000 1.0000
44.4800 865.0000 1.0000
44.5200 854.0000 1.0000
44.5600 878.0000 1.0000
44.6000 788.0000 1.0000
44.6400 825.0000 1.0000
44.6800 806.0000 1.0000
44.7200 804.0000 1.0000
44.7600 806.0000 1.0000
44.8000 839.0000 1.0000
44.8400 830.0000 1.0000
44.8800 847.0000 1.0000
44.9200 810.0000 1.0000
44.9600 815.0000 1.0000
45.0000 792.0000 1.0000
45.0400 803.0000 1.0000
45.0800 832.0000 1.0000
45.1200 781.0000 1.0000
45.1600 827.0000 1.0000
45.2000 848.0000 1.0000
45.2400 820.0000 1.0000
45.2800 857.0000 1.0000
45.3200 818.0000 1.0000
45.3600 803.0000 1.0000
45.4000 841.0000 1.0000
45.4400 760.0000 1.0000
45.4800 807.0000 1.0000
45.5200 802.0000 1.0000
45.5600 764.0000 1.0000
45.6000 777.0000 1.0000
45.6400 821.0000 1.0000
45.6800 805.0000 1.0000
45.7200 836.0000 1.0000
45.7600 760.0000 1.0000
45.8000 790.0000 1.0000
45.8400 795.0000 1.0000
45.8800 798.0000 1.0000
45.9200 815.0000 1.0000
45.9600 801.0000 1.0000
46.0000 809.0000 1.0000
46.0400 837.0000 1.0000
46.0800 824.0000 1.0000
46.1200 771.0000 1.0000
46.1600 825.0000 1.0000
46.2000 828.0000 1.0000
46.2400 807.0000 1.0000
46.2800 748.0000 1.0000
46.3200 826.0000 1.0000
46.3600 802.0000 1.0000
46.4000 788.0000 1.0000
46.4400 762.0000 1.0000
46.4800 773.0000 1.0000
46.5200 804.0000 1.0000
46.5600 775.0000 1.0000
46.6000 778.0000 1.0000
46.6400 803.0000 1.0000
46.6800 759.0000 1.0000
46.7200 827.0000 1.0000
46.7600 731.0000 1.0000
46.8000 768.0000 1.0000
46.8400 773.0000 1.0000
46.8800 762.0000 1.0000
46.9200 825.0000 1.0000
46.9600 752.0000 1.0000
47.0000 756.0000 1.0000
47.0400 797.0000 1.0000
47.0800 773.0000 1.0000
47.1200 778.0000 1.0000
47.1600 837.0000 1.0000
47.2000 785.0000 1.0000
47.2400 768.0000 1.0000
47.2800 783.0000 1.0000
47.3200 760.0000 1.0000
47.3600 770.0000 1.0000
47.4000 778.0000 1.0000
47.4400 770.0000 1.0000
47.4800 753.0000 1.0000
47.5200 741.0000 1.0000
47.5600 756.0000 1.0000
47.6000 750.0000 1.0000
47.6400 761.0000 1.0000
47.6800 778.0000 1.0000
47.7200 797.0000 1.0000
47.7600 767.0000 1.0000
47.8000 737.0000 1.0000
47.8400 783.0000 1.0000
47.8800 758.0000 1.0000
47.9200 735.0000 1.0000
47.9600 765.0000 1.0000
48.0000 737.0000 1.0000
48.0400 772.0000 1.0000
48.0800 792.0000 1.0000
48.1200 742.0000 1.0000
48.1600 766.0000 1.0000
48.2000 754.0000 1.0000
48.2400 767.0000 1.0000
48.2800 730.0000 1.0000
48.3200 721.0000 1.0000
48.3600 769.0000 1.0000
48.4000 765.0000 1.0000
48.4400 734.0000 1.0000
48.4800 770.0000 1.0000
48.5200 745.0000 1.0000
48.5600 727.0000 1.0000
48.6000 761.0000 1.0000
48.6400 772.0000 1.0000
48.6800 759.0000 1.0000
48.7200 717.0000 1.0000
48.7600 712.0000 1.0000
48.8000 712.0000 1.0000
48.8400 711.0000 1.0000
48.8800 708.0000 1.0000
48.9200 703.0000 1.0000
48.9600 743.0000 1.0000
49.0000 702.0000 1.0000
49.0400 726.0000 1.0000
49.0800 735.0000 1.0000
49.1200 744.0000 1.0000
49.1600 743.0000 1.0000
49.2000 747.0000 1.0000
49.2400 742.0000 1.0000
49.2800 683.0000 1.0000
49.3200 764.0000 1.0000
49.3600 725.0000 1.0000
49.4000 736.0000 1.0000
49.4400 727.0000 1.0000
49.4800 729.0000 1.0000
49.5200 723.0000 1.0000
49.5600 724.0000 1.0000
49.6000 747.0000 1.0000
49.6400 735.0000 1.0000
49.6800 737.0000 1.0000
49.7200 761.0000 1.0000
49.7600 730.0000 1.0000
49.8000 733.0000 1.0000
49.8400 689.0000 1.0000
49.8800 720.0000 1.0000
49.9200 747.0000 1.0000
49.9600 722.0000 1.0000
50.0000 737.0000 1.0000
50.0400 742.0000 1.0000
50.0800 772.0000 1.0000
50.1200 715.0000 1.0000
50.1600 778.0000 1.0000
50.2000 834.0000 1.0000
50.2400 737.0000 1.0000
50.2800 847.0000 1.0000
50.3200 756.0000 1.0000
50.3600 820.0000 1.0000
50.4000 732.0000 1.0000
50.4400 734.0000 1.0000
50.4800 782.0000 1.0000
50.5200 720.0000 1.0000
50.5600 740.0000 1.0000
50.6000 757.0000 1.0000
50.6400 718.0000 1.0000
50.6800 767.0000 1.0000
50.7200 733.0000 1.0000
50.7600 689.0000 1.0000
50.8000 696.0000 1.0000
50.8400 758.0000 1.0000
50.8800 719.0000 1.0000
50.9200 781.0000 1.0000
50.9600 766.0000 1.0000
51.0000 768.0000 1.0000
51.0400 681.0000 1.0000
51.0800 781.0000 1.0000
51.1200 777.0000 1.0000
51.1600 754.0000 1.0000
51.2000 744.0000 1.0000
51.2400 723.0000 1.0000
51.2800 734.0000 1.0000
51.3200 709.0000 1.0000
51.3600 727.0000 1.0000
51.4000 792.0000 1.0000
51.4400 788.0000 1.0000
51.4800 792.0000 1.0000
51.5200 776.0000 1.0000
51.5600 758.0000 1.0000
51.6000 771.0000 1.0000
51.6400 750.0000 1.0000
51.6800 800.0000 1.0000
51.7200 772.0000 1.0000
51.7600 837.0000 1.0000
51.8000 859.0000 1.0000
51.8400 854.0000 1.0000
51.8800 953.0000 1.0000
51.9200 966.0000 1.0000
51.9600 1050.0000 1.0000
52.0000 1199.0000 1.0000
52.0400 1335.0000 1.0000
52.0800 1607.0000 1.0000
52.1200 2005.0000 1.0000
52.1600 2823.0000 1.0000
52.2000 3871.0000 1.0000
52.2400 4981.0000 1.0000
52.2800 5457.0000 1.0000
52.3200 5181.0000 1.0000
52.3600 4577.0000 1.0000
52.4000 4121.0000 1.0000
52.4400 3462.0000 1.0000
52.4800 2667.0000 1.0000
52.5200 1976.0000 1.0000
52.5600 1646.0000 1.0000
52.6000 1358.0000 1.0000
52.6400 1208.0000 1.0000
52.6800 1044.0000 1.0000
52.7200 978.0000 1.0000
52.7600 907.0000 1.0000
52.8000 896.0000 1.0000
52.8400 834.0000 1.0000
52.8800 849.0000 1.0000
52.9200 813.0000 1.0000
52.9600 824.0000 1.0000
53.0000 843.0000 1.0000
53.0400 769.0000 1.0000
53.0800 820.0000 1.0000
53.1200 786.0000 1.0000
53.1600 763.0000 1.0000
53.2000 721.0000 1.0000
53.2400 766.0000 1.0000
53.2800 730.0000 1.0000
53.3200 742.0000 1.0000
53.3600 777.0000 1.0000
53.4000 769.0000 1.0000
53.4400 770.0000 1.0000
53.4800 755.0000 1.0000
53.5200 747.0000 1.0000
53.5600 717.0000 1.0000
53.6000 743.0000 1.0000
53.6400 713.0000 1.0000
53.6800 729.0000 1.0000
53.7200 703.0000 1.0000
53.7600 783.0000 1.0000
53.8000 702.0000 1.0000
53.8400 735.0000 1.0000
53.8800 791.0000 1.0000
53.9200 752.0000 1.0000
53.9600 740.0000 1.0000
54.0000 730.0000 1.0000
54.0400 764.0000 1.0000
54.0800 715.0000 1.0000
54.1200 756.0000 1.0000
54.1600 715.0000 1.0000
54.2000 746.0000 1.0000
54.2400 765.0000 1.0000
54.2800 737.0000 1.0000
54.3200 707.0000 1.0000
54.3600 704.0000 1.0000
54.4000 731.0000 1.0000
54.4400 698.0000 1.0000
54.4800 709.0000 1.0000
54.5200 756.0000 1.0000
54.5600 791.0000 1.0000
54.6000 738.0000 1.0000
54.6400 736.0000 1.0000
54.6800 729.0000 1.0000
54.7200 766.0000 1.0000
54.7600 748.0000 1.0000
54.8000 811.0000 1.0000
54.8400 826.0000 1.0000
54.8800 789.0000 1.0000
54.9200 767.0000 1.0000
54.9600 813.0000 1.0000
55.0000 791.0000 1.0000
55.0400 762.0000 1.0000
55.0800 791.0000 1.0000
55.1200 909.0000 1.0000
55.1600 897.0000 1.0000
55.2000 971.0000 1.0000
55.2400 1088.0000 1.0000
55.2800 1138.0000 1.0000
55.3200 1106.0000 1.0000
55.3600 1094.0000 1.0000
55.4000 1069.0000 1.0000
55.4400 979.0000 1.0000
55.4800 933.0000 1.0000
55.5200 873.0000 1.0000
55.5600 872.0000 1.0000
55.6000 864.0000 1.0000
55.6400 771.0000 1.0000
55.6800 781.0000 1.0000
55.7200 728.0000 1.0000
55.7600 737.0000 1.0000
55.8000 701.0000 1.0000
55.8400 705.0000 1.0000
55.8800 746.0000 1.0000
55.9200 699.0000 1.0000
55.9600 662.0000 1.0000
56.0000 732.0000 1.0000
56.0400 756.0000 1.0000
56.0800 778.0000 1.0000
56.1200 726.0000 1.0000
56.1600 748.0000 1.0000
56.2000 691.0000 1.0000
56.2400 689.0000 1.0000
56.2800 738.0000 1.0000
56.3200 707.0000 1.0000
56.3600 717.0000 1.0000
56.4000 698.0000 1.0000
56.4400 714.0000 1.0000
56.4800 685.0000 1.0000
56.5200 698.0000 1.0000
56.5600 735.0000 1.0000
56.6000 696.0000 1.0000
56.6400 682.0000 1.0000
56.6800 657.0000 1.0000
56.7200 690.0000 1.0000
56.7600 732.0000 1.0000
56.8000 718.0000 1.0000
56.8400 721.0000 1.0000
56.8800 672.0000 1.0000
56.9200 709.0000 1.0000
56.9600 707.0000 1.0000
57.0000 741.0000 1.0000
57.0400 680.0000 1.0000
57.0800 715.0000 1.0000
57.1200 721.0000 1.0000
57.1600 675.0000 1.0000
57.2000 689.0000 1.0000
57.2400 628.0000 1.0000
57.2800 711.0000 1.0000
57.3200 676.0000 1.0000
57.3600 680.0000 1.0000
57.4000 657.0000 1.0000
57.4400 722.0000 1.0000
57.4800 697.0000 1.0000
57.5200 668.0000 1.0000
57.5600 712.0000 1.0000
57.6000 701.0000 1.0000
57.6400 697.0000 1.0000
57.6800 700.0000 1.0000
57.7200 677.0000 1.0000
57.7600 668.0000 1.0000
57.8000 712.0000 1.0000
57.8400 691.0000 1.0000
57.8800 690.0000 1.0000
57.9200 729.0000 1.0000
57.9600 733.0000 1.0000
58.0000 720.0000 1.0000
58.0400 696.0000 1.0000
58.0800 706.0000 1.0000
58.1200 691.0000 1.0000
58.1600 731.0000 1.0000
58.2000 740.0000 1.0000
58.2400 705.0000 1.0000
58.2800 704.0000 1.0000
58.3200 687.0000 1.0000
58.3600 682.0000 1.0000
58.4000 738.0000 1.0000
58.4400 684.0000 1.0000
58.4800 681.0000 1.0000
58.5200 649.0000 1.0000
58.5600 710.0000 1.0000
58.6000 676.0000 1.0000
58.6400 694.0000 1.0000
58.6800 668.0000 1.0000
58.7200 731.0000 1.0000
58.7600 679.0000 1.0000
58.8000 698.0000 1.0000
58.8400 693.0000 1.0000
58.8800 677.0000 1.0000
58.9200 706.0000 1.0000
58.9600 698.0000 1.0000
59.0000 683.0000 1.0000
59.0400 672.0000 1.0000
59.0800 653.0000 1.0000
59.1200 661.0000 1.0000
59.1600 690.0000 1.0000
59.2000 733.0000 1.0000
59.2400 711.0000 1.0000
59.2800 720.0000 1.0000
59.3200 725.0000 1.0000
59.3600 683.0000 1.0000
59.4000 700.0000 1.0000
59.4400 716.0000 1.0000
59.4800 712.0000 1.0000
59.5200 683.0000 1.0000
59.5600 697.0000 1.0000
59.6000 688.0000 1.0000
59.6400 719.0000 1.0000
59.6800 719.0000 1.0000
59.7200 665.0000 1.0000
59.7600 686.0000 1.0000
59.8000 669.0000 1.0000
59.8400 686.0000 1.0000
59.8800 672.0000 1.0000
59.9200 644.0000 1.0000
59.9600 690.0000 1.0000
60.0000 690.0000 1.0000
60.0400 714.0000 1.0000
60.0800 743.0000 1.0000
60.1200 694.0000 1.0000
60.1600 694.0000 1.0000
60.2000 738.0000 1.0000
60.2400 723.0000 1.0000
60.2800 697.0000 1.0000
60.3200 709.0000 1.0000
60.3600 675.0000 1.0000
60.4000 691.0000 1.0000
60.4400 682.0000 1.0000
60.4800 688.0000 1.0000
60.5200 656.0000 1.0000
60.5600 669.0000 1.0000
60.6000 638.0000 1.0000
60.6400 701.0000 1.0000
60.6800 680.0000 1.0000
60.7200 648.0000 1.0000
60.7600 729.0000 1.0000
60.8000 673.0000 1.0000
60.8400 688.0000 1.0000
60.8800 655.0000 1.0000
60.9200 667.0000 1.0000
60.9600 732.0000 1.0000
61.0000 730.0000 1.0000
61.0400 679.0000 1.0000
61.0800 662.0000 1.0000
61.1200 702.0000 1.0000
61.1600 666.0000 1.0000
61.2000 704.0000 1.0000
61.2400 679.0000 1.0000
61.2800 692.0000 1.0000
61.3200 686.0000 1.0000
61.3600 696.0000 1.0000
61.4000 735.0000 1.0000
61.4400 705.0000 1.0000
61.4800 728.0000 1.0000
61.5200 740.0000 1.0000
61.5600 719.0000 1.0000
61.6000 707.0000 1.0000
61.6400 726.0000 1.0000
61.6800 707.0000 1.0000
61.7200 720.0000 1.0000
61.7600 751.0000 1.0000
61.8000 726.0000 1.0000
61.8400 723.0000 1.0000
61.8800 787.0000 1.0000
61.9200 767.0000 1.0000
61.9600 849.0000 1.0000
62.0000 890.0000 1.0000
62.0400 939.0000 1.0000
62.0800 985.0000 1.0000
62.1200 1132.0000 1.0000
62.1600 1248.0000 1.0000
62.2000 1435.0000 1.0000
62.2400 1488.0000 1.0000
62.2800 1560.0000 1.0000
62.3200 1565.0000 1.0000
62.3600 1585.0000 1.0000
62.4000 1480.0000 1.0000
62.4400 1422.0000 1.0000
62.4800 1358.0000 1.0000
62.5200 1204.0000 1.0000
62.5600 1171.0000 1.0000
62.6000 1050.0000 1.0000
62.6400 927.0000 1.0000
62.6800 921.0000 1.0000
62.7200 844.0000 1.0000
62.7600 849.0000 1.0000
62.8000 786.0000 1.0000
62.8400 787.0000 1.0000
62.8800 778.0000 1.0000
62.9200 770.0000 1.0000
62.9600 782.0000 1.0000
63.0000 755.0000 1.0000
63.0400 724.0000 1.0000
63.0800 810.0000 1.0000
63.1200 762.0000 1.0000
63.1600 758.0000 1.0000
63.2000 662.0000 1.0000
63.2400 714.0000 1.0000
63.2800 766.0000 1.0000
63.3200 768.0000 1.0000
63.3600 722.0000 1.0000
63.4000 709.0000 1.0000
63.4400 704.0000 1.0000
63.4800 685.0000 1.0000
63.5200 699.0000 1.0000
63.5600 694.0000 1.0000
63.6000 689.0000 1.0000
63.6400 696.0000 1.0000
63.6800 700.0000 1.0000
63.7200 711.0000 1.0000
63.7600 676.0000 1.0000
63.8000 684.0000 1.0000
63.8400 694.0000 1.0000
63.8800 652.0000 1.0000
63.9200 727.0000 1.0000
63.9600 746.0000 1.0000
64.0000 683.0000 1.0000
64.0400 650.0000 1.0000
64.0800 688.0000 1.0000
64.1200 688.0000 1.0000
64.1600 681.0000 1.0000
64.2000 703.0000 1.0000
64.2400 751.0000 1.0000
64.2800 740.0000 1.0000
64.3200 714.0000 1.0000
64.3600 687.0000 1.0000
64.4000 701.0000 1.0000
64.4400 725.0000 1.0000
64.4800 714.0000 1.0000
64.5200 750.0000 1.0000
64.5600 766.0000 1.0000
64.6000 827.0000 1.0000
64.6400 885.0000 1.0000
64.6800 920.0000 1.0000
64.7200 909.0000 1.0000
64.7600 861.0000 1.0000
64.8000 861.0000 1.0000
64.8400 843.0000 1.0000
64.8800 816.0000 1.0000
64.9200 813.0000 1.0000
64.9600 767.0000 1.0000
65.0000 716.0000 1.0000
65.0400 697.0000 1.0000
65.0800 775.0000 1.0000
65.1200 716.0000 1.0000
65.1600 736.0000 1.0000
65.2000 753.0000 1.0000
65.2400 733.0000 1.0000
65.2800 755.0000 1.0000
65.3200 698.0000 1.0000
65.3600 701.0000 1.0000
65.4000 666.0000 1.0000
65.4400 724.0000 1.0000
65.4800 742.0000 1.0000
65.5200 723.0000 1.0000
65.5600 749.0000 1.0000
65.6000 757.0000 1.0000
65.6400 694.0000 1.0000
65.6800 744.0000 1.0000
65.7200 765.0000 1.0000
65.7600 773.0000 1.0000
65.8000 775.0000 1.0000
65.8400 835.0000 1.0000
65.8800 813.0000 1.0000
65.9200 917.0000 1.0000
65.9600 981.0000 1.0000
66.0000 1065.0000 1.0000
66.0400 1161.0000 1.0000
66.0800 1344.0000 1.0000
66.1200 1520.0000 1.0000
66.1600 2012.0000 1.0000
66.2000 2416.0000 1.0000
66.2400 2673.0000 1.0000
66.2800 2843.0000 1.0000
66.3200 2654.0000 1.0000
66.3600 2620.0000 1.0000
66.4000 2409.0000 1.0000
66.4400 2294.0000 1.0000
66.4800 2022.0000 1.0000
66.5200 1742.0000 1.0000
66.5600 1466.0000 1.0000
66.6000 1215.0000 1.0000
66.6400 1149.0000 1.0000
66.6800 982.0000 1.0000
66.7200 913.0000 1.0000
66.7600 901.0000 1.0000
66.8000 808.0000 1.0000
66.8400 823.0000 1.0000
66.8800 746.0000 1.0000
66.9200 752.0000 1.0000
66.9600 700.0000 1.0000
67.0000 703.0000 1.0000
67.0400 710.0000 1.0000
67.0800 665.0000 1.0000
67.1200 675.0000 1.0000
67.1600 686.0000 1.0000
67.2000 707.0000 1.0000
67.2400 662.0000 1.0000
67.2800 661.0000 1.0000
67.3200 639.0000 1.0000
67.3600 670.0000 1.0000
67.4000 689.0000 1.0000
67.4400 642.0000 1.0000
67.4800 657.0000 1.0000
67.5200 664.0000 1.0000
67.5600 619.0000 1.0000
67.6000 657.0000 1.0000
67.6400 670.0000 1.0000
67.6800 634.0000 1.0000
67.7200 654.0000 1.0000
67.7600 661.0000 1.0000
67.8000 651.0000 1.0000
67.8400 644.0000 1.0000
67.8800 677.0000 1.0000
67.9200 621.0000 1.0000
67.9600 625.0000 1.0000
68.0000 646.0000 1.0000
68.0400 658.0000 1.0000
68.0800 634.0000 1.0000
68.1200 677.0000 1.0000
68.1600 638.0000 1.0000
68.2000 667.0000 1.0000
68.2400 625.0000 1.0000
68.2800 632.0000 1.0000
68.3200 607.0000 1.0000
68.3600 637.0000 1.0000
68.4000 645.0000 1.0000
68.4400 626.0000 1.0000
68.4800 634.0000 1.0000
68.5200 642.0000 1.0000
68.5600 575.0000 1.0000
68.6000 626.0000 1.0000
68.6400 624.0000 1.0000
68.6800 624.0000 1.0000
68.7200 610.0000 1.0000
68.7600 622.0000 1.0000
68.8000 630.0000 1.0000
68.8400 626.0000 1.0000
68.8800 620.0000 1.0000
68.9200 644.0000 1.0000
68.9600 584.0000 1.0000
69.0000 572.0000 1.0000
69.0400 585.0000 1.0000
69.0800 635.0000 1.0000
69.1200 606.0000 1.0000
69.1600 610.0000 1.0000
69.2000 605.0000 1.0000
69.2400 626.0000 1.0000
69.2800 622.0000 1.0000
69.3200 613.0000 1.0000
69.3600 624.0000 1.0000
69.4000 616.0000 1.0000
69.4400 652.0000 1.0000
69.4800 599.0000 1.0000
69.5200 626.0000 1.0000
69.5600 657.0000 1.0000
69.6000 641.0000 1.0000
69.6400 621.0000 1.0000
69.6800 605.0000 1.0000
69.7200 620.0000 1.0000
69.7600 590.0000 1.0000
69.8000 570.0000 1.0000
69.8400 630.0000 1.0000
69.8800 643.0000 1.0000
69.9200 538.0000 1.0000
69.9600 618.0000 1.0000
70.0000 624.0000 1.0000
*RAS_INT_END
*RAS_TEMPERATURE_START
*RAS_TEMPERATURE_END
*RAS_DATA_END