File: Section2_75_samples/XRD/No_067_HS2_3.ras
*RAS_DATA_START
*RAS_HEADER_START
*DISP_FMT_X "%.2f"
*DISP_FMT_Y "%.0f"
*DISP_FULLSCALE "14576.0000000000"
*DISP_LINE_COLOR "255.0000000000"
*DISP_LINE_STYLE "0.0000000000"
*DISP_LINE_WIDTH "0.2500000000"
*DISP_NOTE "測定データ-1"
*DISP_OFFSET_Y "0.0000000000"
*DISP_PEAKSEARCH_UNIT_Y "cps"
*DISP_RANGE_BOTTOM "0.0000000000"
*DISP_RANGE_LEFT "20.0000000000"
*DISP_RANGE_LOGCUTOFF "0.0100000000"
*DISP_RANGE_RIGHT "70.0000000000"
*DISP_RANGE_TOP "14576.0000000000"
*DISP_SCALE_MODE_Y "0.0000000000"
*DISP_TAB_NAME "2θ/θ"
*DISP_TITLE_Y "強度"
*DISP_UNIT_Y "cps"
*DISP_WINDOW_NAME "MSG_MACROENGINE"
*FILE_COMMENT " "
*FILE_MD5 ""
*FILE_MEMO " "
*FILE_OPERATOR "Administrator"
*FILE_SAMPLE " "
*FILE_TYPE "RAS_RAW"
*FILE_USERGROUP "システムマネージャ"
*FILE_VERSION "1.0000000000"
*HW_ATTACHMENT_ID "ATT0025"
*HW_ATTACHMENT_NAME "標準|Standard"
*HW_COUNTER_ID-0 "CUT0025"
*HW_COUNTER_ID-1 "CUT0020"
*HW_COUNTER_ID-2 "CUT0020"
*HW_COUNTER_ID-3 "CSL0021"
*HW_COUNTER_ID-4 "CMC0021"
*HW_COUNTER_NAME-0 "D/teX Ultra|D/teX Ultra"
*HW_COUNTER_NAME-1 "None|None"
*HW_COUNTER_NAME-2 "None|None"
*HW_COUNTER_NAME-3 "BBM|BBM"
*HW_COUNTER_NAME-4 "検出器モノクロメータ|Detector monochromator"
*HW_COUNTER_SELECT_NAME "D/teX Ultra|D/teX Ultra"
*HW_GONIOMETER_ID "GON0023"
*HW_GONIOMETER_NAME "SmartLab|SmartLab"
*HW_GONIOMETER_RADIUS-0 "90.0"
*HW_GONIOMETER_RADIUS-1 "114.0"
*HW_GONIOMETER_RADIUS-2 "190.0"
*HW_GONIOMETER_RADIUS-3 "300.0"
*HW_GONIOMETER_RADIUS-4 "187.0"
*HW_GONIOMETER_RADIUS-5 "300.0"
*HW_GONIOMETER_RADIUS-6 "113.0"
*HW_GONIOMETER_RADIUS-7 "331.0"
*HW_I_OPT_ID-0 "CBO0021"
*HW_I_OPT_ID-1 "ICR0023"
*HW_I_OPT_ID-2 "ISL0021"
*HW_I_OPT_ID-3 "ISO0021"
*HW_I_OPT_ID-4 "IAD0021"
*HW_I_OPT_ID-5 "IPR0001"
*HW_I_OPT_NAME-0 "CBOユニット|CBO unit"
*HW_I_OPT_NAME-1 "標準入射光学ユニット|Standard incident optical unit"
*HW_I_OPT_NAME-2 "標準入射スリットボックス|Standard incident slit box"
*HW_I_OPT_NAME-3 "入射平行スリット|Incident parallel slit"
*HW_I_OPT_NAME-4 "長手制限スリット|Length limiting slit"
*HW_I_OPT_NAME-5 "None|None"
*HW_R_ATTENUATER_AUTOMODE "0"
*HW_R_OPT_ID-0 "RSS0021"
*HW_R_OPT_ID-1 "RCR0023"
*HW_R_OPT_ID-2 "RSO0021"
*HW_R_OPT_ID-3 "RRS0021"
*HW_R_OPT_ID-4 "ATN0021"
*HW_R_OPT_ID-5 "RFL0021"
*HW_R_OPT_ID-6 "RAD0021"
*HW_R_OPT_NAME-0 "標準受光スリットボックス1|Standard receiving slit box # 1"
*HW_R_OPT_NAME-1 "標準受光光学ユニット1|Standard receiving unit # 1"
*HW_R_OPT_NAME-2 "標準受光光学ユニット2|Standard receiving optical unit # 2"
*HW_R_OPT_NAME-3 "標準受光スリットボックス2|Standard receiving slit box # 2"
*HW_R_OPT_NAME-4 "標準アッテネータ|Standard Attenuator"
*HW_R_OPT_NAME-5 "Cu Kβ|Cu K-beta"
*HW_R_OPT_NAME-6 "調整用受光スリット|Alignment receiving slit"
*HW_SAMPLE_HOLDER_ID "SMP0023"
*HW_SAMPLE_HOLDER_NAME "標準Zステージ|Standard Z stage"
*HW_XG_CURRENT_MAX "50"
*HW_XG_CURRENT_MIN "2"
*HW_XG_CURRENT_RESOLUTION "1"
*HW_XG_CURRENT_UNIT "mA"
*HW_XG_FOCUS "1mm x 10mm"
*HW_XG_FOCUS_TYPE "Normal"
*HW_XG_ID ""
*HW_XG_NAME "3kW 封入管(ID:1200)|3kW Sealed tube(ID:1200)"
*HW_XG_TARGET_ATOMIC_NUMBER "29.0000000000"
*HW_XG_TARGET_NAME "Cu"
*HW_XG_TYPE "Hermetic"
*HW_XG_VOLTAGE_MAX "60"
*HW_XG_VOLTAGE_MIN "20"
*HW_XG_VOLTAGE_RESOLUTION "1"
*HW_XG_VOLTAGE_UNIT "kV"
*HW_XG_WATT_MAX "1.500"
*HW_XG_WATT_UNIT "kW"
*HW_XG_WAVE_LENGTH_ALPHA1 "1.540593"
*HW_XG_WAVE_LENGTH_ALPHA2 "1.544414"
*HW_XG_WAVE_LENGTH_BETA "1.392250"
*MEAS_COND_AXIS_NAME-0 "2θ/θ"
*MEAS_COND_AXIS_NAME-1 "2θ"
*MEAS_COND_AXIS_NAME-2 "ω"
*MEAS_COND_AXIS_NAME-3 "Z"
*MEAS_COND_AXIS_NAME-4 "2θ/ω"
*MEAS_COND_AXIS_NAME-5 "θs"
*MEAS_COND_AXIS_NAME-6 "θd"
*MEAS_COND_AXIS_NAME-7 "Ts"
*MEAS_COND_AXIS_NAME-8 "CBO選択スリット"
*MEAS_COND_AXIS_NAME-9 "M"
*MEAS_COND_AXIS_NAME-10 "入射平行スリット"
*MEAS_COND_AXIS_NAME-11 "入射スリット"
*MEAS_COND_AXIS_NAME-12 ""
*MEAS_COND_AXIS_NAME-13 "Zs"
*MEAS_COND_AXIS_NAME-14 "入射光学素子"
*MEAS_COND_AXIS_NAME-15 "長手制限スリット"
*MEAS_COND_AXIS_NAME-16 "センタースリット"
*MEAS_COND_AXIS_NAME-17 "フィルター"
*MEAS_COND_AXIS_NAME-18 "受光スリット1"
*MEAS_COND_AXIS_NAME-19 "受光スリット2"
*MEAS_COND_AXIS_NAME-20 "受光光学素子"
*MEAS_COND_AXIS_NAME-21 "受光平行スリット"
*MEAS_COND_AXIS_NAME-22 "調整用受光スリット"
*MEAS_COND_AXIS_NAME-23 ""
*MEAS_COND_AXIS_NAME-24 ""
*MEAS_COND_AXIS_NAME-25 "Zd"
*MEAS_COND_AXIS_NAME-26 "アッテネータ"
*MEAS_COND_AXIS_NAME-27 "検出器モノクロメータ"
*MEAS_COND_AXIS_NAME-28 "モノクロメータスリット"
*MEAS_COND_AXIS_NAME-29 "プライマリビーム"
*MEAS_COND_AXIS_NAME-30 "PHA"
*MEAS_COND_AXIS_NAME_INTERNAL-0 "TwoThetaTheta"
*MEAS_COND_AXIS_NAME_INTERNAL-1 "TwoTheta"
*MEAS_COND_AXIS_NAME_INTERNAL-2 "Omega"
*MEAS_COND_AXIS_NAME_INTERNAL-3 "Z"
*MEAS_COND_AXIS_NAME_INTERNAL-4 "TwoThetaOmega"
*MEAS_COND_AXIS_NAME_INTERNAL-5 "ThetaS"
*MEAS_COND_AXIS_NAME_INTERNAL-6 "ThetaD"
*MEAS_COND_AXIS_NAME_INTERNAL-7 "Ts"
*MEAS_COND_AXIS_NAME_INTERNAL-8 "CBO"
*MEAS_COND_AXIS_NAME_INTERNAL-9 "CBO-M"
*MEAS_COND_AXIS_NAME_INTERNAL-10 "IncidentSollerSlit"
*MEAS_COND_AXIS_NAME_INTERNAL-11 "IncidentSlitBox"
*MEAS_COND_AXIS_NAME_INTERNAL-12 "IncidentSlitBox-_Axis"
*MEAS_COND_AXIS_NAME_INTERNAL-13 "Zs"
*MEAS_COND_AXIS_NAME_INTERNAL-14 "IncidentMonochromator"
*MEAS_COND_AXIS_NAME_INTERNAL-15 "IncidentAxdSlit"
*MEAS_COND_AXIS_NAME_INTERNAL-16 "CenterSlit"
*MEAS_COND_AXIS_NAME_INTERNAL-17 "Filter"
*MEAS_COND_AXIS_NAME_INTERNAL-18 "ReceivingSlitBox1"
*MEAS_COND_AXIS_NAME_INTERNAL-19 "ReceivingSlitBox2"
*MEAS_COND_AXIS_NAME_INTERNAL-20 "ReceivingOptics"
*MEAS_COND_AXIS_NAME_INTERNAL-21 "ReceivingSollerSlit"
*MEAS_COND_AXIS_NAME_INTERNAL-22 "ReceivingAxdSlit"
*MEAS_COND_AXIS_NAME_INTERNAL-23 "ReceivingSlitBox1-_Axis"
*MEAS_COND_AXIS_NAME_INTERNAL-24 "ReceivingSlitBox2-_Axis"
*MEAS_COND_AXIS_NAME_INTERNAL-25 "ReceivingSlitBox2-Zd"
*MEAS_COND_AXIS_NAME_INTERNAL-26 "Attenuator"
*MEAS_COND_AXIS_NAME_INTERNAL-27 "CounterMonochromator"
*MEAS_COND_AXIS_NAME_INTERNAL-28 "CounterSlit"
*MEAS_COND_AXIS_NAME_INTERNAL-29 "IncidentPrimary"
*MEAS_COND_AXIS_NAME_INTERNAL-30 "PHA"
*MEAS_COND_AXIS_NAME_MAGICNO-0 "83951616.0000000000"
*MEAS_COND_AXIS_NAME_MAGICNO-1 "268632064.0000000000"
*MEAS_COND_AXIS_NAME_MAGICNO-2 "268500992.0000000000"
*MEAS_COND_AXIS_NAME_MAGICNO-3 "285278208.0000000000"
*MEAS_COND_AXIS_NAME_MAGICNO-4 "83951616.0000000000"
*MEAS_COND_AXIS_NAME_MAGICNO-5 "131072.0000000000"
*MEAS_COND_AXIS_NAME_MAGICNO-6 "131072.0000000000"
*MEAS_COND_AXIS_NAME_MAGICNO-7 "318898176.0000000000"
*MEAS_COND_AXIS_NAME_MAGICNO-8 "20971521.0000000000"
*MEAS_COND_AXIS_NAME_MAGICNO-9 "285343744.0000000000"
*MEAS_COND_AXIS_NAME_MAGICNO-10 "20971521.0000000000"
*MEAS_COND_AXIS_NAME_MAGICNO-11 "22020097.0000000000"
*MEAS_COND_AXIS_NAME_MAGICNO-12 "25165824.0000000000"
*MEAS_COND_AXIS_NAME_MAGICNO-13 "318898176.0000000000"
*MEAS_COND_AXIS_NAME_MAGICNO-14 "1.0000000000"
*MEAS_COND_AXIS_NAME_MAGICNO-15 "20971521.0000000000"
*MEAS_COND_AXIS_NAME_MAGICNO-16 "20971521.0000000000"
*MEAS_COND_AXIS_NAME_MAGICNO-17 "20971521.0000000000"
*MEAS_COND_AXIS_NAME_MAGICNO-18 "23068673.0000000000"
*MEAS_COND_AXIS_NAME_MAGICNO-19 "23068673.0000000000"
*MEAS_COND_AXIS_NAME_MAGICNO-20 "20971521.0000000000"
*MEAS_COND_AXIS_NAME_MAGICNO-21 "20971521.0000000000"
*MEAS_COND_AXIS_NAME_MAGICNO-22 "20971521.0000000000"
*MEAS_COND_AXIS_NAME_MAGICNO-23 "25165824.0000000000"
*MEAS_COND_AXIS_NAME_MAGICNO-24 "25165824.0000000000"
*MEAS_COND_AXIS_NAME_MAGICNO-25 "285343744.0000000000"
*MEAS_COND_AXIS_NAME_MAGICNO-26 "17301505.0000000000"
*MEAS_COND_AXIS_NAME_MAGICNO-27 "20971521.0000000000"
*MEAS_COND_AXIS_NAME_MAGICNO-28 "20971521.0000000000"
*MEAS_COND_AXIS_NAME_MAGICNO-29 "20971521.0000000000"
*MEAS_COND_AXIS_NAME_MAGICNO-30 "0.0000000000"
*MEAS_COND_AXIS_OFFSET-0 "-"
*MEAS_COND_AXIS_OFFSET-1 "-0.1081000000"
*MEAS_COND_AXIS_OFFSET-2 "0.3758000000"
*MEAS_COND_AXIS_OFFSET-3 "-"
*MEAS_COND_AXIS_OFFSET-4 "-"
*MEAS_COND_AXIS_OFFSET-5 "0.3758000000"
*MEAS_COND_AXIS_OFFSET-6 "-0.4839000000"
*MEAS_COND_AXIS_OFFSET-7 "-"
*MEAS_COND_AXIS_OFFSET-8 "-"
*MEAS_COND_AXIS_OFFSET-9 "-"
*MEAS_COND_AXIS_OFFSET-10 "-"
*MEAS_COND_AXIS_OFFSET-11 "-"
*MEAS_COND_AXIS_OFFSET-12 "-"
*MEAS_COND_AXIS_OFFSET-13 "-"
*MEAS_COND_AXIS_OFFSET-14 "-"
*MEAS_COND_AXIS_OFFSET-15 "-"
*MEAS_COND_AXIS_OFFSET-16 "-"
*MEAS_COND_AXIS_OFFSET-17 "-"
*MEAS_COND_AXIS_OFFSET-18 "-"
*MEAS_COND_AXIS_OFFSET-19 "-"
*MEAS_COND_AXIS_OFFSET-20 "-"
*MEAS_COND_AXIS_OFFSET-21 "-"
*MEAS_COND_AXIS_OFFSET-22 "-"
*MEAS_COND_AXIS_OFFSET-23 "-"
*MEAS_COND_AXIS_OFFSET-24 "-"
*MEAS_COND_AXIS_OFFSET-25 "-"
*MEAS_COND_AXIS_OFFSET-26 "-"
*MEAS_COND_AXIS_OFFSET-27 "-"
*MEAS_COND_AXIS_OFFSET-28 "-"
*MEAS_COND_AXIS_OFFSET-29 "-"
*MEAS_COND_AXIS_OFFSET-30 "-"
*MEAS_COND_AXIS_POSITION-0 "0.0000000000"
*MEAS_COND_AXIS_POSITION-1 "0.0000000000"
*MEAS_COND_AXIS_POSITION-2 "0.0000000000"
*MEAS_COND_AXIS_POSITION-3 "-0.5500000000"
*MEAS_COND_AXIS_POSITION-4 "0.0000000000"
*MEAS_COND_AXIS_POSITION-5 "0.0000000000"
*MEAS_COND_AXIS_POSITION-6 "0.0000000000"
*MEAS_COND_AXIS_POSITION-7 "-0.4278800000"
*MEAS_COND_AXIS_POSITION-8 "BB"
*MEAS_COND_AXIS_POSITION-9 "0.0000000000"
*MEAS_COND_AXIS_POSITION-10 "Soller_slit_5.0deg"
*MEAS_COND_AXIS_POSITION-11 "2/3deg"
*MEAS_COND_AXIS_POSITION-12 "2.2088000000"
*MEAS_COND_AXIS_POSITION-13 "-0.4140600000"
*MEAS_COND_AXIS_POSITION-14 "0.0000000000"
*MEAS_COND_AXIS_POSITION-15 "10.0mm"
*MEAS_COND_AXIS_POSITION-16 "None"
*MEAS_COND_AXIS_POSITION-17 "Cu_K-beta"
*MEAS_COND_AXIS_POSITION-18 "10.036mm"
*MEAS_COND_AXIS_POSITION-19 "13.000mm"
*MEAS_COND_AXIS_POSITION-20 "No_unit"
*MEAS_COND_AXIS_POSITION-21 "Soller_slit_5.0deg"
*MEAS_COND_AXIS_POSITION-22 "None"
*MEAS_COND_AXIS_POSITION-23 "10.0363000000"
*MEAS_COND_AXIS_POSITION-24 "13.0000000000"
*MEAS_COND_AXIS_POSITION-25 "0.0109400000"
*MEAS_COND_AXIS_POSITION-26 "Open"
*MEAS_COND_AXIS_POSITION-27 "None"
*MEAS_COND_AXIS_POSITION-28 "None"
*MEAS_COND_AXIS_POSITION-29 "None"
*MEAS_COND_AXIS_POSITION-30 "38.0000000000"
*MEAS_COND_AXIS_UNIT-0 "deg"
*MEAS_COND_AXIS_UNIT-1 "deg"
*MEAS_COND_AXIS_UNIT-2 "deg"
*MEAS_COND_AXIS_UNIT-3 "mm"
*MEAS_COND_AXIS_UNIT-4 "deg"
*MEAS_COND_AXIS_UNIT-5 "deg"
*MEAS_COND_AXIS_UNIT-6 "deg"
*MEAS_COND_AXIS_UNIT-7 "mm"
*MEAS_COND_AXIS_UNIT-8 ""
*MEAS_COND_AXIS_UNIT-9 "pulse"
*MEAS_COND_AXIS_UNIT-10 ""
*MEAS_COND_AXIS_UNIT-11 ""
*MEAS_COND_AXIS_UNIT-12 "mm"
*MEAS_COND_AXIS_UNIT-13 "mm"
*MEAS_COND_AXIS_UNIT-14 ""
*MEAS_COND_AXIS_UNIT-15 ""
*MEAS_COND_AXIS_UNIT-16 ""
*MEAS_COND_AXIS_UNIT-17 ""
*MEAS_COND_AXIS_UNIT-18 ""
*MEAS_COND_AXIS_UNIT-19 ""
*MEAS_COND_AXIS_UNIT-20 ""
*MEAS_COND_AXIS_UNIT-21 ""
*MEAS_COND_AXIS_UNIT-22 ""
*MEAS_COND_AXIS_UNIT-23 "mm"
*MEAS_COND_AXIS_UNIT-24 "mm"
*MEAS_COND_AXIS_UNIT-25 "mm"
*MEAS_COND_AXIS_UNIT-26 ""
*MEAS_COND_AXIS_UNIT-27 ""
*MEAS_COND_AXIS_UNIT-28 ""
*MEAS_COND_AXIS_UNIT-29 ""
*MEAS_COND_AXIS_UNIT-30 "div"
*MEAS_COND_COUNTER_CNTLOSS_CORR "0.0000000000"
*MEAS_COND_COUNTER_PHABASE "38.0000000000"
*MEAS_COND_COUNTER_PHAWINDOW "16.0000000000"
*MEAS_COND_COUNTER_PHA_UNIT "div"
*MEAS_COND_COUNTER_TAUDIFF "30.0000000000"
*MEAS_COND_COUNTER_TAUINT "0.0000000000"
*MEAS_COND_IRRADIATION_MODE "OFF"
*MEAS_COND_IRRADIATION_WIDTH ""
*MEAS_COND_OPT_ATTR "集中法"
*MEAS_COND_OPT_NAME "@集中法"
*MEAS_COND_UNSYMMETRIC_MODE "OFF"
*MEAS_COND_XG_CURRENT "30.0000000000"
*MEAS_COND_XG_VOLTAGE "40.0000000000"
*MEAS_COND_XG_WAVE_TYPE "Ka"
*MEAS_DATA_COUNT "5001.0000000000"
*MEAS_SCAN_AXIS_X "2θ/θ"
*MEAS_SCAN_AXIS_X_INTERNAL "TwoThetaTheta"
*MEAS_SCAN_END_TIME "07/15/21 11:45:31"
*MEAS_SCAN_MODE "CONTINUOUS"
*MEAS_SCAN_MONITOR "0"
*MEAS_SCAN_RESOLUTION_X "0.0002"
*MEAS_SCAN_SPEED "1.0"
*MEAS_SCAN_SPEED_UNIT "deg/min"
*MEAS_SCAN_START "20.0000000000"
*MEAS_SCAN_START_TIME "07/15/21 10:52:39"
*MEAS_SCAN_STEP "0.0100000000"
*MEAS_SCAN_STOP "70.0000000000"
*MEAS_SCAN_UNIT_X "deg"
*MEAS_SCAN_UNIT_Y "counts"
*RAS_HEADER_END
*RAS_INT_START
20.0000 1416.0000 1.0000
20.0400 1382.0000 1.0000
20.0800 1390.0000 1.0000
20.1200 1383.0000 1.0000
20.1600 1371.0000 1.0000
20.2000 1384.0000 1.0000
20.2400 1392.0000 1.0000
20.2800 1443.0000 1.0000
20.3200 1403.0000 1.0000
20.3600 1349.0000 1.0000
20.4000 1385.0000 1.0000
20.4400 1345.0000 1.0000
20.4800 1407.0000 1.0000
20.5200 1407.0000 1.0000
20.5600 1329.0000 1.0000
20.6000 1385.0000 1.0000
20.6400 1379.0000 1.0000
20.6800 1393.0000 1.0000
20.7200 1383.0000 1.0000
20.7600 1419.0000 1.0000
20.8000 1386.0000 1.0000
20.8400 1389.0000 1.0000
20.8800 1345.0000 1.0000
20.9200 1438.0000 1.0000
20.9600 1358.0000 1.0000
21.0000 1357.0000 1.0000
21.0400 1385.0000 1.0000
21.0800 1371.0000 1.0000
21.1200 1410.0000 1.0000
21.1600 1406.0000 1.0000
21.2000 1407.0000 1.0000
21.2400 1359.0000 1.0000
21.2800 1413.0000 1.0000
21.3200 1364.0000 1.0000
21.3600 1425.0000 1.0000
21.4000 1396.0000 1.0000
21.4400 1301.0000 1.0000
21.4800 1364.0000 1.0000
21.5200 1369.0000 1.0000
21.5600 1440.0000 1.0000
21.6000 1368.0000 1.0000
21.6400 1375.0000 1.0000
21.6800 1360.0000 1.0000
21.7200 1359.0000 1.0000
21.7600 1400.0000 1.0000
21.8000 1315.0000 1.0000
21.8400 1363.0000 1.0000
21.8800 1349.0000 1.0000
21.9200 1374.0000 1.0000
21.9600 1378.0000 1.0000
22.0000 1367.0000 1.0000
22.0400 1392.0000 1.0000
22.0800 1372.0000 1.0000
22.1200 1376.0000 1.0000
22.1600 1350.0000 1.0000
22.2000 1402.0000 1.0000
22.2400 1293.0000 1.0000
22.2800 1407.0000 1.0000
22.3200 1428.0000 1.0000
22.3600 1393.0000 1.0000
22.4000 1406.0000 1.0000
22.4400 1383.0000 1.0000
22.4800 1404.0000 1.0000
22.5200 1392.0000 1.0000
22.5600 1437.0000 1.0000
22.6000 1452.0000 1.0000
22.6400 1370.0000 1.0000
22.6800 1445.0000 1.0000
22.7200 1381.0000 1.0000
22.7600 1404.0000 1.0000
22.8000 1422.0000 1.0000
22.8400 1413.0000 1.0000
22.8800 1442.0000 1.0000
22.9200 1372.0000 1.0000
22.9600 1401.0000 1.0000
23.0000 1358.0000 1.0000
23.0400 1340.0000 1.0000
23.0800 1383.0000 1.0000
23.1200 1393.0000 1.0000
23.1600 1410.0000 1.0000
23.2000 1416.0000 1.0000
23.2400 1429.0000 1.0000
23.2800 1420.0000 1.0000
23.3200 1380.0000 1.0000
23.3600 1382.0000 1.0000
23.4000 1453.0000 1.0000
23.4400 1437.0000 1.0000
23.4800 1426.0000 1.0000
23.5200 1419.0000 1.0000
23.5600 1426.0000 1.0000
23.6000 1425.0000 1.0000
23.6400 1395.0000 1.0000
23.6800 1504.0000 1.0000
23.7200 1397.0000 1.0000
23.7600 1467.0000 1.0000
23.8000 1381.0000 1.0000
23.8400 1384.0000 1.0000
23.8800 1396.0000 1.0000
23.9200 1471.0000 1.0000
23.9600 1416.0000 1.0000
24.0000 1446.0000 1.0000
24.0400 1440.0000 1.0000
24.0800 1432.0000 1.0000
24.1200 1431.0000 1.0000
24.1600 1473.0000 1.0000
24.2000 1475.0000 1.0000
24.2400 1429.0000 1.0000
24.2800 1439.0000 1.0000
24.3200 1402.0000 1.0000
24.3600 1443.0000 1.0000
24.4000 1448.0000 1.0000
24.4400 1477.0000 1.0000
24.4800 1479.0000 1.0000
24.5200 1482.0000 1.0000
24.5600 1495.0000 1.0000
24.6000 1419.0000 1.0000
24.6400 1462.0000 1.0000
24.6800 1425.0000 1.0000
24.7200 1497.0000 1.0000
24.7600 1533.0000 1.0000
24.8000 1498.0000 1.0000
24.8400 1528.0000 1.0000
24.8800 1534.0000 1.0000
24.9200 1560.0000 1.0000
24.9600 1493.0000 1.0000
25.0000 1567.0000 1.0000
25.0400 1586.0000 1.0000
25.0800 1469.0000 1.0000
25.1200 1523.0000 1.0000
25.1600 1512.0000 1.0000
25.2000 1561.0000 1.0000
25.2400 1531.0000 1.0000
25.2800 1582.0000 1.0000
25.3200 1510.0000 1.0000
25.3600 1626.0000 1.0000
25.4000 1572.0000 1.0000
25.4400 1505.0000 1.0000
25.4800 1523.0000 1.0000
25.5200 1510.0000 1.0000
25.5600 1545.0000 1.0000
25.6000 1538.0000 1.0000
25.6400 1521.0000 1.0000
25.6800 1533.0000 1.0000
25.7200 1593.0000 1.0000
25.7600 1595.0000 1.0000
25.8000 1614.0000 1.0000
25.8400 1572.0000 1.0000
25.8800 1563.0000 1.0000
25.9200 1522.0000 1.0000
25.9600 1569.0000 1.0000
26.0000 1571.0000 1.0000
26.0400 1526.0000 1.0000
26.0800 1609.0000 1.0000
26.1200 1557.0000 1.0000
26.1600 1618.0000 1.0000
26.2000 1535.0000 1.0000
26.2400 1593.0000 1.0000
26.2800 1635.0000 1.0000
26.3200 1591.0000 1.0000
26.3600 1649.0000 1.0000
26.4000 1622.0000 1.0000
26.4400 1605.0000 1.0000
26.4800 1653.0000 1.0000
26.5200 1667.0000 1.0000
26.5600 1621.0000 1.0000
26.6000 1578.0000 1.0000
26.6400 1721.0000 1.0000
26.6800 1639.0000 1.0000
26.7200 1703.0000 1.0000
26.7600 1799.0000 1.0000
26.8000 1759.0000 1.0000
26.8400 1831.0000 1.0000
26.8800 1799.0000 1.0000
26.9200 1931.0000 1.0000
26.9600 2043.0000 1.0000
27.0000 2128.0000 1.0000
27.0400 2420.0000 1.0000
27.0800 2666.0000 1.0000
27.1200 3096.0000 1.0000
27.1600 3733.0000 1.0000
27.2000 4662.0000 1.0000
27.2400 6058.0000 1.0000
27.2800 6993.0000 1.0000
27.3200 7063.0000 1.0000
27.3600 6302.0000 1.0000
27.4000 4922.0000 1.0000
27.4400 3935.0000 1.0000
27.4800 3230.0000 1.0000
27.5200 2798.0000 1.0000
27.5600 2455.0000 1.0000
27.6000 2179.0000 1.0000
27.6400 2019.0000 1.0000
27.6800 1967.0000 1.0000
27.7200 1870.0000 1.0000
27.7600 1809.0000 1.0000
27.8000 1761.0000 1.0000
27.8400 1678.0000 1.0000
27.8800 1628.0000 1.0000
27.9200 1686.0000 1.0000
27.9600 1595.0000 1.0000
28.0000 1603.0000 1.0000
28.0400 1568.0000 1.0000
28.0800 1575.0000 1.0000
28.1200 1528.0000 1.0000
28.1600 1551.0000 1.0000
28.2000 1571.0000 1.0000
28.2400 1548.0000 1.0000
28.2800 1565.0000 1.0000
28.3200 1545.0000 1.0000
28.3600 1480.0000 1.0000
28.4000 1505.0000 1.0000
28.4400 1446.0000 1.0000
28.4800 1480.0000 1.0000
28.5200 1503.0000 1.0000
28.5600 1412.0000 1.0000
28.6000 1499.0000 1.0000
28.6400 1428.0000 1.0000
28.6800 1498.0000 1.0000
28.7200 1474.0000 1.0000
28.7600 1424.0000 1.0000
28.8000 1420.0000 1.0000
28.8400 1460.0000 1.0000
28.8800 1431.0000 1.0000
28.9200 1458.0000 1.0000
28.9600 1426.0000 1.0000
29.0000 1425.0000 1.0000
29.0400 1451.0000 1.0000
29.0800 1376.0000 1.0000
29.1200 1433.0000 1.0000
29.1600 1442.0000 1.0000
29.2000 1465.0000 1.0000
29.2400 1444.0000 1.0000
29.2800 1382.0000 1.0000
29.3200 1404.0000 1.0000
29.3600 1410.0000 1.0000
29.4000 1418.0000 1.0000
29.4400 1383.0000 1.0000
29.4800 1321.0000 1.0000
29.5200 1394.0000 1.0000
29.5600 1414.0000 1.0000
29.6000 1407.0000 1.0000
29.6400 1347.0000 1.0000
29.6800 1428.0000 1.0000
29.7200 1388.0000 1.0000
29.7600 1397.0000 1.0000
29.8000 1344.0000 1.0000
29.8400 1331.0000 1.0000
29.8800 1403.0000 1.0000
29.9200 1404.0000 1.0000
29.9600 1380.0000 1.0000
30.0000 1383.0000 1.0000
30.0400 1387.0000 1.0000
30.0800 1333.0000 1.0000
30.1200 1371.0000 1.0000
30.1600 1320.0000 1.0000
30.2000 1377.0000 1.0000
30.2400 1353.0000 1.0000
30.2800 1337.0000 1.0000
30.3200 1302.0000 1.0000
30.3600 1298.0000 1.0000
30.4000 1315.0000 1.0000
30.4400 1303.0000 1.0000
30.4800 1355.0000 1.0000
30.5200 1333.0000 1.0000
30.5600 1303.0000 1.0000
30.6000 1268.0000 1.0000
30.6400 1326.0000 1.0000
30.6800 1283.0000 1.0000
30.7200 1308.0000 1.0000
30.7600 1278.0000 1.0000
30.8000 1283.0000 1.0000
30.8400 1310.0000 1.0000
30.8800 1328.0000 1.0000
30.9200 1300.0000 1.0000
30.9600 1374.0000 1.0000
31.0000 1316.0000 1.0000
31.0400 1290.0000 1.0000
31.0800 1316.0000 1.0000
31.1200 1322.0000 1.0000
31.1600 1272.0000 1.0000
31.2000 1317.0000 1.0000
31.2400 1328.0000 1.0000
31.2800 1256.0000 1.0000
31.3200 1242.0000 1.0000
31.3600 1287.0000 1.0000
31.4000 1243.0000 1.0000
31.4400 1245.0000 1.0000
31.4800 1243.0000 1.0000
31.5200 1313.0000 1.0000
31.5600 1181.0000 1.0000
31.6000 1197.0000 1.0000
31.6400 1255.0000 1.0000
31.6800 1255.0000 1.0000
31.7200 1253.0000 1.0000
31.7600 1252.0000 1.0000
31.8000 1247.0000 1.0000
31.8400 1268.0000 1.0000
31.8800 1324.0000 1.0000
31.9200 1272.0000 1.0000
31.9600 1332.0000 1.0000
32.0000 1305.0000 1.0000
32.0400 1284.0000 1.0000
32.0800 1258.0000 1.0000
32.1200 1238.0000 1.0000
32.1600 1246.0000 1.0000
32.2000 1235.0000 1.0000
32.2400 1202.0000 1.0000
32.2800 1194.0000 1.0000
32.3200 1245.0000 1.0000
32.3600 1221.0000 1.0000
32.4000 1162.0000 1.0000
32.4400 1187.0000 1.0000
32.4800 1243.0000 1.0000
32.5200 1225.0000 1.0000
32.5600 1225.0000 1.0000
32.6000 1157.0000 1.0000
32.6400 1258.0000 1.0000
32.6800 1201.0000 1.0000
32.7200 1191.0000 1.0000
32.7600 1141.0000 1.0000
32.8000 1173.0000 1.0000
32.8400 1164.0000 1.0000
32.8800 1240.0000 1.0000
32.9200 1170.0000 1.0000
32.9600 1145.0000 1.0000
33.0000 1114.0000 1.0000
33.0400 1200.0000 1.0000
33.0800 1196.0000 1.0000
33.1200 1159.0000 1.0000
33.1600 1179.0000 1.0000
33.2000 1170.0000 1.0000
33.2400 1184.0000 1.0000
33.2800 1163.0000 1.0000
33.3200 1182.0000 1.0000
33.3600 1220.0000 1.0000
33.4000 1175.0000 1.0000
33.4400 1161.0000 1.0000
33.4800 1172.0000 1.0000
33.5200 1174.0000 1.0000
33.5600 1221.0000 1.0000
33.6000 1161.0000 1.0000
33.6400 1139.0000 1.0000
33.6800 1248.0000 1.0000
33.7200 1153.0000 1.0000
33.7600 1235.0000 1.0000
33.8000 1200.0000 1.0000
33.8400 1224.0000 1.0000
33.8800 1295.0000 1.0000
33.9200 1256.0000 1.0000
33.9600 1248.0000 1.0000
34.0000 1277.0000 1.0000
34.0400 1316.0000 1.0000
34.0800 1316.0000 1.0000
34.1200 1282.0000 1.0000
34.1600 1356.0000 1.0000
34.2000 1415.0000 1.0000
34.2400 1521.0000 1.0000
34.2800 1662.0000 1.0000
34.3200 1773.0000 1.0000
34.3600 2128.0000 1.0000
34.4000 2481.0000 1.0000
34.4400 3051.0000 1.0000
34.4800 3349.0000 1.0000
34.5200 3342.0000 1.0000
34.5600 3041.0000 1.0000
34.6000 2502.0000 1.0000
34.6400 2058.0000 1.0000
34.6800 1813.0000 1.0000
34.7200 1612.0000 1.0000
34.7600 1557.0000 1.0000
34.8000 1487.0000 1.0000
34.8400 1299.0000 1.0000
34.8800 1284.0000 1.0000
34.9200 1243.0000 1.0000
34.9600 1182.0000 1.0000
35.0000 1183.0000 1.0000
35.0400 1136.0000 1.0000
35.0800 1088.0000 1.0000
35.1200 1107.0000 1.0000
35.1600 1074.0000 1.0000
35.2000 1094.0000 1.0000
35.2400 1076.0000 1.0000
35.2800 1066.0000 1.0000
35.3200 1032.0000 1.0000
35.3600 995.0000 1.0000
35.4000 1052.0000 1.0000
35.4400 1028.0000 1.0000
35.4800 1029.0000 1.0000
35.5200 1051.0000 1.0000
35.5600 1033.0000 1.0000
35.6000 1068.0000 1.0000
35.6400 1038.0000 1.0000
35.6800 960.0000 1.0000
35.7200 961.0000 1.0000
35.7600 968.0000 1.0000
35.8000 995.0000 1.0000
35.8400 1018.0000 1.0000
35.8800 973.0000 1.0000
35.9200 1001.0000 1.0000
35.9600 1031.0000 1.0000
36.0000 1015.0000 1.0000
36.0400 1007.0000 1.0000
36.0800 1004.0000 1.0000
36.1200 991.0000 1.0000
36.1600 997.0000 1.0000
36.2000 1007.0000 1.0000
36.2400 1013.0000 1.0000
36.2800 1072.0000 1.0000
36.3200 1038.0000 1.0000
36.3600 1040.0000 1.0000
36.4000 1053.0000 1.0000
36.4400 1004.0000 1.0000
36.4800 1049.0000 1.0000
36.5200 1049.0000 1.0000
36.5600 1016.0000 1.0000
36.6000 992.0000 1.0000
36.6400 1010.0000 1.0000
36.6800 966.0000 1.0000
36.7200 919.0000 1.0000
36.7600 916.0000 1.0000
36.8000 950.0000 1.0000
36.8400 972.0000 1.0000
36.8800 896.0000 1.0000
36.9200 931.0000 1.0000
36.9600 965.0000 1.0000
37.0000 917.0000 1.0000
37.0400 904.0000 1.0000
37.0800 903.0000 1.0000
37.1200 941.0000 1.0000
37.1600 960.0000 1.0000
37.2000 953.0000 1.0000
37.2400 871.0000 1.0000
37.2800 911.0000 1.0000
37.3200 911.0000 1.0000
37.3600 872.0000 1.0000
37.4000 950.0000 1.0000
37.4400 955.0000 1.0000
37.4800 927.0000 1.0000
37.5200 945.0000 1.0000
37.5600 889.0000 1.0000
37.6000 933.0000 1.0000
37.6400 905.0000 1.0000
37.6800 914.0000 1.0000
37.7200 892.0000 1.0000
37.7600 907.0000 1.0000
37.8000 896.0000 1.0000
37.8400 918.0000 1.0000
37.8800 931.0000 1.0000
37.9200 928.0000 1.0000
37.9600 941.0000 1.0000
38.0000 999.0000 1.0000
38.0400 1011.0000 1.0000
38.0800 985.0000 1.0000
38.1200 1112.0000 1.0000
38.1600 1153.0000 1.0000
38.2000 1274.0000 1.0000
38.2400 1469.0000 1.0000
38.2800 1629.0000 1.0000
38.3200 1977.0000 1.0000
38.3600 2460.0000 1.0000
38.4000 3368.0000 1.0000
38.4400 4375.0000 1.0000
38.4800 5581.0000 1.0000
38.5200 6210.0000 1.0000
38.5600 6004.0000 1.0000
38.6000 5439.0000 1.0000
38.6400 4246.0000 1.0000
38.6800 3424.0000 1.0000
38.7200 2569.0000 1.0000
38.7600 2092.0000 1.0000
38.8000 1625.0000 1.0000
38.8400 1369.0000 1.0000
38.8800 1222.0000 1.0000
38.9200 1066.0000 1.0000
38.9600 1032.0000 1.0000
39.0000 966.0000 1.0000
39.0400 870.0000 1.0000
39.0800 944.0000 1.0000
39.1200 902.0000 1.0000
39.1600 902.0000 1.0000
39.2000 890.0000 1.0000
39.2400 854.0000 1.0000
39.2800 771.0000 1.0000
39.3200 816.0000 1.0000
39.3600 839.0000 1.0000
39.4000 837.0000 1.0000
39.4400 824.0000 1.0000
39.4800 872.0000 1.0000
39.5200 858.0000 1.0000
39.5600 834.0000 1.0000
39.6000 916.0000 1.0000
39.6400 898.0000 1.0000
39.6800 890.0000 1.0000
39.7200 839.0000 1.0000
39.7600 864.0000 1.0000
39.8000 814.0000 1.0000
39.8400 819.0000 1.0000
39.8800 837.0000 1.0000
39.9200 789.0000 1.0000
39.9600 795.0000 1.0000
40.0000 784.0000 1.0000
40.0400 739.0000 1.0000
40.0800 776.0000 1.0000
40.1200 744.0000 1.0000
40.1600 780.0000 1.0000
40.2000 809.0000 1.0000
40.2400 778.0000 1.0000
40.2800 772.0000 1.0000
40.3200 785.0000 1.0000
40.3600 797.0000 1.0000
40.4000 750.0000 1.0000
40.4400 725.0000 1.0000
40.4800 750.0000 1.0000
40.5200 752.0000 1.0000
40.5600 774.0000 1.0000
40.6000 707.0000 1.0000
40.6400 718.0000 1.0000
40.6800 755.0000 1.0000
40.7200 795.0000 1.0000
40.7600 757.0000 1.0000
40.8000 706.0000 1.0000
40.8400 743.0000 1.0000
40.8800 736.0000 1.0000
40.9200 741.0000 1.0000
40.9600 738.0000 1.0000
41.0000 758.0000 1.0000
41.0400 744.0000 1.0000
41.0800 727.0000 1.0000
41.1200 718.0000 1.0000
41.1600 730.0000 1.0000
41.2000 715.0000 1.0000
41.2400 725.0000 1.0000
41.2800 740.0000 1.0000
41.3200 712.0000 1.0000
41.3600 731.0000 1.0000
41.4000 771.0000 1.0000
41.4400 736.0000 1.0000
41.4800 743.0000 1.0000
41.5200 674.0000 1.0000
41.5600 739.0000 1.0000
41.6000 749.0000 1.0000
41.6400 753.0000 1.0000
41.6800 758.0000 1.0000
41.7200 742.0000 1.0000
41.7600 713.0000 1.0000
41.8000 744.0000 1.0000
41.8400 730.0000 1.0000
41.8800 751.0000 1.0000
41.9200 765.0000 1.0000
41.9600 736.0000 1.0000
42.0000 734.0000 1.0000
42.0400 750.0000 1.0000
42.0800 706.0000 1.0000
42.1200 756.0000 1.0000
42.1600 733.0000 1.0000
42.2000 715.0000 1.0000
42.2400 750.0000 1.0000
42.2800 707.0000 1.0000
42.3200 682.0000 1.0000
42.3600 710.0000 1.0000
42.4000 721.0000 1.0000
42.4400 756.0000 1.0000
42.4800 680.0000 1.0000
42.5200 745.0000 1.0000
42.5600 716.0000 1.0000
42.6000 700.0000 1.0000
42.6400 734.0000 1.0000
42.6800 706.0000 1.0000
42.7200 745.0000 1.0000
42.7600 731.0000 1.0000
42.8000 726.0000 1.0000
42.8400 724.0000 1.0000
42.8800 695.0000 1.0000
42.9200 670.0000 1.0000
42.9600 709.0000 1.0000
43.0000 714.0000 1.0000
43.0400 787.0000 1.0000
43.0800 769.0000 1.0000
43.1200 789.0000 1.0000
43.1600 800.0000 1.0000
43.2000 780.0000 1.0000
43.2400 787.0000 1.0000
43.2800 832.0000 1.0000
43.3200 795.0000 1.0000
43.3600 764.0000 1.0000
43.4000 747.0000 1.0000
43.4400 754.0000 1.0000
43.4800 742.0000 1.0000
43.5200 724.0000 1.0000
43.5600 728.0000 1.0000
43.6000 735.0000 1.0000
43.6400 739.0000 1.0000
43.6800 710.0000 1.0000
43.7200 711.0000 1.0000
43.7600 752.0000 1.0000
43.8000 686.0000 1.0000
43.8400 698.0000 1.0000
43.8800 713.0000 1.0000
43.9200 665.0000 1.0000
43.9600 656.0000 1.0000
44.0000 695.0000 1.0000
44.0400 697.0000 1.0000
44.0800 697.0000 1.0000
44.1200 699.0000 1.0000
44.1600 684.0000 1.0000
44.2000 697.0000 1.0000
44.2400 678.0000 1.0000
44.2800 712.0000 1.0000
44.3200 687.0000 1.0000
44.3600 682.0000 1.0000
44.4000 683.0000 1.0000
44.4400 718.0000 1.0000
44.4800 692.0000 1.0000
44.5200 687.0000 1.0000
44.5600 712.0000 1.0000
44.6000 664.0000 1.0000
44.6400 700.0000 1.0000
44.6800 716.0000 1.0000
44.7200 694.0000 1.0000
44.7600 657.0000 1.0000
44.8000 672.0000 1.0000
44.8400 670.0000 1.0000
44.8800 694.0000 1.0000
44.9200 657.0000 1.0000
44.9600 682.0000 1.0000
45.0000 697.0000 1.0000
45.0400 683.0000 1.0000
45.0800 629.0000 1.0000
45.1200 679.0000 1.0000
45.1600 713.0000 1.0000
45.2000 680.0000 1.0000
45.2400 718.0000 1.0000
45.2800 648.0000 1.0000
45.3200 668.0000 1.0000
45.3600 670.0000 1.0000
45.4000 637.0000 1.0000
45.4400 697.0000 1.0000
45.4800 647.0000 1.0000
45.5200 738.0000 1.0000
45.5600 682.0000 1.0000
45.6000 665.0000 1.0000
45.6400 664.0000 1.0000
45.6800 684.0000 1.0000
45.7200 692.0000 1.0000
45.7600 684.0000 1.0000
45.8000 704.0000 1.0000
45.8400 678.0000 1.0000
45.8800 670.0000 1.0000
45.9200 701.0000 1.0000
45.9600 683.0000 1.0000
46.0000 635.0000 1.0000
46.0400 666.0000 1.0000
46.0800 708.0000 1.0000
46.1200 673.0000 1.0000
46.1600 646.0000 1.0000
46.2000 685.0000 1.0000
46.2400 703.0000 1.0000
46.2800 657.0000 1.0000
46.3200 693.0000 1.0000
46.3600 681.0000 1.0000
46.4000 682.0000 1.0000
46.4400 676.0000 1.0000
46.4800 659.0000 1.0000
46.5200 717.0000 1.0000
46.5600 629.0000 1.0000
46.6000 675.0000 1.0000
46.6400 695.0000 1.0000
46.6800 661.0000 1.0000
46.7200 632.0000 1.0000
46.7600 673.0000 1.0000
46.8000 650.0000 1.0000
46.8400 684.0000 1.0000
46.8800 635.0000 1.0000
46.9200 712.0000 1.0000
46.9600 686.0000 1.0000
47.0000 730.0000 1.0000
47.0400 629.0000 1.0000
47.0800 639.0000 1.0000
47.1200 664.0000 1.0000
47.1600 675.0000 1.0000
47.2000 682.0000 1.0000
47.2400 679.0000 1.0000
47.2800 647.0000 1.0000
47.3200 669.0000 1.0000
47.3600 644.0000 1.0000
47.4000 641.0000 1.0000
47.4400 640.0000 1.0000
47.4800 649.0000 1.0000
47.5200 693.0000 1.0000
47.5600 625.0000 1.0000
47.6000 622.0000 1.0000
47.6400 628.0000 1.0000
47.6800 627.0000 1.0000
47.7200 658.0000 1.0000
47.7600 638.0000 1.0000
47.8000 617.0000 1.0000
47.8400 651.0000 1.0000
47.8800 644.0000 1.0000
47.9200 591.0000 1.0000
47.9600 663.0000 1.0000
48.0000 641.0000 1.0000
48.0400 657.0000 1.0000
48.0800 619.0000 1.0000
48.1200 625.0000 1.0000
48.1600 667.0000 1.0000
48.2000 619.0000 1.0000
48.2400 617.0000 1.0000
48.2800 619.0000 1.0000
48.3200 664.0000 1.0000
48.3600 642.0000 1.0000
48.4000 628.0000 1.0000
48.4400 624.0000 1.0000
48.4800 696.0000 1.0000
48.5200 639.0000 1.0000
48.5600 607.0000 1.0000
48.6000 619.0000 1.0000
48.6400 627.0000 1.0000
48.6800 612.0000 1.0000
48.7200 658.0000 1.0000
48.7600 629.0000 1.0000
48.8000 643.0000 1.0000
48.8400 647.0000 1.0000
48.8800 646.0000 1.0000
48.9200 619.0000 1.0000
48.9600 629.0000 1.0000
49.0000 594.0000 1.0000
49.0400 613.0000 1.0000
49.0800 635.0000 1.0000
49.1200 666.0000 1.0000
49.1600 630.0000 1.0000
49.2000 624.0000 1.0000
49.2400 631.0000 1.0000
49.2800 641.0000 1.0000
49.3200 599.0000 1.0000
49.3600 635.0000 1.0000
49.4000 640.0000 1.0000
49.4400 614.0000 1.0000
49.4800 629.0000 1.0000
49.5200 651.0000 1.0000
49.5600 607.0000 1.0000
49.6000 634.0000 1.0000
49.6400 626.0000 1.0000
49.6800 630.0000 1.0000
49.7200 625.0000 1.0000
49.7600 631.0000 1.0000
49.8000 618.0000 1.0000
49.8400 626.0000 1.0000
49.8800 631.0000 1.0000
49.9200 620.0000 1.0000
49.9600 597.0000 1.0000
50.0000 641.0000 1.0000
50.0400 636.0000 1.0000
50.0800 670.0000 1.0000
50.1200 587.0000 1.0000
50.1600 676.0000 1.0000
50.2000 672.0000 1.0000
50.2400 644.0000 1.0000
50.2800 665.0000 1.0000
50.3200 613.0000 1.0000
50.3600 667.0000 1.0000
50.4000 620.0000 1.0000
50.4400 638.0000 1.0000
50.4800 683.0000 1.0000
50.5200 646.0000 1.0000
50.5600 604.0000 1.0000
50.6000 625.0000 1.0000
50.6400 661.0000 1.0000
50.6800 612.0000 1.0000
50.7200 607.0000 1.0000
50.7600 637.0000 1.0000
50.8000 632.0000 1.0000
50.8400 630.0000 1.0000
50.8800 614.0000 1.0000
50.9200 637.0000 1.0000
50.9600 642.0000 1.0000
51.0000 683.0000 1.0000
51.0400 665.0000 1.0000
51.0800 639.0000 1.0000
51.1200 633.0000 1.0000
51.1600 675.0000 1.0000
51.2000 627.0000 1.0000
51.2400 677.0000 1.0000
51.2800 666.0000 1.0000
51.3200 698.0000 1.0000
51.3600 671.0000 1.0000
51.4000 657.0000 1.0000
51.4400 677.0000 1.0000
51.4800 731.0000 1.0000
51.5200 658.0000 1.0000
51.5600 711.0000 1.0000
51.6000 644.0000 1.0000
51.6400 702.0000 1.0000
51.6800 694.0000 1.0000
51.7200 709.0000 1.0000
51.7600 711.0000 1.0000
51.8000 750.0000 1.0000
51.8400 717.0000 1.0000
51.8800 843.0000 1.0000
51.9200 837.0000 1.0000
51.9600 955.0000 1.0000
52.0000 1115.0000 1.0000
52.0400 1385.0000 1.0000
52.0800 1588.0000 1.0000
52.1200 2047.0000 1.0000
52.1600 2918.0000 1.0000
52.2000 4182.0000 1.0000
52.2400 5281.0000 1.0000
52.2800 5439.0000 1.0000
52.3200 4822.0000 1.0000
52.3600 4297.0000 1.0000
52.4000 3951.0000 1.0000
52.4400 3049.0000 1.0000
52.4800 2326.0000 1.0000
52.5200 1783.0000 1.0000
52.5600 1418.0000 1.0000
52.6000 1176.0000 1.0000
52.6400 1003.0000 1.0000
52.6800 939.0000 1.0000
52.7200 831.0000 1.0000
52.7600 831.0000 1.0000
52.8000 769.0000 1.0000
52.8400 762.0000 1.0000
52.8800 704.0000 1.0000
52.9200 720.0000 1.0000
52.9600 716.0000 1.0000
53.0000 691.0000 1.0000
53.0400 650.0000 1.0000
53.0800 690.0000 1.0000
53.1200 668.0000 1.0000
53.1600 712.0000 1.0000
53.2000 676.0000 1.0000
53.2400 663.0000 1.0000
53.2800 662.0000 1.0000
53.3200 641.0000 1.0000
53.3600 654.0000 1.0000
53.4000 603.0000 1.0000
53.4400 653.0000 1.0000
53.4800 640.0000 1.0000
53.5200 659.0000 1.0000
53.5600 600.0000 1.0000
53.6000 609.0000 1.0000
53.6400 617.0000 1.0000
53.6800 660.0000 1.0000
53.7200 601.0000 1.0000
53.7600 607.0000 1.0000
53.8000 677.0000 1.0000
53.8400 615.0000 1.0000
53.8800 626.0000 1.0000
53.9200 652.0000 1.0000
53.9600 589.0000 1.0000
54.0000 671.0000 1.0000
54.0400 646.0000 1.0000
54.0800 633.0000 1.0000
54.1200 669.0000 1.0000
54.1600 691.0000 1.0000
54.2000 620.0000 1.0000
54.2400 623.0000 1.0000
54.2800 610.0000 1.0000
54.3200 579.0000 1.0000
54.3600 671.0000 1.0000
54.4000 594.0000 1.0000
54.4400 629.0000 1.0000
54.4800 628.0000 1.0000
54.5200 610.0000 1.0000
54.5600 674.0000 1.0000
54.6000 659.0000 1.0000
54.6400 661.0000 1.0000
54.6800 653.0000 1.0000
54.7200 643.0000 1.0000
54.7600 650.0000 1.0000
54.8000 679.0000 1.0000
54.8400 681.0000 1.0000
54.8800 658.0000 1.0000
54.9200 672.0000 1.0000
54.9600 660.0000 1.0000
55.0000 687.0000 1.0000
55.0400 714.0000 1.0000
55.0800 735.0000 1.0000
55.1200 781.0000 1.0000
55.1600 820.0000 1.0000
55.2000 926.0000 1.0000
55.2400 1026.0000 1.0000
55.2800 1016.0000 1.0000
55.3200 1039.0000 1.0000
55.3600 1034.0000 1.0000
55.4000 973.0000 1.0000
55.4400 891.0000 1.0000
55.4800 880.0000 1.0000
55.5200 779.0000 1.0000
55.5600 751.0000 1.0000
55.6000 700.0000 1.0000
55.6400 705.0000 1.0000
55.6800 688.0000 1.0000
55.7200 687.0000 1.0000
55.7600 668.0000 1.0000
55.8000 688.0000 1.0000
55.8400 640.0000 1.0000
55.8800 667.0000 1.0000
55.9200 669.0000 1.0000
55.9600 674.0000 1.0000
56.0000 635.0000 1.0000
56.0400 601.0000 1.0000
56.0800 609.0000 1.0000
56.1200 627.0000 1.0000
56.1600 571.0000 1.0000
56.2000 615.0000 1.0000
56.2400 638.0000 1.0000
56.2800 602.0000 1.0000
56.3200 614.0000 1.0000
56.3600 622.0000 1.0000
56.4000 623.0000 1.0000
56.4400 629.0000 1.0000
56.4800 610.0000 1.0000
56.5200 599.0000 1.0000
56.5600 583.0000 1.0000
56.6000 631.0000 1.0000
56.6400 610.0000 1.0000
56.6800 595.0000 1.0000
56.7200 641.0000 1.0000
56.7600 620.0000 1.0000
56.8000 604.0000 1.0000
56.8400 622.0000 1.0000
56.8800 613.0000 1.0000
56.9200 660.0000 1.0000
56.9600 589.0000 1.0000
57.0000 592.0000 1.0000
57.0400 620.0000 1.0000
57.0800 577.0000 1.0000
57.1200 577.0000 1.0000
57.1600 638.0000 1.0000
57.2000 654.0000 1.0000
57.2400 615.0000 1.0000
57.2800 602.0000 1.0000
57.3200 630.0000 1.0000
57.3600 591.0000 1.0000
57.4000 609.0000 1.0000
57.4400 605.0000 1.0000
57.4800 620.0000 1.0000
57.5200 585.0000 1.0000
57.5600 640.0000 1.0000
57.6000 601.0000 1.0000
57.6400 601.0000 1.0000
57.6800 600.0000 1.0000
57.7200 639.0000 1.0000
57.7600 598.0000 1.0000
57.8000 612.0000 1.0000
57.8400 588.0000 1.0000
57.8800 665.0000 1.0000
57.9200 630.0000 1.0000
57.9600 578.0000 1.0000
58.0000 644.0000 1.0000
58.0400 605.0000 1.0000
58.0800 564.0000 1.0000
58.1200 595.0000 1.0000
58.1600 635.0000 1.0000
58.2000 607.0000 1.0000
58.2400 610.0000 1.0000
58.2800 626.0000 1.0000
58.3200 628.0000 1.0000
58.3600 631.0000 1.0000
58.4000 615.0000 1.0000
58.4400 591.0000 1.0000
58.4800 611.0000 1.0000
58.5200 650.0000 1.0000
58.5600 626.0000 1.0000
58.6000 596.0000 1.0000
58.6400 597.0000 1.0000
58.6800 610.0000 1.0000
58.7200 594.0000 1.0000
58.7600 609.0000 1.0000
58.8000 625.0000 1.0000
58.8400 602.0000 1.0000
58.8800 673.0000 1.0000
58.9200 605.0000 1.0000
58.9600 592.0000 1.0000
59.0000 583.0000 1.0000
59.0400 625.0000 1.0000
59.0800 615.0000 1.0000
59.1200 601.0000 1.0000
59.1600 629.0000 1.0000
59.2000 612.0000 1.0000
59.2400 597.0000 1.0000
59.2800 626.0000 1.0000
59.3200 625.0000 1.0000
59.3600 628.0000 1.0000
59.4000 625.0000 1.0000
59.4400 579.0000 1.0000
59.4800 617.0000 1.0000
59.5200 583.0000 1.0000
59.5600 595.0000 1.0000
59.6000 606.0000 1.0000
59.6400 615.0000 1.0000
59.6800 598.0000 1.0000
59.7200 613.0000 1.0000
59.7600 614.0000 1.0000
59.8000 583.0000 1.0000
59.8400 585.0000 1.0000
59.8800 579.0000 1.0000
59.9200 608.0000 1.0000
59.9600 594.0000 1.0000
60.0000 608.0000 1.0000
60.0400 597.0000 1.0000
60.0800 581.0000 1.0000
60.1200 567.0000 1.0000
60.1600 622.0000 1.0000
60.2000 603.0000 1.0000
60.2400 613.0000 1.0000
60.2800 587.0000 1.0000
60.3200 622.0000 1.0000
60.3600 605.0000 1.0000
60.4000 609.0000 1.0000
60.4400 604.0000 1.0000
60.4800 620.0000 1.0000
60.5200 636.0000 1.0000
60.5600 625.0000 1.0000
60.6000 588.0000 1.0000
60.6400 616.0000 1.0000
60.6800 614.0000 1.0000
60.7200 615.0000 1.0000
60.7600 628.0000 1.0000
60.8000 604.0000 1.0000
60.8400 605.0000 1.0000
60.8800 592.0000 1.0000
60.9200 596.0000 1.0000
60.9600 627.0000 1.0000
61.0000 622.0000 1.0000
61.0400 653.0000 1.0000
61.0800 612.0000 1.0000
61.1200 622.0000 1.0000
61.1600 620.0000 1.0000
61.2000 635.0000 1.0000
61.2400 630.0000 1.0000
61.2800 571.0000 1.0000
61.3200 640.0000 1.0000
61.3600 545.0000 1.0000
61.4000 611.0000 1.0000
61.4400 637.0000 1.0000
61.4800 623.0000 1.0000
61.5200 644.0000 1.0000
61.5600 600.0000 1.0000
61.6000 591.0000 1.0000
61.6400 641.0000 1.0000
61.6800 684.0000 1.0000
61.7200 666.0000 1.0000
61.7600 634.0000 1.0000
61.8000 682.0000 1.0000
61.8400 665.0000 1.0000
61.8800 705.0000 1.0000
61.9200 732.0000 1.0000
61.9600 783.0000 1.0000
62.0000 777.0000 1.0000
62.0400 862.0000 1.0000
62.0800 971.0000 1.0000
62.1200 1090.0000 1.0000
62.1600 1207.0000 1.0000
62.2000 1358.0000 1.0000
62.2400 1490.0000 1.0000
62.2800 1509.0000 1.0000
62.3200 1444.0000 1.0000
62.3600 1487.0000 1.0000
62.4000 1359.0000 1.0000
62.4400 1288.0000 1.0000
62.4800 1229.0000 1.0000
62.5200 1123.0000 1.0000
62.5600 1025.0000 1.0000
62.6000 917.0000 1.0000
62.6400 865.0000 1.0000
62.6800 812.0000 1.0000
62.7200 736.0000 1.0000
62.7600 756.0000 1.0000
62.8000 679.0000 1.0000
62.8400 689.0000 1.0000
62.8800 718.0000 1.0000
62.9200 681.0000 1.0000
62.9600 662.0000 1.0000
63.0000 644.0000 1.0000
63.0400 655.0000 1.0000
63.0800 635.0000 1.0000
63.1200 651.0000 1.0000
63.1600 621.0000 1.0000
63.2000 665.0000 1.0000
63.2400 610.0000 1.0000
63.2800 662.0000 1.0000
63.3200 614.0000 1.0000
63.3600 614.0000 1.0000
63.4000 643.0000 1.0000
63.4400 606.0000 1.0000
63.4800 626.0000 1.0000
63.5200 612.0000 1.0000
63.5600 653.0000 1.0000
63.6000 674.0000 1.0000
63.6400 623.0000 1.0000
63.6800 637.0000 1.0000
63.7200 627.0000 1.0000
63.7600 639.0000 1.0000
63.8000 602.0000 1.0000
63.8400 608.0000 1.0000
63.8800 638.0000 1.0000
63.9200 607.0000 1.0000
63.9600 615.0000 1.0000
64.0000 646.0000 1.0000
64.0400 630.0000 1.0000
64.0800 581.0000 1.0000
64.1200 589.0000 1.0000
64.1600 614.0000 1.0000
64.2000 649.0000 1.0000
64.2400 641.0000 1.0000
64.2800 596.0000 1.0000
64.3200 605.0000 1.0000
64.3600 627.0000 1.0000
64.4000 647.0000 1.0000
64.4400 623.0000 1.0000
64.4800 659.0000 1.0000
64.5200 649.0000 1.0000
64.5600 645.0000 1.0000
64.6000 679.0000 1.0000
64.6400 662.0000 1.0000
64.6800 658.0000 1.0000
64.7200 619.0000 1.0000
64.7600 663.0000 1.0000
64.8000 646.0000 1.0000
64.8400 683.0000 1.0000
64.8800 636.0000 1.0000
64.9200 672.0000 1.0000
64.9600 636.0000 1.0000
65.0000 628.0000 1.0000
65.0400 632.0000 1.0000
65.0800 638.0000 1.0000
65.1200 653.0000 1.0000
65.1600 659.0000 1.0000
65.2000 637.0000 1.0000
65.2400 664.0000 1.0000
65.2800 654.0000 1.0000
65.3200 628.0000 1.0000
65.3600 622.0000 1.0000
65.4000 663.0000 1.0000
65.4400 621.0000 1.0000
65.4800 673.0000 1.0000
65.5200 681.0000 1.0000
65.5600 691.0000 1.0000
65.6000 673.0000 1.0000
65.6400 665.0000 1.0000
65.6800 696.0000 1.0000
65.7200 691.0000 1.0000
65.7600 676.0000 1.0000
65.8000 754.0000 1.0000
65.8400 765.0000 1.0000
65.8800 806.0000 1.0000
65.9200 870.0000 1.0000
65.9600 950.0000 1.0000
66.0000 1048.0000 1.0000
66.0400 1173.0000 1.0000
66.0800 1399.0000 1.0000
66.1200 1725.0000 1.0000
66.1600 2212.0000 1.0000
66.2000 2599.0000 1.0000
66.2400 2767.0000 1.0000
66.2800 2668.0000 1.0000
66.3200 2432.0000 1.0000
66.3600 2385.0000 1.0000
66.4000 2267.0000 1.0000
66.4400 2010.0000 1.0000
66.4800 1798.0000 1.0000
66.5200 1497.0000 1.0000
66.5600 1285.0000 1.0000
66.6000 1078.0000 1.0000
66.6400 966.0000 1.0000
66.6800 917.0000 1.0000
66.7200 808.0000 1.0000
66.7600 737.0000 1.0000
66.8000 779.0000 1.0000
66.8400 668.0000 1.0000
66.8800 695.0000 1.0000
66.9200 649.0000 1.0000
66.9600 642.0000 1.0000
67.0000 653.0000 1.0000
67.0400 634.0000 1.0000
67.0800 631.0000 1.0000
67.1200 607.0000 1.0000
67.1600 543.0000 1.0000
67.2000 579.0000 1.0000
67.2400 595.0000 1.0000
67.2800 598.0000 1.0000
67.3200 604.0000 1.0000
67.3600 595.0000 1.0000
67.4000 599.0000 1.0000
67.4400 596.0000 1.0000
67.4800 557.0000 1.0000
67.5200 592.0000 1.0000
67.5600 577.0000 1.0000
67.6000 579.0000 1.0000
67.6400 556.0000 1.0000
67.6800 559.0000 1.0000
67.7200 603.0000 1.0000
67.7600 581.0000 1.0000
67.8000 556.0000 1.0000
67.8400 563.0000 1.0000
67.8800 538.0000 1.0000
67.9200 552.0000 1.0000
67.9600 582.0000 1.0000
68.0000 588.0000 1.0000
68.0400 556.0000 1.0000
68.0800 592.0000 1.0000
68.1200 552.0000 1.0000
68.1600 598.0000 1.0000
68.2000 590.0000 1.0000
68.2400 565.0000 1.0000
68.2800 533.0000 1.0000
68.3200 569.0000 1.0000
68.3600 526.0000 1.0000
68.4000 569.0000 1.0000
68.4400 551.0000 1.0000
68.4800 570.0000 1.0000
68.5200 557.0000 1.0000
68.5600 504.0000 1.0000
68.6000 578.0000 1.0000
68.6400 552.0000 1.0000
68.6800 527.0000 1.0000
68.7200 558.0000 1.0000
68.7600 580.0000 1.0000
68.8000 550.0000 1.0000
68.8400 569.0000 1.0000
68.8800 560.0000 1.0000
68.9200 545.0000 1.0000
68.9600 568.0000 1.0000
69.0000 555.0000 1.0000
69.0400 522.0000 1.0000
69.0800 535.0000 1.0000
69.1200 566.0000 1.0000
69.1600 542.0000 1.0000
69.2000 552.0000 1.0000
69.2400 576.0000 1.0000
69.2800 583.0000 1.0000
69.3200 567.0000 1.0000
69.3600 519.0000 1.0000
69.4000 557.0000 1.0000
69.4400 596.0000 1.0000
69.4800 558.0000 1.0000
69.5200 559.0000 1.0000
69.5600 583.0000 1.0000
69.6000 562.0000 1.0000
69.6400 511.0000 1.0000
69.6800 553.0000 1.0000
69.7200 578.0000 1.0000
69.7600 557.0000 1.0000
69.8000 566.0000 1.0000
69.8400 554.0000 1.0000
69.8800 508.0000 1.0000
69.9200 527.0000 1.0000
69.9600 560.0000 1.0000
70.0000 525.0000 1.0000
*RAS_INT_END
*RAS_TEMPERATURE_START
*RAS_TEMPERATURE_END
*RAS_DATA_END