File: Section2_75_samples/XRD/No_054_NSS2_3.ras
*RAS_DATA_START
*RAS_HEADER_START
*DISP_FMT_X "%.2f"
*DISP_FMT_Y "%.0f"
*DISP_FULLSCALE "14754.0000000000"
*DISP_LINE_COLOR "255.0000000000"
*DISP_LINE_STYLE "0.0000000000"
*DISP_LINE_WIDTH "0.2500000000"
*DISP_NOTE "測定データ-10"
*DISP_OFFSET_Y "0.0000000000"
*DISP_PEAKSEARCH_UNIT_Y "cps"
*DISP_RANGE_BOTTOM "0.0000000000"
*DISP_RANGE_LEFT "20.0000000000"
*DISP_RANGE_LOGCUTOFF "0.0100000000"
*DISP_RANGE_RIGHT "70.0000000000"
*DISP_RANGE_TOP "14754.0000000000"
*DISP_SCALE_MODE_Y "0.0000000000"
*DISP_TAB_NAME "2θ/θ"
*DISP_TITLE_Y "強度"
*DISP_UNIT_Y "cps"
*DISP_WINDOW_NAME "MSG_MACROENGINE"
*FILE_COMMENT " "
*FILE_MD5 ""
*FILE_MEMO " "
*FILE_OPERATOR "Administrator"
*FILE_SAMPLE " "
*FILE_TYPE "RAS_RAW"
*FILE_USERGROUP "システムマネージャ"
*FILE_VERSION "1.0000000000"
*HW_ATTACHMENT_ID "ATT0025"
*HW_ATTACHMENT_NAME "標準|Standard"
*HW_COUNTER_ID-0 "CUT0025"
*HW_COUNTER_ID-1 "CUT0020"
*HW_COUNTER_ID-2 "CUT0020"
*HW_COUNTER_ID-3 "CSL0021"
*HW_COUNTER_ID-4 "CMC0021"
*HW_COUNTER_NAME-0 "D/teX Ultra|D/teX Ultra"
*HW_COUNTER_NAME-1 "None|None"
*HW_COUNTER_NAME-2 "None|None"
*HW_COUNTER_NAME-3 "BBM|BBM"
*HW_COUNTER_NAME-4 "検出器モノクロメータ|Detector monochromator"
*HW_COUNTER_SELECT_NAME "D/teX Ultra|D/teX Ultra"
*HW_GONIOMETER_ID "GON0023"
*HW_GONIOMETER_NAME "SmartLab|SmartLab"
*HW_GONIOMETER_RADIUS-0 "90.0"
*HW_GONIOMETER_RADIUS-1 "114.0"
*HW_GONIOMETER_RADIUS-2 "190.0"
*HW_GONIOMETER_RADIUS-3 "300.0"
*HW_GONIOMETER_RADIUS-4 "187.0"
*HW_GONIOMETER_RADIUS-5 "300.0"
*HW_GONIOMETER_RADIUS-6 "113.0"
*HW_GONIOMETER_RADIUS-7 "331.0"
*HW_I_OPT_ID-0 "CBO0021"
*HW_I_OPT_ID-1 "ICR0023"
*HW_I_OPT_ID-2 "ISL0021"
*HW_I_OPT_ID-3 "ISO0021"
*HW_I_OPT_ID-4 "IAD0021"
*HW_I_OPT_ID-5 "IPR0001"
*HW_I_OPT_NAME-0 "CBOユニット|CBO unit"
*HW_I_OPT_NAME-1 "標準入射光学ユニット|Standard incident optical unit"
*HW_I_OPT_NAME-2 "標準入射スリットボックス|Standard incident slit box"
*HW_I_OPT_NAME-3 "入射平行スリット|Incident parallel slit"
*HW_I_OPT_NAME-4 "長手制限スリット|Length limiting slit"
*HW_I_OPT_NAME-5 "None|None"
*HW_R_ATTENUATER_AUTOMODE "0"
*HW_R_OPT_ID-0 "RSS0021"
*HW_R_OPT_ID-1 "RCR0023"
*HW_R_OPT_ID-2 "RSO0021"
*HW_R_OPT_ID-3 "RRS0021"
*HW_R_OPT_ID-4 "ATN0021"
*HW_R_OPT_ID-5 "RFL0021"
*HW_R_OPT_ID-6 "RAD0021"
*HW_R_OPT_NAME-0 "標準受光スリットボックス1|Standard receiving slit box # 1"
*HW_R_OPT_NAME-1 "標準受光光学ユニット1|Standard receiving unit # 1"
*HW_R_OPT_NAME-2 "標準受光光学ユニット2|Standard receiving optical unit # 2"
*HW_R_OPT_NAME-3 "標準受光スリットボックス2|Standard receiving slit box # 2"
*HW_R_OPT_NAME-4 "標準アッテネータ|Standard Attenuator"
*HW_R_OPT_NAME-5 "Cu Kβ|Cu K-beta"
*HW_R_OPT_NAME-6 "調整用受光スリット|Alignment receiving slit"
*HW_SAMPLE_HOLDER_ID "SMP0023"
*HW_SAMPLE_HOLDER_NAME "標準Zステージ|Standard Z stage"
*HW_XG_CURRENT_MAX "50"
*HW_XG_CURRENT_MIN "2"
*HW_XG_CURRENT_RESOLUTION "1"
*HW_XG_CURRENT_UNIT "mA"
*HW_XG_FOCUS "1mm x 10mm"
*HW_XG_FOCUS_TYPE "Normal"
*HW_XG_ID ""
*HW_XG_NAME "3kW 封入管(ID:1200)|3kW Sealed tube(ID:1200)"
*HW_XG_TARGET_ATOMIC_NUMBER "29.0000000000"
*HW_XG_TARGET_NAME "Cu"
*HW_XG_TYPE "Hermetic"
*HW_XG_VOLTAGE_MAX "60"
*HW_XG_VOLTAGE_MIN "20"
*HW_XG_VOLTAGE_RESOLUTION "1"
*HW_XG_VOLTAGE_UNIT "kV"
*HW_XG_WATT_MAX "1.500"
*HW_XG_WATT_UNIT "kW"
*HW_XG_WAVE_LENGTH_ALPHA1 "1.540593"
*HW_XG_WAVE_LENGTH_ALPHA2 "1.544414"
*HW_XG_WAVE_LENGTH_BETA "1.392250"
*MEAS_COND_AXIS_NAME-0 "2θ/θ"
*MEAS_COND_AXIS_NAME-1 "2θ"
*MEAS_COND_AXIS_NAME-2 "ω"
*MEAS_COND_AXIS_NAME-3 "Z"
*MEAS_COND_AXIS_NAME-4 "2θ/ω"
*MEAS_COND_AXIS_NAME-5 "θs"
*MEAS_COND_AXIS_NAME-6 "θd"
*MEAS_COND_AXIS_NAME-7 "Ts"
*MEAS_COND_AXIS_NAME-8 "CBO選択スリット"
*MEAS_COND_AXIS_NAME-9 "M"
*MEAS_COND_AXIS_NAME-10 "入射平行スリット"
*MEAS_COND_AXIS_NAME-11 "入射スリット"
*MEAS_COND_AXIS_NAME-12 ""
*MEAS_COND_AXIS_NAME-13 "Zs"
*MEAS_COND_AXIS_NAME-14 "入射光学素子"
*MEAS_COND_AXIS_NAME-15 "長手制限スリット"
*MEAS_COND_AXIS_NAME-16 "センタースリット"
*MEAS_COND_AXIS_NAME-17 "フィルター"
*MEAS_COND_AXIS_NAME-18 "受光スリット1"
*MEAS_COND_AXIS_NAME-19 "受光スリット2"
*MEAS_COND_AXIS_NAME-20 "受光光学素子"
*MEAS_COND_AXIS_NAME-21 "受光平行スリット"
*MEAS_COND_AXIS_NAME-22 "調整用受光スリット"
*MEAS_COND_AXIS_NAME-23 ""
*MEAS_COND_AXIS_NAME-24 ""
*MEAS_COND_AXIS_NAME-25 "Zd"
*MEAS_COND_AXIS_NAME-26 "アッテネータ"
*MEAS_COND_AXIS_NAME-27 "検出器モノクロメータ"
*MEAS_COND_AXIS_NAME-28 "モノクロメータスリット"
*MEAS_COND_AXIS_NAME-29 "プライマリビーム"
*MEAS_COND_AXIS_NAME-30 "PHA"
*MEAS_COND_AXIS_NAME_INTERNAL-0 "TwoThetaTheta"
*MEAS_COND_AXIS_NAME_INTERNAL-1 "TwoTheta"
*MEAS_COND_AXIS_NAME_INTERNAL-2 "Omega"
*MEAS_COND_AXIS_NAME_INTERNAL-3 "Z"
*MEAS_COND_AXIS_NAME_INTERNAL-4 "TwoThetaOmega"
*MEAS_COND_AXIS_NAME_INTERNAL-5 "ThetaS"
*MEAS_COND_AXIS_NAME_INTERNAL-6 "ThetaD"
*MEAS_COND_AXIS_NAME_INTERNAL-7 "Ts"
*MEAS_COND_AXIS_NAME_INTERNAL-8 "CBO"
*MEAS_COND_AXIS_NAME_INTERNAL-9 "CBO-M"
*MEAS_COND_AXIS_NAME_INTERNAL-10 "IncidentSollerSlit"
*MEAS_COND_AXIS_NAME_INTERNAL-11 "IncidentSlitBox"
*MEAS_COND_AXIS_NAME_INTERNAL-12 "IncidentSlitBox-_Axis"
*MEAS_COND_AXIS_NAME_INTERNAL-13 "Zs"
*MEAS_COND_AXIS_NAME_INTERNAL-14 "IncidentMonochromator"
*MEAS_COND_AXIS_NAME_INTERNAL-15 "IncidentAxdSlit"
*MEAS_COND_AXIS_NAME_INTERNAL-16 "CenterSlit"
*MEAS_COND_AXIS_NAME_INTERNAL-17 "Filter"
*MEAS_COND_AXIS_NAME_INTERNAL-18 "ReceivingSlitBox1"
*MEAS_COND_AXIS_NAME_INTERNAL-19 "ReceivingSlitBox2"
*MEAS_COND_AXIS_NAME_INTERNAL-20 "ReceivingOptics"
*MEAS_COND_AXIS_NAME_INTERNAL-21 "ReceivingSollerSlit"
*MEAS_COND_AXIS_NAME_INTERNAL-22 "ReceivingAxdSlit"
*MEAS_COND_AXIS_NAME_INTERNAL-23 "ReceivingSlitBox1-_Axis"
*MEAS_COND_AXIS_NAME_INTERNAL-24 "ReceivingSlitBox2-_Axis"
*MEAS_COND_AXIS_NAME_INTERNAL-25 "ReceivingSlitBox2-Zd"
*MEAS_COND_AXIS_NAME_INTERNAL-26 "Attenuator"
*MEAS_COND_AXIS_NAME_INTERNAL-27 "CounterMonochromator"
*MEAS_COND_AXIS_NAME_INTERNAL-28 "CounterSlit"
*MEAS_COND_AXIS_NAME_INTERNAL-29 "IncidentPrimary"
*MEAS_COND_AXIS_NAME_INTERNAL-30 "PHA"
*MEAS_COND_AXIS_NAME_MAGICNO-0 "83951616.0000000000"
*MEAS_COND_AXIS_NAME_MAGICNO-1 "268632064.0000000000"
*MEAS_COND_AXIS_NAME_MAGICNO-2 "268500992.0000000000"
*MEAS_COND_AXIS_NAME_MAGICNO-3 "285278208.0000000000"
*MEAS_COND_AXIS_NAME_MAGICNO-4 "83951616.0000000000"
*MEAS_COND_AXIS_NAME_MAGICNO-5 "131072.0000000000"
*MEAS_COND_AXIS_NAME_MAGICNO-6 "131072.0000000000"
*MEAS_COND_AXIS_NAME_MAGICNO-7 "318898176.0000000000"
*MEAS_COND_AXIS_NAME_MAGICNO-8 "20971521.0000000000"
*MEAS_COND_AXIS_NAME_MAGICNO-9 "285343744.0000000000"
*MEAS_COND_AXIS_NAME_MAGICNO-10 "20971521.0000000000"
*MEAS_COND_AXIS_NAME_MAGICNO-11 "22020097.0000000000"
*MEAS_COND_AXIS_NAME_MAGICNO-12 "25165824.0000000000"
*MEAS_COND_AXIS_NAME_MAGICNO-13 "318898176.0000000000"
*MEAS_COND_AXIS_NAME_MAGICNO-14 "1.0000000000"
*MEAS_COND_AXIS_NAME_MAGICNO-15 "20971521.0000000000"
*MEAS_COND_AXIS_NAME_MAGICNO-16 "20971521.0000000000"
*MEAS_COND_AXIS_NAME_MAGICNO-17 "20971521.0000000000"
*MEAS_COND_AXIS_NAME_MAGICNO-18 "23068673.0000000000"
*MEAS_COND_AXIS_NAME_MAGICNO-19 "23068673.0000000000"
*MEAS_COND_AXIS_NAME_MAGICNO-20 "20971521.0000000000"
*MEAS_COND_AXIS_NAME_MAGICNO-21 "20971521.0000000000"
*MEAS_COND_AXIS_NAME_MAGICNO-22 "20971521.0000000000"
*MEAS_COND_AXIS_NAME_MAGICNO-23 "25165824.0000000000"
*MEAS_COND_AXIS_NAME_MAGICNO-24 "25165824.0000000000"
*MEAS_COND_AXIS_NAME_MAGICNO-25 "285343744.0000000000"
*MEAS_COND_AXIS_NAME_MAGICNO-26 "17301505.0000000000"
*MEAS_COND_AXIS_NAME_MAGICNO-27 "20971521.0000000000"
*MEAS_COND_AXIS_NAME_MAGICNO-28 "20971521.0000000000"
*MEAS_COND_AXIS_NAME_MAGICNO-29 "20971521.0000000000"
*MEAS_COND_AXIS_NAME_MAGICNO-30 "0.0000000000"
*MEAS_COND_AXIS_OFFSET-0 "-"
*MEAS_COND_AXIS_OFFSET-1 "-0.1081000000"
*MEAS_COND_AXIS_OFFSET-2 "0.3758000000"
*MEAS_COND_AXIS_OFFSET-3 "-"
*MEAS_COND_AXIS_OFFSET-4 "-"
*MEAS_COND_AXIS_OFFSET-5 "0.3758000000"
*MEAS_COND_AXIS_OFFSET-6 "-0.4839000000"
*MEAS_COND_AXIS_OFFSET-7 "-"
*MEAS_COND_AXIS_OFFSET-8 "-"
*MEAS_COND_AXIS_OFFSET-9 "-"
*MEAS_COND_AXIS_OFFSET-10 "-"
*MEAS_COND_AXIS_OFFSET-11 "-"
*MEAS_COND_AXIS_OFFSET-12 "-"
*MEAS_COND_AXIS_OFFSET-13 "-"
*MEAS_COND_AXIS_OFFSET-14 "-"
*MEAS_COND_AXIS_OFFSET-15 "-"
*MEAS_COND_AXIS_OFFSET-16 "-"
*MEAS_COND_AXIS_OFFSET-17 "-"
*MEAS_COND_AXIS_OFFSET-18 "-"
*MEAS_COND_AXIS_OFFSET-19 "-"
*MEAS_COND_AXIS_OFFSET-20 "-"
*MEAS_COND_AXIS_OFFSET-21 "-"
*MEAS_COND_AXIS_OFFSET-22 "-"
*MEAS_COND_AXIS_OFFSET-23 "-"
*MEAS_COND_AXIS_OFFSET-24 "-"
*MEAS_COND_AXIS_OFFSET-25 "-"
*MEAS_COND_AXIS_OFFSET-26 "-"
*MEAS_COND_AXIS_OFFSET-27 "-"
*MEAS_COND_AXIS_OFFSET-28 "-"
*MEAS_COND_AXIS_OFFSET-29 "-"
*MEAS_COND_AXIS_OFFSET-30 "-"
*MEAS_COND_AXIS_POSITION-0 "0.0000000000"
*MEAS_COND_AXIS_POSITION-1 "0.0000000000"
*MEAS_COND_AXIS_POSITION-2 "0.0000000000"
*MEAS_COND_AXIS_POSITION-3 "-0.5500000000"
*MEAS_COND_AXIS_POSITION-4 "0.0000000000"
*MEAS_COND_AXIS_POSITION-5 "0.0000000000"
*MEAS_COND_AXIS_POSITION-6 "0.0000000000"
*MEAS_COND_AXIS_POSITION-7 "-0.4278800000"
*MEAS_COND_AXIS_POSITION-8 "BB"
*MEAS_COND_AXIS_POSITION-9 "0.0000000000"
*MEAS_COND_AXIS_POSITION-10 "Soller_slit_5.0deg"
*MEAS_COND_AXIS_POSITION-11 "2/3deg"
*MEAS_COND_AXIS_POSITION-12 "2.2088000000"
*MEAS_COND_AXIS_POSITION-13 "-0.4140600000"
*MEAS_COND_AXIS_POSITION-14 "0.0000000000"
*MEAS_COND_AXIS_POSITION-15 "10.0mm"
*MEAS_COND_AXIS_POSITION-16 "None"
*MEAS_COND_AXIS_POSITION-17 "Cu_K-beta"
*MEAS_COND_AXIS_POSITION-18 "13.000mm"
*MEAS_COND_AXIS_POSITION-19 "13.000mm"
*MEAS_COND_AXIS_POSITION-20 "No_unit"
*MEAS_COND_AXIS_POSITION-21 "Soller_slit_5.0deg"
*MEAS_COND_AXIS_POSITION-22 "None"
*MEAS_COND_AXIS_POSITION-23 "13.0000000000"
*MEAS_COND_AXIS_POSITION-24 "13.0000000000"
*MEAS_COND_AXIS_POSITION-25 "0.0109400000"
*MEAS_COND_AXIS_POSITION-26 "Open"
*MEAS_COND_AXIS_POSITION-27 "None"
*MEAS_COND_AXIS_POSITION-28 "None"
*MEAS_COND_AXIS_POSITION-29 "None"
*MEAS_COND_AXIS_POSITION-30 "38.0000000000"
*MEAS_COND_AXIS_UNIT-0 "deg"
*MEAS_COND_AXIS_UNIT-1 "deg"
*MEAS_COND_AXIS_UNIT-2 "deg"
*MEAS_COND_AXIS_UNIT-3 "mm"
*MEAS_COND_AXIS_UNIT-4 "deg"
*MEAS_COND_AXIS_UNIT-5 "deg"
*MEAS_COND_AXIS_UNIT-6 "deg"
*MEAS_COND_AXIS_UNIT-7 "mm"
*MEAS_COND_AXIS_UNIT-8 ""
*MEAS_COND_AXIS_UNIT-9 "pulse"
*MEAS_COND_AXIS_UNIT-10 ""
*MEAS_COND_AXIS_UNIT-11 ""
*MEAS_COND_AXIS_UNIT-12 "mm"
*MEAS_COND_AXIS_UNIT-13 "mm"
*MEAS_COND_AXIS_UNIT-14 ""
*MEAS_COND_AXIS_UNIT-15 ""
*MEAS_COND_AXIS_UNIT-16 ""
*MEAS_COND_AXIS_UNIT-17 ""
*MEAS_COND_AXIS_UNIT-18 ""
*MEAS_COND_AXIS_UNIT-19 ""
*MEAS_COND_AXIS_UNIT-20 ""
*MEAS_COND_AXIS_UNIT-21 ""
*MEAS_COND_AXIS_UNIT-22 ""
*MEAS_COND_AXIS_UNIT-23 "mm"
*MEAS_COND_AXIS_UNIT-24 "mm"
*MEAS_COND_AXIS_UNIT-25 "mm"
*MEAS_COND_AXIS_UNIT-26 ""
*MEAS_COND_AXIS_UNIT-27 ""
*MEAS_COND_AXIS_UNIT-28 ""
*MEAS_COND_AXIS_UNIT-29 ""
*MEAS_COND_AXIS_UNIT-30 "div"
*MEAS_COND_COUNTER_CNTLOSS_CORR "0.0000000000"
*MEAS_COND_COUNTER_PHABASE "38.0000000000"
*MEAS_COND_COUNTER_PHAWINDOW "16.0000000000"
*MEAS_COND_COUNTER_PHA_UNIT "div"
*MEAS_COND_COUNTER_TAUDIFF "30.0000000000"
*MEAS_COND_COUNTER_TAUINT "0.0000000000"
*MEAS_COND_IRRADIATION_MODE "OFF"
*MEAS_COND_IRRADIATION_WIDTH ""
*MEAS_COND_OPT_ATTR "集中法"
*MEAS_COND_OPT_NAME "@集中法"
*MEAS_COND_UNSYMMETRIC_MODE "OFF"
*MEAS_COND_XG_CURRENT "30.0000000000"
*MEAS_COND_XG_VOLTAGE "40.0000000000"
*MEAS_COND_XG_WAVE_TYPE "Ka"
*MEAS_DATA_COUNT "5001.0000000000"
*MEAS_SCAN_AXIS_X "2θ/θ"
*MEAS_SCAN_AXIS_X_INTERNAL "TwoThetaTheta"
*MEAS_SCAN_END_TIME "07/12/21 17:00:48"
*MEAS_SCAN_MODE "CONTINUOUS"
*MEAS_SCAN_MONITOR "0"
*MEAS_SCAN_RESOLUTION_X "0.0002"
*MEAS_SCAN_SPEED "1.0"
*MEAS_SCAN_SPEED_UNIT "deg/min"
*MEAS_SCAN_START "20.0000000000"
*MEAS_SCAN_START_TIME "07/12/21 16:07:55"
*MEAS_SCAN_STEP "0.0100000000"
*MEAS_SCAN_STOP "70.0000000000"
*MEAS_SCAN_UNIT_X "deg"
*MEAS_SCAN_UNIT_Y "counts"
*RAS_HEADER_END
*RAS_INT_START
20.0000 1517.0000 1.0000
20.0400 1527.0000 1.0000
20.0800 1601.0000 1.0000
20.1200 1577.0000 1.0000
20.1600 1604.0000 1.0000
20.2000 1603.0000 1.0000
20.2400 1531.0000 1.0000
20.2800 1578.0000 1.0000
20.3200 1552.0000 1.0000
20.3600 1620.0000 1.0000
20.4000 1612.0000 1.0000
20.4400 1605.0000 1.0000
20.4800 1605.0000 1.0000
20.5200 1600.0000 1.0000
20.5600 1553.0000 1.0000
20.6000 1593.0000 1.0000
20.6400 1513.0000 1.0000
20.6800 1594.0000 1.0000
20.7200 1584.0000 1.0000
20.7600 1559.0000 1.0000
20.8000 1579.0000 1.0000
20.8400 1550.0000 1.0000
20.8800 1483.0000 1.0000
20.9200 1546.0000 1.0000
20.9600 1585.0000 1.0000
21.0000 1567.0000 1.0000
21.0400 1591.0000 1.0000
21.0800 1624.0000 1.0000
21.1200 1577.0000 1.0000
21.1600 1611.0000 1.0000
21.2000 1593.0000 1.0000
21.2400 1616.0000 1.0000
21.2800 1636.0000 1.0000
21.3200 1626.0000 1.0000
21.3600 1562.0000 1.0000
21.4000 1640.0000 1.0000
21.4400 1637.0000 1.0000
21.4800 1582.0000 1.0000
21.5200 1552.0000 1.0000
21.5600 1617.0000 1.0000
21.6000 1607.0000 1.0000
21.6400 1625.0000 1.0000
21.6800 1599.0000 1.0000
21.7200 1626.0000 1.0000
21.7600 1598.0000 1.0000
21.8000 1624.0000 1.0000
21.8400 1550.0000 1.0000
21.8800 1567.0000 1.0000
21.9200 1591.0000 1.0000
21.9600 1583.0000 1.0000
22.0000 1542.0000 1.0000
22.0400 1628.0000 1.0000
22.0800 1659.0000 1.0000
22.1200 1592.0000 1.0000
22.1600 1702.0000 1.0000
22.2000 1609.0000 1.0000
22.2400 1596.0000 1.0000
22.2800 1637.0000 1.0000
22.3200 1618.0000 1.0000
22.3600 1628.0000 1.0000
22.4000 1542.0000 1.0000
22.4400 1606.0000 1.0000
22.4800 1626.0000 1.0000
22.5200 1626.0000 1.0000
22.5600 1585.0000 1.0000
22.6000 1661.0000 1.0000
22.6400 1493.0000 1.0000
22.6800 1608.0000 1.0000
22.7200 1648.0000 1.0000
22.7600 1591.0000 1.0000
22.8000 1596.0000 1.0000
22.8400 1647.0000 1.0000
22.8800 1692.0000 1.0000
22.9200 1556.0000 1.0000
22.9600 1684.0000 1.0000
23.0000 1630.0000 1.0000
23.0400 1623.0000 1.0000
23.0800 1613.0000 1.0000
23.1200 1672.0000 1.0000
23.1600 1634.0000 1.0000
23.2000 1654.0000 1.0000
23.2400 1652.0000 1.0000
23.2800 1688.0000 1.0000
23.3200 1613.0000 1.0000
23.3600 1626.0000 1.0000
23.4000 1695.0000 1.0000
23.4400 1617.0000 1.0000
23.4800 1644.0000 1.0000
23.5200 1623.0000 1.0000
23.5600 1651.0000 1.0000
23.6000 1603.0000 1.0000
23.6400 1608.0000 1.0000
23.6800 1667.0000 1.0000
23.7200 1626.0000 1.0000
23.7600 1600.0000 1.0000
23.8000 1679.0000 1.0000
23.8400 1640.0000 1.0000
23.8800 1671.0000 1.0000
23.9200 1605.0000 1.0000
23.9600 1687.0000 1.0000
24.0000 1615.0000 1.0000
24.0400 1624.0000 1.0000
24.0800 1612.0000 1.0000
24.1200 1658.0000 1.0000
24.1600 1630.0000 1.0000
24.2000 1627.0000 1.0000
24.2400 1604.0000 1.0000
24.2800 1721.0000 1.0000
24.3200 1670.0000 1.0000
24.3600 1733.0000 1.0000
24.4000 1604.0000 1.0000
24.4400 1716.0000 1.0000
24.4800 1690.0000 1.0000
24.5200 1699.0000 1.0000
24.5600 1656.0000 1.0000
24.6000 1657.0000 1.0000
24.6400 1658.0000 1.0000
24.6800 1653.0000 1.0000
24.7200 1743.0000 1.0000
24.7600 1712.0000 1.0000
24.8000 1743.0000 1.0000
24.8400 1745.0000 1.0000
24.8800 1706.0000 1.0000
24.9200 1699.0000 1.0000
24.9600 1728.0000 1.0000
25.0000 1726.0000 1.0000
25.0400 1769.0000 1.0000
25.0800 1783.0000 1.0000
25.1200 1778.0000 1.0000
25.1600 1626.0000 1.0000
25.2000 1754.0000 1.0000
25.2400 1731.0000 1.0000
25.2800 1760.0000 1.0000
25.3200 1718.0000 1.0000
25.3600 1702.0000 1.0000
25.4000 1713.0000 1.0000
25.4400 1681.0000 1.0000
25.4800 1740.0000 1.0000
25.5200 1727.0000 1.0000
25.5600 1632.0000 1.0000
25.6000 1691.0000 1.0000
25.6400 1676.0000 1.0000
25.6800 1759.0000 1.0000
25.7200 1641.0000 1.0000
25.7600 1681.0000 1.0000
25.8000 1700.0000 1.0000
25.8400 1615.0000 1.0000
25.8800 1711.0000 1.0000
25.9200 1730.0000 1.0000
25.9600 1701.0000 1.0000
26.0000 1692.0000 1.0000
26.0400 1723.0000 1.0000
26.0800 1751.0000 1.0000
26.1200 1727.0000 1.0000
26.1600 1699.0000 1.0000
26.2000 1775.0000 1.0000
26.2400 1712.0000 1.0000
26.2800 1700.0000 1.0000
26.3200 1711.0000 1.0000
26.3600 1696.0000 1.0000
26.4000 1743.0000 1.0000
26.4400 1711.0000 1.0000
26.4800 1802.0000 1.0000
26.5200 1736.0000 1.0000
26.5600 1804.0000 1.0000
26.6000 1831.0000 1.0000
26.6400 1800.0000 1.0000
26.6800 1831.0000 1.0000
26.7200 1879.0000 1.0000
26.7600 1890.0000 1.0000
26.8000 1899.0000 1.0000
26.8400 1863.0000 1.0000
26.8800 1972.0000 1.0000
26.9200 1947.0000 1.0000
26.9600 2090.0000 1.0000
27.0000 2215.0000 1.0000
27.0400 2267.0000 1.0000
27.0800 2508.0000 1.0000
27.1200 2754.0000 1.0000
27.1600 3060.0000 1.0000
27.2000 3564.0000 1.0000
27.2400 4211.0000 1.0000
27.2800 5093.0000 1.0000
27.3200 5895.0000 1.0000
27.3600 6395.0000 1.0000
27.4000 5993.0000 1.0000
27.4400 5029.0000 1.0000
27.4800 4179.0000 1.0000
27.5200 3410.0000 1.0000
27.5600 3070.0000 1.0000
27.6000 2659.0000 1.0000
27.6400 2486.0000 1.0000
27.6800 2281.0000 1.0000
27.7200 2181.0000 1.0000
27.7600 2075.0000 1.0000
27.8000 2015.0000 1.0000
27.8400 1868.0000 1.0000
27.8800 1897.0000 1.0000
27.9200 1876.0000 1.0000
27.9600 1819.0000 1.0000
28.0000 1824.0000 1.0000
28.0400 1766.0000 1.0000
28.0800 1786.0000 1.0000
28.1200 1839.0000 1.0000
28.1600 1762.0000 1.0000
28.2000 1696.0000 1.0000
28.2400 1700.0000 1.0000
28.2800 1693.0000 1.0000
28.3200 1693.0000 1.0000
28.3600 1712.0000 1.0000
28.4000 1704.0000 1.0000
28.4400 1701.0000 1.0000
28.4800 1688.0000 1.0000
28.5200 1667.0000 1.0000
28.5600 1725.0000 1.0000
28.6000 1650.0000 1.0000
28.6400 1653.0000 1.0000
28.6800 1593.0000 1.0000
28.7200 1617.0000 1.0000
28.7600 1659.0000 1.0000
28.8000 1677.0000 1.0000
28.8400 1637.0000 1.0000
28.8800 1649.0000 1.0000
28.9200 1599.0000 1.0000
28.9600 1705.0000 1.0000
29.0000 1662.0000 1.0000
29.0400 1653.0000 1.0000
29.0800 1560.0000 1.0000
29.1200 1593.0000 1.0000
29.1600 1648.0000 1.0000
29.2000 1636.0000 1.0000
29.2400 1676.0000 1.0000
29.2800 1560.0000 1.0000
29.3200 1592.0000 1.0000
29.3600 1610.0000 1.0000
29.4000 1574.0000 1.0000
29.4400 1596.0000 1.0000
29.4800 1560.0000 1.0000
29.5200 1639.0000 1.0000
29.5600 1590.0000 1.0000
29.6000 1626.0000 1.0000
29.6400 1530.0000 1.0000
29.6800 1621.0000 1.0000
29.7200 1606.0000 1.0000
29.7600 1582.0000 1.0000
29.8000 1561.0000 1.0000
29.8400 1522.0000 1.0000
29.8800 1582.0000 1.0000
29.9200 1606.0000 1.0000
29.9600 1509.0000 1.0000
30.0000 1606.0000 1.0000
30.0400 1570.0000 1.0000
30.0800 1554.0000 1.0000
30.1200 1580.0000 1.0000
30.1600 1527.0000 1.0000
30.2000 1564.0000 1.0000
30.2400 1560.0000 1.0000
30.2800 1522.0000 1.0000
30.3200 1534.0000 1.0000
30.3600 1513.0000 1.0000
30.4000 1570.0000 1.0000
30.4400 1586.0000 1.0000
30.4800 1567.0000 1.0000
30.5200 1492.0000 1.0000
30.5600 1487.0000 1.0000
30.6000 1526.0000 1.0000
30.6400 1565.0000 1.0000
30.6800 1510.0000 1.0000
30.7200 1477.0000 1.0000
30.7600 1548.0000 1.0000
30.8000 1532.0000 1.0000
30.8400 1505.0000 1.0000
30.8800 1553.0000 1.0000
30.9200 1511.0000 1.0000
30.9600 1519.0000 1.0000
31.0000 1437.0000 1.0000
31.0400 1528.0000 1.0000
31.0800 1455.0000 1.0000
31.1200 1405.0000 1.0000
31.1600 1502.0000 1.0000
31.2000 1420.0000 1.0000
31.2400 1554.0000 1.0000
31.2800 1498.0000 1.0000
31.3200 1515.0000 1.0000
31.3600 1491.0000 1.0000
31.4000 1493.0000 1.0000
31.4400 1382.0000 1.0000
31.4800 1503.0000 1.0000
31.5200 1538.0000 1.0000
31.5600 1470.0000 1.0000
31.6000 1485.0000 1.0000
31.6400 1472.0000 1.0000
31.6800 1460.0000 1.0000
31.7200 1448.0000 1.0000
31.7600 1421.0000 1.0000
31.8000 1423.0000 1.0000
31.8400 1474.0000 1.0000
31.8800 1457.0000 1.0000
31.9200 1428.0000 1.0000
31.9600 1455.0000 1.0000
32.0000 1505.0000 1.0000
32.0400 1505.0000 1.0000
32.0800 1460.0000 1.0000
32.1200 1506.0000 1.0000
32.1600 1496.0000 1.0000
32.2000 1448.0000 1.0000
32.2400 1431.0000 1.0000
32.2800 1433.0000 1.0000
32.3200 1457.0000 1.0000
32.3600 1447.0000 1.0000
32.4000 1434.0000 1.0000
32.4400 1488.0000 1.0000
32.4800 1456.0000 1.0000
32.5200 1424.0000 1.0000
32.5600 1433.0000 1.0000
32.6000 1446.0000 1.0000
32.6400 1374.0000 1.0000
32.6800 1443.0000 1.0000
32.7200 1408.0000 1.0000
32.7600 1404.0000 1.0000
32.8000 1423.0000 1.0000
32.8400 1403.0000 1.0000
32.8800 1362.0000 1.0000
32.9200 1432.0000 1.0000
32.9600 1393.0000 1.0000
33.0000 1450.0000 1.0000
33.0400 1424.0000 1.0000
33.0800 1388.0000 1.0000
33.1200 1443.0000 1.0000
33.1600 1399.0000 1.0000
33.2000 1375.0000 1.0000
33.2400 1403.0000 1.0000
33.2800 1369.0000 1.0000
33.3200 1369.0000 1.0000
33.3600 1361.0000 1.0000
33.4000 1340.0000 1.0000
33.4400 1404.0000 1.0000
33.4800 1428.0000 1.0000
33.5200 1371.0000 1.0000
33.5600 1397.0000 1.0000
33.6000 1517.0000 1.0000
33.6400 1388.0000 1.0000
33.6800 1435.0000 1.0000
33.7200 1404.0000 1.0000
33.7600 1416.0000 1.0000
33.8000 1520.0000 1.0000
33.8400 1496.0000 1.0000
33.8800 1474.0000 1.0000
33.9200 1469.0000 1.0000
33.9600 1505.0000 1.0000
34.0000 1594.0000 1.0000
34.0400 1523.0000 1.0000
34.0800 1525.0000 1.0000
34.1200 1565.0000 1.0000
34.1600 1626.0000 1.0000
34.2000 1546.0000 1.0000
34.2400 1632.0000 1.0000
34.2800 1650.0000 1.0000
34.3200 1728.0000 1.0000
34.3600 1887.0000 1.0000
34.4000 2000.0000 1.0000
34.4400 2297.0000 1.0000
34.4800 2537.0000 1.0000
34.5200 2838.0000 1.0000
34.5600 2921.0000 1.0000
34.6000 2771.0000 1.0000
34.6400 2542.0000 1.0000
34.6800 2240.0000 1.0000
34.7200 2000.0000 1.0000
34.7600 1850.0000 1.0000
34.8000 1655.0000 1.0000
34.8400 1680.0000 1.0000
34.8800 1527.0000 1.0000
34.9200 1460.0000 1.0000
34.9600 1437.0000 1.0000
35.0000 1374.0000 1.0000
35.0400 1377.0000 1.0000
35.0800 1443.0000 1.0000
35.1200 1327.0000 1.0000
35.1600 1325.0000 1.0000
35.2000 1332.0000 1.0000
35.2400 1287.0000 1.0000
35.2800 1318.0000 1.0000
35.3200 1343.0000 1.0000
35.3600 1256.0000 1.0000
35.4000 1267.0000 1.0000
35.4400 1289.0000 1.0000
35.4800 1225.0000 1.0000
35.5200 1218.0000 1.0000
35.5600 1211.0000 1.0000
35.6000 1232.0000 1.0000
35.6400 1214.0000 1.0000
35.6800 1236.0000 1.0000
35.7200 1226.0000 1.0000
35.7600 1151.0000 1.0000
35.8000 1247.0000 1.0000
35.8400 1232.0000 1.0000
35.8800 1279.0000 1.0000
35.9200 1264.0000 1.0000
35.9600 1262.0000 1.0000
36.0000 1204.0000 1.0000
36.0400 1269.0000 1.0000
36.0800 1299.0000 1.0000
36.1200 1306.0000 1.0000
36.1600 1350.0000 1.0000
36.2000 1332.0000 1.0000
36.2400 1434.0000 1.0000
36.2800 1573.0000 1.0000
36.3200 1616.0000 1.0000
36.3600 1745.0000 1.0000
36.4000 1920.0000 1.0000
36.4400 2042.0000 1.0000
36.4800 2065.0000 1.0000
36.5200 1910.0000 1.0000
36.5600 1865.0000 1.0000
36.6000 1750.0000 1.0000
36.6400 1578.0000 1.0000
36.6800 1546.0000 1.0000
36.7200 1401.0000 1.0000
36.7600 1319.0000 1.0000
36.8000 1291.0000 1.0000
36.8400 1188.0000 1.0000
36.8800 1215.0000 1.0000
36.9200 1209.0000 1.0000
36.9600 1154.0000 1.0000
37.0000 1157.0000 1.0000
37.0400 1145.0000 1.0000
37.0800 1123.0000 1.0000
37.1200 1135.0000 1.0000
37.1600 1090.0000 1.0000
37.2000 1152.0000 1.0000
37.2400 1092.0000 1.0000
37.2800 1152.0000 1.0000
37.3200 1127.0000 1.0000
37.3600 1125.0000 1.0000
37.4000 1094.0000 1.0000
37.4400 1128.0000 1.0000
37.4800 1119.0000 1.0000
37.5200 1096.0000 1.0000
37.5600 1125.0000 1.0000
37.6000 1116.0000 1.0000
37.6400 1157.0000 1.0000
37.6800 1174.0000 1.0000
37.7200 1152.0000 1.0000
37.7600 1086.0000 1.0000
37.8000 1113.0000 1.0000
37.8400 1134.0000 1.0000
37.8800 1108.0000 1.0000
37.9200 1127.0000 1.0000
37.9600 1197.0000 1.0000
38.0000 1173.0000 1.0000
38.0400 1197.0000 1.0000
38.0800 1244.0000 1.0000
38.1200 1297.0000 1.0000
38.1600 1332.0000 1.0000
38.2000 1377.0000 1.0000
38.2400 1517.0000 1.0000
38.2800 1687.0000 1.0000
38.3200 1972.0000 1.0000
38.3600 2224.0000 1.0000
38.4000 2658.0000 1.0000
38.4400 3507.0000 1.0000
38.4800 4472.0000 1.0000
38.5200 5748.0000 1.0000
38.5600 6779.0000 1.0000
38.6000 7278.0000 1.0000
38.6400 6983.0000 1.0000
38.6800 6007.0000 1.0000
38.7200 4836.0000 1.0000
38.7600 3694.0000 1.0000
38.8000 2973.0000 1.0000
38.8400 2339.0000 1.0000
38.8800 1922.0000 1.0000
38.9200 1638.0000 1.0000
38.9600 1495.0000 1.0000
39.0000 1331.0000 1.0000
39.0400 1351.0000 1.0000
39.0800 1155.0000 1.0000
39.1200 1178.0000 1.0000
39.1600 1143.0000 1.0000
39.2000 1058.0000 1.0000
39.2400 1070.0000 1.0000
39.2800 1040.0000 1.0000
39.3200 1010.0000 1.0000
39.3600 1060.0000 1.0000
39.4000 1018.0000 1.0000
39.4400 1036.0000 1.0000
39.4800 1066.0000 1.0000
39.5200 1041.0000 1.0000
39.5600 1052.0000 1.0000
39.6000 1110.0000 1.0000
39.6400 1053.0000 1.0000
39.6800 1018.0000 1.0000
39.7200 1047.0000 1.0000
39.7600 1001.0000 1.0000
39.8000 1004.0000 1.0000
39.8400 950.0000 1.0000
39.8800 949.0000 1.0000
39.9200 1002.0000 1.0000
39.9600 1049.0000 1.0000
40.0000 990.0000 1.0000
40.0400 957.0000 1.0000
40.0800 981.0000 1.0000
40.1200 995.0000 1.0000
40.1600 963.0000 1.0000
40.2000 934.0000 1.0000
40.2400 882.0000 1.0000
40.2800 928.0000 1.0000
40.3200 904.0000 1.0000
40.3600 948.0000 1.0000
40.4000 947.0000 1.0000
40.4400 953.0000 1.0000
40.4800 954.0000 1.0000
40.5200 934.0000 1.0000
40.5600 953.0000 1.0000
40.6000 918.0000 1.0000
40.6400 934.0000 1.0000
40.6800 901.0000 1.0000
40.7200 917.0000 1.0000
40.7600 914.0000 1.0000
40.8000 933.0000 1.0000
40.8400 921.0000 1.0000
40.8800 953.0000 1.0000
40.9200 969.0000 1.0000
40.9600 935.0000 1.0000
41.0000 906.0000 1.0000
41.0400 929.0000 1.0000
41.0800 941.0000 1.0000
41.1200 890.0000 1.0000
41.1600 869.0000 1.0000
41.2000 908.0000 1.0000
41.2400 898.0000 1.0000
41.2800 961.0000 1.0000
41.3200 932.0000 1.0000
41.3600 977.0000 1.0000
41.4000 936.0000 1.0000
41.4400 914.0000 1.0000
41.4800 924.0000 1.0000
41.5200 924.0000 1.0000
41.5600 853.0000 1.0000
41.6000 909.0000 1.0000
41.6400 889.0000 1.0000
41.6800 930.0000 1.0000
41.7200 930.0000 1.0000
41.7600 919.0000 1.0000
41.8000 959.0000 1.0000
41.8400 908.0000 1.0000
41.8800 954.0000 1.0000
41.9200 862.0000 1.0000
41.9600 942.0000 1.0000
42.0000 918.0000 1.0000
42.0400 921.0000 1.0000
42.0800 897.0000 1.0000
42.1200 920.0000 1.0000
42.1600 942.0000 1.0000
42.2000 871.0000 1.0000
42.2400 926.0000 1.0000
42.2800 875.0000 1.0000
42.3200 930.0000 1.0000
42.3600 902.0000 1.0000
42.4000 901.0000 1.0000
42.4400 892.0000 1.0000
42.4800 847.0000 1.0000
42.5200 927.0000 1.0000
42.5600 933.0000 1.0000
42.6000 939.0000 1.0000
42.6400 865.0000 1.0000
42.6800 912.0000 1.0000
42.7200 973.0000 1.0000
42.7600 916.0000 1.0000
42.8000 872.0000 1.0000
42.8400 907.0000 1.0000
42.8800 911.0000 1.0000
42.9200 886.0000 1.0000
42.9600 948.0000 1.0000
43.0000 918.0000 1.0000
43.0400 907.0000 1.0000
43.0800 947.0000 1.0000
43.1200 887.0000 1.0000
43.1600 975.0000 1.0000
43.2000 977.0000 1.0000
43.2400 993.0000 1.0000
43.2800 1002.0000 1.0000
43.3200 1002.0000 1.0000
43.3600 945.0000 1.0000
43.4000 964.0000 1.0000
43.4400 976.0000 1.0000
43.4800 950.0000 1.0000
43.5200 959.0000 1.0000
43.5600 858.0000 1.0000
43.6000 903.0000 1.0000
43.6400 914.0000 1.0000
43.6800 881.0000 1.0000
43.7200 927.0000 1.0000
43.7600 872.0000 1.0000
43.8000 929.0000 1.0000
43.8400 897.0000 1.0000
43.8800 896.0000 1.0000
43.9200 904.0000 1.0000
43.9600 885.0000 1.0000
44.0000 886.0000 1.0000
44.0400 863.0000 1.0000
44.0800 845.0000 1.0000
44.1200 877.0000 1.0000
44.1600 906.0000 1.0000
44.2000 935.0000 1.0000
44.2400 864.0000 1.0000
44.2800 898.0000 1.0000
44.3200 853.0000 1.0000
44.3600 881.0000 1.0000
44.4000 856.0000 1.0000
44.4400 884.0000 1.0000
44.4800 893.0000 1.0000
44.5200 905.0000 1.0000
44.5600 859.0000 1.0000
44.6000 884.0000 1.0000
44.6400 868.0000 1.0000
44.6800 887.0000 1.0000
44.7200 859.0000 1.0000
44.7600 893.0000 1.0000
44.8000 888.0000 1.0000
44.8400 879.0000 1.0000
44.8800 828.0000 1.0000
44.9200 896.0000 1.0000
44.9600 880.0000 1.0000
45.0000 878.0000 1.0000
45.0400 906.0000 1.0000
45.0800 859.0000 1.0000
45.1200 824.0000 1.0000
45.1600 854.0000 1.0000
45.2000 835.0000 1.0000
45.2400 840.0000 1.0000
45.2800 854.0000 1.0000
45.3200 785.0000 1.0000
45.3600 837.0000 1.0000
45.4000 886.0000 1.0000
45.4400 901.0000 1.0000
45.4800 847.0000 1.0000
45.5200 810.0000 1.0000
45.5600 825.0000 1.0000
45.6000 854.0000 1.0000
45.6400 833.0000 1.0000
45.6800 821.0000 1.0000
45.7200 872.0000 1.0000
45.7600 873.0000 1.0000
45.8000 856.0000 1.0000
45.8400 874.0000 1.0000
45.8800 899.0000 1.0000
45.9200 849.0000 1.0000
45.9600 882.0000 1.0000
46.0000 836.0000 1.0000
46.0400 836.0000 1.0000
46.0800 847.0000 1.0000
46.1200 799.0000 1.0000
46.1600 840.0000 1.0000
46.2000 855.0000 1.0000
46.2400 891.0000 1.0000
46.2800 841.0000 1.0000
46.3200 823.0000 1.0000
46.3600 858.0000 1.0000
46.4000 856.0000 1.0000
46.4400 822.0000 1.0000
46.4800 849.0000 1.0000
46.5200 831.0000 1.0000
46.5600 891.0000 1.0000
46.6000 861.0000 1.0000
46.6400 796.0000 1.0000
46.6800 860.0000 1.0000
46.7200 830.0000 1.0000
46.7600 804.0000 1.0000
46.8000 797.0000 1.0000
46.8400 849.0000 1.0000
46.8800 843.0000 1.0000
46.9200 832.0000 1.0000
46.9600 875.0000 1.0000
47.0000 806.0000 1.0000
47.0400 805.0000 1.0000
47.0800 838.0000 1.0000
47.1200 861.0000 1.0000
47.1600 832.0000 1.0000
47.2000 808.0000 1.0000
47.2400 821.0000 1.0000
47.2800 787.0000 1.0000
47.3200 785.0000 1.0000
47.3600 828.0000 1.0000
47.4000 804.0000 1.0000
47.4400 836.0000 1.0000
47.4800 798.0000 1.0000
47.5200 816.0000 1.0000
47.5600 819.0000 1.0000
47.6000 808.0000 1.0000
47.6400 813.0000 1.0000
47.6800 821.0000 1.0000
47.7200 815.0000 1.0000
47.7600 812.0000 1.0000
47.8000 791.0000 1.0000
47.8400 786.0000 1.0000
47.8800 786.0000 1.0000
47.9200 842.0000 1.0000
47.9600 775.0000 1.0000
48.0000 776.0000 1.0000
48.0400 814.0000 1.0000
48.0800 809.0000 1.0000
48.1200 743.0000 1.0000
48.1600 731.0000 1.0000
48.2000 831.0000 1.0000
48.2400 779.0000 1.0000
48.2800 765.0000 1.0000
48.3200 853.0000 1.0000
48.3600 793.0000 1.0000
48.4000 730.0000 1.0000
48.4400 794.0000 1.0000
48.4800 760.0000 1.0000
48.5200 773.0000 1.0000
48.5600 775.0000 1.0000
48.6000 791.0000 1.0000
48.6400 812.0000 1.0000
48.6800 816.0000 1.0000
48.7200 766.0000 1.0000
48.7600 831.0000 1.0000
48.8000 740.0000 1.0000
48.8400 768.0000 1.0000
48.8800 769.0000 1.0000
48.9200 826.0000 1.0000
48.9600 797.0000 1.0000
49.0000 755.0000 1.0000
49.0400 744.0000 1.0000
49.0800 780.0000 1.0000
49.1200 792.0000 1.0000
49.1600 773.0000 1.0000
49.2000 769.0000 1.0000
49.2400 796.0000 1.0000
49.2800 780.0000 1.0000
49.3200 789.0000 1.0000
49.3600 809.0000 1.0000
49.4000 784.0000 1.0000
49.4400 773.0000 1.0000
49.4800 803.0000 1.0000
49.5200 786.0000 1.0000
49.5600 827.0000 1.0000
49.6000 788.0000 1.0000
49.6400 783.0000 1.0000
49.6800 768.0000 1.0000
49.7200 764.0000 1.0000
49.7600 733.0000 1.0000
49.8000 808.0000 1.0000
49.8400 803.0000 1.0000
49.8800 721.0000 1.0000
49.9200 818.0000 1.0000
49.9600 810.0000 1.0000
50.0000 779.0000 1.0000
50.0400 787.0000 1.0000
50.0800 778.0000 1.0000
50.1200 767.0000 1.0000
50.1600 780.0000 1.0000
50.2000 801.0000 1.0000
50.2400 792.0000 1.0000
50.2800 785.0000 1.0000
50.3200 791.0000 1.0000
50.3600 816.0000 1.0000
50.4000 817.0000 1.0000
50.4400 825.0000 1.0000
50.4800 765.0000 1.0000
50.5200 771.0000 1.0000
50.5600 790.0000 1.0000
50.6000 764.0000 1.0000
50.6400 733.0000 1.0000
50.6800 811.0000 1.0000
50.7200 785.0000 1.0000
50.7600 768.0000 1.0000
50.8000 769.0000 1.0000
50.8400 847.0000 1.0000
50.8800 770.0000 1.0000
50.9200 816.0000 1.0000
50.9600 789.0000 1.0000
51.0000 763.0000 1.0000
51.0400 805.0000 1.0000
51.0800 807.0000 1.0000
51.1200 762.0000 1.0000
51.1600 764.0000 1.0000
51.2000 775.0000 1.0000
51.2400 823.0000 1.0000
51.2800 759.0000 1.0000
51.3200 759.0000 1.0000
51.3600 764.0000 1.0000
51.4000 778.0000 1.0000
51.4400 816.0000 1.0000
51.4800 826.0000 1.0000
51.5200 757.0000 1.0000
51.5600 774.0000 1.0000
51.6000 815.0000 1.0000
51.6400 813.0000 1.0000
51.6800 796.0000 1.0000
51.7200 836.0000 1.0000
51.7600 790.0000 1.0000
51.8000 791.0000 1.0000
51.8400 902.0000 1.0000
51.8800 897.0000 1.0000
51.9200 907.0000 1.0000
51.9600 979.0000 1.0000
52.0000 1108.0000 1.0000
52.0400 1131.0000 1.0000
52.0800 1354.0000 1.0000
52.1200 1541.0000 1.0000
52.1600 1836.0000 1.0000
52.2000 2383.0000 1.0000
52.2400 3202.0000 1.0000
52.2800 4197.0000 1.0000
52.3200 4869.0000 1.0000
52.3600 4637.0000 1.0000
52.4000 4126.0000 1.0000
52.4400 3771.0000 1.0000
52.4800 3232.0000 1.0000
52.5200 2516.0000 1.0000
52.5600 1974.0000 1.0000
52.6000 1541.0000 1.0000
52.6400 1387.0000 1.0000
52.6800 1140.0000 1.0000
52.7200 1122.0000 1.0000
52.7600 1049.0000 1.0000
52.8000 1008.0000 1.0000
52.8400 895.0000 1.0000
52.8800 924.0000 1.0000
52.9200 922.0000 1.0000
52.9600 836.0000 1.0000
53.0000 838.0000 1.0000
53.0400 866.0000 1.0000
53.0800 823.0000 1.0000
53.1200 786.0000 1.0000
53.1600 781.0000 1.0000
53.2000 758.0000 1.0000
53.2400 833.0000 1.0000
53.2800 789.0000 1.0000
53.3200 810.0000 1.0000
53.3600 752.0000 1.0000
53.4000 761.0000 1.0000
53.4400 768.0000 1.0000
53.4800 727.0000 1.0000
53.5200 743.0000 1.0000
53.5600 746.0000 1.0000
53.6000 738.0000 1.0000
53.6400 769.0000 1.0000
53.6800 756.0000 1.0000
53.7200 735.0000 1.0000
53.7600 752.0000 1.0000
53.8000 740.0000 1.0000
53.8400 759.0000 1.0000
53.8800 741.0000 1.0000
53.9200 815.0000 1.0000
53.9600 711.0000 1.0000
54.0000 768.0000 1.0000
54.0400 820.0000 1.0000
54.0800 756.0000 1.0000
54.1200 766.0000 1.0000
54.1600 806.0000 1.0000
54.2000 767.0000 1.0000
54.2400 739.0000 1.0000
54.2800 785.0000 1.0000
54.3200 796.0000 1.0000
54.3600 748.0000 1.0000
54.4000 743.0000 1.0000
54.4400 797.0000 1.0000
54.4800 751.0000 1.0000
54.5200 790.0000 1.0000
54.5600 759.0000 1.0000
54.6000 782.0000 1.0000
54.6400 812.0000 1.0000
54.6800 784.0000 1.0000
54.7200 781.0000 1.0000
54.7600 802.0000 1.0000
54.8000 768.0000 1.0000
54.8400 775.0000 1.0000
54.8800 831.0000 1.0000
54.9200 821.0000 1.0000
54.9600 828.0000 1.0000
55.0000 852.0000 1.0000
55.0400 806.0000 1.0000
55.0800 795.0000 1.0000
55.1200 850.0000 1.0000
55.1600 895.0000 1.0000
55.2000 965.0000 1.0000
55.2400 1013.0000 1.0000
55.2800 1048.0000 1.0000
55.3200 1125.0000 1.0000
55.3600 1135.0000 1.0000
55.4000 1152.0000 1.0000
55.4400 1069.0000 1.0000
55.4800 1031.0000 1.0000
55.5200 988.0000 1.0000
55.5600 993.0000 1.0000
55.6000 885.0000 1.0000
55.6400 879.0000 1.0000
55.6800 846.0000 1.0000
55.7200 812.0000 1.0000
55.7600 798.0000 1.0000
55.8000 774.0000 1.0000
55.8400 796.0000 1.0000
55.8800 765.0000 1.0000
55.9200 767.0000 1.0000
55.9600 771.0000 1.0000
56.0000 741.0000 1.0000
56.0400 753.0000 1.0000
56.0800 775.0000 1.0000
56.1200 766.0000 1.0000
56.1600 706.0000 1.0000
56.2000 749.0000 1.0000
56.2400 744.0000 1.0000
56.2800 707.0000 1.0000
56.3200 746.0000 1.0000
56.3600 774.0000 1.0000
56.4000 756.0000 1.0000
56.4400 719.0000 1.0000
56.4800 766.0000 1.0000
56.5200 710.0000 1.0000
56.5600 765.0000 1.0000
56.6000 741.0000 1.0000
56.6400 691.0000 1.0000
56.6800 729.0000 1.0000
56.7200 723.0000 1.0000
56.7600 744.0000 1.0000
56.8000 730.0000 1.0000
56.8400 773.0000 1.0000
56.8800 716.0000 1.0000
56.9200 740.0000 1.0000
56.9600 722.0000 1.0000
57.0000 698.0000 1.0000
57.0400 773.0000 1.0000
57.0800 693.0000 1.0000
57.1200 701.0000 1.0000
57.1600 719.0000 1.0000
57.2000 699.0000 1.0000
57.2400 708.0000 1.0000
57.2800 721.0000 1.0000
57.3200 739.0000 1.0000
57.3600 774.0000 1.0000
57.4000 678.0000 1.0000
57.4400 753.0000 1.0000
57.4800 749.0000 1.0000
57.5200 696.0000 1.0000
57.5600 730.0000 1.0000
57.6000 712.0000 1.0000
57.6400 687.0000 1.0000
57.6800 725.0000 1.0000
57.7200 691.0000 1.0000
57.7600 787.0000 1.0000
57.8000 754.0000 1.0000
57.8400 730.0000 1.0000
57.8800 791.0000 1.0000
57.9200 700.0000 1.0000
57.9600 723.0000 1.0000
58.0000 714.0000 1.0000
58.0400 768.0000 1.0000
58.0800 707.0000 1.0000
58.1200 689.0000 1.0000
58.1600 722.0000 1.0000
58.2000 740.0000 1.0000
58.2400 772.0000 1.0000
58.2800 754.0000 1.0000
58.3200 757.0000 1.0000
58.3600 743.0000 1.0000
58.4000 728.0000 1.0000
58.4400 747.0000 1.0000
58.4800 702.0000 1.0000
58.5200 715.0000 1.0000
58.5600 739.0000 1.0000
58.6000 745.0000 1.0000
58.6400 710.0000 1.0000
58.6800 729.0000 1.0000
58.7200 695.0000 1.0000
58.7600 709.0000 1.0000
58.8000 695.0000 1.0000
58.8400 744.0000 1.0000
58.8800 715.0000 1.0000
58.9200 756.0000 1.0000
58.9600 691.0000 1.0000
59.0000 759.0000 1.0000
59.0400 739.0000 1.0000
59.0800 709.0000 1.0000
59.1200 716.0000 1.0000
59.1600 752.0000 1.0000
59.2000 723.0000 1.0000
59.2400 720.0000 1.0000
59.2800 702.0000 1.0000
59.3200 752.0000 1.0000
59.3600 745.0000 1.0000
59.4000 756.0000 1.0000
59.4400 749.0000 1.0000
59.4800 751.0000 1.0000
59.5200 763.0000 1.0000
59.5600 745.0000 1.0000
59.6000 723.0000 1.0000
59.6400 747.0000 1.0000
59.6800 685.0000 1.0000
59.7200 744.0000 1.0000
59.7600 730.0000 1.0000
59.8000 702.0000 1.0000
59.8400 731.0000 1.0000
59.8800 683.0000 1.0000
59.9200 705.0000 1.0000
59.9600 710.0000 1.0000
60.0000 705.0000 1.0000
60.0400 689.0000 1.0000
60.0800 728.0000 1.0000
60.1200 745.0000 1.0000
60.1600 781.0000 1.0000
60.2000 731.0000 1.0000
60.2400 746.0000 1.0000
60.2800 725.0000 1.0000
60.3200 753.0000 1.0000
60.3600 709.0000 1.0000
60.4000 709.0000 1.0000
60.4400 764.0000 1.0000
60.4800 668.0000 1.0000
60.5200 742.0000 1.0000
60.5600 719.0000 1.0000
60.6000 726.0000 1.0000
60.6400 678.0000 1.0000
60.6800 724.0000 1.0000
60.7200 757.0000 1.0000
60.7600 706.0000 1.0000
60.8000 717.0000 1.0000
60.8400 732.0000 1.0000
60.8800 708.0000 1.0000
60.9200 740.0000 1.0000
60.9600 759.0000 1.0000
61.0000 698.0000 1.0000
61.0400 732.0000 1.0000
61.0800 725.0000 1.0000
61.1200 757.0000 1.0000
61.1600 774.0000 1.0000
61.2000 718.0000 1.0000
61.2400 723.0000 1.0000
61.2800 713.0000 1.0000
61.3200 740.0000 1.0000
61.3600 761.0000 1.0000
61.4000 713.0000 1.0000
61.4400 748.0000 1.0000
61.4800 786.0000 1.0000
61.5200 734.0000 1.0000
61.5600 697.0000 1.0000
61.6000 712.0000 1.0000
61.6400 724.0000 1.0000
61.6800 745.0000 1.0000
61.7200 802.0000 1.0000
61.7600 749.0000 1.0000
61.8000 751.0000 1.0000
61.8400 785.0000 1.0000
61.8800 797.0000 1.0000
61.9200 814.0000 1.0000
61.9600 822.0000 1.0000
62.0000 943.0000 1.0000
62.0400 889.0000 1.0000
62.0800 946.0000 1.0000
62.1200 1105.0000 1.0000
62.1600 1140.0000 1.0000
62.2000 1322.0000 1.0000
62.2400 1406.0000 1.0000
62.2800 1651.0000 1.0000
62.3200 1686.0000 1.0000
62.3600 1788.0000 1.0000
62.4000 1629.0000 1.0000
62.4400 1654.0000 1.0000
62.4800 1648.0000 1.0000
62.5200 1456.0000 1.0000
62.5600 1382.0000 1.0000
62.6000 1223.0000 1.0000
62.6400 1145.0000 1.0000
62.6800 1051.0000 1.0000
62.7200 1016.0000 1.0000
62.7600 984.0000 1.0000
62.8000 958.0000 1.0000
62.8400 849.0000 1.0000
62.8800 865.0000 1.0000
62.9200 820.0000 1.0000
62.9600 789.0000 1.0000
63.0000 820.0000 1.0000
63.0400 785.0000 1.0000
63.0800 763.0000 1.0000
63.1200 847.0000 1.0000
63.1600 833.0000 1.0000
63.2000 738.0000 1.0000
63.2400 762.0000 1.0000
63.2800 759.0000 1.0000
63.3200 781.0000 1.0000
63.3600 760.0000 1.0000
63.4000 777.0000 1.0000
63.4400 727.0000 1.0000
63.4800 744.0000 1.0000
63.5200 764.0000 1.0000
63.5600 736.0000 1.0000
63.6000 701.0000 1.0000
63.6400 704.0000 1.0000
63.6800 753.0000 1.0000
63.7200 709.0000 1.0000
63.7600 710.0000 1.0000
63.8000 719.0000 1.0000
63.8400 726.0000 1.0000
63.8800 743.0000 1.0000
63.9200 792.0000 1.0000
63.9600 765.0000 1.0000
64.0000 728.0000 1.0000
64.0400 768.0000 1.0000
64.0800 751.0000 1.0000
64.1200 742.0000 1.0000
64.1600 746.0000 1.0000
64.2000 717.0000 1.0000
64.2400 771.0000 1.0000
64.2800 802.0000 1.0000
64.3200 767.0000 1.0000
64.3600 758.0000 1.0000
64.4000 762.0000 1.0000
64.4400 788.0000 1.0000
64.4800 845.0000 1.0000
64.5200 784.0000 1.0000
64.5600 874.0000 1.0000
64.6000 948.0000 1.0000
64.6400 866.0000 1.0000
64.6800 952.0000 1.0000
64.7200 993.0000 1.0000
64.7600 1004.0000 1.0000
64.8000 957.0000 1.0000
64.8400 972.0000 1.0000
64.8800 968.0000 1.0000
64.9200 921.0000 1.0000
64.9600 929.0000 1.0000
65.0000 904.0000 1.0000
65.0400 862.0000 1.0000
65.0800 899.0000 1.0000
65.1200 795.0000 1.0000
65.1600 834.0000 1.0000
65.2000 819.0000 1.0000
65.2400 800.0000 1.0000
65.2800 831.0000 1.0000
65.3200 810.0000 1.0000
65.3600 778.0000 1.0000
65.4000 750.0000 1.0000
65.4400 789.0000 1.0000
65.4800 768.0000 1.0000
65.5200 793.0000 1.0000
65.5600 766.0000 1.0000
65.6000 791.0000 1.0000
65.6400 752.0000 1.0000
65.6800 811.0000 1.0000
65.7200 776.0000 1.0000
65.7600 808.0000 1.0000
65.8000 841.0000 1.0000
65.8400 829.0000 1.0000
65.8800 854.0000 1.0000
65.9200 849.0000 1.0000
65.9600 977.0000 1.0000
66.0000 1030.0000 1.0000
66.0400 1066.0000 1.0000
66.0800 1205.0000 1.0000
66.1200 1427.0000 1.0000
66.1600 1635.0000 1.0000
66.2000 1935.0000 1.0000
66.2400 2450.0000 1.0000
66.2800 2668.0000 1.0000
66.3200 2742.0000 1.0000
66.3600 2569.0000 1.0000
66.4000 2425.0000 1.0000
66.4400 2297.0000 1.0000
66.4800 2141.0000 1.0000
66.5200 1900.0000 1.0000
66.5600 1727.0000 1.0000
66.6000 1425.0000 1.0000
66.6400 1278.0000 1.0000
66.6800 1183.0000 1.0000
66.7200 1024.0000 1.0000
66.7600 928.0000 1.0000
66.8000 878.0000 1.0000
66.8400 838.0000 1.0000
66.8800 877.0000 1.0000
66.9200 792.0000 1.0000
66.9600 791.0000 1.0000
67.0000 797.0000 1.0000
67.0400 747.0000 1.0000
67.0800 740.0000 1.0000
67.1200 760.0000 1.0000
67.1600 737.0000 1.0000
67.2000 735.0000 1.0000
67.2400 749.0000 1.0000
67.2800 697.0000 1.0000
67.3200 724.0000 1.0000
67.3600 731.0000 1.0000
67.4000 667.0000 1.0000
67.4400 673.0000 1.0000
67.4800 713.0000 1.0000
67.5200 677.0000 1.0000
67.5600 673.0000 1.0000
67.6000 677.0000 1.0000
67.6400 703.0000 1.0000
67.6800 671.0000 1.0000
67.7200 703.0000 1.0000
67.7600 682.0000 1.0000
67.8000 643.0000 1.0000
67.8400 696.0000 1.0000
67.8800 637.0000 1.0000
67.9200 699.0000 1.0000
67.9600 673.0000 1.0000
68.0000 640.0000 1.0000
68.0400 678.0000 1.0000
68.0800 671.0000 1.0000
68.1200 664.0000 1.0000
68.1600 663.0000 1.0000
68.2000 684.0000 1.0000
68.2400 708.0000 1.0000
68.2800 697.0000 1.0000
68.3200 671.0000 1.0000
68.3600 684.0000 1.0000
68.4000 638.0000 1.0000
68.4400 635.0000 1.0000
68.4800 669.0000 1.0000
68.5200 637.0000 1.0000
68.5600 654.0000 1.0000
68.6000 656.0000 1.0000
68.6400 649.0000 1.0000
68.6800 672.0000 1.0000
68.7200 705.0000 1.0000
68.7600 688.0000 1.0000
68.8000 623.0000 1.0000
68.8400 693.0000 1.0000
68.8800 667.0000 1.0000
68.9200 654.0000 1.0000
68.9600 646.0000 1.0000
69.0000 644.0000 1.0000
69.0400 622.0000 1.0000
69.0800 615.0000 1.0000
69.1200 646.0000 1.0000
69.1600 655.0000 1.0000
69.2000 663.0000 1.0000
69.2400 625.0000 1.0000
69.2800 673.0000 1.0000
69.3200 640.0000 1.0000
69.3600 643.0000 1.0000
69.4000 628.0000 1.0000
69.4400 644.0000 1.0000
69.4800 646.0000 1.0000
69.5200 689.0000 1.0000
69.5600 655.0000 1.0000
69.6000 662.0000 1.0000
69.6400 601.0000 1.0000
69.6800 652.0000 1.0000
69.7200 665.0000 1.0000
69.7600 640.0000 1.0000
69.8000 670.0000 1.0000
69.8400 632.0000 1.0000
69.8800 641.0000 1.0000
69.9200 613.0000 1.0000
69.9600 615.0000 1.0000
70.0000 622.0000 1.0000
*RAS_INT_END
*RAS_TEMPERATURE_START
*RAS_TEMPERATURE_END
*RAS_DATA_END