File: Section2_75_samples/XRD/No_071_VS1_4.ras
*RAS_DATA_START
*RAS_HEADER_START
*DISP_FMT_X "%.2f"
*DISP_FMT_Y "%.0f"
*DISP_FULLSCALE "14312.0000000000"
*DISP_LINE_COLOR "255.0000000000"
*DISP_LINE_STYLE "0.0000000000"
*DISP_LINE_WIDTH "0.2500000000"
*DISP_NOTE "測定データ-6"
*DISP_OFFSET_Y "0.0000000000"
*DISP_PEAKSEARCH_UNIT_Y "cps"
*DISP_RANGE_BOTTOM "0.0000000000"
*DISP_RANGE_LEFT "20.0000000000"
*DISP_RANGE_LOGCUTOFF "0.0100000000"
*DISP_RANGE_RIGHT "70.0000000000"
*DISP_RANGE_TOP "14312.0000000000"
*DISP_SCALE_MODE_Y "0.0000000000"
*DISP_TAB_NAME "2θ/θ"
*DISP_TITLE_Y "強度"
*DISP_UNIT_Y "cps"
*DISP_WINDOW_NAME "MSG_MACROENGINE"
*FILE_COMMENT " "
*FILE_MD5 ""
*FILE_MEMO " "
*FILE_OPERATOR "Administrator"
*FILE_SAMPLE " "
*FILE_TYPE "RAS_RAW"
*FILE_USERGROUP "システムマネージャ"
*FILE_VERSION "1.0000000000"
*HW_ATTACHMENT_ID "ATT0025"
*HW_ATTACHMENT_NAME "標準|Standard"
*HW_COUNTER_ID-0 "CUT0025"
*HW_COUNTER_ID-1 "CUT0020"
*HW_COUNTER_ID-2 "CUT0020"
*HW_COUNTER_ID-3 "CSL0021"
*HW_COUNTER_ID-4 "CMC0021"
*HW_COUNTER_NAME-0 "D/teX Ultra|D/teX Ultra"
*HW_COUNTER_NAME-1 "None|None"
*HW_COUNTER_NAME-2 "None|None"
*HW_COUNTER_NAME-3 "BBM|BBM"
*HW_COUNTER_NAME-4 "検出器モノクロメータ|Detector monochromator"
*HW_COUNTER_SELECT_NAME "D/teX Ultra|D/teX Ultra"
*HW_GONIOMETER_ID "GON0023"
*HW_GONIOMETER_NAME "SmartLab|SmartLab"
*HW_GONIOMETER_RADIUS-0 "90.0"
*HW_GONIOMETER_RADIUS-1 "114.0"
*HW_GONIOMETER_RADIUS-2 "190.0"
*HW_GONIOMETER_RADIUS-3 "300.0"
*HW_GONIOMETER_RADIUS-4 "187.0"
*HW_GONIOMETER_RADIUS-5 "300.0"
*HW_GONIOMETER_RADIUS-6 "113.0"
*HW_GONIOMETER_RADIUS-7 "331.0"
*HW_I_OPT_ID-0 "CBO0021"
*HW_I_OPT_ID-1 "ICR0023"
*HW_I_OPT_ID-2 "ISL0021"
*HW_I_OPT_ID-3 "ISO0021"
*HW_I_OPT_ID-4 "IAD0021"
*HW_I_OPT_ID-5 "IPR0001"
*HW_I_OPT_NAME-0 "CBOユニット|CBO unit"
*HW_I_OPT_NAME-1 "標準入射光学ユニット|Standard incident optical unit"
*HW_I_OPT_NAME-2 "標準入射スリットボックス|Standard incident slit box"
*HW_I_OPT_NAME-3 "入射平行スリット|Incident parallel slit"
*HW_I_OPT_NAME-4 "長手制限スリット|Length limiting slit"
*HW_I_OPT_NAME-5 "None|None"
*HW_R_ATTENUATER_AUTOMODE "0"
*HW_R_OPT_ID-0 "RSS0021"
*HW_R_OPT_ID-1 "RCR0023"
*HW_R_OPT_ID-2 "RSO0021"
*HW_R_OPT_ID-3 "RRS0021"
*HW_R_OPT_ID-4 "ATN0021"
*HW_R_OPT_ID-5 "RFL0021"
*HW_R_OPT_ID-6 "RAD0021"
*HW_R_OPT_NAME-0 "標準受光スリットボックス1|Standard receiving slit box # 1"
*HW_R_OPT_NAME-1 "標準受光光学ユニット1|Standard receiving unit # 1"
*HW_R_OPT_NAME-2 "標準受光光学ユニット2|Standard receiving optical unit # 2"
*HW_R_OPT_NAME-3 "標準受光スリットボックス2|Standard receiving slit box # 2"
*HW_R_OPT_NAME-4 "標準アッテネータ|Standard Attenuator"
*HW_R_OPT_NAME-5 "Cu Kβ|Cu K-beta"
*HW_R_OPT_NAME-6 "調整用受光スリット|Alignment receiving slit"
*HW_SAMPLE_HOLDER_ID "SMP0023"
*HW_SAMPLE_HOLDER_NAME "標準Zステージ|Standard Z stage"
*HW_XG_CURRENT_MAX "50"
*HW_XG_CURRENT_MIN "2"
*HW_XG_CURRENT_RESOLUTION "1"
*HW_XG_CURRENT_UNIT "mA"
*HW_XG_FOCUS "1mm x 10mm"
*HW_XG_FOCUS_TYPE "Normal"
*HW_XG_ID ""
*HW_XG_NAME "3kW 封入管(ID:1200)|3kW Sealed tube(ID:1200)"
*HW_XG_TARGET_ATOMIC_NUMBER "29.0000000000"
*HW_XG_TARGET_NAME "Cu"
*HW_XG_TYPE "Hermetic"
*HW_XG_VOLTAGE_MAX "60"
*HW_XG_VOLTAGE_MIN "20"
*HW_XG_VOLTAGE_RESOLUTION "1"
*HW_XG_VOLTAGE_UNIT "kV"
*HW_XG_WATT_MAX "1.500"
*HW_XG_WATT_UNIT "kW"
*HW_XG_WAVE_LENGTH_ALPHA1 "1.540593"
*HW_XG_WAVE_LENGTH_ALPHA2 "1.544414"
*HW_XG_WAVE_LENGTH_BETA "1.392250"
*MEAS_COND_AXIS_NAME-0 "2θ/θ"
*MEAS_COND_AXIS_NAME-1 "2θ"
*MEAS_COND_AXIS_NAME-2 "ω"
*MEAS_COND_AXIS_NAME-3 "Z"
*MEAS_COND_AXIS_NAME-4 "2θ/ω"
*MEAS_COND_AXIS_NAME-5 "θs"
*MEAS_COND_AXIS_NAME-6 "θd"
*MEAS_COND_AXIS_NAME-7 "Ts"
*MEAS_COND_AXIS_NAME-8 "CBO選択スリット"
*MEAS_COND_AXIS_NAME-9 "M"
*MEAS_COND_AXIS_NAME-10 "入射平行スリット"
*MEAS_COND_AXIS_NAME-11 "入射スリット"
*MEAS_COND_AXIS_NAME-12 ""
*MEAS_COND_AXIS_NAME-13 "Zs"
*MEAS_COND_AXIS_NAME-14 "入射光学素子"
*MEAS_COND_AXIS_NAME-15 "長手制限スリット"
*MEAS_COND_AXIS_NAME-16 "センタースリット"
*MEAS_COND_AXIS_NAME-17 "フィルター"
*MEAS_COND_AXIS_NAME-18 "受光スリット1"
*MEAS_COND_AXIS_NAME-19 "受光スリット2"
*MEAS_COND_AXIS_NAME-20 "受光光学素子"
*MEAS_COND_AXIS_NAME-21 "受光平行スリット"
*MEAS_COND_AXIS_NAME-22 "調整用受光スリット"
*MEAS_COND_AXIS_NAME-23 ""
*MEAS_COND_AXIS_NAME-24 ""
*MEAS_COND_AXIS_NAME-25 "Zd"
*MEAS_COND_AXIS_NAME-26 "アッテネータ"
*MEAS_COND_AXIS_NAME-27 "検出器モノクロメータ"
*MEAS_COND_AXIS_NAME-28 "モノクロメータスリット"
*MEAS_COND_AXIS_NAME-29 "プライマリビーム"
*MEAS_COND_AXIS_NAME-30 "PHA"
*MEAS_COND_AXIS_NAME_INTERNAL-0 "TwoThetaTheta"
*MEAS_COND_AXIS_NAME_INTERNAL-1 "TwoTheta"
*MEAS_COND_AXIS_NAME_INTERNAL-2 "Omega"
*MEAS_COND_AXIS_NAME_INTERNAL-3 "Z"
*MEAS_COND_AXIS_NAME_INTERNAL-4 "TwoThetaOmega"
*MEAS_COND_AXIS_NAME_INTERNAL-5 "ThetaS"
*MEAS_COND_AXIS_NAME_INTERNAL-6 "ThetaD"
*MEAS_COND_AXIS_NAME_INTERNAL-7 "Ts"
*MEAS_COND_AXIS_NAME_INTERNAL-8 "CBO"
*MEAS_COND_AXIS_NAME_INTERNAL-9 "CBO-M"
*MEAS_COND_AXIS_NAME_INTERNAL-10 "IncidentSollerSlit"
*MEAS_COND_AXIS_NAME_INTERNAL-11 "IncidentSlitBox"
*MEAS_COND_AXIS_NAME_INTERNAL-12 "IncidentSlitBox-_Axis"
*MEAS_COND_AXIS_NAME_INTERNAL-13 "Zs"
*MEAS_COND_AXIS_NAME_INTERNAL-14 "IncidentMonochromator"
*MEAS_COND_AXIS_NAME_INTERNAL-15 "IncidentAxdSlit"
*MEAS_COND_AXIS_NAME_INTERNAL-16 "CenterSlit"
*MEAS_COND_AXIS_NAME_INTERNAL-17 "Filter"
*MEAS_COND_AXIS_NAME_INTERNAL-18 "ReceivingSlitBox1"
*MEAS_COND_AXIS_NAME_INTERNAL-19 "ReceivingSlitBox2"
*MEAS_COND_AXIS_NAME_INTERNAL-20 "ReceivingOptics"
*MEAS_COND_AXIS_NAME_INTERNAL-21 "ReceivingSollerSlit"
*MEAS_COND_AXIS_NAME_INTERNAL-22 "ReceivingAxdSlit"
*MEAS_COND_AXIS_NAME_INTERNAL-23 "ReceivingSlitBox1-_Axis"
*MEAS_COND_AXIS_NAME_INTERNAL-24 "ReceivingSlitBox2-_Axis"
*MEAS_COND_AXIS_NAME_INTERNAL-25 "ReceivingSlitBox2-Zd"
*MEAS_COND_AXIS_NAME_INTERNAL-26 "Attenuator"
*MEAS_COND_AXIS_NAME_INTERNAL-27 "CounterMonochromator"
*MEAS_COND_AXIS_NAME_INTERNAL-28 "CounterSlit"
*MEAS_COND_AXIS_NAME_INTERNAL-29 "IncidentPrimary"
*MEAS_COND_AXIS_NAME_INTERNAL-30 "PHA"
*MEAS_COND_AXIS_NAME_MAGICNO-0 "83951616.0000000000"
*MEAS_COND_AXIS_NAME_MAGICNO-1 "268632064.0000000000"
*MEAS_COND_AXIS_NAME_MAGICNO-2 "268500992.0000000000"
*MEAS_COND_AXIS_NAME_MAGICNO-3 "285278208.0000000000"
*MEAS_COND_AXIS_NAME_MAGICNO-4 "83951616.0000000000"
*MEAS_COND_AXIS_NAME_MAGICNO-5 "131072.0000000000"
*MEAS_COND_AXIS_NAME_MAGICNO-6 "131072.0000000000"
*MEAS_COND_AXIS_NAME_MAGICNO-7 "318898176.0000000000"
*MEAS_COND_AXIS_NAME_MAGICNO-8 "20971521.0000000000"
*MEAS_COND_AXIS_NAME_MAGICNO-9 "285343744.0000000000"
*MEAS_COND_AXIS_NAME_MAGICNO-10 "20971521.0000000000"
*MEAS_COND_AXIS_NAME_MAGICNO-11 "22020097.0000000000"
*MEAS_COND_AXIS_NAME_MAGICNO-12 "25165824.0000000000"
*MEAS_COND_AXIS_NAME_MAGICNO-13 "318898176.0000000000"
*MEAS_COND_AXIS_NAME_MAGICNO-14 "1.0000000000"
*MEAS_COND_AXIS_NAME_MAGICNO-15 "20971521.0000000000"
*MEAS_COND_AXIS_NAME_MAGICNO-16 "20971521.0000000000"
*MEAS_COND_AXIS_NAME_MAGICNO-17 "20971521.0000000000"
*MEAS_COND_AXIS_NAME_MAGICNO-18 "23068673.0000000000"
*MEAS_COND_AXIS_NAME_MAGICNO-19 "23068673.0000000000"
*MEAS_COND_AXIS_NAME_MAGICNO-20 "20971521.0000000000"
*MEAS_COND_AXIS_NAME_MAGICNO-21 "20971521.0000000000"
*MEAS_COND_AXIS_NAME_MAGICNO-22 "20971521.0000000000"
*MEAS_COND_AXIS_NAME_MAGICNO-23 "25165824.0000000000"
*MEAS_COND_AXIS_NAME_MAGICNO-24 "25165824.0000000000"
*MEAS_COND_AXIS_NAME_MAGICNO-25 "285343744.0000000000"
*MEAS_COND_AXIS_NAME_MAGICNO-26 "17301505.0000000000"
*MEAS_COND_AXIS_NAME_MAGICNO-27 "20971521.0000000000"
*MEAS_COND_AXIS_NAME_MAGICNO-28 "20971521.0000000000"
*MEAS_COND_AXIS_NAME_MAGICNO-29 "20971521.0000000000"
*MEAS_COND_AXIS_NAME_MAGICNO-30 "0.0000000000"
*MEAS_COND_AXIS_OFFSET-0 "-"
*MEAS_COND_AXIS_OFFSET-1 "-0.1081000000"
*MEAS_COND_AXIS_OFFSET-2 "0.3758000000"
*MEAS_COND_AXIS_OFFSET-3 "-"
*MEAS_COND_AXIS_OFFSET-4 "-"
*MEAS_COND_AXIS_OFFSET-5 "0.3758000000"
*MEAS_COND_AXIS_OFFSET-6 "-0.4839000000"
*MEAS_COND_AXIS_OFFSET-7 "-"
*MEAS_COND_AXIS_OFFSET-8 "-"
*MEAS_COND_AXIS_OFFSET-9 "-"
*MEAS_COND_AXIS_OFFSET-10 "-"
*MEAS_COND_AXIS_OFFSET-11 "-"
*MEAS_COND_AXIS_OFFSET-12 "-"
*MEAS_COND_AXIS_OFFSET-13 "-"
*MEAS_COND_AXIS_OFFSET-14 "-"
*MEAS_COND_AXIS_OFFSET-15 "-"
*MEAS_COND_AXIS_OFFSET-16 "-"
*MEAS_COND_AXIS_OFFSET-17 "-"
*MEAS_COND_AXIS_OFFSET-18 "-"
*MEAS_COND_AXIS_OFFSET-19 "-"
*MEAS_COND_AXIS_OFFSET-20 "-"
*MEAS_COND_AXIS_OFFSET-21 "-"
*MEAS_COND_AXIS_OFFSET-22 "-"
*MEAS_COND_AXIS_OFFSET-23 "-"
*MEAS_COND_AXIS_OFFSET-24 "-"
*MEAS_COND_AXIS_OFFSET-25 "-"
*MEAS_COND_AXIS_OFFSET-26 "-"
*MEAS_COND_AXIS_OFFSET-27 "-"
*MEAS_COND_AXIS_OFFSET-28 "-"
*MEAS_COND_AXIS_OFFSET-29 "-"
*MEAS_COND_AXIS_OFFSET-30 "-"
*MEAS_COND_AXIS_POSITION-0 "0.0000000000"
*MEAS_COND_AXIS_POSITION-1 "0.0000000000"
*MEAS_COND_AXIS_POSITION-2 "0.0000000000"
*MEAS_COND_AXIS_POSITION-3 "-0.5500000000"
*MEAS_COND_AXIS_POSITION-4 "0.0000000000"
*MEAS_COND_AXIS_POSITION-5 "0.0000000000"
*MEAS_COND_AXIS_POSITION-6 "0.0000000000"
*MEAS_COND_AXIS_POSITION-7 "-0.4278800000"
*MEAS_COND_AXIS_POSITION-8 "BB"
*MEAS_COND_AXIS_POSITION-9 "0.0000000000"
*MEAS_COND_AXIS_POSITION-10 "Soller_slit_5.0deg"
*MEAS_COND_AXIS_POSITION-11 "2/3deg"
*MEAS_COND_AXIS_POSITION-12 "2.2088000000"
*MEAS_COND_AXIS_POSITION-13 "-0.4140600000"
*MEAS_COND_AXIS_POSITION-14 "0.0000000000"
*MEAS_COND_AXIS_POSITION-15 "10.0mm"
*MEAS_COND_AXIS_POSITION-16 "None"
*MEAS_COND_AXIS_POSITION-17 "Cu_K-beta"
*MEAS_COND_AXIS_POSITION-18 "10.036mm"
*MEAS_COND_AXIS_POSITION-19 "13.000mm"
*MEAS_COND_AXIS_POSITION-20 "No_unit"
*MEAS_COND_AXIS_POSITION-21 "Soller_slit_5.0deg"
*MEAS_COND_AXIS_POSITION-22 "None"
*MEAS_COND_AXIS_POSITION-23 "10.0363000000"
*MEAS_COND_AXIS_POSITION-24 "13.0000000000"
*MEAS_COND_AXIS_POSITION-25 "0.0109400000"
*MEAS_COND_AXIS_POSITION-26 "Open"
*MEAS_COND_AXIS_POSITION-27 "None"
*MEAS_COND_AXIS_POSITION-28 "None"
*MEAS_COND_AXIS_POSITION-29 "None"
*MEAS_COND_AXIS_POSITION-30 "38.0000000000"
*MEAS_COND_AXIS_UNIT-0 "deg"
*MEAS_COND_AXIS_UNIT-1 "deg"
*MEAS_COND_AXIS_UNIT-2 "deg"
*MEAS_COND_AXIS_UNIT-3 "mm"
*MEAS_COND_AXIS_UNIT-4 "deg"
*MEAS_COND_AXIS_UNIT-5 "deg"
*MEAS_COND_AXIS_UNIT-6 "deg"
*MEAS_COND_AXIS_UNIT-7 "mm"
*MEAS_COND_AXIS_UNIT-8 ""
*MEAS_COND_AXIS_UNIT-9 "pulse"
*MEAS_COND_AXIS_UNIT-10 ""
*MEAS_COND_AXIS_UNIT-11 ""
*MEAS_COND_AXIS_UNIT-12 "mm"
*MEAS_COND_AXIS_UNIT-13 "mm"
*MEAS_COND_AXIS_UNIT-14 ""
*MEAS_COND_AXIS_UNIT-15 ""
*MEAS_COND_AXIS_UNIT-16 ""
*MEAS_COND_AXIS_UNIT-17 ""
*MEAS_COND_AXIS_UNIT-18 ""
*MEAS_COND_AXIS_UNIT-19 ""
*MEAS_COND_AXIS_UNIT-20 ""
*MEAS_COND_AXIS_UNIT-21 ""
*MEAS_COND_AXIS_UNIT-22 ""
*MEAS_COND_AXIS_UNIT-23 "mm"
*MEAS_COND_AXIS_UNIT-24 "mm"
*MEAS_COND_AXIS_UNIT-25 "mm"
*MEAS_COND_AXIS_UNIT-26 ""
*MEAS_COND_AXIS_UNIT-27 ""
*MEAS_COND_AXIS_UNIT-28 ""
*MEAS_COND_AXIS_UNIT-29 ""
*MEAS_COND_AXIS_UNIT-30 "div"
*MEAS_COND_COUNTER_CNTLOSS_CORR "0.0000000000"
*MEAS_COND_COUNTER_PHABASE "38.0000000000"
*MEAS_COND_COUNTER_PHAWINDOW "16.0000000000"
*MEAS_COND_COUNTER_PHA_UNIT "div"
*MEAS_COND_COUNTER_TAUDIFF "30.0000000000"
*MEAS_COND_COUNTER_TAUINT "0.0000000000"
*MEAS_COND_IRRADIATION_MODE "OFF"
*MEAS_COND_IRRADIATION_WIDTH ""
*MEAS_COND_OPT_ATTR "集中法"
*MEAS_COND_OPT_NAME "@集中法"
*MEAS_COND_UNSYMMETRIC_MODE "OFF"
*MEAS_COND_XG_CURRENT "30.0000000000"
*MEAS_COND_XG_VOLTAGE "40.0000000000"
*MEAS_COND_XG_WAVE_TYPE "Ka"
*MEAS_DATA_COUNT "5001.0000000000"
*MEAS_SCAN_AXIS_X "2θ/θ"
*MEAS_SCAN_AXIS_X_INTERNAL "TwoThetaTheta"
*MEAS_SCAN_END_TIME "07/15/21 17:50:14"
*MEAS_SCAN_MODE "CONTINUOUS"
*MEAS_SCAN_MONITOR "0"
*MEAS_SCAN_RESOLUTION_X "0.0002"
*MEAS_SCAN_SPEED "1.0"
*MEAS_SCAN_SPEED_UNIT "deg/min"
*MEAS_SCAN_START "20.0000000000"
*MEAS_SCAN_START_TIME "07/15/21 16:57:20"
*MEAS_SCAN_STEP "0.0100000000"
*MEAS_SCAN_STOP "70.0000000000"
*MEAS_SCAN_UNIT_X "deg"
*MEAS_SCAN_UNIT_Y "counts"
*RAS_HEADER_END
*RAS_INT_START
20.0000 1189.0000 1.0000
20.0400 1226.0000 1.0000
20.0800 1221.0000 1.0000
20.1200 1258.0000 1.0000
20.1600 1236.0000 1.0000
20.2000 1253.0000 1.0000
20.2400 1235.0000 1.0000
20.2800 1248.0000 1.0000
20.3200 1269.0000 1.0000
20.3600 1223.0000 1.0000
20.4000 1223.0000 1.0000
20.4400 1212.0000 1.0000
20.4800 1200.0000 1.0000
20.5200 1260.0000 1.0000
20.5600 1171.0000 1.0000
20.6000 1245.0000 1.0000
20.6400 1249.0000 1.0000
20.6800 1223.0000 1.0000
20.7200 1251.0000 1.0000
20.7600 1265.0000 1.0000
20.8000 1205.0000 1.0000
20.8400 1184.0000 1.0000
20.8800 1270.0000 1.0000
20.9200 1267.0000 1.0000
20.9600 1197.0000 1.0000
21.0000 1227.0000 1.0000
21.0400 1221.0000 1.0000
21.0800 1211.0000 1.0000
21.1200 1220.0000 1.0000
21.1600 1205.0000 1.0000
21.2000 1247.0000 1.0000
21.2400 1251.0000 1.0000
21.2800 1253.0000 1.0000
21.3200 1238.0000 1.0000
21.3600 1286.0000 1.0000
21.4000 1279.0000 1.0000
21.4400 1237.0000 1.0000
21.4800 1236.0000 1.0000
21.5200 1255.0000 1.0000
21.5600 1251.0000 1.0000
21.6000 1206.0000 1.0000
21.6400 1289.0000 1.0000
21.6800 1295.0000 1.0000
21.7200 1294.0000 1.0000
21.7600 1253.0000 1.0000
21.8000 1288.0000 1.0000
21.8400 1298.0000 1.0000
21.8800 1227.0000 1.0000
21.9200 1280.0000 1.0000
21.9600 1276.0000 1.0000
22.0000 1234.0000 1.0000
22.0400 1260.0000 1.0000
22.0800 1261.0000 1.0000
22.1200 1298.0000 1.0000
22.1600 1245.0000 1.0000
22.2000 1247.0000 1.0000
22.2400 1249.0000 1.0000
22.2800 1229.0000 1.0000
22.3200 1263.0000 1.0000
22.3600 1272.0000 1.0000
22.4000 1244.0000 1.0000
22.4400 1315.0000 1.0000
22.4800 1348.0000 1.0000
22.5200 1279.0000 1.0000
22.5600 1322.0000 1.0000
22.6000 1331.0000 1.0000
22.6400 1244.0000 1.0000
22.6800 1287.0000 1.0000
22.7200 1305.0000 1.0000
22.7600 1287.0000 1.0000
22.8000 1265.0000 1.0000
22.8400 1343.0000 1.0000
22.8800 1326.0000 1.0000
22.9200 1279.0000 1.0000
22.9600 1331.0000 1.0000
23.0000 1401.0000 1.0000
23.0400 1303.0000 1.0000
23.0800 1329.0000 1.0000
23.1200 1291.0000 1.0000
23.1600 1326.0000 1.0000
23.2000 1313.0000 1.0000
23.2400 1307.0000 1.0000
23.2800 1321.0000 1.0000
23.3200 1335.0000 1.0000
23.3600 1310.0000 1.0000
23.4000 1328.0000 1.0000
23.4400 1339.0000 1.0000
23.4800 1329.0000 1.0000
23.5200 1331.0000 1.0000
23.5600 1364.0000 1.0000
23.6000 1335.0000 1.0000
23.6400 1385.0000 1.0000
23.6800 1399.0000 1.0000
23.7200 1335.0000 1.0000
23.7600 1414.0000 1.0000
23.8000 1313.0000 1.0000
23.8400 1356.0000 1.0000
23.8800 1325.0000 1.0000
23.9200 1272.0000 1.0000
23.9600 1335.0000 1.0000
24.0000 1271.0000 1.0000
24.0400 1353.0000 1.0000
24.0800 1291.0000 1.0000
24.1200 1346.0000 1.0000
24.1600 1401.0000 1.0000
24.2000 1350.0000 1.0000
24.2400 1350.0000 1.0000
24.2800 1318.0000 1.0000
24.3200 1348.0000 1.0000
24.3600 1412.0000 1.0000
24.4000 1360.0000 1.0000
24.4400 1395.0000 1.0000
24.4800 1399.0000 1.0000
24.5200 1393.0000 1.0000
24.5600 1378.0000 1.0000
24.6000 1391.0000 1.0000
24.6400 1395.0000 1.0000
24.6800 1332.0000 1.0000
24.7200 1447.0000 1.0000
24.7600 1376.0000 1.0000
24.8000 1433.0000 1.0000
24.8400 1390.0000 1.0000
24.8800 1413.0000 1.0000
24.9200 1402.0000 1.0000
24.9600 1450.0000 1.0000
25.0000 1432.0000 1.0000
25.0400 1395.0000 1.0000
25.0800 1430.0000 1.0000
25.1200 1480.0000 1.0000
25.1600 1459.0000 1.0000
25.2000 1443.0000 1.0000
25.2400 1395.0000 1.0000
25.2800 1425.0000 1.0000
25.3200 1412.0000 1.0000
25.3600 1397.0000 1.0000
25.4000 1420.0000 1.0000
25.4400 1412.0000 1.0000
25.4800 1425.0000 1.0000
25.5200 1432.0000 1.0000
25.5600 1432.0000 1.0000
25.6000 1387.0000 1.0000
25.6400 1351.0000 1.0000
25.6800 1372.0000 1.0000
25.7200 1417.0000 1.0000
25.7600 1385.0000 1.0000
25.8000 1438.0000 1.0000
25.8400 1419.0000 1.0000
25.8800 1474.0000 1.0000
25.9200 1469.0000 1.0000
25.9600 1416.0000 1.0000
26.0000 1448.0000 1.0000
26.0400 1405.0000 1.0000
26.0800 1469.0000 1.0000
26.1200 1398.0000 1.0000
26.1600 1495.0000 1.0000
26.2000 1444.0000 1.0000
26.2400 1453.0000 1.0000
26.2800 1431.0000 1.0000
26.3200 1548.0000 1.0000
26.3600 1427.0000 1.0000
26.4000 1475.0000 1.0000
26.4400 1529.0000 1.0000
26.4800 1541.0000 1.0000
26.5200 1487.0000 1.0000
26.5600 1447.0000 1.0000
26.6000 1503.0000 1.0000
26.6400 1563.0000 1.0000
26.6800 1601.0000 1.0000
26.7200 1578.0000 1.0000
26.7600 1613.0000 1.0000
26.8000 1640.0000 1.0000
26.8400 1665.0000 1.0000
26.8800 1762.0000 1.0000
26.9200 1823.0000 1.0000
26.9600 2018.0000 1.0000
27.0000 2172.0000 1.0000
27.0400 2343.0000 1.0000
27.0800 2769.0000 1.0000
27.1200 3336.0000 1.0000
27.1600 4024.0000 1.0000
27.2000 5116.0000 1.0000
27.2400 5908.0000 1.0000
27.2800 6255.0000 1.0000
27.3200 5873.0000 1.0000
27.3600 4865.0000 1.0000
27.4000 3821.0000 1.0000
27.4400 3034.0000 1.0000
27.4800 2646.0000 1.0000
27.5200 2247.0000 1.0000
27.5600 2062.0000 1.0000
27.6000 2010.0000 1.0000
27.6400 1835.0000 1.0000
27.6800 1724.0000 1.0000
27.7200 1701.0000 1.0000
27.7600 1604.0000 1.0000
27.8000 1616.0000 1.0000
27.8400 1597.0000 1.0000
27.8800 1558.0000 1.0000
27.9200 1497.0000 1.0000
27.9600 1478.0000 1.0000
28.0000 1499.0000 1.0000
28.0400 1501.0000 1.0000
28.0800 1408.0000 1.0000
28.1200 1507.0000 1.0000
28.1600 1471.0000 1.0000
28.2000 1434.0000 1.0000
28.2400 1359.0000 1.0000
28.2800 1382.0000 1.0000
28.3200 1451.0000 1.0000
28.3600 1430.0000 1.0000
28.4000 1366.0000 1.0000
28.4400 1356.0000 1.0000
28.4800 1407.0000 1.0000
28.5200 1387.0000 1.0000
28.5600 1362.0000 1.0000
28.6000 1416.0000 1.0000
28.6400 1431.0000 1.0000
28.6800 1385.0000 1.0000
28.7200 1390.0000 1.0000
28.7600 1384.0000 1.0000
28.8000 1398.0000 1.0000
28.8400 1331.0000 1.0000
28.8800 1350.0000 1.0000
28.9200 1336.0000 1.0000
28.9600 1324.0000 1.0000
29.0000 1426.0000 1.0000
29.0400 1364.0000 1.0000
29.0800 1394.0000 1.0000
29.1200 1353.0000 1.0000
29.1600 1314.0000 1.0000
29.2000 1387.0000 1.0000
29.2400 1309.0000 1.0000
29.2800 1383.0000 1.0000
29.3200 1345.0000 1.0000
29.3600 1334.0000 1.0000
29.4000 1304.0000 1.0000
29.4400 1323.0000 1.0000
29.4800 1368.0000 1.0000
29.5200 1344.0000 1.0000
29.5600 1264.0000 1.0000
29.6000 1328.0000 1.0000
29.6400 1303.0000 1.0000
29.6800 1265.0000 1.0000
29.7200 1263.0000 1.0000
29.7600 1228.0000 1.0000
29.8000 1309.0000 1.0000
29.8400 1252.0000 1.0000
29.8800 1300.0000 1.0000
29.9200 1281.0000 1.0000
29.9600 1255.0000 1.0000
30.0000 1333.0000 1.0000
30.0400 1270.0000 1.0000
30.0800 1276.0000 1.0000
30.1200 1312.0000 1.0000
30.1600 1288.0000 1.0000
30.2000 1285.0000 1.0000
30.2400 1212.0000 1.0000
30.2800 1302.0000 1.0000
30.3200 1245.0000 1.0000
30.3600 1280.0000 1.0000
30.4000 1200.0000 1.0000
30.4400 1215.0000 1.0000
30.4800 1258.0000 1.0000
30.5200 1273.0000 1.0000
30.5600 1266.0000 1.0000
30.6000 1270.0000 1.0000
30.6400 1238.0000 1.0000
30.6800 1232.0000 1.0000
30.7200 1265.0000 1.0000
30.7600 1254.0000 1.0000
30.8000 1262.0000 1.0000
30.8400 1254.0000 1.0000
30.8800 1238.0000 1.0000
30.9200 1189.0000 1.0000
30.9600 1242.0000 1.0000
31.0000 1268.0000 1.0000
31.0400 1264.0000 1.0000
31.0800 1239.0000 1.0000
31.1200 1245.0000 1.0000
31.1600 1261.0000 1.0000
31.2000 1220.0000 1.0000
31.2400 1237.0000 1.0000
31.2800 1255.0000 1.0000
31.3200 1261.0000 1.0000
31.3600 1229.0000 1.0000
31.4000 1255.0000 1.0000
31.4400 1221.0000 1.0000
31.4800 1241.0000 1.0000
31.5200 1255.0000 1.0000
31.5600 1257.0000 1.0000
31.6000 1265.0000 1.0000
31.6400 1190.0000 1.0000
31.6800 1213.0000 1.0000
31.7200 1222.0000 1.0000
31.7600 1229.0000 1.0000
31.8000 1186.0000 1.0000
31.8400 1217.0000 1.0000
31.8800 1306.0000 1.0000
31.9200 1278.0000 1.0000
31.9600 1243.0000 1.0000
32.0000 1247.0000 1.0000
32.0400 1215.0000 1.0000
32.0800 1143.0000 1.0000
32.1200 1227.0000 1.0000
32.1600 1250.0000 1.0000
32.2000 1255.0000 1.0000
32.2400 1220.0000 1.0000
32.2800 1192.0000 1.0000
32.3200 1147.0000 1.0000
32.3600 1195.0000 1.0000
32.4000 1218.0000 1.0000
32.4400 1197.0000 1.0000
32.4800 1175.0000 1.0000
32.5200 1203.0000 1.0000
32.5600 1218.0000 1.0000
32.6000 1210.0000 1.0000
32.6400 1171.0000 1.0000
32.6800 1166.0000 1.0000
32.7200 1161.0000 1.0000
32.7600 1197.0000 1.0000
32.8000 1107.0000 1.0000
32.8400 1175.0000 1.0000
32.8800 1122.0000 1.0000
32.9200 1193.0000 1.0000
32.9600 1133.0000 1.0000
33.0000 1164.0000 1.0000
33.0400 1062.0000 1.0000
33.0800 1124.0000 1.0000
33.1200 1128.0000 1.0000
33.1600 1124.0000 1.0000
33.2000 1112.0000 1.0000
33.2400 1132.0000 1.0000
33.2800 1106.0000 1.0000
33.3200 1100.0000 1.0000
33.3600 1116.0000 1.0000
33.4000 1139.0000 1.0000
33.4400 1182.0000 1.0000
33.4800 1132.0000 1.0000
33.5200 1156.0000 1.0000
33.5600 1175.0000 1.0000
33.6000 1144.0000 1.0000
33.6400 1200.0000 1.0000
33.6800 1122.0000 1.0000
33.7200 1197.0000 1.0000
33.7600 1194.0000 1.0000
33.8000 1252.0000 1.0000
33.8400 1230.0000 1.0000
33.8800 1238.0000 1.0000
33.9200 1325.0000 1.0000
33.9600 1290.0000 1.0000
34.0000 1267.0000 1.0000
34.0400 1286.0000 1.0000
34.0800 1289.0000 1.0000
34.1200 1327.0000 1.0000
34.1600 1374.0000 1.0000
34.2000 1406.0000 1.0000
34.2400 1525.0000 1.0000
34.2800 1653.0000 1.0000
34.3200 1881.0000 1.0000
34.3600 2022.0000 1.0000
34.4000 2412.0000 1.0000
34.4400 2655.0000 1.0000
34.4800 2682.0000 1.0000
34.5200 2442.0000 1.0000
34.5600 2234.0000 1.0000
34.6000 1947.0000 1.0000
34.6400 1782.0000 1.0000
34.6800 1536.0000 1.0000
34.7200 1516.0000 1.0000
34.7600 1321.0000 1.0000
34.8000 1288.0000 1.0000
34.8400 1265.0000 1.0000
34.8800 1238.0000 1.0000
34.9200 1169.0000 1.0000
34.9600 1184.0000 1.0000
35.0000 1189.0000 1.0000
35.0400 1139.0000 1.0000
35.0800 1075.0000 1.0000
35.1200 1060.0000 1.0000
35.1600 1090.0000 1.0000
35.2000 1009.0000 1.0000
35.2400 1064.0000 1.0000
35.2800 1046.0000 1.0000
35.3200 984.0000 1.0000
35.3600 987.0000 1.0000
35.4000 1032.0000 1.0000
35.4400 1020.0000 1.0000
35.4800 1058.0000 1.0000
35.5200 954.0000 1.0000
35.5600 994.0000 1.0000
35.6000 993.0000 1.0000
35.6400 999.0000 1.0000
35.6800 928.0000 1.0000
35.7200 1005.0000 1.0000
35.7600 988.0000 1.0000
35.8000 1015.0000 1.0000
35.8400 1005.0000 1.0000
35.8800 974.0000 1.0000
35.9200 969.0000 1.0000
35.9600 964.0000 1.0000
36.0000 1025.0000 1.0000
36.0400 1014.0000 1.0000
36.0800 976.0000 1.0000
36.1200 1041.0000 1.0000
36.1600 1122.0000 1.0000
36.2000 1062.0000 1.0000
36.2400 1187.0000 1.0000
36.2800 1160.0000 1.0000
36.3200 1244.0000 1.0000
36.3600 1298.0000 1.0000
36.4000 1345.0000 1.0000
36.4400 1269.0000 1.0000
36.4800 1180.0000 1.0000
36.5200 1161.0000 1.0000
36.5600 1121.0000 1.0000
36.6000 1067.0000 1.0000
36.6400 1073.0000 1.0000
36.6800 989.0000 1.0000
36.7200 977.0000 1.0000
36.7600 923.0000 1.0000
36.8000 931.0000 1.0000
36.8400 905.0000 1.0000
36.8800 900.0000 1.0000
36.9200 897.0000 1.0000
36.9600 928.0000 1.0000
37.0000 874.0000 1.0000
37.0400 970.0000 1.0000
37.0800 912.0000 1.0000
37.1200 886.0000 1.0000
37.1600 915.0000 1.0000
37.2000 934.0000 1.0000
37.2400 911.0000 1.0000
37.2800 918.0000 1.0000
37.3200 888.0000 1.0000
37.3600 948.0000 1.0000
37.4000 936.0000 1.0000
37.4400 861.0000 1.0000
37.4800 853.0000 1.0000
37.5200 891.0000 1.0000
37.5600 889.0000 1.0000
37.6000 901.0000 1.0000
37.6400 894.0000 1.0000
37.6800 893.0000 1.0000
37.7200 906.0000 1.0000
37.7600 877.0000 1.0000
37.8000 938.0000 1.0000
37.8400 937.0000 1.0000
37.8800 969.0000 1.0000
37.9200 937.0000 1.0000
37.9600 1009.0000 1.0000
38.0000 964.0000 1.0000
38.0400 1031.0000 1.0000
38.0800 1103.0000 1.0000
38.1200 1200.0000 1.0000
38.1600 1256.0000 1.0000
38.2000 1427.0000 1.0000
38.2400 1697.0000 1.0000
38.2800 2018.0000 1.0000
38.3200 2417.0000 1.0000
38.3600 3370.0000 1.0000
38.4000 4403.0000 1.0000
38.4400 5715.0000 1.0000
38.4800 6776.0000 1.0000
38.5200 7156.0000 1.0000
38.5600 6538.0000 1.0000
38.6000 5320.0000 1.0000
38.6400 4346.0000 1.0000
38.6800 3298.0000 1.0000
38.7200 2435.0000 1.0000
38.7600 1948.0000 1.0000
38.8000 1578.0000 1.0000
38.8400 1364.0000 1.0000
38.8800 1208.0000 1.0000
38.9200 1201.0000 1.0000
38.9600 1039.0000 1.0000
39.0000 1019.0000 1.0000
39.0400 946.0000 1.0000
39.0800 911.0000 1.0000
39.1200 849.0000 1.0000
39.1600 886.0000 1.0000
39.2000 851.0000 1.0000
39.2400 838.0000 1.0000
39.2800 830.0000 1.0000
39.3200 802.0000 1.0000
39.3600 844.0000 1.0000
39.4000 832.0000 1.0000
39.4400 832.0000 1.0000
39.4800 850.0000 1.0000
39.5200 847.0000 1.0000
39.5600 863.0000 1.0000
39.6000 815.0000 1.0000
39.6400 826.0000 1.0000
39.6800 847.0000 1.0000
39.7200 845.0000 1.0000
39.7600 798.0000 1.0000
39.8000 793.0000 1.0000
39.8400 783.0000 1.0000
39.8800 779.0000 1.0000
39.9200 743.0000 1.0000
39.9600 775.0000 1.0000
40.0000 782.0000 1.0000
40.0400 795.0000 1.0000
40.0800 750.0000 1.0000
40.1200 775.0000 1.0000
40.1600 740.0000 1.0000
40.2000 768.0000 1.0000
40.2400 731.0000 1.0000
40.2800 728.0000 1.0000
40.3200 782.0000 1.0000
40.3600 751.0000 1.0000
40.4000 710.0000 1.0000
40.4400 790.0000 1.0000
40.4800 790.0000 1.0000
40.5200 775.0000 1.0000
40.5600 808.0000 1.0000
40.6000 767.0000 1.0000
40.6400 708.0000 1.0000
40.6800 757.0000 1.0000
40.7200 758.0000 1.0000
40.7600 734.0000 1.0000
40.8000 760.0000 1.0000
40.8400 726.0000 1.0000
40.8800 739.0000 1.0000
40.9200 747.0000 1.0000
40.9600 729.0000 1.0000
41.0000 744.0000 1.0000
41.0400 730.0000 1.0000
41.0800 745.0000 1.0000
41.1200 751.0000 1.0000
41.1600 729.0000 1.0000
41.2000 716.0000 1.0000
41.2400 708.0000 1.0000
41.2800 742.0000 1.0000
41.3200 732.0000 1.0000
41.3600 695.0000 1.0000
41.4000 745.0000 1.0000
41.4400 721.0000 1.0000
41.4800 769.0000 1.0000
41.5200 790.0000 1.0000
41.5600 754.0000 1.0000
41.6000 757.0000 1.0000
41.6400 729.0000 1.0000
41.6800 738.0000 1.0000
41.7200 744.0000 1.0000
41.7600 770.0000 1.0000
41.8000 749.0000 1.0000
41.8400 686.0000 1.0000
41.8800 766.0000 1.0000
41.9200 746.0000 1.0000
41.9600 710.0000 1.0000
42.0000 702.0000 1.0000
42.0400 738.0000 1.0000
42.0800 783.0000 1.0000
42.1200 770.0000 1.0000
42.1600 722.0000 1.0000
42.2000 729.0000 1.0000
42.2400 740.0000 1.0000
42.2800 710.0000 1.0000
42.3200 718.0000 1.0000
42.3600 723.0000 1.0000
42.4000 729.0000 1.0000
42.4400 741.0000 1.0000
42.4800 697.0000 1.0000
42.5200 755.0000 1.0000
42.5600 737.0000 1.0000
42.6000 717.0000 1.0000
42.6400 716.0000 1.0000
42.6800 699.0000 1.0000
42.7200 714.0000 1.0000
42.7600 754.0000 1.0000
42.8000 724.0000 1.0000
42.8400 722.0000 1.0000
42.8800 709.0000 1.0000
42.9200 734.0000 1.0000
42.9600 768.0000 1.0000
43.0000 719.0000 1.0000
43.0400 767.0000 1.0000
43.0800 773.0000 1.0000
43.1200 779.0000 1.0000
43.1600 801.0000 1.0000
43.2000 824.0000 1.0000
43.2400 817.0000 1.0000
43.2800 766.0000 1.0000
43.3200 794.0000 1.0000
43.3600 789.0000 1.0000
43.4000 745.0000 1.0000
43.4400 799.0000 1.0000
43.4800 727.0000 1.0000
43.5200 755.0000 1.0000
43.5600 662.0000 1.0000
43.6000 695.0000 1.0000
43.6400 739.0000 1.0000
43.6800 745.0000 1.0000
43.7200 733.0000 1.0000
43.7600 735.0000 1.0000
43.8000 695.0000 1.0000
43.8400 721.0000 1.0000
43.8800 668.0000 1.0000
43.9200 698.0000 1.0000
43.9600 701.0000 1.0000
44.0000 653.0000 1.0000
44.0400 669.0000 1.0000
44.0800 696.0000 1.0000
44.1200 673.0000 1.0000
44.1600 664.0000 1.0000
44.2000 740.0000 1.0000
44.2400 705.0000 1.0000
44.2800 755.0000 1.0000
44.3200 673.0000 1.0000
44.3600 661.0000 1.0000
44.4000 729.0000 1.0000
44.4400 657.0000 1.0000
44.4800 695.0000 1.0000
44.5200 691.0000 1.0000
44.5600 727.0000 1.0000
44.6000 709.0000 1.0000
44.6400 677.0000 1.0000
44.6800 696.0000 1.0000
44.7200 695.0000 1.0000
44.7600 690.0000 1.0000
44.8000 719.0000 1.0000
44.8400 693.0000 1.0000
44.8800 670.0000 1.0000
44.9200 682.0000 1.0000
44.9600 670.0000 1.0000
45.0000 671.0000 1.0000
45.0400 693.0000 1.0000
45.0800 703.0000 1.0000
45.1200 738.0000 1.0000
45.1600 692.0000 1.0000
45.2000 670.0000 1.0000
45.2400 675.0000 1.0000
45.2800 650.0000 1.0000
45.3200 680.0000 1.0000
45.3600 682.0000 1.0000
45.4000 644.0000 1.0000
45.4400 707.0000 1.0000
45.4800 649.0000 1.0000
45.5200 675.0000 1.0000
45.5600 651.0000 1.0000
45.6000 645.0000 1.0000
45.6400 626.0000 1.0000
45.6800 667.0000 1.0000
45.7200 661.0000 1.0000
45.7600 682.0000 1.0000
45.8000 637.0000 1.0000
45.8400 643.0000 1.0000
45.8800 684.0000 1.0000
45.9200 682.0000 1.0000
45.9600 662.0000 1.0000
46.0000 684.0000 1.0000
46.0400 659.0000 1.0000
46.0800 690.0000 1.0000
46.1200 665.0000 1.0000
46.1600 629.0000 1.0000
46.2000 663.0000 1.0000
46.2400 656.0000 1.0000
46.2800 650.0000 1.0000
46.3200 670.0000 1.0000
46.3600 642.0000 1.0000
46.4000 660.0000 1.0000
46.4400 711.0000 1.0000
46.4800 648.0000 1.0000
46.5200 657.0000 1.0000
46.5600 692.0000 1.0000
46.6000 667.0000 1.0000
46.6400 636.0000 1.0000
46.6800 621.0000 1.0000
46.7200 642.0000 1.0000
46.7600 634.0000 1.0000
46.8000 640.0000 1.0000
46.8400 679.0000 1.0000
46.8800 694.0000 1.0000
46.9200 656.0000 1.0000
46.9600 665.0000 1.0000
47.0000 668.0000 1.0000
47.0400 674.0000 1.0000
47.0800 707.0000 1.0000
47.1200 633.0000 1.0000
47.1600 646.0000 1.0000
47.2000 698.0000 1.0000
47.2400 636.0000 1.0000
47.2800 661.0000 1.0000
47.3200 671.0000 1.0000
47.3600 618.0000 1.0000
47.4000 632.0000 1.0000
47.4400 636.0000 1.0000
47.4800 618.0000 1.0000
47.5200 594.0000 1.0000
47.5600 601.0000 1.0000
47.6000 652.0000 1.0000
47.6400 599.0000 1.0000
47.6800 617.0000 1.0000
47.7200 638.0000 1.0000
47.7600 616.0000 1.0000
47.8000 651.0000 1.0000
47.8400 645.0000 1.0000
47.8800 610.0000 1.0000
47.9200 615.0000 1.0000
47.9600 636.0000 1.0000
48.0000 646.0000 1.0000
48.0400 596.0000 1.0000
48.0800 625.0000 1.0000
48.1200 646.0000 1.0000
48.1600 621.0000 1.0000
48.2000 659.0000 1.0000
48.2400 638.0000 1.0000
48.2800 616.0000 1.0000
48.3200 626.0000 1.0000
48.3600 646.0000 1.0000
48.4000 612.0000 1.0000
48.4400 638.0000 1.0000
48.4800 602.0000 1.0000
48.5200 595.0000 1.0000
48.5600 602.0000 1.0000
48.6000 662.0000 1.0000
48.6400 606.0000 1.0000
48.6800 640.0000 1.0000
48.7200 612.0000 1.0000
48.7600 638.0000 1.0000
48.8000 631.0000 1.0000
48.8400 636.0000 1.0000
48.8800 635.0000 1.0000
48.9200 599.0000 1.0000
48.9600 601.0000 1.0000
49.0000 603.0000 1.0000
49.0400 656.0000 1.0000
49.0800 611.0000 1.0000
49.1200 587.0000 1.0000
49.1600 597.0000 1.0000
49.2000 623.0000 1.0000
49.2400 605.0000 1.0000
49.2800 582.0000 1.0000
49.3200 610.0000 1.0000
49.3600 595.0000 1.0000
49.4000 619.0000 1.0000
49.4400 609.0000 1.0000
49.4800 637.0000 1.0000
49.5200 637.0000 1.0000
49.5600 607.0000 1.0000
49.6000 635.0000 1.0000
49.6400 632.0000 1.0000
49.6800 603.0000 1.0000
49.7200 636.0000 1.0000
49.7600 617.0000 1.0000
49.8000 606.0000 1.0000
49.8400 642.0000 1.0000
49.8800 604.0000 1.0000
49.9200 607.0000 1.0000
49.9600 652.0000 1.0000
50.0000 615.0000 1.0000
50.0400 608.0000 1.0000
50.0800 620.0000 1.0000
50.1200 655.0000 1.0000
50.1600 635.0000 1.0000
50.2000 621.0000 1.0000
50.2400 612.0000 1.0000
50.2800 615.0000 1.0000
50.3200 634.0000 1.0000
50.3600 633.0000 1.0000
50.4000 614.0000 1.0000
50.4400 643.0000 1.0000
50.4800 670.0000 1.0000
50.5200 580.0000 1.0000
50.5600 609.0000 1.0000
50.6000 623.0000 1.0000
50.6400 627.0000 1.0000
50.6800 645.0000 1.0000
50.7200 611.0000 1.0000
50.7600 610.0000 1.0000
50.8000 650.0000 1.0000
50.8400 656.0000 1.0000
50.8800 656.0000 1.0000
50.9200 631.0000 1.0000
50.9600 626.0000 1.0000
51.0000 620.0000 1.0000
51.0400 656.0000 1.0000
51.0800 592.0000 1.0000
51.1200 617.0000 1.0000
51.1600 646.0000 1.0000
51.2000 647.0000 1.0000
51.2400 617.0000 1.0000
51.2800 654.0000 1.0000
51.3200 639.0000 1.0000
51.3600 638.0000 1.0000
51.4000 601.0000 1.0000
51.4400 624.0000 1.0000
51.4800 668.0000 1.0000
51.5200 614.0000 1.0000
51.5600 668.0000 1.0000
51.6000 681.0000 1.0000
51.6400 692.0000 1.0000
51.6800 732.0000 1.0000
51.7200 685.0000 1.0000
51.7600 685.0000 1.0000
51.8000 731.0000 1.0000
51.8400 754.0000 1.0000
51.8800 808.0000 1.0000
51.9200 889.0000 1.0000
51.9600 1003.0000 1.0000
52.0000 1163.0000 1.0000
52.0400 1341.0000 1.0000
52.0800 1707.0000 1.0000
52.1200 2249.0000 1.0000
52.1600 3112.0000 1.0000
52.2000 4183.0000 1.0000
52.2400 4649.0000 1.0000
52.2800 4091.0000 1.0000
52.3200 3776.0000 1.0000
52.3600 3382.0000 1.0000
52.4000 2851.0000 1.0000
52.4400 2136.0000 1.0000
52.4800 1625.0000 1.0000
52.5200 1353.0000 1.0000
52.5600 1163.0000 1.0000
52.6000 947.0000 1.0000
52.6400 908.0000 1.0000
52.6800 873.0000 1.0000
52.7200 827.0000 1.0000
52.7600 741.0000 1.0000
52.8000 766.0000 1.0000
52.8400 699.0000 1.0000
52.8800 702.0000 1.0000
52.9200 697.0000 1.0000
52.9600 695.0000 1.0000
53.0000 650.0000 1.0000
53.0400 653.0000 1.0000
53.0800 624.0000 1.0000
53.1200 649.0000 1.0000
53.1600 609.0000 1.0000
53.2000 617.0000 1.0000
53.2400 667.0000 1.0000
53.2800 644.0000 1.0000
53.3200 673.0000 1.0000
53.3600 643.0000 1.0000
53.4000 658.0000 1.0000
53.4400 625.0000 1.0000
53.4800 611.0000 1.0000
53.5200 628.0000 1.0000
53.5600 627.0000 1.0000
53.6000 625.0000 1.0000
53.6400 628.0000 1.0000
53.6800 622.0000 1.0000
53.7200 595.0000 1.0000
53.7600 567.0000 1.0000
53.8000 573.0000 1.0000
53.8400 623.0000 1.0000
53.8800 588.0000 1.0000
53.9200 608.0000 1.0000
53.9600 603.0000 1.0000
54.0000 624.0000 1.0000
54.0400 624.0000 1.0000
54.0800 592.0000 1.0000
54.1200 632.0000 1.0000
54.1600 619.0000 1.0000
54.2000 606.0000 1.0000
54.2400 633.0000 1.0000
54.2800 615.0000 1.0000
54.3200 566.0000 1.0000
54.3600 616.0000 1.0000
54.4000 657.0000 1.0000
54.4400 637.0000 1.0000
54.4800 640.0000 1.0000
54.5200 607.0000 1.0000
54.5600 607.0000 1.0000
54.6000 625.0000 1.0000
54.6400 653.0000 1.0000
54.6800 663.0000 1.0000
54.7200 630.0000 1.0000
54.7600 687.0000 1.0000
54.8000 658.0000 1.0000
54.8400 672.0000 1.0000
54.8800 694.0000 1.0000
54.9200 674.0000 1.0000
54.9600 692.0000 1.0000
55.0000 728.0000 1.0000
55.0400 770.0000 1.0000
55.0800 729.0000 1.0000
55.1200 786.0000 1.0000
55.1600 884.0000 1.0000
55.2000 893.0000 1.0000
55.2400 988.0000 1.0000
55.2800 963.0000 1.0000
55.3200 943.0000 1.0000
55.3600 932.0000 1.0000
55.4000 902.0000 1.0000
55.4400 850.0000 1.0000
55.4800 759.0000 1.0000
55.5200 703.0000 1.0000
55.5600 684.0000 1.0000
55.6000 673.0000 1.0000
55.6400 651.0000 1.0000
55.6800 637.0000 1.0000
55.7200 648.0000 1.0000
55.7600 627.0000 1.0000
55.8000 600.0000 1.0000
55.8400 606.0000 1.0000
55.8800 633.0000 1.0000
55.9200 637.0000 1.0000
55.9600 653.0000 1.0000
56.0000 595.0000 1.0000
56.0400 590.0000 1.0000
56.0800 554.0000 1.0000
56.1200 618.0000 1.0000
56.1600 608.0000 1.0000
56.2000 609.0000 1.0000
56.2400 596.0000 1.0000
56.2800 582.0000 1.0000
56.3200 617.0000 1.0000
56.3600 579.0000 1.0000
56.4000 635.0000 1.0000
56.4400 604.0000 1.0000
56.4800 619.0000 1.0000
56.5200 608.0000 1.0000
56.5600 568.0000 1.0000
56.6000 607.0000 1.0000
56.6400 599.0000 1.0000
56.6800 611.0000 1.0000
56.7200 636.0000 1.0000
56.7600 577.0000 1.0000
56.8000 618.0000 1.0000
56.8400 586.0000 1.0000
56.8800 629.0000 1.0000
56.9200 593.0000 1.0000
56.9600 577.0000 1.0000
57.0000 629.0000 1.0000
57.0400 548.0000 1.0000
57.0800 610.0000 1.0000
57.1200 585.0000 1.0000
57.1600 597.0000 1.0000
57.2000 597.0000 1.0000
57.2400 563.0000 1.0000
57.2800 567.0000 1.0000
57.3200 602.0000 1.0000
57.3600 560.0000 1.0000
57.4000 582.0000 1.0000
57.4400 546.0000 1.0000
57.4800 573.0000 1.0000
57.5200 611.0000 1.0000
57.5600 576.0000 1.0000
57.6000 580.0000 1.0000
57.6400 587.0000 1.0000
57.6800 554.0000 1.0000
57.7200 587.0000 1.0000
57.7600 576.0000 1.0000
57.8000 574.0000 1.0000
57.8400 599.0000 1.0000
57.8800 570.0000 1.0000
57.9200 580.0000 1.0000
57.9600 584.0000 1.0000
58.0000 601.0000 1.0000
58.0400 619.0000 1.0000
58.0800 592.0000 1.0000
58.1200 623.0000 1.0000
58.1600 610.0000 1.0000
58.2000 602.0000 1.0000
58.2400 620.0000 1.0000
58.2800 591.0000 1.0000
58.3200 573.0000 1.0000
58.3600 600.0000 1.0000
58.4000 572.0000 1.0000
58.4400 594.0000 1.0000
58.4800 584.0000 1.0000
58.5200 593.0000 1.0000
58.5600 583.0000 1.0000
58.6000 554.0000 1.0000
58.6400 554.0000 1.0000
58.6800 595.0000 1.0000
58.7200 540.0000 1.0000
58.7600 555.0000 1.0000
58.8000 582.0000 1.0000
58.8400 609.0000 1.0000
58.8800 550.0000 1.0000
58.9200 594.0000 1.0000
58.9600 560.0000 1.0000
59.0000 553.0000 1.0000
59.0400 599.0000 1.0000
59.0800 592.0000 1.0000
59.1200 590.0000 1.0000
59.1600 575.0000 1.0000
59.2000 562.0000 1.0000
59.2400 583.0000 1.0000
59.2800 572.0000 1.0000
59.3200 544.0000 1.0000
59.3600 554.0000 1.0000
59.4000 600.0000 1.0000
59.4400 593.0000 1.0000
59.4800 620.0000 1.0000
59.5200 570.0000 1.0000
59.5600 557.0000 1.0000
59.6000 623.0000 1.0000
59.6400 539.0000 1.0000
59.6800 591.0000 1.0000
59.7200 595.0000 1.0000
59.7600 582.0000 1.0000
59.8000 601.0000 1.0000
59.8400 559.0000 1.0000
59.8800 561.0000 1.0000
59.9200 574.0000 1.0000
59.9600 562.0000 1.0000
60.0000 535.0000 1.0000
60.0400 564.0000 1.0000
60.0800 583.0000 1.0000
60.1200 572.0000 1.0000
60.1600 577.0000 1.0000
60.2000 576.0000 1.0000
60.2400 579.0000 1.0000
60.2800 596.0000 1.0000
60.3200 574.0000 1.0000
60.3600 566.0000 1.0000
60.4000 590.0000 1.0000
60.4400 613.0000 1.0000
60.4800 585.0000 1.0000
60.5200 545.0000 1.0000
60.5600 553.0000 1.0000
60.6000 581.0000 1.0000
60.6400 562.0000 1.0000
60.6800 544.0000 1.0000
60.7200 599.0000 1.0000
60.7600 612.0000 1.0000
60.8000 589.0000 1.0000
60.8400 562.0000 1.0000
60.8800 579.0000 1.0000
60.9200 619.0000 1.0000
60.9600 584.0000 1.0000
61.0000 603.0000 1.0000
61.0400 614.0000 1.0000
61.0800 585.0000 1.0000
61.1200 610.0000 1.0000
61.1600 595.0000 1.0000
61.2000 568.0000 1.0000
61.2400 615.0000 1.0000
61.2800 609.0000 1.0000
61.3200 585.0000 1.0000
61.3600 601.0000 1.0000
61.4000 620.0000 1.0000
61.4400 584.0000 1.0000
61.4800 597.0000 1.0000
61.5200 639.0000 1.0000
61.5600 600.0000 1.0000
61.6000 574.0000 1.0000
61.6400 623.0000 1.0000
61.6800 633.0000 1.0000
61.7200 635.0000 1.0000
61.7600 683.0000 1.0000
61.8000 667.0000 1.0000
61.8400 696.0000 1.0000
61.8800 694.0000 1.0000
61.9200 712.0000 1.0000
61.9600 775.0000 1.0000
62.0000 849.0000 1.0000
62.0400 872.0000 1.0000
62.0800 1056.0000 1.0000
62.1200 1179.0000 1.0000
62.1600 1260.0000 1.0000
62.2000 1369.0000 1.0000
62.2400 1495.0000 1.0000
62.2800 1575.0000 1.0000
62.3200 1420.0000 1.0000
62.3600 1426.0000 1.0000
62.4000 1323.0000 1.0000
62.4400 1321.0000 1.0000
62.4800 1108.0000 1.0000
62.5200 1040.0000 1.0000
62.5600 996.0000 1.0000
62.6000 937.0000 1.0000
62.6400 842.0000 1.0000
62.6800 754.0000 1.0000
62.7200 704.0000 1.0000
62.7600 674.0000 1.0000
62.8000 711.0000 1.0000
62.8400 725.0000 1.0000
62.8800 642.0000 1.0000
62.9200 653.0000 1.0000
62.9600 625.0000 1.0000
63.0000 641.0000 1.0000
63.0400 626.0000 1.0000
63.0800 668.0000 1.0000
63.1200 636.0000 1.0000
63.1600 618.0000 1.0000
63.2000 648.0000 1.0000
63.2400 628.0000 1.0000
63.2800 639.0000 1.0000
63.3200 636.0000 1.0000
63.3600 608.0000 1.0000
63.4000 598.0000 1.0000
63.4400 599.0000 1.0000
63.4800 581.0000 1.0000
63.5200 576.0000 1.0000
63.5600 607.0000 1.0000
63.6000 624.0000 1.0000
63.6400 572.0000 1.0000
63.6800 532.0000 1.0000
63.7200 575.0000 1.0000
63.7600 541.0000 1.0000
63.8000 562.0000 1.0000
63.8400 644.0000 1.0000
63.8800 592.0000 1.0000
63.9200 578.0000 1.0000
63.9600 598.0000 1.0000
64.0000 599.0000 1.0000
64.0400 588.0000 1.0000
64.0800 581.0000 1.0000
64.1200 573.0000 1.0000
64.1600 593.0000 1.0000
64.2000 624.0000 1.0000
64.2400 592.0000 1.0000
64.2800 619.0000 1.0000
64.3200 599.0000 1.0000
64.3600 649.0000 1.0000
64.4000 603.0000 1.0000
64.4400 661.0000 1.0000
64.4800 591.0000 1.0000
64.5200 622.0000 1.0000
64.5600 664.0000 1.0000
64.6000 652.0000 1.0000
64.6400 689.0000 1.0000
64.6800 699.0000 1.0000
64.7200 665.0000 1.0000
64.7600 652.0000 1.0000
64.8000 640.0000 1.0000
64.8400 649.0000 1.0000
64.8800 677.0000 1.0000
64.9200 608.0000 1.0000
64.9600 615.0000 1.0000
65.0000 645.0000 1.0000
65.0400 654.0000 1.0000
65.0800 640.0000 1.0000
65.1200 643.0000 1.0000
65.1600 648.0000 1.0000
65.2000 587.0000 1.0000
65.2400 608.0000 1.0000
65.2800 611.0000 1.0000
65.3200 569.0000 1.0000
65.3600 613.0000 1.0000
65.4000 643.0000 1.0000
65.4400 597.0000 1.0000
65.4800 610.0000 1.0000
65.5200 586.0000 1.0000
65.5600 672.0000 1.0000
65.6000 674.0000 1.0000
65.6400 657.0000 1.0000
65.6800 625.0000 1.0000
65.7200 682.0000 1.0000
65.7600 719.0000 1.0000
65.8000 677.0000 1.0000
65.8400 688.0000 1.0000
65.8800 802.0000 1.0000
65.9200 861.0000 1.0000
65.9600 929.0000 1.0000
66.0000 1048.0000 1.0000
66.0400 1193.0000 1.0000
66.0800 1363.0000 1.0000
66.1200 1801.0000 1.0000
66.1600 2187.0000 1.0000
66.2000 2379.0000 1.0000
66.2400 2442.0000 1.0000
66.2800 2291.0000 1.0000
66.3200 2205.0000 1.0000
66.3600 2032.0000 1.0000
66.4000 1832.0000 1.0000
66.4400 1641.0000 1.0000
66.4800 1493.0000 1.0000
66.5200 1185.0000 1.0000
66.5600 1028.0000 1.0000
66.6000 938.0000 1.0000
66.6400 874.0000 1.0000
66.6800 810.0000 1.0000
66.7200 774.0000 1.0000
66.7600 696.0000 1.0000
66.8000 639.0000 1.0000
66.8400 650.0000 1.0000
66.8800 620.0000 1.0000
66.9200 614.0000 1.0000
66.9600 620.0000 1.0000
67.0000 591.0000 1.0000
67.0400 587.0000 1.0000
67.0800 596.0000 1.0000
67.1200 575.0000 1.0000
67.1600 584.0000 1.0000
67.2000 558.0000 1.0000
67.2400 536.0000 1.0000
67.2800 562.0000 1.0000
67.3200 577.0000 1.0000
67.3600 533.0000 1.0000
67.4000 552.0000 1.0000
67.4400 585.0000 1.0000
67.4800 527.0000 1.0000
67.5200 577.0000 1.0000
67.5600 569.0000 1.0000
67.6000 524.0000 1.0000
67.6400 544.0000 1.0000
67.6800 534.0000 1.0000
67.7200 533.0000 1.0000
67.7600 531.0000 1.0000
67.8000 582.0000 1.0000
67.8400 541.0000 1.0000
67.8800 502.0000 1.0000
67.9200 519.0000 1.0000
67.9600 528.0000 1.0000
68.0000 580.0000 1.0000
68.0400 526.0000 1.0000
68.0800 563.0000 1.0000
68.1200 546.0000 1.0000
68.1600 547.0000 1.0000
68.2000 520.0000 1.0000
68.2400 545.0000 1.0000
68.2800 514.0000 1.0000
68.3200 548.0000 1.0000
68.3600 544.0000 1.0000
68.4000 522.0000 1.0000
68.4400 542.0000 1.0000
68.4800 536.0000 1.0000
68.5200 529.0000 1.0000
68.5600 541.0000 1.0000
68.6000 521.0000 1.0000
68.6400 541.0000 1.0000
68.6800 537.0000 1.0000
68.7200 527.0000 1.0000
68.7600 549.0000 1.0000
68.8000 522.0000 1.0000
68.8400 529.0000 1.0000
68.8800 495.0000 1.0000
68.9200 511.0000 1.0000
68.9600 545.0000 1.0000
69.0000 504.0000 1.0000
69.0400 480.0000 1.0000
69.0800 506.0000 1.0000
69.1200 513.0000 1.0000
69.1600 527.0000 1.0000
69.2000 487.0000 1.0000
69.2400 546.0000 1.0000
69.2800 508.0000 1.0000
69.3200 520.0000 1.0000
69.3600 536.0000 1.0000
69.4000 525.0000 1.0000
69.4400 483.0000 1.0000
69.4800 524.0000 1.0000
69.5200 524.0000 1.0000
69.5600 517.0000 1.0000
69.6000 502.0000 1.0000
69.6400 534.0000 1.0000
69.6800 494.0000 1.0000
69.7200 483.0000 1.0000
69.7600 539.0000 1.0000
69.8000 488.0000 1.0000
69.8400 528.0000 1.0000
69.8800 495.0000 1.0000
69.9200 499.0000 1.0000
69.9600 485.0000 1.0000
70.0000 478.0000 1.0000
*RAS_INT_END
*RAS_TEMPERATURE_START
*RAS_TEMPERATURE_END
*RAS_DATA_END