File: Section2_75_samples/XRD/No_060_SS1_1.ras
*RAS_DATA_START
*RAS_HEADER_START
*DISP_FMT_X "%.2f"
*DISP_FMT_Y "%.0f"
*DISP_FULLSCALE "16142.0000000000"
*DISP_LINE_COLOR "255.0000000000"
*DISP_LINE_STYLE "0.0000000000"
*DISP_LINE_WIDTH "0.2500000000"
*DISP_NOTE "測定データ-5"
*DISP_OFFSET_Y "0.0000000000"
*DISP_PEAKSEARCH_UNIT_Y "cps"
*DISP_RANGE_BOTTOM "0.0000000000"
*DISP_RANGE_LEFT "20.0000000000"
*DISP_RANGE_LOGCUTOFF "0.0100000000"
*DISP_RANGE_RIGHT "70.0000000000"
*DISP_RANGE_TOP "16142.0000000000"
*DISP_SCALE_MODE_Y "0.0000000000"
*DISP_TAB_NAME "2θ/θ"
*DISP_TITLE_Y "強度"
*DISP_UNIT_Y "cps"
*DISP_WINDOW_NAME "MSG_MACROENGINE"
*FILE_COMMENT " "
*FILE_MD5 ""
*FILE_MEMO " "
*FILE_OPERATOR "Administrator"
*FILE_SAMPLE " "
*FILE_TYPE "RAS_RAW"
*FILE_USERGROUP "システムマネージャ"
*FILE_VERSION "1.0000000000"
*HW_ATTACHMENT_ID "ATT0025"
*HW_ATTACHMENT_NAME "標準|Standard"
*HW_COUNTER_ID-0 "CUT0025"
*HW_COUNTER_ID-1 "CUT0020"
*HW_COUNTER_ID-2 "CUT0020"
*HW_COUNTER_ID-3 "CSL0021"
*HW_COUNTER_ID-4 "CMC0021"
*HW_COUNTER_NAME-0 "D/teX Ultra|D/teX Ultra"
*HW_COUNTER_NAME-1 "None|None"
*HW_COUNTER_NAME-2 "None|None"
*HW_COUNTER_NAME-3 "BBM|BBM"
*HW_COUNTER_NAME-4 "検出器モノクロメータ|Detector monochromator"
*HW_COUNTER_SELECT_NAME "D/teX Ultra|D/teX Ultra"
*HW_GONIOMETER_ID "GON0023"
*HW_GONIOMETER_NAME "SmartLab|SmartLab"
*HW_GONIOMETER_RADIUS-0 "90.0"
*HW_GONIOMETER_RADIUS-1 "114.0"
*HW_GONIOMETER_RADIUS-2 "190.0"
*HW_GONIOMETER_RADIUS-3 "300.0"
*HW_GONIOMETER_RADIUS-4 "187.0"
*HW_GONIOMETER_RADIUS-5 "300.0"
*HW_GONIOMETER_RADIUS-6 "113.0"
*HW_GONIOMETER_RADIUS-7 "331.0"
*HW_I_OPT_ID-0 "CBO0021"
*HW_I_OPT_ID-1 "ICR0023"
*HW_I_OPT_ID-2 "ISL0021"
*HW_I_OPT_ID-3 "ISO0021"
*HW_I_OPT_ID-4 "IAD0021"
*HW_I_OPT_ID-5 "IPR0001"
*HW_I_OPT_NAME-0 "CBOユニット|CBO unit"
*HW_I_OPT_NAME-1 "標準入射光学ユニット|Standard incident optical unit"
*HW_I_OPT_NAME-2 "標準入射スリットボックス|Standard incident slit box"
*HW_I_OPT_NAME-3 "入射平行スリット|Incident parallel slit"
*HW_I_OPT_NAME-4 "長手制限スリット|Length limiting slit"
*HW_I_OPT_NAME-5 "None|None"
*HW_R_ATTENUATER_AUTOMODE "0"
*HW_R_OPT_ID-0 "RSS0021"
*HW_R_OPT_ID-1 "RCR0023"
*HW_R_OPT_ID-2 "RSO0021"
*HW_R_OPT_ID-3 "RRS0021"
*HW_R_OPT_ID-4 "ATN0021"
*HW_R_OPT_ID-5 "RFL0021"
*HW_R_OPT_ID-6 "RAD0021"
*HW_R_OPT_NAME-0 "標準受光スリットボックス1|Standard receiving slit box # 1"
*HW_R_OPT_NAME-1 "標準受光光学ユニット1|Standard receiving unit # 1"
*HW_R_OPT_NAME-2 "標準受光光学ユニット2|Standard receiving optical unit # 2"
*HW_R_OPT_NAME-3 "標準受光スリットボックス2|Standard receiving slit box # 2"
*HW_R_OPT_NAME-4 "標準アッテネータ|Standard Attenuator"
*HW_R_OPT_NAME-5 "Cu Kβ|Cu K-beta"
*HW_R_OPT_NAME-6 "調整用受光スリット|Alignment receiving slit"
*HW_SAMPLE_HOLDER_ID "SMP0023"
*HW_SAMPLE_HOLDER_NAME "標準Zステージ|Standard Z stage"
*HW_XG_CURRENT_MAX "50"
*HW_XG_CURRENT_MIN "2"
*HW_XG_CURRENT_RESOLUTION "1"
*HW_XG_CURRENT_UNIT "mA"
*HW_XG_FOCUS "1mm x 10mm"
*HW_XG_FOCUS_TYPE "Normal"
*HW_XG_ID ""
*HW_XG_NAME "3kW 封入管(ID:1200)|3kW Sealed tube(ID:1200)"
*HW_XG_TARGET_ATOMIC_NUMBER "29.0000000000"
*HW_XG_TARGET_NAME "Cu"
*HW_XG_TYPE "Hermetic"
*HW_XG_VOLTAGE_MAX "60"
*HW_XG_VOLTAGE_MIN "20"
*HW_XG_VOLTAGE_RESOLUTION "1"
*HW_XG_VOLTAGE_UNIT "kV"
*HW_XG_WATT_MAX "1.500"
*HW_XG_WATT_UNIT "kW"
*HW_XG_WAVE_LENGTH_ALPHA1 "1.540593"
*HW_XG_WAVE_LENGTH_ALPHA2 "1.544414"
*HW_XG_WAVE_LENGTH_BETA "1.392250"
*MEAS_COND_AXIS_NAME-0 "2θ/θ"
*MEAS_COND_AXIS_NAME-1 "2θ"
*MEAS_COND_AXIS_NAME-2 "ω"
*MEAS_COND_AXIS_NAME-3 "Z"
*MEAS_COND_AXIS_NAME-4 "2θ/ω"
*MEAS_COND_AXIS_NAME-5 "θs"
*MEAS_COND_AXIS_NAME-6 "θd"
*MEAS_COND_AXIS_NAME-7 "Ts"
*MEAS_COND_AXIS_NAME-8 "CBO選択スリット"
*MEAS_COND_AXIS_NAME-9 "M"
*MEAS_COND_AXIS_NAME-10 "入射平行スリット"
*MEAS_COND_AXIS_NAME-11 "入射スリット"
*MEAS_COND_AXIS_NAME-12 ""
*MEAS_COND_AXIS_NAME-13 "Zs"
*MEAS_COND_AXIS_NAME-14 "入射光学素子"
*MEAS_COND_AXIS_NAME-15 "長手制限スリット"
*MEAS_COND_AXIS_NAME-16 "センタースリット"
*MEAS_COND_AXIS_NAME-17 "フィルター"
*MEAS_COND_AXIS_NAME-18 "受光スリット1"
*MEAS_COND_AXIS_NAME-19 "受光スリット2"
*MEAS_COND_AXIS_NAME-20 "受光光学素子"
*MEAS_COND_AXIS_NAME-21 "受光平行スリット"
*MEAS_COND_AXIS_NAME-22 "調整用受光スリット"
*MEAS_COND_AXIS_NAME-23 ""
*MEAS_COND_AXIS_NAME-24 ""
*MEAS_COND_AXIS_NAME-25 "Zd"
*MEAS_COND_AXIS_NAME-26 "アッテネータ"
*MEAS_COND_AXIS_NAME-27 "検出器モノクロメータ"
*MEAS_COND_AXIS_NAME-28 "モノクロメータスリット"
*MEAS_COND_AXIS_NAME-29 "プライマリビーム"
*MEAS_COND_AXIS_NAME-30 "PHA"
*MEAS_COND_AXIS_NAME_INTERNAL-0 "TwoThetaTheta"
*MEAS_COND_AXIS_NAME_INTERNAL-1 "TwoTheta"
*MEAS_COND_AXIS_NAME_INTERNAL-2 "Omega"
*MEAS_COND_AXIS_NAME_INTERNAL-3 "Z"
*MEAS_COND_AXIS_NAME_INTERNAL-4 "TwoThetaOmega"
*MEAS_COND_AXIS_NAME_INTERNAL-5 "ThetaS"
*MEAS_COND_AXIS_NAME_INTERNAL-6 "ThetaD"
*MEAS_COND_AXIS_NAME_INTERNAL-7 "Ts"
*MEAS_COND_AXIS_NAME_INTERNAL-8 "CBO"
*MEAS_COND_AXIS_NAME_INTERNAL-9 "CBO-M"
*MEAS_COND_AXIS_NAME_INTERNAL-10 "IncidentSollerSlit"
*MEAS_COND_AXIS_NAME_INTERNAL-11 "IncidentSlitBox"
*MEAS_COND_AXIS_NAME_INTERNAL-12 "IncidentSlitBox-_Axis"
*MEAS_COND_AXIS_NAME_INTERNAL-13 "Zs"
*MEAS_COND_AXIS_NAME_INTERNAL-14 "IncidentMonochromator"
*MEAS_COND_AXIS_NAME_INTERNAL-15 "IncidentAxdSlit"
*MEAS_COND_AXIS_NAME_INTERNAL-16 "CenterSlit"
*MEAS_COND_AXIS_NAME_INTERNAL-17 "Filter"
*MEAS_COND_AXIS_NAME_INTERNAL-18 "ReceivingSlitBox1"
*MEAS_COND_AXIS_NAME_INTERNAL-19 "ReceivingSlitBox2"
*MEAS_COND_AXIS_NAME_INTERNAL-20 "ReceivingOptics"
*MEAS_COND_AXIS_NAME_INTERNAL-21 "ReceivingSollerSlit"
*MEAS_COND_AXIS_NAME_INTERNAL-22 "ReceivingAxdSlit"
*MEAS_COND_AXIS_NAME_INTERNAL-23 "ReceivingSlitBox1-_Axis"
*MEAS_COND_AXIS_NAME_INTERNAL-24 "ReceivingSlitBox2-_Axis"
*MEAS_COND_AXIS_NAME_INTERNAL-25 "ReceivingSlitBox2-Zd"
*MEAS_COND_AXIS_NAME_INTERNAL-26 "Attenuator"
*MEAS_COND_AXIS_NAME_INTERNAL-27 "CounterMonochromator"
*MEAS_COND_AXIS_NAME_INTERNAL-28 "CounterSlit"
*MEAS_COND_AXIS_NAME_INTERNAL-29 "IncidentPrimary"
*MEAS_COND_AXIS_NAME_INTERNAL-30 "PHA"
*MEAS_COND_AXIS_NAME_MAGICNO-0 "83951616.0000000000"
*MEAS_COND_AXIS_NAME_MAGICNO-1 "268632064.0000000000"
*MEAS_COND_AXIS_NAME_MAGICNO-2 "268500992.0000000000"
*MEAS_COND_AXIS_NAME_MAGICNO-3 "285278208.0000000000"
*MEAS_COND_AXIS_NAME_MAGICNO-4 "83951616.0000000000"
*MEAS_COND_AXIS_NAME_MAGICNO-5 "131072.0000000000"
*MEAS_COND_AXIS_NAME_MAGICNO-6 "131072.0000000000"
*MEAS_COND_AXIS_NAME_MAGICNO-7 "318898176.0000000000"
*MEAS_COND_AXIS_NAME_MAGICNO-8 "20971521.0000000000"
*MEAS_COND_AXIS_NAME_MAGICNO-9 "285343744.0000000000"
*MEAS_COND_AXIS_NAME_MAGICNO-10 "20971521.0000000000"
*MEAS_COND_AXIS_NAME_MAGICNO-11 "22020097.0000000000"
*MEAS_COND_AXIS_NAME_MAGICNO-12 "25165824.0000000000"
*MEAS_COND_AXIS_NAME_MAGICNO-13 "318898176.0000000000"
*MEAS_COND_AXIS_NAME_MAGICNO-14 "1.0000000000"
*MEAS_COND_AXIS_NAME_MAGICNO-15 "20971521.0000000000"
*MEAS_COND_AXIS_NAME_MAGICNO-16 "20971521.0000000000"
*MEAS_COND_AXIS_NAME_MAGICNO-17 "20971521.0000000000"
*MEAS_COND_AXIS_NAME_MAGICNO-18 "23068673.0000000000"
*MEAS_COND_AXIS_NAME_MAGICNO-19 "23068673.0000000000"
*MEAS_COND_AXIS_NAME_MAGICNO-20 "20971521.0000000000"
*MEAS_COND_AXIS_NAME_MAGICNO-21 "20971521.0000000000"
*MEAS_COND_AXIS_NAME_MAGICNO-22 "20971521.0000000000"
*MEAS_COND_AXIS_NAME_MAGICNO-23 "25165824.0000000000"
*MEAS_COND_AXIS_NAME_MAGICNO-24 "25165824.0000000000"
*MEAS_COND_AXIS_NAME_MAGICNO-25 "285343744.0000000000"
*MEAS_COND_AXIS_NAME_MAGICNO-26 "17301505.0000000000"
*MEAS_COND_AXIS_NAME_MAGICNO-27 "20971521.0000000000"
*MEAS_COND_AXIS_NAME_MAGICNO-28 "20971521.0000000000"
*MEAS_COND_AXIS_NAME_MAGICNO-29 "20971521.0000000000"
*MEAS_COND_AXIS_NAME_MAGICNO-30 "0.0000000000"
*MEAS_COND_AXIS_OFFSET-0 "-"
*MEAS_COND_AXIS_OFFSET-1 "-0.1081000000"
*MEAS_COND_AXIS_OFFSET-2 "0.3758000000"
*MEAS_COND_AXIS_OFFSET-3 "-"
*MEAS_COND_AXIS_OFFSET-4 "-"
*MEAS_COND_AXIS_OFFSET-5 "0.3758000000"
*MEAS_COND_AXIS_OFFSET-6 "-0.4839000000"
*MEAS_COND_AXIS_OFFSET-7 "-"
*MEAS_COND_AXIS_OFFSET-8 "-"
*MEAS_COND_AXIS_OFFSET-9 "-"
*MEAS_COND_AXIS_OFFSET-10 "-"
*MEAS_COND_AXIS_OFFSET-11 "-"
*MEAS_COND_AXIS_OFFSET-12 "-"
*MEAS_COND_AXIS_OFFSET-13 "-"
*MEAS_COND_AXIS_OFFSET-14 "-"
*MEAS_COND_AXIS_OFFSET-15 "-"
*MEAS_COND_AXIS_OFFSET-16 "-"
*MEAS_COND_AXIS_OFFSET-17 "-"
*MEAS_COND_AXIS_OFFSET-18 "-"
*MEAS_COND_AXIS_OFFSET-19 "-"
*MEAS_COND_AXIS_OFFSET-20 "-"
*MEAS_COND_AXIS_OFFSET-21 "-"
*MEAS_COND_AXIS_OFFSET-22 "-"
*MEAS_COND_AXIS_OFFSET-23 "-"
*MEAS_COND_AXIS_OFFSET-24 "-"
*MEAS_COND_AXIS_OFFSET-25 "-"
*MEAS_COND_AXIS_OFFSET-26 "-"
*MEAS_COND_AXIS_OFFSET-27 "-"
*MEAS_COND_AXIS_OFFSET-28 "-"
*MEAS_COND_AXIS_OFFSET-29 "-"
*MEAS_COND_AXIS_OFFSET-30 "-"
*MEAS_COND_AXIS_POSITION-0 "0.0000000000"
*MEAS_COND_AXIS_POSITION-1 "0.0000000000"
*MEAS_COND_AXIS_POSITION-2 "0.0000000000"
*MEAS_COND_AXIS_POSITION-3 "-0.5500000000"
*MEAS_COND_AXIS_POSITION-4 "0.0000000000"
*MEAS_COND_AXIS_POSITION-5 "0.0000000000"
*MEAS_COND_AXIS_POSITION-6 "0.0000000000"
*MEAS_COND_AXIS_POSITION-7 "-0.4278800000"
*MEAS_COND_AXIS_POSITION-8 "BB"
*MEAS_COND_AXIS_POSITION-9 "0.0000000000"
*MEAS_COND_AXIS_POSITION-10 "Soller_slit_5.0deg"
*MEAS_COND_AXIS_POSITION-11 "2/3deg"
*MEAS_COND_AXIS_POSITION-12 "2.2088000000"
*MEAS_COND_AXIS_POSITION-13 "-0.4140600000"
*MEAS_COND_AXIS_POSITION-14 "0.0000000000"
*MEAS_COND_AXIS_POSITION-15 "10.0mm"
*MEAS_COND_AXIS_POSITION-16 "None"
*MEAS_COND_AXIS_POSITION-17 "Cu_K-beta"
*MEAS_COND_AXIS_POSITION-18 "13.000mm"
*MEAS_COND_AXIS_POSITION-19 "13.000mm"
*MEAS_COND_AXIS_POSITION-20 "No_unit"
*MEAS_COND_AXIS_POSITION-21 "Soller_slit_5.0deg"
*MEAS_COND_AXIS_POSITION-22 "None"
*MEAS_COND_AXIS_POSITION-23 "13.0000000000"
*MEAS_COND_AXIS_POSITION-24 "13.0000000000"
*MEAS_COND_AXIS_POSITION-25 "0.0109400000"
*MEAS_COND_AXIS_POSITION-26 "Open"
*MEAS_COND_AXIS_POSITION-27 "None"
*MEAS_COND_AXIS_POSITION-28 "None"
*MEAS_COND_AXIS_POSITION-29 "None"
*MEAS_COND_AXIS_POSITION-30 "38.0000000000"
*MEAS_COND_AXIS_UNIT-0 "deg"
*MEAS_COND_AXIS_UNIT-1 "deg"
*MEAS_COND_AXIS_UNIT-2 "deg"
*MEAS_COND_AXIS_UNIT-3 "mm"
*MEAS_COND_AXIS_UNIT-4 "deg"
*MEAS_COND_AXIS_UNIT-5 "deg"
*MEAS_COND_AXIS_UNIT-6 "deg"
*MEAS_COND_AXIS_UNIT-7 "mm"
*MEAS_COND_AXIS_UNIT-8 ""
*MEAS_COND_AXIS_UNIT-9 "pulse"
*MEAS_COND_AXIS_UNIT-10 ""
*MEAS_COND_AXIS_UNIT-11 ""
*MEAS_COND_AXIS_UNIT-12 "mm"
*MEAS_COND_AXIS_UNIT-13 "mm"
*MEAS_COND_AXIS_UNIT-14 ""
*MEAS_COND_AXIS_UNIT-15 ""
*MEAS_COND_AXIS_UNIT-16 ""
*MEAS_COND_AXIS_UNIT-17 ""
*MEAS_COND_AXIS_UNIT-18 ""
*MEAS_COND_AXIS_UNIT-19 ""
*MEAS_COND_AXIS_UNIT-20 ""
*MEAS_COND_AXIS_UNIT-21 ""
*MEAS_COND_AXIS_UNIT-22 ""
*MEAS_COND_AXIS_UNIT-23 "mm"
*MEAS_COND_AXIS_UNIT-24 "mm"
*MEAS_COND_AXIS_UNIT-25 "mm"
*MEAS_COND_AXIS_UNIT-26 ""
*MEAS_COND_AXIS_UNIT-27 ""
*MEAS_COND_AXIS_UNIT-28 ""
*MEAS_COND_AXIS_UNIT-29 ""
*MEAS_COND_AXIS_UNIT-30 "div"
*MEAS_COND_COUNTER_CNTLOSS_CORR "0.0000000000"
*MEAS_COND_COUNTER_PHABASE "38.0000000000"
*MEAS_COND_COUNTER_PHAWINDOW "16.0000000000"
*MEAS_COND_COUNTER_PHA_UNIT "div"
*MEAS_COND_COUNTER_TAUDIFF "30.0000000000"
*MEAS_COND_COUNTER_TAUINT "0.0000000000"
*MEAS_COND_IRRADIATION_MODE "OFF"
*MEAS_COND_IRRADIATION_WIDTH ""
*MEAS_COND_OPT_ATTR "集中法"
*MEAS_COND_OPT_NAME "@集中法"
*MEAS_COND_UNSYMMETRIC_MODE "OFF"
*MEAS_COND_XG_CURRENT "30.0000000000"
*MEAS_COND_XG_VOLTAGE "40.0000000000"
*MEAS_COND_XG_WAVE_TYPE "Ka"
*MEAS_DATA_COUNT "5001.0000000000"
*MEAS_SCAN_AXIS_X "2θ/θ"
*MEAS_SCAN_AXIS_X_INTERNAL "TwoThetaTheta"
*MEAS_SCAN_END_TIME "07/08/21 17:04:09"
*MEAS_SCAN_MODE "CONTINUOUS"
*MEAS_SCAN_MONITOR "0"
*MEAS_SCAN_RESOLUTION_X "0.0002"
*MEAS_SCAN_SPEED "1.0"
*MEAS_SCAN_SPEED_UNIT "deg/min"
*MEAS_SCAN_START "20.0000000000"
*MEAS_SCAN_START_TIME "07/08/21 16:11:17"
*MEAS_SCAN_STEP "0.0100000000"
*MEAS_SCAN_STOP "70.0000000000"
*MEAS_SCAN_UNIT_X "deg"
*MEAS_SCAN_UNIT_Y "counts"
*RAS_HEADER_END
*RAS_INT_START
20.0000 1645.0000 1.0000
20.0400 1617.0000 1.0000
20.0800 1607.0000 1.0000
20.1200 1620.0000 1.0000
20.1600 1613.0000 1.0000
20.2000 1648.0000 1.0000
20.2400 1631.0000 1.0000
20.2800 1598.0000 1.0000
20.3200 1640.0000 1.0000
20.3600 1614.0000 1.0000
20.4000 1551.0000 1.0000
20.4400 1669.0000 1.0000
20.4800 1613.0000 1.0000
20.5200 1658.0000 1.0000
20.5600 1561.0000 1.0000
20.6000 1608.0000 1.0000
20.6400 1595.0000 1.0000
20.6800 1570.0000 1.0000
20.7200 1614.0000 1.0000
20.7600 1610.0000 1.0000
20.8000 1619.0000 1.0000
20.8400 1627.0000 1.0000
20.8800 1632.0000 1.0000
20.9200 1611.0000 1.0000
20.9600 1657.0000 1.0000
21.0000 1624.0000 1.0000
21.0400 1591.0000 1.0000
21.0800 1631.0000 1.0000
21.1200 1648.0000 1.0000
21.1600 1651.0000 1.0000
21.2000 1589.0000 1.0000
21.2400 1582.0000 1.0000
21.2800 1552.0000 1.0000
21.3200 1600.0000 1.0000
21.3600 1569.0000 1.0000
21.4000 1646.0000 1.0000
21.4400 1656.0000 1.0000
21.4800 1595.0000 1.0000
21.5200 1639.0000 1.0000
21.5600 1611.0000 1.0000
21.6000 1617.0000 1.0000
21.6400 1567.0000 1.0000
21.6800 1661.0000 1.0000
21.7200 1621.0000 1.0000
21.7600 1644.0000 1.0000
21.8000 1572.0000 1.0000
21.8400 1600.0000 1.0000
21.8800 1590.0000 1.0000
21.9200 1640.0000 1.0000
21.9600 1616.0000 1.0000
22.0000 1608.0000 1.0000
22.0400 1597.0000 1.0000
22.0800 1638.0000 1.0000
22.1200 1634.0000 1.0000
22.1600 1589.0000 1.0000
22.2000 1624.0000 1.0000
22.2400 1661.0000 1.0000
22.2800 1653.0000 1.0000
22.3200 1651.0000 1.0000
22.3600 1640.0000 1.0000
22.4000 1599.0000 1.0000
22.4400 1657.0000 1.0000
22.4800 1666.0000 1.0000
22.5200 1678.0000 1.0000
22.5600 1635.0000 1.0000
22.6000 1642.0000 1.0000
22.6400 1637.0000 1.0000
22.6800 1641.0000 1.0000
22.7200 1643.0000 1.0000
22.7600 1579.0000 1.0000
22.8000 1691.0000 1.0000
22.8400 1614.0000 1.0000
22.8800 1612.0000 1.0000
22.9200 1633.0000 1.0000
22.9600 1667.0000 1.0000
23.0000 1580.0000 1.0000
23.0400 1610.0000 1.0000
23.0800 1632.0000 1.0000
23.1200 1652.0000 1.0000
23.1600 1581.0000 1.0000
23.2000 1661.0000 1.0000
23.2400 1646.0000 1.0000
23.2800 1657.0000 1.0000
23.3200 1650.0000 1.0000
23.3600 1723.0000 1.0000
23.4000 1675.0000 1.0000
23.4400 1646.0000 1.0000
23.4800 1670.0000 1.0000
23.5200 1680.0000 1.0000
23.5600 1676.0000 1.0000
23.6000 1637.0000 1.0000
23.6400 1665.0000 1.0000
23.6800 1695.0000 1.0000
23.7200 1669.0000 1.0000
23.7600 1679.0000 1.0000
23.8000 1712.0000 1.0000
23.8400 1711.0000 1.0000
23.8800 1697.0000 1.0000
23.9200 1689.0000 1.0000
23.9600 1691.0000 1.0000
24.0000 1620.0000 1.0000
24.0400 1599.0000 1.0000
24.0800 1648.0000 1.0000
24.1200 1614.0000 1.0000
24.1600 1715.0000 1.0000
24.2000 1591.0000 1.0000
24.2400 1701.0000 1.0000
24.2800 1674.0000 1.0000
24.3200 1705.0000 1.0000
24.3600 1694.0000 1.0000
24.4000 1612.0000 1.0000
24.4400 1697.0000 1.0000
24.4800 1735.0000 1.0000
24.5200 1722.0000 1.0000
24.5600 1700.0000 1.0000
24.6000 1712.0000 1.0000
24.6400 1694.0000 1.0000
24.6800 1713.0000 1.0000
24.7200 1703.0000 1.0000
24.7600 1672.0000 1.0000
24.8000 1702.0000 1.0000
24.8400 1718.0000 1.0000
24.8800 1665.0000 1.0000
24.9200 1703.0000 1.0000
24.9600 1703.0000 1.0000
25.0000 1750.0000 1.0000
25.0400 1701.0000 1.0000
25.0800 1784.0000 1.0000
25.1200 1744.0000 1.0000
25.1600 1727.0000 1.0000
25.2000 1727.0000 1.0000
25.2400 1730.0000 1.0000
25.2800 1734.0000 1.0000
25.3200 1744.0000 1.0000
25.3600 1703.0000 1.0000
25.4000 1745.0000 1.0000
25.4400 1665.0000 1.0000
25.4800 1710.0000 1.0000
25.5200 1716.0000 1.0000
25.5600 1781.0000 1.0000
25.6000 1750.0000 1.0000
25.6400 1730.0000 1.0000
25.6800 1670.0000 1.0000
25.7200 1679.0000 1.0000
25.7600 1728.0000 1.0000
25.8000 1716.0000 1.0000
25.8400 1688.0000 1.0000
25.8800 1795.0000 1.0000
25.9200 1716.0000 1.0000
25.9600 1702.0000 1.0000
26.0000 1750.0000 1.0000
26.0400 1707.0000 1.0000
26.0800 1717.0000 1.0000
26.1200 1725.0000 1.0000
26.1600 1718.0000 1.0000
26.2000 1745.0000 1.0000
26.2400 1777.0000 1.0000
26.2800 1771.0000 1.0000
26.3200 1783.0000 1.0000
26.3600 1776.0000 1.0000
26.4000 1779.0000 1.0000
26.4400 1823.0000 1.0000
26.4800 1807.0000 1.0000
26.5200 1804.0000 1.0000
26.5600 1880.0000 1.0000
26.6000 1803.0000 1.0000
26.6400 1916.0000 1.0000
26.6800 1858.0000 1.0000
26.7200 1911.0000 1.0000
26.7600 1964.0000 1.0000
26.8000 1970.0000 1.0000
26.8400 2020.0000 1.0000
26.8800 2063.0000 1.0000
26.9200 2148.0000 1.0000
26.9600 2246.0000 1.0000
27.0000 2406.0000 1.0000
27.0400 2582.0000 1.0000
27.0800 2902.0000 1.0000
27.1200 3415.0000 1.0000
27.1600 4042.0000 1.0000
27.2000 4963.0000 1.0000
27.2400 6148.0000 1.0000
27.2800 7102.0000 1.0000
27.3200 6855.0000 1.0000
27.3600 5962.0000 1.0000
27.4000 4819.0000 1.0000
27.4400 3909.0000 1.0000
27.4800 3302.0000 1.0000
27.5200 2859.0000 1.0000
27.5600 2581.0000 1.0000
27.6000 2389.0000 1.0000
27.6400 2282.0000 1.0000
27.6800 2098.0000 1.0000
27.7200 2007.0000 1.0000
27.7600 2017.0000 1.0000
27.8000 1944.0000 1.0000
27.8400 1933.0000 1.0000
27.8800 1874.0000 1.0000
27.9200 1824.0000 1.0000
27.9600 1796.0000 1.0000
28.0000 1837.0000 1.0000
28.0400 1822.0000 1.0000
28.0800 1765.0000 1.0000
28.1200 1775.0000 1.0000
28.1600 1773.0000 1.0000
28.2000 1776.0000 1.0000
28.2400 1755.0000 1.0000
28.2800 1731.0000 1.0000
28.3200 1694.0000 1.0000
28.3600 1711.0000 1.0000
28.4000 1698.0000 1.0000
28.4400 1726.0000 1.0000
28.4800 1675.0000 1.0000
28.5200 1638.0000 1.0000
28.5600 1750.0000 1.0000
28.6000 1667.0000 1.0000
28.6400 1647.0000 1.0000
28.6800 1728.0000 1.0000
28.7200 1703.0000 1.0000
28.7600 1678.0000 1.0000
28.8000 1676.0000 1.0000
28.8400 1694.0000 1.0000
28.8800 1723.0000 1.0000
28.9200 1693.0000 1.0000
28.9600 1642.0000 1.0000
29.0000 1683.0000 1.0000
29.0400 1679.0000 1.0000
29.0800 1725.0000 1.0000
29.1200 1738.0000 1.0000
29.1600 1735.0000 1.0000
29.2000 1722.0000 1.0000
29.2400 1626.0000 1.0000
29.2800 1592.0000 1.0000
29.3200 1641.0000 1.0000
29.3600 1677.0000 1.0000
29.4000 1583.0000 1.0000
29.4400 1743.0000 1.0000
29.4800 1695.0000 1.0000
29.5200 1722.0000 1.0000
29.5600 1660.0000 1.0000
29.6000 1658.0000 1.0000
29.6400 1638.0000 1.0000
29.6800 1604.0000 1.0000
29.7200 1679.0000 1.0000
29.7600 1623.0000 1.0000
29.8000 1585.0000 1.0000
29.8400 1587.0000 1.0000
29.8800 1572.0000 1.0000
29.9200 1614.0000 1.0000
29.9600 1604.0000 1.0000
30.0000 1601.0000 1.0000
30.0400 1612.0000 1.0000
30.0800 1620.0000 1.0000
30.1200 1643.0000 1.0000
30.1600 1626.0000 1.0000
30.2000 1555.0000 1.0000
30.2400 1562.0000 1.0000
30.2800 1572.0000 1.0000
30.3200 1613.0000 1.0000
30.3600 1514.0000 1.0000
30.4000 1582.0000 1.0000
30.4400 1574.0000 1.0000
30.4800 1599.0000 1.0000
30.5200 1597.0000 1.0000
30.5600 1562.0000 1.0000
30.6000 1503.0000 1.0000
30.6400 1564.0000 1.0000
30.6800 1505.0000 1.0000
30.7200 1504.0000 1.0000
30.7600 1541.0000 1.0000
30.8000 1549.0000 1.0000
30.8400 1510.0000 1.0000
30.8800 1512.0000 1.0000
30.9200 1566.0000 1.0000
30.9600 1536.0000 1.0000
31.0000 1547.0000 1.0000
31.0400 1516.0000 1.0000
31.0800 1610.0000 1.0000
31.1200 1503.0000 1.0000
31.1600 1549.0000 1.0000
31.2000 1544.0000 1.0000
31.2400 1608.0000 1.0000
31.2800 1488.0000 1.0000
31.3200 1526.0000 1.0000
31.3600 1533.0000 1.0000
31.4000 1507.0000 1.0000
31.4400 1537.0000 1.0000
31.4800 1507.0000 1.0000
31.5200 1479.0000 1.0000
31.5600 1514.0000 1.0000
31.6000 1411.0000 1.0000
31.6400 1512.0000 1.0000
31.6800 1447.0000 1.0000
31.7200 1467.0000 1.0000
31.7600 1516.0000 1.0000
31.8000 1575.0000 1.0000
31.8400 1504.0000 1.0000
31.8800 1494.0000 1.0000
31.9200 1619.0000 1.0000
31.9600 1480.0000 1.0000
32.0000 1508.0000 1.0000
32.0400 1557.0000 1.0000
32.0800 1495.0000 1.0000
32.1200 1504.0000 1.0000
32.1600 1512.0000 1.0000
32.2000 1458.0000 1.0000
32.2400 1467.0000 1.0000
32.2800 1490.0000 1.0000
32.3200 1465.0000 1.0000
32.3600 1439.0000 1.0000
32.4000 1467.0000 1.0000
32.4400 1470.0000 1.0000
32.4800 1448.0000 1.0000
32.5200 1465.0000 1.0000
32.5600 1524.0000 1.0000
32.6000 1466.0000 1.0000
32.6400 1465.0000 1.0000
32.6800 1448.0000 1.0000
32.7200 1441.0000 1.0000
32.7600 1480.0000 1.0000
32.8000 1461.0000 1.0000
32.8400 1370.0000 1.0000
32.8800 1435.0000 1.0000
32.9200 1445.0000 1.0000
32.9600 1457.0000 1.0000
33.0000 1432.0000 1.0000
33.0400 1426.0000 1.0000
33.0800 1459.0000 1.0000
33.1200 1395.0000 1.0000
33.1600 1419.0000 1.0000
33.2000 1459.0000 1.0000
33.2400 1362.0000 1.0000
33.2800 1422.0000 1.0000
33.3200 1411.0000 1.0000
33.3600 1408.0000 1.0000
33.4000 1413.0000 1.0000
33.4400 1439.0000 1.0000
33.4800 1382.0000 1.0000
33.5200 1382.0000 1.0000
33.5600 1442.0000 1.0000
33.6000 1443.0000 1.0000
33.6400 1431.0000 1.0000
33.6800 1413.0000 1.0000
33.7200 1437.0000 1.0000
33.7600 1427.0000 1.0000
33.8000 1397.0000 1.0000
33.8400 1454.0000 1.0000
33.8800 1403.0000 1.0000
33.9200 1524.0000 1.0000
33.9600 1515.0000 1.0000
34.0000 1528.0000 1.0000
34.0400 1508.0000 1.0000
34.0800 1547.0000 1.0000
34.1200 1570.0000 1.0000
34.1600 1658.0000 1.0000
34.2000 1693.0000 1.0000
34.2400 1768.0000 1.0000
34.2800 1894.0000 1.0000
34.3200 2054.0000 1.0000
34.3600 2399.0000 1.0000
34.4000 2746.0000 1.0000
34.4400 3067.0000 1.0000
34.4800 3240.0000 1.0000
34.5200 3085.0000 1.0000
34.5600 2817.0000 1.0000
34.6000 2434.0000 1.0000
34.6400 2157.0000 1.0000
34.6800 1944.0000 1.0000
34.7200 1762.0000 1.0000
34.7600 1632.0000 1.0000
34.8000 1569.0000 1.0000
34.8400 1490.0000 1.0000
34.8800 1410.0000 1.0000
34.9200 1457.0000 1.0000
34.9600 1442.0000 1.0000
35.0000 1447.0000 1.0000
35.0400 1314.0000 1.0000
35.0800 1318.0000 1.0000
35.1200 1273.0000 1.0000
35.1600 1281.0000 1.0000
35.2000 1278.0000 1.0000
35.2400 1326.0000 1.0000
35.2800 1300.0000 1.0000
35.3200 1192.0000 1.0000
35.3600 1250.0000 1.0000
35.4000 1278.0000 1.0000
35.4400 1232.0000 1.0000
35.4800 1232.0000 1.0000
35.5200 1254.0000 1.0000
35.5600 1263.0000 1.0000
35.6000 1238.0000 1.0000
35.6400 1284.0000 1.0000
35.6800 1214.0000 1.0000
35.7200 1201.0000 1.0000
35.7600 1213.0000 1.0000
35.8000 1271.0000 1.0000
35.8400 1201.0000 1.0000
35.8800 1180.0000 1.0000
35.9200 1247.0000 1.0000
35.9600 1250.0000 1.0000
36.0000 1243.0000 1.0000
36.0400 1241.0000 1.0000
36.0800 1250.0000 1.0000
36.1200 1274.0000 1.0000
36.1600 1317.0000 1.0000
36.2000 1388.0000 1.0000
36.2400 1513.0000 1.0000
36.2800 1656.0000 1.0000
36.3200 1746.0000 1.0000
36.3600 1911.0000 1.0000
36.4000 1912.0000 1.0000
36.4400 1814.0000 1.0000
36.4800 1609.0000 1.0000
36.5200 1485.0000 1.0000
36.5600 1403.0000 1.0000
36.6000 1297.0000 1.0000
36.6400 1232.0000 1.0000
36.6800 1197.0000 1.0000
36.7200 1224.0000 1.0000
36.7600 1170.0000 1.0000
36.8000 1165.0000 1.0000
36.8400 1205.0000 1.0000
36.8800 1172.0000 1.0000
36.9200 1157.0000 1.0000
36.9600 1176.0000 1.0000
37.0000 1107.0000 1.0000
37.0400 1127.0000 1.0000
37.0800 1086.0000 1.0000
37.1200 1184.0000 1.0000
37.1600 1159.0000 1.0000
37.2000 1127.0000 1.0000
37.2400 1095.0000 1.0000
37.2800 1125.0000 1.0000
37.3200 1168.0000 1.0000
37.3600 1162.0000 1.0000
37.4000 1155.0000 1.0000
37.4400 1167.0000 1.0000
37.4800 1164.0000 1.0000
37.5200 1141.0000 1.0000
37.5600 1134.0000 1.0000
37.6000 1097.0000 1.0000
37.6400 1132.0000 1.0000
37.6800 1130.0000 1.0000
37.7200 1150.0000 1.0000
37.7600 1128.0000 1.0000
37.8000 1152.0000 1.0000
37.8400 1107.0000 1.0000
37.8800 1112.0000 1.0000
37.9200 1175.0000 1.0000
37.9600 1198.0000 1.0000
38.0000 1227.0000 1.0000
38.0400 1298.0000 1.0000
38.0800 1314.0000 1.0000
38.1200 1406.0000 1.0000
38.1600 1545.0000 1.0000
38.2000 1710.0000 1.0000
38.2400 1871.0000 1.0000
38.2800 2210.0000 1.0000
38.3200 2714.0000 1.0000
38.3600 3419.0000 1.0000
38.4000 4503.0000 1.0000
38.4400 6080.0000 1.0000
38.4800 7450.0000 1.0000
38.5200 8071.0000 1.0000
38.5600 7506.0000 1.0000
38.6000 6548.0000 1.0000
38.6400 5250.0000 1.0000
38.6800 4012.0000 1.0000
38.7200 3088.0000 1.0000
38.7600 2537.0000 1.0000
38.8000 2079.0000 1.0000
38.8400 1773.0000 1.0000
38.8800 1501.0000 1.0000
38.9200 1395.0000 1.0000
38.9600 1342.0000 1.0000
39.0000 1245.0000 1.0000
39.0400 1168.0000 1.0000
39.0800 1078.0000 1.0000
39.1200 1091.0000 1.0000
39.1600 1075.0000 1.0000
39.2000 1065.0000 1.0000
39.2400 1057.0000 1.0000
39.2800 1021.0000 1.0000
39.3200 1005.0000 1.0000
39.3600 998.0000 1.0000
39.4000 1054.0000 1.0000
39.4400 1069.0000 1.0000
39.4800 997.0000 1.0000
39.5200 1022.0000 1.0000
39.5600 1056.0000 1.0000
39.6000 1041.0000 1.0000
39.6400 1011.0000 1.0000
39.6800 1009.0000 1.0000
39.7200 1018.0000 1.0000
39.7600 954.0000 1.0000
39.8000 969.0000 1.0000
39.8400 968.0000 1.0000
39.8800 1018.0000 1.0000
39.9200 956.0000 1.0000
39.9600 910.0000 1.0000
40.0000 955.0000 1.0000
40.0400 912.0000 1.0000
40.0800 962.0000 1.0000
40.1200 907.0000 1.0000
40.1600 950.0000 1.0000
40.2000 893.0000 1.0000
40.2400 983.0000 1.0000
40.2800 876.0000 1.0000
40.3200 946.0000 1.0000
40.3600 1011.0000 1.0000
40.4000 878.0000 1.0000
40.4400 991.0000 1.0000
40.4800 951.0000 1.0000
40.5200 920.0000 1.0000
40.5600 869.0000 1.0000
40.6000 878.0000 1.0000
40.6400 951.0000 1.0000
40.6800 952.0000 1.0000
40.7200 912.0000 1.0000
40.7600 897.0000 1.0000
40.8000 885.0000 1.0000
40.8400 890.0000 1.0000
40.8800 940.0000 1.0000
40.9200 905.0000 1.0000
40.9600 940.0000 1.0000
41.0000 906.0000 1.0000
41.0400 948.0000 1.0000
41.0800 924.0000 1.0000
41.1200 940.0000 1.0000
41.1600 894.0000 1.0000
41.2000 942.0000 1.0000
41.2400 907.0000 1.0000
41.2800 920.0000 1.0000
41.3200 925.0000 1.0000
41.3600 928.0000 1.0000
41.4000 913.0000 1.0000
41.4400 917.0000 1.0000
41.4800 910.0000 1.0000
41.5200 936.0000 1.0000
41.5600 928.0000 1.0000
41.6000 873.0000 1.0000
41.6400 923.0000 1.0000
41.6800 921.0000 1.0000
41.7200 907.0000 1.0000
41.7600 885.0000 1.0000
41.8000 882.0000 1.0000
41.8400 941.0000 1.0000
41.8800 911.0000 1.0000
41.9200 869.0000 1.0000
41.9600 914.0000 1.0000
42.0000 847.0000 1.0000
42.0400 921.0000 1.0000
42.0800 918.0000 1.0000
42.1200 937.0000 1.0000
42.1600 915.0000 1.0000
42.2000 886.0000 1.0000
42.2400 916.0000 1.0000
42.2800 917.0000 1.0000
42.3200 902.0000 1.0000
42.3600 904.0000 1.0000
42.4000 895.0000 1.0000
42.4400 867.0000 1.0000
42.4800 893.0000 1.0000
42.5200 913.0000 1.0000
42.5600 875.0000 1.0000
42.6000 891.0000 1.0000
42.6400 899.0000 1.0000
42.6800 840.0000 1.0000
42.7200 907.0000 1.0000
42.7600 879.0000 1.0000
42.8000 855.0000 1.0000
42.8400 862.0000 1.0000
42.8800 936.0000 1.0000
42.9200 887.0000 1.0000
42.9600 900.0000 1.0000
43.0000 884.0000 1.0000
43.0400 923.0000 1.0000
43.0800 932.0000 1.0000
43.1200 971.0000 1.0000
43.1600 999.0000 1.0000
43.2000 994.0000 1.0000
43.2400 959.0000 1.0000
43.2800 986.0000 1.0000
43.3200 967.0000 1.0000
43.3600 972.0000 1.0000
43.4000 908.0000 1.0000
43.4400 888.0000 1.0000
43.4800 889.0000 1.0000
43.5200 907.0000 1.0000
43.5600 883.0000 1.0000
43.6000 888.0000 1.0000
43.6400 861.0000 1.0000
43.6800 816.0000 1.0000
43.7200 828.0000 1.0000
43.7600 878.0000 1.0000
43.8000 885.0000 1.0000
43.8400 840.0000 1.0000
43.8800 859.0000 1.0000
43.9200 880.0000 1.0000
43.9600 866.0000 1.0000
44.0000 889.0000 1.0000
44.0400 831.0000 1.0000
44.0800 877.0000 1.0000
44.1200 837.0000 1.0000
44.1600 887.0000 1.0000
44.2000 840.0000 1.0000
44.2400 829.0000 1.0000
44.2800 883.0000 1.0000
44.3200 847.0000 1.0000
44.3600 869.0000 1.0000
44.4000 856.0000 1.0000
44.4400 910.0000 1.0000
44.4800 825.0000 1.0000
44.5200 841.0000 1.0000
44.5600 827.0000 1.0000
44.6000 834.0000 1.0000
44.6400 847.0000 1.0000
44.6800 820.0000 1.0000
44.7200 891.0000 1.0000
44.7600 830.0000 1.0000
44.8000 835.0000 1.0000
44.8400 847.0000 1.0000
44.8800 848.0000 1.0000
44.9200 815.0000 1.0000
44.9600 827.0000 1.0000
45.0000 842.0000 1.0000
45.0400 854.0000 1.0000
45.0800 841.0000 1.0000
45.1200 827.0000 1.0000
45.1600 839.0000 1.0000
45.2000 848.0000 1.0000
45.2400 825.0000 1.0000
45.2800 838.0000 1.0000
45.3200 829.0000 1.0000
45.3600 820.0000 1.0000
45.4000 839.0000 1.0000
45.4400 843.0000 1.0000
45.4800 830.0000 1.0000
45.5200 799.0000 1.0000
45.5600 848.0000 1.0000
45.6000 861.0000 1.0000
45.6400 837.0000 1.0000
45.6800 809.0000 1.0000
45.7200 857.0000 1.0000
45.7600 844.0000 1.0000
45.8000 781.0000 1.0000
45.8400 831.0000 1.0000
45.8800 848.0000 1.0000
45.9200 772.0000 1.0000
45.9600 790.0000 1.0000
46.0000 796.0000 1.0000
46.0400 789.0000 1.0000
46.0800 859.0000 1.0000
46.1200 826.0000 1.0000
46.1600 847.0000 1.0000
46.2000 805.0000 1.0000
46.2400 790.0000 1.0000
46.2800 819.0000 1.0000
46.3200 784.0000 1.0000
46.3600 787.0000 1.0000
46.4000 777.0000 1.0000
46.4400 857.0000 1.0000
46.4800 801.0000 1.0000
46.5200 784.0000 1.0000
46.5600 836.0000 1.0000
46.6000 832.0000 1.0000
46.6400 805.0000 1.0000
46.6800 847.0000 1.0000
46.7200 834.0000 1.0000
46.7600 808.0000 1.0000
46.8000 754.0000 1.0000
46.8400 807.0000 1.0000
46.8800 785.0000 1.0000
46.9200 846.0000 1.0000
46.9600 827.0000 1.0000
47.0000 822.0000 1.0000
47.0400 832.0000 1.0000
47.0800 844.0000 1.0000
47.1200 807.0000 1.0000
47.1600 811.0000 1.0000
47.2000 777.0000 1.0000
47.2400 804.0000 1.0000
47.2800 788.0000 1.0000
47.3200 815.0000 1.0000
47.3600 803.0000 1.0000
47.4000 806.0000 1.0000
47.4400 783.0000 1.0000
47.4800 823.0000 1.0000
47.5200 746.0000 1.0000
47.5600 801.0000 1.0000
47.6000 798.0000 1.0000
47.6400 791.0000 1.0000
47.6800 814.0000 1.0000
47.7200 780.0000 1.0000
47.7600 756.0000 1.0000
47.8000 790.0000 1.0000
47.8400 769.0000 1.0000
47.8800 826.0000 1.0000
47.9200 739.0000 1.0000
47.9600 746.0000 1.0000
48.0000 782.0000 1.0000
48.0400 774.0000 1.0000
48.0800 759.0000 1.0000
48.1200 771.0000 1.0000
48.1600 765.0000 1.0000
48.2000 758.0000 1.0000
48.2400 769.0000 1.0000
48.2800 791.0000 1.0000
48.3200 767.0000 1.0000
48.3600 801.0000 1.0000
48.4000 810.0000 1.0000
48.4400 742.0000 1.0000
48.4800 738.0000 1.0000
48.5200 753.0000 1.0000
48.5600 772.0000 1.0000
48.6000 773.0000 1.0000
48.6400 786.0000 1.0000
48.6800 747.0000 1.0000
48.7200 769.0000 1.0000
48.7600 763.0000 1.0000
48.8000 749.0000 1.0000
48.8400 767.0000 1.0000
48.8800 762.0000 1.0000
48.9200 792.0000 1.0000
48.9600 765.0000 1.0000
49.0000 735.0000 1.0000
49.0400 757.0000 1.0000
49.0800 758.0000 1.0000
49.1200 768.0000 1.0000
49.1600 740.0000 1.0000
49.2000 763.0000 1.0000
49.2400 709.0000 1.0000
49.2800 726.0000 1.0000
49.3200 716.0000 1.0000
49.3600 785.0000 1.0000
49.4000 778.0000 1.0000
49.4400 747.0000 1.0000
49.4800 748.0000 1.0000
49.5200 752.0000 1.0000
49.5600 747.0000 1.0000
49.6000 768.0000 1.0000
49.6400 727.0000 1.0000
49.6800 747.0000 1.0000
49.7200 767.0000 1.0000
49.7600 736.0000 1.0000
49.8000 786.0000 1.0000
49.8400 745.0000 1.0000
49.8800 720.0000 1.0000
49.9200 750.0000 1.0000
49.9600 747.0000 1.0000
50.0000 713.0000 1.0000
50.0400 744.0000 1.0000
50.0800 718.0000 1.0000
50.1200 741.0000 1.0000
50.1600 741.0000 1.0000
50.2000 755.0000 1.0000
50.2400 766.0000 1.0000
50.2800 783.0000 1.0000
50.3200 742.0000 1.0000
50.3600 766.0000 1.0000
50.4000 765.0000 1.0000
50.4400 770.0000 1.0000
50.4800 737.0000 1.0000
50.5200 757.0000 1.0000
50.5600 767.0000 1.0000
50.6000 778.0000 1.0000
50.6400 767.0000 1.0000
50.6800 769.0000 1.0000
50.7200 755.0000 1.0000
50.7600 771.0000 1.0000
50.8000 802.0000 1.0000
50.8400 778.0000 1.0000
50.8800 757.0000 1.0000
50.9200 799.0000 1.0000
50.9600 762.0000 1.0000
51.0000 749.0000 1.0000
51.0400 779.0000 1.0000
51.0800 734.0000 1.0000
51.1200 770.0000 1.0000
51.1600 729.0000 1.0000
51.2000 758.0000 1.0000
51.2400 785.0000 1.0000
51.2800 761.0000 1.0000
51.3200 744.0000 1.0000
51.3600 761.0000 1.0000
51.4000 824.0000 1.0000
51.4400 776.0000 1.0000
51.4800 750.0000 1.0000
51.5200 781.0000 1.0000
51.5600 844.0000 1.0000
51.6000 840.0000 1.0000
51.6400 778.0000 1.0000
51.6800 800.0000 1.0000
51.7200 798.0000 1.0000
51.7600 828.0000 1.0000
51.8000 794.0000 1.0000
51.8400 896.0000 1.0000
51.8800 961.0000 1.0000
51.9200 1011.0000 1.0000
51.9600 1121.0000 1.0000
52.0000 1299.0000 1.0000
52.0400 1521.0000 1.0000
52.0800 1870.0000 1.0000
52.1200 2615.0000 1.0000
52.1600 3481.0000 1.0000
52.2000 4703.0000 1.0000
52.2400 5347.0000 1.0000
52.2800 4875.0000 1.0000
52.3200 4328.0000 1.0000
52.3600 4021.0000 1.0000
52.4000 3457.0000 1.0000
52.4400 2690.0000 1.0000
52.4800 2029.0000 1.0000
52.5200 1641.0000 1.0000
52.5600 1370.0000 1.0000
52.6000 1232.0000 1.0000
52.6400 1139.0000 1.0000
52.6800 1020.0000 1.0000
52.7200 918.0000 1.0000
52.7600 888.0000 1.0000
52.8000 876.0000 1.0000
52.8400 861.0000 1.0000
52.8800 809.0000 1.0000
52.9200 802.0000 1.0000
52.9600 816.0000 1.0000
53.0000 813.0000 1.0000
53.0400 801.0000 1.0000
53.0800 811.0000 1.0000
53.1200 796.0000 1.0000
53.1600 771.0000 1.0000
53.2000 743.0000 1.0000
53.2400 771.0000 1.0000
53.2800 813.0000 1.0000
53.3200 788.0000 1.0000
53.3600 726.0000 1.0000
53.4000 774.0000 1.0000
53.4400 726.0000 1.0000
53.4800 759.0000 1.0000
53.5200 758.0000 1.0000
53.5600 735.0000 1.0000
53.6000 712.0000 1.0000
53.6400 729.0000 1.0000
53.6800 738.0000 1.0000
53.7200 743.0000 1.0000
53.7600 785.0000 1.0000
53.8000 739.0000 1.0000
53.8400 749.0000 1.0000
53.8800 743.0000 1.0000
53.9200 726.0000 1.0000
53.9600 728.0000 1.0000
54.0000 734.0000 1.0000
54.0400 760.0000 1.0000
54.0800 729.0000 1.0000
54.1200 726.0000 1.0000
54.1600 738.0000 1.0000
54.2000 757.0000 1.0000
54.2400 697.0000 1.0000
54.2800 720.0000 1.0000
54.3200 725.0000 1.0000
54.3600 733.0000 1.0000
54.4000 758.0000 1.0000
54.4400 737.0000 1.0000
54.4800 698.0000 1.0000
54.5200 746.0000 1.0000
54.5600 780.0000 1.0000
54.6000 766.0000 1.0000
54.6400 751.0000 1.0000
54.6800 788.0000 1.0000
54.7200 757.0000 1.0000
54.7600 757.0000 1.0000
54.8000 753.0000 1.0000
54.8400 773.0000 1.0000
54.8800 782.0000 1.0000
54.9200 779.0000 1.0000
54.9600 791.0000 1.0000
55.0000 805.0000 1.0000
55.0400 848.0000 1.0000
55.0800 861.0000 1.0000
55.1200 909.0000 1.0000
55.1600 1005.0000 1.0000
55.2000 1099.0000 1.0000
55.2400 1151.0000 1.0000
55.2800 1122.0000 1.0000
55.3200 1145.0000 1.0000
55.3600 1129.0000 1.0000
55.4000 1046.0000 1.0000
55.4400 1047.0000 1.0000
55.4800 950.0000 1.0000
55.5200 874.0000 1.0000
55.5600 846.0000 1.0000
55.6000 796.0000 1.0000
55.6400 802.0000 1.0000
55.6800 814.0000 1.0000
55.7200 779.0000 1.0000
55.7600 762.0000 1.0000
55.8000 697.0000 1.0000
55.8400 743.0000 1.0000
55.8800 761.0000 1.0000
55.9200 748.0000 1.0000
55.9600 741.0000 1.0000
56.0000 758.0000 1.0000
56.0400 725.0000 1.0000
56.0800 727.0000 1.0000
56.1200 705.0000 1.0000
56.1600 760.0000 1.0000
56.2000 747.0000 1.0000
56.2400 718.0000 1.0000
56.2800 767.0000 1.0000
56.3200 753.0000 1.0000
56.3600 696.0000 1.0000
56.4000 694.0000 1.0000
56.4400 712.0000 1.0000
56.4800 718.0000 1.0000
56.5200 725.0000 1.0000
56.5600 702.0000 1.0000
56.6000 639.0000 1.0000
56.6400 766.0000 1.0000
56.6800 719.0000 1.0000
56.7200 703.0000 1.0000
56.7600 730.0000 1.0000
56.8000 706.0000 1.0000
56.8400 659.0000 1.0000
56.8800 679.0000 1.0000
56.9200 716.0000 1.0000
56.9600 718.0000 1.0000
57.0000 716.0000 1.0000
57.0400 740.0000 1.0000
57.0800 753.0000 1.0000
57.1200 715.0000 1.0000
57.1600 687.0000 1.0000
57.2000 720.0000 1.0000
57.2400 726.0000 1.0000
57.2800 733.0000 1.0000
57.3200 708.0000 1.0000
57.3600 697.0000 1.0000
57.4000 705.0000 1.0000
57.4400 770.0000 1.0000
57.4800 715.0000 1.0000
57.5200 746.0000 1.0000
57.5600 712.0000 1.0000
57.6000 750.0000 1.0000
57.6400 671.0000 1.0000
57.6800 719.0000 1.0000
57.7200 702.0000 1.0000
57.7600 699.0000 1.0000
57.8000 693.0000 1.0000
57.8400 705.0000 1.0000
57.8800 661.0000 1.0000
57.9200 704.0000 1.0000
57.9600 728.0000 1.0000
58.0000 686.0000 1.0000
58.0400 712.0000 1.0000
58.0800 677.0000 1.0000
58.1200 720.0000 1.0000
58.1600 691.0000 1.0000
58.2000 712.0000 1.0000
58.2400 661.0000 1.0000
58.2800 741.0000 1.0000
58.3200 699.0000 1.0000
58.3600 764.0000 1.0000
58.4000 715.0000 1.0000
58.4400 699.0000 1.0000
58.4800 713.0000 1.0000
58.5200 709.0000 1.0000
58.5600 713.0000 1.0000
58.6000 698.0000 1.0000
58.6400 718.0000 1.0000
58.6800 718.0000 1.0000
58.7200 680.0000 1.0000
58.7600 694.0000 1.0000
58.8000 705.0000 1.0000
58.8400 709.0000 1.0000
58.8800 719.0000 1.0000
58.9200 741.0000 1.0000
58.9600 694.0000 1.0000
59.0000 727.0000 1.0000
59.0400 703.0000 1.0000
59.0800 712.0000 1.0000
59.1200 727.0000 1.0000
59.1600 664.0000 1.0000
59.2000 709.0000 1.0000
59.2400 694.0000 1.0000
59.2800 692.0000 1.0000
59.3200 683.0000 1.0000
59.3600 699.0000 1.0000
59.4000 691.0000 1.0000
59.4400 732.0000 1.0000
59.4800 673.0000 1.0000
59.5200 689.0000 1.0000
59.5600 688.0000 1.0000
59.6000 667.0000 1.0000
59.6400 685.0000 1.0000
59.6800 726.0000 1.0000
59.7200 735.0000 1.0000
59.7600 686.0000 1.0000
59.8000 710.0000 1.0000
59.8400 675.0000 1.0000
59.8800 690.0000 1.0000
59.9200 717.0000 1.0000
59.9600 700.0000 1.0000
60.0000 666.0000 1.0000
60.0400 694.0000 1.0000
60.0800 710.0000 1.0000
60.1200 681.0000 1.0000
60.1600 730.0000 1.0000
60.2000 680.0000 1.0000
60.2400 683.0000 1.0000
60.2800 704.0000 1.0000
60.3200 690.0000 1.0000
60.3600 698.0000 1.0000
60.4000 728.0000 1.0000
60.4400 684.0000 1.0000
60.4800 704.0000 1.0000
60.5200 687.0000 1.0000
60.5600 744.0000 1.0000
60.6000 724.0000 1.0000
60.6400 716.0000 1.0000
60.6800 723.0000 1.0000
60.7200 767.0000 1.0000
60.7600 707.0000 1.0000
60.8000 734.0000 1.0000
60.8400 730.0000 1.0000
60.8800 683.0000 1.0000
60.9200 709.0000 1.0000
60.9600 728.0000 1.0000
61.0000 731.0000 1.0000
61.0400 691.0000 1.0000
61.0800 693.0000 1.0000
61.1200 704.0000 1.0000
61.1600 727.0000 1.0000
61.2000 681.0000 1.0000
61.2400 708.0000 1.0000
61.2800 666.0000 1.0000
61.3200 740.0000 1.0000
61.3600 701.0000 1.0000
61.4000 710.0000 1.0000
61.4400 716.0000 1.0000
61.4800 745.0000 1.0000
61.5200 763.0000 1.0000
61.5600 738.0000 1.0000
61.6000 758.0000 1.0000
61.6400 722.0000 1.0000
61.6800 740.0000 1.0000
61.7200 749.0000 1.0000
61.7600 788.0000 1.0000
61.8000 794.0000 1.0000
61.8400 786.0000 1.0000
61.8800 846.0000 1.0000
61.9200 858.0000 1.0000
61.9600 877.0000 1.0000
62.0000 927.0000 1.0000
62.0400 1089.0000 1.0000
62.0800 1127.0000 1.0000
62.1200 1289.0000 1.0000
62.1600 1526.0000 1.0000
62.2000 1658.0000 1.0000
62.2400 1704.0000 1.0000
62.2800 1757.0000 1.0000
62.3200 1763.0000 1.0000
62.3600 1650.0000 1.0000
62.4000 1615.0000 1.0000
62.4400 1525.0000 1.0000
62.4800 1459.0000 1.0000
62.5200 1239.0000 1.0000
62.5600 1148.0000 1.0000
62.6000 1084.0000 1.0000
62.6400 1042.0000 1.0000
62.6800 959.0000 1.0000
62.7200 910.0000 1.0000
62.7600 883.0000 1.0000
62.8000 834.0000 1.0000
62.8400 813.0000 1.0000
62.8800 797.0000 1.0000
62.9200 774.0000 1.0000
62.9600 768.0000 1.0000
63.0000 785.0000 1.0000
63.0400 779.0000 1.0000
63.0800 803.0000 1.0000
63.1200 745.0000 1.0000
63.1600 763.0000 1.0000
63.2000 728.0000 1.0000
63.2400 746.0000 1.0000
63.2800 765.0000 1.0000
63.3200 728.0000 1.0000
63.3600 731.0000 1.0000
63.4000 726.0000 1.0000
63.4400 718.0000 1.0000
63.4800 713.0000 1.0000
63.5200 732.0000 1.0000
63.5600 724.0000 1.0000
63.6000 701.0000 1.0000
63.6400 706.0000 1.0000
63.6800 691.0000 1.0000
63.7200 712.0000 1.0000
63.7600 680.0000 1.0000
63.8000 662.0000 1.0000
63.8400 711.0000 1.0000
63.8800 714.0000 1.0000
63.9200 740.0000 1.0000
63.9600 722.0000 1.0000
64.0000 698.0000 1.0000
64.0400 699.0000 1.0000
64.0800 703.0000 1.0000
64.1200 741.0000 1.0000
64.1600 705.0000 1.0000
64.2000 728.0000 1.0000
64.2400 733.0000 1.0000
64.2800 762.0000 1.0000
64.3200 738.0000 1.0000
64.3600 699.0000 1.0000
64.4000 762.0000 1.0000
64.4400 720.0000 1.0000
64.4800 751.0000 1.0000
64.5200 787.0000 1.0000
64.5600 826.0000 1.0000
64.6000 806.0000 1.0000
64.6400 806.0000 1.0000
64.6800 759.0000 1.0000
64.7200 816.0000 1.0000
64.7600 814.0000 1.0000
64.8000 794.0000 1.0000
64.8400 828.0000 1.0000
64.8800 771.0000 1.0000
64.9200 748.0000 1.0000
64.9600 776.0000 1.0000
65.0000 782.0000 1.0000
65.0400 785.0000 1.0000
65.0800 680.0000 1.0000
65.1200 784.0000 1.0000
65.1600 742.0000 1.0000
65.2000 764.0000 1.0000
65.2400 740.0000 1.0000
65.2800 729.0000 1.0000
65.3200 714.0000 1.0000
65.3600 697.0000 1.0000
65.4000 723.0000 1.0000
65.4400 747.0000 1.0000
65.4800 748.0000 1.0000
65.5200 745.0000 1.0000
65.5600 760.0000 1.0000
65.6000 790.0000 1.0000
65.6400 815.0000 1.0000
65.6800 773.0000 1.0000
65.7200 814.0000 1.0000
65.7600 829.0000 1.0000
65.8000 854.0000 1.0000
65.8400 917.0000 1.0000
65.8800 924.0000 1.0000
65.9200 935.0000 1.0000
65.9600 1044.0000 1.0000
66.0000 1233.0000 1.0000
66.0400 1330.0000 1.0000
66.0800 1638.0000 1.0000
66.1200 2059.0000 1.0000
66.1600 2491.0000 1.0000
66.2000 2779.0000 1.0000
66.2400 2755.0000 1.0000
66.2800 2619.0000 1.0000
66.3200 2437.0000 1.0000
66.3600 2403.0000 1.0000
66.4000 2277.0000 1.0000
66.4400 1990.0000 1.0000
66.4800 1639.0000 1.0000
66.5200 1432.0000 1.0000
66.5600 1292.0000 1.0000
66.6000 1097.0000 1.0000
66.6400 999.0000 1.0000
66.6800 928.0000 1.0000
66.7200 895.0000 1.0000
66.7600 801.0000 1.0000
66.8000 806.0000 1.0000
66.8400 793.0000 1.0000
66.8800 766.0000 1.0000
66.9200 759.0000 1.0000
66.9600 738.0000 1.0000
67.0000 684.0000 1.0000
67.0400 723.0000 1.0000
67.0800 711.0000 1.0000
67.1200 674.0000 1.0000
67.1600 710.0000 1.0000
67.2000 664.0000 1.0000
67.2400 662.0000 1.0000
67.2800 697.0000 1.0000
67.3200 669.0000 1.0000
67.3600 718.0000 1.0000
67.4000 649.0000 1.0000
67.4400 689.0000 1.0000
67.4800 644.0000 1.0000
67.5200 672.0000 1.0000
67.5600 671.0000 1.0000
67.6000 661.0000 1.0000
67.6400 694.0000 1.0000
67.6800 654.0000 1.0000
67.7200 669.0000 1.0000
67.7600 629.0000 1.0000
67.8000 668.0000 1.0000
67.8400 612.0000 1.0000
67.8800 612.0000 1.0000
67.9200 649.0000 1.0000
67.9600 628.0000 1.0000
68.0000 652.0000 1.0000
68.0400 638.0000 1.0000
68.0800 675.0000 1.0000
68.1200 609.0000 1.0000
68.1600 657.0000 1.0000
68.2000 626.0000 1.0000
68.2400 572.0000 1.0000
68.2800 641.0000 1.0000
68.3200 654.0000 1.0000
68.3600 625.0000 1.0000
68.4000 680.0000 1.0000
68.4400 666.0000 1.0000
68.4800 635.0000 1.0000
68.5200 660.0000 1.0000
68.5600 652.0000 1.0000
68.6000 645.0000 1.0000
68.6400 641.0000 1.0000
68.6800 612.0000 1.0000
68.7200 668.0000 1.0000
68.7600 663.0000 1.0000
68.8000 643.0000 1.0000
68.8400 597.0000 1.0000
68.8800 618.0000 1.0000
68.9200 617.0000 1.0000
68.9600 625.0000 1.0000
69.0000 610.0000 1.0000
69.0400 646.0000 1.0000
69.0800 608.0000 1.0000
69.1200 616.0000 1.0000
69.1600 630.0000 1.0000
69.2000 633.0000 1.0000
69.2400 621.0000 1.0000
69.2800 602.0000 1.0000
69.3200 643.0000 1.0000
69.3600 664.0000 1.0000
69.4000 592.0000 1.0000
69.4400 634.0000 1.0000
69.4800 617.0000 1.0000
69.5200 645.0000 1.0000
69.5600 662.0000 1.0000
69.6000 650.0000 1.0000
69.6400 607.0000 1.0000
69.6800 620.0000 1.0000
69.7200 626.0000 1.0000
69.7600 609.0000 1.0000
69.8000 609.0000 1.0000
69.8400 606.0000 1.0000
69.8800 603.0000 1.0000
69.9200 655.0000 1.0000
69.9600 577.0000 1.0000
70.0000 595.0000 1.0000
*RAS_INT_END
*RAS_TEMPERATURE_START
*RAS_TEMPERATURE_END
*RAS_DATA_END