File: Section2_75_samples/XRD/No_003_600_14.ras
*RAS_DATA_START
*RAS_HEADER_START
*DISP_FMT_X "%.2f"
*DISP_FMT_Y "%.0f"
*DISP_FULLSCALE "3846.0000000000"
*DISP_LINE_COLOR "255.0000000000"
*DISP_LINE_STYLE "0.0000000000"
*DISP_LINE_WIDTH "0.2500000000"
*DISP_NOTE "測定データ-5"
*DISP_OFFSET_Y "0.0000000000"
*DISP_PEAKSEARCH_UNIT_Y "cps"
*DISP_RANGE_BOTTOM "0.0000000000"
*DISP_RANGE_LEFT "20.0000000000"
*DISP_RANGE_LOGCUTOFF "0.0100000000"
*DISP_RANGE_RIGHT "80.0000000000"
*DISP_RANGE_TOP "3846.0000000000"
*DISP_SCALE_MODE_Y "0.0000000000"
*DISP_TAB_NAME "2θ/θ"
*DISP_TITLE_Y "強度"
*DISP_UNIT_Y "cps"
*DISP_WINDOW_NAME "MSG_MACROENGINE"
*FILE_COMMENT " "
*FILE_MD5 ""
*FILE_MEMO " "
*FILE_OPERATOR "Administrator"
*FILE_SAMPLE " "
*FILE_TYPE "RAS_RAW"
*FILE_USERGROUP "システムマネージャ"
*FILE_VERSION "1.0000000000"
*HW_ATTACHMENT_ID "ATT0025"
*HW_ATTACHMENT_NAME "標準|Standard"
*HW_COUNTER_ID-0 "CUT0025"
*HW_COUNTER_ID-1 "CUT0020"
*HW_COUNTER_ID-2 "CUT0020"
*HW_COUNTER_ID-3 "CSL0021"
*HW_COUNTER_ID-4 "CMC0021"
*HW_COUNTER_NAME-0 "D/teX Ultra|D/teX Ultra"
*HW_COUNTER_NAME-1 "None|None"
*HW_COUNTER_NAME-2 "None|None"
*HW_COUNTER_NAME-3 "BBM|BBM"
*HW_COUNTER_NAME-4 "検出器モノクロメータ|Detector monochromator"
*HW_COUNTER_SELECT_NAME "D/teX Ultra|D/teX Ultra"
*HW_GONIOMETER_ID "GON0023"
*HW_GONIOMETER_NAME "SmartLab|SmartLab"
*HW_GONIOMETER_RADIUS-0 "90.0"
*HW_GONIOMETER_RADIUS-1 "114.0"
*HW_GONIOMETER_RADIUS-2 "190.0"
*HW_GONIOMETER_RADIUS-3 "300.0"
*HW_GONIOMETER_RADIUS-4 "187.0"
*HW_GONIOMETER_RADIUS-5 "300.0"
*HW_GONIOMETER_RADIUS-6 "113.0"
*HW_GONIOMETER_RADIUS-7 "331.0"
*HW_I_OPT_ID-0 "CBO0021"
*HW_I_OPT_ID-1 "ICR0023"
*HW_I_OPT_ID-2 "ISL0021"
*HW_I_OPT_ID-3 "ISO0021"
*HW_I_OPT_ID-4 "IAD0021"
*HW_I_OPT_ID-5 "IPR0001"
*HW_I_OPT_NAME-0 "CBOユニット|CBO unit"
*HW_I_OPT_NAME-1 "標準入射光学ユニット|Standard incident optical unit"
*HW_I_OPT_NAME-2 "標準入射スリットボックス|Standard incident slit box"
*HW_I_OPT_NAME-3 "入射平行スリット|Incident parallel slit"
*HW_I_OPT_NAME-4 "長手制限スリット|Length limiting slit"
*HW_I_OPT_NAME-5 "None|None"
*HW_R_ATTENUATER_AUTOMODE "0"
*HW_R_OPT_ID-0 "RSS0021"
*HW_R_OPT_ID-1 "RCR0023"
*HW_R_OPT_ID-2 "RSO0021"
*HW_R_OPT_ID-3 "RRS0021"
*HW_R_OPT_ID-4 "ATN0021"
*HW_R_OPT_ID-5 "RFL0021"
*HW_R_OPT_ID-6 "RAD0021"
*HW_R_OPT_NAME-0 "標準受光スリットボックス1|Standard receiving slit box # 1"
*HW_R_OPT_NAME-1 "標準受光光学ユニット1|Standard receiving unit # 1"
*HW_R_OPT_NAME-2 "標準受光光学ユニット2|Standard receiving optical unit # 2"
*HW_R_OPT_NAME-3 "標準受光スリットボックス2|Standard receiving slit box # 2"
*HW_R_OPT_NAME-4 "標準アッテネータ|Standard Attenuator"
*HW_R_OPT_NAME-5 "Cu Kβ|Cu K-beta"
*HW_R_OPT_NAME-6 "調整用受光スリット|Alignment receiving slit"
*HW_SAMPLE_HOLDER_ID "SMP0023"
*HW_SAMPLE_HOLDER_NAME "標準Zステージ|Standard Z stage"
*HW_XG_CURRENT_MAX "50"
*HW_XG_CURRENT_MIN "2"
*HW_XG_CURRENT_RESOLUTION "2"
*HW_XG_CURRENT_UNIT "mA"
*HW_XG_FOCUS "1mm x 10mm"
*HW_XG_FOCUS_TYPE "Normal"
*HW_XG_ID ""
*HW_XG_NAME "3kW 封入管(ID:1200)|3kW Sealed tube(ID:1200)"
*HW_XG_TARGET_ATOMIC_NUMBER "29.0000000000"
*HW_XG_TARGET_NAME "Cu"
*HW_XG_TYPE "Hermetic"
*HW_XG_VOLTAGE_MAX "60"
*HW_XG_VOLTAGE_MIN "20"
*HW_XG_VOLTAGE_RESOLUTION "2"
*HW_XG_VOLTAGE_UNIT "kV"
*HW_XG_WATT_MAX "2"
*HW_XG_WATT_UNIT "kW"
*HW_XG_WAVE_LENGTH_ALPHA1 "1.540593"
*HW_XG_WAVE_LENGTH_ALPHA2 "1.544414"
*HW_XG_WAVE_LENGTH_BETA "1.392250"
*MEAS_COND_AXIS_NAME-0 "2θ/θ"
*MEAS_COND_AXIS_NAME-1 "2θ"
*MEAS_COND_AXIS_NAME-2 "ω"
*MEAS_COND_AXIS_NAME-3 "Z"
*MEAS_COND_AXIS_NAME-4 "2θ/ω"
*MEAS_COND_AXIS_NAME-5 "θs"
*MEAS_COND_AXIS_NAME-6 "θd"
*MEAS_COND_AXIS_NAME-7 "Ts"
*MEAS_COND_AXIS_NAME-8 "CBO選択スリット"
*MEAS_COND_AXIS_NAME-9 "M"
*MEAS_COND_AXIS_NAME-10 "入射平行スリット"
*MEAS_COND_AXIS_NAME-11 "入射スリット"
*MEAS_COND_AXIS_NAME-12 ""
*MEAS_COND_AXIS_NAME-13 "Zs"
*MEAS_COND_AXIS_NAME-14 "入射光学素子"
*MEAS_COND_AXIS_NAME-15 "長手制限スリット"
*MEAS_COND_AXIS_NAME-16 "センタースリット"
*MEAS_COND_AXIS_NAME-17 "フィルター"
*MEAS_COND_AXIS_NAME-18 "受光スリット1"
*MEAS_COND_AXIS_NAME-19 "受光スリット2"
*MEAS_COND_AXIS_NAME-20 "受光光学素子"
*MEAS_COND_AXIS_NAME-21 "受光平行スリット"
*MEAS_COND_AXIS_NAME-22 "調整用受光スリット"
*MEAS_COND_AXIS_NAME-23 ""
*MEAS_COND_AXIS_NAME-24 ""
*MEAS_COND_AXIS_NAME-25 "Zd"
*MEAS_COND_AXIS_NAME-26 "アッテネータ"
*MEAS_COND_AXIS_NAME-27 "検出器モノクロメータ"
*MEAS_COND_AXIS_NAME-28 "モノクロメータスリット"
*MEAS_COND_AXIS_NAME-29 "プライマリビーム"
*MEAS_COND_AXIS_NAME-30 "PHA"
*MEAS_COND_AXIS_NAME_INTERNAL-0 "TwoThetaTheta"
*MEAS_COND_AXIS_NAME_INTERNAL-1 "TwoTheta"
*MEAS_COND_AXIS_NAME_INTERNAL-2 "Omega"
*MEAS_COND_AXIS_NAME_INTERNAL-3 "Z"
*MEAS_COND_AXIS_NAME_INTERNAL-4 "TwoThetaOmega"
*MEAS_COND_AXIS_NAME_INTERNAL-5 "ThetaS"
*MEAS_COND_AXIS_NAME_INTERNAL-6 "ThetaD"
*MEAS_COND_AXIS_NAME_INTERNAL-7 "Ts"
*MEAS_COND_AXIS_NAME_INTERNAL-8 "CBO"
*MEAS_COND_AXIS_NAME_INTERNAL-9 "CBO-M"
*MEAS_COND_AXIS_NAME_INTERNAL-10 "IncidentSollerSlit"
*MEAS_COND_AXIS_NAME_INTERNAL-11 "IncidentSlitBox"
*MEAS_COND_AXIS_NAME_INTERNAL-12 "IncidentSlitBox-_Axis"
*MEAS_COND_AXIS_NAME_INTERNAL-13 "Zs"
*MEAS_COND_AXIS_NAME_INTERNAL-14 "IncidentMonochromator"
*MEAS_COND_AXIS_NAME_INTERNAL-15 "IncidentAxdSlit"
*MEAS_COND_AXIS_NAME_INTERNAL-16 "CenterSlit"
*MEAS_COND_AXIS_NAME_INTERNAL-17 "Filter"
*MEAS_COND_AXIS_NAME_INTERNAL-18 "ReceivingSlitBox1"
*MEAS_COND_AXIS_NAME_INTERNAL-19 "ReceivingSlitBox2"
*MEAS_COND_AXIS_NAME_INTERNAL-20 "ReceivingOptics"
*MEAS_COND_AXIS_NAME_INTERNAL-21 "ReceivingSollerSlit"
*MEAS_COND_AXIS_NAME_INTERNAL-22 "ReceivingAxdSlit"
*MEAS_COND_AXIS_NAME_INTERNAL-23 "ReceivingSlitBox1-_Axis"
*MEAS_COND_AXIS_NAME_INTERNAL-24 "ReceivingSlitBox2-_Axis"
*MEAS_COND_AXIS_NAME_INTERNAL-25 "ReceivingSlitBox2-Zd"
*MEAS_COND_AXIS_NAME_INTERNAL-26 "Attenuator"
*MEAS_COND_AXIS_NAME_INTERNAL-27 "CounterMonochromator"
*MEAS_COND_AXIS_NAME_INTERNAL-28 "CounterSlit"
*MEAS_COND_AXIS_NAME_INTERNAL-29 "IncidentPrimary"
*MEAS_COND_AXIS_NAME_INTERNAL-30 "PHA"
*MEAS_COND_AXIS_NAME_MAGICNO-0 "83951616.0000000000"
*MEAS_COND_AXIS_NAME_MAGICNO-1 "268632064.0000000000"
*MEAS_COND_AXIS_NAME_MAGICNO-2 "268500992.0000000000"
*MEAS_COND_AXIS_NAME_MAGICNO-3 "285278208.0000000000"
*MEAS_COND_AXIS_NAME_MAGICNO-4 "83951616.0000000000"
*MEAS_COND_AXIS_NAME_MAGICNO-5 "131072.0000000000"
*MEAS_COND_AXIS_NAME_MAGICNO-6 "131072.0000000000"
*MEAS_COND_AXIS_NAME_MAGICNO-7 "318898176.0000000000"
*MEAS_COND_AXIS_NAME_MAGICNO-8 "20971521.0000000000"
*MEAS_COND_AXIS_NAME_MAGICNO-9 "285343744.0000000000"
*MEAS_COND_AXIS_NAME_MAGICNO-10 "20971521.0000000000"
*MEAS_COND_AXIS_NAME_MAGICNO-11 "22020097.0000000000"
*MEAS_COND_AXIS_NAME_MAGICNO-12 "25165824.0000000000"
*MEAS_COND_AXIS_NAME_MAGICNO-13 "318898176.0000000000"
*MEAS_COND_AXIS_NAME_MAGICNO-14 "1.0000000000"
*MEAS_COND_AXIS_NAME_MAGICNO-15 "20971521.0000000000"
*MEAS_COND_AXIS_NAME_MAGICNO-16 "20971521.0000000000"
*MEAS_COND_AXIS_NAME_MAGICNO-17 "20971521.0000000000"
*MEAS_COND_AXIS_NAME_MAGICNO-18 "23068673.0000000000"
*MEAS_COND_AXIS_NAME_MAGICNO-19 "23068673.0000000000"
*MEAS_COND_AXIS_NAME_MAGICNO-20 "20971521.0000000000"
*MEAS_COND_AXIS_NAME_MAGICNO-21 "20971521.0000000000"
*MEAS_COND_AXIS_NAME_MAGICNO-22 "20971521.0000000000"
*MEAS_COND_AXIS_NAME_MAGICNO-23 "25165824.0000000000"
*MEAS_COND_AXIS_NAME_MAGICNO-24 "25165824.0000000000"
*MEAS_COND_AXIS_NAME_MAGICNO-25 "285343744.0000000000"
*MEAS_COND_AXIS_NAME_MAGICNO-26 "17301505.0000000000"
*MEAS_COND_AXIS_NAME_MAGICNO-27 "20971521.0000000000"
*MEAS_COND_AXIS_NAME_MAGICNO-28 "20971521.0000000000"
*MEAS_COND_AXIS_NAME_MAGICNO-29 "20971521.0000000000"
*MEAS_COND_AXIS_NAME_MAGICNO-30 "0.0000000000"
*MEAS_COND_AXIS_OFFSET-0 "-"
*MEAS_COND_AXIS_OFFSET-1 "-0.1081000000"
*MEAS_COND_AXIS_OFFSET-2 "0.3758000000"
*MEAS_COND_AXIS_OFFSET-3 "-"
*MEAS_COND_AXIS_OFFSET-4 "-"
*MEAS_COND_AXIS_OFFSET-5 "0.3758000000"
*MEAS_COND_AXIS_OFFSET-6 "-0.4839000000"
*MEAS_COND_AXIS_OFFSET-7 "-"
*MEAS_COND_AXIS_OFFSET-8 "-"
*MEAS_COND_AXIS_OFFSET-9 "-"
*MEAS_COND_AXIS_OFFSET-10 "-"
*MEAS_COND_AXIS_OFFSET-11 "-"
*MEAS_COND_AXIS_OFFSET-12 "-"
*MEAS_COND_AXIS_OFFSET-13 "-"
*MEAS_COND_AXIS_OFFSET-14 "-"
*MEAS_COND_AXIS_OFFSET-15 "-"
*MEAS_COND_AXIS_OFFSET-16 "-"
*MEAS_COND_AXIS_OFFSET-17 "-"
*MEAS_COND_AXIS_OFFSET-18 "-"
*MEAS_COND_AXIS_OFFSET-19 "-"
*MEAS_COND_AXIS_OFFSET-20 "-"
*MEAS_COND_AXIS_OFFSET-21 "-"
*MEAS_COND_AXIS_OFFSET-22 "-"
*MEAS_COND_AXIS_OFFSET-23 "-"
*MEAS_COND_AXIS_OFFSET-24 "-"
*MEAS_COND_AXIS_OFFSET-25 "-"
*MEAS_COND_AXIS_OFFSET-26 "-"
*MEAS_COND_AXIS_OFFSET-27 "-"
*MEAS_COND_AXIS_OFFSET-28 "-"
*MEAS_COND_AXIS_OFFSET-29 "-"
*MEAS_COND_AXIS_OFFSET-30 "-"
*MEAS_COND_AXIS_POSITION-0 "0.0000000000"
*MEAS_COND_AXIS_POSITION-1 "0.0000000000"
*MEAS_COND_AXIS_POSITION-2 "0.0000000000"
*MEAS_COND_AXIS_POSITION-3 "-0.5500000000"
*MEAS_COND_AXIS_POSITION-4 "0.0000000000"
*MEAS_COND_AXIS_POSITION-5 "0.0000000000"
*MEAS_COND_AXIS_POSITION-6 "0.0000000000"
*MEAS_COND_AXIS_POSITION-7 "-0.4278800000"
*MEAS_COND_AXIS_POSITION-8 "BB"
*MEAS_COND_AXIS_POSITION-9 "0.0000000000"
*MEAS_COND_AXIS_POSITION-10 "Soller_slit_5.0deg"
*MEAS_COND_AXIS_POSITION-11 "2/3deg"
*MEAS_COND_AXIS_POSITION-12 "2.2088000000"
*MEAS_COND_AXIS_POSITION-13 "-0.4140600000"
*MEAS_COND_AXIS_POSITION-14 "0.0000000000"
*MEAS_COND_AXIS_POSITION-15 "10.0mm"
*MEAS_COND_AXIS_POSITION-16 "None"
*MEAS_COND_AXIS_POSITION-17 "Cu_K-beta"
*MEAS_COND_AXIS_POSITION-18 "13.000mm"
*MEAS_COND_AXIS_POSITION-19 "13.000mm"
*MEAS_COND_AXIS_POSITION-20 "No_unit"
*MEAS_COND_AXIS_POSITION-21 "Soller_slit_5.0deg"
*MEAS_COND_AXIS_POSITION-22 "None"
*MEAS_COND_AXIS_POSITION-23 "13.0000000000"
*MEAS_COND_AXIS_POSITION-24 "13.0000000000"
*MEAS_COND_AXIS_POSITION-25 "0.0109400000"
*MEAS_COND_AXIS_POSITION-26 "Open"
*MEAS_COND_AXIS_POSITION-27 "None"
*MEAS_COND_AXIS_POSITION-28 "None"
*MEAS_COND_AXIS_POSITION-29 "None"
*MEAS_COND_AXIS_POSITION-30 "38.0000000000"
*MEAS_COND_AXIS_UNIT-0 "deg"
*MEAS_COND_AXIS_UNIT-1 "deg"
*MEAS_COND_AXIS_UNIT-2 "deg"
*MEAS_COND_AXIS_UNIT-3 "mm"
*MEAS_COND_AXIS_UNIT-4 "deg"
*MEAS_COND_AXIS_UNIT-5 "deg"
*MEAS_COND_AXIS_UNIT-6 "deg"
*MEAS_COND_AXIS_UNIT-7 "mm"
*MEAS_COND_AXIS_UNIT-8 ""
*MEAS_COND_AXIS_UNIT-9 "pulse"
*MEAS_COND_AXIS_UNIT-10 ""
*MEAS_COND_AXIS_UNIT-11 ""
*MEAS_COND_AXIS_UNIT-12 "mm"
*MEAS_COND_AXIS_UNIT-13 "mm"
*MEAS_COND_AXIS_UNIT-14 ""
*MEAS_COND_AXIS_UNIT-15 ""
*MEAS_COND_AXIS_UNIT-16 ""
*MEAS_COND_AXIS_UNIT-17 ""
*MEAS_COND_AXIS_UNIT-18 ""
*MEAS_COND_AXIS_UNIT-19 ""
*MEAS_COND_AXIS_UNIT-20 ""
*MEAS_COND_AXIS_UNIT-21 ""
*MEAS_COND_AXIS_UNIT-22 ""
*MEAS_COND_AXIS_UNIT-23 "mm"
*MEAS_COND_AXIS_UNIT-24 "mm"
*MEAS_COND_AXIS_UNIT-25 "mm"
*MEAS_COND_AXIS_UNIT-26 ""
*MEAS_COND_AXIS_UNIT-27 ""
*MEAS_COND_AXIS_UNIT-28 ""
*MEAS_COND_AXIS_UNIT-29 ""
*MEAS_COND_AXIS_UNIT-30 "div"
*MEAS_COND_COUNTER_CNTLOSS_CORR "0.0000000000"
*MEAS_COND_COUNTER_PHABASE "38.0000000000"
*MEAS_COND_COUNTER_PHAWINDOW "16.0000000000"
*MEAS_COND_COUNTER_PHA_UNIT "div"
*MEAS_COND_COUNTER_TAUDIFF "30.0000000000"
*MEAS_COND_COUNTER_TAUINT "0.0000000000"
*MEAS_COND_IRRADIATION_MODE "OFF"
*MEAS_COND_IRRADIATION_WIDTH ""
*MEAS_COND_OPT_ATTR "集中法"
*MEAS_COND_OPT_NAME "@集中法"
*MEAS_COND_UNSYMMETRIC_MODE "OFF"
*MEAS_COND_XG_CURRENT "30.0000000000"
*MEAS_COND_XG_VOLTAGE "40.0000000000"
*MEAS_COND_XG_WAVE_TYPE "Ka"
*MEAS_DATA_COUNT "3001.0000000000"
*MEAS_SCAN_AXIS_X "2θ/θ"
*MEAS_SCAN_AXIS_X_INTERNAL "TwoThetaTheta"
*MEAS_SCAN_END_TIME "08/27/20 13:40:33"
*MEAS_SCAN_MODE "CONTINUOUS"
*MEAS_SCAN_MONITOR "0"
*MEAS_SCAN_RESOLUTION_X "0.0002"
*MEAS_SCAN_SPEED "2.0"
*MEAS_SCAN_SPEED_UNIT "deg/min"
*MEAS_SCAN_START "20.0000000000"
*MEAS_SCAN_START_TIME "08/27/20 13:08:54"
*MEAS_SCAN_STEP "0.0200000000"
*MEAS_SCAN_STOP "80.0000000000"
*MEAS_SCAN_UNIT_X "deg"
*MEAS_SCAN_UNIT_Y "counts"
*RAS_HEADER_END
*RAS_INT_START
20.0000 1923.0000 1.0000
20.0600 1921.0000 1.0000
20.1200 1875.0000 1.0000
20.1800 1907.0000 1.0000
20.2400 1818.0000 1.0000
20.3000 1802.0000 1.0000
20.3600 1841.0000 1.0000
20.4200 1809.0000 1.0000
20.4800 1845.0000 1.0000
20.5400 1780.0000 1.0000
20.6000 1732.0000 1.0000
20.6600 1799.0000 1.0000
20.7200 1798.0000 1.0000
20.7800 1755.0000 1.0000
20.8400 1677.0000 1.0000
20.9000 1762.0000 1.0000
20.9600 1775.0000 1.0000
21.0200 1759.0000 1.0000
21.0800 1778.0000 1.0000
21.1400 1709.0000 1.0000
21.2000 1733.0000 1.0000
21.2600 1678.0000 1.0000
21.3200 1715.0000 1.0000
21.3800 1742.0000 1.0000
21.4400 1642.0000 1.0000
21.5000 1741.0000 1.0000
21.5600 1612.0000 1.0000
21.6200 1761.0000 1.0000
21.6800 1602.0000 1.0000
21.7400 1626.0000 1.0000
21.8000 1559.0000 1.0000
21.8600 1619.0000 1.0000
21.9200 1583.0000 1.0000
21.9800 1661.0000 1.0000
22.0400 1554.0000 1.0000
22.1000 1554.0000 1.0000
22.1600 1597.0000 1.0000
22.2200 1479.0000 1.0000
22.2800 1499.0000 1.0000
22.3400 1531.0000 1.0000
22.4000 1502.0000 1.0000
22.4600 1515.0000 1.0000
22.5200 1524.0000 1.0000
22.5800 1508.0000 1.0000
22.6400 1562.0000 1.0000
22.7000 1514.0000 1.0000
22.7600 1463.0000 1.0000
22.8200 1424.0000 1.0000
22.8800 1453.0000 1.0000
22.9400 1519.0000 1.0000
23.0000 1445.0000 1.0000
23.0600 1430.0000 1.0000
23.1200 1472.0000 1.0000
23.1800 1414.0000 1.0000
23.2400 1474.0000 1.0000
23.3000 1475.0000 1.0000
23.3600 1402.0000 1.0000
23.4200 1407.0000 1.0000
23.4800 1427.0000 1.0000
23.5400 1367.0000 1.0000
23.6000 1394.0000 1.0000
23.6600 1388.0000 1.0000
23.7200 1373.0000 1.0000
23.7800 1380.0000 1.0000
23.8400 1359.0000 1.0000
23.9000 1270.0000 1.0000
23.9600 1335.0000 1.0000
24.0200 1332.0000 1.0000
24.0800 1245.0000 1.0000
24.1400 1328.0000 1.0000
24.2000 1316.0000 1.0000
24.2600 1314.0000 1.0000
24.3200 1307.0000 1.0000
24.3800 1286.0000 1.0000
24.4400 1279.0000 1.0000
24.5000 1330.0000 1.0000
24.5600 1269.0000 1.0000
24.6200 1233.0000 1.0000
24.6800 1289.0000 1.0000
24.7400 1235.0000 1.0000
24.8000 1237.0000 1.0000
24.8600 1198.0000 1.0000
24.9200 1266.0000 1.0000
24.9800 1242.0000 1.0000
25.0400 1152.0000 1.0000
25.1000 1221.0000 1.0000
25.1600 1181.0000 1.0000
25.2200 1212.0000 1.0000
25.2800 1161.0000 1.0000
25.3400 1206.0000 1.0000
25.4000 1182.0000 1.0000
25.4600 1170.0000 1.0000
25.5200 1158.0000 1.0000
25.5800 1108.0000 1.0000
25.6400 1100.0000 1.0000
25.7000 1159.0000 1.0000
25.7600 1149.0000 1.0000
25.8200 1151.0000 1.0000
25.8800 1159.0000 1.0000
25.9400 1132.0000 1.0000
26.0000 1113.0000 1.0000
26.0600 1114.0000 1.0000
26.1200 1092.0000 1.0000
26.1800 1111.0000 1.0000
26.2400 1115.0000 1.0000
26.3000 1084.0000 1.0000
26.3600 1073.0000 1.0000
26.4200 1135.0000 1.0000
26.4800 1036.0000 1.0000
26.5400 1081.0000 1.0000
26.6000 1097.0000 1.0000
26.6600 1070.0000 1.0000
26.7200 1035.0000 1.0000
26.7800 986.0000 1.0000
26.8400 1067.0000 1.0000
26.9000 1060.0000 1.0000
26.9600 1064.0000 1.0000
27.0200 1034.0000 1.0000
27.0800 1030.0000 1.0000
27.1400 1004.0000 1.0000
27.2000 1016.0000 1.0000
27.2600 965.0000 1.0000
27.3200 1011.0000 1.0000
27.3800 1006.0000 1.0000
27.4400 1050.0000 1.0000
27.5000 1024.0000 1.0000
27.5600 1013.0000 1.0000
27.6200 1020.0000 1.0000
27.6800 985.0000 1.0000
27.7400 957.0000 1.0000
27.8000 954.0000 1.0000
27.8600 940.0000 1.0000
27.9200 959.0000 1.0000
27.9800 956.0000 1.0000
28.0400 944.0000 1.0000
28.1000 902.0000 1.0000
28.1600 935.0000 1.0000
28.2200 934.0000 1.0000
28.2800 882.0000 1.0000
28.3400 960.0000 1.0000
28.4000 882.0000 1.0000
28.4600 943.0000 1.0000
28.5200 985.0000 1.0000
28.5800 915.0000 1.0000
28.6400 872.0000 1.0000
28.7000 874.0000 1.0000
28.7600 876.0000 1.0000
28.8200 833.0000 1.0000
28.8800 866.0000 1.0000
28.9400 863.0000 1.0000
29.0000 819.0000 1.0000
29.0600 845.0000 1.0000
29.1200 856.0000 1.0000
29.1800 858.0000 1.0000
29.2400 919.0000 1.0000
29.3000 824.0000 1.0000
29.3600 808.0000 1.0000
29.4200 834.0000 1.0000
29.4800 819.0000 1.0000
29.5400 761.0000 1.0000
29.6000 839.0000 1.0000
29.6600 858.0000 1.0000
29.7200 769.0000 1.0000
29.7800 810.0000 1.0000
29.8400 763.0000 1.0000
29.9000 808.0000 1.0000
29.9600 761.0000 1.0000
30.0200 858.0000 1.0000
30.0800 822.0000 1.0000
30.1400 783.0000 1.0000
30.2000 774.0000 1.0000
30.2600 793.0000 1.0000
30.3200 795.0000 1.0000
30.3800 772.0000 1.0000
30.4400 747.0000 1.0000
30.5000 735.0000 1.0000
30.5600 776.0000 1.0000
30.6200 740.0000 1.0000
30.6800 759.0000 1.0000
30.7400 753.0000 1.0000
30.8000 759.0000 1.0000
30.8600 742.0000 1.0000
30.9200 733.0000 1.0000
30.9800 745.0000 1.0000
31.0400 765.0000 1.0000
31.1000 688.0000 1.0000
31.1600 732.0000 1.0000
31.2200 689.0000 1.0000
31.2800 690.0000 1.0000
31.3400 681.0000 1.0000
31.4000 769.0000 1.0000
31.4600 725.0000 1.0000
31.5200 739.0000 1.0000
31.5800 728.0000 1.0000
31.6400 734.0000 1.0000
31.7000 688.0000 1.0000
31.7600 698.0000 1.0000
31.8200 692.0000 1.0000
31.8800 694.0000 1.0000
31.9400 691.0000 1.0000
32.0000 691.0000 1.0000
32.0600 632.0000 1.0000
32.1200 648.0000 1.0000
32.1800 627.0000 1.0000
32.2400 647.0000 1.0000
32.3000 634.0000 1.0000
32.3600 618.0000 1.0000
32.4200 686.0000 1.0000
32.4800 679.0000 1.0000
32.5400 696.0000 1.0000
32.6000 657.0000 1.0000
32.6600 604.0000 1.0000
32.7200 643.0000 1.0000
32.7800 640.0000 1.0000
32.8400 678.0000 1.0000
32.9000 666.0000 1.0000
32.9600 606.0000 1.0000
33.0200 621.0000 1.0000
33.0800 617.0000 1.0000
33.1400 656.0000 1.0000
33.2000 627.0000 1.0000
33.2600 648.0000 1.0000
33.3200 619.0000 1.0000
33.3800 594.0000 1.0000
33.4400 562.0000 1.0000
33.5000 632.0000 1.0000
33.5600 588.0000 1.0000
33.6200 544.0000 1.0000
33.6800 579.0000 1.0000
33.7400 584.0000 1.0000
33.8000 590.0000 1.0000
33.8600 569.0000 1.0000
33.9200 600.0000 1.0000
33.9800 600.0000 1.0000
34.0400 540.0000 1.0000
34.1000 556.0000 1.0000
34.1600 620.0000 1.0000
34.2200 574.0000 1.0000
34.2800 554.0000 1.0000
34.3400 592.0000 1.0000
34.4000 626.0000 1.0000
34.4600 602.0000 1.0000
34.5200 618.0000 1.0000
34.5800 609.0000 1.0000
34.6400 564.0000 1.0000
34.7000 623.0000 1.0000
34.7600 600.0000 1.0000
34.8200 563.0000 1.0000
34.8800 555.0000 1.0000
34.9400 498.0000 1.0000
35.0000 519.0000 1.0000
35.0600 585.0000 1.0000
35.1200 558.0000 1.0000
35.1800 549.0000 1.0000
35.2400 562.0000 1.0000
35.3000 501.0000 1.0000
35.3600 544.0000 1.0000
35.4200 534.0000 1.0000
35.4800 539.0000 1.0000
35.5400 488.0000 1.0000
35.6000 481.0000 1.0000
35.6600 531.0000 1.0000
35.7200 477.0000 1.0000
35.7800 526.0000 1.0000
35.8400 487.0000 1.0000
35.9000 534.0000 1.0000
35.9600 504.0000 1.0000
36.0200 513.0000 1.0000
36.0800 493.0000 1.0000
36.1400 430.0000 1.0000
36.2000 466.0000 1.0000
36.2600 524.0000 1.0000
36.3200 474.0000 1.0000
36.3800 497.0000 1.0000
36.4400 498.0000 1.0000
36.5000 473.0000 1.0000
36.5600 486.0000 1.0000
36.6200 476.0000 1.0000
36.6800 490.0000 1.0000
36.7400 496.0000 1.0000
36.8000 479.0000 1.0000
36.8600 460.0000 1.0000
36.9200 477.0000 1.0000
36.9800 467.0000 1.0000
37.0400 457.0000 1.0000
37.1000 435.0000 1.0000
37.1600 442.0000 1.0000
37.2200 461.0000 1.0000
37.2800 486.0000 1.0000
37.3400 405.0000 1.0000
37.4000 447.0000 1.0000
37.4600 473.0000 1.0000
37.5200 426.0000 1.0000
37.5800 454.0000 1.0000
37.6400 471.0000 1.0000
37.7000 461.0000 1.0000
37.7600 417.0000 1.0000
37.8200 407.0000 1.0000
37.8800 451.0000 1.0000
37.9400 441.0000 1.0000
38.0000 381.0000 1.0000
38.0600 447.0000 1.0000
38.1200 418.0000 1.0000
38.1800 425.0000 1.0000
38.2400 413.0000 1.0000
38.3000 446.0000 1.0000
38.3600 456.0000 1.0000
38.4200 439.0000 1.0000
38.4800 492.0000 1.0000
38.5400 552.0000 1.0000
38.6000 593.0000 1.0000
38.6600 549.0000 1.0000
38.7200 572.0000 1.0000
38.7800 516.0000 1.0000
38.8400 431.0000 1.0000
38.9000 451.0000 1.0000
38.9600 397.0000 1.0000
39.0200 400.0000 1.0000
39.0800 420.0000 1.0000
39.1400 386.0000 1.0000
39.2000 354.0000 1.0000
39.2600 423.0000 1.0000
39.3200 409.0000 1.0000
39.3800 393.0000 1.0000
39.4400 387.0000 1.0000
39.5000 346.0000 1.0000
39.5600 383.0000 1.0000
39.6200 382.0000 1.0000
39.6800 387.0000 1.0000
39.7400 371.0000 1.0000
39.8000 375.0000 1.0000
39.8600 363.0000 1.0000
39.9200 332.0000 1.0000
39.9800 365.0000 1.0000
40.0400 374.0000 1.0000
40.1000 354.0000 1.0000
40.1600 371.0000 1.0000
40.2200 373.0000 1.0000
40.2800 355.0000 1.0000
40.3400 383.0000 1.0000
40.4000 378.0000 1.0000
40.4600 332.0000 1.0000
40.5200 339.0000 1.0000
40.5800 365.0000 1.0000
40.6400 364.0000 1.0000
40.7000 349.0000 1.0000
40.7600 337.0000 1.0000
40.8200 343.0000 1.0000
40.8800 378.0000 1.0000
40.9400 357.0000 1.0000
41.0000 315.0000 1.0000
41.0600 357.0000 1.0000
41.1200 337.0000 1.0000
41.1800 350.0000 1.0000
41.2400 315.0000 1.0000
41.3000 330.0000 1.0000
41.3600 337.0000 1.0000
41.4200 330.0000 1.0000
41.4800 360.0000 1.0000
41.5400 331.0000 1.0000
41.6000 309.0000 1.0000
41.6600 326.0000 1.0000
41.7200 316.0000 1.0000
41.7800 320.0000 1.0000
41.8400 350.0000 1.0000
41.9000 321.0000 1.0000
41.9600 374.0000 1.0000
42.0200 332.0000 1.0000
42.0800 359.0000 1.0000
42.1400 317.0000 1.0000
42.2000 334.0000 1.0000
42.2600 299.0000 1.0000
42.3200 309.0000 1.0000
42.3800 336.0000 1.0000
42.4400 340.0000 1.0000
42.5000 309.0000 1.0000
42.5600 319.0000 1.0000
42.6200 258.0000 1.0000
42.6800 282.0000 1.0000
42.7400 306.0000 1.0000
42.8000 320.0000 1.0000
42.8600 321.0000 1.0000
42.9200 311.0000 1.0000
42.9800 324.0000 1.0000
43.0400 286.0000 1.0000
43.1000 345.0000 1.0000
43.1600 312.0000 1.0000
43.2200 326.0000 1.0000
43.2800 307.0000 1.0000
43.3400 321.0000 1.0000
43.4000 304.0000 1.0000
43.4600 297.0000 1.0000
43.5200 299.0000 1.0000
43.5800 289.0000 1.0000
43.6400 303.0000 1.0000
43.7000 298.0000 1.0000
43.7600 305.0000 1.0000
43.8200 282.0000 1.0000
43.8800 297.0000 1.0000
43.9400 277.0000 1.0000
44.0000 313.0000 1.0000
44.0600 326.0000 1.0000
44.1200 283.0000 1.0000
44.1800 268.0000 1.0000
44.2400 277.0000 1.0000
44.3000 272.0000 1.0000
44.3600 307.0000 1.0000
44.4200 330.0000 1.0000
44.4800 299.0000 1.0000
44.5400 286.0000 1.0000
44.6000 260.0000 1.0000
44.6600 292.0000 1.0000
44.7200 290.0000 1.0000
44.7800 276.0000 1.0000
44.8400 286.0000 1.0000
44.9000 267.0000 1.0000
44.9600 285.0000 1.0000
45.0200 245.0000 1.0000
45.0800 276.0000 1.0000
45.1400 291.0000 1.0000
45.2000 251.0000 1.0000
45.2600 272.0000 1.0000
45.3200 248.0000 1.0000
45.3800 287.0000 1.0000
45.4400 261.0000 1.0000
45.5000 260.0000 1.0000
45.5600 283.0000 1.0000
45.6200 278.0000 1.0000
45.6800 257.0000 1.0000
45.7400 254.0000 1.0000
45.8000 275.0000 1.0000
45.8600 250.0000 1.0000
45.9200 268.0000 1.0000
45.9800 297.0000 1.0000
46.0400 277.0000 1.0000
46.1000 284.0000 1.0000
46.1600 260.0000 1.0000
46.2200 248.0000 1.0000
46.2800 253.0000 1.0000
46.3400 232.0000 1.0000
46.4000 248.0000 1.0000
46.4600 276.0000 1.0000
46.5200 249.0000 1.0000
46.5800 257.0000 1.0000
46.6400 250.0000 1.0000
46.7000 238.0000 1.0000
46.7600 264.0000 1.0000
46.8200 266.0000 1.0000
46.8800 239.0000 1.0000
46.9400 241.0000 1.0000
47.0000 228.0000 1.0000
47.0600 276.0000 1.0000
47.1200 257.0000 1.0000
47.1800 234.0000 1.0000
47.2400 246.0000 1.0000
47.3000 247.0000 1.0000
47.3600 260.0000 1.0000
47.4200 257.0000 1.0000
47.4800 229.0000 1.0000
47.5400 232.0000 1.0000
47.6000 222.0000 1.0000
47.6600 232.0000 1.0000
47.7200 245.0000 1.0000
47.7800 260.0000 1.0000
47.8400 225.0000 1.0000
47.9000 234.0000 1.0000
47.9600 227.0000 1.0000
48.0200 272.0000 1.0000
48.0800 249.0000 1.0000
48.1400 235.0000 1.0000
48.2000 241.0000 1.0000
48.2600 207.0000 1.0000
48.3200 213.0000 1.0000
48.3800 257.0000 1.0000
48.4400 233.0000 1.0000
48.5000 240.0000 1.0000
48.5600 254.0000 1.0000
48.6200 237.0000 1.0000
48.6800 248.0000 1.0000
48.7400 216.0000 1.0000
48.8000 237.0000 1.0000
48.8600 247.0000 1.0000
48.9200 226.0000 1.0000
48.9800 233.0000 1.0000
49.0400 227.0000 1.0000
49.1000 240.0000 1.0000
49.1600 226.0000 1.0000
49.2200 246.0000 1.0000
49.2800 229.0000 1.0000
49.3400 213.0000 1.0000
49.4000 225.0000 1.0000
49.4600 226.0000 1.0000
49.5200 196.0000 1.0000
49.5800 206.0000 1.0000
49.6400 220.0000 1.0000
49.7000 240.0000 1.0000
49.7600 227.0000 1.0000
49.8200 229.0000 1.0000
49.8800 225.0000 1.0000
49.9400 220.0000 1.0000
50.0000 221.0000 1.0000
50.0600 247.0000 1.0000
50.1200 224.0000 1.0000
50.1800 206.0000 1.0000
50.2400 241.0000 1.0000
50.3000 217.0000 1.0000
50.3600 227.0000 1.0000
50.4200 206.0000 1.0000
50.4800 205.0000 1.0000
50.5400 225.0000 1.0000
50.6000 225.0000 1.0000
50.6600 228.0000 1.0000
50.7200 206.0000 1.0000
50.7800 211.0000 1.0000
50.8400 228.0000 1.0000
50.9000 209.0000 1.0000
50.9600 219.0000 1.0000
51.0200 219.0000 1.0000
51.0800 216.0000 1.0000
51.1400 216.0000 1.0000
51.2000 234.0000 1.0000
51.2600 217.0000 1.0000
51.3200 205.0000 1.0000
51.3800 198.0000 1.0000
51.4400 216.0000 1.0000
51.5000 251.0000 1.0000
51.5600 226.0000 1.0000
51.6200 221.0000 1.0000
51.6800 227.0000 1.0000
51.7400 184.0000 1.0000
51.8000 209.0000 1.0000
51.8600 245.0000 1.0000
51.9200 244.0000 1.0000
51.9800 213.0000 1.0000
52.0400 235.0000 1.0000
52.1000 248.0000 1.0000
52.1600 293.0000 1.0000
52.2200 373.0000 1.0000
52.2800 523.0000 1.0000
52.3400 658.0000 1.0000
52.4000 639.0000 1.0000
52.4600 564.0000 1.0000
52.5200 475.0000 1.0000
52.5800 350.0000 1.0000
52.6400 302.0000 1.0000
52.7000 263.0000 1.0000
52.7600 232.0000 1.0000
52.8200 251.0000 1.0000
52.8800 245.0000 1.0000
52.9400 239.0000 1.0000
53.0000 208.0000 1.0000
53.0600 228.0000 1.0000
53.1200 212.0000 1.0000
53.1800 232.0000 1.0000
53.2400 202.0000 1.0000
53.3000 209.0000 1.0000
53.3600 201.0000 1.0000
53.4200 200.0000 1.0000
53.4800 230.0000 1.0000
53.5400 207.0000 1.0000
53.6000 196.0000 1.0000
53.6600 197.0000 1.0000
53.7200 206.0000 1.0000
53.7800 205.0000 1.0000
53.8400 206.0000 1.0000
53.9000 193.0000 1.0000
53.9600 194.0000 1.0000
54.0200 208.0000 1.0000
54.0800 194.0000 1.0000
54.1400 215.0000 1.0000
54.2000 198.0000 1.0000
54.2600 181.0000 1.0000
54.3200 191.0000 1.0000
54.3800 197.0000 1.0000
54.4400 195.0000 1.0000
54.5000 186.0000 1.0000
54.5600 198.0000 1.0000
54.6200 198.0000 1.0000
54.6800 174.0000 1.0000
54.7400 203.0000 1.0000
54.8000 201.0000 1.0000
54.8600 179.0000 1.0000
54.9200 192.0000 1.0000
54.9800 198.0000 1.0000
55.0400 220.0000 1.0000
55.1000 223.0000 1.0000
55.1600 228.0000 1.0000
55.2200 232.0000 1.0000
55.2800 225.0000 1.0000
55.3400 261.0000 1.0000
55.4000 235.0000 1.0000
55.4600 241.0000 1.0000
55.5200 244.0000 1.0000
55.5800 206.0000 1.0000
55.6400 193.0000 1.0000
55.7000 210.0000 1.0000
55.7600 189.0000 1.0000
55.8200 231.0000 1.0000
55.8800 220.0000 1.0000
55.9400 181.0000 1.0000
56.0000 186.0000 1.0000
56.0600 231.0000 1.0000
56.1200 207.0000 1.0000
56.1800 194.0000 1.0000
56.2400 191.0000 1.0000
56.3000 179.0000 1.0000
56.3600 205.0000 1.0000
56.4200 192.0000 1.0000
56.4800 199.0000 1.0000
56.5400 217.0000 1.0000
56.6000 189.0000 1.0000
56.6600 189.0000 1.0000
56.7200 179.0000 1.0000
56.7800 181.0000 1.0000
56.8400 161.0000 1.0000
56.9000 207.0000 1.0000
56.9600 188.0000 1.0000
57.0200 195.0000 1.0000
57.0800 216.0000 1.0000
57.1400 194.0000 1.0000
57.2000 178.0000 1.0000
57.2600 202.0000 1.0000
57.3200 191.0000 1.0000
57.3800 171.0000 1.0000
57.4400 177.0000 1.0000
57.5000 182.0000 1.0000
57.5600 209.0000 1.0000
57.6200 187.0000 1.0000
57.6800 195.0000 1.0000
57.7400 174.0000 1.0000
57.8000 211.0000 1.0000
57.8600 201.0000 1.0000
57.9200 184.0000 1.0000
57.9800 172.0000 1.0000
58.0400 189.0000 1.0000
58.1000 198.0000 1.0000
58.1600 196.0000 1.0000
58.2200 181.0000 1.0000
58.2800 179.0000 1.0000
58.3400 178.0000 1.0000
58.4000 206.0000 1.0000
58.4600 189.0000 1.0000
58.5200 168.0000 1.0000
58.5800 193.0000 1.0000
58.6400 204.0000 1.0000
58.7000 184.0000 1.0000
58.7600 189.0000 1.0000
58.8200 215.0000 1.0000
58.8800 195.0000 1.0000
58.9400 184.0000 1.0000
59.0000 190.0000 1.0000
59.0600 195.0000 1.0000
59.1200 209.0000 1.0000
59.1800 203.0000 1.0000
59.2400 176.0000 1.0000
59.3000 198.0000 1.0000
59.3600 192.0000 1.0000
59.4200 165.0000 1.0000
59.4800 173.0000 1.0000
59.5400 176.0000 1.0000
59.6000 176.0000 1.0000
59.6600 176.0000 1.0000
59.7200 179.0000 1.0000
59.7800 184.0000 1.0000
59.8400 167.0000 1.0000
59.9000 177.0000 1.0000
59.9600 194.0000 1.0000
60.0200 189.0000 1.0000
60.0800 180.0000 1.0000
60.1400 187.0000 1.0000
60.2000 200.0000 1.0000
60.2600 183.0000 1.0000
60.3200 167.0000 1.0000
60.3800 161.0000 1.0000
60.4400 190.0000 1.0000
60.5000 168.0000 1.0000
60.5600 173.0000 1.0000
60.6200 175.0000 1.0000
60.6800 167.0000 1.0000
60.7400 193.0000 1.0000
60.8000 177.0000 1.0000
60.8600 178.0000 1.0000
60.9200 191.0000 1.0000
60.9800 183.0000 1.0000
61.0400 172.0000 1.0000
61.1000 158.0000 1.0000
61.1600 200.0000 1.0000
61.2200 186.0000 1.0000
61.2800 177.0000 1.0000
61.3400 193.0000 1.0000
61.4000 182.0000 1.0000
61.4600 179.0000 1.0000
61.5200 182.0000 1.0000
61.5800 188.0000 1.0000
61.6400 189.0000 1.0000
61.7000 187.0000 1.0000
61.7600 212.0000 1.0000
61.8200 193.0000 1.0000
61.8800 188.0000 1.0000
61.9400 199.0000 1.0000
62.0000 180.0000 1.0000
62.0600 175.0000 1.0000
62.1200 206.0000 1.0000
62.1800 251.0000 1.0000
62.2400 262.0000 1.0000
62.3000 315.0000 1.0000
62.3600 314.0000 1.0000
62.4200 281.0000 1.0000
62.4800 333.0000 1.0000
62.5400 272.0000 1.0000
62.6000 239.0000 1.0000
62.6600 238.0000 1.0000
62.7200 214.0000 1.0000
62.7800 184.0000 1.0000
62.8400 222.0000 1.0000
62.9000 196.0000 1.0000
62.9600 184.0000 1.0000
63.0200 209.0000 1.0000
63.0800 196.0000 1.0000
63.1400 179.0000 1.0000
63.2000 189.0000 1.0000
63.2600 213.0000 1.0000
63.3200 193.0000 1.0000
63.3800 196.0000 1.0000
63.4400 170.0000 1.0000
63.5000 188.0000 1.0000
63.5600 203.0000 1.0000
63.6200 179.0000 1.0000
63.6800 184.0000 1.0000
63.7400 193.0000 1.0000
63.8000 192.0000 1.0000
63.8600 175.0000 1.0000
63.9200 166.0000 1.0000
63.9800 191.0000 1.0000
64.0400 195.0000 1.0000
64.1000 181.0000 1.0000
64.1600 178.0000 1.0000
64.2200 193.0000 1.0000
64.2800 163.0000 1.0000
64.3400 176.0000 1.0000
64.4000 198.0000 1.0000
64.4600 207.0000 1.0000
64.5200 191.0000 1.0000
64.5800 197.0000 1.0000
64.6400 188.0000 1.0000
64.7000 205.0000 1.0000
64.7600 226.0000 1.0000
64.8200 241.0000 1.0000
64.8800 208.0000 1.0000
64.9400 219.0000 1.0000
65.0000 208.0000 1.0000
65.0600 200.0000 1.0000
65.1200 175.0000 1.0000
65.1800 204.0000 1.0000
65.2400 183.0000 1.0000
65.3000 212.0000 1.0000
65.3600 194.0000 1.0000
65.4200 213.0000 1.0000
65.4800 194.0000 1.0000
65.5400 186.0000 1.0000
65.6000 208.0000 1.0000
65.6600 195.0000 1.0000
65.7200 191.0000 1.0000
65.7800 213.0000 1.0000
65.8400 200.0000 1.0000
65.9000 206.0000 1.0000
65.9600 203.0000 1.0000
66.0200 214.0000 1.0000
66.0800 251.0000 1.0000
66.1400 285.0000 1.0000
66.2000 342.0000 1.0000
66.2600 442.0000 1.0000
66.3200 485.0000 1.0000
66.3800 476.0000 1.0000
66.4400 457.0000 1.0000
66.5000 445.0000 1.0000
66.5600 380.0000 1.0000
66.6200 315.0000 1.0000
66.6800 256.0000 1.0000
66.7400 224.0000 1.0000
66.8000 201.0000 1.0000
66.8600 205.0000 1.0000
66.9200 195.0000 1.0000
66.9800 198.0000 1.0000
67.0400 206.0000 1.0000
67.1000 210.0000 1.0000
67.1600 175.0000 1.0000
67.2200 179.0000 1.0000
67.2800 164.0000 1.0000
67.3400 196.0000 1.0000
67.4000 165.0000 1.0000
67.4600 193.0000 1.0000
67.5200 186.0000 1.0000
67.5800 184.0000 1.0000
67.6400 154.0000 1.0000
67.7000 155.0000 1.0000
67.7600 171.0000 1.0000
67.8200 180.0000 1.0000
67.8800 169.0000 1.0000
67.9400 192.0000 1.0000
68.0000 179.0000 1.0000
68.0600 161.0000 1.0000
68.1200 166.0000 1.0000
68.1800 142.0000 1.0000
68.2400 174.0000 1.0000
68.3000 159.0000 1.0000
68.3600 174.0000 1.0000
68.4200 178.0000 1.0000
68.4800 183.0000 1.0000
68.5400 161.0000 1.0000
68.6000 154.0000 1.0000
68.6600 191.0000 1.0000
68.7200 188.0000 1.0000
68.7800 169.0000 1.0000
68.8400 174.0000 1.0000
68.9000 183.0000 1.0000
68.9600 171.0000 1.0000
69.0200 182.0000 1.0000
69.0800 161.0000 1.0000
69.1400 181.0000 1.0000
69.2000 171.0000 1.0000
69.2600 191.0000 1.0000
69.3200 177.0000 1.0000
69.3800 177.0000 1.0000
69.4400 171.0000 1.0000
69.5000 148.0000 1.0000
69.5600 171.0000 1.0000
69.6200 189.0000 1.0000
69.6800 172.0000 1.0000
69.7400 176.0000 1.0000
69.8000 179.0000 1.0000
69.8600 166.0000 1.0000
69.9200 185.0000 1.0000
69.9800 162.0000 1.0000
70.0400 180.0000 1.0000
70.1000 174.0000 1.0000
70.1600 185.0000 1.0000
70.2200 180.0000 1.0000
70.2800 178.0000 1.0000
70.3400 183.0000 1.0000
70.4000 171.0000 1.0000
70.4600 171.0000 1.0000
70.5200 192.0000 1.0000
70.5800 180.0000 1.0000
70.6400 165.0000 1.0000
70.7000 159.0000 1.0000
70.7600 150.0000 1.0000
70.8200 178.0000 1.0000
70.8800 174.0000 1.0000
70.9400 191.0000 1.0000
71.0000 171.0000 1.0000
71.0600 164.0000 1.0000
71.1200 186.0000 1.0000
71.1800 159.0000 1.0000
71.2400 200.0000 1.0000
71.3000 169.0000 1.0000
71.3600 169.0000 1.0000
71.4200 163.0000 1.0000
71.4800 221.0000 1.0000
71.5400 186.0000 1.0000
71.6000 168.0000 1.0000
71.6600 195.0000 1.0000
71.7200 185.0000 1.0000
71.7800 197.0000 1.0000
71.8400 185.0000 1.0000
71.9000 180.0000 1.0000
71.9600 174.0000 1.0000
72.0200 169.0000 1.0000
72.0800 175.0000 1.0000
72.1400 179.0000 1.0000
72.2000 186.0000 1.0000
72.2600 173.0000 1.0000
72.3200 178.0000 1.0000
72.3800 169.0000 1.0000
72.4400 165.0000 1.0000
72.5000 155.0000 1.0000
72.5600 172.0000 1.0000
72.6200 192.0000 1.0000
72.6800 180.0000 1.0000
72.7400 173.0000 1.0000
72.8000 163.0000 1.0000
72.8600 161.0000 1.0000
72.9200 171.0000 1.0000
72.9800 174.0000 1.0000
73.0400 180.0000 1.0000
73.1000 158.0000 1.0000
73.1600 167.0000 1.0000
73.2200 180.0000 1.0000
73.2800 175.0000 1.0000
73.3400 184.0000 1.0000
73.4000 144.0000 1.0000
73.4600 153.0000 1.0000
73.5200 164.0000 1.0000
73.5800 158.0000 1.0000
73.6400 174.0000 1.0000
73.7000 152.0000 1.0000
73.7600 179.0000 1.0000
73.8200 187.0000 1.0000
73.8800 150.0000 1.0000
73.9400 163.0000 1.0000
74.0000 162.0000 1.0000
74.0600 165.0000 1.0000
74.1200 164.0000 1.0000
74.1800 158.0000 1.0000
74.2400 137.0000 1.0000
74.3000 157.0000 1.0000
74.3600 176.0000 1.0000
74.4200 189.0000 1.0000
74.4800 168.0000 1.0000
74.5400 172.0000 1.0000
74.6000 180.0000 1.0000
74.6600 161.0000 1.0000
74.7200 155.0000 1.0000
74.7800 169.0000 1.0000
74.8400 150.0000 1.0000
74.9000 174.0000 1.0000
74.9600 166.0000 1.0000
75.0200 151.0000 1.0000
75.0800 157.0000 1.0000
75.1400 161.0000 1.0000
75.2000 166.0000 1.0000
75.2600 163.0000 1.0000
75.3200 168.0000 1.0000
75.3800 162.0000 1.0000
75.4400 147.0000 1.0000
75.5000 153.0000 1.0000
75.5600 162.0000 1.0000
75.6200 163.0000 1.0000
75.6800 166.0000 1.0000
75.7400 159.0000 1.0000
75.8000 151.0000 1.0000
75.8600 154.0000 1.0000
75.9200 174.0000 1.0000
75.9800 171.0000 1.0000
76.0400 176.0000 1.0000
76.1000 178.0000 1.0000
76.1600 140.0000 1.0000
76.2200 171.0000 1.0000
76.2800 175.0000 1.0000
76.3400 178.0000 1.0000
76.4000 172.0000 1.0000
76.4600 189.0000 1.0000
76.5200 173.0000 1.0000
76.5800 160.0000 1.0000
76.6400 174.0000 1.0000
76.7000 154.0000 1.0000
76.7600 145.0000 1.0000
76.8200 142.0000 1.0000
76.8800 164.0000 1.0000
76.9400 133.0000 1.0000
77.0000 166.0000 1.0000
77.0600 173.0000 1.0000
77.1200 165.0000 1.0000
77.1800 161.0000 1.0000
77.2400 149.0000 1.0000
77.3000 162.0000 1.0000
77.3600 160.0000 1.0000
77.4200 173.0000 1.0000
77.4800 155.0000 1.0000
77.5400 176.0000 1.0000
77.6000 162.0000 1.0000
77.6600 168.0000 1.0000
77.7200 159.0000 1.0000
77.7800 167.0000 1.0000
77.8400 160.0000 1.0000
77.9000 173.0000 1.0000
77.9600 176.0000 1.0000
78.0200 156.0000 1.0000
78.0800 147.0000 1.0000
78.1400 163.0000 1.0000
78.2000 167.0000 1.0000
78.2600 178.0000 1.0000
78.3200 165.0000 1.0000
78.3800 188.0000 1.0000
78.4400 151.0000 1.0000
78.5000 163.0000 1.0000
78.5600 155.0000 1.0000
78.6200 167.0000 1.0000
78.6800 178.0000 1.0000
78.7400 170.0000 1.0000
78.8000 187.0000 1.0000
78.8600 203.0000 1.0000
78.9200 213.0000 1.0000
78.9800 222.0000 1.0000
79.0400 243.0000 1.0000
79.1000 211.0000 1.0000
79.1600 218.0000 1.0000
79.2200 229.0000 1.0000
79.2800 234.0000 1.0000
79.3400 215.0000 1.0000
79.4000 198.0000 1.0000
79.4600 167.0000 1.0000
79.5200 190.0000 1.0000
79.5800 170.0000 1.0000
79.6400 161.0000 1.0000
79.7000 163.0000 1.0000
79.7600 150.0000 1.0000
79.8200 158.0000 1.0000
79.8800 167.0000 1.0000
79.9400 189.0000 1.0000
80.0000 162.0000 1.0000
*RAS_INT_END
*RAS_TEMPERATURE_START
*RAS_TEMPERATURE_END
*RAS_DATA_END