File: Section2_75_samples/XRD/No_053_NSS2_2.ras
*RAS_DATA_START
*RAS_HEADER_START
*DISP_FMT_X "%.2f"
*DISP_FMT_Y "%.0f"
*DISP_FULLSCALE "14878.0000000000"
*DISP_LINE_COLOR "255.0000000000"
*DISP_LINE_STYLE "0.0000000000"
*DISP_LINE_WIDTH "0.2500000000"
*DISP_NOTE "測定データ-9"
*DISP_OFFSET_Y "0.0000000000"
*DISP_PEAKSEARCH_UNIT_Y "cps"
*DISP_RANGE_BOTTOM "0.0000000000"
*DISP_RANGE_LEFT "20.0000000000"
*DISP_RANGE_LOGCUTOFF "0.0100000000"
*DISP_RANGE_RIGHT "70.0000000000"
*DISP_RANGE_TOP "14878.0000000000"
*DISP_SCALE_MODE_Y "0.0000000000"
*DISP_TAB_NAME "2θ/θ"
*DISP_TITLE_Y "強度"
*DISP_UNIT_Y "cps"
*DISP_WINDOW_NAME "MSG_MACROENGINE"
*FILE_COMMENT " "
*FILE_MD5 ""
*FILE_MEMO " "
*FILE_OPERATOR "Administrator"
*FILE_SAMPLE " "
*FILE_TYPE "RAS_RAW"
*FILE_USERGROUP "システムマネージャ"
*FILE_VERSION "1.0000000000"
*HW_ATTACHMENT_ID "ATT0025"
*HW_ATTACHMENT_NAME "標準|Standard"
*HW_COUNTER_ID-0 "CUT0025"
*HW_COUNTER_ID-1 "CUT0020"
*HW_COUNTER_ID-2 "CUT0020"
*HW_COUNTER_ID-3 "CSL0021"
*HW_COUNTER_ID-4 "CMC0021"
*HW_COUNTER_NAME-0 "D/teX Ultra|D/teX Ultra"
*HW_COUNTER_NAME-1 "None|None"
*HW_COUNTER_NAME-2 "None|None"
*HW_COUNTER_NAME-3 "BBM|BBM"
*HW_COUNTER_NAME-4 "検出器モノクロメータ|Detector monochromator"
*HW_COUNTER_SELECT_NAME "D/teX Ultra|D/teX Ultra"
*HW_GONIOMETER_ID "GON0023"
*HW_GONIOMETER_NAME "SmartLab|SmartLab"
*HW_GONIOMETER_RADIUS-0 "90.0"
*HW_GONIOMETER_RADIUS-1 "114.0"
*HW_GONIOMETER_RADIUS-2 "190.0"
*HW_GONIOMETER_RADIUS-3 "300.0"
*HW_GONIOMETER_RADIUS-4 "187.0"
*HW_GONIOMETER_RADIUS-5 "300.0"
*HW_GONIOMETER_RADIUS-6 "113.0"
*HW_GONIOMETER_RADIUS-7 "331.0"
*HW_I_OPT_ID-0 "CBO0021"
*HW_I_OPT_ID-1 "ICR0023"
*HW_I_OPT_ID-2 "ISL0021"
*HW_I_OPT_ID-3 "ISO0021"
*HW_I_OPT_ID-4 "IAD0021"
*HW_I_OPT_ID-5 "IPR0001"
*HW_I_OPT_NAME-0 "CBOユニット|CBO unit"
*HW_I_OPT_NAME-1 "標準入射光学ユニット|Standard incident optical unit"
*HW_I_OPT_NAME-2 "標準入射スリットボックス|Standard incident slit box"
*HW_I_OPT_NAME-3 "入射平行スリット|Incident parallel slit"
*HW_I_OPT_NAME-4 "長手制限スリット|Length limiting slit"
*HW_I_OPT_NAME-5 "None|None"
*HW_R_ATTENUATER_AUTOMODE "0"
*HW_R_OPT_ID-0 "RSS0021"
*HW_R_OPT_ID-1 "RCR0023"
*HW_R_OPT_ID-2 "RSO0021"
*HW_R_OPT_ID-3 "RRS0021"
*HW_R_OPT_ID-4 "ATN0021"
*HW_R_OPT_ID-5 "RFL0021"
*HW_R_OPT_ID-6 "RAD0021"
*HW_R_OPT_NAME-0 "標準受光スリットボックス1|Standard receiving slit box # 1"
*HW_R_OPT_NAME-1 "標準受光光学ユニット1|Standard receiving unit # 1"
*HW_R_OPT_NAME-2 "標準受光光学ユニット2|Standard receiving optical unit # 2"
*HW_R_OPT_NAME-3 "標準受光スリットボックス2|Standard receiving slit box # 2"
*HW_R_OPT_NAME-4 "標準アッテネータ|Standard Attenuator"
*HW_R_OPT_NAME-5 "Cu Kβ|Cu K-beta"
*HW_R_OPT_NAME-6 "調整用受光スリット|Alignment receiving slit"
*HW_SAMPLE_HOLDER_ID "SMP0023"
*HW_SAMPLE_HOLDER_NAME "標準Zステージ|Standard Z stage"
*HW_XG_CURRENT_MAX "50"
*HW_XG_CURRENT_MIN "2"
*HW_XG_CURRENT_RESOLUTION "1"
*HW_XG_CURRENT_UNIT "mA"
*HW_XG_FOCUS "1mm x 10mm"
*HW_XG_FOCUS_TYPE "Normal"
*HW_XG_ID ""
*HW_XG_NAME "3kW 封入管(ID:1200)|3kW Sealed tube(ID:1200)"
*HW_XG_TARGET_ATOMIC_NUMBER "29.0000000000"
*HW_XG_TARGET_NAME "Cu"
*HW_XG_TYPE "Hermetic"
*HW_XG_VOLTAGE_MAX "60"
*HW_XG_VOLTAGE_MIN "20"
*HW_XG_VOLTAGE_RESOLUTION "1"
*HW_XG_VOLTAGE_UNIT "kV"
*HW_XG_WATT_MAX "1.500"
*HW_XG_WATT_UNIT "kW"
*HW_XG_WAVE_LENGTH_ALPHA1 "1.540593"
*HW_XG_WAVE_LENGTH_ALPHA2 "1.544414"
*HW_XG_WAVE_LENGTH_BETA "1.392250"
*MEAS_COND_AXIS_NAME-0 "2θ/θ"
*MEAS_COND_AXIS_NAME-1 "2θ"
*MEAS_COND_AXIS_NAME-2 "ω"
*MEAS_COND_AXIS_NAME-3 "Z"
*MEAS_COND_AXIS_NAME-4 "2θ/ω"
*MEAS_COND_AXIS_NAME-5 "θs"
*MEAS_COND_AXIS_NAME-6 "θd"
*MEAS_COND_AXIS_NAME-7 "Ts"
*MEAS_COND_AXIS_NAME-8 "CBO選択スリット"
*MEAS_COND_AXIS_NAME-9 "M"
*MEAS_COND_AXIS_NAME-10 "入射平行スリット"
*MEAS_COND_AXIS_NAME-11 "入射スリット"
*MEAS_COND_AXIS_NAME-12 ""
*MEAS_COND_AXIS_NAME-13 "Zs"
*MEAS_COND_AXIS_NAME-14 "入射光学素子"
*MEAS_COND_AXIS_NAME-15 "長手制限スリット"
*MEAS_COND_AXIS_NAME-16 "センタースリット"
*MEAS_COND_AXIS_NAME-17 "フィルター"
*MEAS_COND_AXIS_NAME-18 "受光スリット1"
*MEAS_COND_AXIS_NAME-19 "受光スリット2"
*MEAS_COND_AXIS_NAME-20 "受光光学素子"
*MEAS_COND_AXIS_NAME-21 "受光平行スリット"
*MEAS_COND_AXIS_NAME-22 "調整用受光スリット"
*MEAS_COND_AXIS_NAME-23 ""
*MEAS_COND_AXIS_NAME-24 ""
*MEAS_COND_AXIS_NAME-25 "Zd"
*MEAS_COND_AXIS_NAME-26 "アッテネータ"
*MEAS_COND_AXIS_NAME-27 "検出器モノクロメータ"
*MEAS_COND_AXIS_NAME-28 "モノクロメータスリット"
*MEAS_COND_AXIS_NAME-29 "プライマリビーム"
*MEAS_COND_AXIS_NAME-30 "PHA"
*MEAS_COND_AXIS_NAME_INTERNAL-0 "TwoThetaTheta"
*MEAS_COND_AXIS_NAME_INTERNAL-1 "TwoTheta"
*MEAS_COND_AXIS_NAME_INTERNAL-2 "Omega"
*MEAS_COND_AXIS_NAME_INTERNAL-3 "Z"
*MEAS_COND_AXIS_NAME_INTERNAL-4 "TwoThetaOmega"
*MEAS_COND_AXIS_NAME_INTERNAL-5 "ThetaS"
*MEAS_COND_AXIS_NAME_INTERNAL-6 "ThetaD"
*MEAS_COND_AXIS_NAME_INTERNAL-7 "Ts"
*MEAS_COND_AXIS_NAME_INTERNAL-8 "CBO"
*MEAS_COND_AXIS_NAME_INTERNAL-9 "CBO-M"
*MEAS_COND_AXIS_NAME_INTERNAL-10 "IncidentSollerSlit"
*MEAS_COND_AXIS_NAME_INTERNAL-11 "IncidentSlitBox"
*MEAS_COND_AXIS_NAME_INTERNAL-12 "IncidentSlitBox-_Axis"
*MEAS_COND_AXIS_NAME_INTERNAL-13 "Zs"
*MEAS_COND_AXIS_NAME_INTERNAL-14 "IncidentMonochromator"
*MEAS_COND_AXIS_NAME_INTERNAL-15 "IncidentAxdSlit"
*MEAS_COND_AXIS_NAME_INTERNAL-16 "CenterSlit"
*MEAS_COND_AXIS_NAME_INTERNAL-17 "Filter"
*MEAS_COND_AXIS_NAME_INTERNAL-18 "ReceivingSlitBox1"
*MEAS_COND_AXIS_NAME_INTERNAL-19 "ReceivingSlitBox2"
*MEAS_COND_AXIS_NAME_INTERNAL-20 "ReceivingOptics"
*MEAS_COND_AXIS_NAME_INTERNAL-21 "ReceivingSollerSlit"
*MEAS_COND_AXIS_NAME_INTERNAL-22 "ReceivingAxdSlit"
*MEAS_COND_AXIS_NAME_INTERNAL-23 "ReceivingSlitBox1-_Axis"
*MEAS_COND_AXIS_NAME_INTERNAL-24 "ReceivingSlitBox2-_Axis"
*MEAS_COND_AXIS_NAME_INTERNAL-25 "ReceivingSlitBox2-Zd"
*MEAS_COND_AXIS_NAME_INTERNAL-26 "Attenuator"
*MEAS_COND_AXIS_NAME_INTERNAL-27 "CounterMonochromator"
*MEAS_COND_AXIS_NAME_INTERNAL-28 "CounterSlit"
*MEAS_COND_AXIS_NAME_INTERNAL-29 "IncidentPrimary"
*MEAS_COND_AXIS_NAME_INTERNAL-30 "PHA"
*MEAS_COND_AXIS_NAME_MAGICNO-0 "83951616.0000000000"
*MEAS_COND_AXIS_NAME_MAGICNO-1 "268632064.0000000000"
*MEAS_COND_AXIS_NAME_MAGICNO-2 "268500992.0000000000"
*MEAS_COND_AXIS_NAME_MAGICNO-3 "285278208.0000000000"
*MEAS_COND_AXIS_NAME_MAGICNO-4 "83951616.0000000000"
*MEAS_COND_AXIS_NAME_MAGICNO-5 "131072.0000000000"
*MEAS_COND_AXIS_NAME_MAGICNO-6 "131072.0000000000"
*MEAS_COND_AXIS_NAME_MAGICNO-7 "318898176.0000000000"
*MEAS_COND_AXIS_NAME_MAGICNO-8 "20971521.0000000000"
*MEAS_COND_AXIS_NAME_MAGICNO-9 "285343744.0000000000"
*MEAS_COND_AXIS_NAME_MAGICNO-10 "20971521.0000000000"
*MEAS_COND_AXIS_NAME_MAGICNO-11 "22020097.0000000000"
*MEAS_COND_AXIS_NAME_MAGICNO-12 "25165824.0000000000"
*MEAS_COND_AXIS_NAME_MAGICNO-13 "318898176.0000000000"
*MEAS_COND_AXIS_NAME_MAGICNO-14 "1.0000000000"
*MEAS_COND_AXIS_NAME_MAGICNO-15 "20971521.0000000000"
*MEAS_COND_AXIS_NAME_MAGICNO-16 "20971521.0000000000"
*MEAS_COND_AXIS_NAME_MAGICNO-17 "20971521.0000000000"
*MEAS_COND_AXIS_NAME_MAGICNO-18 "23068673.0000000000"
*MEAS_COND_AXIS_NAME_MAGICNO-19 "23068673.0000000000"
*MEAS_COND_AXIS_NAME_MAGICNO-20 "20971521.0000000000"
*MEAS_COND_AXIS_NAME_MAGICNO-21 "20971521.0000000000"
*MEAS_COND_AXIS_NAME_MAGICNO-22 "20971521.0000000000"
*MEAS_COND_AXIS_NAME_MAGICNO-23 "25165824.0000000000"
*MEAS_COND_AXIS_NAME_MAGICNO-24 "25165824.0000000000"
*MEAS_COND_AXIS_NAME_MAGICNO-25 "285343744.0000000000"
*MEAS_COND_AXIS_NAME_MAGICNO-26 "17301505.0000000000"
*MEAS_COND_AXIS_NAME_MAGICNO-27 "20971521.0000000000"
*MEAS_COND_AXIS_NAME_MAGICNO-28 "20971521.0000000000"
*MEAS_COND_AXIS_NAME_MAGICNO-29 "20971521.0000000000"
*MEAS_COND_AXIS_NAME_MAGICNO-30 "0.0000000000"
*MEAS_COND_AXIS_OFFSET-0 "-"
*MEAS_COND_AXIS_OFFSET-1 "-0.1081000000"
*MEAS_COND_AXIS_OFFSET-2 "0.3758000000"
*MEAS_COND_AXIS_OFFSET-3 "-"
*MEAS_COND_AXIS_OFFSET-4 "-"
*MEAS_COND_AXIS_OFFSET-5 "0.3758000000"
*MEAS_COND_AXIS_OFFSET-6 "-0.4839000000"
*MEAS_COND_AXIS_OFFSET-7 "-"
*MEAS_COND_AXIS_OFFSET-8 "-"
*MEAS_COND_AXIS_OFFSET-9 "-"
*MEAS_COND_AXIS_OFFSET-10 "-"
*MEAS_COND_AXIS_OFFSET-11 "-"
*MEAS_COND_AXIS_OFFSET-12 "-"
*MEAS_COND_AXIS_OFFSET-13 "-"
*MEAS_COND_AXIS_OFFSET-14 "-"
*MEAS_COND_AXIS_OFFSET-15 "-"
*MEAS_COND_AXIS_OFFSET-16 "-"
*MEAS_COND_AXIS_OFFSET-17 "-"
*MEAS_COND_AXIS_OFFSET-18 "-"
*MEAS_COND_AXIS_OFFSET-19 "-"
*MEAS_COND_AXIS_OFFSET-20 "-"
*MEAS_COND_AXIS_OFFSET-21 "-"
*MEAS_COND_AXIS_OFFSET-22 "-"
*MEAS_COND_AXIS_OFFSET-23 "-"
*MEAS_COND_AXIS_OFFSET-24 "-"
*MEAS_COND_AXIS_OFFSET-25 "-"
*MEAS_COND_AXIS_OFFSET-26 "-"
*MEAS_COND_AXIS_OFFSET-27 "-"
*MEAS_COND_AXIS_OFFSET-28 "-"
*MEAS_COND_AXIS_OFFSET-29 "-"
*MEAS_COND_AXIS_OFFSET-30 "-"
*MEAS_COND_AXIS_POSITION-0 "0.0000000000"
*MEAS_COND_AXIS_POSITION-1 "0.0000000000"
*MEAS_COND_AXIS_POSITION-2 "0.0000000000"
*MEAS_COND_AXIS_POSITION-3 "-0.5500000000"
*MEAS_COND_AXIS_POSITION-4 "0.0000000000"
*MEAS_COND_AXIS_POSITION-5 "0.0000000000"
*MEAS_COND_AXIS_POSITION-6 "0.0000000000"
*MEAS_COND_AXIS_POSITION-7 "-0.4278800000"
*MEAS_COND_AXIS_POSITION-8 "BB"
*MEAS_COND_AXIS_POSITION-9 "0.0000000000"
*MEAS_COND_AXIS_POSITION-10 "Soller_slit_5.0deg"
*MEAS_COND_AXIS_POSITION-11 "2/3deg"
*MEAS_COND_AXIS_POSITION-12 "2.2088000000"
*MEAS_COND_AXIS_POSITION-13 "-0.4140600000"
*MEAS_COND_AXIS_POSITION-14 "0.0000000000"
*MEAS_COND_AXIS_POSITION-15 "10.0mm"
*MEAS_COND_AXIS_POSITION-16 "None"
*MEAS_COND_AXIS_POSITION-17 "Cu_K-beta"
*MEAS_COND_AXIS_POSITION-18 "13.000mm"
*MEAS_COND_AXIS_POSITION-19 "13.000mm"
*MEAS_COND_AXIS_POSITION-20 "No_unit"
*MEAS_COND_AXIS_POSITION-21 "Soller_slit_5.0deg"
*MEAS_COND_AXIS_POSITION-22 "None"
*MEAS_COND_AXIS_POSITION-23 "13.0000000000"
*MEAS_COND_AXIS_POSITION-24 "13.0000000000"
*MEAS_COND_AXIS_POSITION-25 "0.0109400000"
*MEAS_COND_AXIS_POSITION-26 "Open"
*MEAS_COND_AXIS_POSITION-27 "None"
*MEAS_COND_AXIS_POSITION-28 "None"
*MEAS_COND_AXIS_POSITION-29 "None"
*MEAS_COND_AXIS_POSITION-30 "38.0000000000"
*MEAS_COND_AXIS_UNIT-0 "deg"
*MEAS_COND_AXIS_UNIT-1 "deg"
*MEAS_COND_AXIS_UNIT-2 "deg"
*MEAS_COND_AXIS_UNIT-3 "mm"
*MEAS_COND_AXIS_UNIT-4 "deg"
*MEAS_COND_AXIS_UNIT-5 "deg"
*MEAS_COND_AXIS_UNIT-6 "deg"
*MEAS_COND_AXIS_UNIT-7 "mm"
*MEAS_COND_AXIS_UNIT-8 ""
*MEAS_COND_AXIS_UNIT-9 "pulse"
*MEAS_COND_AXIS_UNIT-10 ""
*MEAS_COND_AXIS_UNIT-11 ""
*MEAS_COND_AXIS_UNIT-12 "mm"
*MEAS_COND_AXIS_UNIT-13 "mm"
*MEAS_COND_AXIS_UNIT-14 ""
*MEAS_COND_AXIS_UNIT-15 ""
*MEAS_COND_AXIS_UNIT-16 ""
*MEAS_COND_AXIS_UNIT-17 ""
*MEAS_COND_AXIS_UNIT-18 ""
*MEAS_COND_AXIS_UNIT-19 ""
*MEAS_COND_AXIS_UNIT-20 ""
*MEAS_COND_AXIS_UNIT-21 ""
*MEAS_COND_AXIS_UNIT-22 ""
*MEAS_COND_AXIS_UNIT-23 "mm"
*MEAS_COND_AXIS_UNIT-24 "mm"
*MEAS_COND_AXIS_UNIT-25 "mm"
*MEAS_COND_AXIS_UNIT-26 ""
*MEAS_COND_AXIS_UNIT-27 ""
*MEAS_COND_AXIS_UNIT-28 ""
*MEAS_COND_AXIS_UNIT-29 ""
*MEAS_COND_AXIS_UNIT-30 "div"
*MEAS_COND_COUNTER_CNTLOSS_CORR "0.0000000000"
*MEAS_COND_COUNTER_PHABASE "38.0000000000"
*MEAS_COND_COUNTER_PHAWINDOW "16.0000000000"
*MEAS_COND_COUNTER_PHA_UNIT "div"
*MEAS_COND_COUNTER_TAUDIFF "30.0000000000"
*MEAS_COND_COUNTER_TAUINT "0.0000000000"
*MEAS_COND_IRRADIATION_MODE "OFF"
*MEAS_COND_IRRADIATION_WIDTH ""
*MEAS_COND_OPT_ATTR "集中法"
*MEAS_COND_OPT_NAME "@集中法"
*MEAS_COND_UNSYMMETRIC_MODE "OFF"
*MEAS_COND_XG_CURRENT "30.0000000000"
*MEAS_COND_XG_VOLTAGE "40.0000000000"
*MEAS_COND_XG_WAVE_TYPE "Ka"
*MEAS_DATA_COUNT "5001.0000000000"
*MEAS_SCAN_AXIS_X "2θ/θ"
*MEAS_SCAN_AXIS_X_INTERNAL "TwoThetaTheta"
*MEAS_SCAN_END_TIME "07/12/21 16:02:37"
*MEAS_SCAN_MODE "CONTINUOUS"
*MEAS_SCAN_MONITOR "0"
*MEAS_SCAN_RESOLUTION_X "0.0002"
*MEAS_SCAN_SPEED "1.0"
*MEAS_SCAN_SPEED_UNIT "deg/min"
*MEAS_SCAN_START "20.0000000000"
*MEAS_SCAN_START_TIME "07/12/21 15:09:44"
*MEAS_SCAN_STEP "0.0100000000"
*MEAS_SCAN_STOP "70.0000000000"
*MEAS_SCAN_UNIT_X "deg"
*MEAS_SCAN_UNIT_Y "counts"
*RAS_HEADER_END
*RAS_INT_START
20.0000 1604.0000 1.0000
20.0400 1569.0000 1.0000
20.0800 1556.0000 1.0000
20.1200 1585.0000 1.0000
20.1600 1535.0000 1.0000
20.2000 1616.0000 1.0000
20.2400 1575.0000 1.0000
20.2800 1569.0000 1.0000
20.3200 1604.0000 1.0000
20.3600 1573.0000 1.0000
20.4000 1534.0000 1.0000
20.4400 1575.0000 1.0000
20.4800 1617.0000 1.0000
20.5200 1552.0000 1.0000
20.5600 1545.0000 1.0000
20.6000 1558.0000 1.0000
20.6400 1551.0000 1.0000
20.6800 1624.0000 1.0000
20.7200 1551.0000 1.0000
20.7600 1566.0000 1.0000
20.8000 1541.0000 1.0000
20.8400 1576.0000 1.0000
20.8800 1563.0000 1.0000
20.9200 1526.0000 1.0000
20.9600 1586.0000 1.0000
21.0000 1554.0000 1.0000
21.0400 1516.0000 1.0000
21.0800 1512.0000 1.0000
21.1200 1531.0000 1.0000
21.1600 1577.0000 1.0000
21.2000 1492.0000 1.0000
21.2400 1589.0000 1.0000
21.2800 1567.0000 1.0000
21.3200 1545.0000 1.0000
21.3600 1586.0000 1.0000
21.4000 1567.0000 1.0000
21.4400 1555.0000 1.0000
21.4800 1592.0000 1.0000
21.5200 1520.0000 1.0000
21.5600 1535.0000 1.0000
21.6000 1568.0000 1.0000
21.6400 1565.0000 1.0000
21.6800 1593.0000 1.0000
21.7200 1661.0000 1.0000
21.7600 1591.0000 1.0000
21.8000 1589.0000 1.0000
21.8400 1567.0000 1.0000
21.8800 1618.0000 1.0000
21.9200 1534.0000 1.0000
21.9600 1584.0000 1.0000
22.0000 1538.0000 1.0000
22.0400 1631.0000 1.0000
22.0800 1549.0000 1.0000
22.1200 1556.0000 1.0000
22.1600 1504.0000 1.0000
22.2000 1604.0000 1.0000
22.2400 1546.0000 1.0000
22.2800 1561.0000 1.0000
22.3200 1618.0000 1.0000
22.3600 1571.0000 1.0000
22.4000 1520.0000 1.0000
22.4400 1563.0000 1.0000
22.4800 1604.0000 1.0000
22.5200 1560.0000 1.0000
22.5600 1571.0000 1.0000
22.6000 1658.0000 1.0000
22.6400 1612.0000 1.0000
22.6800 1595.0000 1.0000
22.7200 1553.0000 1.0000
22.7600 1586.0000 1.0000
22.8000 1559.0000 1.0000
22.8400 1647.0000 1.0000
22.8800 1560.0000 1.0000
22.9200 1545.0000 1.0000
22.9600 1536.0000 1.0000
23.0000 1528.0000 1.0000
23.0400 1553.0000 1.0000
23.0800 1600.0000 1.0000
23.1200 1559.0000 1.0000
23.1600 1564.0000 1.0000
23.2000 1525.0000 1.0000
23.2400 1654.0000 1.0000
23.2800 1547.0000 1.0000
23.3200 1543.0000 1.0000
23.3600 1665.0000 1.0000
23.4000 1621.0000 1.0000
23.4400 1656.0000 1.0000
23.4800 1632.0000 1.0000
23.5200 1673.0000 1.0000
23.5600 1624.0000 1.0000
23.6000 1597.0000 1.0000
23.6400 1613.0000 1.0000
23.6800 1552.0000 1.0000
23.7200 1653.0000 1.0000
23.7600 1591.0000 1.0000
23.8000 1570.0000 1.0000
23.8400 1642.0000 1.0000
23.8800 1563.0000 1.0000
23.9200 1586.0000 1.0000
23.9600 1571.0000 1.0000
24.0000 1648.0000 1.0000
24.0400 1566.0000 1.0000
24.0800 1655.0000 1.0000
24.1200 1621.0000 1.0000
24.1600 1591.0000 1.0000
24.2000 1650.0000 1.0000
24.2400 1591.0000 1.0000
24.2800 1552.0000 1.0000
24.3200 1590.0000 1.0000
24.3600 1612.0000 1.0000
24.4000 1687.0000 1.0000
24.4400 1638.0000 1.0000
24.4800 1599.0000 1.0000
24.5200 1633.0000 1.0000
24.5600 1585.0000 1.0000
24.6000 1641.0000 1.0000
24.6400 1654.0000 1.0000
24.6800 1665.0000 1.0000
24.7200 1609.0000 1.0000
24.7600 1692.0000 1.0000
24.8000 1673.0000 1.0000
24.8400 1691.0000 1.0000
24.8800 1723.0000 1.0000
24.9200 1656.0000 1.0000
24.9600 1642.0000 1.0000
25.0000 1637.0000 1.0000
25.0400 1664.0000 1.0000
25.0800 1637.0000 1.0000
25.1200 1694.0000 1.0000
25.1600 1734.0000 1.0000
25.2000 1659.0000 1.0000
25.2400 1640.0000 1.0000
25.2800 1674.0000 1.0000
25.3200 1660.0000 1.0000
25.3600 1662.0000 1.0000
25.4000 1707.0000 1.0000
25.4400 1648.0000 1.0000
25.4800 1638.0000 1.0000
25.5200 1643.0000 1.0000
25.5600 1671.0000 1.0000
25.6000 1620.0000 1.0000
25.6400 1660.0000 1.0000
25.6800 1705.0000 1.0000
25.7200 1642.0000 1.0000
25.7600 1625.0000 1.0000
25.8000 1645.0000 1.0000
25.8400 1601.0000 1.0000
25.8800 1662.0000 1.0000
25.9200 1605.0000 1.0000
25.9600 1640.0000 1.0000
26.0000 1671.0000 1.0000
26.0400 1709.0000 1.0000
26.0800 1696.0000 1.0000
26.1200 1692.0000 1.0000
26.1600 1632.0000 1.0000
26.2000 1619.0000 1.0000
26.2400 1716.0000 1.0000
26.2800 1624.0000 1.0000
26.3200 1705.0000 1.0000
26.3600 1727.0000 1.0000
26.4000 1748.0000 1.0000
26.4400 1703.0000 1.0000
26.4800 1675.0000 1.0000
26.5200 1699.0000 1.0000
26.5600 1729.0000 1.0000
26.6000 1756.0000 1.0000
26.6400 1709.0000 1.0000
26.6800 1786.0000 1.0000
26.7200 1806.0000 1.0000
26.7600 1764.0000 1.0000
26.8000 1820.0000 1.0000
26.8400 1864.0000 1.0000
26.8800 1935.0000 1.0000
26.9200 1990.0000 1.0000
26.9600 2075.0000 1.0000
27.0000 2205.0000 1.0000
27.0400 2341.0000 1.0000
27.0800 2661.0000 1.0000
27.1200 3041.0000 1.0000
27.1600 3531.0000 1.0000
27.2000 4149.0000 1.0000
27.2400 5100.0000 1.0000
27.2800 5902.0000 1.0000
27.3200 6227.0000 1.0000
27.3600 5585.0000 1.0000
27.4000 4845.0000 1.0000
27.4400 3888.0000 1.0000
27.4800 3330.0000 1.0000
27.5200 2758.0000 1.0000
27.5600 2531.0000 1.0000
27.6000 2280.0000 1.0000
27.6400 2162.0000 1.0000
27.6800 2061.0000 1.0000
27.7200 1951.0000 1.0000
27.7600 1930.0000 1.0000
27.8000 1930.0000 1.0000
27.8400 1803.0000 1.0000
27.8800 1867.0000 1.0000
27.9200 1760.0000 1.0000
27.9600 1754.0000 1.0000
28.0000 1699.0000 1.0000
28.0400 1733.0000 1.0000
28.0800 1735.0000 1.0000
28.1200 1667.0000 1.0000
28.1600 1627.0000 1.0000
28.2000 1686.0000 1.0000
28.2400 1613.0000 1.0000
28.2800 1709.0000 1.0000
28.3200 1656.0000 1.0000
28.3600 1610.0000 1.0000
28.4000 1649.0000 1.0000
28.4400 1587.0000 1.0000
28.4800 1655.0000 1.0000
28.5200 1558.0000 1.0000
28.5600 1638.0000 1.0000
28.6000 1620.0000 1.0000
28.6400 1613.0000 1.0000
28.6800 1652.0000 1.0000
28.7200 1603.0000 1.0000
28.7600 1678.0000 1.0000
28.8000 1591.0000 1.0000
28.8400 1655.0000 1.0000
28.8800 1588.0000 1.0000
28.9200 1594.0000 1.0000
28.9600 1591.0000 1.0000
29.0000 1605.0000 1.0000
29.0400 1546.0000 1.0000
29.0800 1638.0000 1.0000
29.1200 1600.0000 1.0000
29.1600 1518.0000 1.0000
29.2000 1650.0000 1.0000
29.2400 1538.0000 1.0000
29.2800 1574.0000 1.0000
29.3200 1610.0000 1.0000
29.3600 1583.0000 1.0000
29.4000 1560.0000 1.0000
29.4400 1552.0000 1.0000
29.4800 1620.0000 1.0000
29.5200 1486.0000 1.0000
29.5600 1578.0000 1.0000
29.6000 1593.0000 1.0000
29.6400 1566.0000 1.0000
29.6800 1521.0000 1.0000
29.7200 1569.0000 1.0000
29.7600 1551.0000 1.0000
29.8000 1485.0000 1.0000
29.8400 1462.0000 1.0000
29.8800 1466.0000 1.0000
29.9200 1533.0000 1.0000
29.9600 1519.0000 1.0000
30.0000 1523.0000 1.0000
30.0400 1504.0000 1.0000
30.0800 1581.0000 1.0000
30.1200 1580.0000 1.0000
30.1600 1583.0000 1.0000
30.2000 1540.0000 1.0000
30.2400 1502.0000 1.0000
30.2800 1577.0000 1.0000
30.3200 1545.0000 1.0000
30.3600 1529.0000 1.0000
30.4000 1469.0000 1.0000
30.4400 1583.0000 1.0000
30.4800 1466.0000 1.0000
30.5200 1604.0000 1.0000
30.5600 1526.0000 1.0000
30.6000 1517.0000 1.0000
30.6400 1450.0000 1.0000
30.6800 1506.0000 1.0000
30.7200 1548.0000 1.0000
30.7600 1489.0000 1.0000
30.8000 1532.0000 1.0000
30.8400 1487.0000 1.0000
30.8800 1502.0000 1.0000
30.9200 1468.0000 1.0000
30.9600 1452.0000 1.0000
31.0000 1490.0000 1.0000
31.0400 1465.0000 1.0000
31.0800 1461.0000 1.0000
31.1200 1537.0000 1.0000
31.1600 1461.0000 1.0000
31.2000 1461.0000 1.0000
31.2400 1440.0000 1.0000
31.2800 1422.0000 1.0000
31.3200 1530.0000 1.0000
31.3600 1421.0000 1.0000
31.4000 1482.0000 1.0000
31.4400 1435.0000 1.0000
31.4800 1455.0000 1.0000
31.5200 1431.0000 1.0000
31.5600 1429.0000 1.0000
31.6000 1462.0000 1.0000
31.6400 1433.0000 1.0000
31.6800 1436.0000 1.0000
31.7200 1390.0000 1.0000
31.7600 1535.0000 1.0000
31.8000 1504.0000 1.0000
31.8400 1443.0000 1.0000
31.8800 1441.0000 1.0000
31.9200 1429.0000 1.0000
31.9600 1451.0000 1.0000
32.0000 1464.0000 1.0000
32.0400 1477.0000 1.0000
32.0800 1450.0000 1.0000
32.1200 1481.0000 1.0000
32.1600 1441.0000 1.0000
32.2000 1437.0000 1.0000
32.2400 1448.0000 1.0000
32.2800 1505.0000 1.0000
32.3200 1377.0000 1.0000
32.3600 1454.0000 1.0000
32.4000 1421.0000 1.0000
32.4400 1458.0000 1.0000
32.4800 1457.0000 1.0000
32.5200 1429.0000 1.0000
32.5600 1398.0000 1.0000
32.6000 1284.0000 1.0000
32.6400 1360.0000 1.0000
32.6800 1412.0000 1.0000
32.7200 1363.0000 1.0000
32.7600 1357.0000 1.0000
32.8000 1362.0000 1.0000
32.8400 1400.0000 1.0000
32.8800 1431.0000 1.0000
32.9200 1319.0000 1.0000
32.9600 1359.0000 1.0000
33.0000 1371.0000 1.0000
33.0400 1397.0000 1.0000
33.0800 1404.0000 1.0000
33.1200 1367.0000 1.0000
33.1600 1352.0000 1.0000
33.2000 1341.0000 1.0000
33.2400 1338.0000 1.0000
33.2800 1395.0000 1.0000
33.3200 1362.0000 1.0000
33.3600 1373.0000 1.0000
33.4000 1361.0000 1.0000
33.4400 1359.0000 1.0000
33.4800 1424.0000 1.0000
33.5200 1363.0000 1.0000
33.5600 1432.0000 1.0000
33.6000 1402.0000 1.0000
33.6400 1380.0000 1.0000
33.6800 1390.0000 1.0000
33.7200 1432.0000 1.0000
33.7600 1446.0000 1.0000
33.8000 1426.0000 1.0000
33.8400 1473.0000 1.0000
33.8800 1476.0000 1.0000
33.9200 1446.0000 1.0000
33.9600 1466.0000 1.0000
34.0000 1508.0000 1.0000
34.0400 1482.0000 1.0000
34.0800 1463.0000 1.0000
34.1200 1498.0000 1.0000
34.1600 1497.0000 1.0000
34.2000 1540.0000 1.0000
34.2400 1631.0000 1.0000
34.2800 1716.0000 1.0000
34.3200 1805.0000 1.0000
34.3600 1984.0000 1.0000
34.4000 2283.0000 1.0000
34.4400 2586.0000 1.0000
34.4800 2825.0000 1.0000
34.5200 2828.0000 1.0000
34.5600 2679.0000 1.0000
34.6000 2498.0000 1.0000
34.6400 2160.0000 1.0000
34.6800 1940.0000 1.0000
34.7200 1775.0000 1.0000
34.7600 1703.0000 1.0000
34.8000 1593.0000 1.0000
34.8400 1500.0000 1.0000
34.8800 1453.0000 1.0000
34.9200 1402.0000 1.0000
34.9600 1398.0000 1.0000
35.0000 1362.0000 1.0000
35.0400 1306.0000 1.0000
35.0800 1329.0000 1.0000
35.1200 1266.0000 1.0000
35.1600 1264.0000 1.0000
35.2000 1220.0000 1.0000
35.2400 1197.0000 1.0000
35.2800 1293.0000 1.0000
35.3200 1285.0000 1.0000
35.3600 1242.0000 1.0000
35.4000 1241.0000 1.0000
35.4400 1266.0000 1.0000
35.4800 1194.0000 1.0000
35.5200 1209.0000 1.0000
35.5600 1190.0000 1.0000
35.6000 1171.0000 1.0000
35.6400 1256.0000 1.0000
35.6800 1196.0000 1.0000
35.7200 1212.0000 1.0000
35.7600 1218.0000 1.0000
35.8000 1222.0000 1.0000
35.8400 1190.0000 1.0000
35.8800 1180.0000 1.0000
35.9200 1214.0000 1.0000
35.9600 1284.0000 1.0000
36.0000 1276.0000 1.0000
36.0400 1278.0000 1.0000
36.0800 1293.0000 1.0000
36.1200 1344.0000 1.0000
36.1600 1387.0000 1.0000
36.2000 1410.0000 1.0000
36.2400 1553.0000 1.0000
36.2800 1660.0000 1.0000
36.3200 1870.0000 1.0000
36.3600 1939.0000 1.0000
36.4000 2118.0000 1.0000
36.4400 2195.0000 1.0000
36.4800 2029.0000 1.0000
36.5200 1919.0000 1.0000
36.5600 1707.0000 1.0000
36.6000 1595.0000 1.0000
36.6400 1406.0000 1.0000
36.6800 1346.0000 1.0000
36.7200 1262.0000 1.0000
36.7600 1259.0000 1.0000
36.8000 1183.0000 1.0000
36.8400 1165.0000 1.0000
36.8800 1160.0000 1.0000
36.9200 1065.0000 1.0000
36.9600 1121.0000 1.0000
37.0000 1111.0000 1.0000
37.0400 1149.0000 1.0000
37.0800 1118.0000 1.0000
37.1200 1100.0000 1.0000
37.1600 1053.0000 1.0000
37.2000 1096.0000 1.0000
37.2400 1104.0000 1.0000
37.2800 1105.0000 1.0000
37.3200 1124.0000 1.0000
37.3600 1124.0000 1.0000
37.4000 1088.0000 1.0000
37.4400 1180.0000 1.0000
37.4800 1121.0000 1.0000
37.5200 1127.0000 1.0000
37.5600 1124.0000 1.0000
37.6000 1085.0000 1.0000
37.6400 1139.0000 1.0000
37.6800 1118.0000 1.0000
37.7200 1083.0000 1.0000
37.7600 1077.0000 1.0000
37.8000 1143.0000 1.0000
37.8400 1198.0000 1.0000
37.8800 1159.0000 1.0000
37.9200 1145.0000 1.0000
37.9600 1165.0000 1.0000
38.0000 1148.0000 1.0000
38.0400 1238.0000 1.0000
38.0800 1230.0000 1.0000
38.1200 1286.0000 1.0000
38.1600 1430.0000 1.0000
38.2000 1534.0000 1.0000
38.2400 1697.0000 1.0000
38.2800 1928.0000 1.0000
38.3200 2202.0000 1.0000
38.3600 2651.0000 1.0000
38.4000 3370.0000 1.0000
38.4400 4440.0000 1.0000
38.4800 5894.0000 1.0000
38.5200 7038.0000 1.0000
38.5600 7423.0000 1.0000
38.6000 6574.0000 1.0000
38.6400 5983.0000 1.0000
38.6800 4661.0000 1.0000
38.7200 3635.0000 1.0000
38.7600 2835.0000 1.0000
38.8000 2232.0000 1.0000
38.8400 1914.0000 1.0000
38.8800 1594.0000 1.0000
38.9200 1437.0000 1.0000
38.9600 1325.0000 1.0000
39.0000 1227.0000 1.0000
39.0400 1188.0000 1.0000
39.0800 1106.0000 1.0000
39.1200 1109.0000 1.0000
39.1600 1126.0000 1.0000
39.2000 1032.0000 1.0000
39.2400 1044.0000 1.0000
39.2800 1032.0000 1.0000
39.3200 1054.0000 1.0000
39.3600 1009.0000 1.0000
39.4000 963.0000 1.0000
39.4400 1063.0000 1.0000
39.4800 984.0000 1.0000
39.5200 1011.0000 1.0000
39.5600 1089.0000 1.0000
39.6000 1018.0000 1.0000
39.6400 1013.0000 1.0000
39.6800 1060.0000 1.0000
39.7200 1043.0000 1.0000
39.7600 995.0000 1.0000
39.8000 971.0000 1.0000
39.8400 981.0000 1.0000
39.8800 1013.0000 1.0000
39.9200 972.0000 1.0000
39.9600 1029.0000 1.0000
40.0000 974.0000 1.0000
40.0400 971.0000 1.0000
40.0800 923.0000 1.0000
40.1200 970.0000 1.0000
40.1600 947.0000 1.0000
40.2000 959.0000 1.0000
40.2400 897.0000 1.0000
40.2800 943.0000 1.0000
40.3200 940.0000 1.0000
40.3600 957.0000 1.0000
40.4000 917.0000 1.0000
40.4400 942.0000 1.0000
40.4800 950.0000 1.0000
40.5200 940.0000 1.0000
40.5600 951.0000 1.0000
40.6000 870.0000 1.0000
40.6400 954.0000 1.0000
40.6800 954.0000 1.0000
40.7200 928.0000 1.0000
40.7600 910.0000 1.0000
40.8000 915.0000 1.0000
40.8400 933.0000 1.0000
40.8800 889.0000 1.0000
40.9200 911.0000 1.0000
40.9600 898.0000 1.0000
41.0000 937.0000 1.0000
41.0400 946.0000 1.0000
41.0800 923.0000 1.0000
41.1200 876.0000 1.0000
41.1600 938.0000 1.0000
41.2000 917.0000 1.0000
41.2400 922.0000 1.0000
41.2800 874.0000 1.0000
41.3200 920.0000 1.0000
41.3600 895.0000 1.0000
41.4000 850.0000 1.0000
41.4400 989.0000 1.0000
41.4800 932.0000 1.0000
41.5200 937.0000 1.0000
41.5600 933.0000 1.0000
41.6000 917.0000 1.0000
41.6400 868.0000 1.0000
41.6800 914.0000 1.0000
41.7200 922.0000 1.0000
41.7600 906.0000 1.0000
41.8000 933.0000 1.0000
41.8400 927.0000 1.0000
41.8800 963.0000 1.0000
41.9200 935.0000 1.0000
41.9600 936.0000 1.0000
42.0000 916.0000 1.0000
42.0400 911.0000 1.0000
42.0800 902.0000 1.0000
42.1200 871.0000 1.0000
42.1600 892.0000 1.0000
42.2000 892.0000 1.0000
42.2400 897.0000 1.0000
42.2800 892.0000 1.0000
42.3200 897.0000 1.0000
42.3600 871.0000 1.0000
42.4000 929.0000 1.0000
42.4400 857.0000 1.0000
42.4800 858.0000 1.0000
42.5200 904.0000 1.0000
42.5600 885.0000 1.0000
42.6000 914.0000 1.0000
42.6400 840.0000 1.0000
42.6800 931.0000 1.0000
42.7200 903.0000 1.0000
42.7600 905.0000 1.0000
42.8000 901.0000 1.0000
42.8400 902.0000 1.0000
42.8800 856.0000 1.0000
42.9200 881.0000 1.0000
42.9600 880.0000 1.0000
43.0000 905.0000 1.0000
43.0400 890.0000 1.0000
43.0800 904.0000 1.0000
43.1200 961.0000 1.0000
43.1600 961.0000 1.0000
43.2000 978.0000 1.0000
43.2400 989.0000 1.0000
43.2800 977.0000 1.0000
43.3200 941.0000 1.0000
43.3600 943.0000 1.0000
43.4000 931.0000 1.0000
43.4400 914.0000 1.0000
43.4800 887.0000 1.0000
43.5200 910.0000 1.0000
43.5600 850.0000 1.0000
43.6000 863.0000 1.0000
43.6400 898.0000 1.0000
43.6800 927.0000 1.0000
43.7200 877.0000 1.0000
43.7600 899.0000 1.0000
43.8000 915.0000 1.0000
43.8400 904.0000 1.0000
43.8800 871.0000 1.0000
43.9200 856.0000 1.0000
43.9600 889.0000 1.0000
44.0000 818.0000 1.0000
44.0400 819.0000 1.0000
44.0800 841.0000 1.0000
44.1200 902.0000 1.0000
44.1600 871.0000 1.0000
44.2000 888.0000 1.0000
44.2400 850.0000 1.0000
44.2800 897.0000 1.0000
44.3200 848.0000 1.0000
44.3600 859.0000 1.0000
44.4000 918.0000 1.0000
44.4400 856.0000 1.0000
44.4800 938.0000 1.0000
44.5200 842.0000 1.0000
44.5600 885.0000 1.0000
44.6000 888.0000 1.0000
44.6400 854.0000 1.0000
44.6800 850.0000 1.0000
44.7200 843.0000 1.0000
44.7600 810.0000 1.0000
44.8000 900.0000 1.0000
44.8400 830.0000 1.0000
44.8800 808.0000 1.0000
44.9200 832.0000 1.0000
44.9600 816.0000 1.0000
45.0000 864.0000 1.0000
45.0400 878.0000 1.0000
45.0800 898.0000 1.0000
45.1200 828.0000 1.0000
45.1600 810.0000 1.0000
45.2000 843.0000 1.0000
45.2400 800.0000 1.0000
45.2800 837.0000 1.0000
45.3200 837.0000 1.0000
45.3600 801.0000 1.0000
45.4000 794.0000 1.0000
45.4400 899.0000 1.0000
45.4800 789.0000 1.0000
45.5200 847.0000 1.0000
45.5600 860.0000 1.0000
45.6000 832.0000 1.0000
45.6400 829.0000 1.0000
45.6800 826.0000 1.0000
45.7200 803.0000 1.0000
45.7600 849.0000 1.0000
45.8000 819.0000 1.0000
45.8400 885.0000 1.0000
45.8800 844.0000 1.0000
45.9200 869.0000 1.0000
45.9600 802.0000 1.0000
46.0000 807.0000 1.0000
46.0400 830.0000 1.0000
46.0800 806.0000 1.0000
46.1200 811.0000 1.0000
46.1600 837.0000 1.0000
46.2000 849.0000 1.0000
46.2400 858.0000 1.0000
46.2800 808.0000 1.0000
46.3200 796.0000 1.0000
46.3600 826.0000 1.0000
46.4000 784.0000 1.0000
46.4400 780.0000 1.0000
46.4800 805.0000 1.0000
46.5200 798.0000 1.0000
46.5600 825.0000 1.0000
46.6000 826.0000 1.0000
46.6400 835.0000 1.0000
46.6800 805.0000 1.0000
46.7200 790.0000 1.0000
46.7600 821.0000 1.0000
46.8000 773.0000 1.0000
46.8400 803.0000 1.0000
46.8800 818.0000 1.0000
46.9200 813.0000 1.0000
46.9600 806.0000 1.0000
47.0000 931.0000 1.0000
47.0400 778.0000 1.0000
47.0800 859.0000 1.0000
47.1200 791.0000 1.0000
47.1600 831.0000 1.0000
47.2000 788.0000 1.0000
47.2400 752.0000 1.0000
47.2800 814.0000 1.0000
47.3200 845.0000 1.0000
47.3600 803.0000 1.0000
47.4000 817.0000 1.0000
47.4400 775.0000 1.0000
47.4800 743.0000 1.0000
47.5200 795.0000 1.0000
47.5600 780.0000 1.0000
47.6000 820.0000 1.0000
47.6400 823.0000 1.0000
47.6800 773.0000 1.0000
47.7200 822.0000 1.0000
47.7600 784.0000 1.0000
47.8000 797.0000 1.0000
47.8400 795.0000 1.0000
47.8800 797.0000 1.0000
47.9200 748.0000 1.0000
47.9600 798.0000 1.0000
48.0000 768.0000 1.0000
48.0400 811.0000 1.0000
48.0800 787.0000 1.0000
48.1200 831.0000 1.0000
48.1600 779.0000 1.0000
48.2000 749.0000 1.0000
48.2400 787.0000 1.0000
48.2800 801.0000 1.0000
48.3200 809.0000 1.0000
48.3600 789.0000 1.0000
48.4000 796.0000 1.0000
48.4400 777.0000 1.0000
48.4800 771.0000 1.0000
48.5200 773.0000 1.0000
48.5600 772.0000 1.0000
48.6000 785.0000 1.0000
48.6400 709.0000 1.0000
48.6800 780.0000 1.0000
48.7200 745.0000 1.0000
48.7600 755.0000 1.0000
48.8000 817.0000 1.0000
48.8400 742.0000 1.0000
48.8800 757.0000 1.0000
48.9200 771.0000 1.0000
48.9600 770.0000 1.0000
49.0000 821.0000 1.0000
49.0400 800.0000 1.0000
49.0800 720.0000 1.0000
49.1200 757.0000 1.0000
49.1600 786.0000 1.0000
49.2000 757.0000 1.0000
49.2400 758.0000 1.0000
49.2800 765.0000 1.0000
49.3200 732.0000 1.0000
49.3600 751.0000 1.0000
49.4000 759.0000 1.0000
49.4400 730.0000 1.0000
49.4800 777.0000 1.0000
49.5200 757.0000 1.0000
49.5600 817.0000 1.0000
49.6000 728.0000 1.0000
49.6400 736.0000 1.0000
49.6800 739.0000 1.0000
49.7200 752.0000 1.0000
49.7600 742.0000 1.0000
49.8000 784.0000 1.0000
49.8400 749.0000 1.0000
49.8800 784.0000 1.0000
49.9200 774.0000 1.0000
49.9600 780.0000 1.0000
50.0000 759.0000 1.0000
50.0400 786.0000 1.0000
50.0800 785.0000 1.0000
50.1200 764.0000 1.0000
50.1600 810.0000 1.0000
50.2000 785.0000 1.0000
50.2400 799.0000 1.0000
50.2800 783.0000 1.0000
50.3200 789.0000 1.0000
50.3600 747.0000 1.0000
50.4000 714.0000 1.0000
50.4400 758.0000 1.0000
50.4800 790.0000 1.0000
50.5200 823.0000 1.0000
50.5600 806.0000 1.0000
50.6000 766.0000 1.0000
50.6400 794.0000 1.0000
50.6800 797.0000 1.0000
50.7200 802.0000 1.0000
50.7600 739.0000 1.0000
50.8000 775.0000 1.0000
50.8400 744.0000 1.0000
50.8800 800.0000 1.0000
50.9200 813.0000 1.0000
50.9600 725.0000 1.0000
51.0000 766.0000 1.0000
51.0400 754.0000 1.0000
51.0800 826.0000 1.0000
51.1200 759.0000 1.0000
51.1600 785.0000 1.0000
51.2000 755.0000 1.0000
51.2400 763.0000 1.0000
51.2800 833.0000 1.0000
51.3200 775.0000 1.0000
51.3600 757.0000 1.0000
51.4000 818.0000 1.0000
51.4400 739.0000 1.0000
51.4800 757.0000 1.0000
51.5200 776.0000 1.0000
51.5600 790.0000 1.0000
51.6000 754.0000 1.0000
51.6400 878.0000 1.0000
51.6800 814.0000 1.0000
51.7200 808.0000 1.0000
51.7600 861.0000 1.0000
51.8000 844.0000 1.0000
51.8400 871.0000 1.0000
51.8800 879.0000 1.0000
51.9200 964.0000 1.0000
51.9600 1024.0000 1.0000
52.0000 1143.0000 1.0000
52.0400 1296.0000 1.0000
52.0800 1523.0000 1.0000
52.1200 1897.0000 1.0000
52.1600 2322.0000 1.0000
52.2000 3240.0000 1.0000
52.2400 4301.0000 1.0000
52.2800 4777.0000 1.0000
52.3200 4524.0000 1.0000
52.3600 3965.0000 1.0000
52.4000 3639.0000 1.0000
52.4400 3171.0000 1.0000
52.4800 2474.0000 1.0000
52.5200 1968.0000 1.0000
52.5600 1532.0000 1.0000
52.6000 1300.0000 1.0000
52.6400 1160.0000 1.0000
52.6800 1051.0000 1.0000
52.7200 1000.0000 1.0000
52.7600 941.0000 1.0000
52.8000 910.0000 1.0000
52.8400 862.0000 1.0000
52.8800 775.0000 1.0000
52.9200 825.0000 1.0000
52.9600 822.0000 1.0000
53.0000 809.0000 1.0000
53.0400 846.0000 1.0000
53.0800 813.0000 1.0000
53.1200 769.0000 1.0000
53.1600 796.0000 1.0000
53.2000 771.0000 1.0000
53.2400 752.0000 1.0000
53.2800 748.0000 1.0000
53.3200 765.0000 1.0000
53.3600 727.0000 1.0000
53.4000 775.0000 1.0000
53.4400 761.0000 1.0000
53.4800 785.0000 1.0000
53.5200 750.0000 1.0000
53.5600 780.0000 1.0000
53.6000 736.0000 1.0000
53.6400 730.0000 1.0000
53.6800 751.0000 1.0000
53.7200 770.0000 1.0000
53.7600 773.0000 1.0000
53.8000 806.0000 1.0000
53.8400 739.0000 1.0000
53.8800 788.0000 1.0000
53.9200 734.0000 1.0000
53.9600 744.0000 1.0000
54.0000 714.0000 1.0000
54.0400 752.0000 1.0000
54.0800 723.0000 1.0000
54.1200 743.0000 1.0000
54.1600 743.0000 1.0000
54.2000 774.0000 1.0000
54.2400 767.0000 1.0000
54.2800 753.0000 1.0000
54.3200 745.0000 1.0000
54.3600 765.0000 1.0000
54.4000 751.0000 1.0000
54.4400 726.0000 1.0000
54.4800 747.0000 1.0000
54.5200 767.0000 1.0000
54.5600 742.0000 1.0000
54.6000 747.0000 1.0000
54.6400 800.0000 1.0000
54.6800 781.0000 1.0000
54.7200 779.0000 1.0000
54.7600 788.0000 1.0000
54.8000 775.0000 1.0000
54.8400 784.0000 1.0000
54.8800 795.0000 1.0000
54.9200 807.0000 1.0000
54.9600 798.0000 1.0000
55.0000 806.0000 1.0000
55.0400 805.0000 1.0000
55.0800 862.0000 1.0000
55.1200 904.0000 1.0000
55.1600 967.0000 1.0000
55.2000 947.0000 1.0000
55.2400 1097.0000 1.0000
55.2800 1084.0000 1.0000
55.3200 1103.0000 1.0000
55.3600 1126.0000 1.0000
55.4000 1107.0000 1.0000
55.4400 1023.0000 1.0000
55.4800 1013.0000 1.0000
55.5200 943.0000 1.0000
55.5600 886.0000 1.0000
55.6000 862.0000 1.0000
55.6400 820.0000 1.0000
55.6800 806.0000 1.0000
55.7200 785.0000 1.0000
55.7600 787.0000 1.0000
55.8000 751.0000 1.0000
55.8400 754.0000 1.0000
55.8800 726.0000 1.0000
55.9200 684.0000 1.0000
55.9600 740.0000 1.0000
56.0000 728.0000 1.0000
56.0400 712.0000 1.0000
56.0800 731.0000 1.0000
56.1200 753.0000 1.0000
56.1600 797.0000 1.0000
56.2000 748.0000 1.0000
56.2400 759.0000 1.0000
56.2800 720.0000 1.0000
56.3200 751.0000 1.0000
56.3600 688.0000 1.0000
56.4000 730.0000 1.0000
56.4400 719.0000 1.0000
56.4800 694.0000 1.0000
56.5200 689.0000 1.0000
56.5600 745.0000 1.0000
56.6000 721.0000 1.0000
56.6400 742.0000 1.0000
56.6800 680.0000 1.0000
56.7200 702.0000 1.0000
56.7600 742.0000 1.0000
56.8000 717.0000 1.0000
56.8400 680.0000 1.0000
56.8800 752.0000 1.0000
56.9200 721.0000 1.0000
56.9600 753.0000 1.0000
57.0000 777.0000 1.0000
57.0400 735.0000 1.0000
57.0800 720.0000 1.0000
57.1200 745.0000 1.0000
57.1600 711.0000 1.0000
57.2000 727.0000 1.0000
57.2400 730.0000 1.0000
57.2800 728.0000 1.0000
57.3200 717.0000 1.0000
57.3600 718.0000 1.0000
57.4000 740.0000 1.0000
57.4400 694.0000 1.0000
57.4800 728.0000 1.0000
57.5200 689.0000 1.0000
57.5600 746.0000 1.0000
57.6000 699.0000 1.0000
57.6400 658.0000 1.0000
57.6800 733.0000 1.0000
57.7200 751.0000 1.0000
57.7600 737.0000 1.0000
57.8000 698.0000 1.0000
57.8400 758.0000 1.0000
57.8800 712.0000 1.0000
57.9200 664.0000 1.0000
57.9600 764.0000 1.0000
58.0000 761.0000 1.0000
58.0400 725.0000 1.0000
58.0800 748.0000 1.0000
58.1200 752.0000 1.0000
58.1600 742.0000 1.0000
58.2000 731.0000 1.0000
58.2400 726.0000 1.0000
58.2800 731.0000 1.0000
58.3200 681.0000 1.0000
58.3600 715.0000 1.0000
58.4000 728.0000 1.0000
58.4400 729.0000 1.0000
58.4800 700.0000 1.0000
58.5200 710.0000 1.0000
58.5600 758.0000 1.0000
58.6000 725.0000 1.0000
58.6400 709.0000 1.0000
58.6800 748.0000 1.0000
58.7200 778.0000 1.0000
58.7600 721.0000 1.0000
58.8000 693.0000 1.0000
58.8400 746.0000 1.0000
58.8800 704.0000 1.0000
58.9200 730.0000 1.0000
58.9600 713.0000 1.0000
59.0000 679.0000 1.0000
59.0400 684.0000 1.0000
59.0800 770.0000 1.0000
59.1200 717.0000 1.0000
59.1600 698.0000 1.0000
59.2000 729.0000 1.0000
59.2400 743.0000 1.0000
59.2800 656.0000 1.0000
59.3200 700.0000 1.0000
59.3600 682.0000 1.0000
59.4000 743.0000 1.0000
59.4400 694.0000 1.0000
59.4800 725.0000 1.0000
59.5200 712.0000 1.0000
59.5600 742.0000 1.0000
59.6000 700.0000 1.0000
59.6400 680.0000 1.0000
59.6800 733.0000 1.0000
59.7200 725.0000 1.0000
59.7600 779.0000 1.0000
59.8000 707.0000 1.0000
59.8400 725.0000 1.0000
59.8800 693.0000 1.0000
59.9200 748.0000 1.0000
59.9600 672.0000 1.0000
60.0000 713.0000 1.0000
60.0400 693.0000 1.0000
60.0800 686.0000 1.0000
60.1200 720.0000 1.0000
60.1600 721.0000 1.0000
60.2000 697.0000 1.0000
60.2400 724.0000 1.0000
60.2800 726.0000 1.0000
60.3200 718.0000 1.0000
60.3600 702.0000 1.0000
60.4000 738.0000 1.0000
60.4400 707.0000 1.0000
60.4800 720.0000 1.0000
60.5200 708.0000 1.0000
60.5600 714.0000 1.0000
60.6000 699.0000 1.0000
60.6400 704.0000 1.0000
60.6800 708.0000 1.0000
60.7200 745.0000 1.0000
60.7600 693.0000 1.0000
60.8000 706.0000 1.0000
60.8400 714.0000 1.0000
60.8800 738.0000 1.0000
60.9200 701.0000 1.0000
60.9600 720.0000 1.0000
61.0000 696.0000 1.0000
61.0400 772.0000 1.0000
61.0800 706.0000 1.0000
61.1200 744.0000 1.0000
61.1600 733.0000 1.0000
61.2000 686.0000 1.0000
61.2400 743.0000 1.0000
61.2800 735.0000 1.0000
61.3200 726.0000 1.0000
61.3600 735.0000 1.0000
61.4000 722.0000 1.0000
61.4400 744.0000 1.0000
61.4800 729.0000 1.0000
61.5200 749.0000 1.0000
61.5600 739.0000 1.0000
61.6000 737.0000 1.0000
61.6400 743.0000 1.0000
61.6800 732.0000 1.0000
61.7200 783.0000 1.0000
61.7600 754.0000 1.0000
61.8000 756.0000 1.0000
61.8400 757.0000 1.0000
61.8800 846.0000 1.0000
61.9200 814.0000 1.0000
61.9600 849.0000 1.0000
62.0000 957.0000 1.0000
62.0400 997.0000 1.0000
62.0800 1078.0000 1.0000
62.1200 1112.0000 1.0000
62.1600 1282.0000 1.0000
62.2000 1440.0000 1.0000
62.2400 1536.0000 1.0000
62.2800 1653.0000 1.0000
62.3200 1722.0000 1.0000
62.3600 1660.0000 1.0000
62.4000 1602.0000 1.0000
62.4400 1614.0000 1.0000
62.4800 1426.0000 1.0000
62.5200 1327.0000 1.0000
62.5600 1289.0000 1.0000
62.6000 1168.0000 1.0000
62.6400 1042.0000 1.0000
62.6800 1025.0000 1.0000
62.7200 1032.0000 1.0000
62.7600 911.0000 1.0000
62.8000 850.0000 1.0000
62.8400 821.0000 1.0000
62.8800 792.0000 1.0000
62.9200 752.0000 1.0000
62.9600 798.0000 1.0000
63.0000 809.0000 1.0000
63.0400 746.0000 1.0000
63.0800 771.0000 1.0000
63.1200 806.0000 1.0000
63.1600 771.0000 1.0000
63.2000 800.0000 1.0000
63.2400 770.0000 1.0000
63.2800 783.0000 1.0000
63.3200 711.0000 1.0000
63.3600 741.0000 1.0000
63.4000 761.0000 1.0000
63.4400 758.0000 1.0000
63.4800 733.0000 1.0000
63.5200 663.0000 1.0000
63.5600 708.0000 1.0000
63.6000 686.0000 1.0000
63.6400 678.0000 1.0000
63.6800 726.0000 1.0000
63.7200 748.0000 1.0000
63.7600 755.0000 1.0000
63.8000 688.0000 1.0000
63.8400 669.0000 1.0000
63.8800 713.0000 1.0000
63.9200 702.0000 1.0000
63.9600 766.0000 1.0000
64.0000 700.0000 1.0000
64.0400 709.0000 1.0000
64.0800 755.0000 1.0000
64.1200 738.0000 1.0000
64.1600 703.0000 1.0000
64.2000 718.0000 1.0000
64.2400 767.0000 1.0000
64.2800 704.0000 1.0000
64.3200 735.0000 1.0000
64.3600 721.0000 1.0000
64.4000 779.0000 1.0000
64.4400 826.0000 1.0000
64.4800 789.0000 1.0000
64.5200 792.0000 1.0000
64.5600 844.0000 1.0000
64.6000 901.0000 1.0000
64.6400 934.0000 1.0000
64.6800 1016.0000 1.0000
64.7200 1004.0000 1.0000
64.7600 943.0000 1.0000
64.8000 943.0000 1.0000
64.8400 993.0000 1.0000
64.8800 948.0000 1.0000
64.9200 924.0000 1.0000
64.9600 857.0000 1.0000
65.0000 861.0000 1.0000
65.0400 845.0000 1.0000
65.0800 815.0000 1.0000
65.1200 813.0000 1.0000
65.1600 794.0000 1.0000
65.2000 789.0000 1.0000
65.2400 791.0000 1.0000
65.2800 784.0000 1.0000
65.3200 739.0000 1.0000
65.3600 748.0000 1.0000
65.4000 738.0000 1.0000
65.4400 729.0000 1.0000
65.4800 739.0000 1.0000
65.5200 755.0000 1.0000
65.5600 738.0000 1.0000
65.6000 754.0000 1.0000
65.6400 770.0000 1.0000
65.6800 800.0000 1.0000
65.7200 822.0000 1.0000
65.7600 752.0000 1.0000
65.8000 761.0000 1.0000
65.8400 820.0000 1.0000
65.8800 882.0000 1.0000
65.9200 924.0000 1.0000
65.9600 954.0000 1.0000
66.0000 1043.0000 1.0000
66.0400 1077.0000 1.0000
66.0800 1346.0000 1.0000
66.1200 1535.0000 1.0000
66.1600 1922.0000 1.0000
66.2000 2288.0000 1.0000
66.2400 2608.0000 1.0000
66.2800 2646.0000 1.0000
66.3200 2530.0000 1.0000
66.3600 2332.0000 1.0000
66.4000 2216.0000 1.0000
66.4400 2147.0000 1.0000
66.4800 1919.0000 1.0000
66.5200 1647.0000 1.0000
66.5600 1309.0000 1.0000
66.6000 1266.0000 1.0000
66.6400 1117.0000 1.0000
66.6800 970.0000 1.0000
66.7200 941.0000 1.0000
66.7600 900.0000 1.0000
66.8000 851.0000 1.0000
66.8400 806.0000 1.0000
66.8800 774.0000 1.0000
66.9200 747.0000 1.0000
66.9600 807.0000 1.0000
67.0000 719.0000 1.0000
67.0400 679.0000 1.0000
67.0800 721.0000 1.0000
67.1200 779.0000 1.0000
67.1600 672.0000 1.0000
67.2000 690.0000 1.0000
67.2400 710.0000 1.0000
67.2800 691.0000 1.0000
67.3200 731.0000 1.0000
67.3600 666.0000 1.0000
67.4000 710.0000 1.0000
67.4400 680.0000 1.0000
67.4800 668.0000 1.0000
67.5200 669.0000 1.0000
67.5600 678.0000 1.0000
67.6000 634.0000 1.0000
67.6400 645.0000 1.0000
67.6800 709.0000 1.0000
67.7200 641.0000 1.0000
67.7600 647.0000 1.0000
67.8000 643.0000 1.0000
67.8400 666.0000 1.0000
67.8800 669.0000 1.0000
67.9200 676.0000 1.0000
67.9600 652.0000 1.0000
68.0000 690.0000 1.0000
68.0400 659.0000 1.0000
68.0800 716.0000 1.0000
68.1200 697.0000 1.0000
68.1600 634.0000 1.0000
68.2000 678.0000 1.0000
68.2400 641.0000 1.0000
68.2800 668.0000 1.0000
68.3200 651.0000 1.0000
68.3600 655.0000 1.0000
68.4000 631.0000 1.0000
68.4400 660.0000 1.0000
68.4800 658.0000 1.0000
68.5200 660.0000 1.0000
68.5600 649.0000 1.0000
68.6000 646.0000 1.0000
68.6400 666.0000 1.0000
68.6800 643.0000 1.0000
68.7200 633.0000 1.0000
68.7600 654.0000 1.0000
68.8000 660.0000 1.0000
68.8400 674.0000 1.0000
68.8800 643.0000 1.0000
68.9200 670.0000 1.0000
68.9600 631.0000 1.0000
69.0000 685.0000 1.0000
69.0400 657.0000 1.0000
69.0800 625.0000 1.0000
69.1200 660.0000 1.0000
69.1600 640.0000 1.0000
69.2000 640.0000 1.0000
69.2400 657.0000 1.0000
69.2800 635.0000 1.0000
69.3200 653.0000 1.0000
69.3600 704.0000 1.0000
69.4000 648.0000 1.0000
69.4400 651.0000 1.0000
69.4800 690.0000 1.0000
69.5200 632.0000 1.0000
69.5600 634.0000 1.0000
69.6000 675.0000 1.0000
69.6400 628.0000 1.0000
69.6800 621.0000 1.0000
69.7200 634.0000 1.0000
69.7600 640.0000 1.0000
69.8000 623.0000 1.0000
69.8400 623.0000 1.0000
69.8800 626.0000 1.0000
69.9200 614.0000 1.0000
69.9600 630.0000 1.0000
70.0000 613.0000 1.0000
*RAS_INT_END
*RAS_TEMPERATURE_START
*RAS_TEMPERATURE_END
*RAS_DATA_END