File: Section2_75_samples/XRD/No_056_NSS3_1.ras
*RAS_DATA_START
*RAS_HEADER_START
*DISP_FMT_X "%.2f"
*DISP_FMT_Y "%.0f"
*DISP_FULLSCALE "15918.0000000000"
*DISP_LINE_COLOR "255.0000000000"
*DISP_LINE_STYLE "0.0000000000"
*DISP_LINE_WIDTH "0.2500000000"
*DISP_NOTE "測定データ-12"
*DISP_OFFSET_Y "0.0000000000"
*DISP_PEAKSEARCH_UNIT_Y "cps"
*DISP_RANGE_BOTTOM "0.0000000000"
*DISP_RANGE_LEFT "20.0000000000"
*DISP_RANGE_LOGCUTOFF "0.0100000000"
*DISP_RANGE_RIGHT "70.0000000000"
*DISP_RANGE_TOP "15918.0000000000"
*DISP_SCALE_MODE_Y "0.0000000000"
*DISP_TAB_NAME "2θ/θ"
*DISP_TITLE_Y "強度"
*DISP_UNIT_Y "cps"
*DISP_WINDOW_NAME "MSG_MACROENGINE"
*FILE_COMMENT " "
*FILE_MD5 ""
*FILE_MEMO " "
*FILE_OPERATOR "Administrator"
*FILE_SAMPLE " "
*FILE_TYPE "RAS_RAW"
*FILE_USERGROUP "システムマネージャ"
*FILE_VERSION "1.0000000000"
*HW_ATTACHMENT_ID "ATT0025"
*HW_ATTACHMENT_NAME "標準|Standard"
*HW_COUNTER_ID-0 "CUT0025"
*HW_COUNTER_ID-1 "CUT0020"
*HW_COUNTER_ID-2 "CUT0020"
*HW_COUNTER_ID-3 "CSL0021"
*HW_COUNTER_ID-4 "CMC0021"
*HW_COUNTER_NAME-0 "D/teX Ultra|D/teX Ultra"
*HW_COUNTER_NAME-1 "None|None"
*HW_COUNTER_NAME-2 "None|None"
*HW_COUNTER_NAME-3 "BBM|BBM"
*HW_COUNTER_NAME-4 "検出器モノクロメータ|Detector monochromator"
*HW_COUNTER_SELECT_NAME "D/teX Ultra|D/teX Ultra"
*HW_GONIOMETER_ID "GON0023"
*HW_GONIOMETER_NAME "SmartLab|SmartLab"
*HW_GONIOMETER_RADIUS-0 "90.0"
*HW_GONIOMETER_RADIUS-1 "114.0"
*HW_GONIOMETER_RADIUS-2 "190.0"
*HW_GONIOMETER_RADIUS-3 "300.0"
*HW_GONIOMETER_RADIUS-4 "187.0"
*HW_GONIOMETER_RADIUS-5 "300.0"
*HW_GONIOMETER_RADIUS-6 "113.0"
*HW_GONIOMETER_RADIUS-7 "331.0"
*HW_I_OPT_ID-0 "CBO0021"
*HW_I_OPT_ID-1 "ICR0023"
*HW_I_OPT_ID-2 "ISL0021"
*HW_I_OPT_ID-3 "ISO0021"
*HW_I_OPT_ID-4 "IAD0021"
*HW_I_OPT_ID-5 "IPR0001"
*HW_I_OPT_NAME-0 "CBOユニット|CBO unit"
*HW_I_OPT_NAME-1 "標準入射光学ユニット|Standard incident optical unit"
*HW_I_OPT_NAME-2 "標準入射スリットボックス|Standard incident slit box"
*HW_I_OPT_NAME-3 "入射平行スリット|Incident parallel slit"
*HW_I_OPT_NAME-4 "長手制限スリット|Length limiting slit"
*HW_I_OPT_NAME-5 "None|None"
*HW_R_ATTENUATER_AUTOMODE "0"
*HW_R_OPT_ID-0 "RSS0021"
*HW_R_OPT_ID-1 "RCR0023"
*HW_R_OPT_ID-2 "RSO0021"
*HW_R_OPT_ID-3 "RRS0021"
*HW_R_OPT_ID-4 "ATN0021"
*HW_R_OPT_ID-5 "RFL0021"
*HW_R_OPT_ID-6 "RAD0021"
*HW_R_OPT_NAME-0 "標準受光スリットボックス1|Standard receiving slit box # 1"
*HW_R_OPT_NAME-1 "標準受光光学ユニット1|Standard receiving unit # 1"
*HW_R_OPT_NAME-2 "標準受光光学ユニット2|Standard receiving optical unit # 2"
*HW_R_OPT_NAME-3 "標準受光スリットボックス2|Standard receiving slit box # 2"
*HW_R_OPT_NAME-4 "標準アッテネータ|Standard Attenuator"
*HW_R_OPT_NAME-5 "Cu Kβ|Cu K-beta"
*HW_R_OPT_NAME-6 "調整用受光スリット|Alignment receiving slit"
*HW_SAMPLE_HOLDER_ID "SMP0023"
*HW_SAMPLE_HOLDER_NAME "標準Zステージ|Standard Z stage"
*HW_XG_CURRENT_MAX "50"
*HW_XG_CURRENT_MIN "2"
*HW_XG_CURRENT_RESOLUTION "1"
*HW_XG_CURRENT_UNIT "mA"
*HW_XG_FOCUS "1mm x 10mm"
*HW_XG_FOCUS_TYPE "Normal"
*HW_XG_ID ""
*HW_XG_NAME "3kW 封入管(ID:1200)|3kW Sealed tube(ID:1200)"
*HW_XG_TARGET_ATOMIC_NUMBER "29.0000000000"
*HW_XG_TARGET_NAME "Cu"
*HW_XG_TYPE "Hermetic"
*HW_XG_VOLTAGE_MAX "60"
*HW_XG_VOLTAGE_MIN "20"
*HW_XG_VOLTAGE_RESOLUTION "1"
*HW_XG_VOLTAGE_UNIT "kV"
*HW_XG_WATT_MAX "1.500"
*HW_XG_WATT_UNIT "kW"
*HW_XG_WAVE_LENGTH_ALPHA1 "1.540593"
*HW_XG_WAVE_LENGTH_ALPHA2 "1.544414"
*HW_XG_WAVE_LENGTH_BETA "1.392250"
*MEAS_COND_AXIS_NAME-0 "2θ/θ"
*MEAS_COND_AXIS_NAME-1 "2θ"
*MEAS_COND_AXIS_NAME-2 "ω"
*MEAS_COND_AXIS_NAME-3 "Z"
*MEAS_COND_AXIS_NAME-4 "2θ/ω"
*MEAS_COND_AXIS_NAME-5 "θs"
*MEAS_COND_AXIS_NAME-6 "θd"
*MEAS_COND_AXIS_NAME-7 "Ts"
*MEAS_COND_AXIS_NAME-8 "CBO選択スリット"
*MEAS_COND_AXIS_NAME-9 "M"
*MEAS_COND_AXIS_NAME-10 "入射平行スリット"
*MEAS_COND_AXIS_NAME-11 "入射スリット"
*MEAS_COND_AXIS_NAME-12 ""
*MEAS_COND_AXIS_NAME-13 "Zs"
*MEAS_COND_AXIS_NAME-14 "入射光学素子"
*MEAS_COND_AXIS_NAME-15 "長手制限スリット"
*MEAS_COND_AXIS_NAME-16 "センタースリット"
*MEAS_COND_AXIS_NAME-17 "フィルター"
*MEAS_COND_AXIS_NAME-18 "受光スリット1"
*MEAS_COND_AXIS_NAME-19 "受光スリット2"
*MEAS_COND_AXIS_NAME-20 "受光光学素子"
*MEAS_COND_AXIS_NAME-21 "受光平行スリット"
*MEAS_COND_AXIS_NAME-22 "調整用受光スリット"
*MEAS_COND_AXIS_NAME-23 ""
*MEAS_COND_AXIS_NAME-24 ""
*MEAS_COND_AXIS_NAME-25 "Zd"
*MEAS_COND_AXIS_NAME-26 "アッテネータ"
*MEAS_COND_AXIS_NAME-27 "検出器モノクロメータ"
*MEAS_COND_AXIS_NAME-28 "モノクロメータスリット"
*MEAS_COND_AXIS_NAME-29 "プライマリビーム"
*MEAS_COND_AXIS_NAME-30 "PHA"
*MEAS_COND_AXIS_NAME_INTERNAL-0 "TwoThetaTheta"
*MEAS_COND_AXIS_NAME_INTERNAL-1 "TwoTheta"
*MEAS_COND_AXIS_NAME_INTERNAL-2 "Omega"
*MEAS_COND_AXIS_NAME_INTERNAL-3 "Z"
*MEAS_COND_AXIS_NAME_INTERNAL-4 "TwoThetaOmega"
*MEAS_COND_AXIS_NAME_INTERNAL-5 "ThetaS"
*MEAS_COND_AXIS_NAME_INTERNAL-6 "ThetaD"
*MEAS_COND_AXIS_NAME_INTERNAL-7 "Ts"
*MEAS_COND_AXIS_NAME_INTERNAL-8 "CBO"
*MEAS_COND_AXIS_NAME_INTERNAL-9 "CBO-M"
*MEAS_COND_AXIS_NAME_INTERNAL-10 "IncidentSollerSlit"
*MEAS_COND_AXIS_NAME_INTERNAL-11 "IncidentSlitBox"
*MEAS_COND_AXIS_NAME_INTERNAL-12 "IncidentSlitBox-_Axis"
*MEAS_COND_AXIS_NAME_INTERNAL-13 "Zs"
*MEAS_COND_AXIS_NAME_INTERNAL-14 "IncidentMonochromator"
*MEAS_COND_AXIS_NAME_INTERNAL-15 "IncidentAxdSlit"
*MEAS_COND_AXIS_NAME_INTERNAL-16 "CenterSlit"
*MEAS_COND_AXIS_NAME_INTERNAL-17 "Filter"
*MEAS_COND_AXIS_NAME_INTERNAL-18 "ReceivingSlitBox1"
*MEAS_COND_AXIS_NAME_INTERNAL-19 "ReceivingSlitBox2"
*MEAS_COND_AXIS_NAME_INTERNAL-20 "ReceivingOptics"
*MEAS_COND_AXIS_NAME_INTERNAL-21 "ReceivingSollerSlit"
*MEAS_COND_AXIS_NAME_INTERNAL-22 "ReceivingAxdSlit"
*MEAS_COND_AXIS_NAME_INTERNAL-23 "ReceivingSlitBox1-_Axis"
*MEAS_COND_AXIS_NAME_INTERNAL-24 "ReceivingSlitBox2-_Axis"
*MEAS_COND_AXIS_NAME_INTERNAL-25 "ReceivingSlitBox2-Zd"
*MEAS_COND_AXIS_NAME_INTERNAL-26 "Attenuator"
*MEAS_COND_AXIS_NAME_INTERNAL-27 "CounterMonochromator"
*MEAS_COND_AXIS_NAME_INTERNAL-28 "CounterSlit"
*MEAS_COND_AXIS_NAME_INTERNAL-29 "IncidentPrimary"
*MEAS_COND_AXIS_NAME_INTERNAL-30 "PHA"
*MEAS_COND_AXIS_NAME_MAGICNO-0 "83951616.0000000000"
*MEAS_COND_AXIS_NAME_MAGICNO-1 "268632064.0000000000"
*MEAS_COND_AXIS_NAME_MAGICNO-2 "268500992.0000000000"
*MEAS_COND_AXIS_NAME_MAGICNO-3 "285278208.0000000000"
*MEAS_COND_AXIS_NAME_MAGICNO-4 "83951616.0000000000"
*MEAS_COND_AXIS_NAME_MAGICNO-5 "131072.0000000000"
*MEAS_COND_AXIS_NAME_MAGICNO-6 "131072.0000000000"
*MEAS_COND_AXIS_NAME_MAGICNO-7 "318898176.0000000000"
*MEAS_COND_AXIS_NAME_MAGICNO-8 "20971521.0000000000"
*MEAS_COND_AXIS_NAME_MAGICNO-9 "285343744.0000000000"
*MEAS_COND_AXIS_NAME_MAGICNO-10 "20971521.0000000000"
*MEAS_COND_AXIS_NAME_MAGICNO-11 "22020097.0000000000"
*MEAS_COND_AXIS_NAME_MAGICNO-12 "25165824.0000000000"
*MEAS_COND_AXIS_NAME_MAGICNO-13 "318898176.0000000000"
*MEAS_COND_AXIS_NAME_MAGICNO-14 "1.0000000000"
*MEAS_COND_AXIS_NAME_MAGICNO-15 "20971521.0000000000"
*MEAS_COND_AXIS_NAME_MAGICNO-16 "20971521.0000000000"
*MEAS_COND_AXIS_NAME_MAGICNO-17 "20971521.0000000000"
*MEAS_COND_AXIS_NAME_MAGICNO-18 "23068673.0000000000"
*MEAS_COND_AXIS_NAME_MAGICNO-19 "23068673.0000000000"
*MEAS_COND_AXIS_NAME_MAGICNO-20 "20971521.0000000000"
*MEAS_COND_AXIS_NAME_MAGICNO-21 "20971521.0000000000"
*MEAS_COND_AXIS_NAME_MAGICNO-22 "20971521.0000000000"
*MEAS_COND_AXIS_NAME_MAGICNO-23 "25165824.0000000000"
*MEAS_COND_AXIS_NAME_MAGICNO-24 "25165824.0000000000"
*MEAS_COND_AXIS_NAME_MAGICNO-25 "285343744.0000000000"
*MEAS_COND_AXIS_NAME_MAGICNO-26 "17301505.0000000000"
*MEAS_COND_AXIS_NAME_MAGICNO-27 "20971521.0000000000"
*MEAS_COND_AXIS_NAME_MAGICNO-28 "20971521.0000000000"
*MEAS_COND_AXIS_NAME_MAGICNO-29 "20971521.0000000000"
*MEAS_COND_AXIS_NAME_MAGICNO-30 "0.0000000000"
*MEAS_COND_AXIS_OFFSET-0 "-"
*MEAS_COND_AXIS_OFFSET-1 "-0.1081000000"
*MEAS_COND_AXIS_OFFSET-2 "0.3758000000"
*MEAS_COND_AXIS_OFFSET-3 "-"
*MEAS_COND_AXIS_OFFSET-4 "-"
*MEAS_COND_AXIS_OFFSET-5 "0.3758000000"
*MEAS_COND_AXIS_OFFSET-6 "-0.4839000000"
*MEAS_COND_AXIS_OFFSET-7 "-"
*MEAS_COND_AXIS_OFFSET-8 "-"
*MEAS_COND_AXIS_OFFSET-9 "-"
*MEAS_COND_AXIS_OFFSET-10 "-"
*MEAS_COND_AXIS_OFFSET-11 "-"
*MEAS_COND_AXIS_OFFSET-12 "-"
*MEAS_COND_AXIS_OFFSET-13 "-"
*MEAS_COND_AXIS_OFFSET-14 "-"
*MEAS_COND_AXIS_OFFSET-15 "-"
*MEAS_COND_AXIS_OFFSET-16 "-"
*MEAS_COND_AXIS_OFFSET-17 "-"
*MEAS_COND_AXIS_OFFSET-18 "-"
*MEAS_COND_AXIS_OFFSET-19 "-"
*MEAS_COND_AXIS_OFFSET-20 "-"
*MEAS_COND_AXIS_OFFSET-21 "-"
*MEAS_COND_AXIS_OFFSET-22 "-"
*MEAS_COND_AXIS_OFFSET-23 "-"
*MEAS_COND_AXIS_OFFSET-24 "-"
*MEAS_COND_AXIS_OFFSET-25 "-"
*MEAS_COND_AXIS_OFFSET-26 "-"
*MEAS_COND_AXIS_OFFSET-27 "-"
*MEAS_COND_AXIS_OFFSET-28 "-"
*MEAS_COND_AXIS_OFFSET-29 "-"
*MEAS_COND_AXIS_OFFSET-30 "-"
*MEAS_COND_AXIS_POSITION-0 "0.0000000000"
*MEAS_COND_AXIS_POSITION-1 "0.0000000000"
*MEAS_COND_AXIS_POSITION-2 "0.0000000000"
*MEAS_COND_AXIS_POSITION-3 "-0.5500000000"
*MEAS_COND_AXIS_POSITION-4 "0.0000000000"
*MEAS_COND_AXIS_POSITION-5 "0.0000000000"
*MEAS_COND_AXIS_POSITION-6 "0.0000000000"
*MEAS_COND_AXIS_POSITION-7 "-0.4278800000"
*MEAS_COND_AXIS_POSITION-8 "BB"
*MEAS_COND_AXIS_POSITION-9 "0.0000000000"
*MEAS_COND_AXIS_POSITION-10 "Soller_slit_5.0deg"
*MEAS_COND_AXIS_POSITION-11 "2/3deg"
*MEAS_COND_AXIS_POSITION-12 "2.2088000000"
*MEAS_COND_AXIS_POSITION-13 "-0.4140600000"
*MEAS_COND_AXIS_POSITION-14 "0.0000000000"
*MEAS_COND_AXIS_POSITION-15 "10.0mm"
*MEAS_COND_AXIS_POSITION-16 "None"
*MEAS_COND_AXIS_POSITION-17 "Cu_K-beta"
*MEAS_COND_AXIS_POSITION-18 "13.000mm"
*MEAS_COND_AXIS_POSITION-19 "13.000mm"
*MEAS_COND_AXIS_POSITION-20 "No_unit"
*MEAS_COND_AXIS_POSITION-21 "Soller_slit_5.0deg"
*MEAS_COND_AXIS_POSITION-22 "None"
*MEAS_COND_AXIS_POSITION-23 "13.0000000000"
*MEAS_COND_AXIS_POSITION-24 "13.0000000000"
*MEAS_COND_AXIS_POSITION-25 "0.0109400000"
*MEAS_COND_AXIS_POSITION-26 "Open"
*MEAS_COND_AXIS_POSITION-27 "None"
*MEAS_COND_AXIS_POSITION-28 "None"
*MEAS_COND_AXIS_POSITION-29 "None"
*MEAS_COND_AXIS_POSITION-30 "38.0000000000"
*MEAS_COND_AXIS_UNIT-0 "deg"
*MEAS_COND_AXIS_UNIT-1 "deg"
*MEAS_COND_AXIS_UNIT-2 "deg"
*MEAS_COND_AXIS_UNIT-3 "mm"
*MEAS_COND_AXIS_UNIT-4 "deg"
*MEAS_COND_AXIS_UNIT-5 "deg"
*MEAS_COND_AXIS_UNIT-6 "deg"
*MEAS_COND_AXIS_UNIT-7 "mm"
*MEAS_COND_AXIS_UNIT-8 ""
*MEAS_COND_AXIS_UNIT-9 "pulse"
*MEAS_COND_AXIS_UNIT-10 ""
*MEAS_COND_AXIS_UNIT-11 ""
*MEAS_COND_AXIS_UNIT-12 "mm"
*MEAS_COND_AXIS_UNIT-13 "mm"
*MEAS_COND_AXIS_UNIT-14 ""
*MEAS_COND_AXIS_UNIT-15 ""
*MEAS_COND_AXIS_UNIT-16 ""
*MEAS_COND_AXIS_UNIT-17 ""
*MEAS_COND_AXIS_UNIT-18 ""
*MEAS_COND_AXIS_UNIT-19 ""
*MEAS_COND_AXIS_UNIT-20 ""
*MEAS_COND_AXIS_UNIT-21 ""
*MEAS_COND_AXIS_UNIT-22 ""
*MEAS_COND_AXIS_UNIT-23 "mm"
*MEAS_COND_AXIS_UNIT-24 "mm"
*MEAS_COND_AXIS_UNIT-25 "mm"
*MEAS_COND_AXIS_UNIT-26 ""
*MEAS_COND_AXIS_UNIT-27 ""
*MEAS_COND_AXIS_UNIT-28 ""
*MEAS_COND_AXIS_UNIT-29 ""
*MEAS_COND_AXIS_UNIT-30 "div"
*MEAS_COND_COUNTER_CNTLOSS_CORR "0.0000000000"
*MEAS_COND_COUNTER_PHABASE "38.0000000000"
*MEAS_COND_COUNTER_PHAWINDOW "16.0000000000"
*MEAS_COND_COUNTER_PHA_UNIT "div"
*MEAS_COND_COUNTER_TAUDIFF "30.0000000000"
*MEAS_COND_COUNTER_TAUINT "0.0000000000"
*MEAS_COND_IRRADIATION_MODE "OFF"
*MEAS_COND_IRRADIATION_WIDTH ""
*MEAS_COND_OPT_ATTR "集中法"
*MEAS_COND_OPT_NAME "@集中法"
*MEAS_COND_UNSYMMETRIC_MODE "OFF"
*MEAS_COND_XG_CURRENT "30.0000000000"
*MEAS_COND_XG_VOLTAGE "40.0000000000"
*MEAS_COND_XG_WAVE_TYPE "Ka"
*MEAS_DATA_COUNT "5001.0000000000"
*MEAS_SCAN_AXIS_X "2θ/θ"
*MEAS_SCAN_AXIS_X_INTERNAL "TwoThetaTheta"
*MEAS_SCAN_END_TIME "07/12/21 18:58:54"
*MEAS_SCAN_MODE "CONTINUOUS"
*MEAS_SCAN_MONITOR "0"
*MEAS_SCAN_RESOLUTION_X "0.0002"
*MEAS_SCAN_SPEED "1.0"
*MEAS_SCAN_SPEED_UNIT "deg/min"
*MEAS_SCAN_START "20.0000000000"
*MEAS_SCAN_START_TIME "07/12/21 18:06:01"
*MEAS_SCAN_STEP "0.0100000000"
*MEAS_SCAN_STOP "70.0000000000"
*MEAS_SCAN_UNIT_X "deg"
*MEAS_SCAN_UNIT_Y "counts"
*RAS_HEADER_END
*RAS_INT_START
20.0000 1675.0000 1.0000
20.0400 1642.0000 1.0000
20.0800 1653.0000 1.0000
20.1200 1706.0000 1.0000
20.1600 1664.0000 1.0000
20.2000 1719.0000 1.0000
20.2400 1728.0000 1.0000
20.2800 1703.0000 1.0000
20.3200 1726.0000 1.0000
20.3600 1730.0000 1.0000
20.4000 1738.0000 1.0000
20.4400 1708.0000 1.0000
20.4800 1719.0000 1.0000
20.5200 1760.0000 1.0000
20.5600 1706.0000 1.0000
20.6000 1623.0000 1.0000
20.6400 1685.0000 1.0000
20.6800 1722.0000 1.0000
20.7200 1605.0000 1.0000
20.7600 1674.0000 1.0000
20.8000 1636.0000 1.0000
20.8400 1730.0000 1.0000
20.8800 1751.0000 1.0000
20.9200 1634.0000 1.0000
20.9600 1710.0000 1.0000
21.0000 1743.0000 1.0000
21.0400 1685.0000 1.0000
21.0800 1646.0000 1.0000
21.1200 1727.0000 1.0000
21.1600 1740.0000 1.0000
21.2000 1668.0000 1.0000
21.2400 1739.0000 1.0000
21.2800 1658.0000 1.0000
21.3200 1743.0000 1.0000
21.3600 1714.0000 1.0000
21.4000 1696.0000 1.0000
21.4400 1704.0000 1.0000
21.4800 1761.0000 1.0000
21.5200 1743.0000 1.0000
21.5600 1703.0000 1.0000
21.6000 1676.0000 1.0000
21.6400 1701.0000 1.0000
21.6800 1757.0000 1.0000
21.7200 1684.0000 1.0000
21.7600 1691.0000 1.0000
21.8000 1713.0000 1.0000
21.8400 1703.0000 1.0000
21.8800 1703.0000 1.0000
21.9200 1772.0000 1.0000
21.9600 1698.0000 1.0000
22.0000 1702.0000 1.0000
22.0400 1720.0000 1.0000
22.0800 1725.0000 1.0000
22.1200 1697.0000 1.0000
22.1600 1743.0000 1.0000
22.2000 1726.0000 1.0000
22.2400 1720.0000 1.0000
22.2800 1774.0000 1.0000
22.3200 1799.0000 1.0000
22.3600 1699.0000 1.0000
22.4000 1700.0000 1.0000
22.4400 1757.0000 1.0000
22.4800 1726.0000 1.0000
22.5200 1806.0000 1.0000
22.5600 1787.0000 1.0000
22.6000 1703.0000 1.0000
22.6400 1769.0000 1.0000
22.6800 1743.0000 1.0000
22.7200 1697.0000 1.0000
22.7600 1729.0000 1.0000
22.8000 1739.0000 1.0000
22.8400 1772.0000 1.0000
22.8800 1805.0000 1.0000
22.9200 1787.0000 1.0000
22.9600 1820.0000 1.0000
23.0000 1756.0000 1.0000
23.0400 1788.0000 1.0000
23.0800 1801.0000 1.0000
23.1200 1687.0000 1.0000
23.1600 1756.0000 1.0000
23.2000 1800.0000 1.0000
23.2400 1786.0000 1.0000
23.2800 1722.0000 1.0000
23.3200 1737.0000 1.0000
23.3600 1787.0000 1.0000
23.4000 1765.0000 1.0000
23.4400 1731.0000 1.0000
23.4800 1772.0000 1.0000
23.5200 1734.0000 1.0000
23.5600 1759.0000 1.0000
23.6000 1692.0000 1.0000
23.6400 1763.0000 1.0000
23.6800 1784.0000 1.0000
23.7200 1772.0000 1.0000
23.7600 1768.0000 1.0000
23.8000 1818.0000 1.0000
23.8400 1765.0000 1.0000
23.8800 1772.0000 1.0000
23.9200 1793.0000 1.0000
23.9600 1817.0000 1.0000
24.0000 1725.0000 1.0000
24.0400 1755.0000 1.0000
24.0800 1772.0000 1.0000
24.1200 1767.0000 1.0000
24.1600 1803.0000 1.0000
24.2000 1840.0000 1.0000
24.2400 1703.0000 1.0000
24.2800 1786.0000 1.0000
24.3200 1833.0000 1.0000
24.3600 1811.0000 1.0000
24.4000 1795.0000 1.0000
24.4400 1826.0000 1.0000
24.4800 1731.0000 1.0000
24.5200 1816.0000 1.0000
24.5600 1825.0000 1.0000
24.6000 1809.0000 1.0000
24.6400 1803.0000 1.0000
24.6800 1789.0000 1.0000
24.7200 1788.0000 1.0000
24.7600 1808.0000 1.0000
24.8000 1797.0000 1.0000
24.8400 1868.0000 1.0000
24.8800 1777.0000 1.0000
24.9200 1819.0000 1.0000
24.9600 1802.0000 1.0000
25.0000 1956.0000 1.0000
25.0400 1828.0000 1.0000
25.0800 1876.0000 1.0000
25.1200 1793.0000 1.0000
25.1600 1884.0000 1.0000
25.2000 1874.0000 1.0000
25.2400 1832.0000 1.0000
25.2800 1764.0000 1.0000
25.3200 1782.0000 1.0000
25.3600 1783.0000 1.0000
25.4000 1781.0000 1.0000
25.4400 1827.0000 1.0000
25.4800 1785.0000 1.0000
25.5200 1848.0000 1.0000
25.5600 1867.0000 1.0000
25.6000 1855.0000 1.0000
25.6400 1774.0000 1.0000
25.6800 1798.0000 1.0000
25.7200 1797.0000 1.0000
25.7600 1819.0000 1.0000
25.8000 1782.0000 1.0000
25.8400 1790.0000 1.0000
25.8800 1831.0000 1.0000
25.9200 1934.0000 1.0000
25.9600 1783.0000 1.0000
26.0000 1791.0000 1.0000
26.0400 1859.0000 1.0000
26.0800 1895.0000 1.0000
26.1200 1834.0000 1.0000
26.1600 1893.0000 1.0000
26.2000 1839.0000 1.0000
26.2400 1807.0000 1.0000
26.2800 1907.0000 1.0000
26.3200 1896.0000 1.0000
26.3600 1862.0000 1.0000
26.4000 1837.0000 1.0000
26.4400 1855.0000 1.0000
26.4800 1977.0000 1.0000
26.5200 1872.0000 1.0000
26.5600 1888.0000 1.0000
26.6000 1959.0000 1.0000
26.6400 1994.0000 1.0000
26.6800 2002.0000 1.0000
26.7200 2075.0000 1.0000
26.7600 2041.0000 1.0000
26.8000 2114.0000 1.0000
26.8400 2159.0000 1.0000
26.8800 2115.0000 1.0000
26.9200 2250.0000 1.0000
26.9600 2396.0000 1.0000
27.0000 2571.0000 1.0000
27.0400 2895.0000 1.0000
27.0800 3133.0000 1.0000
27.1200 3627.0000 1.0000
27.1600 4309.0000 1.0000
27.2000 5400.0000 1.0000
27.2400 6578.0000 1.0000
27.2800 7087.0000 1.0000
27.3200 6595.0000 1.0000
27.3600 5704.0000 1.0000
27.4000 4530.0000 1.0000
27.4400 3713.0000 1.0000
27.4800 3183.0000 1.0000
27.5200 2825.0000 1.0000
27.5600 2637.0000 1.0000
27.6000 2382.0000 1.0000
27.6400 2316.0000 1.0000
27.6800 2182.0000 1.0000
27.7200 2102.0000 1.0000
27.7600 2072.0000 1.0000
27.8000 2022.0000 1.0000
27.8400 1933.0000 1.0000
27.8800 1904.0000 1.0000
27.9200 1984.0000 1.0000
27.9600 1898.0000 1.0000
28.0000 1876.0000 1.0000
28.0400 1827.0000 1.0000
28.0800 1910.0000 1.0000
28.1200 1774.0000 1.0000
28.1600 1792.0000 1.0000
28.2000 1871.0000 1.0000
28.2400 1760.0000 1.0000
28.2800 1857.0000 1.0000
28.3200 1821.0000 1.0000
28.3600 1859.0000 1.0000
28.4000 1745.0000 1.0000
28.4400 1816.0000 1.0000
28.4800 1749.0000 1.0000
28.5200 1797.0000 1.0000
28.5600 1733.0000 1.0000
28.6000 1735.0000 1.0000
28.6400 1757.0000 1.0000
28.6800 1730.0000 1.0000
28.7200 1762.0000 1.0000
28.7600 1785.0000 1.0000
28.8000 1731.0000 1.0000
28.8400 1709.0000 1.0000
28.8800 1727.0000 1.0000
28.9200 1683.0000 1.0000
28.9600 1735.0000 1.0000
29.0000 1690.0000 1.0000
29.0400 1670.0000 1.0000
29.0800 1713.0000 1.0000
29.1200 1721.0000 1.0000
29.1600 1724.0000 1.0000
29.2000 1775.0000 1.0000
29.2400 1708.0000 1.0000
29.2800 1681.0000 1.0000
29.3200 1699.0000 1.0000
29.3600 1734.0000 1.0000
29.4000 1693.0000 1.0000
29.4400 1712.0000 1.0000
29.4800 1686.0000 1.0000
29.5200 1703.0000 1.0000
29.5600 1665.0000 1.0000
29.6000 1736.0000 1.0000
29.6400 1726.0000 1.0000
29.6800 1669.0000 1.0000
29.7200 1700.0000 1.0000
29.7600 1671.0000 1.0000
29.8000 1636.0000 1.0000
29.8400 1665.0000 1.0000
29.8800 1661.0000 1.0000
29.9200 1640.0000 1.0000
29.9600 1705.0000 1.0000
30.0000 1600.0000 1.0000
30.0400 1669.0000 1.0000
30.0800 1606.0000 1.0000
30.1200 1641.0000 1.0000
30.1600 1621.0000 1.0000
30.2000 1625.0000 1.0000
30.2400 1694.0000 1.0000
30.2800 1671.0000 1.0000
30.3200 1706.0000 1.0000
30.3600 1690.0000 1.0000
30.4000 1599.0000 1.0000
30.4400 1642.0000 1.0000
30.4800 1619.0000 1.0000
30.5200 1627.0000 1.0000
30.5600 1642.0000 1.0000
30.6000 1655.0000 1.0000
30.6400 1668.0000 1.0000
30.6800 1617.0000 1.0000
30.7200 1635.0000 1.0000
30.7600 1587.0000 1.0000
30.8000 1611.0000 1.0000
30.8400 1591.0000 1.0000
30.8800 1610.0000 1.0000
30.9200 1636.0000 1.0000
30.9600 1623.0000 1.0000
31.0000 1570.0000 1.0000
31.0400 1637.0000 1.0000
31.0800 1604.0000 1.0000
31.1200 1609.0000 1.0000
31.1600 1593.0000 1.0000
31.2000 1557.0000 1.0000
31.2400 1512.0000 1.0000
31.2800 1564.0000 1.0000
31.3200 1593.0000 1.0000
31.3600 1572.0000 1.0000
31.4000 1575.0000 1.0000
31.4400 1571.0000 1.0000
31.4800 1616.0000 1.0000
31.5200 1584.0000 1.0000
31.5600 1529.0000 1.0000
31.6000 1601.0000 1.0000
31.6400 1579.0000 1.0000
31.6800 1582.0000 1.0000
31.7200 1559.0000 1.0000
31.7600 1568.0000 1.0000
31.8000 1600.0000 1.0000
31.8400 1600.0000 1.0000
31.8800 1613.0000 1.0000
31.9200 1576.0000 1.0000
31.9600 1625.0000 1.0000
32.0000 1601.0000 1.0000
32.0400 1611.0000 1.0000
32.0800 1483.0000 1.0000
32.1200 1571.0000 1.0000
32.1600 1577.0000 1.0000
32.2000 1544.0000 1.0000
32.2400 1512.0000 1.0000
32.2800 1527.0000 1.0000
32.3200 1554.0000 1.0000
32.3600 1556.0000 1.0000
32.4000 1499.0000 1.0000
32.4400 1495.0000 1.0000
32.4800 1506.0000 1.0000
32.5200 1475.0000 1.0000
32.5600 1540.0000 1.0000
32.6000 1562.0000 1.0000
32.6400 1487.0000 1.0000
32.6800 1533.0000 1.0000
32.7200 1477.0000 1.0000
32.7600 1546.0000 1.0000
32.8000 1556.0000 1.0000
32.8400 1546.0000 1.0000
32.8800 1468.0000 1.0000
32.9200 1487.0000 1.0000
32.9600 1498.0000 1.0000
33.0000 1502.0000 1.0000
33.0400 1484.0000 1.0000
33.0800 1487.0000 1.0000
33.1200 1443.0000 1.0000
33.1600 1499.0000 1.0000
33.2000 1506.0000 1.0000
33.2400 1520.0000 1.0000
33.2800 1444.0000 1.0000
33.3200 1463.0000 1.0000
33.3600 1449.0000 1.0000
33.4000 1450.0000 1.0000
33.4400 1528.0000 1.0000
33.4800 1483.0000 1.0000
33.5200 1428.0000 1.0000
33.5600 1502.0000 1.0000
33.6000 1507.0000 1.0000
33.6400 1415.0000 1.0000
33.6800 1499.0000 1.0000
33.7200 1563.0000 1.0000
33.7600 1520.0000 1.0000
33.8000 1532.0000 1.0000
33.8400 1530.0000 1.0000
33.8800 1652.0000 1.0000
33.9200 1650.0000 1.0000
33.9600 1640.0000 1.0000
34.0000 1566.0000 1.0000
34.0400 1656.0000 1.0000
34.0800 1612.0000 1.0000
34.1200 1632.0000 1.0000
34.1600 1673.0000 1.0000
34.2000 1681.0000 1.0000
34.2400 1840.0000 1.0000
34.2800 1888.0000 1.0000
34.3200 2065.0000 1.0000
34.3600 2339.0000 1.0000
34.4000 2794.0000 1.0000
34.4400 3040.0000 1.0000
34.4800 3126.0000 1.0000
34.5200 2956.0000 1.0000
34.5600 2750.0000 1.0000
34.6000 2409.0000 1.0000
34.6400 2137.0000 1.0000
34.6800 1928.0000 1.0000
34.7200 1796.0000 1.0000
34.7600 1763.0000 1.0000
34.8000 1604.0000 1.0000
34.8400 1629.0000 1.0000
34.8800 1540.0000 1.0000
34.9200 1562.0000 1.0000
34.9600 1494.0000 1.0000
35.0000 1470.0000 1.0000
35.0400 1455.0000 1.0000
35.0800 1442.0000 1.0000
35.1200 1415.0000 1.0000
35.1600 1322.0000 1.0000
35.2000 1338.0000 1.0000
35.2400 1367.0000 1.0000
35.2800 1378.0000 1.0000
35.3200 1312.0000 1.0000
35.3600 1346.0000 1.0000
35.4000 1336.0000 1.0000
35.4400 1291.0000 1.0000
35.4800 1309.0000 1.0000
35.5200 1352.0000 1.0000
35.5600 1276.0000 1.0000
35.6000 1328.0000 1.0000
35.6400 1277.0000 1.0000
35.6800 1363.0000 1.0000
35.7200 1371.0000 1.0000
35.7600 1329.0000 1.0000
35.8000 1293.0000 1.0000
35.8400 1321.0000 1.0000
35.8800 1347.0000 1.0000
35.9200 1346.0000 1.0000
35.9600 1312.0000 1.0000
36.0000 1309.0000 1.0000
36.0400 1359.0000 1.0000
36.0800 1442.0000 1.0000
36.1200 1470.0000 1.0000
36.1600 1531.0000 1.0000
36.2000 1648.0000 1.0000
36.2400 1726.0000 1.0000
36.2800 1855.0000 1.0000
36.3200 2150.0000 1.0000
36.3600 2162.0000 1.0000
36.4000 2189.0000 1.0000
36.4400 2246.0000 1.0000
36.4800 2111.0000 1.0000
36.5200 1851.0000 1.0000
36.5600 1657.0000 1.0000
36.6000 1538.0000 1.0000
36.6400 1454.0000 1.0000
36.6800 1363.0000 1.0000
36.7200 1293.0000 1.0000
36.7600 1298.0000 1.0000
36.8000 1298.0000 1.0000
36.8400 1255.0000 1.0000
36.8800 1248.0000 1.0000
36.9200 1297.0000 1.0000
36.9600 1216.0000 1.0000
37.0000 1183.0000 1.0000
37.0400 1267.0000 1.0000
37.0800 1179.0000 1.0000
37.1200 1187.0000 1.0000
37.1600 1166.0000 1.0000
37.2000 1238.0000 1.0000
37.2400 1239.0000 1.0000
37.2800 1212.0000 1.0000
37.3200 1206.0000 1.0000
37.3600 1244.0000 1.0000
37.4000 1199.0000 1.0000
37.4400 1178.0000 1.0000
37.4800 1186.0000 1.0000
37.5200 1190.0000 1.0000
37.5600 1232.0000 1.0000
37.6000 1200.0000 1.0000
37.6400 1240.0000 1.0000
37.6800 1232.0000 1.0000
37.7200 1173.0000 1.0000
37.7600 1181.0000 1.0000
37.8000 1257.0000 1.0000
37.8400 1228.0000 1.0000
37.8800 1207.0000 1.0000
37.9200 1215.0000 1.0000
37.9600 1224.0000 1.0000
38.0000 1314.0000 1.0000
38.0400 1242.0000 1.0000
38.0800 1436.0000 1.0000
38.1200 1433.0000 1.0000
38.1600 1604.0000 1.0000
38.2000 1779.0000 1.0000
38.2400 2008.0000 1.0000
38.2800 2336.0000 1.0000
38.3200 2684.0000 1.0000
38.3600 3532.0000 1.0000
38.4000 4557.0000 1.0000
38.4400 5850.0000 1.0000
38.4800 7311.0000 1.0000
38.5200 7959.0000 1.0000
38.5600 7553.0000 1.0000
38.6000 6594.0000 1.0000
38.6400 5296.0000 1.0000
38.6800 4124.0000 1.0000
38.7200 3175.0000 1.0000
38.7600 2522.0000 1.0000
38.8000 2059.0000 1.0000
38.8400 1754.0000 1.0000
38.8800 1550.0000 1.0000
38.9200 1469.0000 1.0000
38.9600 1355.0000 1.0000
39.0000 1250.0000 1.0000
39.0400 1213.0000 1.0000
39.0800 1181.0000 1.0000
39.1200 1180.0000 1.0000
39.1600 1153.0000 1.0000
39.2000 1173.0000 1.0000
39.2400 1135.0000 1.0000
39.2800 1048.0000 1.0000
39.3200 1057.0000 1.0000
39.3600 1082.0000 1.0000
39.4000 1068.0000 1.0000
39.4400 1105.0000 1.0000
39.4800 1060.0000 1.0000
39.5200 1142.0000 1.0000
39.5600 1091.0000 1.0000
39.6000 1115.0000 1.0000
39.6400 1072.0000 1.0000
39.6800 1094.0000 1.0000
39.7200 1073.0000 1.0000
39.7600 1041.0000 1.0000
39.8000 1014.0000 1.0000
39.8400 1074.0000 1.0000
39.8800 1032.0000 1.0000
39.9200 1079.0000 1.0000
39.9600 1051.0000 1.0000
40.0000 1050.0000 1.0000
40.0400 1033.0000 1.0000
40.0800 1011.0000 1.0000
40.1200 1040.0000 1.0000
40.1600 1125.0000 1.0000
40.2000 1006.0000 1.0000
40.2400 1040.0000 1.0000
40.2800 986.0000 1.0000
40.3200 972.0000 1.0000
40.3600 953.0000 1.0000
40.4000 1045.0000 1.0000
40.4400 994.0000 1.0000
40.4800 993.0000 1.0000
40.5200 1023.0000 1.0000
40.5600 985.0000 1.0000
40.6000 988.0000 1.0000
40.6400 978.0000 1.0000
40.6800 995.0000 1.0000
40.7200 999.0000 1.0000
40.7600 1005.0000 1.0000
40.8000 934.0000 1.0000
40.8400 979.0000 1.0000
40.8800 992.0000 1.0000
40.9200 955.0000 1.0000
40.9600 949.0000 1.0000
41.0000 1025.0000 1.0000
41.0400 1002.0000 1.0000
41.0800 1006.0000 1.0000
41.1200 963.0000 1.0000
41.1600 1016.0000 1.0000
41.2000 964.0000 1.0000
41.2400 985.0000 1.0000
41.2800 919.0000 1.0000
41.3200 969.0000 1.0000
41.3600 998.0000 1.0000
41.4000 1013.0000 1.0000
41.4400 988.0000 1.0000
41.4800 1020.0000 1.0000
41.5200 986.0000 1.0000
41.5600 1003.0000 1.0000
41.6000 946.0000 1.0000
41.6400 1012.0000 1.0000
41.6800 955.0000 1.0000
41.7200 990.0000 1.0000
41.7600 1060.0000 1.0000
41.8000 967.0000 1.0000
41.8400 967.0000 1.0000
41.8800 996.0000 1.0000
41.9200 967.0000 1.0000
41.9600 980.0000 1.0000
42.0000 994.0000 1.0000
42.0400 984.0000 1.0000
42.0800 938.0000 1.0000
42.1200 978.0000 1.0000
42.1600 965.0000 1.0000
42.2000 955.0000 1.0000
42.2400 986.0000 1.0000
42.2800 990.0000 1.0000
42.3200 925.0000 1.0000
42.3600 963.0000 1.0000
42.4000 947.0000 1.0000
42.4400 983.0000 1.0000
42.4800 925.0000 1.0000
42.5200 937.0000 1.0000
42.5600 959.0000 1.0000
42.6000 927.0000 1.0000
42.6400 891.0000 1.0000
42.6800 947.0000 1.0000
42.7200 951.0000 1.0000
42.7600 976.0000 1.0000
42.8000 976.0000 1.0000
42.8400 958.0000 1.0000
42.8800 971.0000 1.0000
42.9200 922.0000 1.0000
42.9600 974.0000 1.0000
43.0000 991.0000 1.0000
43.0400 988.0000 1.0000
43.0800 985.0000 1.0000
43.1200 1021.0000 1.0000
43.1600 1014.0000 1.0000
43.2000 1037.0000 1.0000
43.2400 1003.0000 1.0000
43.2800 975.0000 1.0000
43.3200 977.0000 1.0000
43.3600 1030.0000 1.0000
43.4000 979.0000 1.0000
43.4400 1022.0000 1.0000
43.4800 1002.0000 1.0000
43.5200 968.0000 1.0000
43.5600 955.0000 1.0000
43.6000 953.0000 1.0000
43.6400 914.0000 1.0000
43.6800 956.0000 1.0000
43.7200 940.0000 1.0000
43.7600 958.0000 1.0000
43.8000 967.0000 1.0000
43.8400 944.0000 1.0000
43.8800 943.0000 1.0000
43.9200 920.0000 1.0000
43.9600 938.0000 1.0000
44.0000 895.0000 1.0000
44.0400 960.0000 1.0000
44.0800 875.0000 1.0000
44.1200 903.0000 1.0000
44.1600 955.0000 1.0000
44.2000 993.0000 1.0000
44.2400 913.0000 1.0000
44.2800 943.0000 1.0000
44.3200 971.0000 1.0000
44.3600 985.0000 1.0000
44.4000 977.0000 1.0000
44.4400 901.0000 1.0000
44.4800 950.0000 1.0000
44.5200 884.0000 1.0000
44.5600 948.0000 1.0000
44.6000 890.0000 1.0000
44.6400 907.0000 1.0000
44.6800 908.0000 1.0000
44.7200 910.0000 1.0000
44.7600 884.0000 1.0000
44.8000 903.0000 1.0000
44.8400 978.0000 1.0000
44.8800 903.0000 1.0000
44.9200 855.0000 1.0000
44.9600 877.0000 1.0000
45.0000 901.0000 1.0000
45.0400 900.0000 1.0000
45.0800 901.0000 1.0000
45.1200 912.0000 1.0000
45.1600 906.0000 1.0000
45.2000 887.0000 1.0000
45.2400 953.0000 1.0000
45.2800 913.0000 1.0000
45.3200 915.0000 1.0000
45.3600 939.0000 1.0000
45.4000 892.0000 1.0000
45.4400 876.0000 1.0000
45.4800 904.0000 1.0000
45.5200 849.0000 1.0000
45.5600 871.0000 1.0000
45.6000 923.0000 1.0000
45.6400 836.0000 1.0000
45.6800 888.0000 1.0000
45.7200 889.0000 1.0000
45.7600 909.0000 1.0000
45.8000 895.0000 1.0000
45.8400 892.0000 1.0000
45.8800 889.0000 1.0000
45.9200 925.0000 1.0000
45.9600 924.0000 1.0000
46.0000 955.0000 1.0000
46.0400 886.0000 1.0000
46.0800 915.0000 1.0000
46.1200 863.0000 1.0000
46.1600 906.0000 1.0000
46.2000 888.0000 1.0000
46.2400 879.0000 1.0000
46.2800 867.0000 1.0000
46.3200 862.0000 1.0000
46.3600 911.0000 1.0000
46.4000 872.0000 1.0000
46.4400 905.0000 1.0000
46.4800 901.0000 1.0000
46.5200 877.0000 1.0000
46.5600 886.0000 1.0000
46.6000 845.0000 1.0000
46.6400 862.0000 1.0000
46.6800 872.0000 1.0000
46.7200 848.0000 1.0000
46.7600 883.0000 1.0000
46.8000 884.0000 1.0000
46.8400 847.0000 1.0000
46.8800 889.0000 1.0000
46.9200 891.0000 1.0000
46.9600 892.0000 1.0000
47.0000 893.0000 1.0000
47.0400 883.0000 1.0000
47.0800 867.0000 1.0000
47.1200 853.0000 1.0000
47.1600 890.0000 1.0000
47.2000 858.0000 1.0000
47.2400 877.0000 1.0000
47.2800 810.0000 1.0000
47.3200 849.0000 1.0000
47.3600 845.0000 1.0000
47.4000 858.0000 1.0000
47.4400 849.0000 1.0000
47.4800 851.0000 1.0000
47.5200 852.0000 1.0000
47.5600 857.0000 1.0000
47.6000 846.0000 1.0000
47.6400 818.0000 1.0000
47.6800 843.0000 1.0000
47.7200 847.0000 1.0000
47.7600 878.0000 1.0000
47.8000 828.0000 1.0000
47.8400 873.0000 1.0000
47.8800 826.0000 1.0000
47.9200 821.0000 1.0000
47.9600 859.0000 1.0000
48.0000 857.0000 1.0000
48.0400 851.0000 1.0000
48.0800 855.0000 1.0000
48.1200 810.0000 1.0000
48.1600 822.0000 1.0000
48.2000 838.0000 1.0000
48.2400 831.0000 1.0000
48.2800 822.0000 1.0000
48.3200 821.0000 1.0000
48.3600 823.0000 1.0000
48.4000 774.0000 1.0000
48.4400 830.0000 1.0000
48.4800 851.0000 1.0000
48.5200 861.0000 1.0000
48.5600 822.0000 1.0000
48.6000 859.0000 1.0000
48.6400 813.0000 1.0000
48.6800 811.0000 1.0000
48.7200 838.0000 1.0000
48.7600 867.0000 1.0000
48.8000 817.0000 1.0000
48.8400 838.0000 1.0000
48.8800 823.0000 1.0000
48.9200 818.0000 1.0000
48.9600 842.0000 1.0000
49.0000 808.0000 1.0000
49.0400 820.0000 1.0000
49.0800 809.0000 1.0000
49.1200 802.0000 1.0000
49.1600 849.0000 1.0000
49.2000 857.0000 1.0000
49.2400 783.0000 1.0000
49.2800 826.0000 1.0000
49.3200 768.0000 1.0000
49.3600 822.0000 1.0000
49.4000 843.0000 1.0000
49.4400 778.0000 1.0000
49.4800 818.0000 1.0000
49.5200 831.0000 1.0000
49.5600 863.0000 1.0000
49.6000 762.0000 1.0000
49.6400 830.0000 1.0000
49.6800 793.0000 1.0000
49.7200 811.0000 1.0000
49.7600 806.0000 1.0000
49.8000 809.0000 1.0000
49.8400 815.0000 1.0000
49.8800 832.0000 1.0000
49.9200 856.0000 1.0000
49.9600 868.0000 1.0000
50.0000 801.0000 1.0000
50.0400 824.0000 1.0000
50.0800 848.0000 1.0000
50.1200 816.0000 1.0000
50.1600 779.0000 1.0000
50.2000 843.0000 1.0000
50.2400 851.0000 1.0000
50.2800 855.0000 1.0000
50.3200 875.0000 1.0000
50.3600 827.0000 1.0000
50.4000 854.0000 1.0000
50.4400 874.0000 1.0000
50.4800 865.0000 1.0000
50.5200 813.0000 1.0000
50.5600 827.0000 1.0000
50.6000 822.0000 1.0000
50.6400 809.0000 1.0000
50.6800 818.0000 1.0000
50.7200 806.0000 1.0000
50.7600 829.0000 1.0000
50.8000 782.0000 1.0000
50.8400 827.0000 1.0000
50.8800 823.0000 1.0000
50.9200 800.0000 1.0000
50.9600 798.0000 1.0000
51.0000 839.0000 1.0000
51.0400 837.0000 1.0000
51.0800 814.0000 1.0000
51.1200 832.0000 1.0000
51.1600 841.0000 1.0000
51.2000 834.0000 1.0000
51.2400 847.0000 1.0000
51.2800 810.0000 1.0000
51.3200 853.0000 1.0000
51.3600 852.0000 1.0000
51.4000 799.0000 1.0000
51.4400 832.0000 1.0000
51.4800 829.0000 1.0000
51.5200 825.0000 1.0000
51.5600 840.0000 1.0000
51.6000 852.0000 1.0000
51.6400 853.0000 1.0000
51.6800 861.0000 1.0000
51.7200 889.0000 1.0000
51.7600 917.0000 1.0000
51.8000 897.0000 1.0000
51.8400 981.0000 1.0000
51.8800 978.0000 1.0000
51.9200 1114.0000 1.0000
51.9600 1217.0000 1.0000
52.0000 1289.0000 1.0000
52.0400 1591.0000 1.0000
52.0800 1864.0000 1.0000
52.1200 2489.0000 1.0000
52.1600 3309.0000 1.0000
52.2000 4390.0000 1.0000
52.2400 5081.0000 1.0000
52.2800 4931.0000 1.0000
52.3200 4369.0000 1.0000
52.3600 4030.0000 1.0000
52.4000 3617.0000 1.0000
52.4400 2848.0000 1.0000
52.4800 2009.0000 1.0000
52.5200 1659.0000 1.0000
52.5600 1478.0000 1.0000
52.6000 1279.0000 1.0000
52.6400 1136.0000 1.0000
52.6800 1069.0000 1.0000
52.7200 1048.0000 1.0000
52.7600 995.0000 1.0000
52.8000 932.0000 1.0000
52.8400 883.0000 1.0000
52.8800 924.0000 1.0000
52.9200 894.0000 1.0000
52.9600 831.0000 1.0000
53.0000 857.0000 1.0000
53.0400 871.0000 1.0000
53.0800 853.0000 1.0000
53.1200 881.0000 1.0000
53.1600 863.0000 1.0000
53.2000 854.0000 1.0000
53.2400 811.0000 1.0000
53.2800 856.0000 1.0000
53.3200 830.0000 1.0000
53.3600 828.0000 1.0000
53.4000 850.0000 1.0000
53.4400 819.0000 1.0000
53.4800 857.0000 1.0000
53.5200 816.0000 1.0000
53.5600 758.0000 1.0000
53.6000 811.0000 1.0000
53.6400 790.0000 1.0000
53.6800 811.0000 1.0000
53.7200 800.0000 1.0000
53.7600 786.0000 1.0000
53.8000 793.0000 1.0000
53.8400 775.0000 1.0000
53.8800 822.0000 1.0000
53.9200 791.0000 1.0000
53.9600 769.0000 1.0000
54.0000 769.0000 1.0000
54.0400 788.0000 1.0000
54.0800 795.0000 1.0000
54.1200 822.0000 1.0000
54.1600 749.0000 1.0000
54.2000 801.0000 1.0000
54.2400 802.0000 1.0000
54.2800 817.0000 1.0000
54.3200 778.0000 1.0000
54.3600 807.0000 1.0000
54.4000 815.0000 1.0000
54.4400 830.0000 1.0000
54.4800 773.0000 1.0000
54.5200 815.0000 1.0000
54.5600 783.0000 1.0000
54.6000 820.0000 1.0000
54.6400 834.0000 1.0000
54.6800 808.0000 1.0000
54.7200 820.0000 1.0000
54.7600 796.0000 1.0000
54.8000 858.0000 1.0000
54.8400 838.0000 1.0000
54.8800 817.0000 1.0000
54.9200 843.0000 1.0000
54.9600 868.0000 1.0000
55.0000 899.0000 1.0000
55.0400 902.0000 1.0000
55.0800 924.0000 1.0000
55.1200 968.0000 1.0000
55.1600 1048.0000 1.0000
55.2000 1099.0000 1.0000
55.2400 1188.0000 1.0000
55.2800 1261.0000 1.0000
55.3200 1171.0000 1.0000
55.3600 1177.0000 1.0000
55.4000 1065.0000 1.0000
55.4400 1015.0000 1.0000
55.4800 986.0000 1.0000
55.5200 965.0000 1.0000
55.5600 881.0000 1.0000
55.6000 859.0000 1.0000
55.6400 858.0000 1.0000
55.6800 846.0000 1.0000
55.7200 818.0000 1.0000
55.7600 815.0000 1.0000
55.8000 826.0000 1.0000
55.8400 801.0000 1.0000
55.8800 766.0000 1.0000
55.9200 789.0000 1.0000
55.9600 777.0000 1.0000
56.0000 783.0000 1.0000
56.0400 790.0000 1.0000
56.0800 772.0000 1.0000
56.1200 749.0000 1.0000
56.1600 777.0000 1.0000
56.2000 767.0000 1.0000
56.2400 759.0000 1.0000
56.2800 730.0000 1.0000
56.3200 762.0000 1.0000
56.3600 770.0000 1.0000
56.4000 744.0000 1.0000
56.4400 755.0000 1.0000
56.4800 745.0000 1.0000
56.5200 775.0000 1.0000
56.5600 783.0000 1.0000
56.6000 805.0000 1.0000
56.6400 787.0000 1.0000
56.6800 739.0000 1.0000
56.7200 788.0000 1.0000
56.7600 712.0000 1.0000
56.8000 764.0000 1.0000
56.8400 749.0000 1.0000
56.8800 743.0000 1.0000
56.9200 761.0000 1.0000
56.9600 758.0000 1.0000
57.0000 755.0000 1.0000
57.0400 752.0000 1.0000
57.0800 765.0000 1.0000
57.1200 818.0000 1.0000
57.1600 763.0000 1.0000
57.2000 778.0000 1.0000
57.2400 743.0000 1.0000
57.2800 779.0000 1.0000
57.3200 754.0000 1.0000
57.3600 765.0000 1.0000
57.4000 742.0000 1.0000
57.4400 748.0000 1.0000
57.4800 786.0000 1.0000
57.5200 754.0000 1.0000
57.5600 741.0000 1.0000
57.6000 788.0000 1.0000
57.6400 755.0000 1.0000
57.6800 767.0000 1.0000
57.7200 766.0000 1.0000
57.7600 776.0000 1.0000
57.8000 800.0000 1.0000
57.8400 739.0000 1.0000
57.8800 784.0000 1.0000
57.9200 787.0000 1.0000
57.9600 759.0000 1.0000
58.0000 720.0000 1.0000
58.0400 768.0000 1.0000
58.0800 810.0000 1.0000
58.1200 819.0000 1.0000
58.1600 810.0000 1.0000
58.2000 721.0000 1.0000
58.2400 764.0000 1.0000
58.2800 808.0000 1.0000
58.3200 771.0000 1.0000
58.3600 833.0000 1.0000
58.4000 733.0000 1.0000
58.4400 801.0000 1.0000
58.4800 756.0000 1.0000
58.5200 812.0000 1.0000
58.5600 769.0000 1.0000
58.6000 746.0000 1.0000
58.6400 755.0000 1.0000
58.6800 746.0000 1.0000
58.7200 793.0000 1.0000
58.7600 725.0000 1.0000
58.8000 772.0000 1.0000
58.8400 752.0000 1.0000
58.8800 792.0000 1.0000
58.9200 742.0000 1.0000
58.9600 771.0000 1.0000
59.0000 770.0000 1.0000
59.0400 790.0000 1.0000
59.0800 780.0000 1.0000
59.1200 803.0000 1.0000
59.1600 728.0000 1.0000
59.2000 753.0000 1.0000
59.2400 797.0000 1.0000
59.2800 759.0000 1.0000
59.3200 785.0000 1.0000
59.3600 780.0000 1.0000
59.4000 767.0000 1.0000
59.4400 781.0000 1.0000
59.4800 736.0000 1.0000
59.5200 790.0000 1.0000
59.5600 771.0000 1.0000
59.6000 741.0000 1.0000
59.6400 772.0000 1.0000
59.6800 760.0000 1.0000
59.7200 762.0000 1.0000
59.7600 712.0000 1.0000
59.8000 688.0000 1.0000
59.8400 747.0000 1.0000
59.8800 757.0000 1.0000
59.9200 748.0000 1.0000
59.9600 755.0000 1.0000
60.0000 784.0000 1.0000
60.0400 737.0000 1.0000
60.0800 759.0000 1.0000
60.1200 801.0000 1.0000
60.1600 771.0000 1.0000
60.2000 766.0000 1.0000
60.2400 753.0000 1.0000
60.2800 762.0000 1.0000
60.3200 726.0000 1.0000
60.3600 794.0000 1.0000
60.4000 754.0000 1.0000
60.4400 720.0000 1.0000
60.4800 753.0000 1.0000
60.5200 729.0000 1.0000
60.5600 773.0000 1.0000
60.6000 773.0000 1.0000
60.6400 755.0000 1.0000
60.6800 765.0000 1.0000
60.7200 766.0000 1.0000
60.7600 809.0000 1.0000
60.8000 716.0000 1.0000
60.8400 754.0000 1.0000
60.8800 788.0000 1.0000
60.9200 796.0000 1.0000
60.9600 753.0000 1.0000
61.0000 727.0000 1.0000
61.0400 742.0000 1.0000
61.0800 764.0000 1.0000
61.1200 784.0000 1.0000
61.1600 742.0000 1.0000
61.2000 778.0000 1.0000
61.2400 786.0000 1.0000
61.2800 748.0000 1.0000
61.3200 764.0000 1.0000
61.3600 768.0000 1.0000
61.4000 789.0000 1.0000
61.4400 765.0000 1.0000
61.4800 775.0000 1.0000
61.5200 798.0000 1.0000
61.5600 776.0000 1.0000
61.6000 819.0000 1.0000
61.6400 827.0000 1.0000
61.6800 834.0000 1.0000
61.7200 771.0000 1.0000
61.7600 830.0000 1.0000
61.8000 865.0000 1.0000
61.8400 906.0000 1.0000
61.8800 907.0000 1.0000
61.9200 919.0000 1.0000
61.9600 967.0000 1.0000
62.0000 985.0000 1.0000
62.0400 1109.0000 1.0000
62.0800 1191.0000 1.0000
62.1200 1340.0000 1.0000
62.1600 1448.0000 1.0000
62.2000 1723.0000 1.0000
62.2400 1819.0000 1.0000
62.2800 1831.0000 1.0000
62.3200 1874.0000 1.0000
62.3600 1765.0000 1.0000
62.4000 1694.0000 1.0000
62.4400 1635.0000 1.0000
62.4800 1428.0000 1.0000
62.5200 1334.0000 1.0000
62.5600 1196.0000 1.0000
62.6000 1170.0000 1.0000
62.6400 1075.0000 1.0000
62.6800 990.0000 1.0000
62.7200 993.0000 1.0000
62.7600 893.0000 1.0000
62.8000 910.0000 1.0000
62.8400 929.0000 1.0000
62.8800 892.0000 1.0000
62.9200 854.0000 1.0000
62.9600 825.0000 1.0000
63.0000 832.0000 1.0000
63.0400 809.0000 1.0000
63.0800 810.0000 1.0000
63.1200 852.0000 1.0000
63.1600 859.0000 1.0000
63.2000 781.0000 1.0000
63.2400 791.0000 1.0000
63.2800 790.0000 1.0000
63.3200 794.0000 1.0000
63.3600 849.0000 1.0000
63.4000 792.0000 1.0000
63.4400 781.0000 1.0000
63.4800 785.0000 1.0000
63.5200 794.0000 1.0000
63.5600 825.0000 1.0000
63.6000 750.0000 1.0000
63.6400 780.0000 1.0000
63.6800 765.0000 1.0000
63.7200 794.0000 1.0000
63.7600 761.0000 1.0000
63.8000 784.0000 1.0000
63.8400 773.0000 1.0000
63.8800 772.0000 1.0000
63.9200 782.0000 1.0000
63.9600 738.0000 1.0000
64.0000 755.0000 1.0000
64.0400 788.0000 1.0000
64.0800 798.0000 1.0000
64.1200 757.0000 1.0000
64.1600 837.0000 1.0000
64.2000 830.0000 1.0000
64.2400 815.0000 1.0000
64.2800 837.0000 1.0000
64.3200 846.0000 1.0000
64.3600 832.0000 1.0000
64.4000 886.0000 1.0000
64.4400 891.0000 1.0000
64.4800 907.0000 1.0000
64.5200 910.0000 1.0000
64.5600 998.0000 1.0000
64.6000 972.0000 1.0000
64.6400 1075.0000 1.0000
64.6800 1086.0000 1.0000
64.7200 1021.0000 1.0000
64.7600 1039.0000 1.0000
64.8000 1030.0000 1.0000
64.8400 967.0000 1.0000
64.8800 967.0000 1.0000
64.9200 988.0000 1.0000
64.9600 907.0000 1.0000
65.0000 883.0000 1.0000
65.0400 893.0000 1.0000
65.0800 804.0000 1.0000
65.1200 866.0000 1.0000
65.1600 827.0000 1.0000
65.2000 827.0000 1.0000
65.2400 810.0000 1.0000
65.2800 803.0000 1.0000
65.3200 790.0000 1.0000
65.3600 864.0000 1.0000
65.4000 810.0000 1.0000
65.4400 807.0000 1.0000
65.4800 791.0000 1.0000
65.5200 843.0000 1.0000
65.5600 788.0000 1.0000
65.6000 807.0000 1.0000
65.6400 852.0000 1.0000
65.6800 840.0000 1.0000
65.7200 841.0000 1.0000
65.7600 846.0000 1.0000
65.8000 887.0000 1.0000
65.8400 944.0000 1.0000
65.8800 987.0000 1.0000
65.9200 990.0000 1.0000
65.9600 1061.0000 1.0000
66.0000 1217.0000 1.0000
66.0400 1357.0000 1.0000
66.0800 1520.0000 1.0000
66.1200 2006.0000 1.0000
66.1600 2335.0000 1.0000
66.2000 2733.0000 1.0000
66.2400 2911.0000 1.0000
66.2800 2751.0000 1.0000
66.3200 2563.0000 1.0000
66.3600 2415.0000 1.0000
66.4000 2251.0000 1.0000
66.4400 2095.0000 1.0000
66.4800 1779.0000 1.0000
66.5200 1565.0000 1.0000
66.5600 1344.0000 1.0000
66.6000 1181.0000 1.0000
66.6400 1098.0000 1.0000
66.6800 995.0000 1.0000
66.7200 929.0000 1.0000
66.7600 919.0000 1.0000
66.8000 889.0000 1.0000
66.8400 821.0000 1.0000
66.8800 823.0000 1.0000
66.9200 799.0000 1.0000
66.9600 811.0000 1.0000
67.0000 813.0000 1.0000
67.0400 764.0000 1.0000
67.0800 776.0000 1.0000
67.1200 781.0000 1.0000
67.1600 727.0000 1.0000
67.2000 764.0000 1.0000
67.2400 763.0000 1.0000
67.2800 705.0000 1.0000
67.3200 766.0000 1.0000
67.3600 737.0000 1.0000
67.4000 767.0000 1.0000
67.4400 699.0000 1.0000
67.4800 741.0000 1.0000
67.5200 673.0000 1.0000
67.5600 742.0000 1.0000
67.6000 737.0000 1.0000
67.6400 716.0000 1.0000
67.6800 678.0000 1.0000
67.7200 710.0000 1.0000
67.7600 717.0000 1.0000
67.8000 690.0000 1.0000
67.8400 740.0000 1.0000
67.8800 653.0000 1.0000
67.9200 725.0000 1.0000
67.9600 719.0000 1.0000
68.0000 695.0000 1.0000
68.0400 732.0000 1.0000
68.0800 709.0000 1.0000
68.1200 673.0000 1.0000
68.1600 708.0000 1.0000
68.2000 696.0000 1.0000
68.2400 668.0000 1.0000
68.2800 691.0000 1.0000
68.3200 699.0000 1.0000
68.3600 690.0000 1.0000
68.4000 696.0000 1.0000
68.4400 690.0000 1.0000
68.4800 659.0000 1.0000
68.5200 725.0000 1.0000
68.5600 691.0000 1.0000
68.6000 681.0000 1.0000
68.6400 709.0000 1.0000
68.6800 718.0000 1.0000
68.7200 683.0000 1.0000
68.7600 658.0000 1.0000
68.8000 654.0000 1.0000
68.8400 697.0000 1.0000
68.8800 678.0000 1.0000
68.9200 647.0000 1.0000
68.9600 668.0000 1.0000
69.0000 640.0000 1.0000
69.0400 695.0000 1.0000
69.0800 669.0000 1.0000
69.1200 685.0000 1.0000
69.1600 716.0000 1.0000
69.2000 677.0000 1.0000
69.2400 674.0000 1.0000
69.2800 692.0000 1.0000
69.3200 684.0000 1.0000
69.3600 636.0000 1.0000
69.4000 668.0000 1.0000
69.4400 677.0000 1.0000
69.4800 695.0000 1.0000
69.5200 688.0000 1.0000
69.5600 661.0000 1.0000
69.6000 685.0000 1.0000
69.6400 681.0000 1.0000
69.6800 690.0000 1.0000
69.7200 678.0000 1.0000
69.7600 685.0000 1.0000
69.8000 672.0000 1.0000
69.8400 636.0000 1.0000
69.8800 696.0000 1.0000
69.9200 631.0000 1.0000
69.9600 615.0000 1.0000
70.0000 654.0000 1.0000
*RAS_INT_END
*RAS_TEMPERATURE_START
*RAS_TEMPERATURE_END
*RAS_DATA_END