File: Section2_75_samples/XRD/No_030_FS1_2.ras
*RAS_DATA_START
*RAS_HEADER_START
*DISP_FMT_X "%.2f"
*DISP_FMT_Y "%.0f"
*DISP_FULLSCALE "13068.0000000000"
*DISP_LINE_COLOR "255.0000000000"
*DISP_LINE_STYLE "0.0000000000"
*DISP_LINE_WIDTH "0.2500000000"
*DISP_NOTE "測定データ-3"
*DISP_OFFSET_Y "0.0000000000"
*DISP_PEAKSEARCH_UNIT_Y "cps"
*DISP_RANGE_BOTTOM "0.0000000000"
*DISP_RANGE_LEFT "20.0000000000"
*DISP_RANGE_LOGCUTOFF "0.0100000000"
*DISP_RANGE_RIGHT "70.0000000000"
*DISP_RANGE_TOP "13068.0000000000"
*DISP_SCALE_MODE_Y "0.0000000000"
*DISP_TAB_NAME "2θ/θ"
*DISP_TITLE_Y "強度"
*DISP_UNIT_Y "cps"
*DISP_WINDOW_NAME "MSG_MACROENGINE"
*FILE_COMMENT " "
*FILE_MD5 ""
*FILE_MEMO " "
*FILE_OPERATOR "Administrator"
*FILE_SAMPLE " "
*FILE_TYPE "RAS_RAW"
*FILE_USERGROUP "システムマネージャ"
*FILE_VERSION "1.0000000000"
*HW_ATTACHMENT_ID "ATT0025"
*HW_ATTACHMENT_NAME "標準|Standard"
*HW_COUNTER_ID-0 "CUT0025"
*HW_COUNTER_ID-1 "CUT0020"
*HW_COUNTER_ID-2 "CUT0020"
*HW_COUNTER_ID-3 "CSL0021"
*HW_COUNTER_ID-4 "CMC0021"
*HW_COUNTER_NAME-0 "D/teX Ultra|D/teX Ultra"
*HW_COUNTER_NAME-1 "None|None"
*HW_COUNTER_NAME-2 "None|None"
*HW_COUNTER_NAME-3 "BBM|BBM"
*HW_COUNTER_NAME-4 "検出器モノクロメータ|Detector monochromator"
*HW_COUNTER_SELECT_NAME "D/teX Ultra|D/teX Ultra"
*HW_GONIOMETER_ID "GON0023"
*HW_GONIOMETER_NAME "SmartLab|SmartLab"
*HW_GONIOMETER_RADIUS-0 "90.0"
*HW_GONIOMETER_RADIUS-1 "114.0"
*HW_GONIOMETER_RADIUS-2 "190.0"
*HW_GONIOMETER_RADIUS-3 "300.0"
*HW_GONIOMETER_RADIUS-4 "187.0"
*HW_GONIOMETER_RADIUS-5 "300.0"
*HW_GONIOMETER_RADIUS-6 "113.0"
*HW_GONIOMETER_RADIUS-7 "331.0"
*HW_I_OPT_ID-0 "CBO0021"
*HW_I_OPT_ID-1 "ICR0023"
*HW_I_OPT_ID-2 "ISL0021"
*HW_I_OPT_ID-3 "ISO0021"
*HW_I_OPT_ID-4 "IAD0021"
*HW_I_OPT_ID-5 "IPR0001"
*HW_I_OPT_NAME-0 "CBOユニット|CBO unit"
*HW_I_OPT_NAME-1 "標準入射光学ユニット|Standard incident optical unit"
*HW_I_OPT_NAME-2 "標準入射スリットボックス|Standard incident slit box"
*HW_I_OPT_NAME-3 "入射平行スリット|Incident parallel slit"
*HW_I_OPT_NAME-4 "長手制限スリット|Length limiting slit"
*HW_I_OPT_NAME-5 "None|None"
*HW_R_ATTENUATER_AUTOMODE "0"
*HW_R_OPT_ID-0 "RSS0021"
*HW_R_OPT_ID-1 "RCR0023"
*HW_R_OPT_ID-2 "RSO0021"
*HW_R_OPT_ID-3 "RRS0021"
*HW_R_OPT_ID-4 "ATN0021"
*HW_R_OPT_ID-5 "RFL0021"
*HW_R_OPT_ID-6 "RAD0021"
*HW_R_OPT_NAME-0 "標準受光スリットボックス1|Standard receiving slit box # 1"
*HW_R_OPT_NAME-1 "標準受光光学ユニット1|Standard receiving unit # 1"
*HW_R_OPT_NAME-2 "標準受光光学ユニット2|Standard receiving optical unit # 2"
*HW_R_OPT_NAME-3 "標準受光スリットボックス2|Standard receiving slit box # 2"
*HW_R_OPT_NAME-4 "標準アッテネータ|Standard Attenuator"
*HW_R_OPT_NAME-5 "Cu Kβ|Cu K-beta"
*HW_R_OPT_NAME-6 "調整用受光スリット|Alignment receiving slit"
*HW_SAMPLE_HOLDER_ID "SMP0023"
*HW_SAMPLE_HOLDER_NAME "標準Zステージ|Standard Z stage"
*HW_XG_CURRENT_MAX "50"
*HW_XG_CURRENT_MIN "2"
*HW_XG_CURRENT_RESOLUTION "1"
*HW_XG_CURRENT_UNIT "mA"
*HW_XG_FOCUS "1mm x 10mm"
*HW_XG_FOCUS_TYPE "Normal"
*HW_XG_ID ""
*HW_XG_NAME "3kW 封入管(ID:1200)|3kW Sealed tube(ID:1200)"
*HW_XG_TARGET_ATOMIC_NUMBER "29.0000000000"
*HW_XG_TARGET_NAME "Cu"
*HW_XG_TYPE "Hermetic"
*HW_XG_VOLTAGE_MAX "60"
*HW_XG_VOLTAGE_MIN "20"
*HW_XG_VOLTAGE_RESOLUTION "1"
*HW_XG_VOLTAGE_UNIT "kV"
*HW_XG_WATT_MAX "1.500"
*HW_XG_WATT_UNIT "kW"
*HW_XG_WAVE_LENGTH_ALPHA1 "1.540593"
*HW_XG_WAVE_LENGTH_ALPHA2 "1.544414"
*HW_XG_WAVE_LENGTH_BETA "1.392250"
*MEAS_COND_AXIS_NAME-0 "2θ/θ"
*MEAS_COND_AXIS_NAME-1 "2θ"
*MEAS_COND_AXIS_NAME-2 "ω"
*MEAS_COND_AXIS_NAME-3 "Z"
*MEAS_COND_AXIS_NAME-4 "2θ/ω"
*MEAS_COND_AXIS_NAME-5 "θs"
*MEAS_COND_AXIS_NAME-6 "θd"
*MEAS_COND_AXIS_NAME-7 "Ts"
*MEAS_COND_AXIS_NAME-8 "CBO選択スリット"
*MEAS_COND_AXIS_NAME-9 "M"
*MEAS_COND_AXIS_NAME-10 "入射平行スリット"
*MEAS_COND_AXIS_NAME-11 "入射スリット"
*MEAS_COND_AXIS_NAME-12 ""
*MEAS_COND_AXIS_NAME-13 "Zs"
*MEAS_COND_AXIS_NAME-14 "入射光学素子"
*MEAS_COND_AXIS_NAME-15 "長手制限スリット"
*MEAS_COND_AXIS_NAME-16 "センタースリット"
*MEAS_COND_AXIS_NAME-17 "フィルター"
*MEAS_COND_AXIS_NAME-18 "受光スリット1"
*MEAS_COND_AXIS_NAME-19 "受光スリット2"
*MEAS_COND_AXIS_NAME-20 "受光光学素子"
*MEAS_COND_AXIS_NAME-21 "受光平行スリット"
*MEAS_COND_AXIS_NAME-22 "調整用受光スリット"
*MEAS_COND_AXIS_NAME-23 ""
*MEAS_COND_AXIS_NAME-24 ""
*MEAS_COND_AXIS_NAME-25 "Zd"
*MEAS_COND_AXIS_NAME-26 "アッテネータ"
*MEAS_COND_AXIS_NAME-27 "検出器モノクロメータ"
*MEAS_COND_AXIS_NAME-28 "モノクロメータスリット"
*MEAS_COND_AXIS_NAME-29 "プライマリビーム"
*MEAS_COND_AXIS_NAME-30 "PHA"
*MEAS_COND_AXIS_NAME_INTERNAL-0 "TwoThetaTheta"
*MEAS_COND_AXIS_NAME_INTERNAL-1 "TwoTheta"
*MEAS_COND_AXIS_NAME_INTERNAL-2 "Omega"
*MEAS_COND_AXIS_NAME_INTERNAL-3 "Z"
*MEAS_COND_AXIS_NAME_INTERNAL-4 "TwoThetaOmega"
*MEAS_COND_AXIS_NAME_INTERNAL-5 "ThetaS"
*MEAS_COND_AXIS_NAME_INTERNAL-6 "ThetaD"
*MEAS_COND_AXIS_NAME_INTERNAL-7 "Ts"
*MEAS_COND_AXIS_NAME_INTERNAL-8 "CBO"
*MEAS_COND_AXIS_NAME_INTERNAL-9 "CBO-M"
*MEAS_COND_AXIS_NAME_INTERNAL-10 "IncidentSollerSlit"
*MEAS_COND_AXIS_NAME_INTERNAL-11 "IncidentSlitBox"
*MEAS_COND_AXIS_NAME_INTERNAL-12 "IncidentSlitBox-_Axis"
*MEAS_COND_AXIS_NAME_INTERNAL-13 "Zs"
*MEAS_COND_AXIS_NAME_INTERNAL-14 "IncidentMonochromator"
*MEAS_COND_AXIS_NAME_INTERNAL-15 "IncidentAxdSlit"
*MEAS_COND_AXIS_NAME_INTERNAL-16 "CenterSlit"
*MEAS_COND_AXIS_NAME_INTERNAL-17 "Filter"
*MEAS_COND_AXIS_NAME_INTERNAL-18 "ReceivingSlitBox1"
*MEAS_COND_AXIS_NAME_INTERNAL-19 "ReceivingSlitBox2"
*MEAS_COND_AXIS_NAME_INTERNAL-20 "ReceivingOptics"
*MEAS_COND_AXIS_NAME_INTERNAL-21 "ReceivingSollerSlit"
*MEAS_COND_AXIS_NAME_INTERNAL-22 "ReceivingAxdSlit"
*MEAS_COND_AXIS_NAME_INTERNAL-23 "ReceivingSlitBox1-_Axis"
*MEAS_COND_AXIS_NAME_INTERNAL-24 "ReceivingSlitBox2-_Axis"
*MEAS_COND_AXIS_NAME_INTERNAL-25 "ReceivingSlitBox2-Zd"
*MEAS_COND_AXIS_NAME_INTERNAL-26 "Attenuator"
*MEAS_COND_AXIS_NAME_INTERNAL-27 "CounterMonochromator"
*MEAS_COND_AXIS_NAME_INTERNAL-28 "CounterSlit"
*MEAS_COND_AXIS_NAME_INTERNAL-29 "IncidentPrimary"
*MEAS_COND_AXIS_NAME_INTERNAL-30 "PHA"
*MEAS_COND_AXIS_NAME_MAGICNO-0 "83951616.0000000000"
*MEAS_COND_AXIS_NAME_MAGICNO-1 "268632064.0000000000"
*MEAS_COND_AXIS_NAME_MAGICNO-2 "268500992.0000000000"
*MEAS_COND_AXIS_NAME_MAGICNO-3 "285278208.0000000000"
*MEAS_COND_AXIS_NAME_MAGICNO-4 "83951616.0000000000"
*MEAS_COND_AXIS_NAME_MAGICNO-5 "131072.0000000000"
*MEAS_COND_AXIS_NAME_MAGICNO-6 "131072.0000000000"
*MEAS_COND_AXIS_NAME_MAGICNO-7 "318898176.0000000000"
*MEAS_COND_AXIS_NAME_MAGICNO-8 "20971521.0000000000"
*MEAS_COND_AXIS_NAME_MAGICNO-9 "285343744.0000000000"
*MEAS_COND_AXIS_NAME_MAGICNO-10 "20971521.0000000000"
*MEAS_COND_AXIS_NAME_MAGICNO-11 "22020097.0000000000"
*MEAS_COND_AXIS_NAME_MAGICNO-12 "25165824.0000000000"
*MEAS_COND_AXIS_NAME_MAGICNO-13 "318898176.0000000000"
*MEAS_COND_AXIS_NAME_MAGICNO-14 "1.0000000000"
*MEAS_COND_AXIS_NAME_MAGICNO-15 "20971521.0000000000"
*MEAS_COND_AXIS_NAME_MAGICNO-16 "20971521.0000000000"
*MEAS_COND_AXIS_NAME_MAGICNO-17 "20971521.0000000000"
*MEAS_COND_AXIS_NAME_MAGICNO-18 "23068673.0000000000"
*MEAS_COND_AXIS_NAME_MAGICNO-19 "23068673.0000000000"
*MEAS_COND_AXIS_NAME_MAGICNO-20 "20971521.0000000000"
*MEAS_COND_AXIS_NAME_MAGICNO-21 "20971521.0000000000"
*MEAS_COND_AXIS_NAME_MAGICNO-22 "20971521.0000000000"
*MEAS_COND_AXIS_NAME_MAGICNO-23 "25165824.0000000000"
*MEAS_COND_AXIS_NAME_MAGICNO-24 "25165824.0000000000"
*MEAS_COND_AXIS_NAME_MAGICNO-25 "285343744.0000000000"
*MEAS_COND_AXIS_NAME_MAGICNO-26 "17301505.0000000000"
*MEAS_COND_AXIS_NAME_MAGICNO-27 "20971521.0000000000"
*MEAS_COND_AXIS_NAME_MAGICNO-28 "20971521.0000000000"
*MEAS_COND_AXIS_NAME_MAGICNO-29 "20971521.0000000000"
*MEAS_COND_AXIS_NAME_MAGICNO-30 "0.0000000000"
*MEAS_COND_AXIS_OFFSET-0 "-"
*MEAS_COND_AXIS_OFFSET-1 "-0.1081000000"
*MEAS_COND_AXIS_OFFSET-2 "0.3758000000"
*MEAS_COND_AXIS_OFFSET-3 "-"
*MEAS_COND_AXIS_OFFSET-4 "-"
*MEAS_COND_AXIS_OFFSET-5 "0.3758000000"
*MEAS_COND_AXIS_OFFSET-6 "-0.4839000000"
*MEAS_COND_AXIS_OFFSET-7 "-"
*MEAS_COND_AXIS_OFFSET-8 "-"
*MEAS_COND_AXIS_OFFSET-9 "-"
*MEAS_COND_AXIS_OFFSET-10 "-"
*MEAS_COND_AXIS_OFFSET-11 "-"
*MEAS_COND_AXIS_OFFSET-12 "-"
*MEAS_COND_AXIS_OFFSET-13 "-"
*MEAS_COND_AXIS_OFFSET-14 "-"
*MEAS_COND_AXIS_OFFSET-15 "-"
*MEAS_COND_AXIS_OFFSET-16 "-"
*MEAS_COND_AXIS_OFFSET-17 "-"
*MEAS_COND_AXIS_OFFSET-18 "-"
*MEAS_COND_AXIS_OFFSET-19 "-"
*MEAS_COND_AXIS_OFFSET-20 "-"
*MEAS_COND_AXIS_OFFSET-21 "-"
*MEAS_COND_AXIS_OFFSET-22 "-"
*MEAS_COND_AXIS_OFFSET-23 "-"
*MEAS_COND_AXIS_OFFSET-24 "-"
*MEAS_COND_AXIS_OFFSET-25 "-"
*MEAS_COND_AXIS_OFFSET-26 "-"
*MEAS_COND_AXIS_OFFSET-27 "-"
*MEAS_COND_AXIS_OFFSET-28 "-"
*MEAS_COND_AXIS_OFFSET-29 "-"
*MEAS_COND_AXIS_OFFSET-30 "-"
*MEAS_COND_AXIS_POSITION-0 "0.0000000000"
*MEAS_COND_AXIS_POSITION-1 "0.0000000000"
*MEAS_COND_AXIS_POSITION-2 "0.0000000000"
*MEAS_COND_AXIS_POSITION-3 "-0.5500000000"
*MEAS_COND_AXIS_POSITION-4 "0.0000000000"
*MEAS_COND_AXIS_POSITION-5 "0.0000000000"
*MEAS_COND_AXIS_POSITION-6 "0.0000000000"
*MEAS_COND_AXIS_POSITION-7 "-0.4278800000"
*MEAS_COND_AXIS_POSITION-8 "BB"
*MEAS_COND_AXIS_POSITION-9 "0.0000000000"
*MEAS_COND_AXIS_POSITION-10 "Soller_slit_5.0deg"
*MEAS_COND_AXIS_POSITION-11 "2/3deg"
*MEAS_COND_AXIS_POSITION-12 "2.2088000000"
*MEAS_COND_AXIS_POSITION-13 "-0.4140600000"
*MEAS_COND_AXIS_POSITION-14 "0.0000000000"
*MEAS_COND_AXIS_POSITION-15 "10.0mm"
*MEAS_COND_AXIS_POSITION-16 "None"
*MEAS_COND_AXIS_POSITION-17 "Cu_K-beta"
*MEAS_COND_AXIS_POSITION-18 "13.000mm"
*MEAS_COND_AXIS_POSITION-19 "13.000mm"
*MEAS_COND_AXIS_POSITION-20 "No_unit"
*MEAS_COND_AXIS_POSITION-21 "Soller_slit_5.0deg"
*MEAS_COND_AXIS_POSITION-22 "None"
*MEAS_COND_AXIS_POSITION-23 "13.0000000000"
*MEAS_COND_AXIS_POSITION-24 "13.0000000000"
*MEAS_COND_AXIS_POSITION-25 "0.0109400000"
*MEAS_COND_AXIS_POSITION-26 "Open"
*MEAS_COND_AXIS_POSITION-27 "None"
*MEAS_COND_AXIS_POSITION-28 "None"
*MEAS_COND_AXIS_POSITION-29 "None"
*MEAS_COND_AXIS_POSITION-30 "38.0000000000"
*MEAS_COND_AXIS_UNIT-0 "deg"
*MEAS_COND_AXIS_UNIT-1 "deg"
*MEAS_COND_AXIS_UNIT-2 "deg"
*MEAS_COND_AXIS_UNIT-3 "mm"
*MEAS_COND_AXIS_UNIT-4 "deg"
*MEAS_COND_AXIS_UNIT-5 "deg"
*MEAS_COND_AXIS_UNIT-6 "deg"
*MEAS_COND_AXIS_UNIT-7 "mm"
*MEAS_COND_AXIS_UNIT-8 ""
*MEAS_COND_AXIS_UNIT-9 "pulse"
*MEAS_COND_AXIS_UNIT-10 ""
*MEAS_COND_AXIS_UNIT-11 ""
*MEAS_COND_AXIS_UNIT-12 "mm"
*MEAS_COND_AXIS_UNIT-13 "mm"
*MEAS_COND_AXIS_UNIT-14 ""
*MEAS_COND_AXIS_UNIT-15 ""
*MEAS_COND_AXIS_UNIT-16 ""
*MEAS_COND_AXIS_UNIT-17 ""
*MEAS_COND_AXIS_UNIT-18 ""
*MEAS_COND_AXIS_UNIT-19 ""
*MEAS_COND_AXIS_UNIT-20 ""
*MEAS_COND_AXIS_UNIT-21 ""
*MEAS_COND_AXIS_UNIT-22 ""
*MEAS_COND_AXIS_UNIT-23 "mm"
*MEAS_COND_AXIS_UNIT-24 "mm"
*MEAS_COND_AXIS_UNIT-25 "mm"
*MEAS_COND_AXIS_UNIT-26 ""
*MEAS_COND_AXIS_UNIT-27 ""
*MEAS_COND_AXIS_UNIT-28 ""
*MEAS_COND_AXIS_UNIT-29 ""
*MEAS_COND_AXIS_UNIT-30 "div"
*MEAS_COND_COUNTER_CNTLOSS_CORR "0.0000000000"
*MEAS_COND_COUNTER_PHABASE "38.0000000000"
*MEAS_COND_COUNTER_PHAWINDOW "16.0000000000"
*MEAS_COND_COUNTER_PHA_UNIT "div"
*MEAS_COND_COUNTER_TAUDIFF "30.0000000000"
*MEAS_COND_COUNTER_TAUINT "0.0000000000"
*MEAS_COND_IRRADIATION_MODE "OFF"
*MEAS_COND_IRRADIATION_WIDTH ""
*MEAS_COND_OPT_ATTR "集中法"
*MEAS_COND_OPT_NAME "@集中法"
*MEAS_COND_UNSYMMETRIC_MODE "OFF"
*MEAS_COND_XG_CURRENT "30.0000000000"
*MEAS_COND_XG_VOLTAGE "40.0000000000"
*MEAS_COND_XG_WAVE_TYPE "Ka"
*MEAS_DATA_COUNT "5001.0000000000"
*MEAS_SCAN_AXIS_X "2θ/θ"
*MEAS_SCAN_AXIS_X_INTERNAL "TwoThetaTheta"
*MEAS_SCAN_END_TIME "06/24/21 17:28:56"
*MEAS_SCAN_MODE "CONTINUOUS"
*MEAS_SCAN_MONITOR "0"
*MEAS_SCAN_RESOLUTION_X "0.0002"
*MEAS_SCAN_SPEED "1.0"
*MEAS_SCAN_SPEED_UNIT "deg/min"
*MEAS_SCAN_START "20.0000000000"
*MEAS_SCAN_START_TIME "06/24/21 16:36:03"
*MEAS_SCAN_STEP "0.0100000000"
*MEAS_SCAN_STOP "70.0000000000"
*MEAS_SCAN_UNIT_X "deg"
*MEAS_SCAN_UNIT_Y "counts"
*RAS_HEADER_END
*RAS_INT_START
20.0000 1510.0000 1.0000
20.0400 1475.0000 1.0000
20.0800 1623.0000 1.0000
20.1200 1513.0000 1.0000
20.1600 1515.0000 1.0000
20.2000 1564.0000 1.0000
20.2400 1532.0000 1.0000
20.2800 1452.0000 1.0000
20.3200 1503.0000 1.0000
20.3600 1544.0000 1.0000
20.4000 1563.0000 1.0000
20.4400 1593.0000 1.0000
20.4800 1507.0000 1.0000
20.5200 1563.0000 1.0000
20.5600 1575.0000 1.0000
20.6000 1487.0000 1.0000
20.6400 1548.0000 1.0000
20.6800 1521.0000 1.0000
20.7200 1507.0000 1.0000
20.7600 1499.0000 1.0000
20.8000 1541.0000 1.0000
20.8400 1565.0000 1.0000
20.8800 1522.0000 1.0000
20.9200 1551.0000 1.0000
20.9600 1613.0000 1.0000
21.0000 1547.0000 1.0000
21.0400 1525.0000 1.0000
21.0800 1531.0000 1.0000
21.1200 1526.0000 1.0000
21.1600 1536.0000 1.0000
21.2000 1494.0000 1.0000
21.2400 1526.0000 1.0000
21.2800 1537.0000 1.0000
21.3200 1480.0000 1.0000
21.3600 1495.0000 1.0000
21.4000 1558.0000 1.0000
21.4400 1501.0000 1.0000
21.4800 1562.0000 1.0000
21.5200 1527.0000 1.0000
21.5600 1526.0000 1.0000
21.6000 1525.0000 1.0000
21.6400 1520.0000 1.0000
21.6800 1561.0000 1.0000
21.7200 1490.0000 1.0000
21.7600 1556.0000 1.0000
21.8000 1525.0000 1.0000
21.8400 1520.0000 1.0000
21.8800 1569.0000 1.0000
21.9200 1560.0000 1.0000
21.9600 1521.0000 1.0000
22.0000 1556.0000 1.0000
22.0400 1552.0000 1.0000
22.0800 1547.0000 1.0000
22.1200 1512.0000 1.0000
22.1600 1572.0000 1.0000
22.2000 1514.0000 1.0000
22.2400 1454.0000 1.0000
22.2800 1530.0000 1.0000
22.3200 1535.0000 1.0000
22.3600 1553.0000 1.0000
22.4000 1577.0000 1.0000
22.4400 1570.0000 1.0000
22.4800 1513.0000 1.0000
22.5200 1515.0000 1.0000
22.5600 1587.0000 1.0000
22.6000 1491.0000 1.0000
22.6400 1525.0000 1.0000
22.6800 1523.0000 1.0000
22.7200 1569.0000 1.0000
22.7600 1632.0000 1.0000
22.8000 1513.0000 1.0000
22.8400 1588.0000 1.0000
22.8800 1518.0000 1.0000
22.9200 1518.0000 1.0000
22.9600 1540.0000 1.0000
23.0000 1528.0000 1.0000
23.0400 1586.0000 1.0000
23.0800 1570.0000 1.0000
23.1200 1566.0000 1.0000
23.1600 1594.0000 1.0000
23.2000 1585.0000 1.0000
23.2400 1527.0000 1.0000
23.2800 1535.0000 1.0000
23.3200 1524.0000 1.0000
23.3600 1601.0000 1.0000
23.4000 1567.0000 1.0000
23.4400 1519.0000 1.0000
23.4800 1619.0000 1.0000
23.5200 1627.0000 1.0000
23.5600 1547.0000 1.0000
23.6000 1594.0000 1.0000
23.6400 1563.0000 1.0000
23.6800 1642.0000 1.0000
23.7200 1568.0000 1.0000
23.7600 1609.0000 1.0000
23.8000 1588.0000 1.0000
23.8400 1546.0000 1.0000
23.8800 1587.0000 1.0000
23.9200 1559.0000 1.0000
23.9600 1550.0000 1.0000
24.0000 1595.0000 1.0000
24.0400 1543.0000 1.0000
24.0800 1681.0000 1.0000
24.1200 1539.0000 1.0000
24.1600 1595.0000 1.0000
24.2000 1626.0000 1.0000
24.2400 1570.0000 1.0000
24.2800 1638.0000 1.0000
24.3200 1555.0000 1.0000
24.3600 1542.0000 1.0000
24.4000 1683.0000 1.0000
24.4400 1630.0000 1.0000
24.4800 1567.0000 1.0000
24.5200 1613.0000 1.0000
24.5600 1580.0000 1.0000
24.6000 1616.0000 1.0000
24.6400 1608.0000 1.0000
24.6800 1619.0000 1.0000
24.7200 1674.0000 1.0000
24.7600 1621.0000 1.0000
24.8000 1623.0000 1.0000
24.8400 1607.0000 1.0000
24.8800 1649.0000 1.0000
24.9200 1746.0000 1.0000
24.9600 1711.0000 1.0000
25.0000 1654.0000 1.0000
25.0400 1702.0000 1.0000
25.0800 1662.0000 1.0000
25.1200 1626.0000 1.0000
25.1600 1572.0000 1.0000
25.2000 1668.0000 1.0000
25.2400 1648.0000 1.0000
25.2800 1603.0000 1.0000
25.3200 1603.0000 1.0000
25.3600 1650.0000 1.0000
25.4000 1659.0000 1.0000
25.4400 1611.0000 1.0000
25.4800 1569.0000 1.0000
25.5200 1630.0000 1.0000
25.5600 1552.0000 1.0000
25.6000 1596.0000 1.0000
25.6400 1676.0000 1.0000
25.6800 1641.0000 1.0000
25.7200 1583.0000 1.0000
25.7600 1546.0000 1.0000
25.8000 1651.0000 1.0000
25.8400 1651.0000 1.0000
25.8800 1664.0000 1.0000
25.9200 1647.0000 1.0000
25.9600 1605.0000 1.0000
26.0000 1602.0000 1.0000
26.0400 1640.0000 1.0000
26.0800 1635.0000 1.0000
26.1200 1672.0000 1.0000
26.1600 1696.0000 1.0000
26.2000 1676.0000 1.0000
26.2400 1666.0000 1.0000
26.2800 1690.0000 1.0000
26.3200 1661.0000 1.0000
26.3600 1696.0000 1.0000
26.4000 1659.0000 1.0000
26.4400 1697.0000 1.0000
26.4800 1692.0000 1.0000
26.5200 1730.0000 1.0000
26.5600 1683.0000 1.0000
26.6000 1729.0000 1.0000
26.6400 1748.0000 1.0000
26.6800 1831.0000 1.0000
26.7200 1725.0000 1.0000
26.7600 1879.0000 1.0000
26.8000 1852.0000 1.0000
26.8400 1898.0000 1.0000
26.8800 1843.0000 1.0000
26.9200 1975.0000 1.0000
26.9600 2102.0000 1.0000
27.0000 2265.0000 1.0000
27.0400 2466.0000 1.0000
27.0800 2693.0000 1.0000
27.1200 3119.0000 1.0000
27.1600 3671.0000 1.0000
27.2000 4385.0000 1.0000
27.2400 5585.0000 1.0000
27.2800 6190.0000 1.0000
27.3200 6369.0000 1.0000
27.3600 5710.0000 1.0000
27.4000 4730.0000 1.0000
27.4400 3998.0000 1.0000
27.4800 3182.0000 1.0000
27.5200 2868.0000 1.0000
27.5600 2494.0000 1.0000
27.6000 2222.0000 1.0000
27.6400 2022.0000 1.0000
27.6800 2002.0000 1.0000
27.7200 1973.0000 1.0000
27.7600 1889.0000 1.0000
27.8000 1821.0000 1.0000
27.8400 1734.0000 1.0000
27.8800 1750.0000 1.0000
27.9200 1758.0000 1.0000
27.9600 1690.0000 1.0000
28.0000 1689.0000 1.0000
28.0400 1657.0000 1.0000
28.0800 1622.0000 1.0000
28.1200 1641.0000 1.0000
28.1600 1606.0000 1.0000
28.2000 1580.0000 1.0000
28.2400 1561.0000 1.0000
28.2800 1497.0000 1.0000
28.3200 1600.0000 1.0000
28.3600 1639.0000 1.0000
28.4000 1540.0000 1.0000
28.4400 1551.0000 1.0000
28.4800 1605.0000 1.0000
28.5200 1616.0000 1.0000
28.5600 1543.0000 1.0000
28.6000 1554.0000 1.0000
28.6400 1617.0000 1.0000
28.6800 1516.0000 1.0000
28.7200 1494.0000 1.0000
28.7600 1582.0000 1.0000
28.8000 1511.0000 1.0000
28.8400 1562.0000 1.0000
28.8800 1521.0000 1.0000
28.9200 1514.0000 1.0000
28.9600 1488.0000 1.0000
29.0000 1462.0000 1.0000
29.0400 1537.0000 1.0000
29.0800 1492.0000 1.0000
29.1200 1487.0000 1.0000
29.1600 1481.0000 1.0000
29.2000 1537.0000 1.0000
29.2400 1519.0000 1.0000
29.2800 1548.0000 1.0000
29.3200 1473.0000 1.0000
29.3600 1464.0000 1.0000
29.4000 1478.0000 1.0000
29.4400 1523.0000 1.0000
29.4800 1487.0000 1.0000
29.5200 1466.0000 1.0000
29.5600 1452.0000 1.0000
29.6000 1480.0000 1.0000
29.6400 1520.0000 1.0000
29.6800 1442.0000 1.0000
29.7200 1489.0000 1.0000
29.7600 1474.0000 1.0000
29.8000 1462.0000 1.0000
29.8400 1460.0000 1.0000
29.8800 1432.0000 1.0000
29.9200 1467.0000 1.0000
29.9600 1395.0000 1.0000
30.0000 1426.0000 1.0000
30.0400 1391.0000 1.0000
30.0800 1434.0000 1.0000
30.1200 1424.0000 1.0000
30.1600 1438.0000 1.0000
30.2000 1441.0000 1.0000
30.2400 1404.0000 1.0000
30.2800 1477.0000 1.0000
30.3200 1402.0000 1.0000
30.3600 1401.0000 1.0000
30.4000 1441.0000 1.0000
30.4400 1445.0000 1.0000
30.4800 1455.0000 1.0000
30.5200 1447.0000 1.0000
30.5600 1421.0000 1.0000
30.6000 1407.0000 1.0000
30.6400 1428.0000 1.0000
30.6800 1426.0000 1.0000
30.7200 1412.0000 1.0000
30.7600 1425.0000 1.0000
30.8000 1443.0000 1.0000
30.8400 1389.0000 1.0000
30.8800 1408.0000 1.0000
30.9200 1381.0000 1.0000
30.9600 1394.0000 1.0000
31.0000 1377.0000 1.0000
31.0400 1394.0000 1.0000
31.0800 1395.0000 1.0000
31.1200 1429.0000 1.0000
31.1600 1427.0000 1.0000
31.2000 1410.0000 1.0000
31.2400 1389.0000 1.0000
31.2800 1392.0000 1.0000
31.3200 1387.0000 1.0000
31.3600 1358.0000 1.0000
31.4000 1369.0000 1.0000
31.4400 1329.0000 1.0000
31.4800 1355.0000 1.0000
31.5200 1385.0000 1.0000
31.5600 1329.0000 1.0000
31.6000 1396.0000 1.0000
31.6400 1327.0000 1.0000
31.6800 1352.0000 1.0000
31.7200 1413.0000 1.0000
31.7600 1274.0000 1.0000
31.8000 1426.0000 1.0000
31.8400 1337.0000 1.0000
31.8800 1362.0000 1.0000
31.9200 1368.0000 1.0000
31.9600 1429.0000 1.0000
32.0000 1386.0000 1.0000
32.0400 1365.0000 1.0000
32.0800 1378.0000 1.0000
32.1200 1371.0000 1.0000
32.1600 1348.0000 1.0000
32.2000 1377.0000 1.0000
32.2400 1334.0000 1.0000
32.2800 1355.0000 1.0000
32.3200 1310.0000 1.0000
32.3600 1310.0000 1.0000
32.4000 1306.0000 1.0000
32.4400 1321.0000 1.0000
32.4800 1328.0000 1.0000
32.5200 1294.0000 1.0000
32.5600 1320.0000 1.0000
32.6000 1321.0000 1.0000
32.6400 1317.0000 1.0000
32.6800 1335.0000 1.0000
32.7200 1299.0000 1.0000
32.7600 1295.0000 1.0000
32.8000 1296.0000 1.0000
32.8400 1293.0000 1.0000
32.8800 1348.0000 1.0000
32.9200 1329.0000 1.0000
32.9600 1279.0000 1.0000
33.0000 1307.0000 1.0000
33.0400 1301.0000 1.0000
33.0800 1235.0000 1.0000
33.1200 1264.0000 1.0000
33.1600 1323.0000 1.0000
33.2000 1258.0000 1.0000
33.2400 1266.0000 1.0000
33.2800 1244.0000 1.0000
33.3200 1246.0000 1.0000
33.3600 1312.0000 1.0000
33.4000 1270.0000 1.0000
33.4400 1273.0000 1.0000
33.4800 1242.0000 1.0000
33.5200 1217.0000 1.0000
33.5600 1251.0000 1.0000
33.6000 1359.0000 1.0000
33.6400 1281.0000 1.0000
33.6800 1294.0000 1.0000
33.7200 1311.0000 1.0000
33.7600 1337.0000 1.0000
33.8000 1314.0000 1.0000
33.8400 1446.0000 1.0000
33.8800 1469.0000 1.0000
33.9200 1499.0000 1.0000
33.9600 1477.0000 1.0000
34.0000 1508.0000 1.0000
34.0400 1502.0000 1.0000
34.0800 1427.0000 1.0000
34.1200 1455.0000 1.0000
34.1600 1460.0000 1.0000
34.2000 1537.0000 1.0000
34.2400 1626.0000 1.0000
34.2800 1651.0000 1.0000
34.3200 1868.0000 1.0000
34.3600 2165.0000 1.0000
34.4000 2501.0000 1.0000
34.4400 2888.0000 1.0000
34.4800 3198.0000 1.0000
34.5200 3240.0000 1.0000
34.5600 3023.0000 1.0000
34.6000 2572.0000 1.0000
34.6400 2227.0000 1.0000
34.6800 1993.0000 1.0000
34.7200 1783.0000 1.0000
34.7600 1629.0000 1.0000
34.8000 1559.0000 1.0000
34.8400 1404.0000 1.0000
34.8800 1435.0000 1.0000
34.9200 1359.0000 1.0000
34.9600 1337.0000 1.0000
35.0000 1261.0000 1.0000
35.0400 1278.0000 1.0000
35.0800 1178.0000 1.0000
35.1200 1176.0000 1.0000
35.1600 1255.0000 1.0000
35.2000 1152.0000 1.0000
35.2400 1125.0000 1.0000
35.2800 1209.0000 1.0000
35.3200 1144.0000 1.0000
35.3600 1177.0000 1.0000
35.4000 1129.0000 1.0000
35.4400 1131.0000 1.0000
35.4800 1131.0000 1.0000
35.5200 1136.0000 1.0000
35.5600 1152.0000 1.0000
35.6000 1161.0000 1.0000
35.6400 1092.0000 1.0000
35.6800 1173.0000 1.0000
35.7200 1136.0000 1.0000
35.7600 1072.0000 1.0000
35.8000 1112.0000 1.0000
35.8400 1099.0000 1.0000
35.8800 1074.0000 1.0000
35.9200 1128.0000 1.0000
35.9600 1092.0000 1.0000
36.0000 1129.0000 1.0000
36.0400 1110.0000 1.0000
36.0800 1065.0000 1.0000
36.1200 1128.0000 1.0000
36.1600 1142.0000 1.0000
36.2000 1199.0000 1.0000
36.2400 1240.0000 1.0000
36.2800 1361.0000 1.0000
36.3200 1522.0000 1.0000
36.3600 1742.0000 1.0000
36.4000 1877.0000 1.0000
36.4400 1967.0000 1.0000
36.4800 1772.0000 1.0000
36.5200 1549.0000 1.0000
36.5600 1301.0000 1.0000
36.6000 1200.0000 1.0000
36.6400 1157.0000 1.0000
36.6800 1101.0000 1.0000
36.7200 1105.0000 1.0000
36.7600 1061.0000 1.0000
36.8000 1033.0000 1.0000
36.8400 1038.0000 1.0000
36.8800 1028.0000 1.0000
36.9200 1054.0000 1.0000
36.9600 1028.0000 1.0000
37.0000 988.0000 1.0000
37.0400 1021.0000 1.0000
37.0800 1049.0000 1.0000
37.1200 1004.0000 1.0000
37.1600 1055.0000 1.0000
37.2000 983.0000 1.0000
37.2400 1035.0000 1.0000
37.2800 1026.0000 1.0000
37.3200 1006.0000 1.0000
37.3600 1017.0000 1.0000
37.4000 989.0000 1.0000
37.4400 971.0000 1.0000
37.4800 1026.0000 1.0000
37.5200 953.0000 1.0000
37.5600 995.0000 1.0000
37.6000 991.0000 1.0000
37.6400 1012.0000 1.0000
37.6800 1048.0000 1.0000
37.7200 1034.0000 1.0000
37.7600 1003.0000 1.0000
37.8000 1006.0000 1.0000
37.8400 1018.0000 1.0000
37.8800 1044.0000 1.0000
37.9200 1047.0000 1.0000
37.9600 1023.0000 1.0000
38.0000 1038.0000 1.0000
38.0400 1086.0000 1.0000
38.0800 1144.0000 1.0000
38.1200 1120.0000 1.0000
38.1600 1244.0000 1.0000
38.2000 1410.0000 1.0000
38.2400 1524.0000 1.0000
38.2800 1649.0000 1.0000
38.3200 1974.0000 1.0000
38.3600 2287.0000 1.0000
38.4000 3058.0000 1.0000
38.4400 4043.0000 1.0000
38.4800 5128.0000 1.0000
38.5200 6014.0000 1.0000
38.5600 6024.0000 1.0000
38.6000 5648.0000 1.0000
38.6400 4759.0000 1.0000
38.6800 3848.0000 1.0000
38.7200 3002.0000 1.0000
38.7600 2318.0000 1.0000
38.8000 1849.0000 1.0000
38.8400 1573.0000 1.0000
38.8800 1370.0000 1.0000
38.9200 1256.0000 1.0000
38.9600 1124.0000 1.0000
39.0000 1113.0000 1.0000
39.0400 1008.0000 1.0000
39.0800 1040.0000 1.0000
39.1200 932.0000 1.0000
39.1600 992.0000 1.0000
39.2000 960.0000 1.0000
39.2400 944.0000 1.0000
39.2800 945.0000 1.0000
39.3200 948.0000 1.0000
39.3600 918.0000 1.0000
39.4000 981.0000 1.0000
39.4400 957.0000 1.0000
39.4800 927.0000 1.0000
39.5200 978.0000 1.0000
39.5600 978.0000 1.0000
39.6000 940.0000 1.0000
39.6400 960.0000 1.0000
39.6800 962.0000 1.0000
39.7200 889.0000 1.0000
39.7600 935.0000 1.0000
39.8000 892.0000 1.0000
39.8400 907.0000 1.0000
39.8800 895.0000 1.0000
39.9200 867.0000 1.0000
39.9600 931.0000 1.0000
40.0000 918.0000 1.0000
40.0400 873.0000 1.0000
40.0800 845.0000 1.0000
40.1200 862.0000 1.0000
40.1600 844.0000 1.0000
40.2000 863.0000 1.0000
40.2400 845.0000 1.0000
40.2800 854.0000 1.0000
40.3200 874.0000 1.0000
40.3600 828.0000 1.0000
40.4000 854.0000 1.0000
40.4400 886.0000 1.0000
40.4800 878.0000 1.0000
40.5200 801.0000 1.0000
40.5600 800.0000 1.0000
40.6000 865.0000 1.0000
40.6400 834.0000 1.0000
40.6800 855.0000 1.0000
40.7200 878.0000 1.0000
40.7600 859.0000 1.0000
40.8000 838.0000 1.0000
40.8400 843.0000 1.0000
40.8800 821.0000 1.0000
40.9200 836.0000 1.0000
40.9600 824.0000 1.0000
41.0000 820.0000 1.0000
41.0400 843.0000 1.0000
41.0800 867.0000 1.0000
41.1200 836.0000 1.0000
41.1600 852.0000 1.0000
41.2000 836.0000 1.0000
41.2400 829.0000 1.0000
41.2800 867.0000 1.0000
41.3200 843.0000 1.0000
41.3600 853.0000 1.0000
41.4000 836.0000 1.0000
41.4400 886.0000 1.0000
41.4800 852.0000 1.0000
41.5200 832.0000 1.0000
41.5600 885.0000 1.0000
41.6000 897.0000 1.0000
41.6400 860.0000 1.0000
41.6800 833.0000 1.0000
41.7200 839.0000 1.0000
41.7600 843.0000 1.0000
41.8000 886.0000 1.0000
41.8400 842.0000 1.0000
41.8800 819.0000 1.0000
41.9200 836.0000 1.0000
41.9600 841.0000 1.0000
42.0000 828.0000 1.0000
42.0400 832.0000 1.0000
42.0800 823.0000 1.0000
42.1200 802.0000 1.0000
42.1600 863.0000 1.0000
42.2000 828.0000 1.0000
42.2400 816.0000 1.0000
42.2800 837.0000 1.0000
42.3200 807.0000 1.0000
42.3600 865.0000 1.0000
42.4000 780.0000 1.0000
42.4400 788.0000 1.0000
42.4800 793.0000 1.0000
42.5200 814.0000 1.0000
42.5600 839.0000 1.0000
42.6000 789.0000 1.0000
42.6400 822.0000 1.0000
42.6800 816.0000 1.0000
42.7200 839.0000 1.0000
42.7600 810.0000 1.0000
42.8000 811.0000 1.0000
42.8400 816.0000 1.0000
42.8800 796.0000 1.0000
42.9200 787.0000 1.0000
42.9600 836.0000 1.0000
43.0000 842.0000 1.0000
43.0400 829.0000 1.0000
43.0800 822.0000 1.0000
43.1200 873.0000 1.0000
43.1600 844.0000 1.0000
43.2000 900.0000 1.0000
43.2400 881.0000 1.0000
43.2800 849.0000 1.0000
43.3200 863.0000 1.0000
43.3600 862.0000 1.0000
43.4000 813.0000 1.0000
43.4400 847.0000 1.0000
43.4800 856.0000 1.0000
43.5200 852.0000 1.0000
43.5600 852.0000 1.0000
43.6000 804.0000 1.0000
43.6400 777.0000 1.0000
43.6800 809.0000 1.0000
43.7200 768.0000 1.0000
43.7600 801.0000 1.0000
43.8000 781.0000 1.0000
43.8400 812.0000 1.0000
43.8800 807.0000 1.0000
43.9200 762.0000 1.0000
43.9600 788.0000 1.0000
44.0000 808.0000 1.0000
44.0400 793.0000 1.0000
44.0800 809.0000 1.0000
44.1200 776.0000 1.0000
44.1600 801.0000 1.0000
44.2000 868.0000 1.0000
44.2400 809.0000 1.0000
44.2800 834.0000 1.0000
44.3200 794.0000 1.0000
44.3600 785.0000 1.0000
44.4000 827.0000 1.0000
44.4400 805.0000 1.0000
44.4800 814.0000 1.0000
44.5200 775.0000 1.0000
44.5600 789.0000 1.0000
44.6000 755.0000 1.0000
44.6400 768.0000 1.0000
44.6800 775.0000 1.0000
44.7200 791.0000 1.0000
44.7600 795.0000 1.0000
44.8000 797.0000 1.0000
44.8400 784.0000 1.0000
44.8800 771.0000 1.0000
44.9200 743.0000 1.0000
44.9600 776.0000 1.0000
45.0000 782.0000 1.0000
45.0400 760.0000 1.0000
45.0800 767.0000 1.0000
45.1200 746.0000 1.0000
45.1600 791.0000 1.0000
45.2000 774.0000 1.0000
45.2400 756.0000 1.0000
45.2800 763.0000 1.0000
45.3200 826.0000 1.0000
45.3600 745.0000 1.0000
45.4000 742.0000 1.0000
45.4400 698.0000 1.0000
45.4800 775.0000 1.0000
45.5200 753.0000 1.0000
45.5600 787.0000 1.0000
45.6000 742.0000 1.0000
45.6400 728.0000 1.0000
45.6800 731.0000 1.0000
45.7200 795.0000 1.0000
45.7600 778.0000 1.0000
45.8000 788.0000 1.0000
45.8400 773.0000 1.0000
45.8800 738.0000 1.0000
45.9200 738.0000 1.0000
45.9600 800.0000 1.0000
46.0000 734.0000 1.0000
46.0400 760.0000 1.0000
46.0800 747.0000 1.0000
46.1200 759.0000 1.0000
46.1600 707.0000 1.0000
46.2000 731.0000 1.0000
46.2400 729.0000 1.0000
46.2800 765.0000 1.0000
46.3200 755.0000 1.0000
46.3600 754.0000 1.0000
46.4000 742.0000 1.0000
46.4400 781.0000 1.0000
46.4800 760.0000 1.0000
46.5200 696.0000 1.0000
46.5600 772.0000 1.0000
46.6000 752.0000 1.0000
46.6400 720.0000 1.0000
46.6800 743.0000 1.0000
46.7200 769.0000 1.0000
46.7600 757.0000 1.0000
46.8000 768.0000 1.0000
46.8400 754.0000 1.0000
46.8800 754.0000 1.0000
46.9200 765.0000 1.0000
46.9600 752.0000 1.0000
47.0000 799.0000 1.0000
47.0400 731.0000 1.0000
47.0800 741.0000 1.0000
47.1200 758.0000 1.0000
47.1600 740.0000 1.0000
47.2000 733.0000 1.0000
47.2400 720.0000 1.0000
47.2800 719.0000 1.0000
47.3200 714.0000 1.0000
47.3600 752.0000 1.0000
47.4000 763.0000 1.0000
47.4400 767.0000 1.0000
47.4800 755.0000 1.0000
47.5200 736.0000 1.0000
47.5600 694.0000 1.0000
47.6000 722.0000 1.0000
47.6400 716.0000 1.0000
47.6800 747.0000 1.0000
47.7200 700.0000 1.0000
47.7600 690.0000 1.0000
47.8000 728.0000 1.0000
47.8400 705.0000 1.0000
47.8800 720.0000 1.0000
47.9200 739.0000 1.0000
47.9600 730.0000 1.0000
48.0000 726.0000 1.0000
48.0400 688.0000 1.0000
48.0800 703.0000 1.0000
48.1200 707.0000 1.0000
48.1600 734.0000 1.0000
48.2000 686.0000 1.0000
48.2400 720.0000 1.0000
48.2800 691.0000 1.0000
48.3200 720.0000 1.0000
48.3600 706.0000 1.0000
48.4000 699.0000 1.0000
48.4400 704.0000 1.0000
48.4800 753.0000 1.0000
48.5200 718.0000 1.0000
48.5600 721.0000 1.0000
48.6000 696.0000 1.0000
48.6400 742.0000 1.0000
48.6800 692.0000 1.0000
48.7200 716.0000 1.0000
48.7600 715.0000 1.0000
48.8000 697.0000 1.0000
48.8400 725.0000 1.0000
48.8800 699.0000 1.0000
48.9200 708.0000 1.0000
48.9600 707.0000 1.0000
49.0000 668.0000 1.0000
49.0400 710.0000 1.0000
49.0800 717.0000 1.0000
49.1200 701.0000 1.0000
49.1600 737.0000 1.0000
49.2000 650.0000 1.0000
49.2400 723.0000 1.0000
49.2800 743.0000 1.0000
49.3200 706.0000 1.0000
49.3600 708.0000 1.0000
49.4000 667.0000 1.0000
49.4400 690.0000 1.0000
49.4800 710.0000 1.0000
49.5200 666.0000 1.0000
49.5600 688.0000 1.0000
49.6000 708.0000 1.0000
49.6400 739.0000 1.0000
49.6800 671.0000 1.0000
49.7200 695.0000 1.0000
49.7600 679.0000 1.0000
49.8000 670.0000 1.0000
49.8400 721.0000 1.0000
49.8800 745.0000 1.0000
49.9200 705.0000 1.0000
49.9600 697.0000 1.0000
50.0000 701.0000 1.0000
50.0400 694.0000 1.0000
50.0800 693.0000 1.0000
50.1200 738.0000 1.0000
50.1600 704.0000 1.0000
50.2000 746.0000 1.0000
50.2400 730.0000 1.0000
50.2800 740.0000 1.0000
50.3200 707.0000 1.0000
50.3600 732.0000 1.0000
50.4000 744.0000 1.0000
50.4400 724.0000 1.0000
50.4800 727.0000 1.0000
50.5200 690.0000 1.0000
50.5600 703.0000 1.0000
50.6000 704.0000 1.0000
50.6400 708.0000 1.0000
50.6800 695.0000 1.0000
50.7200 724.0000 1.0000
50.7600 724.0000 1.0000
50.8000 713.0000 1.0000
50.8400 704.0000 1.0000
50.8800 692.0000 1.0000
50.9200 710.0000 1.0000
50.9600 728.0000 1.0000
51.0000 684.0000 1.0000
51.0400 715.0000 1.0000
51.0800 706.0000 1.0000
51.1200 711.0000 1.0000
51.1600 712.0000 1.0000
51.2000 703.0000 1.0000
51.2400 715.0000 1.0000
51.2800 671.0000 1.0000
51.3200 762.0000 1.0000
51.3600 716.0000 1.0000
51.4000 695.0000 1.0000
51.4400 703.0000 1.0000
51.4800 723.0000 1.0000
51.5200 701.0000 1.0000
51.5600 718.0000 1.0000
51.6000 752.0000 1.0000
51.6400 712.0000 1.0000
51.6800 757.0000 1.0000
51.7200 735.0000 1.0000
51.7600 775.0000 1.0000
51.8000 824.0000 1.0000
51.8400 805.0000 1.0000
51.8800 852.0000 1.0000
51.9200 928.0000 1.0000
51.9600 1019.0000 1.0000
52.0000 1114.0000 1.0000
52.0400 1303.0000 1.0000
52.0800 1551.0000 1.0000
52.1200 1853.0000 1.0000
52.1600 2544.0000 1.0000
52.2000 3540.0000 1.0000
52.2400 4742.0000 1.0000
52.2800 5378.0000 1.0000
52.3200 5152.0000 1.0000
52.3600 4446.0000 1.0000
52.4000 3978.0000 1.0000
52.4400 3423.0000 1.0000
52.4800 2718.0000 1.0000
52.5200 2010.0000 1.0000
52.5600 1540.0000 1.0000
52.6000 1277.0000 1.0000
52.6400 1135.0000 1.0000
52.6800 1080.0000 1.0000
52.7200 910.0000 1.0000
52.7600 906.0000 1.0000
52.8000 857.0000 1.0000
52.8400 813.0000 1.0000
52.8800 785.0000 1.0000
52.9200 783.0000 1.0000
52.9600 775.0000 1.0000
53.0000 766.0000 1.0000
53.0400 734.0000 1.0000
53.0800 739.0000 1.0000
53.1200 741.0000 1.0000
53.1600 726.0000 1.0000
53.2000 747.0000 1.0000
53.2400 725.0000 1.0000
53.2800 701.0000 1.0000
53.3200 750.0000 1.0000
53.3600 711.0000 1.0000
53.4000 709.0000 1.0000
53.4400 703.0000 1.0000
53.4800 693.0000 1.0000
53.5200 720.0000 1.0000
53.5600 701.0000 1.0000
53.6000 659.0000 1.0000
53.6400 718.0000 1.0000
53.6800 708.0000 1.0000
53.7200 706.0000 1.0000
53.7600 701.0000 1.0000
53.8000 722.0000 1.0000
53.8400 707.0000 1.0000
53.8800 633.0000 1.0000
53.9200 668.0000 1.0000
53.9600 692.0000 1.0000
54.0000 668.0000 1.0000
54.0400 682.0000 1.0000
54.0800 690.0000 1.0000
54.1200 695.0000 1.0000
54.1600 703.0000 1.0000
54.2000 664.0000 1.0000
54.2400 661.0000 1.0000
54.2800 692.0000 1.0000
54.3200 683.0000 1.0000
54.3600 684.0000 1.0000
54.4000 694.0000 1.0000
54.4400 707.0000 1.0000
54.4800 693.0000 1.0000
54.5200 704.0000 1.0000
54.5600 692.0000 1.0000
54.6000 688.0000 1.0000
54.6400 672.0000 1.0000
54.6800 733.0000 1.0000
54.7200 751.0000 1.0000
54.7600 752.0000 1.0000
54.8000 689.0000 1.0000
54.8400 714.0000 1.0000
54.8800 781.0000 1.0000
54.9200 729.0000 1.0000
54.9600 768.0000 1.0000
55.0000 777.0000 1.0000
55.0400 772.0000 1.0000
55.0800 751.0000 1.0000
55.1200 791.0000 1.0000
55.1600 855.0000 1.0000
55.2000 958.0000 1.0000
55.2400 1016.0000 1.0000
55.2800 1046.0000 1.0000
55.3200 1036.0000 1.0000
55.3600 1015.0000 1.0000
55.4000 986.0000 1.0000
55.4400 960.0000 1.0000
55.4800 915.0000 1.0000
55.5200 848.0000 1.0000
55.5600 840.0000 1.0000
55.6000 823.0000 1.0000
55.6400 776.0000 1.0000
55.6800 719.0000 1.0000
55.7200 712.0000 1.0000
55.7600 763.0000 1.0000
55.8000 696.0000 1.0000
55.8400 693.0000 1.0000
55.8800 684.0000 1.0000
55.9200 664.0000 1.0000
55.9600 708.0000 1.0000
56.0000 678.0000 1.0000
56.0400 699.0000 1.0000
56.0800 650.0000 1.0000
56.1200 640.0000 1.0000
56.1600 674.0000 1.0000
56.2000 674.0000 1.0000
56.2400 663.0000 1.0000
56.2800 693.0000 1.0000
56.3200 695.0000 1.0000
56.3600 642.0000 1.0000
56.4000 688.0000 1.0000
56.4400 664.0000 1.0000
56.4800 659.0000 1.0000
56.5200 673.0000 1.0000
56.5600 640.0000 1.0000
56.6000 697.0000 1.0000
56.6400 614.0000 1.0000
56.6800 682.0000 1.0000
56.7200 711.0000 1.0000
56.7600 653.0000 1.0000
56.8000 654.0000 1.0000
56.8400 680.0000 1.0000
56.8800 633.0000 1.0000
56.9200 664.0000 1.0000
56.9600 700.0000 1.0000
57.0000 692.0000 1.0000
57.0400 674.0000 1.0000
57.0800 694.0000 1.0000
57.1200 685.0000 1.0000
57.1600 678.0000 1.0000
57.2000 680.0000 1.0000
57.2400 657.0000 1.0000
57.2800 707.0000 1.0000
57.3200 686.0000 1.0000
57.3600 659.0000 1.0000
57.4000 663.0000 1.0000
57.4400 651.0000 1.0000
57.4800 652.0000 1.0000
57.5200 676.0000 1.0000
57.5600 650.0000 1.0000
57.6000 622.0000 1.0000
57.6400 639.0000 1.0000
57.6800 713.0000 1.0000
57.7200 661.0000 1.0000
57.7600 604.0000 1.0000
57.8000 619.0000 1.0000
57.8400 605.0000 1.0000
57.8800 651.0000 1.0000
57.9200 674.0000 1.0000
57.9600 653.0000 1.0000
58.0000 682.0000 1.0000
58.0400 680.0000 1.0000
58.0800 716.0000 1.0000
58.1200 633.0000 1.0000
58.1600 677.0000 1.0000
58.2000 683.0000 1.0000
58.2400 647.0000 1.0000
58.2800 658.0000 1.0000
58.3200 708.0000 1.0000
58.3600 649.0000 1.0000
58.4000 654.0000 1.0000
58.4400 702.0000 1.0000
58.4800 654.0000 1.0000
58.5200 651.0000 1.0000
58.5600 655.0000 1.0000
58.6000 674.0000 1.0000
58.6400 700.0000 1.0000
58.6800 635.0000 1.0000
58.7200 680.0000 1.0000
58.7600 654.0000 1.0000
58.8000 635.0000 1.0000
58.8400 664.0000 1.0000
58.8800 625.0000 1.0000
58.9200 665.0000 1.0000
58.9600 694.0000 1.0000
59.0000 645.0000 1.0000
59.0400 631.0000 1.0000
59.0800 644.0000 1.0000
59.1200 640.0000 1.0000
59.1600 680.0000 1.0000
59.2000 703.0000 1.0000
59.2400 696.0000 1.0000
59.2800 691.0000 1.0000
59.3200 660.0000 1.0000
59.3600 661.0000 1.0000
59.4000 668.0000 1.0000
59.4400 643.0000 1.0000
59.4800 652.0000 1.0000
59.5200 661.0000 1.0000
59.5600 629.0000 1.0000
59.6000 616.0000 1.0000
59.6400 619.0000 1.0000
59.6800 680.0000 1.0000
59.7200 666.0000 1.0000
59.7600 669.0000 1.0000
59.8000 641.0000 1.0000
59.8400 630.0000 1.0000
59.8800 623.0000 1.0000
59.9200 651.0000 1.0000
59.9600 687.0000 1.0000
60.0000 677.0000 1.0000
60.0400 663.0000 1.0000
60.0800 632.0000 1.0000
60.1200 648.0000 1.0000
60.1600 632.0000 1.0000
60.2000 632.0000 1.0000
60.2400 641.0000 1.0000
60.2800 651.0000 1.0000
60.3200 677.0000 1.0000
60.3600 681.0000 1.0000
60.4000 645.0000 1.0000
60.4400 662.0000 1.0000
60.4800 694.0000 1.0000
60.5200 674.0000 1.0000
60.5600 639.0000 1.0000
60.6000 653.0000 1.0000
60.6400 612.0000 1.0000
60.6800 673.0000 1.0000
60.7200 677.0000 1.0000
60.7600 657.0000 1.0000
60.8000 657.0000 1.0000
60.8400 633.0000 1.0000
60.8800 674.0000 1.0000
60.9200 663.0000 1.0000
60.9600 658.0000 1.0000
61.0000 668.0000 1.0000
61.0400 625.0000 1.0000
61.0800 607.0000 1.0000
61.1200 673.0000 1.0000
61.1600 651.0000 1.0000
61.2000 655.0000 1.0000
61.2400 641.0000 1.0000
61.2800 636.0000 1.0000
61.3200 653.0000 1.0000
61.3600 673.0000 1.0000
61.4000 656.0000 1.0000
61.4400 663.0000 1.0000
61.4800 698.0000 1.0000
61.5200 686.0000 1.0000
61.5600 639.0000 1.0000
61.6000 699.0000 1.0000
61.6400 682.0000 1.0000
61.6800 693.0000 1.0000
61.7200 695.0000 1.0000
61.7600 666.0000 1.0000
61.8000 700.0000 1.0000
61.8400 720.0000 1.0000
61.8800 768.0000 1.0000
61.9200 719.0000 1.0000
61.9600 745.0000 1.0000
62.0000 819.0000 1.0000
62.0400 900.0000 1.0000
62.0800 972.0000 1.0000
62.1200 1028.0000 1.0000
62.1600 1199.0000 1.0000
62.2000 1262.0000 1.0000
62.2400 1420.0000 1.0000
62.2800 1450.0000 1.0000
62.3200 1490.0000 1.0000
62.3600 1428.0000 1.0000
62.4000 1444.0000 1.0000
62.4400 1386.0000 1.0000
62.4800 1251.0000 1.0000
62.5200 1244.0000 1.0000
62.5600 1132.0000 1.0000
62.6000 975.0000 1.0000
62.6400 934.0000 1.0000
62.6800 841.0000 1.0000
62.7200 810.0000 1.0000
62.7600 796.0000 1.0000
62.8000 761.0000 1.0000
62.8400 751.0000 1.0000
62.8800 691.0000 1.0000
62.9200 734.0000 1.0000
62.9600 750.0000 1.0000
63.0000 711.0000 1.0000
63.0400 736.0000 1.0000
63.0800 725.0000 1.0000
63.1200 709.0000 1.0000
63.1600 707.0000 1.0000
63.2000 694.0000 1.0000
63.2400 731.0000 1.0000
63.2800 642.0000 1.0000
63.3200 667.0000 1.0000
63.3600 663.0000 1.0000
63.4000 636.0000 1.0000
63.4400 666.0000 1.0000
63.4800 669.0000 1.0000
63.5200 711.0000 1.0000
63.5600 624.0000 1.0000
63.6000 619.0000 1.0000
63.6400 685.0000 1.0000
63.6800 656.0000 1.0000
63.7200 661.0000 1.0000
63.7600 715.0000 1.0000
63.8000 683.0000 1.0000
63.8400 655.0000 1.0000
63.8800 673.0000 1.0000
63.9200 623.0000 1.0000
63.9600 605.0000 1.0000
64.0000 627.0000 1.0000
64.0400 665.0000 1.0000
64.0800 644.0000 1.0000
64.1200 644.0000 1.0000
64.1600 647.0000 1.0000
64.2000 646.0000 1.0000
64.2400 643.0000 1.0000
64.2800 664.0000 1.0000
64.3200 687.0000 1.0000
64.3600 681.0000 1.0000
64.4000 684.0000 1.0000
64.4400 713.0000 1.0000
64.4800 706.0000 1.0000
64.5200 730.0000 1.0000
64.5600 758.0000 1.0000
64.6000 742.0000 1.0000
64.6400 885.0000 1.0000
64.6800 906.0000 1.0000
64.7200 856.0000 1.0000
64.7600 829.0000 1.0000
64.8000 813.0000 1.0000
64.8400 785.0000 1.0000
64.8800 766.0000 1.0000
64.9200 760.0000 1.0000
64.9600 728.0000 1.0000
65.0000 741.0000 1.0000
65.0400 720.0000 1.0000
65.0800 741.0000 1.0000
65.1200 703.0000 1.0000
65.1600 643.0000 1.0000
65.2000 696.0000 1.0000
65.2400 697.0000 1.0000
65.2800 674.0000 1.0000
65.3200 725.0000 1.0000
65.3600 705.0000 1.0000
65.4000 702.0000 1.0000
65.4400 668.0000 1.0000
65.4800 714.0000 1.0000
65.5200 660.0000 1.0000
65.5600 704.0000 1.0000
65.6000 716.0000 1.0000
65.6400 688.0000 1.0000
65.6800 742.0000 1.0000
65.7200 715.0000 1.0000
65.7600 767.0000 1.0000
65.8000 727.0000 1.0000
65.8400 757.0000 1.0000
65.8800 845.0000 1.0000
65.9200 838.0000 1.0000
65.9600 897.0000 1.0000
66.0000 935.0000 1.0000
66.0400 1079.0000 1.0000
66.0800 1245.0000 1.0000
66.1200 1449.0000 1.0000
66.1600 1851.0000 1.0000
66.2000 2303.0000 1.0000
66.2400 2670.0000 1.0000
66.2800 2746.0000 1.0000
66.3200 2688.0000 1.0000
66.3600 2448.0000 1.0000
66.4000 2347.0000 1.0000
66.4400 2180.0000 1.0000
66.4800 1957.0000 1.0000
66.5200 1742.0000 1.0000
66.5600 1416.0000 1.0000
66.6000 1269.0000 1.0000
66.6400 1061.0000 1.0000
66.6800 1022.0000 1.0000
66.7200 854.0000 1.0000
66.7600 902.0000 1.0000
66.8000 763.0000 1.0000
66.8400 758.0000 1.0000
66.8800 731.0000 1.0000
66.9200 719.0000 1.0000
66.9600 653.0000 1.0000
67.0000 641.0000 1.0000
67.0400 663.0000 1.0000
67.0800 615.0000 1.0000
67.1200 708.0000 1.0000
67.1600 635.0000 1.0000
67.2000 670.0000 1.0000
67.2400 618.0000 1.0000
67.2800 656.0000 1.0000
67.3200 620.0000 1.0000
67.3600 641.0000 1.0000
67.4000 669.0000 1.0000
67.4400 638.0000 1.0000
67.4800 599.0000 1.0000
67.5200 615.0000 1.0000
67.5600 619.0000 1.0000
67.6000 624.0000 1.0000
67.6400 645.0000 1.0000
67.6800 620.0000 1.0000
67.7200 595.0000 1.0000
67.7600 620.0000 1.0000
67.8000 621.0000 1.0000
67.8400 570.0000 1.0000
67.8800 641.0000 1.0000
67.9200 594.0000 1.0000
67.9600 626.0000 1.0000
68.0000 630.0000 1.0000
68.0400 617.0000 1.0000
68.0800 592.0000 1.0000
68.1200 594.0000 1.0000
68.1600 621.0000 1.0000
68.2000 617.0000 1.0000
68.2400 637.0000 1.0000
68.2800 568.0000 1.0000
68.3200 626.0000 1.0000
68.3600 622.0000 1.0000
68.4000 600.0000 1.0000
68.4400 610.0000 1.0000
68.4800 625.0000 1.0000
68.5200 589.0000 1.0000
68.5600 555.0000 1.0000
68.6000 568.0000 1.0000
68.6400 602.0000 1.0000
68.6800 587.0000 1.0000
68.7200 616.0000 1.0000
68.7600 596.0000 1.0000
68.8000 575.0000 1.0000
68.8400 574.0000 1.0000
68.8800 601.0000 1.0000
68.9200 609.0000 1.0000
68.9600 562.0000 1.0000
69.0000 595.0000 1.0000
69.0400 561.0000 1.0000
69.0800 572.0000 1.0000
69.1200 607.0000 1.0000
69.1600 575.0000 1.0000
69.2000 572.0000 1.0000
69.2400 588.0000 1.0000
69.2800 585.0000 1.0000
69.3200 587.0000 1.0000
69.3600 588.0000 1.0000
69.4000 596.0000 1.0000
69.4400 588.0000 1.0000
69.4800 610.0000 1.0000
69.5200 564.0000 1.0000
69.5600 590.0000 1.0000
69.6000 594.0000 1.0000
69.6400 611.0000 1.0000
69.6800 602.0000 1.0000
69.7200 609.0000 1.0000
69.7600 585.0000 1.0000
69.8000 561.0000 1.0000
69.8400 538.0000 1.0000
69.8800 591.0000 1.0000
69.9200 587.0000 1.0000
69.9600 547.0000 1.0000
70.0000 602.0000 1.0000
*RAS_INT_END
*RAS_TEMPERATURE_START
*RAS_TEMPERATURE_END
*RAS_DATA_END