File: Section2_75_samples/XRD/No_055_NSS2_4.ras
*RAS_DATA_START
*RAS_HEADER_START
*DISP_FMT_X "%.2f"
*DISP_FMT_Y "%.0f"
*DISP_FULLSCALE "15898.0000000000"
*DISP_LINE_COLOR "255.0000000000"
*DISP_LINE_STYLE "0.0000000000"
*DISP_LINE_WIDTH "0.2500000000"
*DISP_NOTE "測定データ-11"
*DISP_OFFSET_Y "0.0000000000"
*DISP_PEAKSEARCH_UNIT_Y "cps"
*DISP_RANGE_BOTTOM "0.0000000000"
*DISP_RANGE_LEFT "20.0000000000"
*DISP_RANGE_LOGCUTOFF "0.0100000000"
*DISP_RANGE_RIGHT "70.0000000000"
*DISP_RANGE_TOP "15898.0000000000"
*DISP_SCALE_MODE_Y "0.0000000000"
*DISP_TAB_NAME "2θ/θ"
*DISP_TITLE_Y "強度"
*DISP_UNIT_Y "cps"
*DISP_WINDOW_NAME "MSG_MACROENGINE"
*FILE_COMMENT " "
*FILE_MD5 ""
*FILE_MEMO " "
*FILE_OPERATOR "Administrator"
*FILE_SAMPLE " "
*FILE_TYPE "RAS_RAW"
*FILE_USERGROUP "システムマネージャ"
*FILE_VERSION "1.0000000000"
*HW_ATTACHMENT_ID "ATT0025"
*HW_ATTACHMENT_NAME "標準|Standard"
*HW_COUNTER_ID-0 "CUT0025"
*HW_COUNTER_ID-1 "CUT0020"
*HW_COUNTER_ID-2 "CUT0020"
*HW_COUNTER_ID-3 "CSL0021"
*HW_COUNTER_ID-4 "CMC0021"
*HW_COUNTER_NAME-0 "D/teX Ultra|D/teX Ultra"
*HW_COUNTER_NAME-1 "None|None"
*HW_COUNTER_NAME-2 "None|None"
*HW_COUNTER_NAME-3 "BBM|BBM"
*HW_COUNTER_NAME-4 "検出器モノクロメータ|Detector monochromator"
*HW_COUNTER_SELECT_NAME "D/teX Ultra|D/teX Ultra"
*HW_GONIOMETER_ID "GON0023"
*HW_GONIOMETER_NAME "SmartLab|SmartLab"
*HW_GONIOMETER_RADIUS-0 "90.0"
*HW_GONIOMETER_RADIUS-1 "114.0"
*HW_GONIOMETER_RADIUS-2 "190.0"
*HW_GONIOMETER_RADIUS-3 "300.0"
*HW_GONIOMETER_RADIUS-4 "187.0"
*HW_GONIOMETER_RADIUS-5 "300.0"
*HW_GONIOMETER_RADIUS-6 "113.0"
*HW_GONIOMETER_RADIUS-7 "331.0"
*HW_I_OPT_ID-0 "CBO0021"
*HW_I_OPT_ID-1 "ICR0023"
*HW_I_OPT_ID-2 "ISL0021"
*HW_I_OPT_ID-3 "ISO0021"
*HW_I_OPT_ID-4 "IAD0021"
*HW_I_OPT_ID-5 "IPR0001"
*HW_I_OPT_NAME-0 "CBOユニット|CBO unit"
*HW_I_OPT_NAME-1 "標準入射光学ユニット|Standard incident optical unit"
*HW_I_OPT_NAME-2 "標準入射スリットボックス|Standard incident slit box"
*HW_I_OPT_NAME-3 "入射平行スリット|Incident parallel slit"
*HW_I_OPT_NAME-4 "長手制限スリット|Length limiting slit"
*HW_I_OPT_NAME-5 "None|None"
*HW_R_ATTENUATER_AUTOMODE "0"
*HW_R_OPT_ID-0 "RSS0021"
*HW_R_OPT_ID-1 "RCR0023"
*HW_R_OPT_ID-2 "RSO0021"
*HW_R_OPT_ID-3 "RRS0021"
*HW_R_OPT_ID-4 "ATN0021"
*HW_R_OPT_ID-5 "RFL0021"
*HW_R_OPT_ID-6 "RAD0021"
*HW_R_OPT_NAME-0 "標準受光スリットボックス1|Standard receiving slit box # 1"
*HW_R_OPT_NAME-1 "標準受光光学ユニット1|Standard receiving unit # 1"
*HW_R_OPT_NAME-2 "標準受光光学ユニット2|Standard receiving optical unit # 2"
*HW_R_OPT_NAME-3 "標準受光スリットボックス2|Standard receiving slit box # 2"
*HW_R_OPT_NAME-4 "標準アッテネータ|Standard Attenuator"
*HW_R_OPT_NAME-5 "Cu Kβ|Cu K-beta"
*HW_R_OPT_NAME-6 "調整用受光スリット|Alignment receiving slit"
*HW_SAMPLE_HOLDER_ID "SMP0023"
*HW_SAMPLE_HOLDER_NAME "標準Zステージ|Standard Z stage"
*HW_XG_CURRENT_MAX "50"
*HW_XG_CURRENT_MIN "2"
*HW_XG_CURRENT_RESOLUTION "1"
*HW_XG_CURRENT_UNIT "mA"
*HW_XG_FOCUS "1mm x 10mm"
*HW_XG_FOCUS_TYPE "Normal"
*HW_XG_ID ""
*HW_XG_NAME "3kW 封入管(ID:1200)|3kW Sealed tube(ID:1200)"
*HW_XG_TARGET_ATOMIC_NUMBER "29.0000000000"
*HW_XG_TARGET_NAME "Cu"
*HW_XG_TYPE "Hermetic"
*HW_XG_VOLTAGE_MAX "60"
*HW_XG_VOLTAGE_MIN "20"
*HW_XG_VOLTAGE_RESOLUTION "1"
*HW_XG_VOLTAGE_UNIT "kV"
*HW_XG_WATT_MAX "1.500"
*HW_XG_WATT_UNIT "kW"
*HW_XG_WAVE_LENGTH_ALPHA1 "1.540593"
*HW_XG_WAVE_LENGTH_ALPHA2 "1.544414"
*HW_XG_WAVE_LENGTH_BETA "1.392250"
*MEAS_COND_AXIS_NAME-0 "2θ/θ"
*MEAS_COND_AXIS_NAME-1 "2θ"
*MEAS_COND_AXIS_NAME-2 "ω"
*MEAS_COND_AXIS_NAME-3 "Z"
*MEAS_COND_AXIS_NAME-4 "2θ/ω"
*MEAS_COND_AXIS_NAME-5 "θs"
*MEAS_COND_AXIS_NAME-6 "θd"
*MEAS_COND_AXIS_NAME-7 "Ts"
*MEAS_COND_AXIS_NAME-8 "CBO選択スリット"
*MEAS_COND_AXIS_NAME-9 "M"
*MEAS_COND_AXIS_NAME-10 "入射平行スリット"
*MEAS_COND_AXIS_NAME-11 "入射スリット"
*MEAS_COND_AXIS_NAME-12 ""
*MEAS_COND_AXIS_NAME-13 "Zs"
*MEAS_COND_AXIS_NAME-14 "入射光学素子"
*MEAS_COND_AXIS_NAME-15 "長手制限スリット"
*MEAS_COND_AXIS_NAME-16 "センタースリット"
*MEAS_COND_AXIS_NAME-17 "フィルター"
*MEAS_COND_AXIS_NAME-18 "受光スリット1"
*MEAS_COND_AXIS_NAME-19 "受光スリット2"
*MEAS_COND_AXIS_NAME-20 "受光光学素子"
*MEAS_COND_AXIS_NAME-21 "受光平行スリット"
*MEAS_COND_AXIS_NAME-22 "調整用受光スリット"
*MEAS_COND_AXIS_NAME-23 ""
*MEAS_COND_AXIS_NAME-24 ""
*MEAS_COND_AXIS_NAME-25 "Zd"
*MEAS_COND_AXIS_NAME-26 "アッテネータ"
*MEAS_COND_AXIS_NAME-27 "検出器モノクロメータ"
*MEAS_COND_AXIS_NAME-28 "モノクロメータスリット"
*MEAS_COND_AXIS_NAME-29 "プライマリビーム"
*MEAS_COND_AXIS_NAME-30 "PHA"
*MEAS_COND_AXIS_NAME_INTERNAL-0 "TwoThetaTheta"
*MEAS_COND_AXIS_NAME_INTERNAL-1 "TwoTheta"
*MEAS_COND_AXIS_NAME_INTERNAL-2 "Omega"
*MEAS_COND_AXIS_NAME_INTERNAL-3 "Z"
*MEAS_COND_AXIS_NAME_INTERNAL-4 "TwoThetaOmega"
*MEAS_COND_AXIS_NAME_INTERNAL-5 "ThetaS"
*MEAS_COND_AXIS_NAME_INTERNAL-6 "ThetaD"
*MEAS_COND_AXIS_NAME_INTERNAL-7 "Ts"
*MEAS_COND_AXIS_NAME_INTERNAL-8 "CBO"
*MEAS_COND_AXIS_NAME_INTERNAL-9 "CBO-M"
*MEAS_COND_AXIS_NAME_INTERNAL-10 "IncidentSollerSlit"
*MEAS_COND_AXIS_NAME_INTERNAL-11 "IncidentSlitBox"
*MEAS_COND_AXIS_NAME_INTERNAL-12 "IncidentSlitBox-_Axis"
*MEAS_COND_AXIS_NAME_INTERNAL-13 "Zs"
*MEAS_COND_AXIS_NAME_INTERNAL-14 "IncidentMonochromator"
*MEAS_COND_AXIS_NAME_INTERNAL-15 "IncidentAxdSlit"
*MEAS_COND_AXIS_NAME_INTERNAL-16 "CenterSlit"
*MEAS_COND_AXIS_NAME_INTERNAL-17 "Filter"
*MEAS_COND_AXIS_NAME_INTERNAL-18 "ReceivingSlitBox1"
*MEAS_COND_AXIS_NAME_INTERNAL-19 "ReceivingSlitBox2"
*MEAS_COND_AXIS_NAME_INTERNAL-20 "ReceivingOptics"
*MEAS_COND_AXIS_NAME_INTERNAL-21 "ReceivingSollerSlit"
*MEAS_COND_AXIS_NAME_INTERNAL-22 "ReceivingAxdSlit"
*MEAS_COND_AXIS_NAME_INTERNAL-23 "ReceivingSlitBox1-_Axis"
*MEAS_COND_AXIS_NAME_INTERNAL-24 "ReceivingSlitBox2-_Axis"
*MEAS_COND_AXIS_NAME_INTERNAL-25 "ReceivingSlitBox2-Zd"
*MEAS_COND_AXIS_NAME_INTERNAL-26 "Attenuator"
*MEAS_COND_AXIS_NAME_INTERNAL-27 "CounterMonochromator"
*MEAS_COND_AXIS_NAME_INTERNAL-28 "CounterSlit"
*MEAS_COND_AXIS_NAME_INTERNAL-29 "IncidentPrimary"
*MEAS_COND_AXIS_NAME_INTERNAL-30 "PHA"
*MEAS_COND_AXIS_NAME_MAGICNO-0 "83951616.0000000000"
*MEAS_COND_AXIS_NAME_MAGICNO-1 "268632064.0000000000"
*MEAS_COND_AXIS_NAME_MAGICNO-2 "268500992.0000000000"
*MEAS_COND_AXIS_NAME_MAGICNO-3 "285278208.0000000000"
*MEAS_COND_AXIS_NAME_MAGICNO-4 "83951616.0000000000"
*MEAS_COND_AXIS_NAME_MAGICNO-5 "131072.0000000000"
*MEAS_COND_AXIS_NAME_MAGICNO-6 "131072.0000000000"
*MEAS_COND_AXIS_NAME_MAGICNO-7 "318898176.0000000000"
*MEAS_COND_AXIS_NAME_MAGICNO-8 "20971521.0000000000"
*MEAS_COND_AXIS_NAME_MAGICNO-9 "285343744.0000000000"
*MEAS_COND_AXIS_NAME_MAGICNO-10 "20971521.0000000000"
*MEAS_COND_AXIS_NAME_MAGICNO-11 "22020097.0000000000"
*MEAS_COND_AXIS_NAME_MAGICNO-12 "25165824.0000000000"
*MEAS_COND_AXIS_NAME_MAGICNO-13 "318898176.0000000000"
*MEAS_COND_AXIS_NAME_MAGICNO-14 "1.0000000000"
*MEAS_COND_AXIS_NAME_MAGICNO-15 "20971521.0000000000"
*MEAS_COND_AXIS_NAME_MAGICNO-16 "20971521.0000000000"
*MEAS_COND_AXIS_NAME_MAGICNO-17 "20971521.0000000000"
*MEAS_COND_AXIS_NAME_MAGICNO-18 "23068673.0000000000"
*MEAS_COND_AXIS_NAME_MAGICNO-19 "23068673.0000000000"
*MEAS_COND_AXIS_NAME_MAGICNO-20 "20971521.0000000000"
*MEAS_COND_AXIS_NAME_MAGICNO-21 "20971521.0000000000"
*MEAS_COND_AXIS_NAME_MAGICNO-22 "20971521.0000000000"
*MEAS_COND_AXIS_NAME_MAGICNO-23 "25165824.0000000000"
*MEAS_COND_AXIS_NAME_MAGICNO-24 "25165824.0000000000"
*MEAS_COND_AXIS_NAME_MAGICNO-25 "285343744.0000000000"
*MEAS_COND_AXIS_NAME_MAGICNO-26 "17301505.0000000000"
*MEAS_COND_AXIS_NAME_MAGICNO-27 "20971521.0000000000"
*MEAS_COND_AXIS_NAME_MAGICNO-28 "20971521.0000000000"
*MEAS_COND_AXIS_NAME_MAGICNO-29 "20971521.0000000000"
*MEAS_COND_AXIS_NAME_MAGICNO-30 "0.0000000000"
*MEAS_COND_AXIS_OFFSET-0 "-"
*MEAS_COND_AXIS_OFFSET-1 "-0.1081000000"
*MEAS_COND_AXIS_OFFSET-2 "0.3758000000"
*MEAS_COND_AXIS_OFFSET-3 "-"
*MEAS_COND_AXIS_OFFSET-4 "-"
*MEAS_COND_AXIS_OFFSET-5 "0.3758000000"
*MEAS_COND_AXIS_OFFSET-6 "-0.4839000000"
*MEAS_COND_AXIS_OFFSET-7 "-"
*MEAS_COND_AXIS_OFFSET-8 "-"
*MEAS_COND_AXIS_OFFSET-9 "-"
*MEAS_COND_AXIS_OFFSET-10 "-"
*MEAS_COND_AXIS_OFFSET-11 "-"
*MEAS_COND_AXIS_OFFSET-12 "-"
*MEAS_COND_AXIS_OFFSET-13 "-"
*MEAS_COND_AXIS_OFFSET-14 "-"
*MEAS_COND_AXIS_OFFSET-15 "-"
*MEAS_COND_AXIS_OFFSET-16 "-"
*MEAS_COND_AXIS_OFFSET-17 "-"
*MEAS_COND_AXIS_OFFSET-18 "-"
*MEAS_COND_AXIS_OFFSET-19 "-"
*MEAS_COND_AXIS_OFFSET-20 "-"
*MEAS_COND_AXIS_OFFSET-21 "-"
*MEAS_COND_AXIS_OFFSET-22 "-"
*MEAS_COND_AXIS_OFFSET-23 "-"
*MEAS_COND_AXIS_OFFSET-24 "-"
*MEAS_COND_AXIS_OFFSET-25 "-"
*MEAS_COND_AXIS_OFFSET-26 "-"
*MEAS_COND_AXIS_OFFSET-27 "-"
*MEAS_COND_AXIS_OFFSET-28 "-"
*MEAS_COND_AXIS_OFFSET-29 "-"
*MEAS_COND_AXIS_OFFSET-30 "-"
*MEAS_COND_AXIS_POSITION-0 "0.0000000000"
*MEAS_COND_AXIS_POSITION-1 "0.0000000000"
*MEAS_COND_AXIS_POSITION-2 "0.0000000000"
*MEAS_COND_AXIS_POSITION-3 "-0.5500000000"
*MEAS_COND_AXIS_POSITION-4 "0.0000000000"
*MEAS_COND_AXIS_POSITION-5 "0.0000000000"
*MEAS_COND_AXIS_POSITION-6 "0.0000000000"
*MEAS_COND_AXIS_POSITION-7 "-0.4278800000"
*MEAS_COND_AXIS_POSITION-8 "BB"
*MEAS_COND_AXIS_POSITION-9 "0.0000000000"
*MEAS_COND_AXIS_POSITION-10 "Soller_slit_5.0deg"
*MEAS_COND_AXIS_POSITION-11 "2/3deg"
*MEAS_COND_AXIS_POSITION-12 "2.2088000000"
*MEAS_COND_AXIS_POSITION-13 "-0.4140600000"
*MEAS_COND_AXIS_POSITION-14 "0.0000000000"
*MEAS_COND_AXIS_POSITION-15 "10.0mm"
*MEAS_COND_AXIS_POSITION-16 "None"
*MEAS_COND_AXIS_POSITION-17 "Cu_K-beta"
*MEAS_COND_AXIS_POSITION-18 "13.000mm"
*MEAS_COND_AXIS_POSITION-19 "13.000mm"
*MEAS_COND_AXIS_POSITION-20 "No_unit"
*MEAS_COND_AXIS_POSITION-21 "Soller_slit_5.0deg"
*MEAS_COND_AXIS_POSITION-22 "None"
*MEAS_COND_AXIS_POSITION-23 "13.0000000000"
*MEAS_COND_AXIS_POSITION-24 "13.0000000000"
*MEAS_COND_AXIS_POSITION-25 "0.0109400000"
*MEAS_COND_AXIS_POSITION-26 "Open"
*MEAS_COND_AXIS_POSITION-27 "None"
*MEAS_COND_AXIS_POSITION-28 "None"
*MEAS_COND_AXIS_POSITION-29 "None"
*MEAS_COND_AXIS_POSITION-30 "38.0000000000"
*MEAS_COND_AXIS_UNIT-0 "deg"
*MEAS_COND_AXIS_UNIT-1 "deg"
*MEAS_COND_AXIS_UNIT-2 "deg"
*MEAS_COND_AXIS_UNIT-3 "mm"
*MEAS_COND_AXIS_UNIT-4 "deg"
*MEAS_COND_AXIS_UNIT-5 "deg"
*MEAS_COND_AXIS_UNIT-6 "deg"
*MEAS_COND_AXIS_UNIT-7 "mm"
*MEAS_COND_AXIS_UNIT-8 ""
*MEAS_COND_AXIS_UNIT-9 "pulse"
*MEAS_COND_AXIS_UNIT-10 ""
*MEAS_COND_AXIS_UNIT-11 ""
*MEAS_COND_AXIS_UNIT-12 "mm"
*MEAS_COND_AXIS_UNIT-13 "mm"
*MEAS_COND_AXIS_UNIT-14 ""
*MEAS_COND_AXIS_UNIT-15 ""
*MEAS_COND_AXIS_UNIT-16 ""
*MEAS_COND_AXIS_UNIT-17 ""
*MEAS_COND_AXIS_UNIT-18 ""
*MEAS_COND_AXIS_UNIT-19 ""
*MEAS_COND_AXIS_UNIT-20 ""
*MEAS_COND_AXIS_UNIT-21 ""
*MEAS_COND_AXIS_UNIT-22 ""
*MEAS_COND_AXIS_UNIT-23 "mm"
*MEAS_COND_AXIS_UNIT-24 "mm"
*MEAS_COND_AXIS_UNIT-25 "mm"
*MEAS_COND_AXIS_UNIT-26 ""
*MEAS_COND_AXIS_UNIT-27 ""
*MEAS_COND_AXIS_UNIT-28 ""
*MEAS_COND_AXIS_UNIT-29 ""
*MEAS_COND_AXIS_UNIT-30 "div"
*MEAS_COND_COUNTER_CNTLOSS_CORR "0.0000000000"
*MEAS_COND_COUNTER_PHABASE "38.0000000000"
*MEAS_COND_COUNTER_PHAWINDOW "16.0000000000"
*MEAS_COND_COUNTER_PHA_UNIT "div"
*MEAS_COND_COUNTER_TAUDIFF "30.0000000000"
*MEAS_COND_COUNTER_TAUINT "0.0000000000"
*MEAS_COND_IRRADIATION_MODE "OFF"
*MEAS_COND_IRRADIATION_WIDTH ""
*MEAS_COND_OPT_ATTR "集中法"
*MEAS_COND_OPT_NAME "@集中法"
*MEAS_COND_UNSYMMETRIC_MODE "OFF"
*MEAS_COND_XG_CURRENT "30.0000000000"
*MEAS_COND_XG_VOLTAGE "40.0000000000"
*MEAS_COND_XG_WAVE_TYPE "Ka"
*MEAS_DATA_COUNT "5001.0000000000"
*MEAS_SCAN_AXIS_X "2θ/θ"
*MEAS_SCAN_AXIS_X_INTERNAL "TwoThetaTheta"
*MEAS_SCAN_END_TIME "07/12/21 17:57:31"
*MEAS_SCAN_MODE "CONTINUOUS"
*MEAS_SCAN_MONITOR "0"
*MEAS_SCAN_RESOLUTION_X "0.0002"
*MEAS_SCAN_SPEED "1.0"
*MEAS_SCAN_SPEED_UNIT "deg/min"
*MEAS_SCAN_START "20.0000000000"
*MEAS_SCAN_START_TIME "07/12/21 17:04:38"
*MEAS_SCAN_STEP "0.0100000000"
*MEAS_SCAN_STOP "70.0000000000"
*MEAS_SCAN_UNIT_X "deg"
*MEAS_SCAN_UNIT_Y "counts"
*RAS_HEADER_END
*RAS_INT_START
20.0000 1753.0000 1.0000
20.0400 1689.0000 1.0000
20.0800 1671.0000 1.0000
20.1200 1732.0000 1.0000
20.1600 1741.0000 1.0000
20.2000 1639.0000 1.0000
20.2400 1724.0000 1.0000
20.2800 1709.0000 1.0000
20.3200 1689.0000 1.0000
20.3600 1665.0000 1.0000
20.4000 1748.0000 1.0000
20.4400 1697.0000 1.0000
20.4800 1735.0000 1.0000
20.5200 1686.0000 1.0000
20.5600 1689.0000 1.0000
20.6000 1703.0000 1.0000
20.6400 1743.0000 1.0000
20.6800 1716.0000 1.0000
20.7200 1703.0000 1.0000
20.7600 1720.0000 1.0000
20.8000 1676.0000 1.0000
20.8400 1636.0000 1.0000
20.8800 1697.0000 1.0000
20.9200 1713.0000 1.0000
20.9600 1712.0000 1.0000
21.0000 1727.0000 1.0000
21.0400 1718.0000 1.0000
21.0800 1723.0000 1.0000
21.1200 1682.0000 1.0000
21.1600 1709.0000 1.0000
21.2000 1704.0000 1.0000
21.2400 1694.0000 1.0000
21.2800 1717.0000 1.0000
21.3200 1806.0000 1.0000
21.3600 1698.0000 1.0000
21.4000 1699.0000 1.0000
21.4400 1736.0000 1.0000
21.4800 1704.0000 1.0000
21.5200 1783.0000 1.0000
21.5600 1702.0000 1.0000
21.6000 1758.0000 1.0000
21.6400 1745.0000 1.0000
21.6800 1683.0000 1.0000
21.7200 1704.0000 1.0000
21.7600 1726.0000 1.0000
21.8000 1804.0000 1.0000
21.8400 1736.0000 1.0000
21.8800 1740.0000 1.0000
21.9200 1758.0000 1.0000
21.9600 1708.0000 1.0000
22.0000 1709.0000 1.0000
22.0400 1767.0000 1.0000
22.0800 1719.0000 1.0000
22.1200 1786.0000 1.0000
22.1600 1700.0000 1.0000
22.2000 1643.0000 1.0000
22.2400 1763.0000 1.0000
22.2800 1832.0000 1.0000
22.3200 1704.0000 1.0000
22.3600 1812.0000 1.0000
22.4000 1702.0000 1.0000
22.4400 1753.0000 1.0000
22.4800 1814.0000 1.0000
22.5200 1753.0000 1.0000
22.5600 1730.0000 1.0000
22.6000 1725.0000 1.0000
22.6400 1733.0000 1.0000
22.6800 1748.0000 1.0000
22.7200 1780.0000 1.0000
22.7600 1772.0000 1.0000
22.8000 1687.0000 1.0000
22.8400 1742.0000 1.0000
22.8800 1802.0000 1.0000
22.9200 1741.0000 1.0000
22.9600 1726.0000 1.0000
23.0000 1748.0000 1.0000
23.0400 1821.0000 1.0000
23.0800 1787.0000 1.0000
23.1200 1777.0000 1.0000
23.1600 1780.0000 1.0000
23.2000 1763.0000 1.0000
23.2400 1742.0000 1.0000
23.2800 1729.0000 1.0000
23.3200 1782.0000 1.0000
23.3600 1752.0000 1.0000
23.4000 1782.0000 1.0000
23.4400 1745.0000 1.0000
23.4800 1732.0000 1.0000
23.5200 1765.0000 1.0000
23.5600 1790.0000 1.0000
23.6000 1846.0000 1.0000
23.6400 1814.0000 1.0000
23.6800 1751.0000 1.0000
23.7200 1837.0000 1.0000
23.7600 1800.0000 1.0000
23.8000 1732.0000 1.0000
23.8400 1803.0000 1.0000
23.8800 1815.0000 1.0000
23.9200 1757.0000 1.0000
23.9600 1793.0000 1.0000
24.0000 1793.0000 1.0000
24.0400 1781.0000 1.0000
24.0800 1757.0000 1.0000
24.1200 1808.0000 1.0000
24.1600 1880.0000 1.0000
24.2000 1719.0000 1.0000
24.2400 1728.0000 1.0000
24.2800 1825.0000 1.0000
24.3200 1824.0000 1.0000
24.3600 1815.0000 1.0000
24.4000 1824.0000 1.0000
24.4400 1803.0000 1.0000
24.4800 1815.0000 1.0000
24.5200 1847.0000 1.0000
24.5600 1820.0000 1.0000
24.6000 1801.0000 1.0000
24.6400 1772.0000 1.0000
24.6800 1794.0000 1.0000
24.7200 1881.0000 1.0000
24.7600 1877.0000 1.0000
24.8000 1907.0000 1.0000
24.8400 1817.0000 1.0000
24.8800 1862.0000 1.0000
24.9200 1886.0000 1.0000
24.9600 1824.0000 1.0000
25.0000 1865.0000 1.0000
25.0400 1890.0000 1.0000
25.0800 1830.0000 1.0000
25.1200 1916.0000 1.0000
25.1600 1910.0000 1.0000
25.2000 1892.0000 1.0000
25.2400 1804.0000 1.0000
25.2800 1815.0000 1.0000
25.3200 1829.0000 1.0000
25.3600 1914.0000 1.0000
25.4000 1797.0000 1.0000
25.4400 1861.0000 1.0000
25.4800 1791.0000 1.0000
25.5200 1800.0000 1.0000
25.5600 1835.0000 1.0000
25.6000 1830.0000 1.0000
25.6400 1874.0000 1.0000
25.6800 1858.0000 1.0000
25.7200 1823.0000 1.0000
25.7600 1832.0000 1.0000
25.8000 1848.0000 1.0000
25.8400 1908.0000 1.0000
25.8800 1793.0000 1.0000
25.9200 1858.0000 1.0000
25.9600 1811.0000 1.0000
26.0000 1799.0000 1.0000
26.0400 1798.0000 1.0000
26.0800 1897.0000 1.0000
26.1200 1839.0000 1.0000
26.1600 1819.0000 1.0000
26.2000 1909.0000 1.0000
26.2400 1905.0000 1.0000
26.2800 1901.0000 1.0000
26.3200 1897.0000 1.0000
26.3600 1829.0000 1.0000
26.4000 1895.0000 1.0000
26.4400 1872.0000 1.0000
26.4800 1821.0000 1.0000
26.5200 1919.0000 1.0000
26.5600 1967.0000 1.0000
26.6000 1968.0000 1.0000
26.6400 1999.0000 1.0000
26.6800 1998.0000 1.0000
26.7200 1962.0000 1.0000
26.7600 1960.0000 1.0000
26.8000 2055.0000 1.0000
26.8400 2122.0000 1.0000
26.8800 2112.0000 1.0000
26.9200 2251.0000 1.0000
26.9600 2396.0000 1.0000
27.0000 2708.0000 1.0000
27.0400 2897.0000 1.0000
27.0800 3129.0000 1.0000
27.1200 3666.0000 1.0000
27.1600 4444.0000 1.0000
27.2000 5590.0000 1.0000
27.2400 6498.0000 1.0000
27.2800 6976.0000 1.0000
27.3200 6499.0000 1.0000
27.3600 5467.0000 1.0000
27.4000 4409.0000 1.0000
27.4400 3751.0000 1.0000
27.4800 3107.0000 1.0000
27.5200 2799.0000 1.0000
27.5600 2581.0000 1.0000
27.6000 2429.0000 1.0000
27.6400 2185.0000 1.0000
27.6800 2126.0000 1.0000
27.7200 2112.0000 1.0000
27.7600 2035.0000 1.0000
27.8000 2031.0000 1.0000
27.8400 1913.0000 1.0000
27.8800 1859.0000 1.0000
27.9200 1955.0000 1.0000
27.9600 1930.0000 1.0000
28.0000 1910.0000 1.0000
28.0400 1822.0000 1.0000
28.0800 1812.0000 1.0000
28.1200 1866.0000 1.0000
28.1600 1899.0000 1.0000
28.2000 1809.0000 1.0000
28.2400 1789.0000 1.0000
28.2800 1832.0000 1.0000
28.3200 1816.0000 1.0000
28.3600 1840.0000 1.0000
28.4000 1778.0000 1.0000
28.4400 1783.0000 1.0000
28.4800 1748.0000 1.0000
28.5200 1759.0000 1.0000
28.5600 1709.0000 1.0000
28.6000 1767.0000 1.0000
28.6400 1788.0000 1.0000
28.6800 1745.0000 1.0000
28.7200 1772.0000 1.0000
28.7600 1804.0000 1.0000
28.8000 1770.0000 1.0000
28.8400 1733.0000 1.0000
28.8800 1718.0000 1.0000
28.9200 1705.0000 1.0000
28.9600 1688.0000 1.0000
29.0000 1690.0000 1.0000
29.0400 1721.0000 1.0000
29.0800 1739.0000 1.0000
29.1200 1727.0000 1.0000
29.1600 1708.0000 1.0000
29.2000 1712.0000 1.0000
29.2400 1656.0000 1.0000
29.2800 1704.0000 1.0000
29.3200 1587.0000 1.0000
29.3600 1662.0000 1.0000
29.4000 1712.0000 1.0000
29.4400 1648.0000 1.0000
29.4800 1645.0000 1.0000
29.5200 1667.0000 1.0000
29.5600 1659.0000 1.0000
29.6000 1708.0000 1.0000
29.6400 1688.0000 1.0000
29.6800 1652.0000 1.0000
29.7200 1703.0000 1.0000
29.7600 1635.0000 1.0000
29.8000 1645.0000 1.0000
29.8400 1663.0000 1.0000
29.8800 1685.0000 1.0000
29.9200 1627.0000 1.0000
29.9600 1654.0000 1.0000
30.0000 1658.0000 1.0000
30.0400 1607.0000 1.0000
30.0800 1672.0000 1.0000
30.1200 1612.0000 1.0000
30.1600 1642.0000 1.0000
30.2000 1616.0000 1.0000
30.2400 1656.0000 1.0000
30.2800 1610.0000 1.0000
30.3200 1563.0000 1.0000
30.3600 1668.0000 1.0000
30.4000 1551.0000 1.0000
30.4400 1589.0000 1.0000
30.4800 1646.0000 1.0000
30.5200 1631.0000 1.0000
30.5600 1612.0000 1.0000
30.6000 1638.0000 1.0000
30.6400 1567.0000 1.0000
30.6800 1650.0000 1.0000
30.7200 1631.0000 1.0000
30.7600 1622.0000 1.0000
30.8000 1507.0000 1.0000
30.8400 1568.0000 1.0000
30.8800 1559.0000 1.0000
30.9200 1568.0000 1.0000
30.9600 1564.0000 1.0000
31.0000 1549.0000 1.0000
31.0400 1581.0000 1.0000
31.0800 1538.0000 1.0000
31.1200 1633.0000 1.0000
31.1600 1581.0000 1.0000
31.2000 1560.0000 1.0000
31.2400 1587.0000 1.0000
31.2800 1554.0000 1.0000
31.3200 1571.0000 1.0000
31.3600 1614.0000 1.0000
31.4000 1506.0000 1.0000
31.4400 1524.0000 1.0000
31.4800 1571.0000 1.0000
31.5200 1495.0000 1.0000
31.5600 1582.0000 1.0000
31.6000 1569.0000 1.0000
31.6400 1575.0000 1.0000
31.6800 1578.0000 1.0000
31.7200 1526.0000 1.0000
31.7600 1586.0000 1.0000
31.8000 1542.0000 1.0000
31.8400 1583.0000 1.0000
31.8800 1542.0000 1.0000
31.9200 1603.0000 1.0000
31.9600 1594.0000 1.0000
32.0000 1531.0000 1.0000
32.0400 1523.0000 1.0000
32.0800 1515.0000 1.0000
32.1200 1487.0000 1.0000
32.1600 1468.0000 1.0000
32.2000 1528.0000 1.0000
32.2400 1540.0000 1.0000
32.2800 1531.0000 1.0000
32.3200 1460.0000 1.0000
32.3600 1574.0000 1.0000
32.4000 1557.0000 1.0000
32.4400 1523.0000 1.0000
32.4800 1523.0000 1.0000
32.5200 1496.0000 1.0000
32.5600 1466.0000 1.0000
32.6000 1477.0000 1.0000
32.6400 1503.0000 1.0000
32.6800 1522.0000 1.0000
32.7200 1502.0000 1.0000
32.7600 1497.0000 1.0000
32.8000 1484.0000 1.0000
32.8400 1507.0000 1.0000
32.8800 1396.0000 1.0000
32.9200 1459.0000 1.0000
32.9600 1444.0000 1.0000
33.0000 1503.0000 1.0000
33.0400 1457.0000 1.0000
33.0800 1471.0000 1.0000
33.1200 1470.0000 1.0000
33.1600 1453.0000 1.0000
33.2000 1492.0000 1.0000
33.2400 1468.0000 1.0000
33.2800 1404.0000 1.0000
33.3200 1427.0000 1.0000
33.3600 1475.0000 1.0000
33.4000 1474.0000 1.0000
33.4400 1520.0000 1.0000
33.4800 1422.0000 1.0000
33.5200 1452.0000 1.0000
33.5600 1497.0000 1.0000
33.6000 1421.0000 1.0000
33.6400 1494.0000 1.0000
33.6800 1545.0000 1.0000
33.7200 1498.0000 1.0000
33.7600 1510.0000 1.0000
33.8000 1496.0000 1.0000
33.8400 1587.0000 1.0000
33.8800 1570.0000 1.0000
33.9200 1614.0000 1.0000
33.9600 1653.0000 1.0000
34.0000 1600.0000 1.0000
34.0400 1677.0000 1.0000
34.0800 1692.0000 1.0000
34.1200 1596.0000 1.0000
34.1600 1688.0000 1.0000
34.2000 1748.0000 1.0000
34.2400 1767.0000 1.0000
34.2800 1877.0000 1.0000
34.3200 2088.0000 1.0000
34.3600 2417.0000 1.0000
34.4000 2774.0000 1.0000
34.4400 2962.0000 1.0000
34.4800 3039.0000 1.0000
34.5200 2971.0000 1.0000
34.5600 2662.0000 1.0000
34.6000 2429.0000 1.0000
34.6400 2108.0000 1.0000
34.6800 1948.0000 1.0000
34.7200 1815.0000 1.0000
34.7600 1739.0000 1.0000
34.8000 1626.0000 1.0000
34.8400 1595.0000 1.0000
34.8800 1469.0000 1.0000
34.9200 1457.0000 1.0000
34.9600 1457.0000 1.0000
35.0000 1451.0000 1.0000
35.0400 1370.0000 1.0000
35.0800 1387.0000 1.0000
35.1200 1458.0000 1.0000
35.1600 1357.0000 1.0000
35.2000 1329.0000 1.0000
35.2400 1278.0000 1.0000
35.2800 1323.0000 1.0000
35.3200 1360.0000 1.0000
35.3600 1338.0000 1.0000
35.4000 1253.0000 1.0000
35.4400 1282.0000 1.0000
35.4800 1310.0000 1.0000
35.5200 1337.0000 1.0000
35.5600 1248.0000 1.0000
35.6000 1326.0000 1.0000
35.6400 1293.0000 1.0000
35.6800 1305.0000 1.0000
35.7200 1289.0000 1.0000
35.7600 1277.0000 1.0000
35.8000 1358.0000 1.0000
35.8400 1261.0000 1.0000
35.8800 1336.0000 1.0000
35.9200 1319.0000 1.0000
35.9600 1326.0000 1.0000
36.0000 1321.0000 1.0000
36.0400 1331.0000 1.0000
36.0800 1383.0000 1.0000
36.1200 1482.0000 1.0000
36.1600 1492.0000 1.0000
36.2000 1600.0000 1.0000
36.2400 1814.0000 1.0000
36.2800 1887.0000 1.0000
36.3200 2060.0000 1.0000
36.3600 2069.0000 1.0000
36.4000 2126.0000 1.0000
36.4400 2126.0000 1.0000
36.4800 2002.0000 1.0000
36.5200 1807.0000 1.0000
36.5600 1575.0000 1.0000
36.6000 1555.0000 1.0000
36.6400 1533.0000 1.0000
36.6800 1373.0000 1.0000
36.7200 1297.0000 1.0000
36.7600 1298.0000 1.0000
36.8000 1285.0000 1.0000
36.8400 1255.0000 1.0000
36.8800 1232.0000 1.0000
36.9200 1199.0000 1.0000
36.9600 1137.0000 1.0000
37.0000 1167.0000 1.0000
37.0400 1161.0000 1.0000
37.0800 1209.0000 1.0000
37.1200 1169.0000 1.0000
37.1600 1252.0000 1.0000
37.2000 1193.0000 1.0000
37.2400 1209.0000 1.0000
37.2800 1162.0000 1.0000
37.3200 1149.0000 1.0000
37.3600 1188.0000 1.0000
37.4000 1188.0000 1.0000
37.4400 1122.0000 1.0000
37.4800 1190.0000 1.0000
37.5200 1180.0000 1.0000
37.5600 1120.0000 1.0000
37.6000 1231.0000 1.0000
37.6400 1160.0000 1.0000
37.6800 1199.0000 1.0000
37.7200 1174.0000 1.0000
37.7600 1221.0000 1.0000
37.8000 1169.0000 1.0000
37.8400 1205.0000 1.0000
37.8800 1175.0000 1.0000
37.9200 1253.0000 1.0000
37.9600 1324.0000 1.0000
38.0000 1338.0000 1.0000
38.0400 1357.0000 1.0000
38.0800 1415.0000 1.0000
38.1200 1446.0000 1.0000
38.1600 1623.0000 1.0000
38.2000 1789.0000 1.0000
38.2400 1951.0000 1.0000
38.2800 2343.0000 1.0000
38.3200 2854.0000 1.0000
38.3600 3640.0000 1.0000
38.4000 4876.0000 1.0000
38.4400 6297.0000 1.0000
38.4800 7612.0000 1.0000
38.5200 7796.0000 1.0000
38.5600 7332.0000 1.0000
38.6000 6361.0000 1.0000
38.6400 4947.0000 1.0000
38.6800 3946.0000 1.0000
38.7200 3031.0000 1.0000
38.7600 2413.0000 1.0000
38.8000 1975.0000 1.0000
38.8400 1704.0000 1.0000
38.8800 1510.0000 1.0000
38.9200 1397.0000 1.0000
38.9600 1303.0000 1.0000
39.0000 1294.0000 1.0000
39.0400 1206.0000 1.0000
39.0800 1202.0000 1.0000
39.1200 1115.0000 1.0000
39.1600 1111.0000 1.0000
39.2000 1124.0000 1.0000
39.2400 1144.0000 1.0000
39.2800 1085.0000 1.0000
39.3200 1071.0000 1.0000
39.3600 1057.0000 1.0000
39.4000 1083.0000 1.0000
39.4400 1107.0000 1.0000
39.4800 1102.0000 1.0000
39.5200 1142.0000 1.0000
39.5600 1063.0000 1.0000
39.6000 1074.0000 1.0000
39.6400 1101.0000 1.0000
39.6800 1095.0000 1.0000
39.7200 1108.0000 1.0000
39.7600 1066.0000 1.0000
39.8000 1056.0000 1.0000
39.8400 1032.0000 1.0000
39.8800 1033.0000 1.0000
39.9200 1104.0000 1.0000
39.9600 1045.0000 1.0000
40.0000 1080.0000 1.0000
40.0400 992.0000 1.0000
40.0800 1047.0000 1.0000
40.1200 949.0000 1.0000
40.1600 1013.0000 1.0000
40.2000 1022.0000 1.0000
40.2400 1021.0000 1.0000
40.2800 987.0000 1.0000
40.3200 1033.0000 1.0000
40.3600 939.0000 1.0000
40.4000 969.0000 1.0000
40.4400 1007.0000 1.0000
40.4800 979.0000 1.0000
40.5200 990.0000 1.0000
40.5600 1013.0000 1.0000
40.6000 974.0000 1.0000
40.6400 1019.0000 1.0000
40.6800 974.0000 1.0000
40.7200 975.0000 1.0000
40.7600 1021.0000 1.0000
40.8000 963.0000 1.0000
40.8400 980.0000 1.0000
40.8800 1024.0000 1.0000
40.9200 1001.0000 1.0000
40.9600 997.0000 1.0000
41.0000 971.0000 1.0000
41.0400 988.0000 1.0000
41.0800 984.0000 1.0000
41.1200 959.0000 1.0000
41.1600 971.0000 1.0000
41.2000 988.0000 1.0000
41.2400 1020.0000 1.0000
41.2800 933.0000 1.0000
41.3200 1000.0000 1.0000
41.3600 984.0000 1.0000
41.4000 952.0000 1.0000
41.4400 984.0000 1.0000
41.4800 956.0000 1.0000
41.5200 984.0000 1.0000
41.5600 988.0000 1.0000
41.6000 970.0000 1.0000
41.6400 1000.0000 1.0000
41.6800 959.0000 1.0000
41.7200 1011.0000 1.0000
41.7600 931.0000 1.0000
41.8000 984.0000 1.0000
41.8400 956.0000 1.0000
41.8800 947.0000 1.0000
41.9200 934.0000 1.0000
41.9600 973.0000 1.0000
42.0000 942.0000 1.0000
42.0400 915.0000 1.0000
42.0800 937.0000 1.0000
42.1200 999.0000 1.0000
42.1600 963.0000 1.0000
42.2000 987.0000 1.0000
42.2400 964.0000 1.0000
42.2800 991.0000 1.0000
42.3200 980.0000 1.0000
42.3600 982.0000 1.0000
42.4000 938.0000 1.0000
42.4400 880.0000 1.0000
42.4800 932.0000 1.0000
42.5200 975.0000 1.0000
42.5600 945.0000 1.0000
42.6000 963.0000 1.0000
42.6400 954.0000 1.0000
42.6800 898.0000 1.0000
42.7200 1012.0000 1.0000
42.7600 954.0000 1.0000
42.8000 969.0000 1.0000
42.8400 960.0000 1.0000
42.8800 974.0000 1.0000
42.9200 973.0000 1.0000
42.9600 983.0000 1.0000
43.0000 977.0000 1.0000
43.0400 984.0000 1.0000
43.0800 1037.0000 1.0000
43.1200 1020.0000 1.0000
43.1600 1044.0000 1.0000
43.2000 1009.0000 1.0000
43.2400 1060.0000 1.0000
43.2800 1063.0000 1.0000
43.3200 1017.0000 1.0000
43.3600 985.0000 1.0000
43.4000 1027.0000 1.0000
43.4400 959.0000 1.0000
43.4800 947.0000 1.0000
43.5200 972.0000 1.0000
43.5600 881.0000 1.0000
43.6000 919.0000 1.0000
43.6400 922.0000 1.0000
43.6800 909.0000 1.0000
43.7200 921.0000 1.0000
43.7600 930.0000 1.0000
43.8000 987.0000 1.0000
43.8400 892.0000 1.0000
43.8800 931.0000 1.0000
43.9200 940.0000 1.0000
43.9600 999.0000 1.0000
44.0000 923.0000 1.0000
44.0400 939.0000 1.0000
44.0800 959.0000 1.0000
44.1200 887.0000 1.0000
44.1600 950.0000 1.0000
44.2000 955.0000 1.0000
44.2400 941.0000 1.0000
44.2800 887.0000 1.0000
44.3200 935.0000 1.0000
44.3600 909.0000 1.0000
44.4000 898.0000 1.0000
44.4400 923.0000 1.0000
44.4800 925.0000 1.0000
44.5200 908.0000 1.0000
44.5600 924.0000 1.0000
44.6000 858.0000 1.0000
44.6400 929.0000 1.0000
44.6800 908.0000 1.0000
44.7200 926.0000 1.0000
44.7600 906.0000 1.0000
44.8000 936.0000 1.0000
44.8400 904.0000 1.0000
44.8800 890.0000 1.0000
44.9200 893.0000 1.0000
44.9600 909.0000 1.0000
45.0000 909.0000 1.0000
45.0400 916.0000 1.0000
45.0800 883.0000 1.0000
45.1200 915.0000 1.0000
45.1600 957.0000 1.0000
45.2000 850.0000 1.0000
45.2400 884.0000 1.0000
45.2800 895.0000 1.0000
45.3200 888.0000 1.0000
45.3600 871.0000 1.0000
45.4000 875.0000 1.0000
45.4400 910.0000 1.0000
45.4800 869.0000 1.0000
45.5200 885.0000 1.0000
45.5600 931.0000 1.0000
45.6000 825.0000 1.0000
45.6400 898.0000 1.0000
45.6800 862.0000 1.0000
45.7200 908.0000 1.0000
45.7600 903.0000 1.0000
45.8000 861.0000 1.0000
45.8400 849.0000 1.0000
45.8800 884.0000 1.0000
45.9200 848.0000 1.0000
45.9600 871.0000 1.0000
46.0000 881.0000 1.0000
46.0400 886.0000 1.0000
46.0800 880.0000 1.0000
46.1200 914.0000 1.0000
46.1600 865.0000 1.0000
46.2000 924.0000 1.0000
46.2400 878.0000 1.0000
46.2800 848.0000 1.0000
46.3200 905.0000 1.0000
46.3600 878.0000 1.0000
46.4000 922.0000 1.0000
46.4400 876.0000 1.0000
46.4800 872.0000 1.0000
46.5200 890.0000 1.0000
46.5600 882.0000 1.0000
46.6000 859.0000 1.0000
46.6400 878.0000 1.0000
46.6800 891.0000 1.0000
46.7200 816.0000 1.0000
46.7600 892.0000 1.0000
46.8000 843.0000 1.0000
46.8400 902.0000 1.0000
46.8800 839.0000 1.0000
46.9200 864.0000 1.0000
46.9600 903.0000 1.0000
47.0000 936.0000 1.0000
47.0400 860.0000 1.0000
47.0800 842.0000 1.0000
47.1200 885.0000 1.0000
47.1600 847.0000 1.0000
47.2000 860.0000 1.0000
47.2400 817.0000 1.0000
47.2800 853.0000 1.0000
47.3200 855.0000 1.0000
47.3600 859.0000 1.0000
47.4000 842.0000 1.0000
47.4400 848.0000 1.0000
47.4800 846.0000 1.0000
47.5200 864.0000 1.0000
47.5600 824.0000 1.0000
47.6000 818.0000 1.0000
47.6400 806.0000 1.0000
47.6800 865.0000 1.0000
47.7200 845.0000 1.0000
47.7600 836.0000 1.0000
47.8000 827.0000 1.0000
47.8400 842.0000 1.0000
47.8800 852.0000 1.0000
47.9200 842.0000 1.0000
47.9600 869.0000 1.0000
48.0000 810.0000 1.0000
48.0400 875.0000 1.0000
48.0800 866.0000 1.0000
48.1200 850.0000 1.0000
48.1600 841.0000 1.0000
48.2000 823.0000 1.0000
48.2400 844.0000 1.0000
48.2800 857.0000 1.0000
48.3200 828.0000 1.0000
48.3600 825.0000 1.0000
48.4000 831.0000 1.0000
48.4400 827.0000 1.0000
48.4800 819.0000 1.0000
48.5200 846.0000 1.0000
48.5600 812.0000 1.0000
48.6000 844.0000 1.0000
48.6400 832.0000 1.0000
48.6800 857.0000 1.0000
48.7200 809.0000 1.0000
48.7600 831.0000 1.0000
48.8000 836.0000 1.0000
48.8400 809.0000 1.0000
48.8800 826.0000 1.0000
48.9200 831.0000 1.0000
48.9600 826.0000 1.0000
49.0000 797.0000 1.0000
49.0400 765.0000 1.0000
49.0800 860.0000 1.0000
49.1200 843.0000 1.0000
49.1600 838.0000 1.0000
49.2000 823.0000 1.0000
49.2400 830.0000 1.0000
49.2800 809.0000 1.0000
49.3200 802.0000 1.0000
49.3600 834.0000 1.0000
49.4000 751.0000 1.0000
49.4400 856.0000 1.0000
49.4800 816.0000 1.0000
49.5200 827.0000 1.0000
49.5600 861.0000 1.0000
49.6000 804.0000 1.0000
49.6400 816.0000 1.0000
49.6800 815.0000 1.0000
49.7200 819.0000 1.0000
49.7600 799.0000 1.0000
49.8000 808.0000 1.0000
49.8400 822.0000 1.0000
49.8800 847.0000 1.0000
49.9200 831.0000 1.0000
49.9600 824.0000 1.0000
50.0000 824.0000 1.0000
50.0400 803.0000 1.0000
50.0800 822.0000 1.0000
50.1200 863.0000 1.0000
50.1600 858.0000 1.0000
50.2000 844.0000 1.0000
50.2400 809.0000 1.0000
50.2800 843.0000 1.0000
50.3200 840.0000 1.0000
50.3600 850.0000 1.0000
50.4000 858.0000 1.0000
50.4400 848.0000 1.0000
50.4800 817.0000 1.0000
50.5200 851.0000 1.0000
50.5600 824.0000 1.0000
50.6000 832.0000 1.0000
50.6400 824.0000 1.0000
50.6800 820.0000 1.0000
50.7200 822.0000 1.0000
50.7600 849.0000 1.0000
50.8000 846.0000 1.0000
50.8400 788.0000 1.0000
50.8800 805.0000 1.0000
50.9200 804.0000 1.0000
50.9600 818.0000 1.0000
51.0000 823.0000 1.0000
51.0400 883.0000 1.0000
51.0800 832.0000 1.0000
51.1200 787.0000 1.0000
51.1600 835.0000 1.0000
51.2000 817.0000 1.0000
51.2400 845.0000 1.0000
51.2800 880.0000 1.0000
51.3200 846.0000 1.0000
51.3600 835.0000 1.0000
51.4000 850.0000 1.0000
51.4400 827.0000 1.0000
51.4800 853.0000 1.0000
51.5200 854.0000 1.0000
51.5600 830.0000 1.0000
51.6000 847.0000 1.0000
51.6400 875.0000 1.0000
51.6800 876.0000 1.0000
51.7200 874.0000 1.0000
51.7600 912.0000 1.0000
51.8000 979.0000 1.0000
51.8400 977.0000 1.0000
51.8800 1054.0000 1.0000
51.9200 1106.0000 1.0000
51.9600 1250.0000 1.0000
52.0000 1408.0000 1.0000
52.0400 1591.0000 1.0000
52.0800 1945.0000 1.0000
52.1200 2732.0000 1.0000
52.1600 3619.0000 1.0000
52.2000 4682.0000 1.0000
52.2400 5218.0000 1.0000
52.2800 4731.0000 1.0000
52.3200 4117.0000 1.0000
52.3600 3921.0000 1.0000
52.4000 3200.0000 1.0000
52.4400 2558.0000 1.0000
52.4800 2014.0000 1.0000
52.5200 1630.0000 1.0000
52.5600 1326.0000 1.0000
52.6000 1207.0000 1.0000
52.6400 1078.0000 1.0000
52.6800 1076.0000 1.0000
52.7200 1020.0000 1.0000
52.7600 939.0000 1.0000
52.8000 925.0000 1.0000
52.8400 930.0000 1.0000
52.8800 865.0000 1.0000
52.9200 918.0000 1.0000
52.9600 817.0000 1.0000
53.0000 837.0000 1.0000
53.0400 856.0000 1.0000
53.0800 794.0000 1.0000
53.1200 872.0000 1.0000
53.1600 857.0000 1.0000
53.2000 789.0000 1.0000
53.2400 815.0000 1.0000
53.2800 833.0000 1.0000
53.3200 805.0000 1.0000
53.3600 814.0000 1.0000
53.4000 852.0000 1.0000
53.4400 842.0000 1.0000
53.4800 860.0000 1.0000
53.5200 839.0000 1.0000
53.5600 815.0000 1.0000
53.6000 823.0000 1.0000
53.6400 840.0000 1.0000
53.6800 786.0000 1.0000
53.7200 819.0000 1.0000
53.7600 768.0000 1.0000
53.8000 786.0000 1.0000
53.8400 777.0000 1.0000
53.8800 814.0000 1.0000
53.9200 831.0000 1.0000
53.9600 781.0000 1.0000
54.0000 833.0000 1.0000
54.0400 731.0000 1.0000
54.0800 790.0000 1.0000
54.1200 835.0000 1.0000
54.1600 776.0000 1.0000
54.2000 775.0000 1.0000
54.2400 800.0000 1.0000
54.2800 801.0000 1.0000
54.3200 828.0000 1.0000
54.3600 779.0000 1.0000
54.4000 787.0000 1.0000
54.4400 837.0000 1.0000
54.4800 839.0000 1.0000
54.5200 849.0000 1.0000
54.5600 832.0000 1.0000
54.6000 811.0000 1.0000
54.6400 826.0000 1.0000
54.6800 859.0000 1.0000
54.7200 831.0000 1.0000
54.7600 828.0000 1.0000
54.8000 855.0000 1.0000
54.8400 852.0000 1.0000
54.8800 841.0000 1.0000
54.9200 825.0000 1.0000
54.9600 861.0000 1.0000
55.0000 887.0000 1.0000
55.0400 922.0000 1.0000
55.0800 1002.0000 1.0000
55.1200 989.0000 1.0000
55.1600 1152.0000 1.0000
55.2000 1138.0000 1.0000
55.2400 1157.0000 1.0000
55.2800 1188.0000 1.0000
55.3200 1213.0000 1.0000
55.3600 1114.0000 1.0000
55.4000 1145.0000 1.0000
55.4400 982.0000 1.0000
55.4800 981.0000 1.0000
55.5200 944.0000 1.0000
55.5600 905.0000 1.0000
55.6000 868.0000 1.0000
55.6400 867.0000 1.0000
55.6800 810.0000 1.0000
55.7200 810.0000 1.0000
55.7600 820.0000 1.0000
55.8000 826.0000 1.0000
55.8400 780.0000 1.0000
55.8800 800.0000 1.0000
55.9200 789.0000 1.0000
55.9600 781.0000 1.0000
56.0000 807.0000 1.0000
56.0400 801.0000 1.0000
56.0800 833.0000 1.0000
56.1200 787.0000 1.0000
56.1600 823.0000 1.0000
56.2000 779.0000 1.0000
56.2400 773.0000 1.0000
56.2800 780.0000 1.0000
56.3200 783.0000 1.0000
56.3600 762.0000 1.0000
56.4000 753.0000 1.0000
56.4400 790.0000 1.0000
56.4800 746.0000 1.0000
56.5200 783.0000 1.0000
56.5600 727.0000 1.0000
56.6000 778.0000 1.0000
56.6400 800.0000 1.0000
56.6800 772.0000 1.0000
56.7200 735.0000 1.0000
56.7600 791.0000 1.0000
56.8000 728.0000 1.0000
56.8400 796.0000 1.0000
56.8800 769.0000 1.0000
56.9200 762.0000 1.0000
56.9600 768.0000 1.0000
57.0000 816.0000 1.0000
57.0400 762.0000 1.0000
57.0800 772.0000 1.0000
57.1200 810.0000 1.0000
57.1600 732.0000 1.0000
57.2000 818.0000 1.0000
57.2400 758.0000 1.0000
57.2800 791.0000 1.0000
57.3200 790.0000 1.0000
57.3600 766.0000 1.0000
57.4000 761.0000 1.0000
57.4400 754.0000 1.0000
57.4800 774.0000 1.0000
57.5200 760.0000 1.0000
57.5600 745.0000 1.0000
57.6000 802.0000 1.0000
57.6400 739.0000 1.0000
57.6800 768.0000 1.0000
57.7200 796.0000 1.0000
57.7600 768.0000 1.0000
57.8000 823.0000 1.0000
57.8400 750.0000 1.0000
57.8800 770.0000 1.0000
57.9200 787.0000 1.0000
57.9600 748.0000 1.0000
58.0000 805.0000 1.0000
58.0400 788.0000 1.0000
58.0800 770.0000 1.0000
58.1200 762.0000 1.0000
58.1600 773.0000 1.0000
58.2000 750.0000 1.0000
58.2400 805.0000 1.0000
58.2800 746.0000 1.0000
58.3200 773.0000 1.0000
58.3600 848.0000 1.0000
58.4000 837.0000 1.0000
58.4400 781.0000 1.0000
58.4800 760.0000 1.0000
58.5200 746.0000 1.0000
58.5600 754.0000 1.0000
58.6000 738.0000 1.0000
58.6400 794.0000 1.0000
58.6800 753.0000 1.0000
58.7200 760.0000 1.0000
58.7600 800.0000 1.0000
58.8000 737.0000 1.0000
58.8400 810.0000 1.0000
58.8800 773.0000 1.0000
58.9200 760.0000 1.0000
58.9600 801.0000 1.0000
59.0000 753.0000 1.0000
59.0400 795.0000 1.0000
59.0800 781.0000 1.0000
59.1200 750.0000 1.0000
59.1600 749.0000 1.0000
59.2000 774.0000 1.0000
59.2400 776.0000 1.0000
59.2800 749.0000 1.0000
59.3200 791.0000 1.0000
59.3600 738.0000 1.0000
59.4000 714.0000 1.0000
59.4400 773.0000 1.0000
59.4800 766.0000 1.0000
59.5200 809.0000 1.0000
59.5600 754.0000 1.0000
59.6000 776.0000 1.0000
59.6400 763.0000 1.0000
59.6800 762.0000 1.0000
59.7200 802.0000 1.0000
59.7600 746.0000 1.0000
59.8000 794.0000 1.0000
59.8400 755.0000 1.0000
59.8800 776.0000 1.0000
59.9200 792.0000 1.0000
59.9600 778.0000 1.0000
60.0000 732.0000 1.0000
60.0400 773.0000 1.0000
60.0800 762.0000 1.0000
60.1200 742.0000 1.0000
60.1600 825.0000 1.0000
60.2000 735.0000 1.0000
60.2400 753.0000 1.0000
60.2800 800.0000 1.0000
60.3200 756.0000 1.0000
60.3600 763.0000 1.0000
60.4000 799.0000 1.0000
60.4400 772.0000 1.0000
60.4800 788.0000 1.0000
60.5200 779.0000 1.0000
60.5600 755.0000 1.0000
60.6000 757.0000 1.0000
60.6400 764.0000 1.0000
60.6800 739.0000 1.0000
60.7200 768.0000 1.0000
60.7600 794.0000 1.0000
60.8000 781.0000 1.0000
60.8400 759.0000 1.0000
60.8800 805.0000 1.0000
60.9200 761.0000 1.0000
60.9600 770.0000 1.0000
61.0000 782.0000 1.0000
61.0400 729.0000 1.0000
61.0800 741.0000 1.0000
61.1200 759.0000 1.0000
61.1600 763.0000 1.0000
61.2000 794.0000 1.0000
61.2400 749.0000 1.0000
61.2800 744.0000 1.0000
61.3200 763.0000 1.0000
61.3600 783.0000 1.0000
61.4000 748.0000 1.0000
61.4400 759.0000 1.0000
61.4800 792.0000 1.0000
61.5200 774.0000 1.0000
61.5600 765.0000 1.0000
61.6000 767.0000 1.0000
61.6400 838.0000 1.0000
61.6800 789.0000 1.0000
61.7200 797.0000 1.0000
61.7600 841.0000 1.0000
61.8000 846.0000 1.0000
61.8400 881.0000 1.0000
61.8800 923.0000 1.0000
61.9200 967.0000 1.0000
61.9600 967.0000 1.0000
62.0000 1000.0000 1.0000
62.0400 1141.0000 1.0000
62.0800 1220.0000 1.0000
62.1200 1423.0000 1.0000
62.1600 1523.0000 1.0000
62.2000 1690.0000 1.0000
62.2400 1796.0000 1.0000
62.2800 1838.0000 1.0000
62.3200 1755.0000 1.0000
62.3600 1725.0000 1.0000
62.4000 1663.0000 1.0000
62.4400 1507.0000 1.0000
62.4800 1395.0000 1.0000
62.5200 1302.0000 1.0000
62.5600 1134.0000 1.0000
62.6000 1120.0000 1.0000
62.6400 1040.0000 1.0000
62.6800 971.0000 1.0000
62.7200 960.0000 1.0000
62.7600 914.0000 1.0000
62.8000 849.0000 1.0000
62.8400 863.0000 1.0000
62.8800 815.0000 1.0000
62.9200 915.0000 1.0000
62.9600 797.0000 1.0000
63.0000 802.0000 1.0000
63.0400 857.0000 1.0000
63.0800 877.0000 1.0000
63.1200 798.0000 1.0000
63.1600 823.0000 1.0000
63.2000 814.0000 1.0000
63.2400 781.0000 1.0000
63.2800 759.0000 1.0000
63.3200 766.0000 1.0000
63.3600 764.0000 1.0000
63.4000 758.0000 1.0000
63.4400 820.0000 1.0000
63.4800 753.0000 1.0000
63.5200 766.0000 1.0000
63.5600 732.0000 1.0000
63.6000 790.0000 1.0000
63.6400 802.0000 1.0000
63.6800 824.0000 1.0000
63.7200 758.0000 1.0000
63.7600 820.0000 1.0000
63.8000 766.0000 1.0000
63.8400 807.0000 1.0000
63.8800 785.0000 1.0000
63.9200 780.0000 1.0000
63.9600 772.0000 1.0000
64.0000 777.0000 1.0000
64.0400 757.0000 1.0000
64.0800 767.0000 1.0000
64.1200 775.0000 1.0000
64.1600 788.0000 1.0000
64.2000 802.0000 1.0000
64.2400 787.0000 1.0000
64.2800 785.0000 1.0000
64.3200 808.0000 1.0000
64.3600 841.0000 1.0000
64.4000 895.0000 1.0000
64.4400 848.0000 1.0000
64.4800 899.0000 1.0000
64.5200 947.0000 1.0000
64.5600 941.0000 1.0000
64.6000 1000.0000 1.0000
64.6400 1042.0000 1.0000
64.6800 1050.0000 1.0000
64.7200 987.0000 1.0000
64.7600 973.0000 1.0000
64.8000 1043.0000 1.0000
64.8400 1028.0000 1.0000
64.8800 931.0000 1.0000
64.9200 922.0000 1.0000
64.9600 936.0000 1.0000
65.0000 884.0000 1.0000
65.0400 854.0000 1.0000
65.0800 885.0000 1.0000
65.1200 819.0000 1.0000
65.1600 814.0000 1.0000
65.2000 774.0000 1.0000
65.2400 809.0000 1.0000
65.2800 829.0000 1.0000
65.3200 810.0000 1.0000
65.3600 818.0000 1.0000
65.4000 828.0000 1.0000
65.4400 773.0000 1.0000
65.4800 803.0000 1.0000
65.5200 803.0000 1.0000
65.5600 808.0000 1.0000
65.6000 830.0000 1.0000
65.6400 835.0000 1.0000
65.6800 816.0000 1.0000
65.7200 886.0000 1.0000
65.7600 867.0000 1.0000
65.8000 872.0000 1.0000
65.8400 920.0000 1.0000
65.8800 1027.0000 1.0000
65.9200 1050.0000 1.0000
65.9600 1137.0000 1.0000
66.0000 1299.0000 1.0000
66.0400 1444.0000 1.0000
66.0800 1721.0000 1.0000
66.1200 2159.0000 1.0000
66.1600 2563.0000 1.0000
66.2000 2846.0000 1.0000
66.2400 2831.0000 1.0000
66.2800 2586.0000 1.0000
66.3200 2457.0000 1.0000
66.3600 2435.0000 1.0000
66.4000 2205.0000 1.0000
66.4400 1886.0000 1.0000
66.4800 1663.0000 1.0000
66.5200 1473.0000 1.0000
66.5600 1253.0000 1.0000
66.6000 1159.0000 1.0000
66.6400 1013.0000 1.0000
66.6800 1001.0000 1.0000
66.7200 953.0000 1.0000
66.7600 919.0000 1.0000
66.8000 832.0000 1.0000
66.8400 824.0000 1.0000
66.8800 800.0000 1.0000
66.9200 773.0000 1.0000
66.9600 809.0000 1.0000
67.0000 734.0000 1.0000
67.0400 796.0000 1.0000
67.0800 756.0000 1.0000
67.1200 742.0000 1.0000
67.1600 726.0000 1.0000
67.2000 732.0000 1.0000
67.2400 697.0000 1.0000
67.2800 709.0000 1.0000
67.3200 732.0000 1.0000
67.3600 741.0000 1.0000
67.4000 714.0000 1.0000
67.4400 704.0000 1.0000
67.4800 737.0000 1.0000
67.5200 669.0000 1.0000
67.5600 733.0000 1.0000
67.6000 693.0000 1.0000
67.6400 738.0000 1.0000
67.6800 726.0000 1.0000
67.7200 714.0000 1.0000
67.7600 725.0000 1.0000
67.8000 717.0000 1.0000
67.8400 666.0000 1.0000
67.8800 704.0000 1.0000
67.9200 725.0000 1.0000
67.9600 713.0000 1.0000
68.0000 750.0000 1.0000
68.0400 694.0000 1.0000
68.0800 706.0000 1.0000
68.1200 697.0000 1.0000
68.1600 707.0000 1.0000
68.2000 695.0000 1.0000
68.2400 722.0000 1.0000
68.2800 718.0000 1.0000
68.3200 711.0000 1.0000
68.3600 694.0000 1.0000
68.4000 723.0000 1.0000
68.4400 693.0000 1.0000
68.4800 668.0000 1.0000
68.5200 664.0000 1.0000
68.5600 654.0000 1.0000
68.6000 695.0000 1.0000
68.6400 693.0000 1.0000
68.6800 698.0000 1.0000
68.7200 677.0000 1.0000
68.7600 673.0000 1.0000
68.8000 705.0000 1.0000
68.8400 671.0000 1.0000
68.8800 688.0000 1.0000
68.9200 703.0000 1.0000
68.9600 669.0000 1.0000
69.0000 685.0000 1.0000
69.0400 680.0000 1.0000
69.0800 672.0000 1.0000
69.1200 700.0000 1.0000
69.1600 710.0000 1.0000
69.2000 702.0000 1.0000
69.2400 688.0000 1.0000
69.2800 701.0000 1.0000
69.3200 734.0000 1.0000
69.3600 682.0000 1.0000
69.4000 659.0000 1.0000
69.4400 688.0000 1.0000
69.4800 670.0000 1.0000
69.5200 634.0000 1.0000
69.5600 647.0000 1.0000
69.6000 662.0000 1.0000
69.6400 665.0000 1.0000
69.6800 715.0000 1.0000
69.7200 681.0000 1.0000
69.7600 680.0000 1.0000
69.8000 641.0000 1.0000
69.8400 626.0000 1.0000
69.8800 668.0000 1.0000
69.9200 651.0000 1.0000
69.9600 694.0000 1.0000
70.0000 640.0000 1.0000
*RAS_INT_END
*RAS_TEMPERATURE_START
*RAS_TEMPERATURE_END
*RAS_DATA_END