File: Section2_75_samples/XRD/No_062_HS1_2.ras
*RAS_DATA_START
*RAS_HEADER_START
*DISP_FMT_X "%.2f"
*DISP_FMT_Y "%.0f"
*DISP_FULLSCALE "13960.0000000000"
*DISP_LINE_COLOR "255.0000000000"
*DISP_LINE_STYLE "0.0000000000"
*DISP_LINE_WIDTH "0.2500000000"
*DISP_NOTE "測定データ-5"
*DISP_OFFSET_Y "0.0000000000"
*DISP_PEAKSEARCH_UNIT_Y "cps"
*DISP_RANGE_BOTTOM "0.0000000000"
*DISP_RANGE_LEFT "20.0000000000"
*DISP_RANGE_LOGCUTOFF "0.0100000000"
*DISP_RANGE_RIGHT "70.0000000000"
*DISP_RANGE_TOP "13960.0000000000"
*DISP_SCALE_MODE_Y "0.0000000000"
*DISP_TAB_NAME "2θ/θ"
*DISP_TITLE_Y "強度"
*DISP_UNIT_Y "cps"
*DISP_WINDOW_NAME "MSG_MACROENGINE"
*FILE_COMMENT " "
*FILE_MD5 ""
*FILE_MEMO " "
*FILE_OPERATOR "Administrator"
*FILE_SAMPLE " "
*FILE_TYPE "RAS_RAW"
*FILE_USERGROUP "システムマネージャ"
*FILE_VERSION "1.0000000000"
*HW_ATTACHMENT_ID "ATT0025"
*HW_ATTACHMENT_NAME "標準|Standard"
*HW_COUNTER_ID-0 "CUT0025"
*HW_COUNTER_ID-1 "CUT0020"
*HW_COUNTER_ID-2 "CUT0020"
*HW_COUNTER_ID-3 "CSL0021"
*HW_COUNTER_ID-4 "CMC0021"
*HW_COUNTER_NAME-0 "D/teX Ultra|D/teX Ultra"
*HW_COUNTER_NAME-1 "None|None"
*HW_COUNTER_NAME-2 "None|None"
*HW_COUNTER_NAME-3 "BBM|BBM"
*HW_COUNTER_NAME-4 "検出器モノクロメータ|Detector monochromator"
*HW_COUNTER_SELECT_NAME "D/teX Ultra|D/teX Ultra"
*HW_GONIOMETER_ID "GON0023"
*HW_GONIOMETER_NAME "SmartLab|SmartLab"
*HW_GONIOMETER_RADIUS-0 "90.0"
*HW_GONIOMETER_RADIUS-1 "114.0"
*HW_GONIOMETER_RADIUS-2 "190.0"
*HW_GONIOMETER_RADIUS-3 "300.0"
*HW_GONIOMETER_RADIUS-4 "187.0"
*HW_GONIOMETER_RADIUS-5 "300.0"
*HW_GONIOMETER_RADIUS-6 "113.0"
*HW_GONIOMETER_RADIUS-7 "331.0"
*HW_I_OPT_ID-0 "CBO0021"
*HW_I_OPT_ID-1 "ICR0023"
*HW_I_OPT_ID-2 "ISL0021"
*HW_I_OPT_ID-3 "ISO0021"
*HW_I_OPT_ID-4 "IAD0021"
*HW_I_OPT_ID-5 "IPR0001"
*HW_I_OPT_NAME-0 "CBOユニット|CBO unit"
*HW_I_OPT_NAME-1 "標準入射光学ユニット|Standard incident optical unit"
*HW_I_OPT_NAME-2 "標準入射スリットボックス|Standard incident slit box"
*HW_I_OPT_NAME-3 "入射平行スリット|Incident parallel slit"
*HW_I_OPT_NAME-4 "長手制限スリット|Length limiting slit"
*HW_I_OPT_NAME-5 "None|None"
*HW_R_ATTENUATER_AUTOMODE "0"
*HW_R_OPT_ID-0 "RSS0021"
*HW_R_OPT_ID-1 "RCR0023"
*HW_R_OPT_ID-2 "RSO0021"
*HW_R_OPT_ID-3 "RRS0021"
*HW_R_OPT_ID-4 "ATN0021"
*HW_R_OPT_ID-5 "RFL0021"
*HW_R_OPT_ID-6 "RAD0021"
*HW_R_OPT_NAME-0 "標準受光スリットボックス1|Standard receiving slit box # 1"
*HW_R_OPT_NAME-1 "標準受光光学ユニット1|Standard receiving unit # 1"
*HW_R_OPT_NAME-2 "標準受光光学ユニット2|Standard receiving optical unit # 2"
*HW_R_OPT_NAME-3 "標準受光スリットボックス2|Standard receiving slit box # 2"
*HW_R_OPT_NAME-4 "標準アッテネータ|Standard Attenuator"
*HW_R_OPT_NAME-5 "Cu Kβ|Cu K-beta"
*HW_R_OPT_NAME-6 "調整用受光スリット|Alignment receiving slit"
*HW_SAMPLE_HOLDER_ID "SMP0023"
*HW_SAMPLE_HOLDER_NAME "標準Zステージ|Standard Z stage"
*HW_XG_CURRENT_MAX "50"
*HW_XG_CURRENT_MIN "2"
*HW_XG_CURRENT_RESOLUTION "1"
*HW_XG_CURRENT_UNIT "mA"
*HW_XG_FOCUS "1mm x 10mm"
*HW_XG_FOCUS_TYPE "Normal"
*HW_XG_ID ""
*HW_XG_NAME "3kW 封入管(ID:1200)|3kW Sealed tube(ID:1200)"
*HW_XG_TARGET_ATOMIC_NUMBER "29.0000000000"
*HW_XG_TARGET_NAME "Cu"
*HW_XG_TYPE "Hermetic"
*HW_XG_VOLTAGE_MAX "60"
*HW_XG_VOLTAGE_MIN "20"
*HW_XG_VOLTAGE_RESOLUTION "1"
*HW_XG_VOLTAGE_UNIT "kV"
*HW_XG_WATT_MAX "1.500"
*HW_XG_WATT_UNIT "kW"
*HW_XG_WAVE_LENGTH_ALPHA1 "1.540593"
*HW_XG_WAVE_LENGTH_ALPHA2 "1.544414"
*HW_XG_WAVE_LENGTH_BETA "1.392250"
*MEAS_COND_AXIS_NAME-0 "2θ/θ"
*MEAS_COND_AXIS_NAME-1 "2θ"
*MEAS_COND_AXIS_NAME-2 "ω"
*MEAS_COND_AXIS_NAME-3 "Z"
*MEAS_COND_AXIS_NAME-4 "2θ/ω"
*MEAS_COND_AXIS_NAME-5 "θs"
*MEAS_COND_AXIS_NAME-6 "θd"
*MEAS_COND_AXIS_NAME-7 "Ts"
*MEAS_COND_AXIS_NAME-8 "CBO選択スリット"
*MEAS_COND_AXIS_NAME-9 "M"
*MEAS_COND_AXIS_NAME-10 "入射平行スリット"
*MEAS_COND_AXIS_NAME-11 "入射スリット"
*MEAS_COND_AXIS_NAME-12 ""
*MEAS_COND_AXIS_NAME-13 "Zs"
*MEAS_COND_AXIS_NAME-14 "入射光学素子"
*MEAS_COND_AXIS_NAME-15 "長手制限スリット"
*MEAS_COND_AXIS_NAME-16 "センタースリット"
*MEAS_COND_AXIS_NAME-17 "フィルター"
*MEAS_COND_AXIS_NAME-18 "受光スリット1"
*MEAS_COND_AXIS_NAME-19 "受光スリット2"
*MEAS_COND_AXIS_NAME-20 "受光光学素子"
*MEAS_COND_AXIS_NAME-21 "受光平行スリット"
*MEAS_COND_AXIS_NAME-22 "調整用受光スリット"
*MEAS_COND_AXIS_NAME-23 ""
*MEAS_COND_AXIS_NAME-24 ""
*MEAS_COND_AXIS_NAME-25 "Zd"
*MEAS_COND_AXIS_NAME-26 "アッテネータ"
*MEAS_COND_AXIS_NAME-27 "検出器モノクロメータ"
*MEAS_COND_AXIS_NAME-28 "モノクロメータスリット"
*MEAS_COND_AXIS_NAME-29 "プライマリビーム"
*MEAS_COND_AXIS_NAME-30 "PHA"
*MEAS_COND_AXIS_NAME_INTERNAL-0 "TwoThetaTheta"
*MEAS_COND_AXIS_NAME_INTERNAL-1 "TwoTheta"
*MEAS_COND_AXIS_NAME_INTERNAL-2 "Omega"
*MEAS_COND_AXIS_NAME_INTERNAL-3 "Z"
*MEAS_COND_AXIS_NAME_INTERNAL-4 "TwoThetaOmega"
*MEAS_COND_AXIS_NAME_INTERNAL-5 "ThetaS"
*MEAS_COND_AXIS_NAME_INTERNAL-6 "ThetaD"
*MEAS_COND_AXIS_NAME_INTERNAL-7 "Ts"
*MEAS_COND_AXIS_NAME_INTERNAL-8 "CBO"
*MEAS_COND_AXIS_NAME_INTERNAL-9 "CBO-M"
*MEAS_COND_AXIS_NAME_INTERNAL-10 "IncidentSollerSlit"
*MEAS_COND_AXIS_NAME_INTERNAL-11 "IncidentSlitBox"
*MEAS_COND_AXIS_NAME_INTERNAL-12 "IncidentSlitBox-_Axis"
*MEAS_COND_AXIS_NAME_INTERNAL-13 "Zs"
*MEAS_COND_AXIS_NAME_INTERNAL-14 "IncidentMonochromator"
*MEAS_COND_AXIS_NAME_INTERNAL-15 "IncidentAxdSlit"
*MEAS_COND_AXIS_NAME_INTERNAL-16 "CenterSlit"
*MEAS_COND_AXIS_NAME_INTERNAL-17 "Filter"
*MEAS_COND_AXIS_NAME_INTERNAL-18 "ReceivingSlitBox1"
*MEAS_COND_AXIS_NAME_INTERNAL-19 "ReceivingSlitBox2"
*MEAS_COND_AXIS_NAME_INTERNAL-20 "ReceivingOptics"
*MEAS_COND_AXIS_NAME_INTERNAL-21 "ReceivingSollerSlit"
*MEAS_COND_AXIS_NAME_INTERNAL-22 "ReceivingAxdSlit"
*MEAS_COND_AXIS_NAME_INTERNAL-23 "ReceivingSlitBox1-_Axis"
*MEAS_COND_AXIS_NAME_INTERNAL-24 "ReceivingSlitBox2-_Axis"
*MEAS_COND_AXIS_NAME_INTERNAL-25 "ReceivingSlitBox2-Zd"
*MEAS_COND_AXIS_NAME_INTERNAL-26 "Attenuator"
*MEAS_COND_AXIS_NAME_INTERNAL-27 "CounterMonochromator"
*MEAS_COND_AXIS_NAME_INTERNAL-28 "CounterSlit"
*MEAS_COND_AXIS_NAME_INTERNAL-29 "IncidentPrimary"
*MEAS_COND_AXIS_NAME_INTERNAL-30 "PHA"
*MEAS_COND_AXIS_NAME_MAGICNO-0 "83951616.0000000000"
*MEAS_COND_AXIS_NAME_MAGICNO-1 "268632064.0000000000"
*MEAS_COND_AXIS_NAME_MAGICNO-2 "268500992.0000000000"
*MEAS_COND_AXIS_NAME_MAGICNO-3 "285278208.0000000000"
*MEAS_COND_AXIS_NAME_MAGICNO-4 "83951616.0000000000"
*MEAS_COND_AXIS_NAME_MAGICNO-5 "131072.0000000000"
*MEAS_COND_AXIS_NAME_MAGICNO-6 "131072.0000000000"
*MEAS_COND_AXIS_NAME_MAGICNO-7 "318898176.0000000000"
*MEAS_COND_AXIS_NAME_MAGICNO-8 "20971521.0000000000"
*MEAS_COND_AXIS_NAME_MAGICNO-9 "285343744.0000000000"
*MEAS_COND_AXIS_NAME_MAGICNO-10 "20971521.0000000000"
*MEAS_COND_AXIS_NAME_MAGICNO-11 "22020097.0000000000"
*MEAS_COND_AXIS_NAME_MAGICNO-12 "25165824.0000000000"
*MEAS_COND_AXIS_NAME_MAGICNO-13 "318898176.0000000000"
*MEAS_COND_AXIS_NAME_MAGICNO-14 "1.0000000000"
*MEAS_COND_AXIS_NAME_MAGICNO-15 "20971521.0000000000"
*MEAS_COND_AXIS_NAME_MAGICNO-16 "20971521.0000000000"
*MEAS_COND_AXIS_NAME_MAGICNO-17 "20971521.0000000000"
*MEAS_COND_AXIS_NAME_MAGICNO-18 "23068673.0000000000"
*MEAS_COND_AXIS_NAME_MAGICNO-19 "23068673.0000000000"
*MEAS_COND_AXIS_NAME_MAGICNO-20 "20971521.0000000000"
*MEAS_COND_AXIS_NAME_MAGICNO-21 "20971521.0000000000"
*MEAS_COND_AXIS_NAME_MAGICNO-22 "20971521.0000000000"
*MEAS_COND_AXIS_NAME_MAGICNO-23 "25165824.0000000000"
*MEAS_COND_AXIS_NAME_MAGICNO-24 "25165824.0000000000"
*MEAS_COND_AXIS_NAME_MAGICNO-25 "285343744.0000000000"
*MEAS_COND_AXIS_NAME_MAGICNO-26 "17301505.0000000000"
*MEAS_COND_AXIS_NAME_MAGICNO-27 "20971521.0000000000"
*MEAS_COND_AXIS_NAME_MAGICNO-28 "20971521.0000000000"
*MEAS_COND_AXIS_NAME_MAGICNO-29 "20971521.0000000000"
*MEAS_COND_AXIS_NAME_MAGICNO-30 "0.0000000000"
*MEAS_COND_AXIS_OFFSET-0 "-"
*MEAS_COND_AXIS_OFFSET-1 "-0.1081000000"
*MEAS_COND_AXIS_OFFSET-2 "0.3758000000"
*MEAS_COND_AXIS_OFFSET-3 "-"
*MEAS_COND_AXIS_OFFSET-4 "-"
*MEAS_COND_AXIS_OFFSET-5 "0.3758000000"
*MEAS_COND_AXIS_OFFSET-6 "-0.4839000000"
*MEAS_COND_AXIS_OFFSET-7 "-"
*MEAS_COND_AXIS_OFFSET-8 "-"
*MEAS_COND_AXIS_OFFSET-9 "-"
*MEAS_COND_AXIS_OFFSET-10 "-"
*MEAS_COND_AXIS_OFFSET-11 "-"
*MEAS_COND_AXIS_OFFSET-12 "-"
*MEAS_COND_AXIS_OFFSET-13 "-"
*MEAS_COND_AXIS_OFFSET-14 "-"
*MEAS_COND_AXIS_OFFSET-15 "-"
*MEAS_COND_AXIS_OFFSET-16 "-"
*MEAS_COND_AXIS_OFFSET-17 "-"
*MEAS_COND_AXIS_OFFSET-18 "-"
*MEAS_COND_AXIS_OFFSET-19 "-"
*MEAS_COND_AXIS_OFFSET-20 "-"
*MEAS_COND_AXIS_OFFSET-21 "-"
*MEAS_COND_AXIS_OFFSET-22 "-"
*MEAS_COND_AXIS_OFFSET-23 "-"
*MEAS_COND_AXIS_OFFSET-24 "-"
*MEAS_COND_AXIS_OFFSET-25 "-"
*MEAS_COND_AXIS_OFFSET-26 "-"
*MEAS_COND_AXIS_OFFSET-27 "-"
*MEAS_COND_AXIS_OFFSET-28 "-"
*MEAS_COND_AXIS_OFFSET-29 "-"
*MEAS_COND_AXIS_OFFSET-30 "-"
*MEAS_COND_AXIS_POSITION-0 "0.0000000000"
*MEAS_COND_AXIS_POSITION-1 "0.0000000000"
*MEAS_COND_AXIS_POSITION-2 "0.0000000000"
*MEAS_COND_AXIS_POSITION-3 "-0.5500000000"
*MEAS_COND_AXIS_POSITION-4 "0.0000000000"
*MEAS_COND_AXIS_POSITION-5 "0.0000000000"
*MEAS_COND_AXIS_POSITION-6 "0.0000000000"
*MEAS_COND_AXIS_POSITION-7 "-0.4278800000"
*MEAS_COND_AXIS_POSITION-8 "BB"
*MEAS_COND_AXIS_POSITION-9 "0.0000000000"
*MEAS_COND_AXIS_POSITION-10 "Soller_slit_5.0deg"
*MEAS_COND_AXIS_POSITION-11 "2/3deg"
*MEAS_COND_AXIS_POSITION-12 "2.2088000000"
*MEAS_COND_AXIS_POSITION-13 "-0.4140600000"
*MEAS_COND_AXIS_POSITION-14 "0.0000000000"
*MEAS_COND_AXIS_POSITION-15 "10.0mm"
*MEAS_COND_AXIS_POSITION-16 "None"
*MEAS_COND_AXIS_POSITION-17 "Cu_K-beta"
*MEAS_COND_AXIS_POSITION-18 "13.000mm"
*MEAS_COND_AXIS_POSITION-19 "13.000mm"
*MEAS_COND_AXIS_POSITION-20 "No_unit"
*MEAS_COND_AXIS_POSITION-21 "Soller_slit_5.0deg"
*MEAS_COND_AXIS_POSITION-22 "None"
*MEAS_COND_AXIS_POSITION-23 "13.0000000000"
*MEAS_COND_AXIS_POSITION-24 "13.0000000000"
*MEAS_COND_AXIS_POSITION-25 "0.0109400000"
*MEAS_COND_AXIS_POSITION-26 "Open"
*MEAS_COND_AXIS_POSITION-27 "None"
*MEAS_COND_AXIS_POSITION-28 "None"
*MEAS_COND_AXIS_POSITION-29 "None"
*MEAS_COND_AXIS_POSITION-30 "38.0000000000"
*MEAS_COND_AXIS_UNIT-0 "deg"
*MEAS_COND_AXIS_UNIT-1 "deg"
*MEAS_COND_AXIS_UNIT-2 "deg"
*MEAS_COND_AXIS_UNIT-3 "mm"
*MEAS_COND_AXIS_UNIT-4 "deg"
*MEAS_COND_AXIS_UNIT-5 "deg"
*MEAS_COND_AXIS_UNIT-6 "deg"
*MEAS_COND_AXIS_UNIT-7 "mm"
*MEAS_COND_AXIS_UNIT-8 ""
*MEAS_COND_AXIS_UNIT-9 "pulse"
*MEAS_COND_AXIS_UNIT-10 ""
*MEAS_COND_AXIS_UNIT-11 ""
*MEAS_COND_AXIS_UNIT-12 "mm"
*MEAS_COND_AXIS_UNIT-13 "mm"
*MEAS_COND_AXIS_UNIT-14 ""
*MEAS_COND_AXIS_UNIT-15 ""
*MEAS_COND_AXIS_UNIT-16 ""
*MEAS_COND_AXIS_UNIT-17 ""
*MEAS_COND_AXIS_UNIT-18 ""
*MEAS_COND_AXIS_UNIT-19 ""
*MEAS_COND_AXIS_UNIT-20 ""
*MEAS_COND_AXIS_UNIT-21 ""
*MEAS_COND_AXIS_UNIT-22 ""
*MEAS_COND_AXIS_UNIT-23 "mm"
*MEAS_COND_AXIS_UNIT-24 "mm"
*MEAS_COND_AXIS_UNIT-25 "mm"
*MEAS_COND_AXIS_UNIT-26 ""
*MEAS_COND_AXIS_UNIT-27 ""
*MEAS_COND_AXIS_UNIT-28 ""
*MEAS_COND_AXIS_UNIT-29 ""
*MEAS_COND_AXIS_UNIT-30 "div"
*MEAS_COND_COUNTER_CNTLOSS_CORR "0.0000000000"
*MEAS_COND_COUNTER_PHABASE "38.0000000000"
*MEAS_COND_COUNTER_PHAWINDOW "16.0000000000"
*MEAS_COND_COUNTER_PHA_UNIT "div"
*MEAS_COND_COUNTER_TAUDIFF "30.0000000000"
*MEAS_COND_COUNTER_TAUINT "0.0000000000"
*MEAS_COND_IRRADIATION_MODE "OFF"
*MEAS_COND_IRRADIATION_WIDTH ""
*MEAS_COND_OPT_ATTR "集中法"
*MEAS_COND_OPT_NAME "@集中法"
*MEAS_COND_UNSYMMETRIC_MODE "OFF"
*MEAS_COND_XG_CURRENT "30.0000000000"
*MEAS_COND_XG_VOLTAGE "40.0000000000"
*MEAS_COND_XG_WAVE_TYPE "Ka"
*MEAS_DATA_COUNT "5001.0000000000"
*MEAS_SCAN_AXIS_X "2θ/θ"
*MEAS_SCAN_AXIS_X_INTERNAL "TwoThetaTheta"
*MEAS_SCAN_END_TIME "07/14/21 15:47:08"
*MEAS_SCAN_MODE "CONTINUOUS"
*MEAS_SCAN_MONITOR "0"
*MEAS_SCAN_RESOLUTION_X "0.0002"
*MEAS_SCAN_SPEED "1.0"
*MEAS_SCAN_SPEED_UNIT "deg/min"
*MEAS_SCAN_START "20.0000000000"
*MEAS_SCAN_START_TIME "07/14/21 14:54:14"
*MEAS_SCAN_STEP "0.0100000000"
*MEAS_SCAN_STOP "70.0000000000"
*MEAS_SCAN_UNIT_X "deg"
*MEAS_SCAN_UNIT_Y "counts"
*RAS_HEADER_END
*RAS_INT_START
20.0000 1509.0000 1.0000
20.0400 1453.0000 1.0000
20.0800 1552.0000 1.0000
20.1200 1463.0000 1.0000
20.1600 1534.0000 1.0000
20.2000 1511.0000 1.0000
20.2400 1542.0000 1.0000
20.2800 1544.0000 1.0000
20.3200 1508.0000 1.0000
20.3600 1463.0000 1.0000
20.4000 1545.0000 1.0000
20.4400 1552.0000 1.0000
20.4800 1533.0000 1.0000
20.5200 1522.0000 1.0000
20.5600 1545.0000 1.0000
20.6000 1497.0000 1.0000
20.6400 1525.0000 1.0000
20.6800 1547.0000 1.0000
20.7200 1531.0000 1.0000
20.7600 1488.0000 1.0000
20.8000 1556.0000 1.0000
20.8400 1518.0000 1.0000
20.8800 1506.0000 1.0000
20.9200 1512.0000 1.0000
20.9600 1545.0000 1.0000
21.0000 1476.0000 1.0000
21.0400 1520.0000 1.0000
21.0800 1489.0000 1.0000
21.1200 1553.0000 1.0000
21.1600 1504.0000 1.0000
21.2000 1533.0000 1.0000
21.2400 1481.0000 1.0000
21.2800 1537.0000 1.0000
21.3200 1510.0000 1.0000
21.3600 1511.0000 1.0000
21.4000 1467.0000 1.0000
21.4400 1479.0000 1.0000
21.4800 1473.0000 1.0000
21.5200 1506.0000 1.0000
21.5600 1464.0000 1.0000
21.6000 1515.0000 1.0000
21.6400 1574.0000 1.0000
21.6800 1565.0000 1.0000
21.7200 1494.0000 1.0000
21.7600 1516.0000 1.0000
21.8000 1524.0000 1.0000
21.8400 1522.0000 1.0000
21.8800 1521.0000 1.0000
21.9200 1582.0000 1.0000
21.9600 1518.0000 1.0000
22.0000 1534.0000 1.0000
22.0400 1560.0000 1.0000
22.0800 1548.0000 1.0000
22.1200 1528.0000 1.0000
22.1600 1488.0000 1.0000
22.2000 1618.0000 1.0000
22.2400 1537.0000 1.0000
22.2800 1532.0000 1.0000
22.3200 1477.0000 1.0000
22.3600 1557.0000 1.0000
22.4000 1560.0000 1.0000
22.4400 1582.0000 1.0000
22.4800 1573.0000 1.0000
22.5200 1561.0000 1.0000
22.5600 1548.0000 1.0000
22.6000 1547.0000 1.0000
22.6400 1546.0000 1.0000
22.6800 1558.0000 1.0000
22.7200 1492.0000 1.0000
22.7600 1562.0000 1.0000
22.8000 1642.0000 1.0000
22.8400 1631.0000 1.0000
22.8800 1497.0000 1.0000
22.9200 1598.0000 1.0000
22.9600 1588.0000 1.0000
23.0000 1531.0000 1.0000
23.0400 1590.0000 1.0000
23.0800 1590.0000 1.0000
23.1200 1564.0000 1.0000
23.1600 1590.0000 1.0000
23.2000 1495.0000 1.0000
23.2400 1571.0000 1.0000
23.2800 1550.0000 1.0000
23.3200 1547.0000 1.0000
23.3600 1580.0000 1.0000
23.4000 1588.0000 1.0000
23.4400 1521.0000 1.0000
23.4800 1582.0000 1.0000
23.5200 1598.0000 1.0000
23.5600 1573.0000 1.0000
23.6000 1567.0000 1.0000
23.6400 1592.0000 1.0000
23.6800 1597.0000 1.0000
23.7200 1604.0000 1.0000
23.7600 1594.0000 1.0000
23.8000 1562.0000 1.0000
23.8400 1599.0000 1.0000
23.8800 1553.0000 1.0000
23.9200 1609.0000 1.0000
23.9600 1606.0000 1.0000
24.0000 1590.0000 1.0000
24.0400 1573.0000 1.0000
24.0800 1598.0000 1.0000
24.1200 1631.0000 1.0000
24.1600 1610.0000 1.0000
24.2000 1606.0000 1.0000
24.2400 1596.0000 1.0000
24.2800 1593.0000 1.0000
24.3200 1613.0000 1.0000
24.3600 1641.0000 1.0000
24.4000 1589.0000 1.0000
24.4400 1608.0000 1.0000
24.4800 1525.0000 1.0000
24.5200 1634.0000 1.0000
24.5600 1572.0000 1.0000
24.6000 1618.0000 1.0000
24.6400 1679.0000 1.0000
24.6800 1588.0000 1.0000
24.7200 1665.0000 1.0000
24.7600 1627.0000 1.0000
24.8000 1647.0000 1.0000
24.8400 1624.0000 1.0000
24.8800 1644.0000 1.0000
24.9200 1668.0000 1.0000
24.9600 1708.0000 1.0000
25.0000 1663.0000 1.0000
25.0400 1668.0000 1.0000
25.0800 1685.0000 1.0000
25.1200 1682.0000 1.0000
25.1600 1671.0000 1.0000
25.2000 1673.0000 1.0000
25.2400 1666.0000 1.0000
25.2800 1645.0000 1.0000
25.3200 1622.0000 1.0000
25.3600 1642.0000 1.0000
25.4000 1650.0000 1.0000
25.4400 1596.0000 1.0000
25.4800 1620.0000 1.0000
25.5200 1595.0000 1.0000
25.5600 1643.0000 1.0000
25.6000 1701.0000 1.0000
25.6400 1671.0000 1.0000
25.6800 1648.0000 1.0000
25.7200 1676.0000 1.0000
25.7600 1652.0000 1.0000
25.8000 1661.0000 1.0000
25.8400 1715.0000 1.0000
25.8800 1618.0000 1.0000
25.9200 1659.0000 1.0000
25.9600 1631.0000 1.0000
26.0000 1614.0000 1.0000
26.0400 1620.0000 1.0000
26.0800 1631.0000 1.0000
26.1200 1653.0000 1.0000
26.1600 1688.0000 1.0000
26.2000 1710.0000 1.0000
26.2400 1686.0000 1.0000
26.2800 1659.0000 1.0000
26.3200 1755.0000 1.0000
26.3600 1691.0000 1.0000
26.4000 1722.0000 1.0000
26.4400 1722.0000 1.0000
26.4800 1712.0000 1.0000
26.5200 1781.0000 1.0000
26.5600 1789.0000 1.0000
26.6000 1757.0000 1.0000
26.6400 1816.0000 1.0000
26.6800 1771.0000 1.0000
26.7200 1712.0000 1.0000
26.7600 1804.0000 1.0000
26.8000 1898.0000 1.0000
26.8400 1864.0000 1.0000
26.8800 1981.0000 1.0000
26.9200 1999.0000 1.0000
26.9600 2118.0000 1.0000
27.0000 2235.0000 1.0000
27.0400 2559.0000 1.0000
27.0800 2825.0000 1.0000
27.1200 3285.0000 1.0000
27.1600 3984.0000 1.0000
27.2000 4815.0000 1.0000
27.2400 6071.0000 1.0000
27.2800 6980.0000 1.0000
27.3200 6728.0000 1.0000
27.3600 6031.0000 1.0000
27.4000 4827.0000 1.0000
27.4400 3910.0000 1.0000
27.4800 3171.0000 1.0000
27.5200 2736.0000 1.0000
27.5600 2454.0000 1.0000
27.6000 2307.0000 1.0000
27.6400 2120.0000 1.0000
27.6800 2001.0000 1.0000
27.7200 1937.0000 1.0000
27.7600 1868.0000 1.0000
27.8000 1834.0000 1.0000
27.8400 1788.0000 1.0000
27.8800 1829.0000 1.0000
27.9200 1744.0000 1.0000
27.9600 1771.0000 1.0000
28.0000 1670.0000 1.0000
28.0400 1683.0000 1.0000
28.0800 1649.0000 1.0000
28.1200 1661.0000 1.0000
28.1600 1693.0000 1.0000
28.2000 1719.0000 1.0000
28.2400 1602.0000 1.0000
28.2800 1536.0000 1.0000
28.3200 1696.0000 1.0000
28.3600 1619.0000 1.0000
28.4000 1650.0000 1.0000
28.4400 1644.0000 1.0000
28.4800 1575.0000 1.0000
28.5200 1575.0000 1.0000
28.5600 1584.0000 1.0000
28.6000 1595.0000 1.0000
28.6400 1526.0000 1.0000
28.6800 1633.0000 1.0000
28.7200 1502.0000 1.0000
28.7600 1527.0000 1.0000
28.8000 1570.0000 1.0000
28.8400 1538.0000 1.0000
28.8800 1543.0000 1.0000
28.9200 1580.0000 1.0000
28.9600 1556.0000 1.0000
29.0000 1497.0000 1.0000
29.0400 1484.0000 1.0000
29.0800 1507.0000 1.0000
29.1200 1613.0000 1.0000
29.1600 1551.0000 1.0000
29.2000 1543.0000 1.0000
29.2400 1540.0000 1.0000
29.2800 1479.0000 1.0000
29.3200 1480.0000 1.0000
29.3600 1482.0000 1.0000
29.4000 1494.0000 1.0000
29.4400 1527.0000 1.0000
29.4800 1493.0000 1.0000
29.5200 1523.0000 1.0000
29.5600 1531.0000 1.0000
29.6000 1447.0000 1.0000
29.6400 1509.0000 1.0000
29.6800 1486.0000 1.0000
29.7200 1549.0000 1.0000
29.7600 1489.0000 1.0000
29.8000 1487.0000 1.0000
29.8400 1459.0000 1.0000
29.8800 1488.0000 1.0000
29.9200 1459.0000 1.0000
29.9600 1451.0000 1.0000
30.0000 1473.0000 1.0000
30.0400 1472.0000 1.0000
30.0800 1455.0000 1.0000
30.1200 1399.0000 1.0000
30.1600 1418.0000 1.0000
30.2000 1492.0000 1.0000
30.2400 1380.0000 1.0000
30.2800 1468.0000 1.0000
30.3200 1486.0000 1.0000
30.3600 1492.0000 1.0000
30.4000 1437.0000 1.0000
30.4400 1428.0000 1.0000
30.4800 1339.0000 1.0000
30.5200 1396.0000 1.0000
30.5600 1464.0000 1.0000
30.6000 1491.0000 1.0000
30.6400 1400.0000 1.0000
30.6800 1488.0000 1.0000
30.7200 1424.0000 1.0000
30.7600 1373.0000 1.0000
30.8000 1446.0000 1.0000
30.8400 1419.0000 1.0000
30.8800 1404.0000 1.0000
30.9200 1431.0000 1.0000
30.9600 1388.0000 1.0000
31.0000 1409.0000 1.0000
31.0400 1458.0000 1.0000
31.0800 1429.0000 1.0000
31.1200 1445.0000 1.0000
31.1600 1390.0000 1.0000
31.2000 1427.0000 1.0000
31.2400 1385.0000 1.0000
31.2800 1377.0000 1.0000
31.3200 1365.0000 1.0000
31.3600 1408.0000 1.0000
31.4000 1409.0000 1.0000
31.4400 1392.0000 1.0000
31.4800 1364.0000 1.0000
31.5200 1351.0000 1.0000
31.5600 1353.0000 1.0000
31.6000 1389.0000 1.0000
31.6400 1337.0000 1.0000
31.6800 1390.0000 1.0000
31.7200 1344.0000 1.0000
31.7600 1301.0000 1.0000
31.8000 1398.0000 1.0000
31.8400 1351.0000 1.0000
31.8800 1354.0000 1.0000
31.9200 1389.0000 1.0000
31.9600 1425.0000 1.0000
32.0000 1487.0000 1.0000
32.0400 1385.0000 1.0000
32.0800 1425.0000 1.0000
32.1200 1402.0000 1.0000
32.1600 1362.0000 1.0000
32.2000 1379.0000 1.0000
32.2400 1370.0000 1.0000
32.2800 1359.0000 1.0000
32.3200 1361.0000 1.0000
32.3600 1335.0000 1.0000
32.4000 1335.0000 1.0000
32.4400 1333.0000 1.0000
32.4800 1394.0000 1.0000
32.5200 1352.0000 1.0000
32.5600 1261.0000 1.0000
32.6000 1335.0000 1.0000
32.6400 1266.0000 1.0000
32.6800 1286.0000 1.0000
32.7200 1333.0000 1.0000
32.7600 1322.0000 1.0000
32.8000 1299.0000 1.0000
32.8400 1245.0000 1.0000
32.8800 1302.0000 1.0000
32.9200 1301.0000 1.0000
32.9600 1256.0000 1.0000
33.0000 1312.0000 1.0000
33.0400 1264.0000 1.0000
33.0800 1327.0000 1.0000
33.1200 1332.0000 1.0000
33.1600 1312.0000 1.0000
33.2000 1309.0000 1.0000
33.2400 1245.0000 1.0000
33.2800 1315.0000 1.0000
33.3200 1305.0000 1.0000
33.3600 1270.0000 1.0000
33.4000 1326.0000 1.0000
33.4400 1289.0000 1.0000
33.4800 1241.0000 1.0000
33.5200 1267.0000 1.0000
33.5600 1315.0000 1.0000
33.6000 1289.0000 1.0000
33.6400 1295.0000 1.0000
33.6800 1313.0000 1.0000
33.7200 1336.0000 1.0000
33.7600 1376.0000 1.0000
33.8000 1381.0000 1.0000
33.8400 1347.0000 1.0000
33.8800 1348.0000 1.0000
33.9200 1345.0000 1.0000
33.9600 1394.0000 1.0000
34.0000 1367.0000 1.0000
34.0400 1437.0000 1.0000
34.0800 1442.0000 1.0000
34.1200 1459.0000 1.0000
34.1600 1576.0000 1.0000
34.2000 1569.0000 1.0000
34.2400 1776.0000 1.0000
34.2800 1858.0000 1.0000
34.3200 2016.0000 1.0000
34.3600 2326.0000 1.0000
34.4000 2734.0000 1.0000
34.4400 3264.0000 1.0000
34.4800 3594.0000 1.0000
34.5200 3571.0000 1.0000
34.5600 3146.0000 1.0000
34.6000 2712.0000 1.0000
34.6400 2298.0000 1.0000
34.6800 2004.0000 1.0000
34.7200 1744.0000 1.0000
34.7600 1621.0000 1.0000
34.8000 1559.0000 1.0000
34.8400 1472.0000 1.0000
34.8800 1340.0000 1.0000
34.9200 1417.0000 1.0000
34.9600 1263.0000 1.0000
35.0000 1207.0000 1.0000
35.0400 1274.0000 1.0000
35.0800 1313.0000 1.0000
35.1200 1249.0000 1.0000
35.1600 1191.0000 1.0000
35.2000 1217.0000 1.0000
35.2400 1159.0000 1.0000
35.2800 1175.0000 1.0000
35.3200 1163.0000 1.0000
35.3600 1101.0000 1.0000
35.4000 1115.0000 1.0000
35.4400 1127.0000 1.0000
35.4800 1142.0000 1.0000
35.5200 1128.0000 1.0000
35.5600 1126.0000 1.0000
35.6000 1126.0000 1.0000
35.6400 1109.0000 1.0000
35.6800 1096.0000 1.0000
35.7200 1149.0000 1.0000
35.7600 1089.0000 1.0000
35.8000 1076.0000 1.0000
35.8400 1077.0000 1.0000
35.8800 1142.0000 1.0000
35.9200 1083.0000 1.0000
35.9600 1108.0000 1.0000
36.0000 1091.0000 1.0000
36.0400 1098.0000 1.0000
36.0800 1128.0000 1.0000
36.1200 1167.0000 1.0000
36.1600 1146.0000 1.0000
36.2000 1139.0000 1.0000
36.2400 1154.0000 1.0000
36.2800 1211.0000 1.0000
36.3200 1175.0000 1.0000
36.3600 1217.0000 1.0000
36.4000 1205.0000 1.0000
36.4400 1219.0000 1.0000
36.4800 1168.0000 1.0000
36.5200 1138.0000 1.0000
36.5600 1121.0000 1.0000
36.6000 1067.0000 1.0000
36.6400 1071.0000 1.0000
36.6800 1064.0000 1.0000
36.7200 1024.0000 1.0000
36.7600 1035.0000 1.0000
36.8000 1018.0000 1.0000
36.8400 1040.0000 1.0000
36.8800 969.0000 1.0000
36.9200 1051.0000 1.0000
36.9600 1006.0000 1.0000
37.0000 1016.0000 1.0000
37.0400 990.0000 1.0000
37.0800 1014.0000 1.0000
37.1200 1052.0000 1.0000
37.1600 984.0000 1.0000
37.2000 1019.0000 1.0000
37.2400 1042.0000 1.0000
37.2800 999.0000 1.0000
37.3200 986.0000 1.0000
37.3600 954.0000 1.0000
37.4000 1009.0000 1.0000
37.4400 1011.0000 1.0000
37.4800 982.0000 1.0000
37.5200 980.0000 1.0000
37.5600 994.0000 1.0000
37.6000 1010.0000 1.0000
37.6400 991.0000 1.0000
37.6800 1013.0000 1.0000
37.7200 1025.0000 1.0000
37.7600 1021.0000 1.0000
37.8000 991.0000 1.0000
37.8400 999.0000 1.0000
37.8800 1020.0000 1.0000
37.9200 1057.0000 1.0000
37.9600 1059.0000 1.0000
38.0000 1079.0000 1.0000
38.0400 1075.0000 1.0000
38.0800 1119.0000 1.0000
38.1200 1198.0000 1.0000
38.1600 1245.0000 1.0000
38.2000 1438.0000 1.0000
38.2400 1578.0000 1.0000
38.2800 1813.0000 1.0000
38.3200 2160.0000 1.0000
38.3600 2645.0000 1.0000
38.4000 3597.0000 1.0000
38.4400 4671.0000 1.0000
38.4800 5990.0000 1.0000
38.5200 6473.0000 1.0000
38.5600 6081.0000 1.0000
38.6000 5595.0000 1.0000
38.6400 4486.0000 1.0000
38.6800 3506.0000 1.0000
38.7200 2619.0000 1.0000
38.7600 2096.0000 1.0000
38.8000 1716.0000 1.0000
38.8400 1502.0000 1.0000
38.8800 1284.0000 1.0000
38.9200 1185.0000 1.0000
38.9600 1046.0000 1.0000
39.0000 1055.0000 1.0000
39.0400 1032.0000 1.0000
39.0800 984.0000 1.0000
39.1200 961.0000 1.0000
39.1600 911.0000 1.0000
39.2000 962.0000 1.0000
39.2400 892.0000 1.0000
39.2800 942.0000 1.0000
39.3200 887.0000 1.0000
39.3600 939.0000 1.0000
39.4000 931.0000 1.0000
39.4400 931.0000 1.0000
39.4800 949.0000 1.0000
39.5200 982.0000 1.0000
39.5600 934.0000 1.0000
39.6000 932.0000 1.0000
39.6400 918.0000 1.0000
39.6800 956.0000 1.0000
39.7200 907.0000 1.0000
39.7600 899.0000 1.0000
39.8000 866.0000 1.0000
39.8400 824.0000 1.0000
39.8800 842.0000 1.0000
39.9200 828.0000 1.0000
39.9600 896.0000 1.0000
40.0000 889.0000 1.0000
40.0400 871.0000 1.0000
40.0800 867.0000 1.0000
40.1200 851.0000 1.0000
40.1600 842.0000 1.0000
40.2000 829.0000 1.0000
40.2400 818.0000 1.0000
40.2800 831.0000 1.0000
40.3200 811.0000 1.0000
40.3600 805.0000 1.0000
40.4000 824.0000 1.0000
40.4400 829.0000 1.0000
40.4800 854.0000 1.0000
40.5200 829.0000 1.0000
40.5600 807.0000 1.0000
40.6000 808.0000 1.0000
40.6400 762.0000 1.0000
40.6800 816.0000 1.0000
40.7200 794.0000 1.0000
40.7600 787.0000 1.0000
40.8000 804.0000 1.0000
40.8400 822.0000 1.0000
40.8800 805.0000 1.0000
40.9200 808.0000 1.0000
40.9600 799.0000 1.0000
41.0000 828.0000 1.0000
41.0400 800.0000 1.0000
41.0800 806.0000 1.0000
41.1200 839.0000 1.0000
41.1600 782.0000 1.0000
41.2000 801.0000 1.0000
41.2400 836.0000 1.0000
41.2800 798.0000 1.0000
41.3200 824.0000 1.0000
41.3600 854.0000 1.0000
41.4000 825.0000 1.0000
41.4400 811.0000 1.0000
41.4800 772.0000 1.0000
41.5200 771.0000 1.0000
41.5600 852.0000 1.0000
41.6000 820.0000 1.0000
41.6400 861.0000 1.0000
41.6800 842.0000 1.0000
41.7200 810.0000 1.0000
41.7600 810.0000 1.0000
41.8000 876.0000 1.0000
41.8400 768.0000 1.0000
41.8800 789.0000 1.0000
41.9200 828.0000 1.0000
41.9600 825.0000 1.0000
42.0000 786.0000 1.0000
42.0400 814.0000 1.0000
42.0800 792.0000 1.0000
42.1200 847.0000 1.0000
42.1600 778.0000 1.0000
42.2000 765.0000 1.0000
42.2400 816.0000 1.0000
42.2800 837.0000 1.0000
42.3200 797.0000 1.0000
42.3600 751.0000 1.0000
42.4000 806.0000 1.0000
42.4400 778.0000 1.0000
42.4800 847.0000 1.0000
42.5200 785.0000 1.0000
42.5600 801.0000 1.0000
42.6000 768.0000 1.0000
42.6400 790.0000 1.0000
42.6800 819.0000 1.0000
42.7200 747.0000 1.0000
42.7600 825.0000 1.0000
42.8000 741.0000 1.0000
42.8400 812.0000 1.0000
42.8800 784.0000 1.0000
42.9200 812.0000 1.0000
42.9600 854.0000 1.0000
43.0000 801.0000 1.0000
43.0400 787.0000 1.0000
43.0800 824.0000 1.0000
43.1200 809.0000 1.0000
43.1600 875.0000 1.0000
43.2000 875.0000 1.0000
43.2400 891.0000 1.0000
43.2800 892.0000 1.0000
43.3200 884.0000 1.0000
43.3600 842.0000 1.0000
43.4000 833.0000 1.0000
43.4400 822.0000 1.0000
43.4800 786.0000 1.0000
43.5200 769.0000 1.0000
43.5600 770.0000 1.0000
43.6000 803.0000 1.0000
43.6400 774.0000 1.0000
43.6800 765.0000 1.0000
43.7200 792.0000 1.0000
43.7600 790.0000 1.0000
43.8000 760.0000 1.0000
43.8400 782.0000 1.0000
43.8800 811.0000 1.0000
43.9200 804.0000 1.0000
43.9600 768.0000 1.0000
44.0000 781.0000 1.0000
44.0400 759.0000 1.0000
44.0800 766.0000 1.0000
44.1200 762.0000 1.0000
44.1600 781.0000 1.0000
44.2000 777.0000 1.0000
44.2400 769.0000 1.0000
44.2800 778.0000 1.0000
44.3200 791.0000 1.0000
44.3600 720.0000 1.0000
44.4000 770.0000 1.0000
44.4400 772.0000 1.0000
44.4800 729.0000 1.0000
44.5200 800.0000 1.0000
44.5600 713.0000 1.0000
44.6000 759.0000 1.0000
44.6400 755.0000 1.0000
44.6800 764.0000 1.0000
44.7200 759.0000 1.0000
44.7600 739.0000 1.0000
44.8000 725.0000 1.0000
44.8400 762.0000 1.0000
44.8800 774.0000 1.0000
44.9200 752.0000 1.0000
44.9600 796.0000 1.0000
45.0000 760.0000 1.0000
45.0400 780.0000 1.0000
45.0800 765.0000 1.0000
45.1200 752.0000 1.0000
45.1600 733.0000 1.0000
45.2000 721.0000 1.0000
45.2400 719.0000 1.0000
45.2800 773.0000 1.0000
45.3200 703.0000 1.0000
45.3600 742.0000 1.0000
45.4000 797.0000 1.0000
45.4400 709.0000 1.0000
45.4800 731.0000 1.0000
45.5200 733.0000 1.0000
45.5600 751.0000 1.0000
45.6000 775.0000 1.0000
45.6400 725.0000 1.0000
45.6800 726.0000 1.0000
45.7200 741.0000 1.0000
45.7600 756.0000 1.0000
45.8000 738.0000 1.0000
45.8400 762.0000 1.0000
45.8800 761.0000 1.0000
45.9200 721.0000 1.0000
45.9600 765.0000 1.0000
46.0000 721.0000 1.0000
46.0400 701.0000 1.0000
46.0800 753.0000 1.0000
46.1200 741.0000 1.0000
46.1600 724.0000 1.0000
46.2000 745.0000 1.0000
46.2400 743.0000 1.0000
46.2800 735.0000 1.0000
46.3200 694.0000 1.0000
46.3600 727.0000 1.0000
46.4000 725.0000 1.0000
46.4400 695.0000 1.0000
46.4800 730.0000 1.0000
46.5200 747.0000 1.0000
46.5600 686.0000 1.0000
46.6000 724.0000 1.0000
46.6400 714.0000 1.0000
46.6800 732.0000 1.0000
46.7200 733.0000 1.0000
46.7600 704.0000 1.0000
46.8000 700.0000 1.0000
46.8400 753.0000 1.0000
46.8800 739.0000 1.0000
46.9200 729.0000 1.0000
46.9600 743.0000 1.0000
47.0000 761.0000 1.0000
47.0400 788.0000 1.0000
47.0800 741.0000 1.0000
47.1200 698.0000 1.0000
47.1600 694.0000 1.0000
47.2000 707.0000 1.0000
47.2400 702.0000 1.0000
47.2800 683.0000 1.0000
47.3200 743.0000 1.0000
47.3600 731.0000 1.0000
47.4000 719.0000 1.0000
47.4400 685.0000 1.0000
47.4800 710.0000 1.0000
47.5200 706.0000 1.0000
47.5600 716.0000 1.0000
47.6000 722.0000 1.0000
47.6400 727.0000 1.0000
47.6800 667.0000 1.0000
47.7200 701.0000 1.0000
47.7600 689.0000 1.0000
47.8000 671.0000 1.0000
47.8400 704.0000 1.0000
47.8800 696.0000 1.0000
47.9200 715.0000 1.0000
47.9600 712.0000 1.0000
48.0000 682.0000 1.0000
48.0400 696.0000 1.0000
48.0800 714.0000 1.0000
48.1200 739.0000 1.0000
48.1600 682.0000 1.0000
48.2000 665.0000 1.0000
48.2400 654.0000 1.0000
48.2800 683.0000 1.0000
48.3200 738.0000 1.0000
48.3600 705.0000 1.0000
48.4000 712.0000 1.0000
48.4400 682.0000 1.0000
48.4800 709.0000 1.0000
48.5200 687.0000 1.0000
48.5600 645.0000 1.0000
48.6000 718.0000 1.0000
48.6400 648.0000 1.0000
48.6800 688.0000 1.0000
48.7200 658.0000 1.0000
48.7600 700.0000 1.0000
48.8000 707.0000 1.0000
48.8400 698.0000 1.0000
48.8800 727.0000 1.0000
48.9200 724.0000 1.0000
48.9600 632.0000 1.0000
49.0000 679.0000 1.0000
49.0400 672.0000 1.0000
49.0800 665.0000 1.0000
49.1200 680.0000 1.0000
49.1600 661.0000 1.0000
49.2000 694.0000 1.0000
49.2400 724.0000 1.0000
49.2800 662.0000 1.0000
49.3200 700.0000 1.0000
49.3600 642.0000 1.0000
49.4000 647.0000 1.0000
49.4400 663.0000 1.0000
49.4800 690.0000 1.0000
49.5200 652.0000 1.0000
49.5600 720.0000 1.0000
49.6000 692.0000 1.0000
49.6400 710.0000 1.0000
49.6800 675.0000 1.0000
49.7200 648.0000 1.0000
49.7600 682.0000 1.0000
49.8000 709.0000 1.0000
49.8400 647.0000 1.0000
49.8800 702.0000 1.0000
49.9200 689.0000 1.0000
49.9600 648.0000 1.0000
50.0000 644.0000 1.0000
50.0400 679.0000 1.0000
50.0800 676.0000 1.0000
50.1200 663.0000 1.0000
50.1600 660.0000 1.0000
50.2000 713.0000 1.0000
50.2400 682.0000 1.0000
50.2800 666.0000 1.0000
50.3200 692.0000 1.0000
50.3600 656.0000 1.0000
50.4000 695.0000 1.0000
50.4400 712.0000 1.0000
50.4800 702.0000 1.0000
50.5200 693.0000 1.0000
50.5600 742.0000 1.0000
50.6000 689.0000 1.0000
50.6400 690.0000 1.0000
50.6800 715.0000 1.0000
50.7200 728.0000 1.0000
50.7600 725.0000 1.0000
50.8000 633.0000 1.0000
50.8400 700.0000 1.0000
50.8800 729.0000 1.0000
50.9200 698.0000 1.0000
50.9600 685.0000 1.0000
51.0000 705.0000 1.0000
51.0400 669.0000 1.0000
51.0800 723.0000 1.0000
51.1200 715.0000 1.0000
51.1600 666.0000 1.0000
51.2000 659.0000 1.0000
51.2400 676.0000 1.0000
51.2800 761.0000 1.0000
51.3200 710.0000 1.0000
51.3600 693.0000 1.0000
51.4000 708.0000 1.0000
51.4400 732.0000 1.0000
51.4800 685.0000 1.0000
51.5200 712.0000 1.0000
51.5600 712.0000 1.0000
51.6000 710.0000 1.0000
51.6400 697.0000 1.0000
51.6800 735.0000 1.0000
51.7200 772.0000 1.0000
51.7600 806.0000 1.0000
51.8000 808.0000 1.0000
51.8400 845.0000 1.0000
51.8800 917.0000 1.0000
51.9200 992.0000 1.0000
51.9600 1113.0000 1.0000
52.0000 1170.0000 1.0000
52.0400 1426.0000 1.0000
52.0800 1711.0000 1.0000
52.1200 2249.0000 1.0000
52.1600 3247.0000 1.0000
52.2000 4605.0000 1.0000
52.2400 5776.0000 1.0000
52.2800 5972.0000 1.0000
52.3200 5224.0000 1.0000
52.3600 4699.0000 1.0000
52.4000 4160.0000 1.0000
52.4400 3454.0000 1.0000
52.4800 2386.0000 1.0000
52.5200 1870.0000 1.0000
52.5600 1491.0000 1.0000
52.6000 1285.0000 1.0000
52.6400 1099.0000 1.0000
52.6800 1005.0000 1.0000
52.7200 926.0000 1.0000
52.7600 849.0000 1.0000
52.8000 819.0000 1.0000
52.8400 778.0000 1.0000
52.8800 781.0000 1.0000
52.9200 751.0000 1.0000
52.9600 761.0000 1.0000
53.0000 790.0000 1.0000
53.0400 784.0000 1.0000
53.0800 734.0000 1.0000
53.1200 730.0000 1.0000
53.1600 690.0000 1.0000
53.2000 686.0000 1.0000
53.2400 697.0000 1.0000
53.2800 712.0000 1.0000
53.3200 710.0000 1.0000
53.3600 697.0000 1.0000
53.4000 657.0000 1.0000
53.4400 691.0000 1.0000
53.4800 692.0000 1.0000
53.5200 641.0000 1.0000
53.5600 688.0000 1.0000
53.6000 697.0000 1.0000
53.6400 707.0000 1.0000
53.6800 643.0000 1.0000
53.7200 679.0000 1.0000
53.7600 666.0000 1.0000
53.8000 706.0000 1.0000
53.8400 674.0000 1.0000
53.8800 643.0000 1.0000
53.9200 663.0000 1.0000
53.9600 698.0000 1.0000
54.0000 656.0000 1.0000
54.0400 656.0000 1.0000
54.0800 694.0000 1.0000
54.1200 704.0000 1.0000
54.1600 694.0000 1.0000
54.2000 653.0000 1.0000
54.2400 695.0000 1.0000
54.2800 656.0000 1.0000
54.3200 613.0000 1.0000
54.3600 643.0000 1.0000
54.4000 671.0000 1.0000
54.4400 690.0000 1.0000
54.4800 654.0000 1.0000
54.5200 632.0000 1.0000
54.5600 682.0000 1.0000
54.6000 715.0000 1.0000
54.6400 696.0000 1.0000
54.6800 711.0000 1.0000
54.7200 693.0000 1.0000
54.7600 700.0000 1.0000
54.8000 746.0000 1.0000
54.8400 703.0000 1.0000
54.8800 683.0000 1.0000
54.9200 741.0000 1.0000
54.9600 740.0000 1.0000
55.0000 761.0000 1.0000
55.0400 718.0000 1.0000
55.0800 795.0000 1.0000
55.1200 849.0000 1.0000
55.1600 918.0000 1.0000
55.2000 1003.0000 1.0000
55.2400 1066.0000 1.0000
55.2800 1062.0000 1.0000
55.3200 1056.0000 1.0000
55.3600 1010.0000 1.0000
55.4000 1024.0000 1.0000
55.4400 926.0000 1.0000
55.4800 865.0000 1.0000
55.5200 797.0000 1.0000
55.5600 747.0000 1.0000
55.6000 764.0000 1.0000
55.6400 768.0000 1.0000
55.6800 714.0000 1.0000
55.7200 707.0000 1.0000
55.7600 685.0000 1.0000
55.8000 748.0000 1.0000
55.8400 671.0000 1.0000
55.8800 663.0000 1.0000
55.9200 700.0000 1.0000
55.9600 631.0000 1.0000
56.0000 651.0000 1.0000
56.0400 718.0000 1.0000
56.0800 632.0000 1.0000
56.1200 623.0000 1.0000
56.1600 675.0000 1.0000
56.2000 620.0000 1.0000
56.2400 690.0000 1.0000
56.2800 678.0000 1.0000
56.3200 631.0000 1.0000
56.3600 605.0000 1.0000
56.4000 615.0000 1.0000
56.4400 620.0000 1.0000
56.4800 654.0000 1.0000
56.5200 639.0000 1.0000
56.5600 598.0000 1.0000
56.6000 635.0000 1.0000
56.6400 629.0000 1.0000
56.6800 656.0000 1.0000
56.7200 615.0000 1.0000
56.7600 648.0000 1.0000
56.8000 614.0000 1.0000
56.8400 595.0000 1.0000
56.8800 654.0000 1.0000
56.9200 638.0000 1.0000
56.9600 650.0000 1.0000
57.0000 684.0000 1.0000
57.0400 625.0000 1.0000
57.0800 635.0000 1.0000
57.1200 660.0000 1.0000
57.1600 649.0000 1.0000
57.2000 643.0000 1.0000
57.2400 621.0000 1.0000
57.2800 658.0000 1.0000
57.3200 652.0000 1.0000
57.3600 626.0000 1.0000
57.4000 664.0000 1.0000
57.4400 645.0000 1.0000
57.4800 620.0000 1.0000
57.5200 656.0000 1.0000
57.5600 620.0000 1.0000
57.6000 666.0000 1.0000
57.6400 614.0000 1.0000
57.6800 632.0000 1.0000
57.7200 645.0000 1.0000
57.7600 653.0000 1.0000
57.8000 659.0000 1.0000
57.8400 671.0000 1.0000
57.8800 634.0000 1.0000
57.9200 660.0000 1.0000
57.9600 649.0000 1.0000
58.0000 621.0000 1.0000
58.0400 668.0000 1.0000
58.0800 630.0000 1.0000
58.1200 634.0000 1.0000
58.1600 605.0000 1.0000
58.2000 647.0000 1.0000
58.2400 641.0000 1.0000
58.2800 666.0000 1.0000
58.3200 648.0000 1.0000
58.3600 655.0000 1.0000
58.4000 599.0000 1.0000
58.4400 634.0000 1.0000
58.4800 614.0000 1.0000
58.5200 632.0000 1.0000
58.5600 690.0000 1.0000
58.6000 658.0000 1.0000
58.6400 618.0000 1.0000
58.6800 589.0000 1.0000
58.7200 628.0000 1.0000
58.7600 627.0000 1.0000
58.8000 646.0000 1.0000
58.8400 627.0000 1.0000
58.8800 627.0000 1.0000
58.9200 685.0000 1.0000
58.9600 612.0000 1.0000
59.0000 641.0000 1.0000
59.0400 593.0000 1.0000
59.0800 667.0000 1.0000
59.1200 592.0000 1.0000
59.1600 601.0000 1.0000
59.2000 627.0000 1.0000
59.2400 656.0000 1.0000
59.2800 635.0000 1.0000
59.3200 692.0000 1.0000
59.3600 665.0000 1.0000
59.4000 657.0000 1.0000
59.4400 641.0000 1.0000
59.4800 642.0000 1.0000
59.5200 660.0000 1.0000
59.5600 644.0000 1.0000
59.6000 649.0000 1.0000
59.6400 638.0000 1.0000
59.6800 657.0000 1.0000
59.7200 645.0000 1.0000
59.7600 656.0000 1.0000
59.8000 609.0000 1.0000
59.8400 611.0000 1.0000
59.8800 633.0000 1.0000
59.9200 594.0000 1.0000
59.9600 660.0000 1.0000
60.0000 628.0000 1.0000
60.0400 630.0000 1.0000
60.0800 619.0000 1.0000
60.1200 663.0000 1.0000
60.1600 673.0000 1.0000
60.2000 662.0000 1.0000
60.2400 638.0000 1.0000
60.2800 630.0000 1.0000
60.3200 640.0000 1.0000
60.3600 646.0000 1.0000
60.4000 628.0000 1.0000
60.4400 648.0000 1.0000
60.4800 625.0000 1.0000
60.5200 667.0000 1.0000
60.5600 664.0000 1.0000
60.6000 645.0000 1.0000
60.6400 636.0000 1.0000
60.6800 617.0000 1.0000
60.7200 621.0000 1.0000
60.7600 634.0000 1.0000
60.8000 609.0000 1.0000
60.8400 613.0000 1.0000
60.8800 650.0000 1.0000
60.9200 659.0000 1.0000
60.9600 621.0000 1.0000
61.0000 665.0000 1.0000
61.0400 643.0000 1.0000
61.0800 607.0000 1.0000
61.1200 620.0000 1.0000
61.1600 656.0000 1.0000
61.2000 644.0000 1.0000
61.2400 583.0000 1.0000
61.2800 673.0000 1.0000
61.3200 683.0000 1.0000
61.3600 631.0000 1.0000
61.4000 639.0000 1.0000
61.4400 656.0000 1.0000
61.4800 649.0000 1.0000
61.5200 677.0000 1.0000
61.5600 649.0000 1.0000
61.6000 664.0000 1.0000
61.6400 656.0000 1.0000
61.6800 654.0000 1.0000
61.7200 678.0000 1.0000
61.7600 704.0000 1.0000
61.8000 721.0000 1.0000
61.8400 689.0000 1.0000
61.8800 785.0000 1.0000
61.9200 744.0000 1.0000
61.9600 791.0000 1.0000
62.0000 844.0000 1.0000
62.0400 888.0000 1.0000
62.0800 947.0000 1.0000
62.1200 1029.0000 1.0000
62.1600 1198.0000 1.0000
62.2000 1315.0000 1.0000
62.2400 1468.0000 1.0000
62.2800 1465.0000 1.0000
62.3200 1530.0000 1.0000
62.3600 1508.0000 1.0000
62.4000 1421.0000 1.0000
62.4400 1290.0000 1.0000
62.4800 1176.0000 1.0000
62.5200 1094.0000 1.0000
62.5600 1049.0000 1.0000
62.6000 942.0000 1.0000
62.6400 871.0000 1.0000
62.6800 847.0000 1.0000
62.7200 747.0000 1.0000
62.7600 752.0000 1.0000
62.8000 741.0000 1.0000
62.8400 707.0000 1.0000
62.8800 724.0000 1.0000
62.9200 700.0000 1.0000
62.9600 670.0000 1.0000
63.0000 700.0000 1.0000
63.0400 717.0000 1.0000
63.0800 679.0000 1.0000
63.1200 637.0000 1.0000
63.1600 707.0000 1.0000
63.2000 647.0000 1.0000
63.2400 653.0000 1.0000
63.2800 646.0000 1.0000
63.3200 643.0000 1.0000
63.3600 654.0000 1.0000
63.4000 647.0000 1.0000
63.4400 639.0000 1.0000
63.4800 625.0000 1.0000
63.5200 653.0000 1.0000
63.5600 627.0000 1.0000
63.6000 660.0000 1.0000
63.6400 617.0000 1.0000
63.6800 642.0000 1.0000
63.7200 662.0000 1.0000
63.7600 664.0000 1.0000
63.8000 656.0000 1.0000
63.8400 670.0000 1.0000
63.8800 645.0000 1.0000
63.9200 670.0000 1.0000
63.9600 671.0000 1.0000
64.0000 665.0000 1.0000
64.0400 643.0000 1.0000
64.0800 667.0000 1.0000
64.1200 671.0000 1.0000
64.1600 609.0000 1.0000
64.2000 648.0000 1.0000
64.2400 642.0000 1.0000
64.2800 663.0000 1.0000
64.3200 649.0000 1.0000
64.3600 643.0000 1.0000
64.4000 650.0000 1.0000
64.4400 670.0000 1.0000
64.4800 657.0000 1.0000
64.5200 677.0000 1.0000
64.5600 743.0000 1.0000
64.6000 691.0000 1.0000
64.6400 674.0000 1.0000
64.6800 651.0000 1.0000
64.7200 654.0000 1.0000
64.7600 670.0000 1.0000
64.8000 714.0000 1.0000
64.8400 718.0000 1.0000
64.8800 656.0000 1.0000
64.9200 688.0000 1.0000
64.9600 719.0000 1.0000
65.0000 672.0000 1.0000
65.0400 675.0000 1.0000
65.0800 710.0000 1.0000
65.1200 703.0000 1.0000
65.1600 691.0000 1.0000
65.2000 688.0000 1.0000
65.2400 687.0000 1.0000
65.2800 680.0000 1.0000
65.3200 632.0000 1.0000
65.3600 665.0000 1.0000
65.4000 651.0000 1.0000
65.4400 665.0000 1.0000
65.4800 677.0000 1.0000
65.5200 688.0000 1.0000
65.5600 704.0000 1.0000
65.6000 693.0000 1.0000
65.6400 691.0000 1.0000
65.6800 718.0000 1.0000
65.7200 748.0000 1.0000
65.7600 720.0000 1.0000
65.8000 785.0000 1.0000
65.8400 800.0000 1.0000
65.8800 849.0000 1.0000
65.9200 926.0000 1.0000
65.9600 955.0000 1.0000
66.0000 1062.0000 1.0000
66.0400 1204.0000 1.0000
66.0800 1477.0000 1.0000
66.1200 1797.0000 1.0000
66.1600 2236.0000 1.0000
66.2000 2732.0000 1.0000
66.2400 2886.0000 1.0000
66.2800 2886.0000 1.0000
66.3200 2645.0000 1.0000
66.3600 2460.0000 1.0000
66.4000 2448.0000 1.0000
66.4400 2158.0000 1.0000
66.4800 1897.0000 1.0000
66.5200 1612.0000 1.0000
66.5600 1341.0000 1.0000
66.6000 1204.0000 1.0000
66.6400 1054.0000 1.0000
66.6800 969.0000 1.0000
66.7200 879.0000 1.0000
66.7600 833.0000 1.0000
66.8000 800.0000 1.0000
66.8400 736.0000 1.0000
66.8800 714.0000 1.0000
66.9200 657.0000 1.0000
66.9600 665.0000 1.0000
67.0000 659.0000 1.0000
67.0400 670.0000 1.0000
67.0800 680.0000 1.0000
67.1200 588.0000 1.0000
67.1600 635.0000 1.0000
67.2000 633.0000 1.0000
67.2400 654.0000 1.0000
67.2800 675.0000 1.0000
67.3200 632.0000 1.0000
67.3600 610.0000 1.0000
67.4000 600.0000 1.0000
67.4400 587.0000 1.0000
67.4800 612.0000 1.0000
67.5200 595.0000 1.0000
67.5600 568.0000 1.0000
67.6000 635.0000 1.0000
67.6400 636.0000 1.0000
67.6800 620.0000 1.0000
67.7200 611.0000 1.0000
67.7600 600.0000 1.0000
67.8000 595.0000 1.0000
67.8400 593.0000 1.0000
67.8800 599.0000 1.0000
67.9200 556.0000 1.0000
67.9600 534.0000 1.0000
68.0000 578.0000 1.0000
68.0400 591.0000 1.0000
68.0800 582.0000 1.0000
68.1200 570.0000 1.0000
68.1600 575.0000 1.0000
68.2000 583.0000 1.0000
68.2400 645.0000 1.0000
68.2800 570.0000 1.0000
68.3200 583.0000 1.0000
68.3600 618.0000 1.0000
68.4000 578.0000 1.0000
68.4400 582.0000 1.0000
68.4800 568.0000 1.0000
68.5200 588.0000 1.0000
68.5600 606.0000 1.0000
68.6000 573.0000 1.0000
68.6400 587.0000 1.0000
68.6800 585.0000 1.0000
68.7200 571.0000 1.0000
68.7600 581.0000 1.0000
68.8000 573.0000 1.0000
68.8400 580.0000 1.0000
68.8800 601.0000 1.0000
68.9200 581.0000 1.0000
68.9600 577.0000 1.0000
69.0000 576.0000 1.0000
69.0400 561.0000 1.0000
69.0800 581.0000 1.0000
69.1200 576.0000 1.0000
69.1600 565.0000 1.0000
69.2000 607.0000 1.0000
69.2400 559.0000 1.0000
69.2800 623.0000 1.0000
69.3200 585.0000 1.0000
69.3600 559.0000 1.0000
69.4000 591.0000 1.0000
69.4400 551.0000 1.0000
69.4800 576.0000 1.0000
69.5200 545.0000 1.0000
69.5600 605.0000 1.0000
69.6000 536.0000 1.0000
69.6400 582.0000 1.0000
69.6800 569.0000 1.0000
69.7200 562.0000 1.0000
69.7600 619.0000 1.0000
69.8000 539.0000 1.0000
69.8400 549.0000 1.0000
69.8800 500.0000 1.0000
69.9200 581.0000 1.0000
69.9600 542.0000 1.0000
70.0000 572.0000 1.0000
*RAS_INT_END
*RAS_TEMPERATURE_START
*RAS_TEMPERATURE_END
*RAS_DATA_END