File: Section2_75_samples/XRD/No_068_VS1_1.ras
*RAS_DATA_START
*RAS_HEADER_START
*DISP_FMT_X "%.2f"
*DISP_FMT_Y "%.0f"
*DISP_FULLSCALE "15166.0000000000"
*DISP_LINE_COLOR "255.0000000000"
*DISP_LINE_STYLE "0.0000000000"
*DISP_LINE_WIDTH "0.2500000000"
*DISP_NOTE "測定データ-3"
*DISP_OFFSET_Y "0.0000000000"
*DISP_PEAKSEARCH_UNIT_Y "cps"
*DISP_RANGE_BOTTOM "0.0000000000"
*DISP_RANGE_LEFT "20.0000000000"
*DISP_RANGE_LOGCUTOFF "0.0100000000"
*DISP_RANGE_RIGHT "70.0000000000"
*DISP_RANGE_TOP "15166.0000000000"
*DISP_SCALE_MODE_Y "0.0000000000"
*DISP_TAB_NAME "2θ/θ"
*DISP_TITLE_Y "強度"
*DISP_UNIT_Y "cps"
*DISP_WINDOW_NAME "MSG_MACROENGINE"
*FILE_COMMENT " "
*FILE_MD5 ""
*FILE_MEMO " "
*FILE_OPERATOR "Administrator"
*FILE_SAMPLE " "
*FILE_TYPE "RAS_RAW"
*FILE_USERGROUP "システムマネージャ"
*FILE_VERSION "1.0000000000"
*HW_ATTACHMENT_ID "ATT0025"
*HW_ATTACHMENT_NAME "標準|Standard"
*HW_COUNTER_ID-0 "CUT0025"
*HW_COUNTER_ID-1 "CUT0020"
*HW_COUNTER_ID-2 "CUT0020"
*HW_COUNTER_ID-3 "CSL0021"
*HW_COUNTER_ID-4 "CMC0021"
*HW_COUNTER_NAME-0 "D/teX Ultra|D/teX Ultra"
*HW_COUNTER_NAME-1 "None|None"
*HW_COUNTER_NAME-2 "None|None"
*HW_COUNTER_NAME-3 "BBM|BBM"
*HW_COUNTER_NAME-4 "検出器モノクロメータ|Detector monochromator"
*HW_COUNTER_SELECT_NAME "D/teX Ultra|D/teX Ultra"
*HW_GONIOMETER_ID "GON0023"
*HW_GONIOMETER_NAME "SmartLab|SmartLab"
*HW_GONIOMETER_RADIUS-0 "90.0"
*HW_GONIOMETER_RADIUS-1 "114.0"
*HW_GONIOMETER_RADIUS-2 "190.0"
*HW_GONIOMETER_RADIUS-3 "300.0"
*HW_GONIOMETER_RADIUS-4 "187.0"
*HW_GONIOMETER_RADIUS-5 "300.0"
*HW_GONIOMETER_RADIUS-6 "113.0"
*HW_GONIOMETER_RADIUS-7 "331.0"
*HW_I_OPT_ID-0 "CBO0021"
*HW_I_OPT_ID-1 "ICR0023"
*HW_I_OPT_ID-2 "ISL0021"
*HW_I_OPT_ID-3 "ISO0021"
*HW_I_OPT_ID-4 "IAD0021"
*HW_I_OPT_ID-5 "IPR0001"
*HW_I_OPT_NAME-0 "CBOユニット|CBO unit"
*HW_I_OPT_NAME-1 "標準入射光学ユニット|Standard incident optical unit"
*HW_I_OPT_NAME-2 "標準入射スリットボックス|Standard incident slit box"
*HW_I_OPT_NAME-3 "入射平行スリット|Incident parallel slit"
*HW_I_OPT_NAME-4 "長手制限スリット|Length limiting slit"
*HW_I_OPT_NAME-5 "None|None"
*HW_R_ATTENUATER_AUTOMODE "0"
*HW_R_OPT_ID-0 "RSS0021"
*HW_R_OPT_ID-1 "RCR0023"
*HW_R_OPT_ID-2 "RSO0021"
*HW_R_OPT_ID-3 "RRS0021"
*HW_R_OPT_ID-4 "ATN0021"
*HW_R_OPT_ID-5 "RFL0021"
*HW_R_OPT_ID-6 "RAD0021"
*HW_R_OPT_NAME-0 "標準受光スリットボックス1|Standard receiving slit box # 1"
*HW_R_OPT_NAME-1 "標準受光光学ユニット1|Standard receiving unit # 1"
*HW_R_OPT_NAME-2 "標準受光光学ユニット2|Standard receiving optical unit # 2"
*HW_R_OPT_NAME-3 "標準受光スリットボックス2|Standard receiving slit box # 2"
*HW_R_OPT_NAME-4 "標準アッテネータ|Standard Attenuator"
*HW_R_OPT_NAME-5 "Cu Kβ|Cu K-beta"
*HW_R_OPT_NAME-6 "調整用受光スリット|Alignment receiving slit"
*HW_SAMPLE_HOLDER_ID "SMP0023"
*HW_SAMPLE_HOLDER_NAME "標準Zステージ|Standard Z stage"
*HW_XG_CURRENT_MAX "50"
*HW_XG_CURRENT_MIN "2"
*HW_XG_CURRENT_RESOLUTION "1"
*HW_XG_CURRENT_UNIT "mA"
*HW_XG_FOCUS "1mm x 10mm"
*HW_XG_FOCUS_TYPE "Normal"
*HW_XG_ID ""
*HW_XG_NAME "3kW 封入管(ID:1200)|3kW Sealed tube(ID:1200)"
*HW_XG_TARGET_ATOMIC_NUMBER "29.0000000000"
*HW_XG_TARGET_NAME "Cu"
*HW_XG_TYPE "Hermetic"
*HW_XG_VOLTAGE_MAX "60"
*HW_XG_VOLTAGE_MIN "20"
*HW_XG_VOLTAGE_RESOLUTION "1"
*HW_XG_VOLTAGE_UNIT "kV"
*HW_XG_WATT_MAX "1.500"
*HW_XG_WATT_UNIT "kW"
*HW_XG_WAVE_LENGTH_ALPHA1 "1.540593"
*HW_XG_WAVE_LENGTH_ALPHA2 "1.544414"
*HW_XG_WAVE_LENGTH_BETA "1.392250"
*MEAS_COND_AXIS_NAME-0 "2θ/θ"
*MEAS_COND_AXIS_NAME-1 "2θ"
*MEAS_COND_AXIS_NAME-2 "ω"
*MEAS_COND_AXIS_NAME-3 "Z"
*MEAS_COND_AXIS_NAME-4 "2θ/ω"
*MEAS_COND_AXIS_NAME-5 "θs"
*MEAS_COND_AXIS_NAME-6 "θd"
*MEAS_COND_AXIS_NAME-7 "Ts"
*MEAS_COND_AXIS_NAME-8 "CBO選択スリット"
*MEAS_COND_AXIS_NAME-9 "M"
*MEAS_COND_AXIS_NAME-10 "入射平行スリット"
*MEAS_COND_AXIS_NAME-11 "入射スリット"
*MEAS_COND_AXIS_NAME-12 ""
*MEAS_COND_AXIS_NAME-13 "Zs"
*MEAS_COND_AXIS_NAME-14 "入射光学素子"
*MEAS_COND_AXIS_NAME-15 "長手制限スリット"
*MEAS_COND_AXIS_NAME-16 "センタースリット"
*MEAS_COND_AXIS_NAME-17 "フィルター"
*MEAS_COND_AXIS_NAME-18 "受光スリット1"
*MEAS_COND_AXIS_NAME-19 "受光スリット2"
*MEAS_COND_AXIS_NAME-20 "受光光学素子"
*MEAS_COND_AXIS_NAME-21 "受光平行スリット"
*MEAS_COND_AXIS_NAME-22 "調整用受光スリット"
*MEAS_COND_AXIS_NAME-23 ""
*MEAS_COND_AXIS_NAME-24 ""
*MEAS_COND_AXIS_NAME-25 "Zd"
*MEAS_COND_AXIS_NAME-26 "アッテネータ"
*MEAS_COND_AXIS_NAME-27 "検出器モノクロメータ"
*MEAS_COND_AXIS_NAME-28 "モノクロメータスリット"
*MEAS_COND_AXIS_NAME-29 "プライマリビーム"
*MEAS_COND_AXIS_NAME-30 "PHA"
*MEAS_COND_AXIS_NAME_INTERNAL-0 "TwoThetaTheta"
*MEAS_COND_AXIS_NAME_INTERNAL-1 "TwoTheta"
*MEAS_COND_AXIS_NAME_INTERNAL-2 "Omega"
*MEAS_COND_AXIS_NAME_INTERNAL-3 "Z"
*MEAS_COND_AXIS_NAME_INTERNAL-4 "TwoThetaOmega"
*MEAS_COND_AXIS_NAME_INTERNAL-5 "ThetaS"
*MEAS_COND_AXIS_NAME_INTERNAL-6 "ThetaD"
*MEAS_COND_AXIS_NAME_INTERNAL-7 "Ts"
*MEAS_COND_AXIS_NAME_INTERNAL-8 "CBO"
*MEAS_COND_AXIS_NAME_INTERNAL-9 "CBO-M"
*MEAS_COND_AXIS_NAME_INTERNAL-10 "IncidentSollerSlit"
*MEAS_COND_AXIS_NAME_INTERNAL-11 "IncidentSlitBox"
*MEAS_COND_AXIS_NAME_INTERNAL-12 "IncidentSlitBox-_Axis"
*MEAS_COND_AXIS_NAME_INTERNAL-13 "Zs"
*MEAS_COND_AXIS_NAME_INTERNAL-14 "IncidentMonochromator"
*MEAS_COND_AXIS_NAME_INTERNAL-15 "IncidentAxdSlit"
*MEAS_COND_AXIS_NAME_INTERNAL-16 "CenterSlit"
*MEAS_COND_AXIS_NAME_INTERNAL-17 "Filter"
*MEAS_COND_AXIS_NAME_INTERNAL-18 "ReceivingSlitBox1"
*MEAS_COND_AXIS_NAME_INTERNAL-19 "ReceivingSlitBox2"
*MEAS_COND_AXIS_NAME_INTERNAL-20 "ReceivingOptics"
*MEAS_COND_AXIS_NAME_INTERNAL-21 "ReceivingSollerSlit"
*MEAS_COND_AXIS_NAME_INTERNAL-22 "ReceivingAxdSlit"
*MEAS_COND_AXIS_NAME_INTERNAL-23 "ReceivingSlitBox1-_Axis"
*MEAS_COND_AXIS_NAME_INTERNAL-24 "ReceivingSlitBox2-_Axis"
*MEAS_COND_AXIS_NAME_INTERNAL-25 "ReceivingSlitBox2-Zd"
*MEAS_COND_AXIS_NAME_INTERNAL-26 "Attenuator"
*MEAS_COND_AXIS_NAME_INTERNAL-27 "CounterMonochromator"
*MEAS_COND_AXIS_NAME_INTERNAL-28 "CounterSlit"
*MEAS_COND_AXIS_NAME_INTERNAL-29 "IncidentPrimary"
*MEAS_COND_AXIS_NAME_INTERNAL-30 "PHA"
*MEAS_COND_AXIS_NAME_MAGICNO-0 "83951616.0000000000"
*MEAS_COND_AXIS_NAME_MAGICNO-1 "268632064.0000000000"
*MEAS_COND_AXIS_NAME_MAGICNO-2 "268500992.0000000000"
*MEAS_COND_AXIS_NAME_MAGICNO-3 "285278208.0000000000"
*MEAS_COND_AXIS_NAME_MAGICNO-4 "83951616.0000000000"
*MEAS_COND_AXIS_NAME_MAGICNO-5 "131072.0000000000"
*MEAS_COND_AXIS_NAME_MAGICNO-6 "131072.0000000000"
*MEAS_COND_AXIS_NAME_MAGICNO-7 "318898176.0000000000"
*MEAS_COND_AXIS_NAME_MAGICNO-8 "20971521.0000000000"
*MEAS_COND_AXIS_NAME_MAGICNO-9 "285343744.0000000000"
*MEAS_COND_AXIS_NAME_MAGICNO-10 "20971521.0000000000"
*MEAS_COND_AXIS_NAME_MAGICNO-11 "22020097.0000000000"
*MEAS_COND_AXIS_NAME_MAGICNO-12 "25165824.0000000000"
*MEAS_COND_AXIS_NAME_MAGICNO-13 "318898176.0000000000"
*MEAS_COND_AXIS_NAME_MAGICNO-14 "1.0000000000"
*MEAS_COND_AXIS_NAME_MAGICNO-15 "20971521.0000000000"
*MEAS_COND_AXIS_NAME_MAGICNO-16 "20971521.0000000000"
*MEAS_COND_AXIS_NAME_MAGICNO-17 "20971521.0000000000"
*MEAS_COND_AXIS_NAME_MAGICNO-18 "23068673.0000000000"
*MEAS_COND_AXIS_NAME_MAGICNO-19 "23068673.0000000000"
*MEAS_COND_AXIS_NAME_MAGICNO-20 "20971521.0000000000"
*MEAS_COND_AXIS_NAME_MAGICNO-21 "20971521.0000000000"
*MEAS_COND_AXIS_NAME_MAGICNO-22 "20971521.0000000000"
*MEAS_COND_AXIS_NAME_MAGICNO-23 "25165824.0000000000"
*MEAS_COND_AXIS_NAME_MAGICNO-24 "25165824.0000000000"
*MEAS_COND_AXIS_NAME_MAGICNO-25 "285343744.0000000000"
*MEAS_COND_AXIS_NAME_MAGICNO-26 "17301505.0000000000"
*MEAS_COND_AXIS_NAME_MAGICNO-27 "20971521.0000000000"
*MEAS_COND_AXIS_NAME_MAGICNO-28 "20971521.0000000000"
*MEAS_COND_AXIS_NAME_MAGICNO-29 "20971521.0000000000"
*MEAS_COND_AXIS_NAME_MAGICNO-30 "0.0000000000"
*MEAS_COND_AXIS_OFFSET-0 "-"
*MEAS_COND_AXIS_OFFSET-1 "-0.1081000000"
*MEAS_COND_AXIS_OFFSET-2 "0.3758000000"
*MEAS_COND_AXIS_OFFSET-3 "-"
*MEAS_COND_AXIS_OFFSET-4 "-"
*MEAS_COND_AXIS_OFFSET-5 "0.3758000000"
*MEAS_COND_AXIS_OFFSET-6 "-0.4839000000"
*MEAS_COND_AXIS_OFFSET-7 "-"
*MEAS_COND_AXIS_OFFSET-8 "-"
*MEAS_COND_AXIS_OFFSET-9 "-"
*MEAS_COND_AXIS_OFFSET-10 "-"
*MEAS_COND_AXIS_OFFSET-11 "-"
*MEAS_COND_AXIS_OFFSET-12 "-"
*MEAS_COND_AXIS_OFFSET-13 "-"
*MEAS_COND_AXIS_OFFSET-14 "-"
*MEAS_COND_AXIS_OFFSET-15 "-"
*MEAS_COND_AXIS_OFFSET-16 "-"
*MEAS_COND_AXIS_OFFSET-17 "-"
*MEAS_COND_AXIS_OFFSET-18 "-"
*MEAS_COND_AXIS_OFFSET-19 "-"
*MEAS_COND_AXIS_OFFSET-20 "-"
*MEAS_COND_AXIS_OFFSET-21 "-"
*MEAS_COND_AXIS_OFFSET-22 "-"
*MEAS_COND_AXIS_OFFSET-23 "-"
*MEAS_COND_AXIS_OFFSET-24 "-"
*MEAS_COND_AXIS_OFFSET-25 "-"
*MEAS_COND_AXIS_OFFSET-26 "-"
*MEAS_COND_AXIS_OFFSET-27 "-"
*MEAS_COND_AXIS_OFFSET-28 "-"
*MEAS_COND_AXIS_OFFSET-29 "-"
*MEAS_COND_AXIS_OFFSET-30 "-"
*MEAS_COND_AXIS_POSITION-0 "0.0000000000"
*MEAS_COND_AXIS_POSITION-1 "0.0000000000"
*MEAS_COND_AXIS_POSITION-2 "0.0000000000"
*MEAS_COND_AXIS_POSITION-3 "-0.5500000000"
*MEAS_COND_AXIS_POSITION-4 "0.0000000000"
*MEAS_COND_AXIS_POSITION-5 "0.0000000000"
*MEAS_COND_AXIS_POSITION-6 "0.0000000000"
*MEAS_COND_AXIS_POSITION-7 "-0.4278800000"
*MEAS_COND_AXIS_POSITION-8 "BB"
*MEAS_COND_AXIS_POSITION-9 "0.0000000000"
*MEAS_COND_AXIS_POSITION-10 "Soller_slit_5.0deg"
*MEAS_COND_AXIS_POSITION-11 "2/3deg"
*MEAS_COND_AXIS_POSITION-12 "2.2088000000"
*MEAS_COND_AXIS_POSITION-13 "-0.4140600000"
*MEAS_COND_AXIS_POSITION-14 "0.0000000000"
*MEAS_COND_AXIS_POSITION-15 "10.0mm"
*MEAS_COND_AXIS_POSITION-16 "None"
*MEAS_COND_AXIS_POSITION-17 "Cu_K-beta"
*MEAS_COND_AXIS_POSITION-18 "10.036mm"
*MEAS_COND_AXIS_POSITION-19 "13.000mm"
*MEAS_COND_AXIS_POSITION-20 "No_unit"
*MEAS_COND_AXIS_POSITION-21 "Soller_slit_5.0deg"
*MEAS_COND_AXIS_POSITION-22 "None"
*MEAS_COND_AXIS_POSITION-23 "10.0363000000"
*MEAS_COND_AXIS_POSITION-24 "13.0000000000"
*MEAS_COND_AXIS_POSITION-25 "0.0109400000"
*MEAS_COND_AXIS_POSITION-26 "Open"
*MEAS_COND_AXIS_POSITION-27 "None"
*MEAS_COND_AXIS_POSITION-28 "None"
*MEAS_COND_AXIS_POSITION-29 "None"
*MEAS_COND_AXIS_POSITION-30 "38.0000000000"
*MEAS_COND_AXIS_UNIT-0 "deg"
*MEAS_COND_AXIS_UNIT-1 "deg"
*MEAS_COND_AXIS_UNIT-2 "deg"
*MEAS_COND_AXIS_UNIT-3 "mm"
*MEAS_COND_AXIS_UNIT-4 "deg"
*MEAS_COND_AXIS_UNIT-5 "deg"
*MEAS_COND_AXIS_UNIT-6 "deg"
*MEAS_COND_AXIS_UNIT-7 "mm"
*MEAS_COND_AXIS_UNIT-8 ""
*MEAS_COND_AXIS_UNIT-9 "pulse"
*MEAS_COND_AXIS_UNIT-10 ""
*MEAS_COND_AXIS_UNIT-11 ""
*MEAS_COND_AXIS_UNIT-12 "mm"
*MEAS_COND_AXIS_UNIT-13 "mm"
*MEAS_COND_AXIS_UNIT-14 ""
*MEAS_COND_AXIS_UNIT-15 ""
*MEAS_COND_AXIS_UNIT-16 ""
*MEAS_COND_AXIS_UNIT-17 ""
*MEAS_COND_AXIS_UNIT-18 ""
*MEAS_COND_AXIS_UNIT-19 ""
*MEAS_COND_AXIS_UNIT-20 ""
*MEAS_COND_AXIS_UNIT-21 ""
*MEAS_COND_AXIS_UNIT-22 ""
*MEAS_COND_AXIS_UNIT-23 "mm"
*MEAS_COND_AXIS_UNIT-24 "mm"
*MEAS_COND_AXIS_UNIT-25 "mm"
*MEAS_COND_AXIS_UNIT-26 ""
*MEAS_COND_AXIS_UNIT-27 ""
*MEAS_COND_AXIS_UNIT-28 ""
*MEAS_COND_AXIS_UNIT-29 ""
*MEAS_COND_AXIS_UNIT-30 "div"
*MEAS_COND_COUNTER_CNTLOSS_CORR "0.0000000000"
*MEAS_COND_COUNTER_PHABASE "38.0000000000"
*MEAS_COND_COUNTER_PHAWINDOW "16.0000000000"
*MEAS_COND_COUNTER_PHA_UNIT "div"
*MEAS_COND_COUNTER_TAUDIFF "30.0000000000"
*MEAS_COND_COUNTER_TAUINT "0.0000000000"
*MEAS_COND_IRRADIATION_MODE "OFF"
*MEAS_COND_IRRADIATION_WIDTH ""
*MEAS_COND_OPT_ATTR "集中法"
*MEAS_COND_OPT_NAME "@集中法"
*MEAS_COND_UNSYMMETRIC_MODE "OFF"
*MEAS_COND_XG_CURRENT "30.0000000000"
*MEAS_COND_XG_VOLTAGE "40.0000000000"
*MEAS_COND_XG_WAVE_TYPE "Ka"
*MEAS_DATA_COUNT "5001.0000000000"
*MEAS_SCAN_AXIS_X "2θ/θ"
*MEAS_SCAN_AXIS_X_INTERNAL "TwoThetaTheta"
*MEAS_SCAN_END_TIME "07/15/21 13:37:19"
*MEAS_SCAN_MODE "CONTINUOUS"
*MEAS_SCAN_MONITOR "0"
*MEAS_SCAN_RESOLUTION_X "0.0002"
*MEAS_SCAN_SPEED "1.0"
*MEAS_SCAN_SPEED_UNIT "deg/min"
*MEAS_SCAN_START "20.0000000000"
*MEAS_SCAN_START_TIME "07/15/21 12:44:26"
*MEAS_SCAN_STEP "0.0100000000"
*MEAS_SCAN_STOP "70.0000000000"
*MEAS_SCAN_UNIT_X "deg"
*MEAS_SCAN_UNIT_Y "counts"
*RAS_HEADER_END
*RAS_INT_START
20.0000 1326.0000 1.0000
20.0400 1275.0000 1.0000
20.0800 1305.0000 1.0000
20.1200 1290.0000 1.0000
20.1600 1331.0000 1.0000
20.2000 1244.0000 1.0000
20.2400 1256.0000 1.0000
20.2800 1304.0000 1.0000
20.3200 1252.0000 1.0000
20.3600 1260.0000 1.0000
20.4000 1242.0000 1.0000
20.4400 1219.0000 1.0000
20.4800 1228.0000 1.0000
20.5200 1280.0000 1.0000
20.5600 1223.0000 1.0000
20.6000 1267.0000 1.0000
20.6400 1286.0000 1.0000
20.6800 1310.0000 1.0000
20.7200 1263.0000 1.0000
20.7600 1253.0000 1.0000
20.8000 1279.0000 1.0000
20.8400 1292.0000 1.0000
20.8800 1241.0000 1.0000
20.9200 1224.0000 1.0000
20.9600 1307.0000 1.0000
21.0000 1255.0000 1.0000
21.0400 1237.0000 1.0000
21.0800 1291.0000 1.0000
21.1200 1272.0000 1.0000
21.1600 1298.0000 1.0000
21.2000 1293.0000 1.0000
21.2400 1388.0000 1.0000
21.2800 1228.0000 1.0000
21.3200 1323.0000 1.0000
21.3600 1264.0000 1.0000
21.4000 1365.0000 1.0000
21.4400 1258.0000 1.0000
21.4800 1302.0000 1.0000
21.5200 1253.0000 1.0000
21.5600 1351.0000 1.0000
21.6000 1354.0000 1.0000
21.6400 1362.0000 1.0000
21.6800 1290.0000 1.0000
21.7200 1295.0000 1.0000
21.7600 1324.0000 1.0000
21.8000 1344.0000 1.0000
21.8400 1416.0000 1.0000
21.8800 1345.0000 1.0000
21.9200 1307.0000 1.0000
21.9600 1328.0000 1.0000
22.0000 1320.0000 1.0000
22.0400 1303.0000 1.0000
22.0800 1264.0000 1.0000
22.1200 1310.0000 1.0000
22.1600 1326.0000 1.0000
22.2000 1366.0000 1.0000
22.2400 1339.0000 1.0000
22.2800 1311.0000 1.0000
22.3200 1328.0000 1.0000
22.3600 1291.0000 1.0000
22.4000 1276.0000 1.0000
22.4400 1349.0000 1.0000
22.4800 1292.0000 1.0000
22.5200 1314.0000 1.0000
22.5600 1312.0000 1.0000
22.6000 1338.0000 1.0000
22.6400 1371.0000 1.0000
22.6800 1323.0000 1.0000
22.7200 1318.0000 1.0000
22.7600 1347.0000 1.0000
22.8000 1372.0000 1.0000
22.8400 1311.0000 1.0000
22.8800 1378.0000 1.0000
22.9200 1309.0000 1.0000
22.9600 1382.0000 1.0000
23.0000 1361.0000 1.0000
23.0400 1378.0000 1.0000
23.0800 1381.0000 1.0000
23.1200 1348.0000 1.0000
23.1600 1294.0000 1.0000
23.2000 1364.0000 1.0000
23.2400 1362.0000 1.0000
23.2800 1366.0000 1.0000
23.3200 1337.0000 1.0000
23.3600 1298.0000 1.0000
23.4000 1346.0000 1.0000
23.4400 1370.0000 1.0000
23.4800 1423.0000 1.0000
23.5200 1357.0000 1.0000
23.5600 1373.0000 1.0000
23.6000 1349.0000 1.0000
23.6400 1369.0000 1.0000
23.6800 1353.0000 1.0000
23.7200 1357.0000 1.0000
23.7600 1362.0000 1.0000
23.8000 1357.0000 1.0000
23.8400 1385.0000 1.0000
23.8800 1388.0000 1.0000
23.9200 1408.0000 1.0000
23.9600 1400.0000 1.0000
24.0000 1379.0000 1.0000
24.0400 1371.0000 1.0000
24.0800 1367.0000 1.0000
24.1200 1390.0000 1.0000
24.1600 1382.0000 1.0000
24.2000 1389.0000 1.0000
24.2400 1407.0000 1.0000
24.2800 1366.0000 1.0000
24.3200 1410.0000 1.0000
24.3600 1453.0000 1.0000
24.4000 1359.0000 1.0000
24.4400 1406.0000 1.0000
24.4800 1472.0000 1.0000
24.5200 1422.0000 1.0000
24.5600 1439.0000 1.0000
24.6000 1475.0000 1.0000
24.6400 1406.0000 1.0000
24.6800 1464.0000 1.0000
24.7200 1436.0000 1.0000
24.7600 1439.0000 1.0000
24.8000 1430.0000 1.0000
24.8400 1454.0000 1.0000
24.8800 1458.0000 1.0000
24.9200 1427.0000 1.0000
24.9600 1434.0000 1.0000
25.0000 1430.0000 1.0000
25.0400 1510.0000 1.0000
25.0800 1503.0000 1.0000
25.1200 1499.0000 1.0000
25.1600 1447.0000 1.0000
25.2000 1422.0000 1.0000
25.2400 1469.0000 1.0000
25.2800 1444.0000 1.0000
25.3200 1417.0000 1.0000
25.3600 1477.0000 1.0000
25.4000 1437.0000 1.0000
25.4400 1376.0000 1.0000
25.4800 1417.0000 1.0000
25.5200 1460.0000 1.0000
25.5600 1457.0000 1.0000
25.6000 1370.0000 1.0000
25.6400 1465.0000 1.0000
25.6800 1404.0000 1.0000
25.7200 1493.0000 1.0000
25.7600 1396.0000 1.0000
25.8000 1485.0000 1.0000
25.8400 1449.0000 1.0000
25.8800 1460.0000 1.0000
25.9200 1471.0000 1.0000
25.9600 1468.0000 1.0000
26.0000 1425.0000 1.0000
26.0400 1424.0000 1.0000
26.0800 1458.0000 1.0000
26.1200 1434.0000 1.0000
26.1600 1434.0000 1.0000
26.2000 1469.0000 1.0000
26.2400 1551.0000 1.0000
26.2800 1469.0000 1.0000
26.3200 1522.0000 1.0000
26.3600 1573.0000 1.0000
26.4000 1505.0000 1.0000
26.4400 1536.0000 1.0000
26.4800 1482.0000 1.0000
26.5200 1525.0000 1.0000
26.5600 1565.0000 1.0000
26.6000 1543.0000 1.0000
26.6400 1506.0000 1.0000
26.6800 1592.0000 1.0000
26.7200 1596.0000 1.0000
26.7600 1673.0000 1.0000
26.8000 1631.0000 1.0000
26.8400 1704.0000 1.0000
26.8800 1753.0000 1.0000
26.9200 1898.0000 1.0000
26.9600 1920.0000 1.0000
27.0000 2152.0000 1.0000
27.0400 2363.0000 1.0000
27.0800 2698.0000 1.0000
27.1200 3073.0000 1.0000
27.1600 3802.0000 1.0000
27.2000 4731.0000 1.0000
27.2400 5835.0000 1.0000
27.2800 6511.0000 1.0000
27.3200 6021.0000 1.0000
27.3600 5243.0000 1.0000
27.4000 4169.0000 1.0000
27.4400 3368.0000 1.0000
27.4800 2886.0000 1.0000
27.5200 2447.0000 1.0000
27.5600 2235.0000 1.0000
27.6000 2065.0000 1.0000
27.6400 1943.0000 1.0000
27.6800 1856.0000 1.0000
27.7200 1735.0000 1.0000
27.7600 1686.0000 1.0000
27.8000 1609.0000 1.0000
27.8400 1598.0000 1.0000
27.8800 1613.0000 1.0000
27.9200 1630.0000 1.0000
27.9600 1522.0000 1.0000
28.0000 1625.0000 1.0000
28.0400 1535.0000 1.0000
28.0800 1551.0000 1.0000
28.1200 1477.0000 1.0000
28.1600 1530.0000 1.0000
28.2000 1457.0000 1.0000
28.2400 1465.0000 1.0000
28.2800 1511.0000 1.0000
28.3200 1492.0000 1.0000
28.3600 1538.0000 1.0000
28.4000 1461.0000 1.0000
28.4400 1511.0000 1.0000
28.4800 1443.0000 1.0000
28.5200 1405.0000 1.0000
28.5600 1436.0000 1.0000
28.6000 1386.0000 1.0000
28.6400 1502.0000 1.0000
28.6800 1436.0000 1.0000
28.7200 1450.0000 1.0000
28.7600 1402.0000 1.0000
28.8000 1426.0000 1.0000
28.8400 1440.0000 1.0000
28.8800 1376.0000 1.0000
28.9200 1436.0000 1.0000
28.9600 1407.0000 1.0000
29.0000 1467.0000 1.0000
29.0400 1439.0000 1.0000
29.0800 1396.0000 1.0000
29.1200 1337.0000 1.0000
29.1600 1375.0000 1.0000
29.2000 1369.0000 1.0000
29.2400 1300.0000 1.0000
29.2800 1346.0000 1.0000
29.3200 1377.0000 1.0000
29.3600 1312.0000 1.0000
29.4000 1367.0000 1.0000
29.4400 1421.0000 1.0000
29.4800 1408.0000 1.0000
29.5200 1371.0000 1.0000
29.5600 1387.0000 1.0000
29.6000 1417.0000 1.0000
29.6400 1361.0000 1.0000
29.6800 1352.0000 1.0000
29.7200 1395.0000 1.0000
29.7600 1366.0000 1.0000
29.8000 1370.0000 1.0000
29.8400 1341.0000 1.0000
29.8800 1417.0000 1.0000
29.9200 1368.0000 1.0000
29.9600 1387.0000 1.0000
30.0000 1331.0000 1.0000
30.0400 1355.0000 1.0000
30.0800 1394.0000 1.0000
30.1200 1303.0000 1.0000
30.1600 1325.0000 1.0000
30.2000 1342.0000 1.0000
30.2400 1412.0000 1.0000
30.2800 1261.0000 1.0000
30.3200 1337.0000 1.0000
30.3600 1394.0000 1.0000
30.4000 1326.0000 1.0000
30.4400 1301.0000 1.0000
30.4800 1286.0000 1.0000
30.5200 1301.0000 1.0000
30.5600 1284.0000 1.0000
30.6000 1316.0000 1.0000
30.6400 1285.0000 1.0000
30.6800 1254.0000 1.0000
30.7200 1295.0000 1.0000
30.7600 1267.0000 1.0000
30.8000 1316.0000 1.0000
30.8400 1315.0000 1.0000
30.8800 1314.0000 1.0000
30.9200 1283.0000 1.0000
30.9600 1313.0000 1.0000
31.0000 1287.0000 1.0000
31.0400 1264.0000 1.0000
31.0800 1336.0000 1.0000
31.1200 1295.0000 1.0000
31.1600 1370.0000 1.0000
31.2000 1240.0000 1.0000
31.2400 1280.0000 1.0000
31.2800 1310.0000 1.0000
31.3200 1299.0000 1.0000
31.3600 1271.0000 1.0000
31.4000 1284.0000 1.0000
31.4400 1294.0000 1.0000
31.4800 1215.0000 1.0000
31.5200 1276.0000 1.0000
31.5600 1263.0000 1.0000
31.6000 1307.0000 1.0000
31.6400 1296.0000 1.0000
31.6800 1232.0000 1.0000
31.7200 1286.0000 1.0000
31.7600 1314.0000 1.0000
31.8000 1305.0000 1.0000
31.8400 1364.0000 1.0000
31.8800 1285.0000 1.0000
31.9200 1297.0000 1.0000
31.9600 1400.0000 1.0000
32.0000 1337.0000 1.0000
32.0400 1285.0000 1.0000
32.0800 1300.0000 1.0000
32.1200 1297.0000 1.0000
32.1600 1260.0000 1.0000
32.2000 1276.0000 1.0000
32.2400 1267.0000 1.0000
32.2800 1255.0000 1.0000
32.3200 1233.0000 1.0000
32.3600 1246.0000 1.0000
32.4000 1262.0000 1.0000
32.4400 1215.0000 1.0000
32.4800 1297.0000 1.0000
32.5200 1243.0000 1.0000
32.5600 1284.0000 1.0000
32.6000 1241.0000 1.0000
32.6400 1275.0000 1.0000
32.6800 1230.0000 1.0000
32.7200 1255.0000 1.0000
32.7600 1243.0000 1.0000
32.8000 1210.0000 1.0000
32.8400 1232.0000 1.0000
32.8800 1190.0000 1.0000
32.9200 1249.0000 1.0000
32.9600 1227.0000 1.0000
33.0000 1224.0000 1.0000
33.0400 1227.0000 1.0000
33.0800 1223.0000 1.0000
33.1200 1223.0000 1.0000
33.1600 1233.0000 1.0000
33.2000 1195.0000 1.0000
33.2400 1218.0000 1.0000
33.2800 1251.0000 1.0000
33.3200 1207.0000 1.0000
33.3600 1221.0000 1.0000
33.4000 1183.0000 1.0000
33.4400 1248.0000 1.0000
33.4800 1174.0000 1.0000
33.5200 1191.0000 1.0000
33.5600 1279.0000 1.0000
33.6000 1220.0000 1.0000
33.6400 1240.0000 1.0000
33.6800 1232.0000 1.0000
33.7200 1335.0000 1.0000
33.7600 1205.0000 1.0000
33.8000 1320.0000 1.0000
33.8400 1333.0000 1.0000
33.8800 1302.0000 1.0000
33.9200 1365.0000 1.0000
33.9600 1325.0000 1.0000
34.0000 1362.0000 1.0000
34.0400 1352.0000 1.0000
34.0800 1415.0000 1.0000
34.1200 1356.0000 1.0000
34.1600 1443.0000 1.0000
34.2000 1563.0000 1.0000
34.2400 1563.0000 1.0000
34.2800 1726.0000 1.0000
34.3200 1783.0000 1.0000
34.3600 2085.0000 1.0000
34.4000 2449.0000 1.0000
34.4400 2806.0000 1.0000
34.4800 2939.0000 1.0000
34.5200 2713.0000 1.0000
34.5600 2433.0000 1.0000
34.6000 2071.0000 1.0000
34.6400 1854.0000 1.0000
34.6800 1760.0000 1.0000
34.7200 1572.0000 1.0000
34.7600 1435.0000 1.0000
34.8000 1382.0000 1.0000
34.8400 1360.0000 1.0000
34.8800 1262.0000 1.0000
34.9200 1263.0000 1.0000
34.9600 1237.0000 1.0000
35.0000 1163.0000 1.0000
35.0400 1159.0000 1.0000
35.0800 1196.0000 1.0000
35.1200 1139.0000 1.0000
35.1600 1148.0000 1.0000
35.2000 1155.0000 1.0000
35.2400 1061.0000 1.0000
35.2800 1062.0000 1.0000
35.3200 1170.0000 1.0000
35.3600 1081.0000 1.0000
35.4000 1097.0000 1.0000
35.4400 1077.0000 1.0000
35.4800 1056.0000 1.0000
35.5200 1094.0000 1.0000
35.5600 1028.0000 1.0000
35.6000 1094.0000 1.0000
35.6400 1042.0000 1.0000
35.6800 1024.0000 1.0000
35.7200 1005.0000 1.0000
35.7600 1063.0000 1.0000
35.8000 1061.0000 1.0000
35.8400 1074.0000 1.0000
35.8800 1028.0000 1.0000
35.9200 1031.0000 1.0000
35.9600 1092.0000 1.0000
36.0000 1044.0000 1.0000
36.0400 1093.0000 1.0000
36.0800 1131.0000 1.0000
36.1200 1084.0000 1.0000
36.1600 1123.0000 1.0000
36.2000 1142.0000 1.0000
36.2400 1226.0000 1.0000
36.2800 1282.0000 1.0000
36.3200 1333.0000 1.0000
36.3600 1353.0000 1.0000
36.4000 1362.0000 1.0000
36.4400 1352.0000 1.0000
36.4800 1334.0000 1.0000
36.5200 1251.0000 1.0000
36.5600 1185.0000 1.0000
36.6000 1190.0000 1.0000
36.6400 1118.0000 1.0000
36.6800 1054.0000 1.0000
36.7200 1039.0000 1.0000
36.7600 1062.0000 1.0000
36.8000 1047.0000 1.0000
36.8400 983.0000 1.0000
36.8800 966.0000 1.0000
36.9200 999.0000 1.0000
36.9600 1016.0000 1.0000
37.0000 961.0000 1.0000
37.0400 984.0000 1.0000
37.0800 956.0000 1.0000
37.1200 936.0000 1.0000
37.1600 971.0000 1.0000
37.2000 909.0000 1.0000
37.2400 954.0000 1.0000
37.2800 979.0000 1.0000
37.3200 967.0000 1.0000
37.3600 993.0000 1.0000
37.4000 920.0000 1.0000
37.4400 972.0000 1.0000
37.4800 974.0000 1.0000
37.5200 939.0000 1.0000
37.5600 964.0000 1.0000
37.6000 963.0000 1.0000
37.6400 931.0000 1.0000
37.6800 954.0000 1.0000
37.7200 960.0000 1.0000
37.7600 1021.0000 1.0000
37.8000 918.0000 1.0000
37.8400 951.0000 1.0000
37.8800 971.0000 1.0000
37.9200 1010.0000 1.0000
37.9600 1044.0000 1.0000
38.0000 1058.0000 1.0000
38.0400 1113.0000 1.0000
38.0800 1107.0000 1.0000
38.1200 1222.0000 1.0000
38.1600 1305.0000 1.0000
38.2000 1510.0000 1.0000
38.2400 1745.0000 1.0000
38.2800 2057.0000 1.0000
38.3200 2521.0000 1.0000
38.3600 3201.0000 1.0000
38.4000 4225.0000 1.0000
38.4400 5580.0000 1.0000
38.4800 7032.0000 1.0000
38.5200 7583.0000 1.0000
38.5600 6960.0000 1.0000
38.6000 6033.0000 1.0000
38.6400 4856.0000 1.0000
38.6800 3660.0000 1.0000
38.7200 2849.0000 1.0000
38.7600 2266.0000 1.0000
38.8000 1769.0000 1.0000
38.8400 1525.0000 1.0000
38.8800 1350.0000 1.0000
38.9200 1196.0000 1.0000
38.9600 1063.0000 1.0000
39.0000 1021.0000 1.0000
39.0400 978.0000 1.0000
39.0800 979.0000 1.0000
39.1200 932.0000 1.0000
39.1600 926.0000 1.0000
39.2000 919.0000 1.0000
39.2400 876.0000 1.0000
39.2800 925.0000 1.0000
39.3200 943.0000 1.0000
39.3600 902.0000 1.0000
39.4000 926.0000 1.0000
39.4400 890.0000 1.0000
39.4800 919.0000 1.0000
39.5200 942.0000 1.0000
39.5600 936.0000 1.0000
39.6000 877.0000 1.0000
39.6400 865.0000 1.0000
39.6800 900.0000 1.0000
39.7200 856.0000 1.0000
39.7600 860.0000 1.0000
39.8000 859.0000 1.0000
39.8400 841.0000 1.0000
39.8800 780.0000 1.0000
39.9200 838.0000 1.0000
39.9600 799.0000 1.0000
40.0000 833.0000 1.0000
40.0400 801.0000 1.0000
40.0800 800.0000 1.0000
40.1200 786.0000 1.0000
40.1600 817.0000 1.0000
40.2000 788.0000 1.0000
40.2400 839.0000 1.0000
40.2800 803.0000 1.0000
40.3200 811.0000 1.0000
40.3600 785.0000 1.0000
40.4000 806.0000 1.0000
40.4400 788.0000 1.0000
40.4800 787.0000 1.0000
40.5200 808.0000 1.0000
40.5600 776.0000 1.0000
40.6000 792.0000 1.0000
40.6400 800.0000 1.0000
40.6800 778.0000 1.0000
40.7200 821.0000 1.0000
40.7600 767.0000 1.0000
40.8000 762.0000 1.0000
40.8400 804.0000 1.0000
40.8800 759.0000 1.0000
40.9200 812.0000 1.0000
40.9600 810.0000 1.0000
41.0000 815.0000 1.0000
41.0400 747.0000 1.0000
41.0800 769.0000 1.0000
41.1200 806.0000 1.0000
41.1600 811.0000 1.0000
41.2000 789.0000 1.0000
41.2400 814.0000 1.0000
41.2800 784.0000 1.0000
41.3200 817.0000 1.0000
41.3600 806.0000 1.0000
41.4000 779.0000 1.0000
41.4400 733.0000 1.0000
41.4800 762.0000 1.0000
41.5200 772.0000 1.0000
41.5600 811.0000 1.0000
41.6000 782.0000 1.0000
41.6400 790.0000 1.0000
41.6800 791.0000 1.0000
41.7200 801.0000 1.0000
41.7600 838.0000 1.0000
41.8000 769.0000 1.0000
41.8400 791.0000 1.0000
41.8800 799.0000 1.0000
41.9200 756.0000 1.0000
41.9600 771.0000 1.0000
42.0000 759.0000 1.0000
42.0400 712.0000 1.0000
42.0800 769.0000 1.0000
42.1200 773.0000 1.0000
42.1600 785.0000 1.0000
42.2000 770.0000 1.0000
42.2400 830.0000 1.0000
42.2800 783.0000 1.0000
42.3200 776.0000 1.0000
42.3600 768.0000 1.0000
42.4000 787.0000 1.0000
42.4400 780.0000 1.0000
42.4800 762.0000 1.0000
42.5200 755.0000 1.0000
42.5600 776.0000 1.0000
42.6000 810.0000 1.0000
42.6400 774.0000 1.0000
42.6800 774.0000 1.0000
42.7200 783.0000 1.0000
42.7600 750.0000 1.0000
42.8000 784.0000 1.0000
42.8400 804.0000 1.0000
42.8800 827.0000 1.0000
42.9200 820.0000 1.0000
42.9600 797.0000 1.0000
43.0000 810.0000 1.0000
43.0400 842.0000 1.0000
43.0800 816.0000 1.0000
43.1200 833.0000 1.0000
43.1600 878.0000 1.0000
43.2000 874.0000 1.0000
43.2400 844.0000 1.0000
43.2800 854.0000 1.0000
43.3200 857.0000 1.0000
43.3600 786.0000 1.0000
43.4000 833.0000 1.0000
43.4400 780.0000 1.0000
43.4800 777.0000 1.0000
43.5200 765.0000 1.0000
43.5600 779.0000 1.0000
43.6000 800.0000 1.0000
43.6400 784.0000 1.0000
43.6800 799.0000 1.0000
43.7200 757.0000 1.0000
43.7600 730.0000 1.0000
43.8000 754.0000 1.0000
43.8400 747.0000 1.0000
43.8800 729.0000 1.0000
43.9200 745.0000 1.0000
43.9600 752.0000 1.0000
44.0000 774.0000 1.0000
44.0400 703.0000 1.0000
44.0800 739.0000 1.0000
44.1200 731.0000 1.0000
44.1600 755.0000 1.0000
44.2000 753.0000 1.0000
44.2400 728.0000 1.0000
44.2800 769.0000 1.0000
44.3200 790.0000 1.0000
44.3600 763.0000 1.0000
44.4000 737.0000 1.0000
44.4400 707.0000 1.0000
44.4800 725.0000 1.0000
44.5200 743.0000 1.0000
44.5600 754.0000 1.0000
44.6000 744.0000 1.0000
44.6400 745.0000 1.0000
44.6800 736.0000 1.0000
44.7200 756.0000 1.0000
44.7600 702.0000 1.0000
44.8000 723.0000 1.0000
44.8400 738.0000 1.0000
44.8800 715.0000 1.0000
44.9200 740.0000 1.0000
44.9600 745.0000 1.0000
45.0000 735.0000 1.0000
45.0400 712.0000 1.0000
45.0800 785.0000 1.0000
45.1200 727.0000 1.0000
45.1600 721.0000 1.0000
45.2000 730.0000 1.0000
45.2400 720.0000 1.0000
45.2800 737.0000 1.0000
45.3200 685.0000 1.0000
45.3600 717.0000 1.0000
45.4000 750.0000 1.0000
45.4400 669.0000 1.0000
45.4800 686.0000 1.0000
45.5200 716.0000 1.0000
45.5600 727.0000 1.0000
45.6000 709.0000 1.0000
45.6400 699.0000 1.0000
45.6800 696.0000 1.0000
45.7200 735.0000 1.0000
45.7600 733.0000 1.0000
45.8000 680.0000 1.0000
45.8400 693.0000 1.0000
45.8800 696.0000 1.0000
45.9200 723.0000 1.0000
45.9600 720.0000 1.0000
46.0000 690.0000 1.0000
46.0400 702.0000 1.0000
46.0800 698.0000 1.0000
46.1200 689.0000 1.0000
46.1600 693.0000 1.0000
46.2000 707.0000 1.0000
46.2400 705.0000 1.0000
46.2800 733.0000 1.0000
46.3200 709.0000 1.0000
46.3600 677.0000 1.0000
46.4000 738.0000 1.0000
46.4400 658.0000 1.0000
46.4800 689.0000 1.0000
46.5200 682.0000 1.0000
46.5600 684.0000 1.0000
46.6000 638.0000 1.0000
46.6400 724.0000 1.0000
46.6800 759.0000 1.0000
46.7200 705.0000 1.0000
46.7600 712.0000 1.0000
46.8000 691.0000 1.0000
46.8400 684.0000 1.0000
46.8800 694.0000 1.0000
46.9200 697.0000 1.0000
46.9600 718.0000 1.0000
47.0000 720.0000 1.0000
47.0400 738.0000 1.0000
47.0800 739.0000 1.0000
47.1200 753.0000 1.0000
47.1600 723.0000 1.0000
47.2000 704.0000 1.0000
47.2400 727.0000 1.0000
47.2800 674.0000 1.0000
47.3200 694.0000 1.0000
47.3600 689.0000 1.0000
47.4000 702.0000 1.0000
47.4400 712.0000 1.0000
47.4800 676.0000 1.0000
47.5200 703.0000 1.0000
47.5600 652.0000 1.0000
47.6000 665.0000 1.0000
47.6400 699.0000 1.0000
47.6800 717.0000 1.0000
47.7200 678.0000 1.0000
47.7600 658.0000 1.0000
47.8000 688.0000 1.0000
47.8400 657.0000 1.0000
47.8800 703.0000 1.0000
47.9200 637.0000 1.0000
47.9600 682.0000 1.0000
48.0000 667.0000 1.0000
48.0400 681.0000 1.0000
48.0800 675.0000 1.0000
48.1200 682.0000 1.0000
48.1600 705.0000 1.0000
48.2000 631.0000 1.0000
48.2400 703.0000 1.0000
48.2800 677.0000 1.0000
48.3200 695.0000 1.0000
48.3600 722.0000 1.0000
48.4000 683.0000 1.0000
48.4400 685.0000 1.0000
48.4800 608.0000 1.0000
48.5200 674.0000 1.0000
48.5600 669.0000 1.0000
48.6000 629.0000 1.0000
48.6400 645.0000 1.0000
48.6800 605.0000 1.0000
48.7200 661.0000 1.0000
48.7600 662.0000 1.0000
48.8000 659.0000 1.0000
48.8400 685.0000 1.0000
48.8800 650.0000 1.0000
48.9200 667.0000 1.0000
48.9600 650.0000 1.0000
49.0000 671.0000 1.0000
49.0400 669.0000 1.0000
49.0800 701.0000 1.0000
49.1200 678.0000 1.0000
49.1600 658.0000 1.0000
49.2000 667.0000 1.0000
49.2400 691.0000 1.0000
49.2800 616.0000 1.0000
49.3200 662.0000 1.0000
49.3600 687.0000 1.0000
49.4000 694.0000 1.0000
49.4400 699.0000 1.0000
49.4800 677.0000 1.0000
49.5200 671.0000 1.0000
49.5600 680.0000 1.0000
49.6000 634.0000 1.0000
49.6400 644.0000 1.0000
49.6800 674.0000 1.0000
49.7200 641.0000 1.0000
49.7600 617.0000 1.0000
49.8000 652.0000 1.0000
49.8400 642.0000 1.0000
49.8800 639.0000 1.0000
49.9200 608.0000 1.0000
49.9600 615.0000 1.0000
50.0000 654.0000 1.0000
50.0400 646.0000 1.0000
50.0800 647.0000 1.0000
50.1200 683.0000 1.0000
50.1600 675.0000 1.0000
50.2000 655.0000 1.0000
50.2400 661.0000 1.0000
50.2800 647.0000 1.0000
50.3200 654.0000 1.0000
50.3600 665.0000 1.0000
50.4000 652.0000 1.0000
50.4400 676.0000 1.0000
50.4800 686.0000 1.0000
50.5200 674.0000 1.0000
50.5600 705.0000 1.0000
50.6000 680.0000 1.0000
50.6400 686.0000 1.0000
50.6800 690.0000 1.0000
50.7200 673.0000 1.0000
50.7600 697.0000 1.0000
50.8000 689.0000 1.0000
50.8400 683.0000 1.0000
50.8800 658.0000 1.0000
50.9200 685.0000 1.0000
50.9600 681.0000 1.0000
51.0000 643.0000 1.0000
51.0400 678.0000 1.0000
51.0800 663.0000 1.0000
51.1200 666.0000 1.0000
51.1600 638.0000 1.0000
51.2000 684.0000 1.0000
51.2400 670.0000 1.0000
51.2800 678.0000 1.0000
51.3200 686.0000 1.0000
51.3600 663.0000 1.0000
51.4000 650.0000 1.0000
51.4400 715.0000 1.0000
51.4800 670.0000 1.0000
51.5200 685.0000 1.0000
51.5600 701.0000 1.0000
51.6000 700.0000 1.0000
51.6400 707.0000 1.0000
51.6800 695.0000 1.0000
51.7200 734.0000 1.0000
51.7600 733.0000 1.0000
51.8000 795.0000 1.0000
51.8400 816.0000 1.0000
51.8800 836.0000 1.0000
51.9200 963.0000 1.0000
51.9600 1031.0000 1.0000
52.0000 1249.0000 1.0000
52.0400 1441.0000 1.0000
52.0800 1678.0000 1.0000
52.1200 2276.0000 1.0000
52.1600 3204.0000 1.0000
52.2000 4286.0000 1.0000
52.2400 4835.0000 1.0000
52.2800 4554.0000 1.0000
52.3200 4089.0000 1.0000
52.3600 3662.0000 1.0000
52.4000 3221.0000 1.0000
52.4400 2492.0000 1.0000
52.4800 1902.0000 1.0000
52.5200 1435.0000 1.0000
52.5600 1244.0000 1.0000
52.6000 1061.0000 1.0000
52.6400 942.0000 1.0000
52.6800 889.0000 1.0000
52.7200 860.0000 1.0000
52.7600 784.0000 1.0000
52.8000 798.0000 1.0000
52.8400 746.0000 1.0000
52.8800 742.0000 1.0000
52.9200 723.0000 1.0000
52.9600 693.0000 1.0000
53.0000 672.0000 1.0000
53.0400 687.0000 1.0000
53.0800 674.0000 1.0000
53.1200 711.0000 1.0000
53.1600 670.0000 1.0000
53.2000 732.0000 1.0000
53.2400 662.0000 1.0000
53.2800 674.0000 1.0000
53.3200 689.0000 1.0000
53.3600 643.0000 1.0000
53.4000 703.0000 1.0000
53.4400 701.0000 1.0000
53.4800 657.0000 1.0000
53.5200 665.0000 1.0000
53.5600 632.0000 1.0000
53.6000 657.0000 1.0000
53.6400 619.0000 1.0000
53.6800 641.0000 1.0000
53.7200 643.0000 1.0000
53.7600 652.0000 1.0000
53.8000 636.0000 1.0000
53.8400 662.0000 1.0000
53.8800 669.0000 1.0000
53.9200 623.0000 1.0000
53.9600 657.0000 1.0000
54.0000 627.0000 1.0000
54.0400 671.0000 1.0000
54.0800 656.0000 1.0000
54.1200 690.0000 1.0000
54.1600 669.0000 1.0000
54.2000 682.0000 1.0000
54.2400 645.0000 1.0000
54.2800 684.0000 1.0000
54.3200 638.0000 1.0000
54.3600 605.0000 1.0000
54.4000 685.0000 1.0000
54.4400 658.0000 1.0000
54.4800 646.0000 1.0000
54.5200 668.0000 1.0000
54.5600 693.0000 1.0000
54.6000 682.0000 1.0000
54.6400 675.0000 1.0000
54.6800 668.0000 1.0000
54.7200 674.0000 1.0000
54.7600 709.0000 1.0000
54.8000 720.0000 1.0000
54.8400 725.0000 1.0000
54.8800 712.0000 1.0000
54.9200 736.0000 1.0000
54.9600 764.0000 1.0000
55.0000 740.0000 1.0000
55.0400 757.0000 1.0000
55.0800 824.0000 1.0000
55.1200 858.0000 1.0000
55.1600 957.0000 1.0000
55.2000 1036.0000 1.0000
55.2400 1109.0000 1.0000
55.2800 1066.0000 1.0000
55.3200 1015.0000 1.0000
55.3600 991.0000 1.0000
55.4000 970.0000 1.0000
55.4400 875.0000 1.0000
55.4800 834.0000 1.0000
55.5200 751.0000 1.0000
55.5600 744.0000 1.0000
55.6000 732.0000 1.0000
55.6400 697.0000 1.0000
55.6800 686.0000 1.0000
55.7200 635.0000 1.0000
55.7600 681.0000 1.0000
55.8000 693.0000 1.0000
55.8400 673.0000 1.0000
55.8800 636.0000 1.0000
55.9200 666.0000 1.0000
55.9600 648.0000 1.0000
56.0000 664.0000 1.0000
56.0400 662.0000 1.0000
56.0800 660.0000 1.0000
56.1200 643.0000 1.0000
56.1600 621.0000 1.0000
56.2000 655.0000 1.0000
56.2400 636.0000 1.0000
56.2800 654.0000 1.0000
56.3200 617.0000 1.0000
56.3600 637.0000 1.0000
56.4000 643.0000 1.0000
56.4400 651.0000 1.0000
56.4800 646.0000 1.0000
56.5200 600.0000 1.0000
56.5600 635.0000 1.0000
56.6000 631.0000 1.0000
56.6400 654.0000 1.0000
56.6800 587.0000 1.0000
56.7200 642.0000 1.0000
56.7600 627.0000 1.0000
56.8000 632.0000 1.0000
56.8400 616.0000 1.0000
56.8800 642.0000 1.0000
56.9200 616.0000 1.0000
56.9600 636.0000 1.0000
57.0000 642.0000 1.0000
57.0400 615.0000 1.0000
57.0800 642.0000 1.0000
57.1200 648.0000 1.0000
57.1600 641.0000 1.0000
57.2000 623.0000 1.0000
57.2400 656.0000 1.0000
57.2800 611.0000 1.0000
57.3200 633.0000 1.0000
57.3600 632.0000 1.0000
57.4000 626.0000 1.0000
57.4400 606.0000 1.0000
57.4800 611.0000 1.0000
57.5200 642.0000 1.0000
57.5600 585.0000 1.0000
57.6000 639.0000 1.0000
57.6400 601.0000 1.0000
57.6800 628.0000 1.0000
57.7200 608.0000 1.0000
57.7600 655.0000 1.0000
57.8000 642.0000 1.0000
57.8400 633.0000 1.0000
57.8800 635.0000 1.0000
57.9200 587.0000 1.0000
57.9600 634.0000 1.0000
58.0000 623.0000 1.0000
58.0400 621.0000 1.0000
58.0800 604.0000 1.0000
58.1200 614.0000 1.0000
58.1600 629.0000 1.0000
58.2000 654.0000 1.0000
58.2400 664.0000 1.0000
58.2800 670.0000 1.0000
58.3200 666.0000 1.0000
58.3600 643.0000 1.0000
58.4000 621.0000 1.0000
58.4400 672.0000 1.0000
58.4800 605.0000 1.0000
58.5200 616.0000 1.0000
58.5600 650.0000 1.0000
58.6000 643.0000 1.0000
58.6400 640.0000 1.0000
58.6800 608.0000 1.0000
58.7200 630.0000 1.0000
58.7600 613.0000 1.0000
58.8000 612.0000 1.0000
58.8400 634.0000 1.0000
58.8800 634.0000 1.0000
58.9200 609.0000 1.0000
58.9600 652.0000 1.0000
59.0000 592.0000 1.0000
59.0400 641.0000 1.0000
59.0800 618.0000 1.0000
59.1200 660.0000 1.0000
59.1600 648.0000 1.0000
59.2000 647.0000 1.0000
59.2400 642.0000 1.0000
59.2800 628.0000 1.0000
59.3200 643.0000 1.0000
59.3600 638.0000 1.0000
59.4000 672.0000 1.0000
59.4400 614.0000 1.0000
59.4800 585.0000 1.0000
59.5200 606.0000 1.0000
59.5600 651.0000 1.0000
59.6000 642.0000 1.0000
59.6400 648.0000 1.0000
59.6800 623.0000 1.0000
59.7200 641.0000 1.0000
59.7600 635.0000 1.0000
59.8000 607.0000 1.0000
59.8400 629.0000 1.0000
59.8800 605.0000 1.0000
59.9200 611.0000 1.0000
59.9600 592.0000 1.0000
60.0000 618.0000 1.0000
60.0400 616.0000 1.0000
60.0800 647.0000 1.0000
60.1200 641.0000 1.0000
60.1600 654.0000 1.0000
60.2000 642.0000 1.0000
60.2400 635.0000 1.0000
60.2800 591.0000 1.0000
60.3200 594.0000 1.0000
60.3600 632.0000 1.0000
60.4000 652.0000 1.0000
60.4400 645.0000 1.0000
60.4800 623.0000 1.0000
60.5200 622.0000 1.0000
60.5600 657.0000 1.0000
60.6000 637.0000 1.0000
60.6400 608.0000 1.0000
60.6800 639.0000 1.0000
60.7200 609.0000 1.0000
60.7600 598.0000 1.0000
60.8000 601.0000 1.0000
60.8400 619.0000 1.0000
60.8800 644.0000 1.0000
60.9200 579.0000 1.0000
60.9600 641.0000 1.0000
61.0000 663.0000 1.0000
61.0400 634.0000 1.0000
61.0800 621.0000 1.0000
61.1200 572.0000 1.0000
61.1600 629.0000 1.0000
61.2000 614.0000 1.0000
61.2400 627.0000 1.0000
61.2800 620.0000 1.0000
61.3200 598.0000 1.0000
61.3600 602.0000 1.0000
61.4000 625.0000 1.0000
61.4400 587.0000 1.0000
61.4800 654.0000 1.0000
61.5200 662.0000 1.0000
61.5600 595.0000 1.0000
61.6000 635.0000 1.0000
61.6400 672.0000 1.0000
61.6800 655.0000 1.0000
61.7200 685.0000 1.0000
61.7600 690.0000 1.0000
61.8000 741.0000 1.0000
61.8400 708.0000 1.0000
61.8800 743.0000 1.0000
61.9200 780.0000 1.0000
61.9600 856.0000 1.0000
62.0000 911.0000 1.0000
62.0400 994.0000 1.0000
62.0800 1103.0000 1.0000
62.1200 1161.0000 1.0000
62.1600 1371.0000 1.0000
62.2000 1510.0000 1.0000
62.2400 1566.0000 1.0000
62.2800 1627.0000 1.0000
62.3200 1554.0000 1.0000
62.3600 1513.0000 1.0000
62.4000 1508.0000 1.0000
62.4400 1404.0000 1.0000
62.4800 1258.0000 1.0000
62.5200 1130.0000 1.0000
62.5600 1098.0000 1.0000
62.6000 963.0000 1.0000
62.6400 957.0000 1.0000
62.6800 860.0000 1.0000
62.7200 813.0000 1.0000
62.7600 813.0000 1.0000
62.8000 732.0000 1.0000
62.8400 760.0000 1.0000
62.8800 681.0000 1.0000
62.9200 716.0000 1.0000
62.9600 718.0000 1.0000
63.0000 727.0000 1.0000
63.0400 696.0000 1.0000
63.0800 683.0000 1.0000
63.1200 638.0000 1.0000
63.1600 660.0000 1.0000
63.2000 624.0000 1.0000
63.2400 684.0000 1.0000
63.2800 704.0000 1.0000
63.3200 700.0000 1.0000
63.3600 689.0000 1.0000
63.4000 629.0000 1.0000
63.4400 666.0000 1.0000
63.4800 644.0000 1.0000
63.5200 649.0000 1.0000
63.5600 646.0000 1.0000
63.6000 639.0000 1.0000
63.6400 665.0000 1.0000
63.6800 656.0000 1.0000
63.7200 615.0000 1.0000
63.7600 637.0000 1.0000
63.8000 625.0000 1.0000
63.8400 639.0000 1.0000
63.8800 666.0000 1.0000
63.9200 670.0000 1.0000
63.9600 644.0000 1.0000
64.0000 653.0000 1.0000
64.0400 664.0000 1.0000
64.0800 651.0000 1.0000
64.1200 576.0000 1.0000
64.1600 629.0000 1.0000
64.2000 666.0000 1.0000
64.2400 627.0000 1.0000
64.2800 624.0000 1.0000
64.3200 674.0000 1.0000
64.3600 632.0000 1.0000
64.4000 656.0000 1.0000
64.4400 673.0000 1.0000
64.4800 678.0000 1.0000
64.5200 648.0000 1.0000
64.5600 713.0000 1.0000
64.6000 724.0000 1.0000
64.6400 707.0000 1.0000
64.6800 721.0000 1.0000
64.7200 668.0000 1.0000
64.7600 738.0000 1.0000
64.8000 767.0000 1.0000
64.8400 681.0000 1.0000
64.8800 690.0000 1.0000
64.9200 729.0000 1.0000
64.9600 692.0000 1.0000
65.0000 708.0000 1.0000
65.0400 682.0000 1.0000
65.0800 699.0000 1.0000
65.1200 692.0000 1.0000
65.1600 661.0000 1.0000
65.2000 688.0000 1.0000
65.2400 669.0000 1.0000
65.2800 704.0000 1.0000
65.3200 679.0000 1.0000
65.3600 656.0000 1.0000
65.4000 690.0000 1.0000
65.4400 646.0000 1.0000
65.4800 676.0000 1.0000
65.5200 673.0000 1.0000
65.5600 701.0000 1.0000
65.6000 662.0000 1.0000
65.6400 684.0000 1.0000
65.6800 697.0000 1.0000
65.7200 731.0000 1.0000
65.7600 758.0000 1.0000
65.8000 748.0000 1.0000
65.8400 795.0000 1.0000
65.8800 834.0000 1.0000
65.9200 889.0000 1.0000
65.9600 1015.0000 1.0000
66.0000 1113.0000 1.0000
66.0400 1247.0000 1.0000
66.0800 1544.0000 1.0000
66.1200 1920.0000 1.0000
66.1600 2317.0000 1.0000
66.2000 2547.0000 1.0000
66.2400 2604.0000 1.0000
66.2800 2505.0000 1.0000
66.3200 2285.0000 1.0000
66.3600 2257.0000 1.0000
66.4000 2048.0000 1.0000
66.4400 1837.0000 1.0000
66.4800 1538.0000 1.0000
66.5200 1410.0000 1.0000
66.5600 1116.0000 1.0000
66.6000 1044.0000 1.0000
66.6400 959.0000 1.0000
66.6800 862.0000 1.0000
66.7200 773.0000 1.0000
66.7600 757.0000 1.0000
66.8000 717.0000 1.0000
66.8400 692.0000 1.0000
66.8800 656.0000 1.0000
66.9200 714.0000 1.0000
66.9600 660.0000 1.0000
67.0000 626.0000 1.0000
67.0400 639.0000 1.0000
67.0800 623.0000 1.0000
67.1200 607.0000 1.0000
67.1600 620.0000 1.0000
67.2000 650.0000 1.0000
67.2400 642.0000 1.0000
67.2800 642.0000 1.0000
67.3200 634.0000 1.0000
67.3600 603.0000 1.0000
67.4000 631.0000 1.0000
67.4400 582.0000 1.0000
67.4800 624.0000 1.0000
67.5200 547.0000 1.0000
67.5600 591.0000 1.0000
67.6000 633.0000 1.0000
67.6400 588.0000 1.0000
67.6800 621.0000 1.0000
67.7200 571.0000 1.0000
67.7600 588.0000 1.0000
67.8000 570.0000 1.0000
67.8400 568.0000 1.0000
67.8800 568.0000 1.0000
67.9200 583.0000 1.0000
67.9600 570.0000 1.0000
68.0000 588.0000 1.0000
68.0400 593.0000 1.0000
68.0800 619.0000 1.0000
68.1200 587.0000 1.0000
68.1600 555.0000 1.0000
68.2000 596.0000 1.0000
68.2400 606.0000 1.0000
68.2800 579.0000 1.0000
68.3200 554.0000 1.0000
68.3600 592.0000 1.0000
68.4000 623.0000 1.0000
68.4400 579.0000 1.0000
68.4800 549.0000 1.0000
68.5200 590.0000 1.0000
68.5600 577.0000 1.0000
68.6000 624.0000 1.0000
68.6400 546.0000 1.0000
68.6800 557.0000 1.0000
68.7200 544.0000 1.0000
68.7600 558.0000 1.0000
68.8000 562.0000 1.0000
68.8400 556.0000 1.0000
68.8800 556.0000 1.0000
68.9200 560.0000 1.0000
68.9600 560.0000 1.0000
69.0000 563.0000 1.0000
69.0400 571.0000 1.0000
69.0800 561.0000 1.0000
69.1200 536.0000 1.0000
69.1600 576.0000 1.0000
69.2000 612.0000 1.0000
69.2400 563.0000 1.0000
69.2800 574.0000 1.0000
69.3200 551.0000 1.0000
69.3600 555.0000 1.0000
69.4000 543.0000 1.0000
69.4400 589.0000 1.0000
69.4800 610.0000 1.0000
69.5200 599.0000 1.0000
69.5600 558.0000 1.0000
69.6000 566.0000 1.0000
69.6400 548.0000 1.0000
69.6800 536.0000 1.0000
69.7200 522.0000 1.0000
69.7600 581.0000 1.0000
69.8000 572.0000 1.0000
69.8400 545.0000 1.0000
69.8800 549.0000 1.0000
69.9200 581.0000 1.0000
69.9600 560.0000 1.0000
70.0000 574.0000 1.0000
*RAS_INT_END
*RAS_TEMPERATURE_START
*RAS_TEMPERATURE_END
*RAS_DATA_END