File: Section2_75_samples/XRD/No_007_600_18.ras
*RAS_DATA_START
*RAS_HEADER_START
*DISP_FMT_X "%.2f"
*DISP_FMT_Y "%.0f"
*DISP_FULLSCALE "4064.0000000000"
*DISP_LINE_COLOR "255.0000000000"
*DISP_LINE_STYLE "0.0000000000"
*DISP_LINE_WIDTH "0.2500000000"
*DISP_NOTE "測定データ-1"
*DISP_OFFSET_Y "0.0000000000"
*DISP_PEAKSEARCH_UNIT_Y "cps"
*DISP_RANGE_BOTTOM "0.0000000000"
*DISP_RANGE_LEFT "20.0000000000"
*DISP_RANGE_LOGCUTOFF "0.0100000000"
*DISP_RANGE_RIGHT "80.0000000000"
*DISP_RANGE_TOP "4064.0000000000"
*DISP_SCALE_MODE_Y "0.0000000000"
*DISP_TAB_NAME "2θ/θ"
*DISP_TITLE_Y "強度"
*DISP_UNIT_Y "cps"
*DISP_WINDOW_NAME "MSG_MACROENGINE"
*FILE_COMMENT " "
*FILE_MD5 ""
*FILE_MEMO " "
*FILE_OPERATOR "Administrator"
*FILE_SAMPLE " "
*FILE_TYPE "RAS_RAW"
*FILE_USERGROUP "システムマネージャ"
*FILE_VERSION "1.0000000000"
*HW_ATTACHMENT_ID "ATT0025"
*HW_ATTACHMENT_NAME "標準|Standard"
*HW_COUNTER_ID-0 "CUT0025"
*HW_COUNTER_ID-1 "CUT0020"
*HW_COUNTER_ID-2 "CUT0020"
*HW_COUNTER_ID-3 "CSL0021"
*HW_COUNTER_ID-4 "CMC0021"
*HW_COUNTER_NAME-0 "D/teX Ultra|D/teX Ultra"
*HW_COUNTER_NAME-1 "None|None"
*HW_COUNTER_NAME-2 "None|None"
*HW_COUNTER_NAME-3 "BBM|BBM"
*HW_COUNTER_NAME-4 "検出器モノクロメータ|Detector monochromator"
*HW_COUNTER_SELECT_NAME "D/teX Ultra|D/teX Ultra"
*HW_GONIOMETER_ID "GON0023"
*HW_GONIOMETER_NAME "SmartLab|SmartLab"
*HW_GONIOMETER_RADIUS-0 "90.0"
*HW_GONIOMETER_RADIUS-1 "114.0"
*HW_GONIOMETER_RADIUS-2 "190.0"
*HW_GONIOMETER_RADIUS-3 "300.0"
*HW_GONIOMETER_RADIUS-4 "187.0"
*HW_GONIOMETER_RADIUS-5 "300.0"
*HW_GONIOMETER_RADIUS-6 "113.0"
*HW_GONIOMETER_RADIUS-7 "331.0"
*HW_I_OPT_ID-0 "CBO0021"
*HW_I_OPT_ID-1 "ICR0023"
*HW_I_OPT_ID-2 "ISL0021"
*HW_I_OPT_ID-3 "ISO0021"
*HW_I_OPT_ID-4 "IAD0021"
*HW_I_OPT_ID-5 "IPR0001"
*HW_I_OPT_NAME-0 "CBOユニット|CBO unit"
*HW_I_OPT_NAME-1 "標準入射光学ユニット|Standard incident optical unit"
*HW_I_OPT_NAME-2 "標準入射スリットボックス|Standard incident slit box"
*HW_I_OPT_NAME-3 "入射平行スリット|Incident parallel slit"
*HW_I_OPT_NAME-4 "長手制限スリット|Length limiting slit"
*HW_I_OPT_NAME-5 "None|None"
*HW_R_ATTENUATER_AUTOMODE "0"
*HW_R_OPT_ID-0 "RSS0021"
*HW_R_OPT_ID-1 "RCR0023"
*HW_R_OPT_ID-2 "RSO0021"
*HW_R_OPT_ID-3 "RRS0021"
*HW_R_OPT_ID-4 "ATN0021"
*HW_R_OPT_ID-5 "RFL0021"
*HW_R_OPT_ID-6 "RAD0021"
*HW_R_OPT_NAME-0 "標準受光スリットボックス1|Standard receiving slit box # 1"
*HW_R_OPT_NAME-1 "標準受光光学ユニット1|Standard receiving unit # 1"
*HW_R_OPT_NAME-2 "標準受光光学ユニット2|Standard receiving optical unit # 2"
*HW_R_OPT_NAME-3 "標準受光スリットボックス2|Standard receiving slit box # 2"
*HW_R_OPT_NAME-4 "標準アッテネータ|Standard Attenuator"
*HW_R_OPT_NAME-5 "Cu Kβ|Cu K-beta"
*HW_R_OPT_NAME-6 "調整用受光スリット|Alignment receiving slit"
*HW_SAMPLE_HOLDER_ID "SMP0023"
*HW_SAMPLE_HOLDER_NAME "標準Zステージ|Standard Z stage"
*HW_XG_CURRENT_MAX "50"
*HW_XG_CURRENT_MIN "2"
*HW_XG_CURRENT_RESOLUTION "2"
*HW_XG_CURRENT_UNIT "mA"
*HW_XG_FOCUS "1mm x 10mm"
*HW_XG_FOCUS_TYPE "Normal"
*HW_XG_ID ""
*HW_XG_NAME "3kW 封入管(ID:1200)|3kW Sealed tube(ID:1200)"
*HW_XG_TARGET_ATOMIC_NUMBER "29.0000000000"
*HW_XG_TARGET_NAME "Cu"
*HW_XG_TYPE "Hermetic"
*HW_XG_VOLTAGE_MAX "60"
*HW_XG_VOLTAGE_MIN "20"
*HW_XG_VOLTAGE_RESOLUTION "2"
*HW_XG_VOLTAGE_UNIT "kV"
*HW_XG_WATT_MAX "2"
*HW_XG_WATT_UNIT "kW"
*HW_XG_WAVE_LENGTH_ALPHA1 "1.540593"
*HW_XG_WAVE_LENGTH_ALPHA2 "1.544414"
*HW_XG_WAVE_LENGTH_BETA "1.392250"
*MEAS_COND_AXIS_NAME-0 "2θ/θ"
*MEAS_COND_AXIS_NAME-1 "2θ"
*MEAS_COND_AXIS_NAME-2 "ω"
*MEAS_COND_AXIS_NAME-3 "Z"
*MEAS_COND_AXIS_NAME-4 "2θ/ω"
*MEAS_COND_AXIS_NAME-5 "θs"
*MEAS_COND_AXIS_NAME-6 "θd"
*MEAS_COND_AXIS_NAME-7 "Ts"
*MEAS_COND_AXIS_NAME-8 "CBO選択スリット"
*MEAS_COND_AXIS_NAME-9 "M"
*MEAS_COND_AXIS_NAME-10 "入射平行スリット"
*MEAS_COND_AXIS_NAME-11 "入射スリット"
*MEAS_COND_AXIS_NAME-12 ""
*MEAS_COND_AXIS_NAME-13 "Zs"
*MEAS_COND_AXIS_NAME-14 "入射光学素子"
*MEAS_COND_AXIS_NAME-15 "長手制限スリット"
*MEAS_COND_AXIS_NAME-16 "センタースリット"
*MEAS_COND_AXIS_NAME-17 "フィルター"
*MEAS_COND_AXIS_NAME-18 "受光スリット1"
*MEAS_COND_AXIS_NAME-19 "受光スリット2"
*MEAS_COND_AXIS_NAME-20 "受光光学素子"
*MEAS_COND_AXIS_NAME-21 "受光平行スリット"
*MEAS_COND_AXIS_NAME-22 "調整用受光スリット"
*MEAS_COND_AXIS_NAME-23 ""
*MEAS_COND_AXIS_NAME-24 ""
*MEAS_COND_AXIS_NAME-25 "Zd"
*MEAS_COND_AXIS_NAME-26 "アッテネータ"
*MEAS_COND_AXIS_NAME-27 "検出器モノクロメータ"
*MEAS_COND_AXIS_NAME-28 "モノクロメータスリット"
*MEAS_COND_AXIS_NAME-29 "プライマリビーム"
*MEAS_COND_AXIS_NAME-30 "PHA"
*MEAS_COND_AXIS_NAME_INTERNAL-0 "TwoThetaTheta"
*MEAS_COND_AXIS_NAME_INTERNAL-1 "TwoTheta"
*MEAS_COND_AXIS_NAME_INTERNAL-2 "Omega"
*MEAS_COND_AXIS_NAME_INTERNAL-3 "Z"
*MEAS_COND_AXIS_NAME_INTERNAL-4 "TwoThetaOmega"
*MEAS_COND_AXIS_NAME_INTERNAL-5 "ThetaS"
*MEAS_COND_AXIS_NAME_INTERNAL-6 "ThetaD"
*MEAS_COND_AXIS_NAME_INTERNAL-7 "Ts"
*MEAS_COND_AXIS_NAME_INTERNAL-8 "CBO"
*MEAS_COND_AXIS_NAME_INTERNAL-9 "CBO-M"
*MEAS_COND_AXIS_NAME_INTERNAL-10 "IncidentSollerSlit"
*MEAS_COND_AXIS_NAME_INTERNAL-11 "IncidentSlitBox"
*MEAS_COND_AXIS_NAME_INTERNAL-12 "IncidentSlitBox-_Axis"
*MEAS_COND_AXIS_NAME_INTERNAL-13 "Zs"
*MEAS_COND_AXIS_NAME_INTERNAL-14 "IncidentMonochromator"
*MEAS_COND_AXIS_NAME_INTERNAL-15 "IncidentAxdSlit"
*MEAS_COND_AXIS_NAME_INTERNAL-16 "CenterSlit"
*MEAS_COND_AXIS_NAME_INTERNAL-17 "Filter"
*MEAS_COND_AXIS_NAME_INTERNAL-18 "ReceivingSlitBox1"
*MEAS_COND_AXIS_NAME_INTERNAL-19 "ReceivingSlitBox2"
*MEAS_COND_AXIS_NAME_INTERNAL-20 "ReceivingOptics"
*MEAS_COND_AXIS_NAME_INTERNAL-21 "ReceivingSollerSlit"
*MEAS_COND_AXIS_NAME_INTERNAL-22 "ReceivingAxdSlit"
*MEAS_COND_AXIS_NAME_INTERNAL-23 "ReceivingSlitBox1-_Axis"
*MEAS_COND_AXIS_NAME_INTERNAL-24 "ReceivingSlitBox2-_Axis"
*MEAS_COND_AXIS_NAME_INTERNAL-25 "ReceivingSlitBox2-Zd"
*MEAS_COND_AXIS_NAME_INTERNAL-26 "Attenuator"
*MEAS_COND_AXIS_NAME_INTERNAL-27 "CounterMonochromator"
*MEAS_COND_AXIS_NAME_INTERNAL-28 "CounterSlit"
*MEAS_COND_AXIS_NAME_INTERNAL-29 "IncidentPrimary"
*MEAS_COND_AXIS_NAME_INTERNAL-30 "PHA"
*MEAS_COND_AXIS_NAME_MAGICNO-0 "83951616.0000000000"
*MEAS_COND_AXIS_NAME_MAGICNO-1 "268632064.0000000000"
*MEAS_COND_AXIS_NAME_MAGICNO-2 "268500992.0000000000"
*MEAS_COND_AXIS_NAME_MAGICNO-3 "285278208.0000000000"
*MEAS_COND_AXIS_NAME_MAGICNO-4 "83951616.0000000000"
*MEAS_COND_AXIS_NAME_MAGICNO-5 "131072.0000000000"
*MEAS_COND_AXIS_NAME_MAGICNO-6 "131072.0000000000"
*MEAS_COND_AXIS_NAME_MAGICNO-7 "318898176.0000000000"
*MEAS_COND_AXIS_NAME_MAGICNO-8 "20971521.0000000000"
*MEAS_COND_AXIS_NAME_MAGICNO-9 "285343744.0000000000"
*MEAS_COND_AXIS_NAME_MAGICNO-10 "20971521.0000000000"
*MEAS_COND_AXIS_NAME_MAGICNO-11 "22020097.0000000000"
*MEAS_COND_AXIS_NAME_MAGICNO-12 "25165824.0000000000"
*MEAS_COND_AXIS_NAME_MAGICNO-13 "318898176.0000000000"
*MEAS_COND_AXIS_NAME_MAGICNO-14 "1.0000000000"
*MEAS_COND_AXIS_NAME_MAGICNO-15 "20971521.0000000000"
*MEAS_COND_AXIS_NAME_MAGICNO-16 "20971521.0000000000"
*MEAS_COND_AXIS_NAME_MAGICNO-17 "20971521.0000000000"
*MEAS_COND_AXIS_NAME_MAGICNO-18 "23068673.0000000000"
*MEAS_COND_AXIS_NAME_MAGICNO-19 "23068673.0000000000"
*MEAS_COND_AXIS_NAME_MAGICNO-20 "20971521.0000000000"
*MEAS_COND_AXIS_NAME_MAGICNO-21 "20971521.0000000000"
*MEAS_COND_AXIS_NAME_MAGICNO-22 "20971521.0000000000"
*MEAS_COND_AXIS_NAME_MAGICNO-23 "25165824.0000000000"
*MEAS_COND_AXIS_NAME_MAGICNO-24 "25165824.0000000000"
*MEAS_COND_AXIS_NAME_MAGICNO-25 "285343744.0000000000"
*MEAS_COND_AXIS_NAME_MAGICNO-26 "17301505.0000000000"
*MEAS_COND_AXIS_NAME_MAGICNO-27 "20971521.0000000000"
*MEAS_COND_AXIS_NAME_MAGICNO-28 "20971521.0000000000"
*MEAS_COND_AXIS_NAME_MAGICNO-29 "20971521.0000000000"
*MEAS_COND_AXIS_NAME_MAGICNO-30 "0.0000000000"
*MEAS_COND_AXIS_OFFSET-0 "-"
*MEAS_COND_AXIS_OFFSET-1 "-0.1081000000"
*MEAS_COND_AXIS_OFFSET-2 "0.3758000000"
*MEAS_COND_AXIS_OFFSET-3 "-"
*MEAS_COND_AXIS_OFFSET-4 "-"
*MEAS_COND_AXIS_OFFSET-5 "0.3758000000"
*MEAS_COND_AXIS_OFFSET-6 "-0.4839000000"
*MEAS_COND_AXIS_OFFSET-7 "-"
*MEAS_COND_AXIS_OFFSET-8 "-"
*MEAS_COND_AXIS_OFFSET-9 "-"
*MEAS_COND_AXIS_OFFSET-10 "-"
*MEAS_COND_AXIS_OFFSET-11 "-"
*MEAS_COND_AXIS_OFFSET-12 "-"
*MEAS_COND_AXIS_OFFSET-13 "-"
*MEAS_COND_AXIS_OFFSET-14 "-"
*MEAS_COND_AXIS_OFFSET-15 "-"
*MEAS_COND_AXIS_OFFSET-16 "-"
*MEAS_COND_AXIS_OFFSET-17 "-"
*MEAS_COND_AXIS_OFFSET-18 "-"
*MEAS_COND_AXIS_OFFSET-19 "-"
*MEAS_COND_AXIS_OFFSET-20 "-"
*MEAS_COND_AXIS_OFFSET-21 "-"
*MEAS_COND_AXIS_OFFSET-22 "-"
*MEAS_COND_AXIS_OFFSET-23 "-"
*MEAS_COND_AXIS_OFFSET-24 "-"
*MEAS_COND_AXIS_OFFSET-25 "-"
*MEAS_COND_AXIS_OFFSET-26 "-"
*MEAS_COND_AXIS_OFFSET-27 "-"
*MEAS_COND_AXIS_OFFSET-28 "-"
*MEAS_COND_AXIS_OFFSET-29 "-"
*MEAS_COND_AXIS_OFFSET-30 "-"
*MEAS_COND_AXIS_POSITION-0 "0.0000000000"
*MEAS_COND_AXIS_POSITION-1 "0.0000000000"
*MEAS_COND_AXIS_POSITION-2 "0.0000000000"
*MEAS_COND_AXIS_POSITION-3 "-0.5500000000"
*MEAS_COND_AXIS_POSITION-4 "0.0000000000"
*MEAS_COND_AXIS_POSITION-5 "0.0000000000"
*MEAS_COND_AXIS_POSITION-6 "0.0000000000"
*MEAS_COND_AXIS_POSITION-7 "-0.4278800000"
*MEAS_COND_AXIS_POSITION-8 "BB"
*MEAS_COND_AXIS_POSITION-9 "0.0000000000"
*MEAS_COND_AXIS_POSITION-10 "Soller_slit_5.0deg"
*MEAS_COND_AXIS_POSITION-11 "2/3deg"
*MEAS_COND_AXIS_POSITION-12 "2.2088000000"
*MEAS_COND_AXIS_POSITION-13 "-0.4140600000"
*MEAS_COND_AXIS_POSITION-14 "0.0000000000"
*MEAS_COND_AXIS_POSITION-15 "10.0mm"
*MEAS_COND_AXIS_POSITION-16 "None"
*MEAS_COND_AXIS_POSITION-17 "Cu_K-beta"
*MEAS_COND_AXIS_POSITION-18 "13.000mm"
*MEAS_COND_AXIS_POSITION-19 "13.000mm"
*MEAS_COND_AXIS_POSITION-20 "No_unit"
*MEAS_COND_AXIS_POSITION-21 "Soller_slit_5.0deg"
*MEAS_COND_AXIS_POSITION-22 "None"
*MEAS_COND_AXIS_POSITION-23 "13.0000000000"
*MEAS_COND_AXIS_POSITION-24 "13.0000000000"
*MEAS_COND_AXIS_POSITION-25 "0.0109400000"
*MEAS_COND_AXIS_POSITION-26 "Open"
*MEAS_COND_AXIS_POSITION-27 "None"
*MEAS_COND_AXIS_POSITION-28 "None"
*MEAS_COND_AXIS_POSITION-29 "None"
*MEAS_COND_AXIS_POSITION-30 "38.0000000000"
*MEAS_COND_AXIS_UNIT-0 "deg"
*MEAS_COND_AXIS_UNIT-1 "deg"
*MEAS_COND_AXIS_UNIT-2 "deg"
*MEAS_COND_AXIS_UNIT-3 "mm"
*MEAS_COND_AXIS_UNIT-4 "deg"
*MEAS_COND_AXIS_UNIT-5 "deg"
*MEAS_COND_AXIS_UNIT-6 "deg"
*MEAS_COND_AXIS_UNIT-7 "mm"
*MEAS_COND_AXIS_UNIT-8 ""
*MEAS_COND_AXIS_UNIT-9 "pulse"
*MEAS_COND_AXIS_UNIT-10 ""
*MEAS_COND_AXIS_UNIT-11 ""
*MEAS_COND_AXIS_UNIT-12 "mm"
*MEAS_COND_AXIS_UNIT-13 "mm"
*MEAS_COND_AXIS_UNIT-14 ""
*MEAS_COND_AXIS_UNIT-15 ""
*MEAS_COND_AXIS_UNIT-16 ""
*MEAS_COND_AXIS_UNIT-17 ""
*MEAS_COND_AXIS_UNIT-18 ""
*MEAS_COND_AXIS_UNIT-19 ""
*MEAS_COND_AXIS_UNIT-20 ""
*MEAS_COND_AXIS_UNIT-21 ""
*MEAS_COND_AXIS_UNIT-22 ""
*MEAS_COND_AXIS_UNIT-23 "mm"
*MEAS_COND_AXIS_UNIT-24 "mm"
*MEAS_COND_AXIS_UNIT-25 "mm"
*MEAS_COND_AXIS_UNIT-26 ""
*MEAS_COND_AXIS_UNIT-27 ""
*MEAS_COND_AXIS_UNIT-28 ""
*MEAS_COND_AXIS_UNIT-29 ""
*MEAS_COND_AXIS_UNIT-30 "div"
*MEAS_COND_COUNTER_CNTLOSS_CORR "0.0000000000"
*MEAS_COND_COUNTER_PHABASE "38.0000000000"
*MEAS_COND_COUNTER_PHAWINDOW "16.0000000000"
*MEAS_COND_COUNTER_PHA_UNIT "div"
*MEAS_COND_COUNTER_TAUDIFF "30.0000000000"
*MEAS_COND_COUNTER_TAUINT "0.0000000000"
*MEAS_COND_IRRADIATION_MODE "OFF"
*MEAS_COND_IRRADIATION_WIDTH ""
*MEAS_COND_OPT_ATTR "集中法"
*MEAS_COND_OPT_NAME "@集中法"
*MEAS_COND_UNSYMMETRIC_MODE "OFF"
*MEAS_COND_XG_CURRENT "30.0000000000"
*MEAS_COND_XG_VOLTAGE "40.0000000000"
*MEAS_COND_XG_WAVE_TYPE "Ka"
*MEAS_DATA_COUNT "3001.0000000000"
*MEAS_SCAN_AXIS_X "2θ/θ"
*MEAS_SCAN_AXIS_X_INTERNAL "TwoThetaTheta"
*MEAS_SCAN_END_TIME "09/04/20 10:26:58"
*MEAS_SCAN_MODE "CONTINUOUS"
*MEAS_SCAN_MONITOR "0"
*MEAS_SCAN_RESOLUTION_X "0.0002"
*MEAS_SCAN_SPEED "2.0"
*MEAS_SCAN_SPEED_UNIT "deg/min"
*MEAS_SCAN_START "20.0000000000"
*MEAS_SCAN_START_TIME "09/04/20 09:55:18"
*MEAS_SCAN_STEP "0.0200000000"
*MEAS_SCAN_STOP "80.0000000000"
*MEAS_SCAN_UNIT_X "deg"
*MEAS_SCAN_UNIT_Y "counts"
*RAS_HEADER_END
*RAS_INT_START
20.0000 1958.0000 1.0000
20.0600 1979.0000 1.0000
20.1200 1840.0000 1.0000
20.1800 1995.0000 1.0000
20.2400 1854.0000 1.0000
20.3000 1875.0000 1.0000
20.3600 1892.0000 1.0000
20.4200 1818.0000 1.0000
20.4800 1874.0000 1.0000
20.5400 1809.0000 1.0000
20.6000 1821.0000 1.0000
20.6600 1860.0000 1.0000
20.7200 1851.0000 1.0000
20.7800 1828.0000 1.0000
20.8400 1865.0000 1.0000
20.9000 1806.0000 1.0000
20.9600 1810.0000 1.0000
21.0200 1746.0000 1.0000
21.0800 1762.0000 1.0000
21.1400 1823.0000 1.0000
21.2000 1762.0000 1.0000
21.2600 1754.0000 1.0000
21.3200 1723.0000 1.0000
21.3800 1730.0000 1.0000
21.4400 1772.0000 1.0000
21.5000 1746.0000 1.0000
21.5600 1687.0000 1.0000
21.6200 1722.0000 1.0000
21.6800 1719.0000 1.0000
21.7400 1648.0000 1.0000
21.8000 1630.0000 1.0000
21.8600 1713.0000 1.0000
21.9200 1610.0000 1.0000
21.9800 1690.0000 1.0000
22.0400 1683.0000 1.0000
22.1000 1589.0000 1.0000
22.1600 1581.0000 1.0000
22.2200 1629.0000 1.0000
22.2800 1607.0000 1.0000
22.3400 1611.0000 1.0000
22.4000 1560.0000 1.0000
22.4600 1552.0000 1.0000
22.5200 1614.0000 1.0000
22.5800 1595.0000 1.0000
22.6400 1556.0000 1.0000
22.7000 1536.0000 1.0000
22.7600 1487.0000 1.0000
22.8200 1607.0000 1.0000
22.8800 1540.0000 1.0000
22.9400 1573.0000 1.0000
23.0000 1437.0000 1.0000
23.0600 1514.0000 1.0000
23.1200 1580.0000 1.0000
23.1800 1440.0000 1.0000
23.2400 1506.0000 1.0000
23.3000 1520.0000 1.0000
23.3600 1523.0000 1.0000
23.4200 1391.0000 1.0000
23.4800 1476.0000 1.0000
23.5400 1469.0000 1.0000
23.6000 1411.0000 1.0000
23.6600 1414.0000 1.0000
23.7200 1471.0000 1.0000
23.7800 1341.0000 1.0000
23.8400 1421.0000 1.0000
23.9000 1436.0000 1.0000
23.9600 1393.0000 1.0000
24.0200 1406.0000 1.0000
24.0800 1401.0000 1.0000
24.1400 1358.0000 1.0000
24.2000 1409.0000 1.0000
24.2600 1372.0000 1.0000
24.3200 1313.0000 1.0000
24.3800 1339.0000 1.0000
24.4400 1293.0000 1.0000
24.5000 1320.0000 1.0000
24.5600 1391.0000 1.0000
24.6200 1303.0000 1.0000
24.6800 1327.0000 1.0000
24.7400 1230.0000 1.0000
24.8000 1336.0000 1.0000
24.8600 1255.0000 1.0000
24.9200 1275.0000 1.0000
24.9800 1353.0000 1.0000
25.0400 1292.0000 1.0000
25.1000 1328.0000 1.0000
25.1600 1305.0000 1.0000
25.2200 1201.0000 1.0000
25.2800 1252.0000 1.0000
25.3400 1173.0000 1.0000
25.4000 1247.0000 1.0000
25.4600 1185.0000 1.0000
25.5200 1249.0000 1.0000
25.5800 1286.0000 1.0000
25.6400 1227.0000 1.0000
25.7000 1260.0000 1.0000
25.7600 1150.0000 1.0000
25.8200 1196.0000 1.0000
25.8800 1224.0000 1.0000
25.9400 1157.0000 1.0000
26.0000 1166.0000 1.0000
26.0600 1230.0000 1.0000
26.1200 1153.0000 1.0000
26.1800 1130.0000 1.0000
26.2400 1114.0000 1.0000
26.3000 1079.0000 1.0000
26.3600 1149.0000 1.0000
26.4200 1143.0000 1.0000
26.4800 1093.0000 1.0000
26.5400 1104.0000 1.0000
26.6000 1081.0000 1.0000
26.6600 1093.0000 1.0000
26.7200 1088.0000 1.0000
26.7800 1086.0000 1.0000
26.8400 1076.0000 1.0000
26.9000 1084.0000 1.0000
26.9600 1100.0000 1.0000
27.0200 1051.0000 1.0000
27.0800 1095.0000 1.0000
27.1400 1137.0000 1.0000
27.2000 1203.0000 1.0000
27.2600 1347.0000 1.0000
27.3200 1380.0000 1.0000
27.3800 1266.0000 1.0000
27.4400 1139.0000 1.0000
27.5000 1051.0000 1.0000
27.5600 1051.0000 1.0000
27.6200 1025.0000 1.0000
27.6800 960.0000 1.0000
27.7400 966.0000 1.0000
27.8000 975.0000 1.0000
27.8600 956.0000 1.0000
27.9200 969.0000 1.0000
27.9800 949.0000 1.0000
28.0400 935.0000 1.0000
28.1000 965.0000 1.0000
28.1600 951.0000 1.0000
28.2200 937.0000 1.0000
28.2800 925.0000 1.0000
28.3400 884.0000 1.0000
28.4000 892.0000 1.0000
28.4600 914.0000 1.0000
28.5200 899.0000 1.0000
28.5800 919.0000 1.0000
28.6400 891.0000 1.0000
28.7000 867.0000 1.0000
28.7600 883.0000 1.0000
28.8200 896.0000 1.0000
28.8800 862.0000 1.0000
28.9400 855.0000 1.0000
29.0000 838.0000 1.0000
29.0600 887.0000 1.0000
29.1200 914.0000 1.0000
29.1800 843.0000 1.0000
29.2400 898.0000 1.0000
29.3000 890.0000 1.0000
29.3600 826.0000 1.0000
29.4200 835.0000 1.0000
29.4800 856.0000 1.0000
29.5400 865.0000 1.0000
29.6000 828.0000 1.0000
29.6600 812.0000 1.0000
29.7200 826.0000 1.0000
29.7800 820.0000 1.0000
29.8400 851.0000 1.0000
29.9000 851.0000 1.0000
29.9600 824.0000 1.0000
30.0200 832.0000 1.0000
30.0800 859.0000 1.0000
30.1400 799.0000 1.0000
30.2000 797.0000 1.0000
30.2600 791.0000 1.0000
30.3200 792.0000 1.0000
30.3800 798.0000 1.0000
30.4400 816.0000 1.0000
30.5000 819.0000 1.0000
30.5600 730.0000 1.0000
30.6200 762.0000 1.0000
30.6800 745.0000 1.0000
30.7400 743.0000 1.0000
30.8000 762.0000 1.0000
30.8600 739.0000 1.0000
30.9200 750.0000 1.0000
30.9800 735.0000 1.0000
31.0400 764.0000 1.0000
31.1000 773.0000 1.0000
31.1600 741.0000 1.0000
31.2200 752.0000 1.0000
31.2800 747.0000 1.0000
31.3400 729.0000 1.0000
31.4000 724.0000 1.0000
31.4600 733.0000 1.0000
31.5200 730.0000 1.0000
31.5800 711.0000 1.0000
31.6400 719.0000 1.0000
31.7000 719.0000 1.0000
31.7600 697.0000 1.0000
31.8200 745.0000 1.0000
31.8800 723.0000 1.0000
31.9400 727.0000 1.0000
32.0000 696.0000 1.0000
32.0600 716.0000 1.0000
32.1200 684.0000 1.0000
32.1800 706.0000 1.0000
32.2400 703.0000 1.0000
32.3000 732.0000 1.0000
32.3600 691.0000 1.0000
32.4200 679.0000 1.0000
32.4800 645.0000 1.0000
32.5400 683.0000 1.0000
32.6000 664.0000 1.0000
32.6600 676.0000 1.0000
32.7200 732.0000 1.0000
32.7800 655.0000 1.0000
32.8400 657.0000 1.0000
32.9000 653.0000 1.0000
32.9600 650.0000 1.0000
33.0200 650.0000 1.0000
33.0800 680.0000 1.0000
33.1400 636.0000 1.0000
33.2000 628.0000 1.0000
33.2600 630.0000 1.0000
33.3200 588.0000 1.0000
33.3800 620.0000 1.0000
33.4400 602.0000 1.0000
33.5000 579.0000 1.0000
33.5600 602.0000 1.0000
33.6200 694.0000 1.0000
33.6800 628.0000 1.0000
33.7400 589.0000 1.0000
33.8000 622.0000 1.0000
33.8600 611.0000 1.0000
33.9200 621.0000 1.0000
33.9800 629.0000 1.0000
34.0400 643.0000 1.0000
34.1000 615.0000 1.0000
34.1600 635.0000 1.0000
34.2200 650.0000 1.0000
34.2800 667.0000 1.0000
34.3400 676.0000 1.0000
34.4000 770.0000 1.0000
34.4600 728.0000 1.0000
34.5200 817.0000 1.0000
34.5800 676.0000 1.0000
34.6400 711.0000 1.0000
34.7000 656.0000 1.0000
34.7600 599.0000 1.0000
34.8200 573.0000 1.0000
34.8800 560.0000 1.0000
34.9400 588.0000 1.0000
35.0000 559.0000 1.0000
35.0600 542.0000 1.0000
35.1200 516.0000 1.0000
35.1800 513.0000 1.0000
35.2400 557.0000 1.0000
35.3000 559.0000 1.0000
35.3600 535.0000 1.0000
35.4200 577.0000 1.0000
35.4800 582.0000 1.0000
35.5400 538.0000 1.0000
35.6000 507.0000 1.0000
35.6600 552.0000 1.0000
35.7200 548.0000 1.0000
35.7800 534.0000 1.0000
35.8400 545.0000 1.0000
35.9000 513.0000 1.0000
35.9600 508.0000 1.0000
36.0200 521.0000 1.0000
36.0800 519.0000 1.0000
36.1400 509.0000 1.0000
36.2000 555.0000 1.0000
36.2600 556.0000 1.0000
36.3200 563.0000 1.0000
36.3800 611.0000 1.0000
36.4400 564.0000 1.0000
36.5000 557.0000 1.0000
36.5600 517.0000 1.0000
36.6200 538.0000 1.0000
36.6800 515.0000 1.0000
36.7400 509.0000 1.0000
36.8000 481.0000 1.0000
36.8600 461.0000 1.0000
36.9200 461.0000 1.0000
36.9800 479.0000 1.0000
37.0400 454.0000 1.0000
37.1000 471.0000 1.0000
37.1600 507.0000 1.0000
37.2200 503.0000 1.0000
37.2800 463.0000 1.0000
37.3400 497.0000 1.0000
37.4000 465.0000 1.0000
37.4600 439.0000 1.0000
37.5200 496.0000 1.0000
37.5800 455.0000 1.0000
37.6400 495.0000 1.0000
37.7000 448.0000 1.0000
37.7600 449.0000 1.0000
37.8200 488.0000 1.0000
37.8800 448.0000 1.0000
37.9400 468.0000 1.0000
38.0000 431.0000 1.0000
38.0600 450.0000 1.0000
38.1200 462.0000 1.0000
38.1800 437.0000 1.0000
38.2400 548.0000 1.0000
38.3000 553.0000 1.0000
38.3600 643.0000 1.0000
38.4200 713.0000 1.0000
38.4800 927.0000 1.0000
38.5400 897.0000 1.0000
38.6000 795.0000 1.0000
38.6600 685.0000 1.0000
38.7200 599.0000 1.0000
38.7800 529.0000 1.0000
38.8400 456.0000 1.0000
38.9000 430.0000 1.0000
38.9600 405.0000 1.0000
39.0200 442.0000 1.0000
39.0800 424.0000 1.0000
39.1400 423.0000 1.0000
39.2000 417.0000 1.0000
39.2600 396.0000 1.0000
39.3200 440.0000 1.0000
39.3800 431.0000 1.0000
39.4400 406.0000 1.0000
39.5000 418.0000 1.0000
39.5600 416.0000 1.0000
39.6200 440.0000 1.0000
39.6800 390.0000 1.0000
39.7400 423.0000 1.0000
39.8000 411.0000 1.0000
39.8600 387.0000 1.0000
39.9200 419.0000 1.0000
39.9800 382.0000 1.0000
40.0400 382.0000 1.0000
40.1000 410.0000 1.0000
40.1600 379.0000 1.0000
40.2200 394.0000 1.0000
40.2800 408.0000 1.0000
40.3400 378.0000 1.0000
40.4000 405.0000 1.0000
40.4600 388.0000 1.0000
40.5200 366.0000 1.0000
40.5800 412.0000 1.0000
40.6400 364.0000 1.0000
40.7000 387.0000 1.0000
40.7600 345.0000 1.0000
40.8200 377.0000 1.0000
40.8800 380.0000 1.0000
40.9400 352.0000 1.0000
41.0000 361.0000 1.0000
41.0600 365.0000 1.0000
41.1200 387.0000 1.0000
41.1800 413.0000 1.0000
41.2400 392.0000 1.0000
41.3000 368.0000 1.0000
41.3600 381.0000 1.0000
41.4200 386.0000 1.0000
41.4800 376.0000 1.0000
41.5400 409.0000 1.0000
41.6000 369.0000 1.0000
41.6600 347.0000 1.0000
41.7200 378.0000 1.0000
41.7800 361.0000 1.0000
41.8400 356.0000 1.0000
41.9000 360.0000 1.0000
41.9600 357.0000 1.0000
42.0200 366.0000 1.0000
42.0800 347.0000 1.0000
42.1400 332.0000 1.0000
42.2000 364.0000 1.0000
42.2600 378.0000 1.0000
42.3200 355.0000 1.0000
42.3800 333.0000 1.0000
42.4400 339.0000 1.0000
42.5000 351.0000 1.0000
42.5600 338.0000 1.0000
42.6200 348.0000 1.0000
42.6800 369.0000 1.0000
42.7400 372.0000 1.0000
42.8000 356.0000 1.0000
42.8600 341.0000 1.0000
42.9200 349.0000 1.0000
42.9800 308.0000 1.0000
43.0400 358.0000 1.0000
43.1000 361.0000 1.0000
43.1600 322.0000 1.0000
43.2200 342.0000 1.0000
43.2800 352.0000 1.0000
43.3400 331.0000 1.0000
43.4000 337.0000 1.0000
43.4600 328.0000 1.0000
43.5200 335.0000 1.0000
43.5800 339.0000 1.0000
43.6400 317.0000 1.0000
43.7000 324.0000 1.0000
43.7600 365.0000 1.0000
43.8200 310.0000 1.0000
43.8800 337.0000 1.0000
43.9400 326.0000 1.0000
44.0000 346.0000 1.0000
44.0600 349.0000 1.0000
44.1200 329.0000 1.0000
44.1800 313.0000 1.0000
44.2400 326.0000 1.0000
44.3000 326.0000 1.0000
44.3600 318.0000 1.0000
44.4200 358.0000 1.0000
44.4800 287.0000 1.0000
44.5400 340.0000 1.0000
44.6000 309.0000 1.0000
44.6600 325.0000 1.0000
44.7200 347.0000 1.0000
44.7800 339.0000 1.0000
44.8400 292.0000 1.0000
44.9000 308.0000 1.0000
44.9600 327.0000 1.0000
45.0200 315.0000 1.0000
45.0800 292.0000 1.0000
45.1400 303.0000 1.0000
45.2000 305.0000 1.0000
45.2600 310.0000 1.0000
45.3200 308.0000 1.0000
45.3800 338.0000 1.0000
45.4400 309.0000 1.0000
45.5000 322.0000 1.0000
45.5600 299.0000 1.0000
45.6200 291.0000 1.0000
45.6800 287.0000 1.0000
45.7400 303.0000 1.0000
45.8000 318.0000 1.0000
45.8600 326.0000 1.0000
45.9200 322.0000 1.0000
45.9800 304.0000 1.0000
46.0400 316.0000 1.0000
46.1000 311.0000 1.0000
46.1600 299.0000 1.0000
46.2200 282.0000 1.0000
46.2800 316.0000 1.0000
46.3400 332.0000 1.0000
46.4000 283.0000 1.0000
46.4600 304.0000 1.0000
46.5200 310.0000 1.0000
46.5800 274.0000 1.0000
46.6400 273.0000 1.0000
46.7000 290.0000 1.0000
46.7600 268.0000 1.0000
46.8200 300.0000 1.0000
46.8800 267.0000 1.0000
46.9400 297.0000 1.0000
47.0000 293.0000 1.0000
47.0600 326.0000 1.0000
47.1200 253.0000 1.0000
47.1800 275.0000 1.0000
47.2400 276.0000 1.0000
47.3000 279.0000 1.0000
47.3600 294.0000 1.0000
47.4200 268.0000 1.0000
47.4800 286.0000 1.0000
47.5400 291.0000 1.0000
47.6000 269.0000 1.0000
47.6600 271.0000 1.0000
47.7200 267.0000 1.0000
47.7800 274.0000 1.0000
47.8400 263.0000 1.0000
47.9000 270.0000 1.0000
47.9600 282.0000 1.0000
48.0200 289.0000 1.0000
48.0800 297.0000 1.0000
48.1400 302.0000 1.0000
48.2000 272.0000 1.0000
48.2600 303.0000 1.0000
48.3200 293.0000 1.0000
48.3800 272.0000 1.0000
48.4400 283.0000 1.0000
48.5000 297.0000 1.0000
48.5600 262.0000 1.0000
48.6200 271.0000 1.0000
48.6800 263.0000 1.0000
48.7400 282.0000 1.0000
48.8000 247.0000 1.0000
48.8600 268.0000 1.0000
48.9200 264.0000 1.0000
48.9800 253.0000 1.0000
49.0400 242.0000 1.0000
49.1000 256.0000 1.0000
49.1600 242.0000 1.0000
49.2200 257.0000 1.0000
49.2800 263.0000 1.0000
49.3400 281.0000 1.0000
49.4000 270.0000 1.0000
49.4600 243.0000 1.0000
49.5200 261.0000 1.0000
49.5800 286.0000 1.0000
49.6400 271.0000 1.0000
49.7000 267.0000 1.0000
49.7600 239.0000 1.0000
49.8200 243.0000 1.0000
49.8800 265.0000 1.0000
49.9400 253.0000 1.0000
50.0000 262.0000 1.0000
50.0600 247.0000 1.0000
50.1200 241.0000 1.0000
50.1800 252.0000 1.0000
50.2400 269.0000 1.0000
50.3000 271.0000 1.0000
50.3600 261.0000 1.0000
50.4200 236.0000 1.0000
50.4800 270.0000 1.0000
50.5400 279.0000 1.0000
50.6000 254.0000 1.0000
50.6600 254.0000 1.0000
50.7200 236.0000 1.0000
50.7800 278.0000 1.0000
50.8400 241.0000 1.0000
50.9000 232.0000 1.0000
50.9600 244.0000 1.0000
51.0200 250.0000 1.0000
51.0800 253.0000 1.0000
51.1400 262.0000 1.0000
51.2000 242.0000 1.0000
51.2600 261.0000 1.0000
51.3200 246.0000 1.0000
51.3800 245.0000 1.0000
51.4400 245.0000 1.0000
51.5000 253.0000 1.0000
51.5600 273.0000 1.0000
51.6200 273.0000 1.0000
51.6800 260.0000 1.0000
51.7400 248.0000 1.0000
51.8000 260.0000 1.0000
51.8600 271.0000 1.0000
51.9200 270.0000 1.0000
51.9800 304.0000 1.0000
52.0400 323.0000 1.0000
52.1000 451.0000 1.0000
52.1600 682.0000 1.0000
52.2200 998.0000 1.0000
52.2800 1000.0000 1.0000
52.3400 900.0000 1.0000
52.4000 742.0000 1.0000
52.4600 521.0000 1.0000
52.5200 421.0000 1.0000
52.5800 338.0000 1.0000
52.6400 298.0000 1.0000
52.7000 283.0000 1.0000
52.7600 273.0000 1.0000
52.8200 287.0000 1.0000
52.8800 255.0000 1.0000
52.9400 260.0000 1.0000
53.0000 236.0000 1.0000
53.0600 277.0000 1.0000
53.1200 268.0000 1.0000
53.1800 223.0000 1.0000
53.2400 235.0000 1.0000
53.3000 248.0000 1.0000
53.3600 246.0000 1.0000
53.4200 251.0000 1.0000
53.4800 238.0000 1.0000
53.5400 260.0000 1.0000
53.6000 233.0000 1.0000
53.6600 226.0000 1.0000
53.7200 242.0000 1.0000
53.7800 237.0000 1.0000
53.8400 203.0000 1.0000
53.9000 240.0000 1.0000
53.9600 210.0000 1.0000
54.0200 241.0000 1.0000
54.0800 236.0000 1.0000
54.1400 254.0000 1.0000
54.2000 253.0000 1.0000
54.2600 251.0000 1.0000
54.3200 243.0000 1.0000
54.3800 254.0000 1.0000
54.4400 251.0000 1.0000
54.5000 248.0000 1.0000
54.5600 233.0000 1.0000
54.6200 243.0000 1.0000
54.6800 251.0000 1.0000
54.7400 250.0000 1.0000
54.8000 247.0000 1.0000
54.8600 249.0000 1.0000
54.9200 269.0000 1.0000
54.9800 263.0000 1.0000
55.0400 266.0000 1.0000
55.1000 277.0000 1.0000
55.1600 263.0000 1.0000
55.2200 304.0000 1.0000
55.2800 305.0000 1.0000
55.3400 285.0000 1.0000
55.4000 288.0000 1.0000
55.4600 264.0000 1.0000
55.5200 242.0000 1.0000
55.5800 273.0000 1.0000
55.6400 239.0000 1.0000
55.7000 218.0000 1.0000
55.7600 230.0000 1.0000
55.8200 220.0000 1.0000
55.8800 250.0000 1.0000
55.9400 239.0000 1.0000
56.0000 240.0000 1.0000
56.0600 219.0000 1.0000
56.1200 240.0000 1.0000
56.1800 210.0000 1.0000
56.2400 231.0000 1.0000
56.3000 227.0000 1.0000
56.3600 200.0000 1.0000
56.4200 258.0000 1.0000
56.4800 231.0000 1.0000
56.5400 264.0000 1.0000
56.6000 217.0000 1.0000
56.6600 221.0000 1.0000
56.7200 250.0000 1.0000
56.7800 234.0000 1.0000
56.8400 234.0000 1.0000
56.9000 208.0000 1.0000
56.9600 216.0000 1.0000
57.0200 227.0000 1.0000
57.0800 271.0000 1.0000
57.1400 230.0000 1.0000
57.2000 223.0000 1.0000
57.2600 248.0000 1.0000
57.3200 236.0000 1.0000
57.3800 226.0000 1.0000
57.4400 211.0000 1.0000
57.5000 232.0000 1.0000
57.5600 239.0000 1.0000
57.6200 225.0000 1.0000
57.6800 219.0000 1.0000
57.7400 208.0000 1.0000
57.8000 248.0000 1.0000
57.8600 238.0000 1.0000
57.9200 249.0000 1.0000
57.9800 221.0000 1.0000
58.0400 247.0000 1.0000
58.1000 235.0000 1.0000
58.1600 228.0000 1.0000
58.2200 231.0000 1.0000
58.2800 232.0000 1.0000
58.3400 241.0000 1.0000
58.4000 232.0000 1.0000
58.4600 227.0000 1.0000
58.5200 244.0000 1.0000
58.5800 224.0000 1.0000
58.6400 182.0000 1.0000
58.7000 219.0000 1.0000
58.7600 209.0000 1.0000
58.8200 238.0000 1.0000
58.8800 226.0000 1.0000
58.9400 229.0000 1.0000
59.0000 212.0000 1.0000
59.0600 237.0000 1.0000
59.1200 223.0000 1.0000
59.1800 238.0000 1.0000
59.2400 225.0000 1.0000
59.3000 218.0000 1.0000
59.3600 220.0000 1.0000
59.4200 253.0000 1.0000
59.4800 232.0000 1.0000
59.5400 206.0000 1.0000
59.6000 237.0000 1.0000
59.6600 244.0000 1.0000
59.7200 200.0000 1.0000
59.7800 238.0000 1.0000
59.8400 221.0000 1.0000
59.9000 192.0000 1.0000
59.9600 217.0000 1.0000
60.0200 221.0000 1.0000
60.0800 232.0000 1.0000
60.1400 209.0000 1.0000
60.2000 231.0000 1.0000
60.2600 208.0000 1.0000
60.3200 233.0000 1.0000
60.3800 237.0000 1.0000
60.4400 222.0000 1.0000
60.5000 224.0000 1.0000
60.5600 206.0000 1.0000
60.6200 234.0000 1.0000
60.6800 222.0000 1.0000
60.7400 226.0000 1.0000
60.8000 233.0000 1.0000
60.8600 216.0000 1.0000
60.9200 232.0000 1.0000
60.9800 220.0000 1.0000
61.0400 207.0000 1.0000
61.1000 207.0000 1.0000
61.1600 243.0000 1.0000
61.2200 233.0000 1.0000
61.2800 195.0000 1.0000
61.3400 209.0000 1.0000
61.4000 204.0000 1.0000
61.4600 245.0000 1.0000
61.5200 216.0000 1.0000
61.5800 229.0000 1.0000
61.6400 242.0000 1.0000
61.7000 251.0000 1.0000
61.7600 250.0000 1.0000
61.8200 236.0000 1.0000
61.8800 243.0000 1.0000
61.9400 236.0000 1.0000
62.0000 255.0000 1.0000
62.0600 258.0000 1.0000
62.1200 312.0000 1.0000
62.1800 375.0000 1.0000
62.2400 384.0000 1.0000
62.3000 425.0000 1.0000
62.3600 365.0000 1.0000
62.4200 383.0000 1.0000
62.4800 337.0000 1.0000
62.5400 277.0000 1.0000
62.6000 280.0000 1.0000
62.6600 260.0000 1.0000
62.7200 251.0000 1.0000
62.7800 241.0000 1.0000
62.8400 237.0000 1.0000
62.9000 235.0000 1.0000
62.9600 217.0000 1.0000
63.0200 254.0000 1.0000
63.0800 240.0000 1.0000
63.1400 244.0000 1.0000
63.2000 230.0000 1.0000
63.2600 238.0000 1.0000
63.3200 179.0000 1.0000
63.3800 217.0000 1.0000
63.4400 244.0000 1.0000
63.5000 207.0000 1.0000
63.5600 214.0000 1.0000
63.6200 205.0000 1.0000
63.6800 233.0000 1.0000
63.7400 218.0000 1.0000
63.8000 217.0000 1.0000
63.8600 249.0000 1.0000
63.9200 224.0000 1.0000
63.9800 234.0000 1.0000
64.0400 230.0000 1.0000
64.1000 242.0000 1.0000
64.1600 206.0000 1.0000
64.2200 218.0000 1.0000
64.2800 230.0000 1.0000
64.3400 232.0000 1.0000
64.4000 234.0000 1.0000
64.4600 248.0000 1.0000
64.5200 217.0000 1.0000
64.5800 267.0000 1.0000
64.6400 257.0000 1.0000
64.7000 265.0000 1.0000
64.7600 259.0000 1.0000
64.8200 280.0000 1.0000
64.8800 262.0000 1.0000
64.9400 253.0000 1.0000
65.0000 228.0000 1.0000
65.0600 253.0000 1.0000
65.1200 254.0000 1.0000
65.1800 257.0000 1.0000
65.2400 238.0000 1.0000
65.3000 240.0000 1.0000
65.3600 230.0000 1.0000
65.4200 232.0000 1.0000
65.4800 247.0000 1.0000
65.5400 213.0000 1.0000
65.6000 198.0000 1.0000
65.6600 250.0000 1.0000
65.7200 266.0000 1.0000
65.7800 237.0000 1.0000
65.8400 241.0000 1.0000
65.9000 235.0000 1.0000
65.9600 291.0000 1.0000
66.0200 313.0000 1.0000
66.0800 399.0000 1.0000
66.1400 509.0000 1.0000
66.2000 645.0000 1.0000
66.2600 601.0000 1.0000
66.3200 563.0000 1.0000
66.3800 585.0000 1.0000
66.4400 513.0000 1.0000
66.5000 414.0000 1.0000
66.5600 364.0000 1.0000
66.6200 298.0000 1.0000
66.6800 263.0000 1.0000
66.7400 285.0000 1.0000
66.8000 273.0000 1.0000
66.8600 246.0000 1.0000
66.9200 240.0000 1.0000
66.9800 236.0000 1.0000
67.0400 218.0000 1.0000
67.1000 199.0000 1.0000
67.1600 239.0000 1.0000
67.2200 228.0000 1.0000
67.2800 206.0000 1.0000
67.3400 234.0000 1.0000
67.4000 220.0000 1.0000
67.4600 195.0000 1.0000
67.5200 217.0000 1.0000
67.5800 203.0000 1.0000
67.6400 186.0000 1.0000
67.7000 218.0000 1.0000
67.7600 217.0000 1.0000
67.8200 216.0000 1.0000
67.8800 229.0000 1.0000
67.9400 222.0000 1.0000
68.0000 217.0000 1.0000
68.0600 220.0000 1.0000
68.1200 212.0000 1.0000
68.1800 200.0000 1.0000
68.2400 210.0000 1.0000
68.3000 225.0000 1.0000
68.3600 234.0000 1.0000
68.4200 198.0000 1.0000
68.4800 217.0000 1.0000
68.5400 205.0000 1.0000
68.6000 224.0000 1.0000
68.6600 188.0000 1.0000
68.7200 227.0000 1.0000
68.7800 223.0000 1.0000
68.8400 205.0000 1.0000
68.9000 242.0000 1.0000
68.9600 211.0000 1.0000
69.0200 206.0000 1.0000
69.0800 210.0000 1.0000
69.1400 210.0000 1.0000
69.2000 205.0000 1.0000
69.2600 200.0000 1.0000
69.3200 220.0000 1.0000
69.3800 230.0000 1.0000
69.4400 189.0000 1.0000
69.5000 202.0000 1.0000
69.5600 208.0000 1.0000
69.6200 226.0000 1.0000
69.6800 232.0000 1.0000
69.7400 202.0000 1.0000
69.8000 209.0000 1.0000
69.8600 203.0000 1.0000
69.9200 194.0000 1.0000
69.9800 219.0000 1.0000
70.0400 241.0000 1.0000
70.1000 215.0000 1.0000
70.1600 220.0000 1.0000
70.2200 209.0000 1.0000
70.2800 221.0000 1.0000
70.3400 205.0000 1.0000
70.4000 198.0000 1.0000
70.4600 210.0000 1.0000
70.5200 208.0000 1.0000
70.5800 211.0000 1.0000
70.6400 190.0000 1.0000
70.7000 225.0000 1.0000
70.7600 191.0000 1.0000
70.8200 200.0000 1.0000
70.8800 213.0000 1.0000
70.9400 204.0000 1.0000
71.0000 218.0000 1.0000
71.0600 220.0000 1.0000
71.1200 231.0000 1.0000
71.1800 199.0000 1.0000
71.2400 225.0000 1.0000
71.3000 207.0000 1.0000
71.3600 211.0000 1.0000
71.4200 239.0000 1.0000
71.4800 203.0000 1.0000
71.5400 244.0000 1.0000
71.6000 227.0000 1.0000
71.6600 200.0000 1.0000
71.7200 237.0000 1.0000
71.7800 232.0000 1.0000
71.8400 236.0000 1.0000
71.9000 205.0000 1.0000
71.9600 218.0000 1.0000
72.0200 190.0000 1.0000
72.0800 211.0000 1.0000
72.1400 210.0000 1.0000
72.2000 195.0000 1.0000
72.2600 205.0000 1.0000
72.3200 225.0000 1.0000
72.3800 194.0000 1.0000
72.4400 188.0000 1.0000
72.5000 205.0000 1.0000
72.5600 203.0000 1.0000
72.6200 192.0000 1.0000
72.6800 201.0000 1.0000
72.7400 188.0000 1.0000
72.8000 216.0000 1.0000
72.8600 229.0000 1.0000
72.9200 163.0000 1.0000
72.9800 211.0000 1.0000
73.0400 188.0000 1.0000
73.1000 179.0000 1.0000
73.1600 201.0000 1.0000
73.2200 190.0000 1.0000
73.2800 194.0000 1.0000
73.3400 205.0000 1.0000
73.4000 199.0000 1.0000
73.4600 186.0000 1.0000
73.5200 215.0000 1.0000
73.5800 198.0000 1.0000
73.6400 208.0000 1.0000
73.7000 198.0000 1.0000
73.7600 225.0000 1.0000
73.8200 201.0000 1.0000
73.8800 212.0000 1.0000
73.9400 175.0000 1.0000
74.0000 214.0000 1.0000
74.0600 179.0000 1.0000
74.1200 200.0000 1.0000
74.1800 210.0000 1.0000
74.2400 196.0000 1.0000
74.3000 173.0000 1.0000
74.3600 187.0000 1.0000
74.4200 189.0000 1.0000
74.4800 188.0000 1.0000
74.5400 209.0000 1.0000
74.6000 208.0000 1.0000
74.6600 188.0000 1.0000
74.7200 187.0000 1.0000
74.7800 198.0000 1.0000
74.8400 211.0000 1.0000
74.9000 195.0000 1.0000
74.9600 195.0000 1.0000
75.0200 198.0000 1.0000
75.0800 187.0000 1.0000
75.1400 181.0000 1.0000
75.2000 212.0000 1.0000
75.2600 216.0000 1.0000
75.3200 217.0000 1.0000
75.3800 184.0000 1.0000
75.4400 206.0000 1.0000
75.5000 214.0000 1.0000
75.5600 188.0000 1.0000
75.6200 196.0000 1.0000
75.6800 203.0000 1.0000
75.7400 195.0000 1.0000
75.8000 177.0000 1.0000
75.8600 180.0000 1.0000
75.9200 217.0000 1.0000
75.9800 212.0000 1.0000
76.0400 184.0000 1.0000
76.1000 193.0000 1.0000
76.1600 193.0000 1.0000
76.2200 209.0000 1.0000
76.2800 198.0000 1.0000
76.3400 182.0000 1.0000
76.4000 211.0000 1.0000
76.4600 200.0000 1.0000
76.5200 186.0000 1.0000
76.5800 210.0000 1.0000
76.6400 183.0000 1.0000
76.7000 226.0000 1.0000
76.7600 199.0000 1.0000
76.8200 205.0000 1.0000
76.8800 186.0000 1.0000
76.9400 210.0000 1.0000
77.0000 199.0000 1.0000
77.0600 213.0000 1.0000
77.1200 194.0000 1.0000
77.1800 191.0000 1.0000
77.2400 200.0000 1.0000
77.3000 210.0000 1.0000
77.3600 221.0000 1.0000
77.4200 208.0000 1.0000
77.4800 179.0000 1.0000
77.5400 200.0000 1.0000
77.6000 189.0000 1.0000
77.6600 224.0000 1.0000
77.7200 191.0000 1.0000
77.7800 189.0000 1.0000
77.8400 199.0000 1.0000
77.9000 185.0000 1.0000
77.9600 198.0000 1.0000
78.0200 192.0000 1.0000
78.0800 215.0000 1.0000
78.1400 198.0000 1.0000
78.2000 203.0000 1.0000
78.2600 209.0000 1.0000
78.3200 220.0000 1.0000
78.3800 177.0000 1.0000
78.4400 201.0000 1.0000
78.5000 216.0000 1.0000
78.5600 184.0000 1.0000
78.6200 229.0000 1.0000
78.6800 223.0000 1.0000
78.7400 241.0000 1.0000
78.8000 228.0000 1.0000
78.8600 281.0000 1.0000
78.9200 273.0000 1.0000
78.9800 270.0000 1.0000
79.0400 277.0000 1.0000
79.1000 253.0000 1.0000
79.1600 240.0000 1.0000
79.2200 278.0000 1.0000
79.2800 236.0000 1.0000
79.3400 202.0000 1.0000
79.4000 207.0000 1.0000
79.4600 202.0000 1.0000
79.5200 195.0000 1.0000
79.5800 205.0000 1.0000
79.6400 213.0000 1.0000
79.7000 198.0000 1.0000
79.7600 200.0000 1.0000
79.8200 204.0000 1.0000
79.8800 207.0000 1.0000
79.9400 193.0000 1.0000
80.0000 190.0000 1.0000
*RAS_INT_END
*RAS_TEMPERATURE_START
*RAS_TEMPERATURE_END
*RAS_DATA_END