File: Section2_75_samples/XRD/No_063_HS1_3.ras
*RAS_DATA_START
*RAS_HEADER_START
*DISP_FMT_X "%.2f"
*DISP_FMT_Y "%.0f"
*DISP_FULLSCALE "12890.0000000000"
*DISP_LINE_COLOR "255.0000000000"
*DISP_LINE_STYLE "0.0000000000"
*DISP_LINE_WIDTH "0.2500000000"
*DISP_NOTE "測定データ-6"
*DISP_OFFSET_Y "0.0000000000"
*DISP_PEAKSEARCH_UNIT_Y "cps"
*DISP_RANGE_BOTTOM "0.0000000000"
*DISP_RANGE_LEFT "20.0000000000"
*DISP_RANGE_LOGCUTOFF "0.0100000000"
*DISP_RANGE_RIGHT "70.0000000000"
*DISP_RANGE_TOP "12890.0000000000"
*DISP_SCALE_MODE_Y "0.0000000000"
*DISP_TAB_NAME "2θ/θ"
*DISP_TITLE_Y "強度"
*DISP_UNIT_Y "cps"
*DISP_WINDOW_NAME "MSG_MACROENGINE"
*FILE_COMMENT " "
*FILE_MD5 ""
*FILE_MEMO " "
*FILE_OPERATOR "Administrator"
*FILE_SAMPLE " "
*FILE_TYPE "RAS_RAW"
*FILE_USERGROUP "システムマネージャ"
*FILE_VERSION "1.0000000000"
*HW_ATTACHMENT_ID "ATT0025"
*HW_ATTACHMENT_NAME "標準|Standard"
*HW_COUNTER_ID-0 "CUT0025"
*HW_COUNTER_ID-1 "CUT0020"
*HW_COUNTER_ID-2 "CUT0020"
*HW_COUNTER_ID-3 "CSL0021"
*HW_COUNTER_ID-4 "CMC0021"
*HW_COUNTER_NAME-0 "D/teX Ultra|D/teX Ultra"
*HW_COUNTER_NAME-1 "None|None"
*HW_COUNTER_NAME-2 "None|None"
*HW_COUNTER_NAME-3 "BBM|BBM"
*HW_COUNTER_NAME-4 "検出器モノクロメータ|Detector monochromator"
*HW_COUNTER_SELECT_NAME "D/teX Ultra|D/teX Ultra"
*HW_GONIOMETER_ID "GON0023"
*HW_GONIOMETER_NAME "SmartLab|SmartLab"
*HW_GONIOMETER_RADIUS-0 "90.0"
*HW_GONIOMETER_RADIUS-1 "114.0"
*HW_GONIOMETER_RADIUS-2 "190.0"
*HW_GONIOMETER_RADIUS-3 "300.0"
*HW_GONIOMETER_RADIUS-4 "187.0"
*HW_GONIOMETER_RADIUS-5 "300.0"
*HW_GONIOMETER_RADIUS-6 "113.0"
*HW_GONIOMETER_RADIUS-7 "331.0"
*HW_I_OPT_ID-0 "CBO0021"
*HW_I_OPT_ID-1 "ICR0023"
*HW_I_OPT_ID-2 "ISL0021"
*HW_I_OPT_ID-3 "ISO0021"
*HW_I_OPT_ID-4 "IAD0021"
*HW_I_OPT_ID-5 "IPR0001"
*HW_I_OPT_NAME-0 "CBOユニット|CBO unit"
*HW_I_OPT_NAME-1 "標準入射光学ユニット|Standard incident optical unit"
*HW_I_OPT_NAME-2 "標準入射スリットボックス|Standard incident slit box"
*HW_I_OPT_NAME-3 "入射平行スリット|Incident parallel slit"
*HW_I_OPT_NAME-4 "長手制限スリット|Length limiting slit"
*HW_I_OPT_NAME-5 "None|None"
*HW_R_ATTENUATER_AUTOMODE "0"
*HW_R_OPT_ID-0 "RSS0021"
*HW_R_OPT_ID-1 "RCR0023"
*HW_R_OPT_ID-2 "RSO0021"
*HW_R_OPT_ID-3 "RRS0021"
*HW_R_OPT_ID-4 "ATN0021"
*HW_R_OPT_ID-5 "RFL0021"
*HW_R_OPT_ID-6 "RAD0021"
*HW_R_OPT_NAME-0 "標準受光スリットボックス1|Standard receiving slit box # 1"
*HW_R_OPT_NAME-1 "標準受光光学ユニット1|Standard receiving unit # 1"
*HW_R_OPT_NAME-2 "標準受光光学ユニット2|Standard receiving optical unit # 2"
*HW_R_OPT_NAME-3 "標準受光スリットボックス2|Standard receiving slit box # 2"
*HW_R_OPT_NAME-4 "標準アッテネータ|Standard Attenuator"
*HW_R_OPT_NAME-5 "Cu Kβ|Cu K-beta"
*HW_R_OPT_NAME-6 "調整用受光スリット|Alignment receiving slit"
*HW_SAMPLE_HOLDER_ID "SMP0023"
*HW_SAMPLE_HOLDER_NAME "標準Zステージ|Standard Z stage"
*HW_XG_CURRENT_MAX "50"
*HW_XG_CURRENT_MIN "2"
*HW_XG_CURRENT_RESOLUTION "1"
*HW_XG_CURRENT_UNIT "mA"
*HW_XG_FOCUS "1mm x 10mm"
*HW_XG_FOCUS_TYPE "Normal"
*HW_XG_ID ""
*HW_XG_NAME "3kW 封入管(ID:1200)|3kW Sealed tube(ID:1200)"
*HW_XG_TARGET_ATOMIC_NUMBER "29.0000000000"
*HW_XG_TARGET_NAME "Cu"
*HW_XG_TYPE "Hermetic"
*HW_XG_VOLTAGE_MAX "60"
*HW_XG_VOLTAGE_MIN "20"
*HW_XG_VOLTAGE_RESOLUTION "1"
*HW_XG_VOLTAGE_UNIT "kV"
*HW_XG_WATT_MAX "1.500"
*HW_XG_WATT_UNIT "kW"
*HW_XG_WAVE_LENGTH_ALPHA1 "1.540593"
*HW_XG_WAVE_LENGTH_ALPHA2 "1.544414"
*HW_XG_WAVE_LENGTH_BETA "1.392250"
*MEAS_COND_AXIS_NAME-0 "2θ/θ"
*MEAS_COND_AXIS_NAME-1 "2θ"
*MEAS_COND_AXIS_NAME-2 "ω"
*MEAS_COND_AXIS_NAME-3 "Z"
*MEAS_COND_AXIS_NAME-4 "2θ/ω"
*MEAS_COND_AXIS_NAME-5 "θs"
*MEAS_COND_AXIS_NAME-6 "θd"
*MEAS_COND_AXIS_NAME-7 "Ts"
*MEAS_COND_AXIS_NAME-8 "CBO選択スリット"
*MEAS_COND_AXIS_NAME-9 "M"
*MEAS_COND_AXIS_NAME-10 "入射平行スリット"
*MEAS_COND_AXIS_NAME-11 "入射スリット"
*MEAS_COND_AXIS_NAME-12 ""
*MEAS_COND_AXIS_NAME-13 "Zs"
*MEAS_COND_AXIS_NAME-14 "入射光学素子"
*MEAS_COND_AXIS_NAME-15 "長手制限スリット"
*MEAS_COND_AXIS_NAME-16 "センタースリット"
*MEAS_COND_AXIS_NAME-17 "フィルター"
*MEAS_COND_AXIS_NAME-18 "受光スリット1"
*MEAS_COND_AXIS_NAME-19 "受光スリット2"
*MEAS_COND_AXIS_NAME-20 "受光光学素子"
*MEAS_COND_AXIS_NAME-21 "受光平行スリット"
*MEAS_COND_AXIS_NAME-22 "調整用受光スリット"
*MEAS_COND_AXIS_NAME-23 ""
*MEAS_COND_AXIS_NAME-24 ""
*MEAS_COND_AXIS_NAME-25 "Zd"
*MEAS_COND_AXIS_NAME-26 "アッテネータ"
*MEAS_COND_AXIS_NAME-27 "検出器モノクロメータ"
*MEAS_COND_AXIS_NAME-28 "モノクロメータスリット"
*MEAS_COND_AXIS_NAME-29 "プライマリビーム"
*MEAS_COND_AXIS_NAME-30 "PHA"
*MEAS_COND_AXIS_NAME_INTERNAL-0 "TwoThetaTheta"
*MEAS_COND_AXIS_NAME_INTERNAL-1 "TwoTheta"
*MEAS_COND_AXIS_NAME_INTERNAL-2 "Omega"
*MEAS_COND_AXIS_NAME_INTERNAL-3 "Z"
*MEAS_COND_AXIS_NAME_INTERNAL-4 "TwoThetaOmega"
*MEAS_COND_AXIS_NAME_INTERNAL-5 "ThetaS"
*MEAS_COND_AXIS_NAME_INTERNAL-6 "ThetaD"
*MEAS_COND_AXIS_NAME_INTERNAL-7 "Ts"
*MEAS_COND_AXIS_NAME_INTERNAL-8 "CBO"
*MEAS_COND_AXIS_NAME_INTERNAL-9 "CBO-M"
*MEAS_COND_AXIS_NAME_INTERNAL-10 "IncidentSollerSlit"
*MEAS_COND_AXIS_NAME_INTERNAL-11 "IncidentSlitBox"
*MEAS_COND_AXIS_NAME_INTERNAL-12 "IncidentSlitBox-_Axis"
*MEAS_COND_AXIS_NAME_INTERNAL-13 "Zs"
*MEAS_COND_AXIS_NAME_INTERNAL-14 "IncidentMonochromator"
*MEAS_COND_AXIS_NAME_INTERNAL-15 "IncidentAxdSlit"
*MEAS_COND_AXIS_NAME_INTERNAL-16 "CenterSlit"
*MEAS_COND_AXIS_NAME_INTERNAL-17 "Filter"
*MEAS_COND_AXIS_NAME_INTERNAL-18 "ReceivingSlitBox1"
*MEAS_COND_AXIS_NAME_INTERNAL-19 "ReceivingSlitBox2"
*MEAS_COND_AXIS_NAME_INTERNAL-20 "ReceivingOptics"
*MEAS_COND_AXIS_NAME_INTERNAL-21 "ReceivingSollerSlit"
*MEAS_COND_AXIS_NAME_INTERNAL-22 "ReceivingAxdSlit"
*MEAS_COND_AXIS_NAME_INTERNAL-23 "ReceivingSlitBox1-_Axis"
*MEAS_COND_AXIS_NAME_INTERNAL-24 "ReceivingSlitBox2-_Axis"
*MEAS_COND_AXIS_NAME_INTERNAL-25 "ReceivingSlitBox2-Zd"
*MEAS_COND_AXIS_NAME_INTERNAL-26 "Attenuator"
*MEAS_COND_AXIS_NAME_INTERNAL-27 "CounterMonochromator"
*MEAS_COND_AXIS_NAME_INTERNAL-28 "CounterSlit"
*MEAS_COND_AXIS_NAME_INTERNAL-29 "IncidentPrimary"
*MEAS_COND_AXIS_NAME_INTERNAL-30 "PHA"
*MEAS_COND_AXIS_NAME_MAGICNO-0 "83951616.0000000000"
*MEAS_COND_AXIS_NAME_MAGICNO-1 "268632064.0000000000"
*MEAS_COND_AXIS_NAME_MAGICNO-2 "268500992.0000000000"
*MEAS_COND_AXIS_NAME_MAGICNO-3 "285278208.0000000000"
*MEAS_COND_AXIS_NAME_MAGICNO-4 "83951616.0000000000"
*MEAS_COND_AXIS_NAME_MAGICNO-5 "131072.0000000000"
*MEAS_COND_AXIS_NAME_MAGICNO-6 "131072.0000000000"
*MEAS_COND_AXIS_NAME_MAGICNO-7 "318898176.0000000000"
*MEAS_COND_AXIS_NAME_MAGICNO-8 "20971521.0000000000"
*MEAS_COND_AXIS_NAME_MAGICNO-9 "285343744.0000000000"
*MEAS_COND_AXIS_NAME_MAGICNO-10 "20971521.0000000000"
*MEAS_COND_AXIS_NAME_MAGICNO-11 "22020097.0000000000"
*MEAS_COND_AXIS_NAME_MAGICNO-12 "25165824.0000000000"
*MEAS_COND_AXIS_NAME_MAGICNO-13 "318898176.0000000000"
*MEAS_COND_AXIS_NAME_MAGICNO-14 "1.0000000000"
*MEAS_COND_AXIS_NAME_MAGICNO-15 "20971521.0000000000"
*MEAS_COND_AXIS_NAME_MAGICNO-16 "20971521.0000000000"
*MEAS_COND_AXIS_NAME_MAGICNO-17 "20971521.0000000000"
*MEAS_COND_AXIS_NAME_MAGICNO-18 "23068673.0000000000"
*MEAS_COND_AXIS_NAME_MAGICNO-19 "23068673.0000000000"
*MEAS_COND_AXIS_NAME_MAGICNO-20 "20971521.0000000000"
*MEAS_COND_AXIS_NAME_MAGICNO-21 "20971521.0000000000"
*MEAS_COND_AXIS_NAME_MAGICNO-22 "20971521.0000000000"
*MEAS_COND_AXIS_NAME_MAGICNO-23 "25165824.0000000000"
*MEAS_COND_AXIS_NAME_MAGICNO-24 "25165824.0000000000"
*MEAS_COND_AXIS_NAME_MAGICNO-25 "285343744.0000000000"
*MEAS_COND_AXIS_NAME_MAGICNO-26 "17301505.0000000000"
*MEAS_COND_AXIS_NAME_MAGICNO-27 "20971521.0000000000"
*MEAS_COND_AXIS_NAME_MAGICNO-28 "20971521.0000000000"
*MEAS_COND_AXIS_NAME_MAGICNO-29 "20971521.0000000000"
*MEAS_COND_AXIS_NAME_MAGICNO-30 "0.0000000000"
*MEAS_COND_AXIS_OFFSET-0 "-"
*MEAS_COND_AXIS_OFFSET-1 "-0.1081000000"
*MEAS_COND_AXIS_OFFSET-2 "0.3758000000"
*MEAS_COND_AXIS_OFFSET-3 "-"
*MEAS_COND_AXIS_OFFSET-4 "-"
*MEAS_COND_AXIS_OFFSET-5 "0.3758000000"
*MEAS_COND_AXIS_OFFSET-6 "-0.4839000000"
*MEAS_COND_AXIS_OFFSET-7 "-"
*MEAS_COND_AXIS_OFFSET-8 "-"
*MEAS_COND_AXIS_OFFSET-9 "-"
*MEAS_COND_AXIS_OFFSET-10 "-"
*MEAS_COND_AXIS_OFFSET-11 "-"
*MEAS_COND_AXIS_OFFSET-12 "-"
*MEAS_COND_AXIS_OFFSET-13 "-"
*MEAS_COND_AXIS_OFFSET-14 "-"
*MEAS_COND_AXIS_OFFSET-15 "-"
*MEAS_COND_AXIS_OFFSET-16 "-"
*MEAS_COND_AXIS_OFFSET-17 "-"
*MEAS_COND_AXIS_OFFSET-18 "-"
*MEAS_COND_AXIS_OFFSET-19 "-"
*MEAS_COND_AXIS_OFFSET-20 "-"
*MEAS_COND_AXIS_OFFSET-21 "-"
*MEAS_COND_AXIS_OFFSET-22 "-"
*MEAS_COND_AXIS_OFFSET-23 "-"
*MEAS_COND_AXIS_OFFSET-24 "-"
*MEAS_COND_AXIS_OFFSET-25 "-"
*MEAS_COND_AXIS_OFFSET-26 "-"
*MEAS_COND_AXIS_OFFSET-27 "-"
*MEAS_COND_AXIS_OFFSET-28 "-"
*MEAS_COND_AXIS_OFFSET-29 "-"
*MEAS_COND_AXIS_OFFSET-30 "-"
*MEAS_COND_AXIS_POSITION-0 "0.0000000000"
*MEAS_COND_AXIS_POSITION-1 "0.0000000000"
*MEAS_COND_AXIS_POSITION-2 "0.0000000000"
*MEAS_COND_AXIS_POSITION-3 "-0.5500000000"
*MEAS_COND_AXIS_POSITION-4 "0.0000000000"
*MEAS_COND_AXIS_POSITION-5 "0.0000000000"
*MEAS_COND_AXIS_POSITION-6 "0.0000000000"
*MEAS_COND_AXIS_POSITION-7 "-0.4278800000"
*MEAS_COND_AXIS_POSITION-8 "BB"
*MEAS_COND_AXIS_POSITION-9 "0.0000000000"
*MEAS_COND_AXIS_POSITION-10 "Soller_slit_5.0deg"
*MEAS_COND_AXIS_POSITION-11 "2/3deg"
*MEAS_COND_AXIS_POSITION-12 "2.2088000000"
*MEAS_COND_AXIS_POSITION-13 "-0.4140600000"
*MEAS_COND_AXIS_POSITION-14 "0.0000000000"
*MEAS_COND_AXIS_POSITION-15 "10.0mm"
*MEAS_COND_AXIS_POSITION-16 "None"
*MEAS_COND_AXIS_POSITION-17 "Cu_K-beta"
*MEAS_COND_AXIS_POSITION-18 "13.000mm"
*MEAS_COND_AXIS_POSITION-19 "13.000mm"
*MEAS_COND_AXIS_POSITION-20 "No_unit"
*MEAS_COND_AXIS_POSITION-21 "Soller_slit_5.0deg"
*MEAS_COND_AXIS_POSITION-22 "None"
*MEAS_COND_AXIS_POSITION-23 "13.0000000000"
*MEAS_COND_AXIS_POSITION-24 "13.0000000000"
*MEAS_COND_AXIS_POSITION-25 "0.0109400000"
*MEAS_COND_AXIS_POSITION-26 "Open"
*MEAS_COND_AXIS_POSITION-27 "None"
*MEAS_COND_AXIS_POSITION-28 "None"
*MEAS_COND_AXIS_POSITION-29 "None"
*MEAS_COND_AXIS_POSITION-30 "38.0000000000"
*MEAS_COND_AXIS_UNIT-0 "deg"
*MEAS_COND_AXIS_UNIT-1 "deg"
*MEAS_COND_AXIS_UNIT-2 "deg"
*MEAS_COND_AXIS_UNIT-3 "mm"
*MEAS_COND_AXIS_UNIT-4 "deg"
*MEAS_COND_AXIS_UNIT-5 "deg"
*MEAS_COND_AXIS_UNIT-6 "deg"
*MEAS_COND_AXIS_UNIT-7 "mm"
*MEAS_COND_AXIS_UNIT-8 ""
*MEAS_COND_AXIS_UNIT-9 "pulse"
*MEAS_COND_AXIS_UNIT-10 ""
*MEAS_COND_AXIS_UNIT-11 ""
*MEAS_COND_AXIS_UNIT-12 "mm"
*MEAS_COND_AXIS_UNIT-13 "mm"
*MEAS_COND_AXIS_UNIT-14 ""
*MEAS_COND_AXIS_UNIT-15 ""
*MEAS_COND_AXIS_UNIT-16 ""
*MEAS_COND_AXIS_UNIT-17 ""
*MEAS_COND_AXIS_UNIT-18 ""
*MEAS_COND_AXIS_UNIT-19 ""
*MEAS_COND_AXIS_UNIT-20 ""
*MEAS_COND_AXIS_UNIT-21 ""
*MEAS_COND_AXIS_UNIT-22 ""
*MEAS_COND_AXIS_UNIT-23 "mm"
*MEAS_COND_AXIS_UNIT-24 "mm"
*MEAS_COND_AXIS_UNIT-25 "mm"
*MEAS_COND_AXIS_UNIT-26 ""
*MEAS_COND_AXIS_UNIT-27 ""
*MEAS_COND_AXIS_UNIT-28 ""
*MEAS_COND_AXIS_UNIT-29 ""
*MEAS_COND_AXIS_UNIT-30 "div"
*MEAS_COND_COUNTER_CNTLOSS_CORR "0.0000000000"
*MEAS_COND_COUNTER_PHABASE "38.0000000000"
*MEAS_COND_COUNTER_PHAWINDOW "16.0000000000"
*MEAS_COND_COUNTER_PHA_UNIT "div"
*MEAS_COND_COUNTER_TAUDIFF "30.0000000000"
*MEAS_COND_COUNTER_TAUINT "0.0000000000"
*MEAS_COND_IRRADIATION_MODE "OFF"
*MEAS_COND_IRRADIATION_WIDTH ""
*MEAS_COND_OPT_ATTR "集中法"
*MEAS_COND_OPT_NAME "@集中法"
*MEAS_COND_UNSYMMETRIC_MODE "OFF"
*MEAS_COND_XG_CURRENT "30.0000000000"
*MEAS_COND_XG_VOLTAGE "40.0000000000"
*MEAS_COND_XG_WAVE_TYPE "Ka"
*MEAS_DATA_COUNT "5001.0000000000"
*MEAS_SCAN_AXIS_X "2θ/θ"
*MEAS_SCAN_AXIS_X_INTERNAL "TwoThetaTheta"
*MEAS_SCAN_END_TIME "07/14/21 16:44:32"
*MEAS_SCAN_MODE "CONTINUOUS"
*MEAS_SCAN_MONITOR "0"
*MEAS_SCAN_RESOLUTION_X "0.0002"
*MEAS_SCAN_SPEED "1.0"
*MEAS_SCAN_SPEED_UNIT "deg/min"
*MEAS_SCAN_START "20.0000000000"
*MEAS_SCAN_START_TIME "07/14/21 15:51:39"
*MEAS_SCAN_STEP "0.0100000000"
*MEAS_SCAN_STOP "70.0000000000"
*MEAS_SCAN_UNIT_X "deg"
*MEAS_SCAN_UNIT_Y "counts"
*RAS_HEADER_END
*RAS_INT_START
20.0000 1433.0000 1.0000
20.0400 1518.0000 1.0000
20.0800 1494.0000 1.0000
20.1200 1491.0000 1.0000
20.1600 1481.0000 1.0000
20.2000 1497.0000 1.0000
20.2400 1471.0000 1.0000
20.2800 1457.0000 1.0000
20.3200 1465.0000 1.0000
20.3600 1437.0000 1.0000
20.4000 1505.0000 1.0000
20.4400 1479.0000 1.0000
20.4800 1438.0000 1.0000
20.5200 1431.0000 1.0000
20.5600 1474.0000 1.0000
20.6000 1463.0000 1.0000
20.6400 1452.0000 1.0000
20.6800 1472.0000 1.0000
20.7200 1462.0000 1.0000
20.7600 1455.0000 1.0000
20.8000 1372.0000 1.0000
20.8400 1511.0000 1.0000
20.8800 1472.0000 1.0000
20.9200 1460.0000 1.0000
20.9600 1435.0000 1.0000
21.0000 1546.0000 1.0000
21.0400 1461.0000 1.0000
21.0800 1497.0000 1.0000
21.1200 1464.0000 1.0000
21.1600 1464.0000 1.0000
21.2000 1458.0000 1.0000
21.2400 1473.0000 1.0000
21.2800 1438.0000 1.0000
21.3200 1494.0000 1.0000
21.3600 1452.0000 1.0000
21.4000 1500.0000 1.0000
21.4400 1475.0000 1.0000
21.4800 1519.0000 1.0000
21.5200 1444.0000 1.0000
21.5600 1501.0000 1.0000
21.6000 1400.0000 1.0000
21.6400 1476.0000 1.0000
21.6800 1467.0000 1.0000
21.7200 1493.0000 1.0000
21.7600 1489.0000 1.0000
21.8000 1475.0000 1.0000
21.8400 1475.0000 1.0000
21.8800 1511.0000 1.0000
21.9200 1512.0000 1.0000
21.9600 1519.0000 1.0000
22.0000 1437.0000 1.0000
22.0400 1531.0000 1.0000
22.0800 1545.0000 1.0000
22.1200 1457.0000 1.0000
22.1600 1534.0000 1.0000
22.2000 1451.0000 1.0000
22.2400 1523.0000 1.0000
22.2800 1485.0000 1.0000
22.3200 1493.0000 1.0000
22.3600 1459.0000 1.0000
22.4000 1459.0000 1.0000
22.4400 1490.0000 1.0000
22.4800 1480.0000 1.0000
22.5200 1471.0000 1.0000
22.5600 1460.0000 1.0000
22.6000 1511.0000 1.0000
22.6400 1520.0000 1.0000
22.6800 1453.0000 1.0000
22.7200 1455.0000 1.0000
22.7600 1528.0000 1.0000
22.8000 1526.0000 1.0000
22.8400 1515.0000 1.0000
22.8800 1488.0000 1.0000
22.9200 1540.0000 1.0000
22.9600 1502.0000 1.0000
23.0000 1475.0000 1.0000
23.0400 1497.0000 1.0000
23.0800 1467.0000 1.0000
23.1200 1481.0000 1.0000
23.1600 1510.0000 1.0000
23.2000 1497.0000 1.0000
23.2400 1500.0000 1.0000
23.2800 1535.0000 1.0000
23.3200 1489.0000 1.0000
23.3600 1549.0000 1.0000
23.4000 1510.0000 1.0000
23.4400 1535.0000 1.0000
23.4800 1514.0000 1.0000
23.5200 1516.0000 1.0000
23.5600 1527.0000 1.0000
23.6000 1516.0000 1.0000
23.6400 1518.0000 1.0000
23.6800 1494.0000 1.0000
23.7200 1547.0000 1.0000
23.7600 1495.0000 1.0000
23.8000 1478.0000 1.0000
23.8400 1570.0000 1.0000
23.8800 1525.0000 1.0000
23.9200 1534.0000 1.0000
23.9600 1469.0000 1.0000
24.0000 1446.0000 1.0000
24.0400 1558.0000 1.0000
24.0800 1502.0000 1.0000
24.1200 1534.0000 1.0000
24.1600 1537.0000 1.0000
24.2000 1542.0000 1.0000
24.2400 1467.0000 1.0000
24.2800 1519.0000 1.0000
24.3200 1464.0000 1.0000
24.3600 1468.0000 1.0000
24.4000 1521.0000 1.0000
24.4400 1505.0000 1.0000
24.4800 1529.0000 1.0000
24.5200 1576.0000 1.0000
24.5600 1596.0000 1.0000
24.6000 1592.0000 1.0000
24.6400 1554.0000 1.0000
24.6800 1544.0000 1.0000
24.7200 1509.0000 1.0000
24.7600 1513.0000 1.0000
24.8000 1544.0000 1.0000
24.8400 1574.0000 1.0000
24.8800 1547.0000 1.0000
24.9200 1539.0000 1.0000
24.9600 1601.0000 1.0000
25.0000 1534.0000 1.0000
25.0400 1550.0000 1.0000
25.0800 1517.0000 1.0000
25.1200 1540.0000 1.0000
25.1600 1534.0000 1.0000
25.2000 1551.0000 1.0000
25.2400 1570.0000 1.0000
25.2800 1521.0000 1.0000
25.3200 1544.0000 1.0000
25.3600 1585.0000 1.0000
25.4000 1544.0000 1.0000
25.4400 1554.0000 1.0000
25.4800 1541.0000 1.0000
25.5200 1495.0000 1.0000
25.5600 1529.0000 1.0000
25.6000 1493.0000 1.0000
25.6400 1544.0000 1.0000
25.6800 1577.0000 1.0000
25.7200 1556.0000 1.0000
25.7600 1562.0000 1.0000
25.8000 1499.0000 1.0000
25.8400 1528.0000 1.0000
25.8800 1540.0000 1.0000
25.9200 1538.0000 1.0000
25.9600 1523.0000 1.0000
26.0000 1547.0000 1.0000
26.0400 1507.0000 1.0000
26.0800 1548.0000 1.0000
26.1200 1566.0000 1.0000
26.1600 1566.0000 1.0000
26.2000 1578.0000 1.0000
26.2400 1536.0000 1.0000
26.2800 1622.0000 1.0000
26.3200 1564.0000 1.0000
26.3600 1593.0000 1.0000
26.4000 1656.0000 1.0000
26.4400 1554.0000 1.0000
26.4800 1633.0000 1.0000
26.5200 1696.0000 1.0000
26.5600 1639.0000 1.0000
26.6000 1622.0000 1.0000
26.6400 1630.0000 1.0000
26.6800 1643.0000 1.0000
26.7200 1710.0000 1.0000
26.7600 1686.0000 1.0000
26.8000 1703.0000 1.0000
26.8400 1800.0000 1.0000
26.8800 1764.0000 1.0000
26.9200 1897.0000 1.0000
26.9600 1995.0000 1.0000
27.0000 2027.0000 1.0000
27.0400 2246.0000 1.0000
27.0800 2557.0000 1.0000
27.1200 2832.0000 1.0000
27.1600 3417.0000 1.0000
27.2000 4174.0000 1.0000
27.2400 5198.0000 1.0000
27.2800 6191.0000 1.0000
27.3200 6223.0000 1.0000
27.3600 5560.0000 1.0000
27.4000 4528.0000 1.0000
27.4400 3668.0000 1.0000
27.4800 2980.0000 1.0000
27.5200 2573.0000 1.0000
27.5600 2352.0000 1.0000
27.6000 2124.0000 1.0000
27.6400 2017.0000 1.0000
27.6800 1969.0000 1.0000
27.7200 1846.0000 1.0000
27.7600 1728.0000 1.0000
27.8000 1730.0000 1.0000
27.8400 1767.0000 1.0000
27.8800 1688.0000 1.0000
27.9200 1614.0000 1.0000
27.9600 1698.0000 1.0000
28.0000 1639.0000 1.0000
28.0400 1567.0000 1.0000
28.0800 1557.0000 1.0000
28.1200 1543.0000 1.0000
28.1600 1585.0000 1.0000
28.2000 1483.0000 1.0000
28.2400 1478.0000 1.0000
28.2800 1526.0000 1.0000
28.3200 1587.0000 1.0000
28.3600 1565.0000 1.0000
28.4000 1547.0000 1.0000
28.4400 1515.0000 1.0000
28.4800 1500.0000 1.0000
28.5200 1505.0000 1.0000
28.5600 1528.0000 1.0000
28.6000 1477.0000 1.0000
28.6400 1547.0000 1.0000
28.6800 1532.0000 1.0000
28.7200 1518.0000 1.0000
28.7600 1553.0000 1.0000
28.8000 1457.0000 1.0000
28.8400 1438.0000 1.0000
28.8800 1521.0000 1.0000
28.9200 1501.0000 1.0000
28.9600 1498.0000 1.0000
29.0000 1472.0000 1.0000
29.0400 1462.0000 1.0000
29.0800 1438.0000 1.0000
29.1200 1446.0000 1.0000
29.1600 1507.0000 1.0000
29.2000 1425.0000 1.0000
29.2400 1430.0000 1.0000
29.2800 1472.0000 1.0000
29.3200 1540.0000 1.0000
29.3600 1516.0000 1.0000
29.4000 1501.0000 1.0000
29.4400 1480.0000 1.0000
29.4800 1459.0000 1.0000
29.5200 1486.0000 1.0000
29.5600 1457.0000 1.0000
29.6000 1411.0000 1.0000
29.6400 1485.0000 1.0000
29.6800 1514.0000 1.0000
29.7200 1433.0000 1.0000
29.7600 1392.0000 1.0000
29.8000 1462.0000 1.0000
29.8400 1420.0000 1.0000
29.8800 1410.0000 1.0000
29.9200 1471.0000 1.0000
29.9600 1448.0000 1.0000
30.0000 1422.0000 1.0000
30.0400 1373.0000 1.0000
30.0800 1432.0000 1.0000
30.1200 1355.0000 1.0000
30.1600 1407.0000 1.0000
30.2000 1394.0000 1.0000
30.2400 1410.0000 1.0000
30.2800 1363.0000 1.0000
30.3200 1412.0000 1.0000
30.3600 1442.0000 1.0000
30.4000 1386.0000 1.0000
30.4400 1383.0000 1.0000
30.4800 1380.0000 1.0000
30.5200 1424.0000 1.0000
30.5600 1413.0000 1.0000
30.6000 1291.0000 1.0000
30.6400 1347.0000 1.0000
30.6800 1401.0000 1.0000
30.7200 1384.0000 1.0000
30.7600 1360.0000 1.0000
30.8000 1399.0000 1.0000
30.8400 1362.0000 1.0000
30.8800 1427.0000 1.0000
30.9200 1343.0000 1.0000
30.9600 1408.0000 1.0000
31.0000 1368.0000 1.0000
31.0400 1330.0000 1.0000
31.0800 1335.0000 1.0000
31.1200 1413.0000 1.0000
31.1600 1376.0000 1.0000
31.2000 1313.0000 1.0000
31.2400 1352.0000 1.0000
31.2800 1332.0000 1.0000
31.3200 1305.0000 1.0000
31.3600 1388.0000 1.0000
31.4000 1313.0000 1.0000
31.4400 1348.0000 1.0000
31.4800 1329.0000 1.0000
31.5200 1406.0000 1.0000
31.5600 1328.0000 1.0000
31.6000 1324.0000 1.0000
31.6400 1385.0000 1.0000
31.6800 1335.0000 1.0000
31.7200 1356.0000 1.0000
31.7600 1400.0000 1.0000
31.8000 1320.0000 1.0000
31.8400 1386.0000 1.0000
31.8800 1360.0000 1.0000
31.9200 1410.0000 1.0000
31.9600 1389.0000 1.0000
32.0000 1386.0000 1.0000
32.0400 1328.0000 1.0000
32.0800 1345.0000 1.0000
32.1200 1372.0000 1.0000
32.1600 1331.0000 1.0000
32.2000 1307.0000 1.0000
32.2400 1341.0000 1.0000
32.2800 1302.0000 1.0000
32.3200 1280.0000 1.0000
32.3600 1302.0000 1.0000
32.4000 1371.0000 1.0000
32.4400 1313.0000 1.0000
32.4800 1330.0000 1.0000
32.5200 1339.0000 1.0000
32.5600 1335.0000 1.0000
32.6000 1302.0000 1.0000
32.6400 1293.0000 1.0000
32.6800 1279.0000 1.0000
32.7200 1302.0000 1.0000
32.7600 1242.0000 1.0000
32.8000 1252.0000 1.0000
32.8400 1255.0000 1.0000
32.8800 1237.0000 1.0000
32.9200 1330.0000 1.0000
32.9600 1232.0000 1.0000
33.0000 1220.0000 1.0000
33.0400 1231.0000 1.0000
33.0800 1247.0000 1.0000
33.1200 1239.0000 1.0000
33.1600 1283.0000 1.0000
33.2000 1260.0000 1.0000
33.2400 1312.0000 1.0000
33.2800 1233.0000 1.0000
33.3200 1259.0000 1.0000
33.3600 1216.0000 1.0000
33.4000 1278.0000 1.0000
33.4400 1225.0000 1.0000
33.4800 1243.0000 1.0000
33.5200 1272.0000 1.0000
33.5600 1260.0000 1.0000
33.6000 1284.0000 1.0000
33.6400 1280.0000 1.0000
33.6800 1284.0000 1.0000
33.7200 1254.0000 1.0000
33.7600 1218.0000 1.0000
33.8000 1298.0000 1.0000
33.8400 1377.0000 1.0000
33.8800 1321.0000 1.0000
33.9200 1390.0000 1.0000
33.9600 1411.0000 1.0000
34.0000 1358.0000 1.0000
34.0400 1329.0000 1.0000
34.0800 1312.0000 1.0000
34.1200 1414.0000 1.0000
34.1600 1454.0000 1.0000
34.2000 1544.0000 1.0000
34.2400 1513.0000 1.0000
34.2800 1704.0000 1.0000
34.3200 1875.0000 1.0000
34.3600 2256.0000 1.0000
34.4000 2617.0000 1.0000
34.4400 3087.0000 1.0000
34.4800 3443.0000 1.0000
34.5200 3351.0000 1.0000
34.5600 3077.0000 1.0000
34.6000 2640.0000 1.0000
34.6400 2338.0000 1.0000
34.6800 1943.0000 1.0000
34.7200 1720.0000 1.0000
34.7600 1603.0000 1.0000
34.8000 1480.0000 1.0000
34.8400 1396.0000 1.0000
34.8800 1291.0000 1.0000
34.9200 1284.0000 1.0000
34.9600 1243.0000 1.0000
35.0000 1216.0000 1.0000
35.0400 1253.0000 1.0000
35.0800 1214.0000 1.0000
35.1200 1153.0000 1.0000
35.1600 1185.0000 1.0000
35.2000 1221.0000 1.0000
35.2400 1160.0000 1.0000
35.2800 1193.0000 1.0000
35.3200 1133.0000 1.0000
35.3600 1111.0000 1.0000
35.4000 1115.0000 1.0000
35.4400 1134.0000 1.0000
35.4800 1085.0000 1.0000
35.5200 1077.0000 1.0000
35.5600 1039.0000 1.0000
35.6000 1047.0000 1.0000
35.6400 1161.0000 1.0000
35.6800 1082.0000 1.0000
35.7200 1059.0000 1.0000
35.7600 1096.0000 1.0000
35.8000 1020.0000 1.0000
35.8400 1068.0000 1.0000
35.8800 1027.0000 1.0000
35.9200 1050.0000 1.0000
35.9600 1116.0000 1.0000
36.0000 1048.0000 1.0000
36.0400 1111.0000 1.0000
36.0800 1113.0000 1.0000
36.1200 988.0000 1.0000
36.1600 1052.0000 1.0000
36.2000 1107.0000 1.0000
36.2400 1117.0000 1.0000
36.2800 1145.0000 1.0000
36.3200 1137.0000 1.0000
36.3600 1091.0000 1.0000
36.4000 1230.0000 1.0000
36.4400 1208.0000 1.0000
36.4800 1109.0000 1.0000
36.5200 1129.0000 1.0000
36.5600 1088.0000 1.0000
36.6000 1093.0000 1.0000
36.6400 1103.0000 1.0000
36.6800 1029.0000 1.0000
36.7200 989.0000 1.0000
36.7600 984.0000 1.0000
36.8000 978.0000 1.0000
36.8400 981.0000 1.0000
36.8800 1040.0000 1.0000
36.9200 1003.0000 1.0000
36.9600 959.0000 1.0000
37.0000 996.0000 1.0000
37.0400 992.0000 1.0000
37.0800 972.0000 1.0000
37.1200 919.0000 1.0000
37.1600 975.0000 1.0000
37.2000 968.0000 1.0000
37.2400 972.0000 1.0000
37.2800 914.0000 1.0000
37.3200 956.0000 1.0000
37.3600 940.0000 1.0000
37.4000 991.0000 1.0000
37.4400 972.0000 1.0000
37.4800 979.0000 1.0000
37.5200 1004.0000 1.0000
37.5600 990.0000 1.0000
37.6000 964.0000 1.0000
37.6400 962.0000 1.0000
37.6800 990.0000 1.0000
37.7200 982.0000 1.0000
37.7600 1008.0000 1.0000
37.8000 983.0000 1.0000
37.8400 961.0000 1.0000
37.8800 947.0000 1.0000
37.9200 1027.0000 1.0000
37.9600 1027.0000 1.0000
38.0000 1009.0000 1.0000
38.0400 1092.0000 1.0000
38.0800 1086.0000 1.0000
38.1200 1148.0000 1.0000
38.1600 1274.0000 1.0000
38.2000 1324.0000 1.0000
38.2400 1507.0000 1.0000
38.2800 1671.0000 1.0000
38.3200 1990.0000 1.0000
38.3600 2454.0000 1.0000
38.4000 3225.0000 1.0000
38.4400 4214.0000 1.0000
38.4800 5538.0000 1.0000
38.5200 6139.0000 1.0000
38.5600 6043.0000 1.0000
38.6000 5304.0000 1.0000
38.6400 4307.0000 1.0000
38.6800 3387.0000 1.0000
38.7200 2620.0000 1.0000
38.7600 2115.0000 1.0000
38.8000 1618.0000 1.0000
38.8400 1424.0000 1.0000
38.8800 1249.0000 1.0000
38.9200 1109.0000 1.0000
38.9600 1070.0000 1.0000
39.0000 998.0000 1.0000
39.0400 1004.0000 1.0000
39.0800 908.0000 1.0000
39.1200 914.0000 1.0000
39.1600 938.0000 1.0000
39.2000 956.0000 1.0000
39.2400 880.0000 1.0000
39.2800 889.0000 1.0000
39.3200 867.0000 1.0000
39.3600 916.0000 1.0000
39.4000 878.0000 1.0000
39.4400 886.0000 1.0000
39.4800 889.0000 1.0000
39.5200 925.0000 1.0000
39.5600 936.0000 1.0000
39.6000 938.0000 1.0000
39.6400 861.0000 1.0000
39.6800 890.0000 1.0000
39.7200 902.0000 1.0000
39.7600 867.0000 1.0000
39.8000 847.0000 1.0000
39.8400 863.0000 1.0000
39.8800 858.0000 1.0000
39.9200 801.0000 1.0000
39.9600 820.0000 1.0000
40.0000 817.0000 1.0000
40.0400 840.0000 1.0000
40.0800 834.0000 1.0000
40.1200 810.0000 1.0000
40.1600 836.0000 1.0000
40.2000 809.0000 1.0000
40.2400 793.0000 1.0000
40.2800 844.0000 1.0000
40.3200 840.0000 1.0000
40.3600 838.0000 1.0000
40.4000 789.0000 1.0000
40.4400 772.0000 1.0000
40.4800 811.0000 1.0000
40.5200 830.0000 1.0000
40.5600 793.0000 1.0000
40.6000 776.0000 1.0000
40.6400 780.0000 1.0000
40.6800 796.0000 1.0000
40.7200 761.0000 1.0000
40.7600 764.0000 1.0000
40.8000 827.0000 1.0000
40.8400 765.0000 1.0000
40.8800 772.0000 1.0000
40.9200 776.0000 1.0000
40.9600 798.0000 1.0000
41.0000 787.0000 1.0000
41.0400 738.0000 1.0000
41.0800 832.0000 1.0000
41.1200 762.0000 1.0000
41.1600 755.0000 1.0000
41.2000 816.0000 1.0000
41.2400 793.0000 1.0000
41.2800 762.0000 1.0000
41.3200 813.0000 1.0000
41.3600 744.0000 1.0000
41.4000 783.0000 1.0000
41.4400 778.0000 1.0000
41.4800 778.0000 1.0000
41.5200 763.0000 1.0000
41.5600 767.0000 1.0000
41.6000 760.0000 1.0000
41.6400 829.0000 1.0000
41.6800 773.0000 1.0000
41.7200 769.0000 1.0000
41.7600 772.0000 1.0000
41.8000 809.0000 1.0000
41.8400 755.0000 1.0000
41.8800 754.0000 1.0000
41.9200 776.0000 1.0000
41.9600 783.0000 1.0000
42.0000 817.0000 1.0000
42.0400 777.0000 1.0000
42.0800 758.0000 1.0000
42.1200 787.0000 1.0000
42.1600 732.0000 1.0000
42.2000 738.0000 1.0000
42.2400 764.0000 1.0000
42.2800 833.0000 1.0000
42.3200 801.0000 1.0000
42.3600 754.0000 1.0000
42.4000 786.0000 1.0000
42.4400 775.0000 1.0000
42.4800 780.0000 1.0000
42.5200 771.0000 1.0000
42.5600 740.0000 1.0000
42.6000 761.0000 1.0000
42.6400 780.0000 1.0000
42.6800 738.0000 1.0000
42.7200 781.0000 1.0000
42.7600 773.0000 1.0000
42.8000 769.0000 1.0000
42.8400 745.0000 1.0000
42.8800 754.0000 1.0000
42.9200 774.0000 1.0000
42.9600 763.0000 1.0000
43.0000 740.0000 1.0000
43.0400 768.0000 1.0000
43.0800 787.0000 1.0000
43.1200 828.0000 1.0000
43.1600 832.0000 1.0000
43.2000 860.0000 1.0000
43.2400 847.0000 1.0000
43.2800 866.0000 1.0000
43.3200 841.0000 1.0000
43.3600 829.0000 1.0000
43.4000 789.0000 1.0000
43.4400 795.0000 1.0000
43.4800 753.0000 1.0000
43.5200 769.0000 1.0000
43.5600 759.0000 1.0000
43.6000 703.0000 1.0000
43.6400 772.0000 1.0000
43.6800 756.0000 1.0000
43.7200 704.0000 1.0000
43.7600 761.0000 1.0000
43.8000 797.0000 1.0000
43.8400 739.0000 1.0000
43.8800 754.0000 1.0000
43.9200 782.0000 1.0000
43.9600 747.0000 1.0000
44.0000 768.0000 1.0000
44.0400 775.0000 1.0000
44.0800 772.0000 1.0000
44.1200 758.0000 1.0000
44.1600 710.0000 1.0000
44.2000 757.0000 1.0000
44.2400 747.0000 1.0000
44.2800 768.0000 1.0000
44.3200 751.0000 1.0000
44.3600 708.0000 1.0000
44.4000 756.0000 1.0000
44.4400 731.0000 1.0000
44.4800 710.0000 1.0000
44.5200 731.0000 1.0000
44.5600 725.0000 1.0000
44.6000 732.0000 1.0000
44.6400 779.0000 1.0000
44.6800 714.0000 1.0000
44.7200 735.0000 1.0000
44.7600 698.0000 1.0000
44.8000 708.0000 1.0000
44.8400 693.0000 1.0000
44.8800 710.0000 1.0000
44.9200 707.0000 1.0000
44.9600 750.0000 1.0000
45.0000 734.0000 1.0000
45.0400 704.0000 1.0000
45.0800 710.0000 1.0000
45.1200 737.0000 1.0000
45.1600 714.0000 1.0000
45.2000 742.0000 1.0000
45.2400 740.0000 1.0000
45.2800 710.0000 1.0000
45.3200 758.0000 1.0000
45.3600 719.0000 1.0000
45.4000 681.0000 1.0000
45.4400 720.0000 1.0000
45.4800 704.0000 1.0000
45.5200 731.0000 1.0000
45.5600 703.0000 1.0000
45.6000 721.0000 1.0000
45.6400 715.0000 1.0000
45.6800 708.0000 1.0000
45.7200 726.0000 1.0000
45.7600 716.0000 1.0000
45.8000 712.0000 1.0000
45.8400 737.0000 1.0000
45.8800 714.0000 1.0000
45.9200 714.0000 1.0000
45.9600 717.0000 1.0000
46.0000 721.0000 1.0000
46.0400 713.0000 1.0000
46.0800 681.0000 1.0000
46.1200 672.0000 1.0000
46.1600 695.0000 1.0000
46.2000 681.0000 1.0000
46.2400 697.0000 1.0000
46.2800 707.0000 1.0000
46.3200 718.0000 1.0000
46.3600 692.0000 1.0000
46.4000 706.0000 1.0000
46.4400 700.0000 1.0000
46.4800 694.0000 1.0000
46.5200 684.0000 1.0000
46.5600 688.0000 1.0000
46.6000 693.0000 1.0000
46.6400 716.0000 1.0000
46.6800 691.0000 1.0000
46.7200 689.0000 1.0000
46.7600 688.0000 1.0000
46.8000 732.0000 1.0000
46.8400 710.0000 1.0000
46.8800 739.0000 1.0000
46.9200 745.0000 1.0000
46.9600 701.0000 1.0000
47.0000 713.0000 1.0000
47.0400 715.0000 1.0000
47.0800 662.0000 1.0000
47.1200 723.0000 1.0000
47.1600 701.0000 1.0000
47.2000 667.0000 1.0000
47.2400 662.0000 1.0000
47.2800 674.0000 1.0000
47.3200 731.0000 1.0000
47.3600 709.0000 1.0000
47.4000 694.0000 1.0000
47.4400 647.0000 1.0000
47.4800 676.0000 1.0000
47.5200 672.0000 1.0000
47.5600 682.0000 1.0000
47.6000 711.0000 1.0000
47.6400 721.0000 1.0000
47.6800 673.0000 1.0000
47.7200 655.0000 1.0000
47.7600 657.0000 1.0000
47.8000 678.0000 1.0000
47.8400 649.0000 1.0000
47.8800 650.0000 1.0000
47.9200 652.0000 1.0000
47.9600 679.0000 1.0000
48.0000 715.0000 1.0000
48.0400 663.0000 1.0000
48.0800 673.0000 1.0000
48.1200 703.0000 1.0000
48.1600 692.0000 1.0000
48.2000 624.0000 1.0000
48.2400 660.0000 1.0000
48.2800 665.0000 1.0000
48.3200 666.0000 1.0000
48.3600 677.0000 1.0000
48.4000 670.0000 1.0000
48.4400 633.0000 1.0000
48.4800 639.0000 1.0000
48.5200 652.0000 1.0000
48.5600 655.0000 1.0000
48.6000 682.0000 1.0000
48.6400 646.0000 1.0000
48.6800 658.0000 1.0000
48.7200 624.0000 1.0000
48.7600 635.0000 1.0000
48.8000 608.0000 1.0000
48.8400 645.0000 1.0000
48.8800 639.0000 1.0000
48.9200 643.0000 1.0000
48.9600 647.0000 1.0000
49.0000 617.0000 1.0000
49.0400 654.0000 1.0000
49.0800 704.0000 1.0000
49.1200 668.0000 1.0000
49.1600 617.0000 1.0000
49.2000 694.0000 1.0000
49.2400 632.0000 1.0000
49.2800 670.0000 1.0000
49.3200 641.0000 1.0000
49.3600 619.0000 1.0000
49.4000 640.0000 1.0000
49.4400 666.0000 1.0000
49.4800 667.0000 1.0000
49.5200 656.0000 1.0000
49.5600 665.0000 1.0000
49.6000 674.0000 1.0000
49.6400 610.0000 1.0000
49.6800 640.0000 1.0000
49.7200 644.0000 1.0000
49.7600 637.0000 1.0000
49.8000 619.0000 1.0000
49.8400 652.0000 1.0000
49.8800 643.0000 1.0000
49.9200 638.0000 1.0000
49.9600 655.0000 1.0000
50.0000 650.0000 1.0000
50.0400 652.0000 1.0000
50.0800 658.0000 1.0000
50.1200 655.0000 1.0000
50.1600 647.0000 1.0000
50.2000 657.0000 1.0000
50.2400 657.0000 1.0000
50.2800 670.0000 1.0000
50.3200 634.0000 1.0000
50.3600 649.0000 1.0000
50.4000 694.0000 1.0000
50.4400 684.0000 1.0000
50.4800 676.0000 1.0000
50.5200 680.0000 1.0000
50.5600 651.0000 1.0000
50.6000 657.0000 1.0000
50.6400 656.0000 1.0000
50.6800 638.0000 1.0000
50.7200 658.0000 1.0000
50.7600 636.0000 1.0000
50.8000 646.0000 1.0000
50.8400 624.0000 1.0000
50.8800 646.0000 1.0000
50.9200 676.0000 1.0000
50.9600 705.0000 1.0000
51.0000 656.0000 1.0000
51.0400 681.0000 1.0000
51.0800 676.0000 1.0000
51.1200 620.0000 1.0000
51.1600 664.0000 1.0000
51.2000 660.0000 1.0000
51.2400 679.0000 1.0000
51.2800 639.0000 1.0000
51.3200 643.0000 1.0000
51.3600 684.0000 1.0000
51.4000 672.0000 1.0000
51.4400 682.0000 1.0000
51.4800 706.0000 1.0000
51.5200 682.0000 1.0000
51.5600 687.0000 1.0000
51.6000 692.0000 1.0000
51.6400 731.0000 1.0000
51.6800 698.0000 1.0000
51.7200 711.0000 1.0000
51.7600 763.0000 1.0000
51.8000 799.0000 1.0000
51.8400 787.0000 1.0000
51.8800 818.0000 1.0000
51.9200 912.0000 1.0000
51.9600 1067.0000 1.0000
52.0000 1143.0000 1.0000
52.0400 1325.0000 1.0000
52.0800 1586.0000 1.0000
52.1200 2202.0000 1.0000
52.1600 2915.0000 1.0000
52.2000 4280.0000 1.0000
52.2400 5444.0000 1.0000
52.2800 5638.0000 1.0000
52.3200 4895.0000 1.0000
52.3600 4593.0000 1.0000
52.4000 4106.0000 1.0000
52.4400 3284.0000 1.0000
52.4800 2402.0000 1.0000
52.5200 1814.0000 1.0000
52.5600 1430.0000 1.0000
52.6000 1213.0000 1.0000
52.6400 1011.0000 1.0000
52.6800 918.0000 1.0000
52.7200 908.0000 1.0000
52.7600 808.0000 1.0000
52.8000 794.0000 1.0000
52.8400 753.0000 1.0000
52.8800 778.0000 1.0000
52.9200 736.0000 1.0000
52.9600 779.0000 1.0000
53.0000 669.0000 1.0000
53.0400 670.0000 1.0000
53.0800 645.0000 1.0000
53.1200 715.0000 1.0000
53.1600 700.0000 1.0000
53.2000 693.0000 1.0000
53.2400 621.0000 1.0000
53.2800 646.0000 1.0000
53.3200 671.0000 1.0000
53.3600 662.0000 1.0000
53.4000 658.0000 1.0000
53.4400 681.0000 1.0000
53.4800 608.0000 1.0000
53.5200 675.0000 1.0000
53.5600 673.0000 1.0000
53.6000 623.0000 1.0000
53.6400 632.0000 1.0000
53.6800 657.0000 1.0000
53.7200 611.0000 1.0000
53.7600 653.0000 1.0000
53.8000 655.0000 1.0000
53.8400 658.0000 1.0000
53.8800 648.0000 1.0000
53.9200 655.0000 1.0000
53.9600 634.0000 1.0000
54.0000 617.0000 1.0000
54.0400 629.0000 1.0000
54.0800 628.0000 1.0000
54.1200 599.0000 1.0000
54.1600 651.0000 1.0000
54.2000 633.0000 1.0000
54.2400 621.0000 1.0000
54.2800 605.0000 1.0000
54.3200 664.0000 1.0000
54.3600 666.0000 1.0000
54.4000 633.0000 1.0000
54.4400 652.0000 1.0000
54.4800 638.0000 1.0000
54.5200 665.0000 1.0000
54.5600 682.0000 1.0000
54.6000 637.0000 1.0000
54.6400 623.0000 1.0000
54.6800 646.0000 1.0000
54.7200 644.0000 1.0000
54.7600 702.0000 1.0000
54.8000 658.0000 1.0000
54.8400 668.0000 1.0000
54.8800 681.0000 1.0000
54.9200 686.0000 1.0000
54.9600 681.0000 1.0000
55.0000 719.0000 1.0000
55.0400 710.0000 1.0000
55.0800 746.0000 1.0000
55.1200 767.0000 1.0000
55.1600 832.0000 1.0000
55.2000 944.0000 1.0000
55.2400 1040.0000 1.0000
55.2800 1030.0000 1.0000
55.3200 1024.0000 1.0000
55.3600 985.0000 1.0000
55.4000 899.0000 1.0000
55.4400 897.0000 1.0000
55.4800 855.0000 1.0000
55.5200 797.0000 1.0000
55.5600 790.0000 1.0000
55.6000 733.0000 1.0000
55.6400 702.0000 1.0000
55.6800 683.0000 1.0000
55.7200 692.0000 1.0000
55.7600 656.0000 1.0000
55.8000 657.0000 1.0000
55.8400 674.0000 1.0000
55.8800 635.0000 1.0000
55.9200 629.0000 1.0000
55.9600 630.0000 1.0000
56.0000 617.0000 1.0000
56.0400 640.0000 1.0000
56.0800 634.0000 1.0000
56.1200 632.0000 1.0000
56.1600 635.0000 1.0000
56.2000 654.0000 1.0000
56.2400 620.0000 1.0000
56.2800 565.0000 1.0000
56.3200 634.0000 1.0000
56.3600 616.0000 1.0000
56.4000 588.0000 1.0000
56.4400 596.0000 1.0000
56.4800 597.0000 1.0000
56.5200 603.0000 1.0000
56.5600 596.0000 1.0000
56.6000 582.0000 1.0000
56.6400 598.0000 1.0000
56.6800 631.0000 1.0000
56.7200 644.0000 1.0000
56.7600 615.0000 1.0000
56.8000 662.0000 1.0000
56.8400 603.0000 1.0000
56.8800 583.0000 1.0000
56.9200 599.0000 1.0000
56.9600 574.0000 1.0000
57.0000 608.0000 1.0000
57.0400 647.0000 1.0000
57.0800 627.0000 1.0000
57.1200 612.0000 1.0000
57.1600 614.0000 1.0000
57.2000 622.0000 1.0000
57.2400 647.0000 1.0000
57.2800 583.0000 1.0000
57.3200 596.0000 1.0000
57.3600 594.0000 1.0000
57.4000 616.0000 1.0000
57.4400 628.0000 1.0000
57.4800 632.0000 1.0000
57.5200 616.0000 1.0000
57.5600 603.0000 1.0000
57.6000 588.0000 1.0000
57.6400 654.0000 1.0000
57.6800 582.0000 1.0000
57.7200 582.0000 1.0000
57.7600 594.0000 1.0000
57.8000 616.0000 1.0000
57.8400 634.0000 1.0000
57.8800 613.0000 1.0000
57.9200 599.0000 1.0000
57.9600 579.0000 1.0000
58.0000 625.0000 1.0000
58.0400 608.0000 1.0000
58.0800 660.0000 1.0000
58.1200 622.0000 1.0000
58.1600 603.0000 1.0000
58.2000 621.0000 1.0000
58.2400 627.0000 1.0000
58.2800 609.0000 1.0000
58.3200 609.0000 1.0000
58.3600 638.0000 1.0000
58.4000 623.0000 1.0000
58.4400 588.0000 1.0000
58.4800 618.0000 1.0000
58.5200 578.0000 1.0000
58.5600 607.0000 1.0000
58.6000 596.0000 1.0000
58.6400 621.0000 1.0000
58.6800 604.0000 1.0000
58.7200 625.0000 1.0000
58.7600 597.0000 1.0000
58.8000 576.0000 1.0000
58.8400 585.0000 1.0000
58.8800 605.0000 1.0000
58.9200 616.0000 1.0000
58.9600 622.0000 1.0000
59.0000 661.0000 1.0000
59.0400 591.0000 1.0000
59.0800 597.0000 1.0000
59.1200 584.0000 1.0000
59.1600 585.0000 1.0000
59.2000 636.0000 1.0000
59.2400 624.0000 1.0000
59.2800 650.0000 1.0000
59.3200 626.0000 1.0000
59.3600 603.0000 1.0000
59.4000 612.0000 1.0000
59.4400 607.0000 1.0000
59.4800 625.0000 1.0000
59.5200 614.0000 1.0000
59.5600 595.0000 1.0000
59.6000 635.0000 1.0000
59.6400 599.0000 1.0000
59.6800 597.0000 1.0000
59.7200 572.0000 1.0000
59.7600 627.0000 1.0000
59.8000 619.0000 1.0000
59.8400 621.0000 1.0000
59.8800 607.0000 1.0000
59.9200 628.0000 1.0000
59.9600 603.0000 1.0000
60.0000 615.0000 1.0000
60.0400 626.0000 1.0000
60.0800 608.0000 1.0000
60.1200 600.0000 1.0000
60.1600 588.0000 1.0000
60.2000 594.0000 1.0000
60.2400 603.0000 1.0000
60.2800 615.0000 1.0000
60.3200 627.0000 1.0000
60.3600 607.0000 1.0000
60.4000 588.0000 1.0000
60.4400 588.0000 1.0000
60.4800 597.0000 1.0000
60.5200 562.0000 1.0000
60.5600 620.0000 1.0000
60.6000 581.0000 1.0000
60.6400 582.0000 1.0000
60.6800 593.0000 1.0000
60.7200 583.0000 1.0000
60.7600 625.0000 1.0000
60.8000 627.0000 1.0000
60.8400 621.0000 1.0000
60.8800 561.0000 1.0000
60.9200 598.0000 1.0000
60.9600 565.0000 1.0000
61.0000 611.0000 1.0000
61.0400 613.0000 1.0000
61.0800 598.0000 1.0000
61.1200 611.0000 1.0000
61.1600 572.0000 1.0000
61.2000 646.0000 1.0000
61.2400 565.0000 1.0000
61.2800 613.0000 1.0000
61.3200 596.0000 1.0000
61.3600 628.0000 1.0000
61.4000 633.0000 1.0000
61.4400 609.0000 1.0000
61.4800 662.0000 1.0000
61.5200 592.0000 1.0000
61.5600 631.0000 1.0000
61.6000 621.0000 1.0000
61.6400 662.0000 1.0000
61.6800 603.0000 1.0000
61.7200 631.0000 1.0000
61.7600 646.0000 1.0000
61.8000 661.0000 1.0000
61.8400 637.0000 1.0000
61.8800 707.0000 1.0000
61.9200 738.0000 1.0000
61.9600 747.0000 1.0000
62.0000 802.0000 1.0000
62.0400 854.0000 1.0000
62.0800 898.0000 1.0000
62.1200 992.0000 1.0000
62.1600 1089.0000 1.0000
62.2000 1324.0000 1.0000
62.2400 1403.0000 1.0000
62.2800 1437.0000 1.0000
62.3200 1430.0000 1.0000
62.3600 1397.0000 1.0000
62.4000 1330.0000 1.0000
62.4400 1270.0000 1.0000
62.4800 1215.0000 1.0000
62.5200 1013.0000 1.0000
62.5600 943.0000 1.0000
62.6000 891.0000 1.0000
62.6400 831.0000 1.0000
62.6800 812.0000 1.0000
62.7200 749.0000 1.0000
62.7600 695.0000 1.0000
62.8000 700.0000 1.0000
62.8400 649.0000 1.0000
62.8800 665.0000 1.0000
62.9200 681.0000 1.0000
62.9600 654.0000 1.0000
63.0000 632.0000 1.0000
63.0400 686.0000 1.0000
63.0800 628.0000 1.0000
63.1200 652.0000 1.0000
63.1600 658.0000 1.0000
63.2000 633.0000 1.0000
63.2400 634.0000 1.0000
63.2800 610.0000 1.0000
63.3200 668.0000 1.0000
63.3600 645.0000 1.0000
63.4000 620.0000 1.0000
63.4400 569.0000 1.0000
63.4800 614.0000 1.0000
63.5200 628.0000 1.0000
63.5600 647.0000 1.0000
63.6000 610.0000 1.0000
63.6400 620.0000 1.0000
63.6800 647.0000 1.0000
63.7200 615.0000 1.0000
63.7600 596.0000 1.0000
63.8000 602.0000 1.0000
63.8400 616.0000 1.0000
63.8800 624.0000 1.0000
63.9200 649.0000 1.0000
63.9600 605.0000 1.0000
64.0000 636.0000 1.0000
64.0400 603.0000 1.0000
64.0800 626.0000 1.0000
64.1200 615.0000 1.0000
64.1600 611.0000 1.0000
64.2000 621.0000 1.0000
64.2400 595.0000 1.0000
64.2800 594.0000 1.0000
64.3200 592.0000 1.0000
64.3600 625.0000 1.0000
64.4000 640.0000 1.0000
64.4400 614.0000 1.0000
64.4800 617.0000 1.0000
64.5200 662.0000 1.0000
64.5600 642.0000 1.0000
64.6000 642.0000 1.0000
64.6400 628.0000 1.0000
64.6800 663.0000 1.0000
64.7200 612.0000 1.0000
64.7600 654.0000 1.0000
64.8000 676.0000 1.0000
64.8400 654.0000 1.0000
64.8800 655.0000 1.0000
64.9200 687.0000 1.0000
64.9600 678.0000 1.0000
65.0000 640.0000 1.0000
65.0400 665.0000 1.0000
65.0800 656.0000 1.0000
65.1200 680.0000 1.0000
65.1600 652.0000 1.0000
65.2000 671.0000 1.0000
65.2400 655.0000 1.0000
65.2800 664.0000 1.0000
65.3200 635.0000 1.0000
65.3600 650.0000 1.0000
65.4000 613.0000 1.0000
65.4400 659.0000 1.0000
65.4800 600.0000 1.0000
65.5200 659.0000 1.0000
65.5600 642.0000 1.0000
65.6000 654.0000 1.0000
65.6400 655.0000 1.0000
65.6800 681.0000 1.0000
65.7200 668.0000 1.0000
65.7600 697.0000 1.0000
65.8000 729.0000 1.0000
65.8400 700.0000 1.0000
65.8800 744.0000 1.0000
65.9200 802.0000 1.0000
65.9600 924.0000 1.0000
66.0000 968.0000 1.0000
66.0400 1116.0000 1.0000
66.0800 1356.0000 1.0000
66.1200 1668.0000 1.0000
66.1600 2122.0000 1.0000
66.2000 2541.0000 1.0000
66.2400 2812.0000 1.0000
66.2800 2734.0000 1.0000
66.3200 2496.0000 1.0000
66.3600 2353.0000 1.0000
66.4000 2221.0000 1.0000
66.4400 2026.0000 1.0000
66.4800 1788.0000 1.0000
66.5200 1509.0000 1.0000
66.5600 1204.0000 1.0000
66.6000 1055.0000 1.0000
66.6400 1017.0000 1.0000
66.6800 863.0000 1.0000
66.7200 796.0000 1.0000
66.7600 717.0000 1.0000
66.8000 715.0000 1.0000
66.8400 722.0000 1.0000
66.8800 649.0000 1.0000
66.9200 653.0000 1.0000
66.9600 621.0000 1.0000
67.0000 633.0000 1.0000
67.0400 592.0000 1.0000
67.0800 616.0000 1.0000
67.1200 585.0000 1.0000
67.1600 638.0000 1.0000
67.2000 570.0000 1.0000
67.2400 600.0000 1.0000
67.2800 557.0000 1.0000
67.3200 594.0000 1.0000
67.3600 602.0000 1.0000
67.4000 569.0000 1.0000
67.4400 601.0000 1.0000
67.4800 602.0000 1.0000
67.5200 547.0000 1.0000
67.5600 578.0000 1.0000
67.6000 571.0000 1.0000
67.6400 570.0000 1.0000
67.6800 569.0000 1.0000
67.7200 581.0000 1.0000
67.7600 533.0000 1.0000
67.8000 563.0000 1.0000
67.8400 570.0000 1.0000
67.8800 539.0000 1.0000
67.9200 557.0000 1.0000
67.9600 546.0000 1.0000
68.0000 566.0000 1.0000
68.0400 570.0000 1.0000
68.0800 536.0000 1.0000
68.1200 601.0000 1.0000
68.1600 539.0000 1.0000
68.2000 531.0000 1.0000
68.2400 567.0000 1.0000
68.2800 541.0000 1.0000
68.3200 539.0000 1.0000
68.3600 536.0000 1.0000
68.4000 556.0000 1.0000
68.4400 526.0000 1.0000
68.4800 504.0000 1.0000
68.5200 544.0000 1.0000
68.5600 579.0000 1.0000
68.6000 530.0000 1.0000
68.6400 562.0000 1.0000
68.6800 530.0000 1.0000
68.7200 515.0000 1.0000
68.7600 557.0000 1.0000
68.8000 519.0000 1.0000
68.8400 540.0000 1.0000
68.8800 535.0000 1.0000
68.9200 556.0000 1.0000
68.9600 540.0000 1.0000
69.0000 554.0000 1.0000
69.0400 534.0000 1.0000
69.0800 527.0000 1.0000
69.1200 551.0000 1.0000
69.1600 513.0000 1.0000
69.2000 546.0000 1.0000
69.2400 533.0000 1.0000
69.2800 530.0000 1.0000
69.3200 577.0000 1.0000
69.3600 528.0000 1.0000
69.4000 537.0000 1.0000
69.4400 542.0000 1.0000
69.4800 529.0000 1.0000
69.5200 533.0000 1.0000
69.5600 519.0000 1.0000
69.6000 532.0000 1.0000
69.6400 512.0000 1.0000
69.6800 544.0000 1.0000
69.7200 545.0000 1.0000
69.7600 576.0000 1.0000
69.8000 506.0000 1.0000
69.8400 511.0000 1.0000
69.8800 519.0000 1.0000
69.9200 516.0000 1.0000
69.9600 523.0000 1.0000
70.0000 516.0000 1.0000
*RAS_INT_END
*RAS_TEMPERATURE_START
*RAS_TEMPERATURE_END
*RAS_DATA_END