File: Section2_75_samples/XRD/No_065_HS2_1.ras
*RAS_DATA_START
*RAS_HEADER_START
*DISP_FMT_X "%.2f"
*DISP_FMT_Y "%.0f"
*DISP_FULLSCALE "13034.0000000000"
*DISP_LINE_COLOR "255.0000000000"
*DISP_LINE_STYLE "0.0000000000"
*DISP_LINE_WIDTH "0.2500000000"
*DISP_NOTE "測定データ-8"
*DISP_OFFSET_Y "0.0000000000"
*DISP_PEAKSEARCH_UNIT_Y "cps"
*DISP_RANGE_BOTTOM "0.0000000000"
*DISP_RANGE_LEFT "20.0000000000"
*DISP_RANGE_LOGCUTOFF "0.0100000000"
*DISP_RANGE_RIGHT "70.0000000000"
*DISP_RANGE_TOP "13034.0000000000"
*DISP_SCALE_MODE_Y "0.0000000000"
*DISP_TAB_NAME "2θ/θ"
*DISP_TITLE_Y "強度"
*DISP_UNIT_Y "cps"
*DISP_WINDOW_NAME "MSG_MACROENGINE"
*FILE_COMMENT " "
*FILE_MD5 ""
*FILE_MEMO " "
*FILE_OPERATOR "Administrator"
*FILE_SAMPLE " "
*FILE_TYPE "RAS_RAW"
*FILE_USERGROUP "システムマネージャ"
*FILE_VERSION "1.0000000000"
*HW_ATTACHMENT_ID "ATT0025"
*HW_ATTACHMENT_NAME "標準|Standard"
*HW_COUNTER_ID-0 "CUT0025"
*HW_COUNTER_ID-1 "CUT0020"
*HW_COUNTER_ID-2 "CUT0020"
*HW_COUNTER_ID-3 "CSL0021"
*HW_COUNTER_ID-4 "CMC0021"
*HW_COUNTER_NAME-0 "D/teX Ultra|D/teX Ultra"
*HW_COUNTER_NAME-1 "None|None"
*HW_COUNTER_NAME-2 "None|None"
*HW_COUNTER_NAME-3 "BBM|BBM"
*HW_COUNTER_NAME-4 "検出器モノクロメータ|Detector monochromator"
*HW_COUNTER_SELECT_NAME "D/teX Ultra|D/teX Ultra"
*HW_GONIOMETER_ID "GON0023"
*HW_GONIOMETER_NAME "SmartLab|SmartLab"
*HW_GONIOMETER_RADIUS-0 "90.0"
*HW_GONIOMETER_RADIUS-1 "114.0"
*HW_GONIOMETER_RADIUS-2 "190.0"
*HW_GONIOMETER_RADIUS-3 "300.0"
*HW_GONIOMETER_RADIUS-4 "187.0"
*HW_GONIOMETER_RADIUS-5 "300.0"
*HW_GONIOMETER_RADIUS-6 "113.0"
*HW_GONIOMETER_RADIUS-7 "331.0"
*HW_I_OPT_ID-0 "CBO0021"
*HW_I_OPT_ID-1 "ICR0023"
*HW_I_OPT_ID-2 "ISL0021"
*HW_I_OPT_ID-3 "ISO0021"
*HW_I_OPT_ID-4 "IAD0021"
*HW_I_OPT_ID-5 "IPR0001"
*HW_I_OPT_NAME-0 "CBOユニット|CBO unit"
*HW_I_OPT_NAME-1 "標準入射光学ユニット|Standard incident optical unit"
*HW_I_OPT_NAME-2 "標準入射スリットボックス|Standard incident slit box"
*HW_I_OPT_NAME-3 "入射平行スリット|Incident parallel slit"
*HW_I_OPT_NAME-4 "長手制限スリット|Length limiting slit"
*HW_I_OPT_NAME-5 "None|None"
*HW_R_ATTENUATER_AUTOMODE "0"
*HW_R_OPT_ID-0 "RSS0021"
*HW_R_OPT_ID-1 "RCR0023"
*HW_R_OPT_ID-2 "RSO0021"
*HW_R_OPT_ID-3 "RRS0021"
*HW_R_OPT_ID-4 "ATN0021"
*HW_R_OPT_ID-5 "RFL0021"
*HW_R_OPT_ID-6 "RAD0021"
*HW_R_OPT_NAME-0 "標準受光スリットボックス1|Standard receiving slit box # 1"
*HW_R_OPT_NAME-1 "標準受光光学ユニット1|Standard receiving unit # 1"
*HW_R_OPT_NAME-2 "標準受光光学ユニット2|Standard receiving optical unit # 2"
*HW_R_OPT_NAME-3 "標準受光スリットボックス2|Standard receiving slit box # 2"
*HW_R_OPT_NAME-4 "標準アッテネータ|Standard Attenuator"
*HW_R_OPT_NAME-5 "Cu Kβ|Cu K-beta"
*HW_R_OPT_NAME-6 "調整用受光スリット|Alignment receiving slit"
*HW_SAMPLE_HOLDER_ID "SMP0023"
*HW_SAMPLE_HOLDER_NAME "標準Zステージ|Standard Z stage"
*HW_XG_CURRENT_MAX "50"
*HW_XG_CURRENT_MIN "2"
*HW_XG_CURRENT_RESOLUTION "1"
*HW_XG_CURRENT_UNIT "mA"
*HW_XG_FOCUS "1mm x 10mm"
*HW_XG_FOCUS_TYPE "Normal"
*HW_XG_ID ""
*HW_XG_NAME "3kW 封入管(ID:1200)|3kW Sealed tube(ID:1200)"
*HW_XG_TARGET_ATOMIC_NUMBER "29.0000000000"
*HW_XG_TARGET_NAME "Cu"
*HW_XG_TYPE "Hermetic"
*HW_XG_VOLTAGE_MAX "60"
*HW_XG_VOLTAGE_MIN "20"
*HW_XG_VOLTAGE_RESOLUTION "1"
*HW_XG_VOLTAGE_UNIT "kV"
*HW_XG_WATT_MAX "1.500"
*HW_XG_WATT_UNIT "kW"
*HW_XG_WAVE_LENGTH_ALPHA1 "1.540593"
*HW_XG_WAVE_LENGTH_ALPHA2 "1.544414"
*HW_XG_WAVE_LENGTH_BETA "1.392250"
*MEAS_COND_AXIS_NAME-0 "2θ/θ"
*MEAS_COND_AXIS_NAME-1 "2θ"
*MEAS_COND_AXIS_NAME-2 "ω"
*MEAS_COND_AXIS_NAME-3 "Z"
*MEAS_COND_AXIS_NAME-4 "2θ/ω"
*MEAS_COND_AXIS_NAME-5 "θs"
*MEAS_COND_AXIS_NAME-6 "θd"
*MEAS_COND_AXIS_NAME-7 "Ts"
*MEAS_COND_AXIS_NAME-8 "CBO選択スリット"
*MEAS_COND_AXIS_NAME-9 "M"
*MEAS_COND_AXIS_NAME-10 "入射平行スリット"
*MEAS_COND_AXIS_NAME-11 "入射スリット"
*MEAS_COND_AXIS_NAME-12 ""
*MEAS_COND_AXIS_NAME-13 "Zs"
*MEAS_COND_AXIS_NAME-14 "入射光学素子"
*MEAS_COND_AXIS_NAME-15 "長手制限スリット"
*MEAS_COND_AXIS_NAME-16 "センタースリット"
*MEAS_COND_AXIS_NAME-17 "フィルター"
*MEAS_COND_AXIS_NAME-18 "受光スリット1"
*MEAS_COND_AXIS_NAME-19 "受光スリット2"
*MEAS_COND_AXIS_NAME-20 "受光光学素子"
*MEAS_COND_AXIS_NAME-21 "受光平行スリット"
*MEAS_COND_AXIS_NAME-22 "調整用受光スリット"
*MEAS_COND_AXIS_NAME-23 ""
*MEAS_COND_AXIS_NAME-24 ""
*MEAS_COND_AXIS_NAME-25 "Zd"
*MEAS_COND_AXIS_NAME-26 "アッテネータ"
*MEAS_COND_AXIS_NAME-27 "検出器モノクロメータ"
*MEAS_COND_AXIS_NAME-28 "モノクロメータスリット"
*MEAS_COND_AXIS_NAME-29 "プライマリビーム"
*MEAS_COND_AXIS_NAME-30 "PHA"
*MEAS_COND_AXIS_NAME_INTERNAL-0 "TwoThetaTheta"
*MEAS_COND_AXIS_NAME_INTERNAL-1 "TwoTheta"
*MEAS_COND_AXIS_NAME_INTERNAL-2 "Omega"
*MEAS_COND_AXIS_NAME_INTERNAL-3 "Z"
*MEAS_COND_AXIS_NAME_INTERNAL-4 "TwoThetaOmega"
*MEAS_COND_AXIS_NAME_INTERNAL-5 "ThetaS"
*MEAS_COND_AXIS_NAME_INTERNAL-6 "ThetaD"
*MEAS_COND_AXIS_NAME_INTERNAL-7 "Ts"
*MEAS_COND_AXIS_NAME_INTERNAL-8 "CBO"
*MEAS_COND_AXIS_NAME_INTERNAL-9 "CBO-M"
*MEAS_COND_AXIS_NAME_INTERNAL-10 "IncidentSollerSlit"
*MEAS_COND_AXIS_NAME_INTERNAL-11 "IncidentSlitBox"
*MEAS_COND_AXIS_NAME_INTERNAL-12 "IncidentSlitBox-_Axis"
*MEAS_COND_AXIS_NAME_INTERNAL-13 "Zs"
*MEAS_COND_AXIS_NAME_INTERNAL-14 "IncidentMonochromator"
*MEAS_COND_AXIS_NAME_INTERNAL-15 "IncidentAxdSlit"
*MEAS_COND_AXIS_NAME_INTERNAL-16 "CenterSlit"
*MEAS_COND_AXIS_NAME_INTERNAL-17 "Filter"
*MEAS_COND_AXIS_NAME_INTERNAL-18 "ReceivingSlitBox1"
*MEAS_COND_AXIS_NAME_INTERNAL-19 "ReceivingSlitBox2"
*MEAS_COND_AXIS_NAME_INTERNAL-20 "ReceivingOptics"
*MEAS_COND_AXIS_NAME_INTERNAL-21 "ReceivingSollerSlit"
*MEAS_COND_AXIS_NAME_INTERNAL-22 "ReceivingAxdSlit"
*MEAS_COND_AXIS_NAME_INTERNAL-23 "ReceivingSlitBox1-_Axis"
*MEAS_COND_AXIS_NAME_INTERNAL-24 "ReceivingSlitBox2-_Axis"
*MEAS_COND_AXIS_NAME_INTERNAL-25 "ReceivingSlitBox2-Zd"
*MEAS_COND_AXIS_NAME_INTERNAL-26 "Attenuator"
*MEAS_COND_AXIS_NAME_INTERNAL-27 "CounterMonochromator"
*MEAS_COND_AXIS_NAME_INTERNAL-28 "CounterSlit"
*MEAS_COND_AXIS_NAME_INTERNAL-29 "IncidentPrimary"
*MEAS_COND_AXIS_NAME_INTERNAL-30 "PHA"
*MEAS_COND_AXIS_NAME_MAGICNO-0 "83951616.0000000000"
*MEAS_COND_AXIS_NAME_MAGICNO-1 "268632064.0000000000"
*MEAS_COND_AXIS_NAME_MAGICNO-2 "268500992.0000000000"
*MEAS_COND_AXIS_NAME_MAGICNO-3 "285278208.0000000000"
*MEAS_COND_AXIS_NAME_MAGICNO-4 "83951616.0000000000"
*MEAS_COND_AXIS_NAME_MAGICNO-5 "131072.0000000000"
*MEAS_COND_AXIS_NAME_MAGICNO-6 "131072.0000000000"
*MEAS_COND_AXIS_NAME_MAGICNO-7 "318898176.0000000000"
*MEAS_COND_AXIS_NAME_MAGICNO-8 "20971521.0000000000"
*MEAS_COND_AXIS_NAME_MAGICNO-9 "285343744.0000000000"
*MEAS_COND_AXIS_NAME_MAGICNO-10 "20971521.0000000000"
*MEAS_COND_AXIS_NAME_MAGICNO-11 "22020097.0000000000"
*MEAS_COND_AXIS_NAME_MAGICNO-12 "25165824.0000000000"
*MEAS_COND_AXIS_NAME_MAGICNO-13 "318898176.0000000000"
*MEAS_COND_AXIS_NAME_MAGICNO-14 "1.0000000000"
*MEAS_COND_AXIS_NAME_MAGICNO-15 "20971521.0000000000"
*MEAS_COND_AXIS_NAME_MAGICNO-16 "20971521.0000000000"
*MEAS_COND_AXIS_NAME_MAGICNO-17 "20971521.0000000000"
*MEAS_COND_AXIS_NAME_MAGICNO-18 "23068673.0000000000"
*MEAS_COND_AXIS_NAME_MAGICNO-19 "23068673.0000000000"
*MEAS_COND_AXIS_NAME_MAGICNO-20 "20971521.0000000000"
*MEAS_COND_AXIS_NAME_MAGICNO-21 "20971521.0000000000"
*MEAS_COND_AXIS_NAME_MAGICNO-22 "20971521.0000000000"
*MEAS_COND_AXIS_NAME_MAGICNO-23 "25165824.0000000000"
*MEAS_COND_AXIS_NAME_MAGICNO-24 "25165824.0000000000"
*MEAS_COND_AXIS_NAME_MAGICNO-25 "285343744.0000000000"
*MEAS_COND_AXIS_NAME_MAGICNO-26 "17301505.0000000000"
*MEAS_COND_AXIS_NAME_MAGICNO-27 "20971521.0000000000"
*MEAS_COND_AXIS_NAME_MAGICNO-28 "20971521.0000000000"
*MEAS_COND_AXIS_NAME_MAGICNO-29 "20971521.0000000000"
*MEAS_COND_AXIS_NAME_MAGICNO-30 "0.0000000000"
*MEAS_COND_AXIS_OFFSET-0 "-"
*MEAS_COND_AXIS_OFFSET-1 "-0.1081000000"
*MEAS_COND_AXIS_OFFSET-2 "0.3758000000"
*MEAS_COND_AXIS_OFFSET-3 "-"
*MEAS_COND_AXIS_OFFSET-4 "-"
*MEAS_COND_AXIS_OFFSET-5 "0.3758000000"
*MEAS_COND_AXIS_OFFSET-6 "-0.4839000000"
*MEAS_COND_AXIS_OFFSET-7 "-"
*MEAS_COND_AXIS_OFFSET-8 "-"
*MEAS_COND_AXIS_OFFSET-9 "-"
*MEAS_COND_AXIS_OFFSET-10 "-"
*MEAS_COND_AXIS_OFFSET-11 "-"
*MEAS_COND_AXIS_OFFSET-12 "-"
*MEAS_COND_AXIS_OFFSET-13 "-"
*MEAS_COND_AXIS_OFFSET-14 "-"
*MEAS_COND_AXIS_OFFSET-15 "-"
*MEAS_COND_AXIS_OFFSET-16 "-"
*MEAS_COND_AXIS_OFFSET-17 "-"
*MEAS_COND_AXIS_OFFSET-18 "-"
*MEAS_COND_AXIS_OFFSET-19 "-"
*MEAS_COND_AXIS_OFFSET-20 "-"
*MEAS_COND_AXIS_OFFSET-21 "-"
*MEAS_COND_AXIS_OFFSET-22 "-"
*MEAS_COND_AXIS_OFFSET-23 "-"
*MEAS_COND_AXIS_OFFSET-24 "-"
*MEAS_COND_AXIS_OFFSET-25 "-"
*MEAS_COND_AXIS_OFFSET-26 "-"
*MEAS_COND_AXIS_OFFSET-27 "-"
*MEAS_COND_AXIS_OFFSET-28 "-"
*MEAS_COND_AXIS_OFFSET-29 "-"
*MEAS_COND_AXIS_OFFSET-30 "-"
*MEAS_COND_AXIS_POSITION-0 "0.0000000000"
*MEAS_COND_AXIS_POSITION-1 "0.0000000000"
*MEAS_COND_AXIS_POSITION-2 "0.0000000000"
*MEAS_COND_AXIS_POSITION-3 "-0.5500000000"
*MEAS_COND_AXIS_POSITION-4 "0.0000000000"
*MEAS_COND_AXIS_POSITION-5 "0.0000000000"
*MEAS_COND_AXIS_POSITION-6 "0.0000000000"
*MEAS_COND_AXIS_POSITION-7 "-0.4278800000"
*MEAS_COND_AXIS_POSITION-8 "BB"
*MEAS_COND_AXIS_POSITION-9 "0.0000000000"
*MEAS_COND_AXIS_POSITION-10 "Soller_slit_5.0deg"
*MEAS_COND_AXIS_POSITION-11 "2/3deg"
*MEAS_COND_AXIS_POSITION-12 "2.2088000000"
*MEAS_COND_AXIS_POSITION-13 "-0.4140600000"
*MEAS_COND_AXIS_POSITION-14 "0.0000000000"
*MEAS_COND_AXIS_POSITION-15 "10.0mm"
*MEAS_COND_AXIS_POSITION-16 "None"
*MEAS_COND_AXIS_POSITION-17 "Cu_K-beta"
*MEAS_COND_AXIS_POSITION-18 "13.000mm"
*MEAS_COND_AXIS_POSITION-19 "13.000mm"
*MEAS_COND_AXIS_POSITION-20 "No_unit"
*MEAS_COND_AXIS_POSITION-21 "Soller_slit_5.0deg"
*MEAS_COND_AXIS_POSITION-22 "None"
*MEAS_COND_AXIS_POSITION-23 "13.0000000000"
*MEAS_COND_AXIS_POSITION-24 "13.0000000000"
*MEAS_COND_AXIS_POSITION-25 "0.0109400000"
*MEAS_COND_AXIS_POSITION-26 "Open"
*MEAS_COND_AXIS_POSITION-27 "None"
*MEAS_COND_AXIS_POSITION-28 "None"
*MEAS_COND_AXIS_POSITION-29 "None"
*MEAS_COND_AXIS_POSITION-30 "38.0000000000"
*MEAS_COND_AXIS_UNIT-0 "deg"
*MEAS_COND_AXIS_UNIT-1 "deg"
*MEAS_COND_AXIS_UNIT-2 "deg"
*MEAS_COND_AXIS_UNIT-3 "mm"
*MEAS_COND_AXIS_UNIT-4 "deg"
*MEAS_COND_AXIS_UNIT-5 "deg"
*MEAS_COND_AXIS_UNIT-6 "deg"
*MEAS_COND_AXIS_UNIT-7 "mm"
*MEAS_COND_AXIS_UNIT-8 ""
*MEAS_COND_AXIS_UNIT-9 "pulse"
*MEAS_COND_AXIS_UNIT-10 ""
*MEAS_COND_AXIS_UNIT-11 ""
*MEAS_COND_AXIS_UNIT-12 "mm"
*MEAS_COND_AXIS_UNIT-13 "mm"
*MEAS_COND_AXIS_UNIT-14 ""
*MEAS_COND_AXIS_UNIT-15 ""
*MEAS_COND_AXIS_UNIT-16 ""
*MEAS_COND_AXIS_UNIT-17 ""
*MEAS_COND_AXIS_UNIT-18 ""
*MEAS_COND_AXIS_UNIT-19 ""
*MEAS_COND_AXIS_UNIT-20 ""
*MEAS_COND_AXIS_UNIT-21 ""
*MEAS_COND_AXIS_UNIT-22 ""
*MEAS_COND_AXIS_UNIT-23 "mm"
*MEAS_COND_AXIS_UNIT-24 "mm"
*MEAS_COND_AXIS_UNIT-25 "mm"
*MEAS_COND_AXIS_UNIT-26 ""
*MEAS_COND_AXIS_UNIT-27 ""
*MEAS_COND_AXIS_UNIT-28 ""
*MEAS_COND_AXIS_UNIT-29 ""
*MEAS_COND_AXIS_UNIT-30 "div"
*MEAS_COND_COUNTER_CNTLOSS_CORR "0.0000000000"
*MEAS_COND_COUNTER_PHABASE "38.0000000000"
*MEAS_COND_COUNTER_PHAWINDOW "16.0000000000"
*MEAS_COND_COUNTER_PHA_UNIT "div"
*MEAS_COND_COUNTER_TAUDIFF "30.0000000000"
*MEAS_COND_COUNTER_TAUINT "0.0000000000"
*MEAS_COND_IRRADIATION_MODE "OFF"
*MEAS_COND_IRRADIATION_WIDTH ""
*MEAS_COND_OPT_ATTR "集中法"
*MEAS_COND_OPT_NAME "@集中法"
*MEAS_COND_UNSYMMETRIC_MODE "OFF"
*MEAS_COND_XG_CURRENT "30.0000000000"
*MEAS_COND_XG_VOLTAGE "40.0000000000"
*MEAS_COND_XG_WAVE_TYPE "Ka"
*MEAS_DATA_COUNT "5001.0000000000"
*MEAS_SCAN_AXIS_X "2θ/θ"
*MEAS_SCAN_AXIS_X_INTERNAL "TwoThetaTheta"
*MEAS_SCAN_END_TIME "07/14/21 18:37:52"
*MEAS_SCAN_MODE "CONTINUOUS"
*MEAS_SCAN_MONITOR "0"
*MEAS_SCAN_RESOLUTION_X "0.0002"
*MEAS_SCAN_SPEED "1.0"
*MEAS_SCAN_SPEED_UNIT "deg/min"
*MEAS_SCAN_START "20.0000000000"
*MEAS_SCAN_START_TIME "07/14/21 17:44:58"
*MEAS_SCAN_STEP "0.0100000000"
*MEAS_SCAN_STOP "70.0000000000"
*MEAS_SCAN_UNIT_X "deg"
*MEAS_SCAN_UNIT_Y "counts"
*RAS_HEADER_END
*RAS_INT_START
20.0000 1403.0000 1.0000
20.0400 1384.0000 1.0000
20.0800 1392.0000 1.0000
20.1200 1450.0000 1.0000
20.1600 1402.0000 1.0000
20.2000 1411.0000 1.0000
20.2400 1384.0000 1.0000
20.2800 1435.0000 1.0000
20.3200 1466.0000 1.0000
20.3600 1405.0000 1.0000
20.4000 1378.0000 1.0000
20.4400 1357.0000 1.0000
20.4800 1400.0000 1.0000
20.5200 1464.0000 1.0000
20.5600 1414.0000 1.0000
20.6000 1404.0000 1.0000
20.6400 1409.0000 1.0000
20.6800 1389.0000 1.0000
20.7200 1392.0000 1.0000
20.7600 1387.0000 1.0000
20.8000 1410.0000 1.0000
20.8400 1382.0000 1.0000
20.8800 1418.0000 1.0000
20.9200 1350.0000 1.0000
20.9600 1376.0000 1.0000
21.0000 1445.0000 1.0000
21.0400 1401.0000 1.0000
21.0800 1383.0000 1.0000
21.1200 1380.0000 1.0000
21.1600 1362.0000 1.0000
21.2000 1438.0000 1.0000
21.2400 1406.0000 1.0000
21.2800 1370.0000 1.0000
21.3200 1356.0000 1.0000
21.3600 1422.0000 1.0000
21.4000 1393.0000 1.0000
21.4400 1412.0000 1.0000
21.4800 1423.0000 1.0000
21.5200 1457.0000 1.0000
21.5600 1392.0000 1.0000
21.6000 1385.0000 1.0000
21.6400 1435.0000 1.0000
21.6800 1370.0000 1.0000
21.7200 1411.0000 1.0000
21.7600 1333.0000 1.0000
21.8000 1459.0000 1.0000
21.8400 1466.0000 1.0000
21.8800 1358.0000 1.0000
21.9200 1448.0000 1.0000
21.9600 1443.0000 1.0000
22.0000 1415.0000 1.0000
22.0400 1484.0000 1.0000
22.0800 1399.0000 1.0000
22.1200 1373.0000 1.0000
22.1600 1361.0000 1.0000
22.2000 1446.0000 1.0000
22.2400 1461.0000 1.0000
22.2800 1451.0000 1.0000
22.3200 1430.0000 1.0000
22.3600 1392.0000 1.0000
22.4000 1466.0000 1.0000
22.4400 1381.0000 1.0000
22.4800 1421.0000 1.0000
22.5200 1430.0000 1.0000
22.5600 1412.0000 1.0000
22.6000 1481.0000 1.0000
22.6400 1490.0000 1.0000
22.6800 1442.0000 1.0000
22.7200 1418.0000 1.0000
22.7600 1448.0000 1.0000
22.8000 1400.0000 1.0000
22.8400 1465.0000 1.0000
22.8800 1411.0000 1.0000
22.9200 1409.0000 1.0000
22.9600 1438.0000 1.0000
23.0000 1381.0000 1.0000
23.0400 1437.0000 1.0000
23.0800 1396.0000 1.0000
23.1200 1411.0000 1.0000
23.1600 1443.0000 1.0000
23.2000 1451.0000 1.0000
23.2400 1438.0000 1.0000
23.2800 1407.0000 1.0000
23.3200 1462.0000 1.0000
23.3600 1417.0000 1.0000
23.4000 1469.0000 1.0000
23.4400 1498.0000 1.0000
23.4800 1524.0000 1.0000
23.5200 1443.0000 1.0000
23.5600 1429.0000 1.0000
23.6000 1415.0000 1.0000
23.6400 1420.0000 1.0000
23.6800 1441.0000 1.0000
23.7200 1411.0000 1.0000
23.7600 1461.0000 1.0000
23.8000 1442.0000 1.0000
23.8400 1460.0000 1.0000
23.8800 1461.0000 1.0000
23.9200 1440.0000 1.0000
23.9600 1452.0000 1.0000
24.0000 1421.0000 1.0000
24.0400 1455.0000 1.0000
24.0800 1394.0000 1.0000
24.1200 1504.0000 1.0000
24.1600 1443.0000 1.0000
24.2000 1426.0000 1.0000
24.2400 1405.0000 1.0000
24.2800 1527.0000 1.0000
24.3200 1477.0000 1.0000
24.3600 1462.0000 1.0000
24.4000 1446.0000 1.0000
24.4400 1458.0000 1.0000
24.4800 1482.0000 1.0000
24.5200 1429.0000 1.0000
24.5600 1465.0000 1.0000
24.6000 1477.0000 1.0000
24.6400 1502.0000 1.0000
24.6800 1473.0000 1.0000
24.7200 1461.0000 1.0000
24.7600 1477.0000 1.0000
24.8000 1473.0000 1.0000
24.8400 1451.0000 1.0000
24.8800 1462.0000 1.0000
24.9200 1486.0000 1.0000
24.9600 1502.0000 1.0000
25.0000 1479.0000 1.0000
25.0400 1500.0000 1.0000
25.0800 1484.0000 1.0000
25.1200 1513.0000 1.0000
25.1600 1522.0000 1.0000
25.2000 1520.0000 1.0000
25.2400 1500.0000 1.0000
25.2800 1469.0000 1.0000
25.3200 1494.0000 1.0000
25.3600 1459.0000 1.0000
25.4000 1438.0000 1.0000
25.4400 1511.0000 1.0000
25.4800 1521.0000 1.0000
25.5200 1407.0000 1.0000
25.5600 1431.0000 1.0000
25.6000 1492.0000 1.0000
25.6400 1449.0000 1.0000
25.6800 1445.0000 1.0000
25.7200 1521.0000 1.0000
25.7600 1496.0000 1.0000
25.8000 1469.0000 1.0000
25.8400 1510.0000 1.0000
25.8800 1473.0000 1.0000
25.9200 1552.0000 1.0000
25.9600 1457.0000 1.0000
26.0000 1480.0000 1.0000
26.0400 1486.0000 1.0000
26.0800 1509.0000 1.0000
26.1200 1486.0000 1.0000
26.1600 1536.0000 1.0000
26.2000 1468.0000 1.0000
26.2400 1488.0000 1.0000
26.2800 1538.0000 1.0000
26.3200 1510.0000 1.0000
26.3600 1610.0000 1.0000
26.4000 1551.0000 1.0000
26.4400 1638.0000 1.0000
26.4800 1505.0000 1.0000
26.5200 1516.0000 1.0000
26.5600 1633.0000 1.0000
26.6000 1584.0000 1.0000
26.6400 1646.0000 1.0000
26.6800 1689.0000 1.0000
26.7200 1585.0000 1.0000
26.7600 1644.0000 1.0000
26.8000 1632.0000 1.0000
26.8400 1662.0000 1.0000
26.8800 1707.0000 1.0000
26.9200 1744.0000 1.0000
26.9600 1879.0000 1.0000
27.0000 2034.0000 1.0000
27.0400 2153.0000 1.0000
27.0800 2523.0000 1.0000
27.1200 2902.0000 1.0000
27.1600 3487.0000 1.0000
27.2000 4404.0000 1.0000
27.2400 5549.0000 1.0000
27.2800 6500.0000 1.0000
27.3200 6252.0000 1.0000
27.3600 5453.0000 1.0000
27.4000 4289.0000 1.0000
27.4400 3411.0000 1.0000
27.4800 2813.0000 1.0000
27.5200 2557.0000 1.0000
27.5600 2248.0000 1.0000
27.6000 2041.0000 1.0000
27.6400 1958.0000 1.0000
27.6800 1811.0000 1.0000
27.7200 1775.0000 1.0000
27.7600 1691.0000 1.0000
27.8000 1639.0000 1.0000
27.8400 1587.0000 1.0000
27.8800 1619.0000 1.0000
27.9200 1555.0000 1.0000
27.9600 1589.0000 1.0000
28.0000 1580.0000 1.0000
28.0400 1575.0000 1.0000
28.0800 1552.0000 1.0000
28.1200 1473.0000 1.0000
28.1600 1560.0000 1.0000
28.2000 1504.0000 1.0000
28.2400 1524.0000 1.0000
28.2800 1472.0000 1.0000
28.3200 1476.0000 1.0000
28.3600 1439.0000 1.0000
28.4000 1434.0000 1.0000
28.4400 1464.0000 1.0000
28.4800 1417.0000 1.0000
28.5200 1426.0000 1.0000
28.5600 1418.0000 1.0000
28.6000 1418.0000 1.0000
28.6400 1465.0000 1.0000
28.6800 1443.0000 1.0000
28.7200 1440.0000 1.0000
28.7600 1451.0000 1.0000
28.8000 1407.0000 1.0000
28.8400 1377.0000 1.0000
28.8800 1455.0000 1.0000
28.9200 1404.0000 1.0000
28.9600 1378.0000 1.0000
29.0000 1429.0000 1.0000
29.0400 1398.0000 1.0000
29.0800 1543.0000 1.0000
29.1200 1615.0000 1.0000
29.1600 1638.0000 1.0000
29.2000 1512.0000 1.0000
29.2400 1428.0000 1.0000
29.2800 1385.0000 1.0000
29.3200 1431.0000 1.0000
29.3600 1410.0000 1.0000
29.4000 1342.0000 1.0000
29.4400 1427.0000 1.0000
29.4800 1405.0000 1.0000
29.5200 1405.0000 1.0000
29.5600 1306.0000 1.0000
29.6000 1329.0000 1.0000
29.6400 1319.0000 1.0000
29.6800 1362.0000 1.0000
29.7200 1341.0000 1.0000
29.7600 1363.0000 1.0000
29.8000 1337.0000 1.0000
29.8400 1362.0000 1.0000
29.8800 1367.0000 1.0000
29.9200 1317.0000 1.0000
29.9600 1328.0000 1.0000
30.0000 1355.0000 1.0000
30.0400 1336.0000 1.0000
30.0800 1276.0000 1.0000
30.1200 1367.0000 1.0000
30.1600 1245.0000 1.0000
30.2000 1295.0000 1.0000
30.2400 1346.0000 1.0000
30.2800 1456.0000 1.0000
30.3200 1269.0000 1.0000
30.3600 1296.0000 1.0000
30.4000 1293.0000 1.0000
30.4400 1254.0000 1.0000
30.4800 1330.0000 1.0000
30.5200 1285.0000 1.0000
30.5600 1294.0000 1.0000
30.6000 1282.0000 1.0000
30.6400 1285.0000 1.0000
30.6800 1317.0000 1.0000
30.7200 1295.0000 1.0000
30.7600 1330.0000 1.0000
30.8000 1284.0000 1.0000
30.8400 1275.0000 1.0000
30.8800 1296.0000 1.0000
30.9200 1333.0000 1.0000
30.9600 1293.0000 1.0000
31.0000 1304.0000 1.0000
31.0400 1267.0000 1.0000
31.0800 1299.0000 1.0000
31.1200 1313.0000 1.0000
31.1600 1308.0000 1.0000
31.2000 1280.0000 1.0000
31.2400 1323.0000 1.0000
31.2800 1269.0000 1.0000
31.3200 1225.0000 1.0000
31.3600 1314.0000 1.0000
31.4000 1257.0000 1.0000
31.4400 1262.0000 1.0000
31.4800 1273.0000 1.0000
31.5200 1190.0000 1.0000
31.5600 1277.0000 1.0000
31.6000 1289.0000 1.0000
31.6400 1241.0000 1.0000
31.6800 1230.0000 1.0000
31.7200 1194.0000 1.0000
31.7600 1283.0000 1.0000
31.8000 1264.0000 1.0000
31.8400 1253.0000 1.0000
31.8800 1331.0000 1.0000
31.9200 1212.0000 1.0000
31.9600 1252.0000 1.0000
32.0000 1229.0000 1.0000
32.0400 1251.0000 1.0000
32.0800 1265.0000 1.0000
32.1200 1226.0000 1.0000
32.1600 1239.0000 1.0000
32.2000 1214.0000 1.0000
32.2400 1183.0000 1.0000
32.2800 1218.0000 1.0000
32.3200 1279.0000 1.0000
32.3600 1243.0000 1.0000
32.4000 1285.0000 1.0000
32.4400 1235.0000 1.0000
32.4800 1201.0000 1.0000
32.5200 1179.0000 1.0000
32.5600 1209.0000 1.0000
32.6000 1210.0000 1.0000
32.6400 1217.0000 1.0000
32.6800 1171.0000 1.0000
32.7200 1233.0000 1.0000
32.7600 1175.0000 1.0000
32.8000 1200.0000 1.0000
32.8400 1235.0000 1.0000
32.8800 1174.0000 1.0000
32.9200 1193.0000 1.0000
32.9600 1202.0000 1.0000
33.0000 1143.0000 1.0000
33.0400 1166.0000 1.0000
33.0800 1156.0000 1.0000
33.1200 1194.0000 1.0000
33.1600 1122.0000 1.0000
33.2000 1187.0000 1.0000
33.2400 1144.0000 1.0000
33.2800 1140.0000 1.0000
33.3200 1144.0000 1.0000
33.3600 1133.0000 1.0000
33.4000 1206.0000 1.0000
33.4400 1200.0000 1.0000
33.4800 1191.0000 1.0000
33.5200 1188.0000 1.0000
33.5600 1165.0000 1.0000
33.6000 1205.0000 1.0000
33.6400 1185.0000 1.0000
33.6800 1166.0000 1.0000
33.7200 1199.0000 1.0000
33.7600 1206.0000 1.0000
33.8000 1253.0000 1.0000
33.8400 1219.0000 1.0000
33.8800 1216.0000 1.0000
33.9200 1231.0000 1.0000
33.9600 1215.0000 1.0000
34.0000 1254.0000 1.0000
34.0400 1278.0000 1.0000
34.0800 1277.0000 1.0000
34.1200 1248.0000 1.0000
34.1600 1375.0000 1.0000
34.2000 1387.0000 1.0000
34.2400 1519.0000 1.0000
34.2800 1610.0000 1.0000
34.3200 1806.0000 1.0000
34.3600 2058.0000 1.0000
34.4000 2585.0000 1.0000
34.4400 3005.0000 1.0000
34.4800 3394.0000 1.0000
34.5200 3134.0000 1.0000
34.5600 2763.0000 1.0000
34.6000 2458.0000 1.0000
34.6400 2050.0000 1.0000
34.6800 1737.0000 1.0000
34.7200 1567.0000 1.0000
34.7600 1487.0000 1.0000
34.8000 1351.0000 1.0000
34.8400 1322.0000 1.0000
34.8800 1271.0000 1.0000
34.9200 1236.0000 1.0000
34.9600 1165.0000 1.0000
35.0000 1097.0000 1.0000
35.0400 1075.0000 1.0000
35.0800 1160.0000 1.0000
35.1200 1114.0000 1.0000
35.1600 1079.0000 1.0000
35.2000 1045.0000 1.0000
35.2400 1071.0000 1.0000
35.2800 1048.0000 1.0000
35.3200 1012.0000 1.0000
35.3600 1011.0000 1.0000
35.4000 1013.0000 1.0000
35.4400 1075.0000 1.0000
35.4800 1020.0000 1.0000
35.5200 1024.0000 1.0000
35.5600 1011.0000 1.0000
35.6000 993.0000 1.0000
35.6400 960.0000 1.0000
35.6800 1038.0000 1.0000
35.7200 1017.0000 1.0000
35.7600 1010.0000 1.0000
35.8000 1039.0000 1.0000
35.8400 1021.0000 1.0000
35.8800 975.0000 1.0000
35.9200 974.0000 1.0000
35.9600 1028.0000 1.0000
36.0000 994.0000 1.0000
36.0400 1052.0000 1.0000
36.0800 1043.0000 1.0000
36.1200 1014.0000 1.0000
36.1600 983.0000 1.0000
36.2000 1032.0000 1.0000
36.2400 1022.0000 1.0000
36.2800 1068.0000 1.0000
36.3200 1086.0000 1.0000
36.3600 1013.0000 1.0000
36.4000 999.0000 1.0000
36.4400 1000.0000 1.0000
36.4800 1014.0000 1.0000
36.5200 975.0000 1.0000
36.5600 974.0000 1.0000
36.6000 967.0000 1.0000
36.6400 923.0000 1.0000
36.6800 984.0000 1.0000
36.7200 916.0000 1.0000
36.7600 926.0000 1.0000
36.8000 953.0000 1.0000
36.8400 944.0000 1.0000
36.8800 920.0000 1.0000
36.9200 892.0000 1.0000
36.9600 916.0000 1.0000
37.0000 872.0000 1.0000
37.0400 889.0000 1.0000
37.0800 927.0000 1.0000
37.1200 911.0000 1.0000
37.1600 908.0000 1.0000
37.2000 944.0000 1.0000
37.2400 929.0000 1.0000
37.2800 877.0000 1.0000
37.3200 857.0000 1.0000
37.3600 896.0000 1.0000
37.4000 876.0000 1.0000
37.4400 892.0000 1.0000
37.4800 895.0000 1.0000
37.5200 921.0000 1.0000
37.5600 884.0000 1.0000
37.6000 908.0000 1.0000
37.6400 955.0000 1.0000
37.6800 899.0000 1.0000
37.7200 889.0000 1.0000
37.7600 889.0000 1.0000
37.8000 898.0000 1.0000
37.8400 888.0000 1.0000
37.8800 911.0000 1.0000
37.9200 953.0000 1.0000
37.9600 928.0000 1.0000
38.0000 990.0000 1.0000
38.0400 967.0000 1.0000
38.0800 1059.0000 1.0000
38.1200 1060.0000 1.0000
38.1600 1162.0000 1.0000
38.2000 1295.0000 1.0000
38.2400 1402.0000 1.0000
38.2800 1680.0000 1.0000
38.3200 1980.0000 1.0000
38.3600 2465.0000 1.0000
38.4000 3274.0000 1.0000
38.4400 4447.0000 1.0000
38.4800 5334.0000 1.0000
38.5200 5944.0000 1.0000
38.5600 5627.0000 1.0000
38.6000 4942.0000 1.0000
38.6400 4105.0000 1.0000
38.6800 3041.0000 1.0000
38.7200 2284.0000 1.0000
38.7600 1732.0000 1.0000
38.8000 1542.0000 1.0000
38.8400 1302.0000 1.0000
38.8800 1170.0000 1.0000
38.9200 1047.0000 1.0000
38.9600 938.0000 1.0000
39.0000 966.0000 1.0000
39.0400 938.0000 1.0000
39.0800 914.0000 1.0000
39.1200 878.0000 1.0000
39.1600 870.0000 1.0000
39.2000 843.0000 1.0000
39.2400 821.0000 1.0000
39.2800 811.0000 1.0000
39.3200 775.0000 1.0000
39.3600 785.0000 1.0000
39.4000 825.0000 1.0000
39.4400 866.0000 1.0000
39.4800 811.0000 1.0000
39.5200 865.0000 1.0000
39.5600 829.0000 1.0000
39.6000 795.0000 1.0000
39.6400 861.0000 1.0000
39.6800 804.0000 1.0000
39.7200 844.0000 1.0000
39.7600 804.0000 1.0000
39.8000 790.0000 1.0000
39.8400 803.0000 1.0000
39.8800 763.0000 1.0000
39.9200 766.0000 1.0000
39.9600 747.0000 1.0000
40.0000 782.0000 1.0000
40.0400 700.0000 1.0000
40.0800 750.0000 1.0000
40.1200 741.0000 1.0000
40.1600 736.0000 1.0000
40.2000 757.0000 1.0000
40.2400 741.0000 1.0000
40.2800 718.0000 1.0000
40.3200 766.0000 1.0000
40.3600 736.0000 1.0000
40.4000 756.0000 1.0000
40.4400 747.0000 1.0000
40.4800 710.0000 1.0000
40.5200 754.0000 1.0000
40.5600 736.0000 1.0000
40.6000 720.0000 1.0000
40.6400 716.0000 1.0000
40.6800 778.0000 1.0000
40.7200 715.0000 1.0000
40.7600 736.0000 1.0000
40.8000 776.0000 1.0000
40.8400 727.0000 1.0000
40.8800 705.0000 1.0000
40.9200 727.0000 1.0000
40.9600 725.0000 1.0000
41.0000 735.0000 1.0000
41.0400 679.0000 1.0000
41.0800 696.0000 1.0000
41.1200 708.0000 1.0000
41.1600 693.0000 1.0000
41.2000 730.0000 1.0000
41.2400 752.0000 1.0000
41.2800 706.0000 1.0000
41.3200 707.0000 1.0000
41.3600 696.0000 1.0000
41.4000 746.0000 1.0000
41.4400 744.0000 1.0000
41.4800 702.0000 1.0000
41.5200 681.0000 1.0000
41.5600 718.0000 1.0000
41.6000 701.0000 1.0000
41.6400 735.0000 1.0000
41.6800 693.0000 1.0000
41.7200 730.0000 1.0000
41.7600 724.0000 1.0000
41.8000 717.0000 1.0000
41.8400 727.0000 1.0000
41.8800 721.0000 1.0000
41.9200 724.0000 1.0000
41.9600 733.0000 1.0000
42.0000 748.0000 1.0000
42.0400 710.0000 1.0000
42.0800 727.0000 1.0000
42.1200 733.0000 1.0000
42.1600 710.0000 1.0000
42.2000 757.0000 1.0000
42.2400 673.0000 1.0000
42.2800 720.0000 1.0000
42.3200 715.0000 1.0000
42.3600 723.0000 1.0000
42.4000 750.0000 1.0000
42.4400 708.0000 1.0000
42.4800 693.0000 1.0000
42.5200 717.0000 1.0000
42.5600 707.0000 1.0000
42.6000 697.0000 1.0000
42.6400 695.0000 1.0000
42.6800 687.0000 1.0000
42.7200 711.0000 1.0000
42.7600 672.0000 1.0000
42.8000 729.0000 1.0000
42.8400 698.0000 1.0000
42.8800 714.0000 1.0000
42.9200 683.0000 1.0000
42.9600 714.0000 1.0000
43.0000 685.0000 1.0000
43.0400 717.0000 1.0000
43.0800 742.0000 1.0000
43.1200 787.0000 1.0000
43.1600 773.0000 1.0000
43.2000 778.0000 1.0000
43.2400 763.0000 1.0000
43.2800 820.0000 1.0000
43.3200 718.0000 1.0000
43.3600 749.0000 1.0000
43.4000 712.0000 1.0000
43.4400 728.0000 1.0000
43.4800 701.0000 1.0000
43.5200 682.0000 1.0000
43.5600 685.0000 1.0000
43.6000 649.0000 1.0000
43.6400 679.0000 1.0000
43.6800 662.0000 1.0000
43.7200 678.0000 1.0000
43.7600 700.0000 1.0000
43.8000 670.0000 1.0000
43.8400 720.0000 1.0000
43.8800 690.0000 1.0000
43.9200 652.0000 1.0000
43.9600 670.0000 1.0000
44.0000 662.0000 1.0000
44.0400 691.0000 1.0000
44.0800 665.0000 1.0000
44.1200 757.0000 1.0000
44.1600 674.0000 1.0000
44.2000 664.0000 1.0000
44.2400 623.0000 1.0000
44.2800 707.0000 1.0000
44.3200 702.0000 1.0000
44.3600 678.0000 1.0000
44.4000 664.0000 1.0000
44.4400 714.0000 1.0000
44.4800 701.0000 1.0000
44.5200 702.0000 1.0000
44.5600 672.0000 1.0000
44.6000 690.0000 1.0000
44.6400 694.0000 1.0000
44.6800 683.0000 1.0000
44.7200 637.0000 1.0000
44.7600 712.0000 1.0000
44.8000 642.0000 1.0000
44.8400 639.0000 1.0000
44.8800 720.0000 1.0000
44.9200 652.0000 1.0000
44.9600 653.0000 1.0000
45.0000 664.0000 1.0000
45.0400 657.0000 1.0000
45.0800 648.0000 1.0000
45.1200 644.0000 1.0000
45.1600 641.0000 1.0000
45.2000 679.0000 1.0000
45.2400 642.0000 1.0000
45.2800 651.0000 1.0000
45.3200 655.0000 1.0000
45.3600 688.0000 1.0000
45.4000 655.0000 1.0000
45.4400 657.0000 1.0000
45.4800 662.0000 1.0000
45.5200 621.0000 1.0000
45.5600 649.0000 1.0000
45.6000 646.0000 1.0000
45.6400 656.0000 1.0000
45.6800 641.0000 1.0000
45.7200 658.0000 1.0000
45.7600 652.0000 1.0000
45.8000 674.0000 1.0000
45.8400 648.0000 1.0000
45.8800 638.0000 1.0000
45.9200 622.0000 1.0000
45.9600 622.0000 1.0000
46.0000 658.0000 1.0000
46.0400 631.0000 1.0000
46.0800 631.0000 1.0000
46.1200 648.0000 1.0000
46.1600 665.0000 1.0000
46.2000 659.0000 1.0000
46.2400 618.0000 1.0000
46.2800 632.0000 1.0000
46.3200 664.0000 1.0000
46.3600 638.0000 1.0000
46.4000 628.0000 1.0000
46.4400 649.0000 1.0000
46.4800 675.0000 1.0000
46.5200 629.0000 1.0000
46.5600 630.0000 1.0000
46.6000 623.0000 1.0000
46.6400 649.0000 1.0000
46.6800 656.0000 1.0000
46.7200 606.0000 1.0000
46.7600 634.0000 1.0000
46.8000 607.0000 1.0000
46.8400 653.0000 1.0000
46.8800 671.0000 1.0000
46.9200 629.0000 1.0000
46.9600 653.0000 1.0000
47.0000 666.0000 1.0000
47.0400 652.0000 1.0000
47.0800 638.0000 1.0000
47.1200 627.0000 1.0000
47.1600 652.0000 1.0000
47.2000 636.0000 1.0000
47.2400 572.0000 1.0000
47.2800 620.0000 1.0000
47.3200 640.0000 1.0000
47.3600 606.0000 1.0000
47.4000 620.0000 1.0000
47.4400 613.0000 1.0000
47.4800 574.0000 1.0000
47.5200 612.0000 1.0000
47.5600 642.0000 1.0000
47.6000 607.0000 1.0000
47.6400 591.0000 1.0000
47.6800 609.0000 1.0000
47.7200 613.0000 1.0000
47.7600 617.0000 1.0000
47.8000 629.0000 1.0000
47.8400 624.0000 1.0000
47.8800 611.0000 1.0000
47.9200 647.0000 1.0000
47.9600 627.0000 1.0000
48.0000 556.0000 1.0000
48.0400 622.0000 1.0000
48.0800 615.0000 1.0000
48.1200 600.0000 1.0000
48.1600 657.0000 1.0000
48.2000 601.0000 1.0000
48.2400 594.0000 1.0000
48.2800 612.0000 1.0000
48.3200 631.0000 1.0000
48.3600 613.0000 1.0000
48.4000 615.0000 1.0000
48.4400 579.0000 1.0000
48.4800 556.0000 1.0000
48.5200 592.0000 1.0000
48.5600 580.0000 1.0000
48.6000 613.0000 1.0000
48.6400 601.0000 1.0000
48.6800 605.0000 1.0000
48.7200 630.0000 1.0000
48.7600 620.0000 1.0000
48.8000 595.0000 1.0000
48.8400 610.0000 1.0000
48.8800 571.0000 1.0000
48.9200 564.0000 1.0000
48.9600 555.0000 1.0000
49.0000 617.0000 1.0000
49.0400 626.0000 1.0000
49.0800 595.0000 1.0000
49.1200 588.0000 1.0000
49.1600 582.0000 1.0000
49.2000 573.0000 1.0000
49.2400 615.0000 1.0000
49.2800 605.0000 1.0000
49.3200 598.0000 1.0000
49.3600 593.0000 1.0000
49.4000 588.0000 1.0000
49.4400 551.0000 1.0000
49.4800 571.0000 1.0000
49.5200 601.0000 1.0000
49.5600 578.0000 1.0000
49.6000 574.0000 1.0000
49.6400 596.0000 1.0000
49.6800 588.0000 1.0000
49.7200 600.0000 1.0000
49.7600 597.0000 1.0000
49.8000 585.0000 1.0000
49.8400 539.0000 1.0000
49.8800 587.0000 1.0000
49.9200 619.0000 1.0000
49.9600 547.0000 1.0000
50.0000 594.0000 1.0000
50.0400 596.0000 1.0000
50.0800 570.0000 1.0000
50.1200 604.0000 1.0000
50.1600 606.0000 1.0000
50.2000 578.0000 1.0000
50.2400 547.0000 1.0000
50.2800 565.0000 1.0000
50.3200 607.0000 1.0000
50.3600 587.0000 1.0000
50.4000 620.0000 1.0000
50.4400 602.0000 1.0000
50.4800 604.0000 1.0000
50.5200 542.0000 1.0000
50.5600 596.0000 1.0000
50.6000 613.0000 1.0000
50.6400 624.0000 1.0000
50.6800 552.0000 1.0000
50.7200 639.0000 1.0000
50.7600 612.0000 1.0000
50.8000 617.0000 1.0000
50.8400 596.0000 1.0000
50.8800 576.0000 1.0000
50.9200 616.0000 1.0000
50.9600 554.0000 1.0000
51.0000 604.0000 1.0000
51.0400 566.0000 1.0000
51.0800 568.0000 1.0000
51.1200 608.0000 1.0000
51.1600 602.0000 1.0000
51.2000 593.0000 1.0000
51.2400 620.0000 1.0000
51.2800 604.0000 1.0000
51.3200 587.0000 1.0000
51.3600 641.0000 1.0000
51.4000 617.0000 1.0000
51.4400 653.0000 1.0000
51.4800 634.0000 1.0000
51.5200 602.0000 1.0000
51.5600 622.0000 1.0000
51.6000 618.0000 1.0000
51.6400 617.0000 1.0000
51.6800 646.0000 1.0000
51.7200 663.0000 1.0000
51.7600 642.0000 1.0000
51.8000 673.0000 1.0000
51.8400 665.0000 1.0000
51.8800 779.0000 1.0000
51.9200 807.0000 1.0000
51.9600 915.0000 1.0000
52.0000 1051.0000 1.0000
52.0400 1300.0000 1.0000
52.0800 1515.0000 1.0000
52.1200 1947.0000 1.0000
52.1600 2872.0000 1.0000
52.2000 4004.0000 1.0000
52.2400 4950.0000 1.0000
52.2800 4730.0000 1.0000
52.3200 4166.0000 1.0000
52.3600 3797.0000 1.0000
52.4000 3375.0000 1.0000
52.4400 2731.0000 1.0000
52.4800 1948.0000 1.0000
52.5200 1462.0000 1.0000
52.5600 1224.0000 1.0000
52.6000 1037.0000 1.0000
52.6400 917.0000 1.0000
52.6800 889.0000 1.0000
52.7200 790.0000 1.0000
52.7600 684.0000 1.0000
52.8000 685.0000 1.0000
52.8400 690.0000 1.0000
52.8800 666.0000 1.0000
52.9200 631.0000 1.0000
52.9600 633.0000 1.0000
53.0000 589.0000 1.0000
53.0400 606.0000 1.0000
53.0800 629.0000 1.0000
53.1200 607.0000 1.0000
53.1600 612.0000 1.0000
53.2000 645.0000 1.0000
53.2400 630.0000 1.0000
53.2800 620.0000 1.0000
53.3200 599.0000 1.0000
53.3600 575.0000 1.0000
53.4000 562.0000 1.0000
53.4400 545.0000 1.0000
53.4800 580.0000 1.0000
53.5200 569.0000 1.0000
53.5600 567.0000 1.0000
53.6000 586.0000 1.0000
53.6400 619.0000 1.0000
53.6800 586.0000 1.0000
53.7200 573.0000 1.0000
53.7600 593.0000 1.0000
53.8000 558.0000 1.0000
53.8400 578.0000 1.0000
53.8800 569.0000 1.0000
53.9200 534.0000 1.0000
53.9600 592.0000 1.0000
54.0000 546.0000 1.0000
54.0400 553.0000 1.0000
54.0800 580.0000 1.0000
54.1200 582.0000 1.0000
54.1600 557.0000 1.0000
54.2000 594.0000 1.0000
54.2400 564.0000 1.0000
54.2800 604.0000 1.0000
54.3200 565.0000 1.0000
54.3600 519.0000 1.0000
54.4000 600.0000 1.0000
54.4400 595.0000 1.0000
54.4800 557.0000 1.0000
54.5200 566.0000 1.0000
54.5600 639.0000 1.0000
54.6000 595.0000 1.0000
54.6400 597.0000 1.0000
54.6800 599.0000 1.0000
54.7200 603.0000 1.0000
54.7600 553.0000 1.0000
54.8000 596.0000 1.0000
54.8400 591.0000 1.0000
54.8800 576.0000 1.0000
54.9200 616.0000 1.0000
54.9600 621.0000 1.0000
55.0000 629.0000 1.0000
55.0400 654.0000 1.0000
55.0800 696.0000 1.0000
55.1200 729.0000 1.0000
55.1600 750.0000 1.0000
55.2000 855.0000 1.0000
55.2400 976.0000 1.0000
55.2800 969.0000 1.0000
55.3200 864.0000 1.0000
55.3600 868.0000 1.0000
55.4000 871.0000 1.0000
55.4400 784.0000 1.0000
55.4800 742.0000 1.0000
55.5200 697.0000 1.0000
55.5600 695.0000 1.0000
55.6000 641.0000 1.0000
55.6400 609.0000 1.0000
55.6800 593.0000 1.0000
55.7200 574.0000 1.0000
55.7600 601.0000 1.0000
55.8000 563.0000 1.0000
55.8400 571.0000 1.0000
55.8800 566.0000 1.0000
55.9200 581.0000 1.0000
55.9600 570.0000 1.0000
56.0000 603.0000 1.0000
56.0400 551.0000 1.0000
56.0800 571.0000 1.0000
56.1200 548.0000 1.0000
56.1600 576.0000 1.0000
56.2000 558.0000 1.0000
56.2400 552.0000 1.0000
56.2800 568.0000 1.0000
56.3200 550.0000 1.0000
56.3600 508.0000 1.0000
56.4000 562.0000 1.0000
56.4400 542.0000 1.0000
56.4800 582.0000 1.0000
56.5200 540.0000 1.0000
56.5600 545.0000 1.0000
56.6000 579.0000 1.0000
56.6400 566.0000 1.0000
56.6800 563.0000 1.0000
56.7200 546.0000 1.0000
56.7600 566.0000 1.0000
56.8000 532.0000 1.0000
56.8400 570.0000 1.0000
56.8800 525.0000 1.0000
56.9200 546.0000 1.0000
56.9600 576.0000 1.0000
57.0000 533.0000 1.0000
57.0400 519.0000 1.0000
57.0800 541.0000 1.0000
57.1200 549.0000 1.0000
57.1600 528.0000 1.0000
57.2000 549.0000 1.0000
57.2400 555.0000 1.0000
57.2800 562.0000 1.0000
57.3200 536.0000 1.0000
57.3600 558.0000 1.0000
57.4000 554.0000 1.0000
57.4400 514.0000 1.0000
57.4800 551.0000 1.0000
57.5200 577.0000 1.0000
57.5600 493.0000 1.0000
57.6000 549.0000 1.0000
57.6400 519.0000 1.0000
57.6800 519.0000 1.0000
57.7200 547.0000 1.0000
57.7600 546.0000 1.0000
57.8000 507.0000 1.0000
57.8400 532.0000 1.0000
57.8800 535.0000 1.0000
57.9200 513.0000 1.0000
57.9600 543.0000 1.0000
58.0000 532.0000 1.0000
58.0400 510.0000 1.0000
58.0800 598.0000 1.0000
58.1200 577.0000 1.0000
58.1600 549.0000 1.0000
58.2000 541.0000 1.0000
58.2400 544.0000 1.0000
58.2800 547.0000 1.0000
58.3200 556.0000 1.0000
58.3600 537.0000 1.0000
58.4000 550.0000 1.0000
58.4400 521.0000 1.0000
58.4800 505.0000 1.0000
58.5200 559.0000 1.0000
58.5600 544.0000 1.0000
58.6000 532.0000 1.0000
58.6400 514.0000 1.0000
58.6800 537.0000 1.0000
58.7200 556.0000 1.0000
58.7600 539.0000 1.0000
58.8000 546.0000 1.0000
58.8400 557.0000 1.0000
58.8800 555.0000 1.0000
58.9200 544.0000 1.0000
58.9600 531.0000 1.0000
59.0000 587.0000 1.0000
59.0400 539.0000 1.0000
59.0800 549.0000 1.0000
59.1200 552.0000 1.0000
59.1600 518.0000 1.0000
59.2000 540.0000 1.0000
59.2400 570.0000 1.0000
59.2800 561.0000 1.0000
59.3200 533.0000 1.0000
59.3600 544.0000 1.0000
59.4000 527.0000 1.0000
59.4400 506.0000 1.0000
59.4800 553.0000 1.0000
59.5200 537.0000 1.0000
59.5600 508.0000 1.0000
59.6000 528.0000 1.0000
59.6400 536.0000 1.0000
59.6800 507.0000 1.0000
59.7200 499.0000 1.0000
59.7600 518.0000 1.0000
59.8000 539.0000 1.0000
59.8400 519.0000 1.0000
59.8800 557.0000 1.0000
59.9200 500.0000 1.0000
59.9600 539.0000 1.0000
60.0000 547.0000 1.0000
60.0400 538.0000 1.0000
60.0800 518.0000 1.0000
60.1200 562.0000 1.0000
60.1600 518.0000 1.0000
60.2000 533.0000 1.0000
60.2400 493.0000 1.0000
60.2800 541.0000 1.0000
60.3200 516.0000 1.0000
60.3600 508.0000 1.0000
60.4000 533.0000 1.0000
60.4400 542.0000 1.0000
60.4800 543.0000 1.0000
60.5200 529.0000 1.0000
60.5600 548.0000 1.0000
60.6000 548.0000 1.0000
60.6400 553.0000 1.0000
60.6800 525.0000 1.0000
60.7200 536.0000 1.0000
60.7600 512.0000 1.0000
60.8000 518.0000 1.0000
60.8400 506.0000 1.0000
60.8800 505.0000 1.0000
60.9200 523.0000 1.0000
60.9600 530.0000 1.0000
61.0000 534.0000 1.0000
61.0400 525.0000 1.0000
61.0800 509.0000 1.0000
61.1200 570.0000 1.0000
61.1600 548.0000 1.0000
61.2000 545.0000 1.0000
61.2400 534.0000 1.0000
61.2800 508.0000 1.0000
61.3200 534.0000 1.0000
61.3600 588.0000 1.0000
61.4000 550.0000 1.0000
61.4400 552.0000 1.0000
61.4800 553.0000 1.0000
61.5200 564.0000 1.0000
61.5600 534.0000 1.0000
61.6000 558.0000 1.0000
61.6400 557.0000 1.0000
61.6800 570.0000 1.0000
61.7200 599.0000 1.0000
61.7600 553.0000 1.0000
61.8000 570.0000 1.0000
61.8400 660.0000 1.0000
61.8800 595.0000 1.0000
61.9200 624.0000 1.0000
61.9600 696.0000 1.0000
62.0000 712.0000 1.0000
62.0400 769.0000 1.0000
62.0800 867.0000 1.0000
62.1200 955.0000 1.0000
62.1600 1065.0000 1.0000
62.2000 1191.0000 1.0000
62.2400 1339.0000 1.0000
62.2800 1290.0000 1.0000
62.3200 1284.0000 1.0000
62.3600 1211.0000 1.0000
62.4000 1231.0000 1.0000
62.4400 1050.0000 1.0000
62.4800 1036.0000 1.0000
62.5200 923.0000 1.0000
62.5600 825.0000 1.0000
62.6000 778.0000 1.0000
62.6400 727.0000 1.0000
62.6800 692.0000 1.0000
62.7200 641.0000 1.0000
62.7600 646.0000 1.0000
62.8000 609.0000 1.0000
62.8400 633.0000 1.0000
62.8800 610.0000 1.0000
62.9200 572.0000 1.0000
62.9600 563.0000 1.0000
63.0000 613.0000 1.0000
63.0400 570.0000 1.0000
63.0800 568.0000 1.0000
63.1200 587.0000 1.0000
63.1600 539.0000 1.0000
63.2000 536.0000 1.0000
63.2400 555.0000 1.0000
63.2800 569.0000 1.0000
63.3200 556.0000 1.0000
63.3600 541.0000 1.0000
63.4000 531.0000 1.0000
63.4400 543.0000 1.0000
63.4800 559.0000 1.0000
63.5200 528.0000 1.0000
63.5600 547.0000 1.0000
63.6000 534.0000 1.0000
63.6400 515.0000 1.0000
63.6800 551.0000 1.0000
63.7200 581.0000 1.0000
63.7600 533.0000 1.0000
63.8000 517.0000 1.0000
63.8400 534.0000 1.0000
63.8800 505.0000 1.0000
63.9200 508.0000 1.0000
63.9600 539.0000 1.0000
64.0000 546.0000 1.0000
64.0400 507.0000 1.0000
64.0800 539.0000 1.0000
64.1200 512.0000 1.0000
64.1600 519.0000 1.0000
64.2000 524.0000 1.0000
64.2400 542.0000 1.0000
64.2800 563.0000 1.0000
64.3200 531.0000 1.0000
64.3600 501.0000 1.0000
64.4000 525.0000 1.0000
64.4400 565.0000 1.0000
64.4800 545.0000 1.0000
64.5200 522.0000 1.0000
64.5600 531.0000 1.0000
64.6000 567.0000 1.0000
64.6400 561.0000 1.0000
64.6800 566.0000 1.0000
64.7200 554.0000 1.0000
64.7600 548.0000 1.0000
64.8000 586.0000 1.0000
64.8400 583.0000 1.0000
64.8800 577.0000 1.0000
64.9200 568.0000 1.0000
64.9600 560.0000 1.0000
65.0000 600.0000 1.0000
65.0400 542.0000 1.0000
65.0800 585.0000 1.0000
65.1200 554.0000 1.0000
65.1600 584.0000 1.0000
65.2000 563.0000 1.0000
65.2400 551.0000 1.0000
65.2800 541.0000 1.0000
65.3200 481.0000 1.0000
65.3600 560.0000 1.0000
65.4000 560.0000 1.0000
65.4400 567.0000 1.0000
65.4800 558.0000 1.0000
65.5200 587.0000 1.0000
65.5600 540.0000 1.0000
65.6000 560.0000 1.0000
65.6400 568.0000 1.0000
65.6800 581.0000 1.0000
65.7200 555.0000 1.0000
65.7600 623.0000 1.0000
65.8000 629.0000 1.0000
65.8400 632.0000 1.0000
65.8800 679.0000 1.0000
65.9200 759.0000 1.0000
65.9600 797.0000 1.0000
66.0000 882.0000 1.0000
66.0400 1024.0000 1.0000
66.0800 1199.0000 1.0000
66.1200 1478.0000 1.0000
66.1600 1876.0000 1.0000
66.2000 2238.0000 1.0000
66.2400 2301.0000 1.0000
66.2800 2119.0000 1.0000
66.3200 2041.0000 1.0000
66.3600 1940.0000 1.0000
66.4000 1798.0000 1.0000
66.4400 1623.0000 1.0000
66.4800 1461.0000 1.0000
66.5200 1225.0000 1.0000
66.5600 1032.0000 1.0000
66.6000 906.0000 1.0000
66.6400 836.0000 1.0000
66.6800 749.0000 1.0000
66.7200 678.0000 1.0000
66.7600 648.0000 1.0000
66.8000 627.0000 1.0000
66.8400 581.0000 1.0000
66.8800 628.0000 1.0000
66.9200 560.0000 1.0000
66.9600 563.0000 1.0000
67.0000 520.0000 1.0000
67.0400 523.0000 1.0000
67.0800 528.0000 1.0000
67.1200 485.0000 1.0000
67.1600 492.0000 1.0000
67.2000 516.0000 1.0000
67.2400 517.0000 1.0000
67.2800 525.0000 1.0000
67.3200 490.0000 1.0000
67.3600 489.0000 1.0000
67.4000 483.0000 1.0000
67.4400 476.0000 1.0000
67.4800 497.0000 1.0000
67.5200 507.0000 1.0000
67.5600 483.0000 1.0000
67.6000 504.0000 1.0000
67.6400 496.0000 1.0000
67.6800 502.0000 1.0000
67.7200 500.0000 1.0000
67.7600 463.0000 1.0000
67.8000 479.0000 1.0000
67.8400 498.0000 1.0000
67.8800 482.0000 1.0000
67.9200 475.0000 1.0000
67.9600 519.0000 1.0000
68.0000 465.0000 1.0000
68.0400 457.0000 1.0000
68.0800 496.0000 1.0000
68.1200 457.0000 1.0000
68.1600 499.0000 1.0000
68.2000 510.0000 1.0000
68.2400 445.0000 1.0000
68.2800 464.0000 1.0000
68.3200 485.0000 1.0000
68.3600 494.0000 1.0000
68.4000 477.0000 1.0000
68.4400 469.0000 1.0000
68.4800 453.0000 1.0000
68.5200 473.0000 1.0000
68.5600 455.0000 1.0000
68.6000 464.0000 1.0000
68.6400 477.0000 1.0000
68.6800 475.0000 1.0000
68.7200 490.0000 1.0000
68.7600 482.0000 1.0000
68.8000 430.0000 1.0000
68.8400 455.0000 1.0000
68.8800 472.0000 1.0000
68.9200 478.0000 1.0000
68.9600 459.0000 1.0000
69.0000 442.0000 1.0000
69.0400 489.0000 1.0000
69.0800 437.0000 1.0000
69.1200 458.0000 1.0000
69.1600 446.0000 1.0000
69.2000 458.0000 1.0000
69.2400 442.0000 1.0000
69.2800 439.0000 1.0000
69.3200 445.0000 1.0000
69.3600 461.0000 1.0000
69.4000 445.0000 1.0000
69.4400 456.0000 1.0000
69.4800 450.0000 1.0000
69.5200 465.0000 1.0000
69.5600 445.0000 1.0000
69.6000 441.0000 1.0000
69.6400 448.0000 1.0000
69.6800 448.0000 1.0000
69.7200 438.0000 1.0000
69.7600 470.0000 1.0000
69.8000 434.0000 1.0000
69.8400 437.0000 1.0000
69.8800 465.0000 1.0000
69.9200 470.0000 1.0000
69.9600 454.0000 1.0000
70.0000 429.0000 1.0000
*RAS_INT_END
*RAS_TEMPERATURE_START
*RAS_TEMPERATURE_END
*RAS_DATA_END